Workbook

Sheet Dashboard
A1: DECLARACION PATRIMONIAL - TABLERO EJECUTIVO
A2: GONZALEZ NAVAS MARCO VINICIO | R - RUC: 1709164899001 | SOC - Sociedad conyugal o union de hecho | Comparativo 2025 vs 2026
B6: TOTAL ACTIVOS | D6: TOTAL PASIVOS | F6: PATRIMONIO NETO
B7: =D20 | D7: =D25 | F7: =D31
B8: Var. proyectada | C8: =G20 | D8: Var. proyectada | E8: =G25 | F8: Var. proyectada | G8: =G31
B10: ACTIVOS
B11: Concepto | D11: Total 2025 | E11: Total 2026 | F11: Variacion | G11: Variacion %
B12: Dinero e inversiones | D12: ='Dinero'!J10 | E12: ='Dinero'!K10 | F12: =E12-D12 | G12: =IF(D12=0,"",(E12-D12)/D12)
B13: Derechos representativos de capital | D13: ='Derechos de Capital'!J14 | E13: ='Derechos de Capital'!K14 | F13: =E13-D13 | G13: =IF(D13=0,"",(E13-D13)/D13)
B14: Cuentas por cobrar | D14: ='Cuentas por Cobrar'!J14 | E14: ='Cuentas por Cobrar'!K14 | F14: =E14-D14 | G14: =IF(D14=0,"",(E14-D14)/D14)
B15: Bienes muebles | D15: ='Bienes Muebles'!F14 | E15: ='Bienes Muebles'!G14 | F15: =E15-D15 | G15: =IF(D15=0,"",(E15-D15)/D15)
B16: Vehiculos, naves y aeronaves | D16: ='Vehiculos'!G9 | E16: ='Vehiculos'!H9 | F16: =E16-D16 | G16: =IF(D16=0,"",(E16-D16)/D16)
B17: Derechos (usufructo, uso, etc.) | D17: ='Derechos'!F14 | E17: ='Derechos'!G14 | F17: =E17-D17 | G17: =IF(D17=0,"",(E17-D17)/D17)
B18: Bienes inmuebles | D18: ='Bienes Inmuebles'!J10 | E18: ='Bienes Inmuebles'!K10 | F18: =E18-D18 | G18: =IF(D18=0,"",(E18-D18)/D18)
B19: Otros activos | D19: ='Otros Activos'!F14 | E19: ='Otros Activos'!G14 | F19: =E19-D19 | G19: =IF(D19=0,"",(E19-D19)/D19)
B20: TOTAL ACTIVOS | D20: =SUM(D12:D19) | E20: =SUM(E12:E19) | F20: =E20-D20 | G20: =IF(D20=0,"",(E20-D20)/D20)
B22: PASIVOS
B23: Concepto | D23: Total 2025 | E23: Total 2026 | F23: Variacion | G23: Variacion %
B24: Deudas y obligaciones | D24: ='Pasivos'!I8 | E24: ='Pasivos'!J8 | F24: =E24-D24 | G24: =IF(D24=0,"",(E24-D24)/D24)
B25: TOTAL PASIVOS | D25: =SUM(D24:D24) | E25: =SUM(E24:E24) | F25: =E25-D25 | G25: =IF(D25=0,"",(E25-D25)/D25)
B27: PATRIMONIO NETO
B28: Concepto | D28: Total 2025 | E28: Total 2026 | F28: Variacion | G28: Variacion %
B29: (+) Total activos | D29: =D20 | E29: =E20 | F29: =E29-D29 | G29: =IF(D29=0,"",(E29-D29)/D29)
B30: (-) Total pasivos | D30: =D25 | E30: =E25 | F30: =E30-D30 | G30: =IF(D30=0,"",(E30-D30)/D30)
B31: (=) PATRIMONIO NETO | D31: =D29-D30 | E31: =E29-E30 | F31: =E31-D31 | G31: =IF(D31=0,"",(E31-D31)/D31)
B32: Patrimonio declarado en el XML (2025) | D32: 883285.56
B33: Patrimonio neto del anio anterior | D33: 801569.97
B34: Crecimiento / decremento patrimonial (XML) | D34: 81715.59
B36: CONSOLIDADO
B37: Concepto | D37: Total 2025 | E37: Total 2026 | F37: Variacion | G37: Variacion %
B38: Activos | D38: =D20 | E38: =E20 | F38: =E38-D38 | G38: =IF(D38=0,"",(E38-D38)/D38)
B39: Pasivos | D39: =D25 | E39: =E25 | F39: =E39-D39 | G39: =IF(D39=0,"",(E39-D39)/D39)
B40: Patrimonio neto | D40: =D31 | E40: =E31 | F40: =E40-D40 | G40: =IF(D40=0,"",(E40-D40)/D40)
B42: Edite las columnas amarillas en las hojas de cada modulo; las tarjetas, secciones y graficos se recalculan solos.

Sheet Dinero
A1: 4.1.1 DINERO E INVERSIONES EN INSTITUCIONES FINANCIERAS
A2: Declaracion 2025 - columna 2026 editable
A5: Dinero en | B5: Tipo de inversion | C5: Ubicacion | D5: Pais | E5: Institucion financiera | F5: Tipo de moneda | G5: Partes relacionadas | H5: Regularizacion activos | I5: Anio fiscal adquisicion | J5: Valor 2025 | K5: Valor 2026 | L5: Variacion | M5: Variacion %
A6: IFI - Instituciones financieras | B6: 3 - Cuenta de ahorros | C6: ECU - En el Ecuador | D6: 593 - ECUADOR | E6: 1029 - BANCO PICHINCHA C.A. | F6: DOLARES | G6: 2 - No | J6: 130.2 | K6: 130.2 | L6: =K6-J6 | M6: =IF(J6=0,"",(K6-J6)/J6)
A7: IFI - Instituciones financieras | B7: 4 - Cuenta corriente | C7: ECU - En el Ecuador | D7: 593 - ECUADOR | E7: 1029 - BANCO PICHINCHA C.A. | F7: DOLARES | G7: 2 - No | J7: 5590.32 | K7: 5590.32 | L7: =K7-J7 | M7: =IF(J7=0,"",(K7-J7)/J7)
A8: IFI - Instituciones financieras | B8: 3 - Cuenta de ahorros | C8: ECU - En el Ecuador | D8: 593 - ECUADOR | E8: 1418 - BANCO PROMERICA S.A. | F8: DOLARES | G8: 2 - No | J8: 53237.31 | K8: 53237.31 | L8: =K8-J8 | M8: =IF(J8=0,"",(K8-J8)/J8)
A9: IFI - Instituciones financieras | B9: 2 - Inversiones financieras | C9: EXT - En el exterior | D9: 118 - PANAMA | E9: BANCO PICHINCHA CA | F9: DOLARES | G9: 2 - No | J9: 189049.31 | K9: 189049.31 | L9: =K9-J9 | M9: =IF(J9=0,"",(K9-J9)/J9)
A10: TOTAL | J10: =SUM(J6:J9) | K10: =SUM(K6:K9) | L10: =K10-J10 | M10: =IF(J10=0,"",(K10-J10)/J10)

Sheet Derechos de Capital
A1: 4.1.2 INVERSIONES EN DERECHOS REPRESENTATIVOS DE CAPITAL
A2: Declaracion 2025 - columna 2026 editable | PLANTILLA EN BLANCO (este modulo no consta en el XML)
A5: Tipo de inversion | B5: Ubicacion | C5: Pais | D5: Empresa / Administradora / Fideicomiso | E5: % de participacion | F5: N. de acciones / participaciones | G5: Partes relacionadas | H5: Regularizacion activos | I5: Anio fiscal adquisicion | J5: Valor 2025 | K5: Valor 2026 | L5: Variacion | M5: Variacion %
J6: 0 | K6: 0 | L6: =K6-J6 | M6: =IF(J6=0,"",(K6-J6)/J6)
J7: 0 | K7: 0 | L7: =K7-J7 | M7: =IF(J7=0,"",(K7-J7)/J7)
J8: 0 | K8: 0 | L8: =K8-J8 | M8: =IF(J8=0,"",(K8-J8)/J8)
J9: 0 | K9: 0 | L9: =K9-J9 | M9: =IF(J9=0,"",(K9-J9)/J9)
J10: 0 | K10: 0 | L10: =K10-J10 | M10: =IF(J10=0,"",(K10-J10)/J10)
J11: 0 | K11: 0 | L11: =K11-J11 | M11: =IF(J11=0,"",(K11-J11)/J11)
J12: 0 | K12: 0 | L12: =K12-J12 | M12: =IF(J12=0,"",(K12-J12)/J12)
J13: 0 | K13: 0 | L13: =K13-J13 | M13: =IF(J13=0,"",(K13-J13)/J13)
A14: TOTAL | J14: =SUM(J6:J13) | K14: =SUM(K6:K13) | L14: =K14-J14 | M14: =IF(J14=0,"",(K14-J14)/J14)

Sheet Cuentas por Cobrar
A1: 4.1.3 CREDITOS, DOCUMENTOS Y CUENTAS POR COBRAR
A2: Declaracion 2025 - columna 2026 editable | PLANTILLA EN BLANCO (este modulo no consta en el XML)
A5: Nombre del deudor | B5: Tipo de deudor | C5: Tipo de identificacion | D5: N. de identificacion | E5: Ubicacion | F5: Pais | G5: Partes relacionadas | H5: Regularizacion activos | I5: Anio fiscal adquisicion | J5: Valor 2025 | K5: Valor 2026 | L5: Variacion | M5: Variacion %
J6: 0 | K6: 0 | L6: =K6-J6 | M6: =IF(J6=0,"",(K6-J6)/J6)
J7: 0 | K7: 0 | L7: =K7-J7 | M7: =IF(J7=0,"",(K7-J7)/J7)
J8: 0 | K8: 0 | L8: =K8-J8 | M8: =IF(J8=0,"",(K8-J8)/J8)
J9: 0 | K9: 0 | L9: =K9-J9 | M9: =IF(J9=0,"",(K9-J9)/J9)
J10: 0 | K10: 0 | L10: =K10-J10 | M10: =IF(J10=0,"",(K10-J10)/J10)
J11: 0 | K11: 0 | L11: =K11-J11 | M11: =IF(J11=0,"",(K11-J11)/J11)
J12: 0 | K12: 0 | L12: =K12-J12 | M12: =IF(J12=0,"",(K12-J12)/J12)
J13: 0 | K13: 0 | L13: =K13-J13 | M13: =IF(J13=0,"",(K13-J13)/J13)
A14: TOTAL | J14: =SUM(J6:J13) | K14: =SUM(K6:K13) | L14: =K14-J14 | M14: =IF(J14=0,"",(K14-J14)/J14)

Sheet Bienes Muebles
A1: 4.1.4 BIENES MUEBLES
A2: Declaracion 2025 - columna 2026 editable | PLANTILLA EN BLANCO (este modulo no consta en el XML)
A5: Tipo de bien | B5: Ubicacion | C5: Pais | D5: Regularizacion activos | E5: Anio fiscal adquisicion | F5: Valor 2025 | G5: Valor 2026 | H5: Variacion | I5: Variacion %
F6: 0 | G6: 0 | H6: =G6-F6 | I6: =IF(F6=0,"",(G6-F6)/F6)
F7: 0 | G7: 0 | H7: =G7-F7 | I7: =IF(F7=0,"",(G7-F7)/F7)
F8: 0 | G8: 0 | H8: =G8-F8 | I8: =IF(F8=0,"",(G8-F8)/F8)
F9: 0 | G9: 0 | H9: =G9-F9 | I9: =IF(F9=0,"",(G9-F9)/F9)
F10: 0 | G10: 0 | H10: =G10-F10 | I10: =IF(F10=0,"",(G10-F10)/F10)
F11: 0 | G11: 0 | H11: =G11-F11 | I11: =IF(F11=0,"",(G11-F11)/F11)
F12: 0 | G12: 0 | H12: =G12-F12 | I12: =IF(F12=0,"",(G12-F12)/F12)
F13: 0 | G13: 0 | H13: =G13-F13 | I13: =IF(F13=0,"",(G13-F13)/F13)
A14: TOTAL | F14: =SUM(F6:F13) | G14: =SUM(G6:G13) | H14: =G14-F14 | I14: =IF(F14=0,"",(G14-F14)/F14)

Sheet Vehiculos
A1: 4.1.5 VEHICULOS MOTORIZADOS TERRESTRES, NAVES Y AERONAVES
A2: Declaracion 2025 - columna 2026 editable
A5: Tipo de vehiculo | B5: Registro / placa / chasis | C5: Ubicacion | D5: Pais | E5: Regularizacion activos | F5: Anio fiscal adquisicion | G5: Valor 2025 | H5: Valor 2026 | I5: Variacion | J5: Variacion %
A6: 1 - Vehiculos motorizados terrestres | B6: PBO7092 | C6: ECU - En el Ecuador | D6: 593 - ECUADOR | G6: 12000 | H6: 12000 | I6: =H6-G6 | J6: =IF(G6=0,"",(H6-G6)/G6)
A7: 1 - Vehiculos motorizados terrestres | B7: PBF9690 | C7: ECU - En el Ecuador | D7: 593 - ECUADOR | G7: 20000 | H7: 20000 | I7: =H7-G7 | J7: =IF(G7=0,"",(H7-G7)/G7)
A8: 1 - Vehiculos motorizados terrestres | B8: PFC8683 | C8: ECU - En el Ecuador | D8: 593 - ECUADOR | G8: 32000 | H8: 32000 | I8: =H8-G8 | J8: =IF(G8=0,"",(H8-G8)/G8)
A9: TOTAL | G9: =SUM(G6:G8) | H9: =SUM(H6:H8) | I9: =H9-G9 | J9: =IF(G9=0,"",(H9-G9)/G9)

Sheet Derechos
A1: 4.1.6 DERECHOS (USUFRUCTO, USO, HABITACION, MARCAS, ETC.)
A2: Declaracion 2025 - columna 2026 editable | PLANTILLA EN BLANCO (este modulo no consta en el XML)
A5: Tipo de derecho | B5: Ubicacion | C5: Pais | D5: Regularizacion activos | E5: Anio fiscal adquisicion | F5: Valor 2025 | G5: Valor 2026 | H5: Variacion | I5: Variacion %
F6: 0 | G6: 0 | H6: =G6-F6 | I6: =IF(F6=0,"",(G6-F6)/F6)
F7: 0 | G7: 0 | H7: =G7-F7 | I7: =IF(F7=0,"",(G7-F7)/F7)
F8: 0 | G8: 0 | H8: =G8-F8 | I8: =IF(F8=0,"",(G8-F8)/F8)
F9: 0 | G9: 0 | H9: =G9-F9 | I9: =IF(F9=0,"",(G9-F9)/F9)
F10: 0 | G10: 0 | H10: =G10-F10 | I10: =IF(F10=0,"",(G10-F10)/F10)
F11: 0 | G11: 0 | H11: =G11-F11 | I11: =IF(F11=0,"",(G11-F11)/F11)
F12: 0 | G12: 0 | H12: =G12-F12 | I12: =IF(F12=0,"",(G12-F12)/F12)
F13: 0 | G13: 0 | H13: =G13-F13 | I13: =IF(F13=0,"",(G13-F13)/F13)
A14: TOTAL | F14: =SUM(F6:F13) | G14: =SUM(G6:G13) | H14: =G14-F14 | I14: =IF(F14=0,"",(G14-F14)/F14)

Sheet Bienes Inmuebles
A1: 4.1.7 BIENES INMUEBLES
A2: Declaracion 2025 - columna 2026 editable
A5: Tipo de inmueble | B5: Ubicacion | C5: Pais | D5: Provincia | E5: Canton | F5: Fecha de inscripcion | G5: Clave catastral | H5: Regularizacion activos | I5: Anio fiscal adquisicion | J5: Valor 2025 | K5: Valor 2026 | L5: Variacion | M5: Variacion %
A6: 3 - Terreno | B6: ECU - En el Ecuador | C6: 593 - ECUADOR | D6: 217 - PICHINCHA | E6: 21701 - QUITO | F6: 22/10/2008 | G6: 1042203018 | J6: 267340.8 | K6: 267340.8 | L6: =K6-J6 | M6: =IF(J6=0,"",(K6-J6)/J6)
A7: 1 - Casa | B7: ECU - En el Ecuador | C7: 593 - ECUADOR | D7: 217 - PICHINCHA | E7: 21701 - QUITO | F7: 13/03/1997 | G7: 1012005008000000000 | J7: 198118.55 | K7: 198118.55 | L7: =K7-J7 | M7: =IF(J7=0,"",(K7-J7)/J7)
A8: 1 - Casa | B8: ECU - En el Ecuador | C8: 593 - ECUADOR | D8: 217 - PICHINCHA | E8: 21701 - QUITO | G8: 1042203018 | J8: 33634.04 | K8: 33634.04 | L8: =K8-J8 | M8: =IF(J8=0,"",(K8-J8)/J8)
A9: 3 - Terreno | B9: ECU - En el Ecuador | C9: 593 - ECUADOR | D9: 217 - PICHINCHA | E9: 21701 - QUITO | G9: 1012005008000000000 | J9: 82624.22 | K9: 82624.22 | L9: =K9-J9 | M9: =IF(J9=0,"",(K9-J9)/J9)
A10: TOTAL | J10: =SUM(J6:J9) | K10: =SUM(K6:K9) | L10: =K10-J10 | M10: =IF(J10=0,"",(K10-J10)/J10)

Sheet Otros Activos
A1: 4.1.8 OTROS ACTIVOS (CREDITOS TRIBUTARIOS Y OTROS)
A2: Declaracion 2025 - columna 2026 editable | PLANTILLA EN BLANCO (este modulo no consta en el XML)
A5: Ubicacion | B5: Pais | C5: Descripcion | D5: Regularizacion activos | E5: Anio fiscal adquisicion | F5: Valor 2025 | G5: Valor 2026 | H5: Variacion | I5: Variacion %
F6: 0 | G6: 0 | H6: =G6-F6 | I6: =IF(F6=0,"",(G6-F6)/F6)
F7: 0 | G7: 0 | H7: =G7-F7 | I7: =IF(F7=0,"",(G7-F7)/F7)
F8: 0 | G8: 0 | H8: =G8-F8 | I8: =IF(F8=0,"",(G8-F8)/F8)
F9: 0 | G9: 0 | H9: =G9-F9 | I9: =IF(F9=0,"",(G9-F9)/F9)
F10: 0 | G10: 0 | H10: =G10-F10 | I10: =IF(F10=0,"",(G10-F10)/F10)
F11: 0 | G11: 0 | H11: =G11-F11 | I11: =IF(F11=0,"",(G11-F11)/F11)
F12: 0 | G12: 0 | H12: =G12-F12 | I12: =IF(F12=0,"",(G12-F12)/F12)
F13: 0 | G13: 0 | H13: =G13-F13 | I13: =IF(F13=0,"",(G13-F13)/F13)
A14: TOTAL | F14: =SUM(F6:F13) | G14: =SUM(G6:G13) | H14: =G14-F14 | I14: =IF(F14=0,"",(G14-F14)/F14)

Sheet Pasivos
A1: 4.2.1 DEUDAS CONTRAIDAS / PASIVOS
A2: Declaracion 2025 - columna 2026 editable
A5: Tipo de acreedor | B5: Domicilio del acreedor | C5: Pais | D5: Nombre del acreedor | E5: Tipo de identificacion | F5: N. de identificacion | G5: N. registro Banco Central | H5: Partes relacionadas | I5: Valor 2025 | J5: Valor 2026 | K5: Variacion | L5: Variacion %
A6: IFI - Instituciones financieras | B6: ECU - En el Ecuador | C6: 593 - ECUADOR | D6: DINERS CLUB DEL ECUADOR | E6: R - RUC | F6: 1792260957001 | H6: 2 - No | I6: 4891.88 | J6: 4891.88 | K6: =J6-I6 | L6: =IF(I6=0,"",(J6-I6)/I6)
A7: IFI - Instituciones financieras | B7: ECU - En el Ecuador | C7: 593 - ECUADOR | D7: BANCO DEL PICHINCHA | E7: R - RUC | F7: 1790010937001 | H7: 2 - No | I7: 5547.31 | J7: 5547.31 | K7: =J7-I7 | L7: =IF(I7=0,"",(J7-I7)/I7)
A8: TOTAL | I8: =SUM(I6:I7) | J8: =SUM(J6:J7) | K8: =J8-I8 | L8: =IF(I8=0,"",(J8-I8)/I8)

Sheet Justificacion
A1: JUSTIFICACION DE LA VARIACION PATRIMONIAL
A2: Marque 'Si' los conceptos que justifican la variacion patrimonial - ejercicio 2025
B5: Incremento patrimonial declarado en el XML | E5: 81715.59
B7: Concepto (Tabla 14 del SRI) | E7: Justifica la variacion
B8: 1 - Ingresos locales | E8: Si
B9: 2 - Ingresos exterior | E9: No
B10: 3 - Herencias, legados o donaciones | E10: No
B11: 4 - Loterias o rifas | E11: No
B12: 5 - Ganancias de capital | E12: No
B13: 6 - Otros | E13: Si
B15: Esta hoja reproduce la seccion Justificacion del formulario del SRI. Marque 'Si' en los conceptos que apliquen; el generador de XML los toma de aqui.

Sheet Generar XML
A1: GENERAR XML PARA EL SRI
A2: Convierte este libro en el archivo XML de la Declaracion Patrimonial, listo para subir al portal del SRI
B5: ► GENERAR XML
B7: En el archivo .xlsm el boton verde ya esta vinculado a la macro GenerarXmlSRI.
B9: COMO USAR ESTE ARCHIVO
B10: 1. Al abrir el archivo .xlsm, pulse 'Habilitar contenido' en la barra de seguridad de Excel.
B11: 2. Llene las columnas amarillas de cada modulo (Dinero, Vehiculos, etc.) y la hoja Justificacion.
B12: 3. Pulse el boton verde GENERAR XML, indique el anio y elija donde guardar el archivo.
B13: 4. El archivo .xml queda listo para subir al portal del SRI.
B15: SI EXCEL BLOQUEA LAS MACROS
B16: - Cierre Excel. En el Explorador, clic derecho sobre el archivo > Propiedades.
B17: - Al final de la pestana General marque 'Desbloquear' y pulse Aceptar.
B18: - Vuelva a abrirlo y pulse 'Habilitar contenido'. Conserve siempre la extension .xlsm.
B20: Alternativa sin macros: ejecutar python tools/generar_xml_sri.py desde la terminal.

Sheet Datos del XML
A1: DATOS GENERALES DE LA DECLARACION
A5: IDENTIFICACION
A6: Anio de la declaracion | B6: 2025
A7: Tipo de declaracion | B7: SOC - Sociedad conyugal o union de hecho
A8: Tipo de identificacion | B8: R - RUC
A9: Numero de identificacion | B9: 1709164899001
A10: Nombre del declarante | B10: GONZALEZ NAVAS MARCO VINICIO
A11: Identificacion del conyuge | B11: C - Cedula
A12: Numero ident. conyuge | B12: 1709784225
A13: Nombre del conyuge | B13: HIDALGO LOZA ROSA CONSUELO
A14: Total creditos / cuentas por cobrar | B14: 0
A16: PATRIMONIO NETO (enlazado a la hoja Dashboard)
A17: Patrimonio neto 2025 | B17: =Dashboard!D31
A18: Patrimonio neto 2026 (proyectado) | B18: =Dashboard!E31
A19: Variacion proyectada | B19: =Dashboard!F31
A20: Variacion % proyectada | B20: =Dashboard!G31
A22: PATRIMONIO DECLARADO EN EL XML
A23: Patrimonio total declarado | B23: 883285.56
A24: Atribuible a hijos no emancipados | B24: 0
A25: Patrimonio en la sociedad conyugal | B25: 883285.56
A26: Patrimonio individual del declarante | B26: 0
A27: Patrimonio del anio anterior | B27: 801569.97
A28: Crecimiento / decremento patrimonial | B28: 81715.59
A30: Justificacion de la variacion (ver hoja Justificacion)
A31: - 1 - Ingresos locales
A32: - 6 - Otros
A34: Catalogos del SRI integrados (Tablas 1-19 del archivo CATALOGO.xls). El XML se genera con generar_xml_sri.py.

Sheet _Mapa
A1: key | B1: hoja | C1: contenedor | D1: detalle | E1: clase | F1: ordenXml | G1: tipo | H1: xmlTag | I1: descIndex
A2: dinero | B2: Dinero | C2: dinero | D2: detalleDinero | E2: activo | F2: 0 | G2: cod | H2: dineroEn | I2: 1
A3: dinero | B3: Dinero | C3: dinero | D3: detalleDinero | E3: activo | F3: 0 | G3: cod | H3: tipoInversion | I3: 2
A4: dinero | B4: Dinero | C4: dinero | D4: detalleDinero | E4: activo | F4: 0 | G4: cod | H4: ubicacion | I4: 3
A5: dinero | B5: Dinero | C5: dinero | D5: detalleDinero | E5: activo | F5: 0 | G5: cod | H5: pais | I5: 4
A6: dinero | B6: Dinero | C6: dinero | D6: detalleDinero | E6: activo | F6: 0 | G6: cod | H6: _ifi | I6: 5
A7: dinero | B7: Dinero | C7: dinero | D7: detalleDinero | E7: activo | F7: 0 | G7: txt | H7: tipoMoneda | I7: 6
A8: dinero | B8: Dinero | C8: dinero | D8: detalleDinero | E8: activo | F8: 0 | G8: val | H8: saldo | I8: 0
A9: dinero | B9: Dinero | C9: dinero | D9: detalleDinero | E9: activo | F9: 0 | G9: cod | H9: partesRelacionadas | I9: 7
A10: dinero | B10: Dinero | C10: dinero | D10: detalleDinero | E10: activo | F10: 0 | G10: cod | H10: regularizacionActivos | I10: 8
A11: dinero | B11: Dinero | C11: dinero | D11: detalleDinero | E11: activo | F11: 0 | G11: txt | H11: anioFiscalAdquisicion | I11: 9
A12: drc | B12: Derechos de Capital | C12: inversiones | D12: detalleInversiones | E12: activo | F12: 1 | G12: cod | H12: tipoInversion | I12: 1
A13: drc | B13: Derechos de Capital | C13: inversiones | D13: detalleInversiones | E13: activo | F13: 1 | G13: cod | H13: ubicacion | I13: 2
... A75: pasivo | B75: Pasivos | C75: pasivo | D75: detallePasivo | E75: pasivo | F75: 6 | G75: cod | H75: partesRelacionadas | I75: 8

Sheet Catalogos
A1: DINERO_EN | B1: TIPO_INVERSION | C1: UBICACION | D1: PAIS | E1: INSTITUCION_FINANCIERA | F1: PARTES_RELACIONADAS | G1: TIPO_DRC | H1: TIPO_PERSONA | I1: TIPO_BIEN_MUEBLE | J1: TIPO_VEHICULO | K1: TIPO_DERECHO | L1: TIPO_INMUEBLE | M1: PROVINCIA | N1: CANTON | O1: TIPO_ACREEDOR | P1: TIPO_IDENTIFICACION | Q1: REGULARIZACION | R1: JUSTIF_INCREMENTO | S1: JUSTIF_DECREMENTO
A2: EFE - Efectivo | B2: 1 - Efectivo | C2: ECU - En el Ecuador | D2: 16 - AMERICAN SAMOA | E2: 1002 - BANCO AMAZONAS S.A. | F2: 1 - Si | G2: 2 - Acciones o participaciones en sociedades | H2: 1 - Persona natural | I2: 1 - Maquinaria y equipo | J2: 1 - Vehiculos motorizados terrestres | K2: 1 - Usufructo | L2: 1 - Casa | M2: 107 - EL ORO | N2: 10701 - MACHALA | O2: ACC - Accionistas, participes o socios | P2: C - Cedula | Q2: 1 - Si | R2: 1 - Ingresos locales | S2: 1 - Compra de bienes
A3: IFI - Instituciones financieras | B3: 2 - Inversiones financieras | C3: EXT - En el exterior | D3: 74 - BOUVET ISLAND | E3: 1004 - BANCO DEL AUSTRO S.A. | F3: 2 - No | G3: 5 - Fondos de inversion | H3: 2 - Persona juridica | I3: 2 - Inventario de mercaderias | J3: 2 - Naves | K3: 2 - Uso | L3: 2 - Departamento | M3: 108 - ESMERALDAS | N3: 10702 - ARENILLAS | O3: CRD - Credito a mutuo | P3: E - Identificacion del exterior | Q3: 2 - No | R3: 2 - Ingresos exterior | S3: 2 - Pago de servicios
A4: OTR - Otros depositarios | B4: 3 - Cuenta de ahorros | D4: 101 - ARGENTINA | E4: 1006 - BANCO DE GUAYAQUIL S.A. | G4: 6 - Fideicomisos | I4: 3 - Activo biologico (incluye semovientes) | J4: 3 - Aeronaves | K4: 3 - Habitacion | L4: 3 - Terreno | M4: 109 - GUAYAS | N4: 10703 - ATAHUALPA | O4: CRE - Credito a mutuo | P4: P - Pasaporte | R4: 3 - Herencias, legados o donaciones | S4: 3 - Nuevas inversiones
B5: 4 - Cuenta corriente | D5: 102 - BOLIVIA | E5: 1007 - BANCO BOLIVARIANO C.A. | I5: 4 - Muebles, enseres y otros (incluye obras de arte y joyas) | K5: 4 - Propiedad intelectual | L5: 4 - Oficina | M5: 112 - LOS RIOS | N5: 10704 - BALSAS | O5: DIV - Dividendos | P5: R - RUC | R5: 4 - Loterias o rifas | S5: 4 - Otros
B6: 5 - Inversiones financieras (bonos, obligaciones y otros) | D6: 103 - BRASIL | E6: 1008 - BANCO CENTRO MUNDO S.A. | I6: 5 - Plantas productoras | K6: 5 - Plusvalia o goodwill | L6: 5 - Local comercial | M6: 113 - MANABI | N6: 10705 - CHILLA | O6: IES - IESS | R6: 5 - Ganancias de capital
B7: 6 - Fondos complementarios previsionales cerrados | D7: 104 - CANADA | E7: 1009 - CITIBANK N.A. | I7: 6 - Construcciones en curso | K7: 6 - Marcas, patentes | L7: 6 - Almacenera o bodega | M7: 124 - SANTA ELENA | N7: 10706 - EL GUABO | O7: IFI - Instituciones financieras | R7: 6 - Otros
B8: 7 - En sociedades sin fines de lucro | D8: 105 - COLOMBIA | E8: 1010 - BANCO COFIEC C.A. | K8: 7 - Derechos en acuerdos de concesion | L8: 7 - Propiedad rural | M8: 201 - AZUAY | N8: 10707 - HUAQUILLAS | O8: OTR - Otros pasivos
D9: 106 - COSTA RICA | E9: 1011 - BANCO COMERCIAL DE MANABI C.A. | K9: 8 - Otros | L9: 8 - Otros | M9: 202 - BOLIVAR | N9: 10708 - MARCABELI | O9: TRA - Transferencias casa matriz
D10: 107 - CUBA | E10: 1014 - BANCO DEL LITORAL S.A. | L10: 9 - Otros | M10: 203 - CAÑAR | N10: 10709 - PASAJE
D11: 108 - CHILE | E11: 1016 - RED BANCARIA | M11: 204 - CARCHI | N11: 10710 - PIÑAS
D12: 109 - ANGUILA | E12: 1020 - BANCO GENERAL RUMIÑAHUI S.A. | M12: 205 - COTOPAXI | N12: 10711 - PORTOVELO
D13: 110 - ESTADOS UNIDOS | E13: 1022 - ING BANK N.V. | M13: 206 - CHIMBORAZO | N13: 10712 - SANTA ROSA
D14: 111 - GUATEMALA | E14: 1023 - BANCO INTERNACIONAL S.A. | M14: 210 - IMBABURA | N14: 10713 - ZARUMA
D15: 112 - HAITI | E15: 1024 - LLOYDS BANK BLSA LIMITED | M15: 211 - LOJA | N15: 10714 - LAS LAJAS
D16: 113 - HONDURAS | E16: 1025 - BANCO DE LOJA S.A. | M16: 217 - PICHINCHA | N16: 10801 - ESMERALDAS
D17: 114 - JAMAICA | E17: 1026 - BANCO DE MACHALA S.A. | M17: 218 - TUNGURAHUA | N17: 10802 - ELOY ALFARO
D18: 115 - MALVINAS ISLAS | E18: 1027 - TRUST FIDUCIARIA S.A. | M18: 223 - SANTO DOMINGO DE LOS TSÁCHILAS | N18: 10803 - MUISNE
D19: 116 - MEXICO | E19: 1028 - BANCO DEL PACIFICO S.A. | M19: 314 - MORONA SANTIAGO | N19: 10804 - QUININDE
D20: 117 - NICARAGUA | E20: 1029 - BANCO PICHINCHA C.A. | M20: 315 - NAPO | N20: 10805 - SAN LORENZO
D21: 118 - PANAMA | E21: 1033 - BANCO DE LA PRODUCCION S.A. PRODUBANCO | M21: 316 - PASTAZA | N21: 10806 - ATACAMES
D22: 119 - PARAGUAY | E22: 1035 - BANCO DE DESARROLLO ECONOMICO Y SOCIAL DE VENEZUELA | M22: 319 - ZAMORA CHINCHIPE | N22: 10807 - RIO VERDE
... D25: 122 - REPUBLICA DOMINICANA | E25: 1039 - BANCO TERRITORIAL S.A. | M25: 420 - GALAPAGOS | N25: 10902 - ALFREDO BAQUERIZO MORENO
D26: 123 - EL SALVADOR | E26: 1043 - ALMACENERA CONTINENTAL S.A. ALMACONTI | N26: 10903 - BALAO
D27: 124 - TRINIDAD Y TOBAGO | E27: 1044 - ALMACENERA ALMACOPIO S.A. | N27: 10904 - BALZAR
D28: 125 - URUGUAY | E28: 1045 - ALMACENERA DE GRANOS Y MERCADERIAS ALGRACESA | N28: 10905 - COLIMES
D29: 126 - VENEZUELA | E29: 1046 - ALMACENERA DEL AGRO S.A. ALMAGRO | N29: 10906 - DAULE
D30: 127 - CURAZAO | E30: 1047 - ALMACENERA DEL PROGRESO ALMACEPRO | N30: 10907 - DURAN
D31: 129 - BAHAMAS | E31: 1048 - ALMACENERA DEL ECUADOR S.A. ALMESA | N31: 10908 - EL EMPALME
D32: 130 - BARBADOS | E32: 1049 - ALMACENERA GUAYAQUIL S.A. ALMAQUIL | N32: 10909 - EL TRIUNFO
D33: 131 - GRANADA | E33: 1050 - BANCO CENTRAL DEL ECUADOR | N33: 10910 - MILAGRO
D34: 132 - GUYANA | E34: 1051 - BANCO DEL ESTADO | N34: 10911 - NARANJAL
D35: 133 - SURINAM | E35: 1052 - BANCO ECUATORIANO DE LA VIVIENDA | N35: 10912 - NARANJITO
D36: 134 - ANTIGUA Y BARBUDA | E36: 1053 - BANCO NACIONAL DE FOMENTO | N36: 10913 - PALESTINA
D37: 135 - BELICE | E37: 1054 - CORPORACION FINANCIERA NACIONAL | N37: 10914 - PEDRO CARBO
... D222: 513 - NAURU | E222: 1275 - COMPAÑIA DE SERVICIOS AUXILIARES DEL PACIFICO S.A. SERENTRESA | N222: 42003 - SANTA CRUZ
D223: 514 - SALOMON ISLAS | E223: 1276 - SEVIMAC S.A.
D224: 515 - TUVALU | E224: 1277 - SICOBRA S.A.
D225: 516 - VANUATU | E225: 1279 - TECSOFT S.A.
D226: 517 - GUAM | E226: 1280 - COMPAÑIA DE TRANSPORTE DE VALORES Y SEGURIDAD RUMIÑAHUI S.A.
...
