Workbook

Sheet 00_Inicio
B2: AuditConsulting Auditores Cía. Ltda. · AUDIT-IA
B4: Activos biológicos y agricultura
B6: Cliente | C6: Cliente de muestra S.A. | D6: RUC | E6: 1790000000001
B7: Marco contable | C7: NIIF completas | D7: Fecha de corte | E7: 2025-12-31
B8: Preparó | C8: Ejercicio modelo | D8: Revisó | E8: Pendiente
B10: INDICADORES CLAVE
B11: Ajuste propuesto (partidas medidas) | C11: Problemas encontrados
B12: 22320 | C12: 12
B15: IR A LA CÉDULA
B16: Carátula | C16: Programa | D16: Base técnica | E16: Resumen y ajuste propuesto
B17: Parámetros y ruta por marco | C17: Activos biológicos: clasificación y datos | D17: Existencia: conteo vs registros | E17: Valoración: VR menos costos de venta
B18: Transformación biológica y cambio de VR | C18: Conciliación de cambios (NIC 41.50) | D18: Modelo del costo y deterioro | E18: Producto agrícola en el punto de cosecha
B19: Problemas encontrados | C19: Conclusión | D19: Control de revisión
B21: PANORAMA | N21: Datos de los gráficos (fórmulas a las cédulas)
N22: Cifras del resumen | O22: Importe (USD)
N23: ='01_Resumen'!A5 | O23: ='01_Resumen'!B5
N24: ='01_Resumen'!A6 | O24: ='01_Resumen'!B6
N25: ='01_Resumen'!A7 | O25: ='01_Resumen'!B7
N26: ='01_Resumen'!A8 | O26: ='01_Resumen'!B8
N27: ='01_Resumen'!A9 | O27: ='01_Resumen'!B9
N28: ='01_Resumen'!A10 | O28: ='01_Resumen'!B10
N29: ='01_Resumen'!A11 | O29: ='01_Resumen'!B11
N30: ='01_Resumen'!A12 | O30: ='01_Resumen'!B12
N31: ='01_Resumen'!A13 | O31: ='01_Resumen'!B13
N32: ='01_Resumen'!A14 | O32: ='01_Resumen'!B14
N33: ='01_Resumen'!A15 | O33: ='01_Resumen'!B15
N34: ='01_Resumen'!A16 | O34: ='01_Resumen'!B16
... N40: ='01_Resumen'!A22 | O40: ='01_Resumen'!B22
N42: Hallazgos de mayor impacto | O42: Importe (USD)
N43: Sin conteo | O43: =SUMIFS('10_Problemas'!$C$5:$C$16,'10_Problemas'!$A$5:$A$16,"SIN_CONTEO",'10_Problemas'!$C$5:$C$16,">0")-SUMIFS('10_Problemas'!$C$5:$C$16,'10_Problemas'!$A$5:$A$16,"SIN_CONTEO",'10_Problemas'!$C$5:$C$16,"<0")
N44: Planta productora | O44: =SUMIFS('10_Problemas'!$C$5:$C$16,'10_Problemas'!$A$5:$A$16,"PLANTA_PRODUCTORA",'10_Problemas'!$C$5:$C$16,">0")-SUMIFS('10_Problemas'!$C$5:$C$16,'10_Problemas'!$A$5:$A$16,"PLANTA_PRODUCTORA",'10_Problemas'!$C$5:$C$16,"<0")
N45: Cambio vr no reconocido | O45: =SUMIFS('10_Problemas'!$C$5:$C$16,'10_Problemas'!$A$5:$A$16,"CAMBIO_VR_NO_RECONOCIDO",'10_Problemas'!$C$5:$C$16,">0")-SUMIFS('10_Problemas'!$C$5:$C$16,'10_Problemas'!$A$5:$A$16,"CAMBIO_VR_NO_RECONOCIDO",'10_Problemas'!$C$5:$C$16,"<0")
N46: Valoracion difiere | O46: =SUMIFS('10_Problemas'!$C$5:$C$16,'10_Problemas'!$A$5:$A$16,"VALORACION_DIFIERE",'10_Problemas'!$C$5:$C$16,">0")-SUMIFS('10_Problemas'!$C$5:$C$16,'10_Problemas'!$A$5:$A$16,"VALORACION_DIFIERE",'10_Problemas'!$C$5:$C$16,"<0")
N47: Cosecha no a vr | O47: =SUMIFS('10_Problemas'!$C$5:$C$16,'10_Problemas'!$A$5:$A$16,"COSECHA_NO_A_VR",'10_Problemas'!$C$5:$C$16,">0")-SUMIFS('10_Problemas'!$C$5:$C$16,'10_Problemas'!$A$5:$A$16,"COSECHA_NO_A_VR",'10_Problemas'!$C$5:$C$16,"<0")
N48: Modelo costo sin justificar | O48: =SUMIFS('10_Problemas'!$C$5:$C$16,'10_Problemas'!$A$5:$A$16,"MODELO_COSTO_SIN_JUSTIFICAR",'10_Problemas'!$C$5:$C$16,">0")-SUMIFS('10_Problemas'!$C$5:$C$16,'10_Problemas'!$A$5:$A$16,"MODELO_COSTO_SIN_JUSTIFICAR",'10_Problemas'!$C$5:$C$16,"<0")
N49: Deterioro costo | O49: =SUMIFS('10_Problemas'!$C$5:$C$16,'10_Problemas'!$A$5:$A$16,"DETERIORO_COSTO",'10_Problemas'!$C$5:$C$16,">0")-SUMIFS('10_Problemas'!$C$5:$C$16,'10_Problemas'!$A$5:$A$16,"DETERIORO_COSTO",'10_Problemas'!$C$5:$C$16,"<0")
N50: Otros (3 tipos) | O50: =SUMIF('10_Problemas'!$C$5:$C$16,">0")-SUMIF('10_Problemas'!$C$5:$C$16,"<0")-((SUMIFS('10_Problemas'!$C$5:$C$16,'10_Problemas'!$A$5:$A$16,"SIN_CONTEO",'10_Problemas'!$C$5:$C$16,">0")-SUMIFS('10_Problemas'!$C$5:$C$16,'10_Problemas'!$A$5:$A$16,"SIN_CONTEO",'10_Problemas'!$C$5:$C$16,"<0"))+(SUMIFS('10_Problemas'!$C$5:$C$16,'10_Problemas'!$A$5:$A$16,"PLANTA_PRODUCTORA",'10_Problemas'!$C$5:$C$16,">0")-SUMIFS('10_Problemas'!$C$5:$C$16,'10_Problemas'!$A$5:$A$16,"PLANTA_PRODUCTORA",'10_Problemas'!$C$5:$C$16,"<0"))+(SUMIFS('10_Problemas'!$C$5:$C$16,'10_Problemas'!$A$5:$A$16,"CAMBIO_VR_NO_RECONOCIDO",'10_Problemas'!$C$5:$C$16,">0")-SUMIFS('10_Problemas'!$C$5:$C$16,'10_Problemas'!$A$5:$A$16,"CAMBIO_VR_NO_RECONOCIDO",'10_Problemas'!$C$5:$C$16,"<0"))+(SUMIFS('10_Problemas'!$C$5:$C$16,'10_Problemas'!$A$5:$A$16,"VALORACION_DIFIERE",'10_Problemas'!$C$5:$C$16,">0")-SUMIFS('10_Problemas'!$C$5:$C$16,'10_Problemas'!$A$5:$A$16,"VALORACION_DIFIERE",'10_Problemas'!$C$5:$C$16,"<0"))+(SUMIFS('10_Problemas'!$C$5:$C$16,'10_Problemas'!$A$5:$A$16,"COSECHA_NO_A_VR",'10_Problemas'!$C$5:$C$16,">0")-SUMIFS('10_Problemas'!$C$5:$C$16,'10_Problemas'!$A$5:$A$16,"COSECHA_NO_A_VR",'10_Problemas'!$C$5:$C$16,"<0"))+(SUMIFS('10_Problemas'!$C$5:$C$16,'10_Problemas'!$A$5:$A$16,"MODELO_COSTO_SIN_JUSTIFICAR",'10_Problemas'!$C$5:$C$16,">0")-SUMIFS('10_Problemas'!$C$5:$C$16,'10_Problemas'!$A$5:$A$16,"MODELO_COSTO_SIN_JUSTIFICAR",'10_Problemas'!$C$5:$C$16,"<0"))+(SUMIFS('10_Problemas'!$C$5:$C$16,'10_Problemas'!$A$5:$A$16,"DETERIORO_COSTO",'10_Problemas'!$C$5:$C$16,">0")-SUMIFS('10_Problemas'!$C$5:$C$16,'10_Problemas'!$A$5:$A$16,"DETERIORO_COSTO",'10_Problemas'!$C$5:$C$16,"<0")))

Sheet 00_Caratula
A1: Carátula | H1: ⟵ Inicio | J1: Siguiente ▶
A2: Activos biológicos y agricultura · Cliente de muestra S.A. · corte 2025-12-31
A4: Concepto | B4: Detalle
A5: Firma | B5: AuditConsulting Auditores Cía. Ltda.
A6: Cliente | B6: Cliente de muestra S.A.
A7: RUC | B7: 1790000000001
A8: Ejercicio | B8: 2025
A9: Fecha de corte | B9: 2025-12-31
A10: Marco contable | B10: NIIF completas
A11: Herramienta | B11: Activos biológicos y agricultura
A12: Rubro | B12: Activos biológicos
A13: Motor | B13: activos_biologicos 1.0
A14: Versión del papel | B14: v1
A15: Estado | B15: MUESTRA
... A17: Revisó | B17: Pendiente
A18: Aprobó
A19: Fecha de aprobación
A20: Huella de la ejecución (SHA-256)

Sheet 00_Programa
A1: Programa | H1: ⟵ Inicio | I1: ◀ Anterior | J1: Siguiente ▶
A2: Activos biológicos y agricultura · Cliente de muestra S.A. · corte 2025-12-31
A4: Código | B4: Objetivo | C4: Afirmación | D4: Procedimiento | E4: Evidencia | F4: Criterio | G4: Referencia
A5: BIO-01 | B5: Clasificación | C5: Clasificación | D5: Clasificar cada lote: consumo/productor, planta productora (NIC 16 en NIIF completas; Sección 17 en PYMES 2025 si puede medirse por separado de su producto, 34.2A) o activo biológico | E5: Descripción de lotes, políticas | F5: Cada lote en la norma que le corresponde | G5: NIC 41.1-2, 41.5-5C · PYMES 34.2, 34.2A, 17.3 a, BIO-07
A6: BIO-02 | B6: Existencia | C6: Existencia | D6: Presenciar el conteo o la estimación de biomasa y compararlo con los registros | E6: Actas de conteo, registros de campo, informes de mortalidad | F6: Diferencias valorizadas y ajustadas | G6: NIA 501
A7: BIO-03 | B7: Valoración | C7: Valoración | D7: Recalcular VR menos costos de venta con precios de mercado y costos de venta | E7: Cotizaciones de mercado, informes de peritos, costos de flete y comisiones | F7: Valor auditado = libros | G7: NIC 41.12, NIIF 13 · PYMES 34.4
A8: BIO-04 | B8: Transformación biológica | C8: Exactitud | D8: Separar el cambio físico y de precio y recalcular la ganancia del ejercicio | E8: Anexo inicial y final, mayor de resultados | F8: Ganancia registrada = recalculada | G8: NIC 41.26, 41.50-41.51 · PYMES 34.4, BIO-05
A9: BIO-05 | B9: Producto agrícola | C9: Valoración | D9: Recalcular la cosecha a VR menos costos de venta en el punto de cosecha | E9: Reportes de cosecha, precios a la fecha de cosecha | F9: Inventario inicial del producto = VR menos costos de venta | G9: NIC 41.13, 41.32 · PYMES 34.5
A10: BIO-06 | B10: Modelo del costo y deterioro | C10: Valoración | D10: Evaluar la justificación del modelo del costo y comparar el neto con el importe recuperable | E10: Análisis de fiabilidad del VR, costeo, tasación | F10: Costo solo si procede; sin exceso sobre el recuperable | G10: NIC 41.30-41.33, NIC 36 · PYMES 34.8-34.10, 27
A11: BIO-07 | B11: Conciliación y revelaciones | C11: Presentación | D11: Conciliar los cambios del importe en libros y el anexo con el mayor | E11: Movimiento del rubro, mayor | F11: Conciliación cuadrada y revelada | G11: NIC 41.50 · PYMES 34.7 c)

Sheet 00_Fuentes
A1: Base técnica | H1: ⟵ Inicio | I1: ◀ Anterior | J1: Siguiente ▶
A2: Activos biológicos y agricultura · Cliente de muestra S.A. · corte 2025-12-31
A4: Categoría | B4: Documento | C4: Párrafos | D4: URL | E4: Verificada
A5: NIA · NIA 501 | B5: Presenciar el recuento de los activos biológicos materiales y probar sus resultados. | C5: párr. 4 (aplicada por analogía; el párr. 4 trata de inventarios)
A6: NIA · NIA 540 (Revisada) | B6: El VR menos costos de venta es una estimación: evaluar método, datos y supuestos. | C6: párr. 13, 16–17, 18–27 y 28–30
A7: NIA · NIA 500 | B7: Evaluar el trabajo del experto (veterinario, ingeniero forestal, biólogo o valuador). | C7: párr. 8 si el perito es del cliente (NIA 620 solo si lo contrata el auditor)
A8: NIA · NIA 500 | B8: Exactitud e integridad del anexo contra el mayor y los registros de campo. | C8: párr. 9
A9: NIA · NIA 330 | B9: Procedimientos sustantivos y conciliación de los estados con los registros. | C9: párr. 18 y 20

Sheet 01_Resumen
A1: Resumen y ajuste propuesto | H1: ⟵ Inicio | I1: ◀ Anterior | J1: Siguiente ▶
A2: Activos biológicos y agricultura · Cliente de muestra S.A. · corte 2025-12-31
A4: Concepto | B4: Importe
A5: Activos biológicos auditados | B5: =SUM('05_Valoracion'!$J$5:$J$14)
A6: Activos biológicos según el anexo (libros) | B6: =SUM('03_Activos'!$M$5:$M$14)
A7: Ajuste propuesto (partidas medidas) | B7: =SUM('05_Valoracion'!$L$5:$L$14)
A8: Activos biológicos según el mayor | B8: =IF('02_Parametros'!$B$9="",SUM('03_Activos'!$M$5:$M$14),'02_Parametros'!$B$9)
A9: Diferencia anexo − mayor | B9: =B6-B8
A10: Diferencias físicas valorizadas | B10: =SUM('04_Existencia'!$H$5:$H$14)
A11: Cambio de VR por cambios físicos (NIC 41.51) | B11: =SUM('06_Transformacion'!$G$5:$G$14)
A12: Cambio de VR por precios (NIC 41.51) | B12: =SUM('06_Transformacion'!$H$5:$H$14)
A13: Cambio total del VR menos costos de venta | B13: =SUM('06_Transformacion'!$I$5:$I$14)
A14: Ganancia por cambio de VR recalculada | B14: =SUM('06_Transformacion'!$N$5:$N$14)
A15: Ganancia por cambio de VR registrada | B15: =SUM('03_Activos'!$Q$5:$Q$14)
A16: Cambio de VR no reconocido (recalculado − registrado) | B16: =SUM('06_Transformacion'!$P$5:$P$14)
A17: Diferencia en la conciliación de cambios (NIC 41.50) | B17: =SUM('07_Conciliacion'!$I$5:$I$14)
A18: Deterioro adicional (modelo del costo) | B18: =SUM('08_Modelo_costo'!$H$5:$H$14)
A19: Plantas productoras fuera de NIC 41 (NIC 16) | B19: =SUMIF('05_Valoracion'!$C$5:$C$14,"NIC 16",'05_Valoracion'!$K$5:$K$14)
A20: Cosecha a VR menos costos de venta | B20: =SUM('09_Cosecha'!$H$5:$H$10)
A21: Cosecha registrada en inventario | B21: =SUM('09_Cosecha'!$I$5:$I$10)
A22: Diferencia en la medición de la cosecha | B22: =SUM('09_Cosecha'!$J$5:$J$10)
A24: ⓘ Cómo se calcula esta hoja
A25: Columna | B25: Fórmula (Excel) | C25: Cómo se calcula (sencillo) | D25: Ejemplo con números reales | E25: De dónde viene | F25: Norma
A26: Importe | B26: '=SUM('05_Valoracion'!$J$5:$J$14) | C26: Trae cada importe de la hoja de cálculo que le corresponde, concepto por concepto: valor auditado y ajuste de la hoja 05, valor en libros y ganancia registrada de la 03, diferencias físicas de la 04, cambios y ganancia de la 06, conciliación de la 07, deterioro de la 08 y cosecha de la 09. El saldo del mayor es el del parámetro o, si está en blanco, el valor en libros del anexo. | D26: Fila 1: SUM([«Valor auditado» de «Valoración: VR menos costos de venta», 10 filas]) → 1.524.120,00 | E26: hoja «Valoración: VR menos costos de venta» | F26: —

Sheet 02_Parametros
A1: Parámetros y ruta por marco | H1: ⟵ Inicio | I1: ◀ Anterior | J1: Siguiente ▶
A2: Activos biológicos y agricultura · Cliente de muestra S.A. · corte 2025-12-31
A4: Parámetro | B4: Valor | C4: Sustento
A5: Corte del ejercicio | B5: 46022 | C5: Ficha del encargo
A6: Marco y ruta de cálculo | B6: NIIF completas · NIC 41 y NIIF 13 | C6: NIC 41: VR menos costos de venta (41.12); costo solo si el VR no es fiable y el activo ya estaba al costo (41.30-41.31); plantas productoras a NIC 16 (41.2 b)
A7: NIIF completas: ¿el VR de los activos puede medirse con fiabilidad? (Sí/No, NIC 41.30) | B7: Sí | C7: Se aplica en NIIF completas; cada lote puede indicar otra cosa en su columna «VR fiable»
A8: PYMES: ¿el VR es fácilmente determinable sin costo o esfuerzo desproporcionado? (Sí/No, 34.2) | B8: Sí | C8: Se aplica en PYMES; juicio documentado del auditor
A9: Saldo de activos biológicos según el mayor | B9: 1500000 | C9: Mayor contable (en blanco: se toma el anexo)

Sheet 03_Activos
A1: Activos biológicos: clasificación y datos | H1: ⟵ Inicio | I1: ◀ Anterior | J1: Siguiente ▶
A2: Activos biológicos y agricultura · Cliente de muestra S.A. · corte 2025-12-31
A4: Lote | B4: Categoría | C4: Unidad | D4: Planta productora | E4: Modelo del cliente | F4: VR fiable (lote) | G4: Cantidad inicial | H4: Cantidad según registros | I4: Cantidad contada | J4: VR unitario inicial | K4: VR unitario al corte | L4: Costo de venta unitario | M4: Valor en libros | N4: Libros al inicio | O4: Compras e incrementos | P4: Disminuciones | Q4: Ganancia VR registrada | R4: Costo acumulado | S4: Depreciación acumulada | T4: Deterioro registrado | U4: Importe recuperable | V4: VR medible (aplicado) | W4: Modelo auditado | X4: Cantidad auditada | Y4: VR − costos de venta unitario | Z4: VR − costos de venta unitario inicial | AA4: Planta productora medible por separado (34.2A)
A5: G-01 | B5: Ganado lechero | C5: cabezas | D5: No | E5: Valor razonable | G5: 120 | H5: 125 | I5: 123 | J5: 1500 | K5: 1600 | L5: 40 | M5: 195000 | N5: 175200 | O5: 6000 | P5: 4500 | Q5: 18300 | V5: =IF(F5<>"",F5,'02_Parametros'!$B$7) | W5: =IF(D5="Sí","NIC 16",IF(AND(V5="No",E5="Costo"),"Costo","Valor razonable")) | X5: =IF(I5<>"",I5,H5) | Y5: =IF(K5="","",K5-L5) | Z5: =IF(J5="","",J5-L5)
A6: G-02 | B6: Ganado de engorde | C6: cabezas | D6: No | E6: Valor razonable | G6: 300 | H6: 280 | I6: 280 | J6: 800 | K6: 850 | L6: 25 | M6: 224000 | N6: 232500 | O6: 40000 | P6: 48500 | Q6: 0 | V6: =IF(F6<>"",F6,'02_Parametros'!$B$7) | W6: =IF(D6="Sí","NIC 16",IF(AND(V6="No",E6="Costo"),"Costo","Valor razonable")) | X6: =IF(I6<>"",I6,H6) | Y6: =IF(K6="","",K6-L6) | Z6: =IF(J6="","",J6-L6)
A7: P-01 | B7: Plantación de teca | C7: hectáreas | D7: No | E7: Valor razonable | G7: 50 | H7: 50 | I7: 50 | J7: 12000 | K7: 13500 | L7: 500 | M7: 650000 | N7: 575000 | O7: 0 | P7: 0 | Q7: 75000 | V7: =IF(F7<>"",F7,'02_Parametros'!$B$7) | W7: =IF(D7="Sí","NIC 16",IF(AND(V7="No",E7="Costo"),"Costo","Valor razonable")) | X7: =IF(I7<>"",I7,H7) | Y7: =IF(K7="","",K7-L7) | Z7: =IF(J7="","",J7-L7)
A8: C-01 | B8: Camarón en piscinas | C8: kg | D8: No | E8: Valor razonable | G8: 20000 | H8: 45000 | J8: 3 | K8: 3.2 | L8: 0.2 | M8: 130000 | N8: 56000 | O8: 30000 | P8: 0 | Q8: 44000 | V8: =IF(F8<>"",F8,'02_Parametros'!$B$7) | W8: =IF(D8="Sí","NIC 16",IF(AND(V8="No",E8="Costo"),"Costo","Valor razonable")) | X8: =IF(I8<>"",I8,H8) | Y8: =IF(K8="","",K8-L8) | Z8: =IF(J8="","",J8-L8)
A9: F-01 | B9: Rosales en producción | C9: plantas | D9: Sí | E9: Costo | G9: 100000 | H9: 100000 | I9: 100000 | M9: 80000 | N9: 80000 | O9: 0 | P9: 0 | V9: =IF(F9<>"",F9,'02_Parametros'!$B$7) | W9: =IF(D9="Sí","NIC 16",IF(AND(V9="No",E9="Costo"),"Costo","Valor razonable")) | X9: =IF(I9<>"",I9,H9) | Y9: =IF(K9="","",K9-L9) | Z9: =IF(J9="","",J9-L9) | AA9: Sí
A10: F-02 | B10: Botones de rosa en crecimiento | C10: tallos | D10: No | E10: Valor razonable | G10: 200000 | H10: 250000 | I10: 250000 | J10: 0.1 | K10: 0.12 | L10: 0.02 | M10: 25000 | N10: 16000 | O10: 0 | P10: 0 | Q10: 8000 | V10: =IF(F10<>"",F10,'02_Parametros'!$B$7) | W10: =IF(D10="Sí","NIC 16",IF(AND(V10="No",E10="Costo"),"Costo","Valor razonable")) | X10: =IF(I10<>"",I10,H10) | Y10: =IF(K10="","",K10-L10) | Z10: =IF(J10="","",J10-L10)
A11: G-03 | B11: Toros reproductores importados | C11: cabezas | D11: No | E11: Costo | F11: No | G11: 5 | H11: 5 | I11: 5 | M11: 42000 | N11: 48000 | O11: 0 | P11: 6000 | R11: 60000 | S11: 18000 | T11: 0 | U11: 38000 | V11: =IF(F11<>"",F11,'02_Parametros'!$B$7) | W11: =IF(D11="Sí","NIC 16",IF(AND(V11="No",E11="Costo"),"Costo","Valor razonable")) | X11: =IF(I11<>"",I11,H11) | Y11: =IF(K11="","",K11-L11) | Z11: =IF(J11="","",J11-L11)
A12: G-04 | B12: Cerdos de engorde | C12: cabezas | D12: No | E12: Costo | G12: 400 | H12: 420 | I12: 418 | J12: 180 | K12: 190 | L12: 10 | M12: 63000 | N12: 60000 | O12: 20000 | P12: 17000 | Q12: 0 | R12: 63000 | V12: =IF(F12<>"",F12,'02_Parametros'!$B$7) | W12: =IF(D12="Sí","NIC 16",IF(AND(V12="No",E12="Costo"),"Costo","Valor razonable")) | X12: =IF(I12<>"",I12,H12) | Y12: =IF(K12="","",K12-L12) | Z12: =IF(J12="","",J12-L12)
A13: P-02 | B13: Cultivo de maíz | C13: hectáreas | D13: No | E13: Valor razonable | G13: 0 | H13: 80 | I13: 80 | K13: 900 | L13: 50 | M13: 64000 | N13: 0 | O13: 64000 | P13: 0 | Q13: 0 | V13: =IF(F13<>"",F13,'02_Parametros'!$B$7) | W13: =IF(D13="Sí","NIC 16",IF(AND(V13="No",E13="Costo"),"Costo","Valor razonable")) | X13: =IF(I13<>"",I13,H13) | Y13: =IF(K13="","",K13-L13) | Z13: =IF(J13="","",J13-L13)
A14: C-02 | B14: Tilapia en estanques | C14: kg | D14: No | E14: Valor razonable | G14: 10000 | H14: 12000 | I14: 12500 | J14: 2.5 | K14: 2.4 | M14: 28800 | N14: 25000 | O14: 5000 | P14: 3000 | Q14: 1800 | V14: =IF(F14<>"",F14,'02_Parametros'!$B$7) | W14: =IF(D14="Sí","NIC 16",IF(AND(V14="No",E14="Costo"),"Costo","Valor razonable")) | X14: =IF(I14<>"",I14,H14) | Y14: =IF(K14="","",K14-L14) | Z14: =IF(J14="","",J14-L14)
A15: TOTAL | M15: =SUM(M5:M14) | Q15: =SUM(Q5:Q14)
A17: ⓘ Cómo se calcula esta hoja
A18: Columna | B18: Fórmula (Excel) | C18: Cómo se calcula (sencillo) | D18: Ejemplo con números reales | E18: De dónde viene | F18: Norma
A19: VR medible (aplicado) | B19: '=IF(F5<>"",F5,'02_Parametros'!$B$7) | C19: Usa la respuesta del lote en la columna «VR fiable (lote)»; si está en blanco, aplica el parámetro general «VR fiable» (NIIF completas) de la hoja 02 (Parámetros). | D19: Fila 1: IF((vacío)<>""; (vacío); «Sí») → Sí | E19: «VR fiable (lote)» (esta hoja), hoja «Parámetros y ruta por marco» | F19: —
A20: Modelo auditado | B20: '=IF(D5="Sí","NIC 16",IF(AND(V5="No",E5="Costo"),"Costo","Valor razonable")) | C20: Decide cómo se mide el lote: las plantas productoras van a NIC 16; queda al costo solo si el VR no es fiable y el cliente ya lo tenía al costo; en los demás casos, a valor razonable. | D20: Fila 1: IF(«No»="Sí"; "NIC 16"; IF(AND(«Sí»="No"; «Valor razonable»="Costo"); "Costo"; "Valor razonable")) → Valor razonable | E20: «Planta productora» (esta hoja), «VR medible (aplicado)» (esta hoja), «Modelo del cliente» (esta hoja) | F20: —
A21: Cantidad auditada | B21: '=IF(I5<>"",I5,H5) | C21: Usa la cantidad contada por el auditor; si no hubo conteo del lote, toma la cantidad según los registros. | D21: Fila 1: IF(123,00<>""; 123,00; 125,00) → 123,00 | E21: «Cantidad contada» (esta hoja), «Cantidad según registros» (esta hoja) | F21: —
A22: VR − costos de venta unitario | B22: '=IF(K5="","",K5-L5) | C22: Resta el costo de venta unitario al valor razonable unitario al corte; queda en blanco si no hay valor razonable al corte. | D22: Fila 1: IF(1.600,00=""; ""; 1.600,00-40,00) → 1.560,00 | E22: «VR unitario al corte» (esta hoja), «Costo de venta unitario» (esta hoja) | F22: —
A23: VR − costos de venta unitario inicial | B23: '=IF(J5="","",J5-L5) | C23: Resta el costo de venta unitario al valor razonable unitario inicial; queda en blanco si no hay valor razonable inicial. | D23: Fila 1: IF(1.500,00=""; ""; 1.500,00-40,00) → 1.460,00 | E23: «VR unitario inicial» (esta hoja), «Costo de venta unitario» (esta hoja) | F23: —

Sheet 04_Existencia
A1: Existencia: conteo vs registros | H1: ⟵ Inicio | I1: ◀ Anterior | J1: Siguiente ▶
A2: Activos biológicos y agricultura · Cliente de muestra S.A. · corte 2025-12-31
A4: Lote | B4: Categoría | C4: Unidad | D4: Cantidad según registros | E4: Cantidad contada | F4: Diferencia (unidades) | G4: Valor unitario | H4: Diferencia valorizada
A5: G-01 | B5: Ganado lechero | C5: cabezas | D5: ='03_Activos'!H5 | E5: =IF('03_Activos'!I5="","",'03_Activos'!I5) | F5: =IF(E5="","",E5-D5) | G5: =IF('03_Activos'!Y5<>"",'03_Activos'!Y5,IF('03_Activos'!H5=0,"",'03_Activos'!M5/'03_Activos'!H5)) | H5: =IF(OR(F5="",G5=""),"",F5*G5)
A6: G-02 | B6: Ganado de engorde | C6: cabezas | D6: ='03_Activos'!H6 | E6: =IF('03_Activos'!I6="","",'03_Activos'!I6) | F6: =IF(E6="","",E6-D6) | G6: =IF('03_Activos'!Y6<>"",'03_Activos'!Y6,IF('03_Activos'!H6=0,"",'03_Activos'!M6/'03_Activos'!H6)) | H6: =IF(OR(F6="",G6=""),"",F6*G6)
A7: P-01 | B7: Plantación de teca | C7: hectáreas | D7: ='03_Activos'!H7 | E7: =IF('03_Activos'!I7="","",'03_Activos'!I7) | F7: =IF(E7="","",E7-D7) | G7: =IF('03_Activos'!Y7<>"",'03_Activos'!Y7,IF('03_Activos'!H7=0,"",'03_Activos'!M7/'03_Activos'!H7)) | H7: =IF(OR(F7="",G7=""),"",F7*G7)
A8: C-01 | B8: Camarón en piscinas | C8: kg | D8: ='03_Activos'!H8 | E8: =IF('03_Activos'!I8="","",'03_Activos'!I8) | F8: =IF(E8="","",E8-D8) | G8: =IF('03_Activos'!Y8<>"",'03_Activos'!Y8,IF('03_Activos'!H8=0,"",'03_Activos'!M8/'03_Activos'!H8)) | H8: =IF(OR(F8="",G8=""),"",F8*G8)
A9: F-01 | B9: Rosales en producción | C9: plantas | D9: ='03_Activos'!H9 | E9: =IF('03_Activos'!I9="","",'03_Activos'!I9) | F9: =IF(E9="","",E9-D9) | G9: =IF('03_Activos'!Y9<>"",'03_Activos'!Y9,IF('03_Activos'!H9=0,"",'03_Activos'!M9/'03_Activos'!H9)) | H9: =IF(OR(F9="",G9=""),"",F9*G9)
A10: F-02 | B10: Botones de rosa en crecimiento | C10: tallos | D10: ='03_Activos'!H10 | E10: =IF('03_Activos'!I10="","",'03_Activos'!I10) | F10: =IF(E10="","",E10-D10) | G10: =IF('03_Activos'!Y10<>"",'03_Activos'!Y10,IF('03_Activos'!H10=0,"",'03_Activos'!M10/'03_Activos'!H10)) | H10: =IF(OR(F10="",G10=""),"",F10*G10)
A11: G-03 | B11: Toros reproductores importados | C11: cabezas | D11: ='03_Activos'!H11 | E11: =IF('03_Activos'!I11="","",'03_Activos'!I11) | F11: =IF(E11="","",E11-D11) | G11: =IF('03_Activos'!Y11<>"",'03_Activos'!Y11,IF('03_Activos'!H11=0,"",'03_Activos'!M11/'03_Activos'!H11)) | H11: =IF(OR(F11="",G11=""),"",F11*G11)
A12: G-04 | B12: Cerdos de engorde | C12: cabezas | D12: ='03_Activos'!H12 | E12: =IF('03_Activos'!I12="","",'03_Activos'!I12) | F12: =IF(E12="","",E12-D12) | G12: =IF('03_Activos'!Y12<>"",'03_Activos'!Y12,IF('03_Activos'!H12=0,"",'03_Activos'!M12/'03_Activos'!H12)) | H12: =IF(OR(F12="",G12=""),"",F12*G12)
A13: P-02 | B13: Cultivo de maíz | C13: hectáreas | D13: ='03_Activos'!H13 | E13: =IF('03_Activos'!I13="","",'03_Activos'!I13) | F13: =IF(E13="","",E13-D13) | G13: =IF('03_Activos'!Y13<>"",'03_Activos'!Y13,IF('03_Activos'!H13=0,"",'03_Activos'!M13/'03_Activos'!H13)) | H13: =IF(OR(F13="",G13=""),"",F13*G13)
A14: C-02 | B14: Tilapia en estanques | C14: kg | D14: ='03_Activos'!H14 | E14: =IF('03_Activos'!I14="","",'03_Activos'!I14) | F14: =IF(E14="","",E14-D14) | G14: =IF('03_Activos'!Y14<>"",'03_Activos'!Y14,IF('03_Activos'!H14=0,"",'03_Activos'!M14/'03_Activos'!H14)) | H14: =IF(OR(F14="",G14=""),"",F14*G14)
A15: TOTAL | H15: =SUM(H5:H14)
A17: ⓘ Cómo se calcula esta hoja
A18: Columna | B18: Fórmula (Excel) | C18: Cómo se calcula (sencillo) | D18: Ejemplo con números reales | E18: De dónde viene | F18: Norma
A19: Cantidad según registros | B19: '='03_Activos'!H5 | C19: Trae la cantidad de unidades que muestran los registros del cliente en la hoja 03 (Activos biológicos: clasificación y datos). | D19: Fila 1: 125,00 → 125,00 | E19: hoja «Activos biológicos: clasificación y datos» | F19: —
A20: Cantidad contada | B20: '=IF('03_Activos'!I5="","",'03_Activos'!I5) | C20: Trae la cantidad contada físicamente en la hoja 03 (Activos biológicos: clasificación y datos); si el lote no se contó, queda en blanco. | D20: Fila 1: IF(123,00=""; ""; 123,00) → 123,00 | E20: hoja «Activos biológicos: clasificación y datos» | F20: —
A21: Diferencia (unidades) | B21: '=IF(E5="","",E5-D5) | C21: Resta la cantidad según registros a la contada: negativo es faltante, positivo sobrante; en blanco sin conteo. | D21: Fila 1: IF(123,00=""; ""; 123,00-125,00) → -2,00 | E21: «Cantidad contada» (esta hoja), «Cantidad según registros» (esta hoja) | F21: —
A22: Valor unitario | B22: '=IF('03_Activos'!Y5<>"",'03_Activos'!Y5,IF('03_Activos'!H5=0,"",'03_Activos'!M5/'03_Activos'!H5)) | C22: Usa el VR menos costos de venta unitario de la hoja 03 (Activos biológicos: clasificación y datos); si no lo hay, divide el valor en libros entre la cantidad según registros (en blanco si esa cantidad es cero). | D22: Fila 1: IF(1.560,00<>""; 1.560,00; IF(125,00=0; ""; 195.000,00/125,00)) → 1.560,00 | E22: hoja «Activos biológicos: clasificación y datos» | F22: —
A23: Diferencia valorizada | B23: '=IF(OR(F5="",G5=""),"",F5*G5) | C23: Multiplica la diferencia en unidades por el valor unitario; en blanco si falta alguno de los dos. | D23: Fila 1: IF(OR(-2,00=""; 1.560,00=""); ""; -2,00*1.560,00) → -3.120,00 | E23: «Diferencia (unidades)» (esta hoja), «Valor unitario» (esta hoja) | F23: —

Sheet 05_Valoracion
A1: Valoración: VR menos costos de venta | H1: ⟵ Inicio | I1: ◀ Anterior | J1: Siguiente ▶
A2: Activos biológicos y agricultura · Cliente de muestra S.A. · corte 2025-12-31
A4: Lote | B4: Categoría | C4: Modelo auditado | D4: Cantidad auditada | E4: VR unitario al corte | F4: Costo de venta unitario | G4: VR − costos de venta unitario | H4: VR − costos de venta total | I4: Valor modelo del costo | J4: Valor auditado | K4: Valor en libros | L4: Ajuste
A5: G-01 | B5: Ganado lechero | C5: ='03_Activos'!W5 | D5: ='03_Activos'!X5 | E5: =IF('03_Activos'!K5="","",'03_Activos'!K5) | F5: ='03_Activos'!L5 | G5: =IF(E5="","",E5-F5) | H5: =IF(OR(C5<>"Valor razonable",G5=""),"",D5*G5) | I5: =IF(C5="Costo",IF('08_Modelo_costo'!I5="","",'08_Modelo_costo'!I5),"") | J5: =IF(C5="NIC 16",K5,IF(C5="Valor razonable",H5,I5)) | K5: ='03_Activos'!M5 | L5: =IF(J5="","",J5-K5)
A6: G-02 | B6: Ganado de engorde | C6: ='03_Activos'!W6 | D6: ='03_Activos'!X6 | E6: =IF('03_Activos'!K6="","",'03_Activos'!K6) | F6: ='03_Activos'!L6 | G6: =IF(E6="","",E6-F6) | H6: =IF(OR(C6<>"Valor razonable",G6=""),"",D6*G6) | I6: =IF(C6="Costo",IF('08_Modelo_costo'!I6="","",'08_Modelo_costo'!I6),"") | J6: =IF(C6="NIC 16",K6,IF(C6="Valor razonable",H6,I6)) | K6: ='03_Activos'!M6 | L6: =IF(J6="","",J6-K6)
A7: P-01 | B7: Plantación de teca | C7: ='03_Activos'!W7 | D7: ='03_Activos'!X7 | E7: =IF('03_Activos'!K7="","",'03_Activos'!K7) | F7: ='03_Activos'!L7 | G7: =IF(E7="","",E7-F7) | H7: =IF(OR(C7<>"Valor razonable",G7=""),"",D7*G7) | I7: =IF(C7="Costo",IF('08_Modelo_costo'!I7="","",'08_Modelo_costo'!I7),"") | J7: =IF(C7="NIC 16",K7,IF(C7="Valor razonable",H7,I7)) | K7: ='03_Activos'!M7 | L7: =IF(J7="","",J7-K7)
A8: C-01 | B8: Camarón en piscinas | C8: ='03_Activos'!W8 | D8: ='03_Activos'!X8 | E8: =IF('03_Activos'!K8="","",'03_Activos'!K8) | F8: ='03_Activos'!L8 | G8: =IF(E8="","",E8-F8) | H8: =IF(OR(C8<>"Valor razonable",G8=""),"",D8*G8) | I8: =IF(C8="Costo",IF('08_Modelo_costo'!I8="","",'08_Modelo_costo'!I8),"") | J8: =IF(C8="NIC 16",K8,IF(C8="Valor razonable",H8,I8)) | K8: ='03_Activos'!M8 | L8: =IF(J8="","",J8-K8)
A9: F-01 | B9: Rosales en producción | C9: ='03_Activos'!W9 | D9: ='03_Activos'!X9 | E9: =IF('03_Activos'!K9="","",'03_Activos'!K9) | F9: ='03_Activos'!L9 | G9: =IF(E9="","",E9-F9) | H9: =IF(OR(C9<>"Valor razonable",G9=""),"",D9*G9) | I9: =IF(C9="Costo",IF('08_Modelo_costo'!I9="","",'08_Modelo_costo'!I9),"") | J9: =IF(C9="NIC 16",K9,IF(C9="Valor razonable",H9,I9)) | K9: ='03_Activos'!M9 | L9: =IF(J9="","",J9-K9)
A10: F-02 | B10: Botones de rosa en crecimiento | C10: ='03_Activos'!W10 | D10: ='03_Activos'!X10 | E10: =IF('03_Activos'!K10="","",'03_Activos'!K10) | F10: ='03_Activos'!L10 | G10: =IF(E10="","",E10-F10) | H10: =IF(OR(C10<>"Valor razonable",G10=""),"",D10*G10) | I10: =IF(C10="Costo",IF('08_Modelo_costo'!I10="","",'08_Modelo_costo'!I10),"") | J10: =IF(C10="NIC 16",K10,IF(C10="Valor razonable",H10,I10)) | K10: ='03_Activos'!M10 | L10: =IF(J10="","",J10-K10)
A11: G-03 | B11: Toros reproductores importados | C11: ='03_Activos'!W11 | D11: ='03_Activos'!X11 | E11: =IF('03_Activos'!K11="","",'03_Activos'!K11) | F11: ='03_Activos'!L11 | G11: =IF(E11="","",E11-F11) | H11: =IF(OR(C11<>"Valor razonable",G11=""),"",D11*G11) | I11: =IF(C11="Costo",IF('08_Modelo_costo'!I11="","",'08_Modelo_costo'!I11),"") | J11: =IF(C11="NIC 16",K11,IF(C11="Valor razonable",H11,I11)) | K11: ='03_Activos'!M11 | L11: =IF(J11="","",J11-K11)
A12: G-04 | B12: Cerdos de engorde | C12: ='03_Activos'!W12 | D12: ='03_Activos'!X12 | E12: =IF('03_Activos'!K12="","",'03_Activos'!K12) | F12: ='03_Activos'!L12 | G12: =IF(E12="","",E12-F12) | H12: =IF(OR(C12<>"Valor razonable",G12=""),"",D12*G12) | I12: =IF(C12="Costo",IF('08_Modelo_costo'!I12="","",'08_Modelo_costo'!I12),"") | J12: =IF(C12="NIC 16",K12,IF(C12="Valor razonable",H12,I12)) | K12: ='03_Activos'!M12 | L12: =IF(J12="","",J12-K12)
A13: P-02 | B13: Cultivo de maíz | C13: ='03_Activos'!W13 | D13: ='03_Activos'!X13 | E13: =IF('03_Activos'!K13="","",'03_Activos'!K13) | F13: ='03_Activos'!L13 | G13: =IF(E13="","",E13-F13) | H13: =IF(OR(C13<>"Valor razonable",G13=""),"",D13*G13) | I13: =IF(C13="Costo",IF('08_Modelo_costo'!I13="","",'08_Modelo_costo'!I13),"") | J13: =IF(C13="NIC 16",K13,IF(C13="Valor razonable",H13,I13)) | K13: ='03_Activos'!M13 | L13: =IF(J13="","",J13-K13)
A14: C-02 | B14: Tilapia en estanques | C14: ='03_Activos'!W14 | D14: ='03_Activos'!X14 | E14: =IF('03_Activos'!K14="","",'03_Activos'!K14) | F14: ='03_Activos'!L14 | G14: =IF(E14="","",E14-F14) | H14: =IF(OR(C14<>"Valor razonable",G14=""),"",D14*G14) | I14: =IF(C14="Costo",IF('08_Modelo_costo'!I14="","",'08_Modelo_costo'!I14),"") | J14: =IF(C14="NIC 16",K14,IF(C14="Valor razonable",H14,I14)) | K14: ='03_Activos'!M14 | L14: =IF(J14="","",J14-K14)
A15: TOTAL | H15: =SUM(H5:H14) | I15: =SUM(I5:I14) | J15: =SUM(J5:J14) | K15: =SUM(K5:K14) | L15: =SUM(L5:L14)
A17: ⓘ Cómo se calcula esta hoja
A18: Columna | B18: Fórmula (Excel) | C18: Cómo se calcula (sencillo) | D18: Ejemplo con números reales | E18: De dónde viene | F18: Norma
A19: Modelo auditado | B19: '='03_Activos'!W5 | C19: Trae de la hoja 03 (Activos biológicos: clasificación y datos) el modelo con que el auditor mide el lote (valor razonable, costo o NIC 16 para plantas productoras). | D19: Fila 1: «Valor razonable» → Valor razonable | E19: hoja «Activos biológicos: clasificación y datos» | F19: —
A20: Cantidad auditada | B20: '='03_Activos'!X5 | C20: Trae la cantidad auditada de la hoja 03 (Activos biológicos: clasificación y datos): la contada o, sin conteo, la de los registros. | D20: Fila 1: 123,00 → 123,00 | E20: hoja «Activos biológicos: clasificación y datos» | F20: —
A21: VR unitario al corte | B21: '=IF('03_Activos'!K5="","",'03_Activos'!K5) | C21: Trae el valor razonable unitario al corte informado en la hoja 03 (Activos biológicos: clasificación y datos); en blanco si no se informó. | D21: Fila 1: IF(1.600,00=""; ""; 1.600,00) → 1.600,00 | E21: hoja «Activos biológicos: clasificación y datos» | F21: —
A22: Costo de venta unitario | B22: '='03_Activos'!L5 | C22: Trae el costo de venta unitario del lote (por ejemplo, comisiones) informado en la hoja 03 (Activos biológicos: clasificación y datos). | D22: Fila 1: 40,00 → 40,00 | E22: hoja «Activos biológicos: clasificación y datos» | F22: —
A23: VR − costos de venta unitario | B23: '=IF(E5="","",E5-F5) | C23: Resta el costo de venta unitario al VR unitario al corte; queda en blanco si no hay VR al corte. | D23: Fila 1: IF(1.600,00=""; ""; 1.600,00-40,00) → 1.560,00 | E23: «VR unitario al corte» (esta hoja), «Costo de venta unitario» (esta hoja) | F23: —
A24: VR − costos de venta total | B24: '=IF(OR(C5<>"Valor razonable",G5=""),"",D5*G5) | C24: Multiplica la cantidad auditada por el VR menos costos de venta unitario. Solo se calcula para lotes medidos a valor razonable; en los demás queda en blanco. | D24: Fila 1: IF(OR(«Valor razonable»<>"Valor razonable"; 1.560,00=""); ""; 123,00*1.560,00) → 191.880,00 | E24: «Modelo auditado» (esta hoja), «VR − costos de venta unitario» (esta hoja), «Cantidad auditada» (esta hoja) | F24: —
A25: Valor modelo del costo | B25: '=IF(C5="Costo",IF('08_Modelo_costo'!I5="","",'08_Modelo_costo'!I5),"") | C25: Para lotes medidos al costo, trae el valor auditado al costo de la hoja 08 (Modelo del costo y deterioro); en los demás modelos queda en blanco. | D25: Fila 1: IF(«Valor razonable»="Costo"; IF((vacío)=""; ""; (vacío)); "") → (en blanco) | E25: «Modelo auditado» (esta hoja), hoja «Modelo del costo y deterioro» | F25: —
A26: Valor auditado | B26: '=IF(C5="NIC 16",K5,IF(C5="Valor razonable",H5,I5)) | C26: Elige el valor según el modelo: para plantas productoras medidas con NIC 16 acepta el valor en libros; a valor razonable, el VR menos costos de venta total; al costo, el valor de la hoja 08 (Modelo del costo). | D26: Fila 1: IF(«Valor razonable»="NIC 16"; 195.000,00; IF(«Valor razonable»="Valor razonable"; 191.880,00; (vacío))) → 191.880,00 | E26: «Modelo auditado» (esta hoja), «Valor en libros» (esta hoja), «VR − costos de venta total» (esta hoja), «Valor modelo del costo» (esta hoja) | F26: —
A27: Valor en libros | B27: '='03_Activos'!M5 | C27: Trae el valor en libros del lote al corte registrado por el cliente en la hoja 03 (Activos biológicos: clasificación y datos). | D27: Fila 1: 195.000,00 → 195.000,00 | E27: hoja «Activos biológicos: clasificación y datos» | F27: —
A28: Ajuste | B28: '=IF(J5="","",J5-K5) | C28: Resta el valor en libros al valor auditado: positivo aumenta el activo y negativo lo disminuye; en blanco sin valor auditado. | D28: Fila 1: IF(191.880,00=""; ""; 191.880,00-195.000,00) → -3.120,00 | E28: «Valor auditado» (esta hoja), «Valor en libros» (esta hoja) | F28: —

Sheet 06_Transformacion
A1: Transformación biológica y cambio de VR | H1: ⟵ Inicio | I1: ◀ Anterior | J1: Siguiente ▶
A2: Activos biológicos y agricultura · Cliente de muestra S.A. · corte 2025-12-31
A4: Lote | B4: Modelo auditado | C4: Cantidad inicial | D4: Cantidad final auditada | E4: VR − CV unitario inicial | F4: VR − CV unitario final | G4: Cambio físico | H4: Cambio de precio | I4: Cambio total | J4: Libros al inicio | K4: Compras | L4: Disminuciones | M4: VR − CV final total | N4: Ganancia recalculada | O4: Ganancia registrada | P4: No reconocido
A5: G-01 | B5: ='05_Valoracion'!C5 | C5: =IF('03_Activos'!G5="","",'03_Activos'!G5) | D5: ='03_Activos'!X5 | E5: =IF('03_Activos'!Z5="","",'03_Activos'!Z5) | F5: =IF('03_Activos'!Y5="","",'03_Activos'!Y5) | G5: =IF(OR(B5<>"Valor razonable",C5="",E5=""),"",(D5-C5)*E5) | H5: =IF(OR(B5<>"Valor razonable",E5="",F5=""),"",D5*(F5-E5)) | I5: =IF(OR(G5="",H5=""),"",G5+H5) | J5: =IF('03_Activos'!N5="","",'03_Activos'!N5) | K5: =IF('03_Activos'!O5="",0,'03_Activos'!O5) | L5: =IF('03_Activos'!P5="",0,'03_Activos'!P5) | M5: =IF('05_Valoracion'!H5="","",'05_Valoracion'!H5) | N5: =IF(OR(M5="",J5=""),"",M5-J5-K5+L5) | O5: =IF('03_Activos'!Q5="","",'03_Activos'!Q5) | P5: =IF(OR(N5="",O5=""),"",N5-O5)
A6: G-02 | B6: ='05_Valoracion'!C6 | C6: =IF('03_Activos'!G6="","",'03_Activos'!G6) | D6: ='03_Activos'!X6 | E6: =IF('03_Activos'!Z6="","",'03_Activos'!Z6) | F6: =IF('03_Activos'!Y6="","",'03_Activos'!Y6) | G6: =IF(OR(B6<>"Valor razonable",C6="",E6=""),"",(D6-C6)*E6) | H6: =IF(OR(B6<>"Valor razonable",E6="",F6=""),"",D6*(F6-E6)) | I6: =IF(OR(G6="",H6=""),"",G6+H6) | J6: =IF('03_Activos'!N6="","",'03_Activos'!N6) | K6: =IF('03_Activos'!O6="",0,'03_Activos'!O6) | L6: =IF('03_Activos'!P6="",0,'03_Activos'!P6) | M6: =IF('05_Valoracion'!H6="","",'05_Valoracion'!H6) | N6: =IF(OR(M6="",J6=""),"",M6-J6-K6+L6) | O6: =IF('03_Activos'!Q6="","",'03_Activos'!Q6) | P6: =IF(OR(N6="",O6=""),"",N6-O6)
A7: P-01 | B7: ='05_Valoracion'!C7 | C7: =IF('03_Activos'!G7="","",'03_Activos'!G7) | D7: ='03_Activos'!X7 | E7: =IF('03_Activos'!Z7="","",'03_Activos'!Z7) | F7: =IF('03_Activos'!Y7="","",'03_Activos'!Y7) | G7: =IF(OR(B7<>"Valor razonable",C7="",E7=""),"",(D7-C7)*E7) | H7: =IF(OR(B7<>"Valor razonable",E7="",F7=""),"",D7*(F7-E7)) | I7: =IF(OR(G7="",H7=""),"",G7+H7) | J7: =IF('03_Activos'!N7="","",'03_Activos'!N7) | K7: =IF('03_Activos'!O7="",0,'03_Activos'!O7) | L7: =IF('03_Activos'!P7="",0,'03_Activos'!P7) | M7: =IF('05_Valoracion'!H7="","",'05_Valoracion'!H7) | N7: =IF(OR(M7="",J7=""),"",M7-J7-K7+L7) | O7: =IF('03_Activos'!Q7="","",'03_Activos'!Q7) | P7: =IF(OR(N7="",O7=""),"",N7-O7)
A8: C-01 | B8: ='05_Valoracion'!C8 | C8: =IF('03_Activos'!G8="","",'03_Activos'!G8) | D8: ='03_Activos'!X8 | E8: =IF('03_Activos'!Z8="","",'03_Activos'!Z8) | F8: =IF('03_Activos'!Y8="","",'03_Activos'!Y8) | G8: =IF(OR(B8<>"Valor razonable",C8="",E8=""),"",(D8-C8)*E8) | H8: =IF(OR(B8<>"Valor razonable",E8="",F8=""),"",D8*(F8-E8)) | I8: =IF(OR(G8="",H8=""),"",G8+H8) | J8: =IF('03_Activos'!N8="","",'03_Activos'!N8) | K8: =IF('03_Activos'!O8="",0,'03_Activos'!O8) | L8: =IF('03_Activos'!P8="",0,'03_Activos'!P8) | M8: =IF('05_Valoracion'!H8="","",'05_Valoracion'!H8) | N8: =IF(OR(M8="",J8=""),"",M8-J8-K8+L8) | O8: =IF('03_Activos'!Q8="","",'03_Activos'!Q8) | P8: =IF(OR(N8="",O8=""),"",N8-O8)
A9: F-01 | B9: ='05_Valoracion'!C9 | C9: =IF('03_Activos'!G9="","",'03_Activos'!G9) | D9: ='03_Activos'!X9 | E9: =IF('03_Activos'!Z9="","",'03_Activos'!Z9) | F9: =IF('03_Activos'!Y9="","",'03_Activos'!Y9) | G9: =IF(OR(B9<>"Valor razonable",C9="",E9=""),"",(D9-C9)*E9) | H9: =IF(OR(B9<>"Valor razonable",E9="",F9=""),"",D9*(F9-E9)) | I9: =IF(OR(G9="",H9=""),"",G9+H9) | J9: =IF('03_Activos'!N9="","",'03_Activos'!N9) | K9: =IF('03_Activos'!O9="",0,'03_Activos'!O9) | L9: =IF('03_Activos'!P9="",0,'03_Activos'!P9) | M9: =IF('05_Valoracion'!H9="","",'05_Valoracion'!H9) | N9: =IF(OR(M9="",J9=""),"",M9-J9-K9+L9) | O9: =IF('03_Activos'!Q9="","",'03_Activos'!Q9) | P9: =IF(OR(N9="",O9=""),"",N9-O9)
A10: F-02 | B10: ='05_Valoracion'!C10 | C10: =IF('03_Activos'!G10="","",'03_Activos'!G10) | D10: ='03_Activos'!X10 | E10: =IF('03_Activos'!Z10="","",'03_Activos'!Z10) | F10: =IF('03_Activos'!Y10="","",'03_Activos'!Y10) | G10: =IF(OR(B10<>"Valor razonable",C10="",E10=""),"",(D10-C10)*E10) | H10: =IF(OR(B10<>"Valor razonable",E10="",F10=""),"",D10*(F10-E10)) | I10: =IF(OR(G10="",H10=""),"",G10+H10) | J10: =IF('03_Activos'!N10="","",'03_Activos'!N10) | K10: =IF('03_Activos'!O10="",0,'03_Activos'!O10) | L10: =IF('03_Activos'!P10="",0,'03_Activos'!P10) | M10: =IF('05_Valoracion'!H10="","",'05_Valoracion'!H10) | N10: =IF(OR(M10="",J10=""),"",M10-J10-K10+L10) | O10: =IF('03_Activos'!Q10="","",'03_Activos'!Q10) | P10: =IF(OR(N10="",O10=""),"",N10-O10)
A11: G-03 | B11: ='05_Valoracion'!C11 | C11: =IF('03_Activos'!G11="","",'03_Activos'!G11) | D11: ='03_Activos'!X11 | E11: =IF('03_Activos'!Z11="","",'03_Activos'!Z11) | F11: =IF('03_Activos'!Y11="","",'03_Activos'!Y11) | G11: =IF(OR(B11<>"Valor razonable",C11="",E11=""),"",(D11-C11)*E11) | H11: =IF(OR(B11<>"Valor razonable",E11="",F11=""),"",D11*(F11-E11)) | I11: =IF(OR(G11="",H11=""),"",G11+H11) | J11: =IF('03_Activos'!N11="","",'03_Activos'!N11) | K11: =IF('03_Activos'!O11="",0,'03_Activos'!O11) | L11: =IF('03_Activos'!P11="",0,'03_Activos'!P11) | M11: =IF('05_Valoracion'!H11="","",'05_Valoracion'!H11) | N11: =IF(OR(M11="",J11=""),"",M11-J11-K11+L11) | O11: =IF('03_Activos'!Q11="","",'03_Activos'!Q11) | P11: =IF(OR(N11="",O11=""),"",N11-O11)
A12: G-04 | B12: ='05_Valoracion'!C12 | C12: =IF('03_Activos'!G12="","",'03_Activos'!G12) | D12: ='03_Activos'!X12 | E12: =IF('03_Activos'!Z12="","",'03_Activos'!Z12) | F12: =IF('03_Activos'!Y12="","",'03_Activos'!Y12) | G12: =IF(OR(B12<>"Valor razonable",C12="",E12=""),"",(D12-C12)*E12) | H12: =IF(OR(B12<>"Valor razonable",E12="",F12=""),"",D12*(F12-E12)) | I12: =IF(OR(G12="",H12=""),"",G12+H12) | J12: =IF('03_Activos'!N12="","",'03_Activos'!N12) | K12: =IF('03_Activos'!O12="",0,'03_Activos'!O12) | L12: =IF('03_Activos'!P12="",0,'03_Activos'!P12) | M12: =IF('05_Valoracion'!H12="","",'05_Valoracion'!H12) | N12: =IF(OR(M12="",J12=""),"",M12-J12-K12+L12) | O12: =IF('03_Activos'!Q12="","",'03_Activos'!Q12) | P12: =IF(OR(N12="",O12=""),"",N12-O12)
A13: P-02 | B13: ='05_Valoracion'!C13 | C13: =IF('03_Activos'!G13="","",'03_Activos'!G13) | D13: ='03_Activos'!X13 | E13: =IF('03_Activos'!Z13="","",'03_Activos'!Z13) | F13: =IF('03_Activos'!Y13="","",'03_Activos'!Y13) | G13: =IF(OR(B13<>"Valor razonable",C13="",E13=""),"",(D13-C13)*E13) | H13: =IF(OR(B13<>"Valor razonable",E13="",F13=""),"",D13*(F13-E13)) | I13: =IF(OR(G13="",H13=""),"",G13+H13) | J13: =IF('03_Activos'!N13="","",'03_Activos'!N13) | K13: =IF('03_Activos'!O13="",0,'03_Activos'!O13) | L13: =IF('03_Activos'!P13="",0,'03_Activos'!P13) | M13: =IF('05_Valoracion'!H13="","",'05_Valoracion'!H13) | N13: =IF(OR(M13="",J13=""),"",M13-J13-K13+L13) | O13: =IF('03_Activos'!Q13="","",'03_Activos'!Q13) | P13: =IF(OR(N13="",O13=""),"",N13-O13)
A14: C-02 | B14: ='05_Valoracion'!C14 | C14: =IF('03_Activos'!G14="","",'03_Activos'!G14) | D14: ='03_Activos'!X14 | E14: =IF('03_Activos'!Z14="","",'03_Activos'!Z14) | F14: =IF('03_Activos'!Y14="","",'03_Activos'!Y14) | G14: =IF(OR(B14<>"Valor razonable",C14="",E14=""),"",(D14-C14)*E14) | H14: =IF(OR(B14<>"Valor razonable",E14="",F14=""),"",D14*(F14-E14)) | I14: =IF(OR(G14="",H14=""),"",G14+H14) | J14: =IF('03_Activos'!N14="","",'03_Activos'!N14) | K14: =IF('03_Activos'!O14="",0,'03_Activos'!O14) | L14: =IF('03_Activos'!P14="",0,'03_Activos'!P14) | M14: =IF('05_Valoracion'!H14="","",'05_Valoracion'!H14) | N14: =IF(OR(M14="",J14=""),"",M14-J14-K14+L14) | O14: =IF('03_Activos'!Q14="","",'03_Activos'!Q14) | P14: =IF(OR(N14="",O14=""),"",N14-O14)
A15: TOTAL | G15: =SUM(G5:G14) | H15: =SUM(H5:H14) | I15: =SUM(I5:I14) | N15: =SUM(N5:N14) | P15: =SUM(P5:P14)
A17: ⓘ Cómo se calcula esta hoja
A18: Columna | B18: Fórmula (Excel) | C18: Cómo se calcula (sencillo) | D18: Ejemplo con números reales | E18: De dónde viene | F18: Norma
A19: Modelo auditado | B19: '='05_Valoracion'!C5 | C19: Trae de la hoja 05 (Valoración) el modelo del lote; los cambios de VR solo se calculan a valor razonable. | D19: Fila 1: «Valor razonable» → Valor razonable | E19: hoja «Valoración: VR menos costos de venta» | F19: —
A20: Cantidad inicial | B20: '=IF('03_Activos'!G5="","",'03_Activos'!G5) | C20: Trae la cantidad de unidades al inicio del ejercicio informada en la hoja 03 (Activos biológicos: clasificación y datos); en blanco si falta. | D20: Fila 1: IF(120,00=""; ""; 120,00) → 120,00 | E20: hoja «Activos biológicos: clasificación y datos» | F20: —
A21: Cantidad final auditada | B21: '='03_Activos'!X5 | C21: Trae de la hoja 03 (Activos biológicos: clasificación y datos) la cantidad auditada al corte: la contada o, si no hubo conteo, la de los registros. | D21: Fila 1: 123,00 → 123,00 | E21: hoja «Activos biológicos: clasificación y datos» | F21: —
A22: VR − CV unitario inicial | B22: '=IF('03_Activos'!Z5="","",'03_Activos'!Z5) | C22: Trae el VR menos costos de venta unitario al inicio calculado en la hoja 03 (Activos biológicos: clasificación y datos); en blanco si no hay. | D22: Fila 1: IF(1.460,00=""; ""; 1.460,00) → 1.460,00 | E22: hoja «Activos biológicos: clasificación y datos» | F22: —
A23: VR − CV unitario final | B23: '=IF('03_Activos'!Y5="","",'03_Activos'!Y5) | C23: Trae el VR menos costos de venta unitario al corte calculado en la hoja 03 (Activos biológicos: clasificación y datos); en blanco si no hay. | D23: Fila 1: IF(1.560,00=""; ""; 1.560,00) → 1.560,00 | E23: hoja «Activos biológicos: clasificación y datos» | F23: —
A24: Cambio físico | B24: '=IF(OR(B5<>"Valor razonable",C5="",E5=""),"",(D5-C5)*E5) | C24: Multiplica el aumento o disminución de unidades (final menos inicial) por el VR menos costos de venta unitario inicial. Solo para lotes a valor razonable con cantidad y precio inicial. | D24: Fila 1: IF(OR(«Valor razonable»<>"Valor razonable"; 120,00=""; 1.460,00=""); ""; (123,00-120,00)*1.460,00) → 4.380,00 | E24: «Modelo auditado» (esta hoja), «Cantidad inicial» (esta hoja), «VR − CV unitario inicial» (esta hoja), «Cantidad final auditada» (esta hoja) | F24: —
A25: Cambio de precio | B25: '=IF(OR(B5<>"Valor razonable",E5="",F5=""),"",D5*(F5-E5)) | C25: Multiplica la cantidad final por la variación del VR menos costos de venta unitario (final menos inicial). Solo para lotes a valor razonable con ambos precios. | D25: Fila 1: IF(OR(«Valor razonable»<>"Valor razonable"; 1.460,00=""; 1.560,00=""); ""; 123,00*(1.560,00-1.460,00)) → 12.300,00 | E25: «Modelo auditado» (esta hoja), «VR − CV unitario inicial» (esta hoja), «VR − CV unitario final» (esta hoja), «Cantidad final auditada» (esta hoja) | F25: —
A26: Cambio total | B26: '=IF(OR(G5="",H5=""),"",G5+H5) | C26: Suma el cambio físico y el cambio de precio; en blanco si falta alguno de los dos. | D26: Fila 1: IF(OR(4.380,00=""; 12.300,00=""); ""; 4.380,00+12.300,00) → 16.680,00 | E26: «Cambio físico» (esta hoja), «Cambio de precio» (esta hoja) | F26: —
A27: Libros al inicio | B27: '=IF('03_Activos'!N5="","",'03_Activos'!N5) | C27: Trae el valor en libros del lote al inicio del ejercicio desde la hoja 03 (Activos biológicos: clasificación y datos); en blanco si falta. | D27: Fila 1: IF(175.200,00=""; ""; 175.200,00) → 175.200,00 | E27: hoja «Activos biológicos: clasificación y datos» | F27: —
A28: Compras | B28: '=IF('03_Activos'!O5="",0,'03_Activos'!O5) | C28: Trae las compras e incrementos del año informados en la hoja 03 (Activos biológicos: clasificación y datos); si están en blanco, cuenta cero. | D28: Fila 1: IF(6.000,00=""; 0; 6.000,00) → 6.000,00 | E28: hoja «Activos biológicos: clasificación y datos» | F28: —
A29: Disminuciones | B29: '=IF('03_Activos'!P5="",0,'03_Activos'!P5) | C29: Trae las disminuciones del año (ventas, cosecha, depreciación) informadas en la hoja 03 (Activos biológicos: clasificación y datos); en blanco cuenta cero. | D29: Fila 1: IF(4.500,00=""; 0; 4.500,00) → 4.500,00 | E29: hoja «Activos biológicos: clasificación y datos» | F29: —
... A33: No reconocido | B33: '=IF(OR(N5="",O5=""),"",N5-O5) | C33: Resta la ganancia registrada a la recalculada: positivo es ganancia no reconocida, negativo exceso reconocido; en blanco si falta alguna. | D33: Fila 1: IF(OR(15.180,00=""; 18.300,00=""); ""; 15.180,00-18.300,00) → -3.120,00 | E33: «Ganancia recalculada» (esta hoja), «Ganancia registrada» (esta hoja) | F33: —

Sheet 07_Conciliacion
A1: Conciliación de cambios (NIC 41.50) | H1: ⟵ Inicio | I1: ◀ Anterior | J1: Siguiente ▶
A2: Activos biológicos y agricultura · Cliente de muestra S.A. · corte 2025-12-31
A4: Lote | B4: Categoría | C4: Libros al inicio | D4: (+) Compras e incrementos | E4: (−) Disminuciones | F4: (+) Ganancia VR registrada | G4: Saldo final calculado | H4: Saldo final en libros | I4: Diferencia
A5: G-01 | B5: Ganado lechero | C5: =IF('03_Activos'!N5="","",'03_Activos'!N5) | D5: =IF('03_Activos'!O5="",0,'03_Activos'!O5) | E5: =IF('03_Activos'!P5="",0,'03_Activos'!P5) | F5: =IF('03_Activos'!Q5="","",'03_Activos'!Q5) | G5: =IF(C5="","",C5+D5-E5+IF(F5="",0,F5)) | H5: ='03_Activos'!M5 | I5: =IF(G5="","",H5-G5)
A6: G-02 | B6: Ganado de engorde | C6: =IF('03_Activos'!N6="","",'03_Activos'!N6) | D6: =IF('03_Activos'!O6="",0,'03_Activos'!O6) | E6: =IF('03_Activos'!P6="",0,'03_Activos'!P6) | F6: =IF('03_Activos'!Q6="","",'03_Activos'!Q6) | G6: =IF(C6="","",C6+D6-E6+IF(F6="",0,F6)) | H6: ='03_Activos'!M6 | I6: =IF(G6="","",H6-G6)
A7: P-01 | B7: Plantación de teca | C7: =IF('03_Activos'!N7="","",'03_Activos'!N7) | D7: =IF('03_Activos'!O7="",0,'03_Activos'!O7) | E7: =IF('03_Activos'!P7="",0,'03_Activos'!P7) | F7: =IF('03_Activos'!Q7="","",'03_Activos'!Q7) | G7: =IF(C7="","",C7+D7-E7+IF(F7="",0,F7)) | H7: ='03_Activos'!M7 | I7: =IF(G7="","",H7-G7)
A8: C-01 | B8: Camarón en piscinas | C8: =IF('03_Activos'!N8="","",'03_Activos'!N8) | D8: =IF('03_Activos'!O8="",0,'03_Activos'!O8) | E8: =IF('03_Activos'!P8="",0,'03_Activos'!P8) | F8: =IF('03_Activos'!Q8="","",'03_Activos'!Q8) | G8: =IF(C8="","",C8+D8-E8+IF(F8="",0,F8)) | H8: ='03_Activos'!M8 | I8: =IF(G8="","",H8-G8)
A9: F-01 | B9: Rosales en producción | C9: =IF('03_Activos'!N9="","",'03_Activos'!N9) | D9: =IF('03_Activos'!O9="",0,'03_Activos'!O9) | E9: =IF('03_Activos'!P9="",0,'03_Activos'!P9) | F9: =IF('03_Activos'!Q9="","",'03_Activos'!Q9) | G9: =IF(C9="","",C9+D9-E9+IF(F9="",0,F9)) | H9: ='03_Activos'!M9 | I9: =IF(G9="","",H9-G9)
A10: F-02 | B10: Botones de rosa en crecimiento | C10: =IF('03_Activos'!N10="","",'03_Activos'!N10) | D10: =IF('03_Activos'!O10="",0,'03_Activos'!O10) | E10: =IF('03_Activos'!P10="",0,'03_Activos'!P10) | F10: =IF('03_Activos'!Q10="","",'03_Activos'!Q10) | G10: =IF(C10="","",C10+D10-E10+IF(F10="",0,F10)) | H10: ='03_Activos'!M10 | I10: =IF(G10="","",H10-G10)
A11: G-03 | B11: Toros reproductores importados | C11: =IF('03_Activos'!N11="","",'03_Activos'!N11) | D11: =IF('03_Activos'!O11="",0,'03_Activos'!O11) | E11: =IF('03_Activos'!P11="",0,'03_Activos'!P11) | F11: =IF('03_Activos'!Q11="","",'03_Activos'!Q11) | G11: =IF(C11="","",C11+D11-E11+IF(F11="",0,F11)) | H11: ='03_Activos'!M11 | I11: =IF(G11="","",H11-G11)
A12: G-04 | B12: Cerdos de engorde | C12: =IF('03_Activos'!N12="","",'03_Activos'!N12) | D12: =IF('03_Activos'!O12="",0,'03_Activos'!O12) | E12: =IF('03_Activos'!P12="",0,'03_Activos'!P12) | F12: =IF('03_Activos'!Q12="","",'03_Activos'!Q12) | G12: =IF(C12="","",C12+D12-E12+IF(F12="",0,F12)) | H12: ='03_Activos'!M12 | I12: =IF(G12="","",H12-G12)
A13: P-02 | B13: Cultivo de maíz | C13: =IF('03_Activos'!N13="","",'03_Activos'!N13) | D13: =IF('03_Activos'!O13="",0,'03_Activos'!O13) | E13: =IF('03_Activos'!P13="",0,'03_Activos'!P13) | F13: =IF('03_Activos'!Q13="","",'03_Activos'!Q13) | G13: =IF(C13="","",C13+D13-E13+IF(F13="",0,F13)) | H13: ='03_Activos'!M13 | I13: =IF(G13="","",H13-G13)
A14: C-02 | B14: Tilapia en estanques | C14: =IF('03_Activos'!N14="","",'03_Activos'!N14) | D14: =IF('03_Activos'!O14="",0,'03_Activos'!O14) | E14: =IF('03_Activos'!P14="",0,'03_Activos'!P14) | F14: =IF('03_Activos'!Q14="","",'03_Activos'!Q14) | G14: =IF(C14="","",C14+D14-E14+IF(F14="",0,F14)) | H14: ='03_Activos'!M14 | I14: =IF(G14="","",H14-G14)
A15: TOTAL | C15: =SUM(C5:C14) | D15: =SUM(D5:D14) | E15: =SUM(E5:E14) | F15: =SUM(F5:F14) | G15: =SUM(G5:G14) | H15: =SUM(H5:H14) | I15: =SUM(I5:I14)
A17: ⓘ Cómo se calcula esta hoja
A18: Columna | B18: Fórmula (Excel) | C18: Cómo se calcula (sencillo) | D18: Ejemplo con números reales | E18: De dónde viene | F18: Norma
A19: Libros al inicio | B19: '=IF('03_Activos'!N5="","",'03_Activos'!N5) | C19: Trae el saldo del lote al inicio del ejercicio, tal como lo informó el cliente en la hoja 03 (Activos biológicos: clasificación y datos). | D19: Fila 1: IF(175.200,00=""; ""; 175.200,00) → 175.200,00 | E19: hoja «Activos biológicos: clasificación y datos» | F19: —
A20: (+) Compras e incrementos | B20: '=IF('03_Activos'!O5="",0,'03_Activos'!O5) | C20: Trae las compras e incrementos del año de la hoja 03 (Activos biológicos: clasificación y datos); en blanco se toma como cero. | D20: Fila 1: IF(6.000,00=""; 0; 6.000,00) → 6.000,00 | E20: hoja «Activos biológicos: clasificación y datos» | F20: —
A21: (−) Disminuciones | B21: '=IF('03_Activos'!P5="",0,'03_Activos'!P5) | C21: Trae las disminuciones del año al valor en libros (ventas, cosecha, depreciación) de la hoja 03 (Activos biológicos: clasificación y datos); en blanco, cero. | D21: Fila 1: IF(4.500,00=""; 0; 4.500,00) → 4.500,00 | E21: hoja «Activos biológicos: clasificación y datos» | F21: —
A22: (+) Ganancia VR registrada | B22: '=IF('03_Activos'!Q5="","",'03_Activos'!Q5) | C22: Trae la ganancia por cambio de valor razonable registrada por el cliente en la hoja 03 (Activos biológicos: clasificación y datos). | D22: Fila 1: IF(18.300,00=""; ""; 18.300,00) → 18.300,00 | E22: hoja «Activos biológicos: clasificación y datos» | F22: —
A23: Saldo final calculado | B23: '=IF(C5="","",C5+D5-E5+IF(F5="",0,F5)) | C23: Suma libros al inicio y compras, resta disminuciones y suma la ganancia registrada (cero si está en blanco); si no hay saldo inicial, queda en blanco. | D23: Fila 1: IF(175.200,00=""; ""; 175.200,00+6.000,00-4.500,00+IF(18.300,00=""; 0; 18.300,00)) → 195.000,00 | E23: «Libros al inicio» (esta hoja), «(+) Compras e incrementos» (esta hoja), «(−) Disminuciones» (esta hoja), «(+) Ganancia VR registrada» (esta hoja) | F23: —
A24: Saldo final en libros | B24: '='03_Activos'!M5 | C24: Trae el valor en libros del lote al corte registrado por el cliente en la hoja 03 (Activos biológicos: clasificación y datos). | D24: Fila 1: 195.000,00 → 195.000,00 | E24: hoja «Activos biológicos: clasificación y datos» | F24: —
A25: Diferencia | B25: '=IF(G5="","",H5-G5) | C25: Resta el saldo final calculado al saldo en libros: distinto de cero indica que el movimiento del año no explica el saldo; en blanco sin saldo calculado. | D25: Fila 1: IF(195.000,00=""; ""; 195.000,00-195.000,00) → 0,00 | E25: «Saldo final calculado» (esta hoja), «Saldo final en libros» (esta hoja) | F25: —

Sheet 08_Modelo_costo
A1: Modelo del costo y deterioro | H1: ⟵ Inicio | I1: ◀ Anterior | J1: Siguiente ▶
A2: Activos biológicos y agricultura · Cliente de muestra S.A. · corte 2025-12-31
A4: Lote | B4: Modelo auditado | C4: Costo acumulado | D4: Depreciación acumulada | E4: Deterioro registrado | F4: Valor neto al costo | G4: Importe recuperable | H4: Deterioro adicional | I4: Valor auditado al costo
A5: G-01 | B5: ='03_Activos'!W5 | C5: =IF('03_Activos'!R5="","",'03_Activos'!R5) | D5: =IF('03_Activos'!S5="","",'03_Activos'!S5) | E5: =IF('03_Activos'!T5="","",'03_Activos'!T5) | F5: =IF(OR(B5<>"Costo",C5=""),"",C5-IF(D5="",0,D5)-IF(E5="",0,E5)) | G5: =IF('03_Activos'!U5="","",'03_Activos'!U5) | H5: =IF(OR(F5="",G5=""),"",MAX(0,F5-G5)) | I5: =IF(F5="","",F5-IF(H5="",0,H5))
A6: G-02 | B6: ='03_Activos'!W6 | C6: =IF('03_Activos'!R6="","",'03_Activos'!R6) | D6: =IF('03_Activos'!S6="","",'03_Activos'!S6) | E6: =IF('03_Activos'!T6="","",'03_Activos'!T6) | F6: =IF(OR(B6<>"Costo",C6=""),"",C6-IF(D6="",0,D6)-IF(E6="",0,E6)) | G6: =IF('03_Activos'!U6="","",'03_Activos'!U6) | H6: =IF(OR(F6="",G6=""),"",MAX(0,F6-G6)) | I6: =IF(F6="","",F6-IF(H6="",0,H6))
A7: P-01 | B7: ='03_Activos'!W7 | C7: =IF('03_Activos'!R7="","",'03_Activos'!R7) | D7: =IF('03_Activos'!S7="","",'03_Activos'!S7) | E7: =IF('03_Activos'!T7="","",'03_Activos'!T7) | F7: =IF(OR(B7<>"Costo",C7=""),"",C7-IF(D7="",0,D7)-IF(E7="",0,E7)) | G7: =IF('03_Activos'!U7="","",'03_Activos'!U7) | H7: =IF(OR(F7="",G7=""),"",MAX(0,F7-G7)) | I7: =IF(F7="","",F7-IF(H7="",0,H7))
A8: C-01 | B8: ='03_Activos'!W8 | C8: =IF('03_Activos'!R8="","",'03_Activos'!R8) | D8: =IF('03_Activos'!S8="","",'03_Activos'!S8) | E8: =IF('03_Activos'!T8="","",'03_Activos'!T8) | F8: =IF(OR(B8<>"Costo",C8=""),"",C8-IF(D8="",0,D8)-IF(E8="",0,E8)) | G8: =IF('03_Activos'!U8="","",'03_Activos'!U8) | H8: =IF(OR(F8="",G8=""),"",MAX(0,F8-G8)) | I8: =IF(F8="","",F8-IF(H8="",0,H8))
A9: F-01 | B9: ='03_Activos'!W9 | C9: =IF('03_Activos'!R9="","",'03_Activos'!R9) | D9: =IF('03_Activos'!S9="","",'03_Activos'!S9) | E9: =IF('03_Activos'!T9="","",'03_Activos'!T9) | F9: =IF(OR(B9<>"Costo",C9=""),"",C9-IF(D9="",0,D9)-IF(E9="",0,E9)) | G9: =IF('03_Activos'!U9="","",'03_Activos'!U9) | H9: =IF(OR(F9="",G9=""),"",MAX(0,F9-G9)) | I9: =IF(F9="","",F9-IF(H9="",0,H9))
A10: F-02 | B10: ='03_Activos'!W10 | C10: =IF('03_Activos'!R10="","",'03_Activos'!R10) | D10: =IF('03_Activos'!S10="","",'03_Activos'!S10) | E10: =IF('03_Activos'!T10="","",'03_Activos'!T10) | F10: =IF(OR(B10<>"Costo",C10=""),"",C10-IF(D10="",0,D10)-IF(E10="",0,E10)) | G10: =IF('03_Activos'!U10="","",'03_Activos'!U10) | H10: =IF(OR(F10="",G10=""),"",MAX(0,F10-G10)) | I10: =IF(F10="","",F10-IF(H10="",0,H10))
A11: G-03 | B11: ='03_Activos'!W11 | C11: =IF('03_Activos'!R11="","",'03_Activos'!R11) | D11: =IF('03_Activos'!S11="","",'03_Activos'!S11) | E11: =IF('03_Activos'!T11="","",'03_Activos'!T11) | F11: =IF(OR(B11<>"Costo",C11=""),"",C11-IF(D11="",0,D11)-IF(E11="",0,E11)) | G11: =IF('03_Activos'!U11="","",'03_Activos'!U11) | H11: =IF(OR(F11="",G11=""),"",MAX(0,F11-G11)) | I11: =IF(F11="","",F11-IF(H11="",0,H11))
A12: G-04 | B12: ='03_Activos'!W12 | C12: =IF('03_Activos'!R12="","",'03_Activos'!R12) | D12: =IF('03_Activos'!S12="","",'03_Activos'!S12) | E12: =IF('03_Activos'!T12="","",'03_Activos'!T12) | F12: =IF(OR(B12<>"Costo",C12=""),"",C12-IF(D12="",0,D12)-IF(E12="",0,E12)) | G12: =IF('03_Activos'!U12="","",'03_Activos'!U12) | H12: =IF(OR(F12="",G12=""),"",MAX(0,F12-G12)) | I12: =IF(F12="","",F12-IF(H12="",0,H12))
A13: P-02 | B13: ='03_Activos'!W13 | C13: =IF('03_Activos'!R13="","",'03_Activos'!R13) | D13: =IF('03_Activos'!S13="","",'03_Activos'!S13) | E13: =IF('03_Activos'!T13="","",'03_Activos'!T13) | F13: =IF(OR(B13<>"Costo",C13=""),"",C13-IF(D13="",0,D13)-IF(E13="",0,E13)) | G13: =IF('03_Activos'!U13="","",'03_Activos'!U13) | H13: =IF(OR(F13="",G13=""),"",MAX(0,F13-G13)) | I13: =IF(F13="","",F13-IF(H13="",0,H13))
A14: C-02 | B14: ='03_Activos'!W14 | C14: =IF('03_Activos'!R14="","",'03_Activos'!R14) | D14: =IF('03_Activos'!S14="","",'03_Activos'!S14) | E14: =IF('03_Activos'!T14="","",'03_Activos'!T14) | F14: =IF(OR(B14<>"Costo",C14=""),"",C14-IF(D14="",0,D14)-IF(E14="",0,E14)) | G14: =IF('03_Activos'!U14="","",'03_Activos'!U14) | H14: =IF(OR(F14="",G14=""),"",MAX(0,F14-G14)) | I14: =IF(F14="","",F14-IF(H14="",0,H14))
A15: TOTAL | F15: =SUM(F5:F14) | H15: =SUM(H5:H14) | I15: =SUM(I5:I14)
A17: ⓘ Cómo se calcula esta hoja
A18: Columna | B18: Fórmula (Excel) | C18: Cómo se calcula (sencillo) | D18: Ejemplo con números reales | E18: De dónde viene | F18: Norma
A19: Modelo auditado | B19: '='03_Activos'!W5 | C19: Trae el modelo del lote desde la hoja 03 (Activos biológicos: clasificación y datos); esta hoja solo calcula los lotes medidos al costo. | D19: Fila 1: «Valor razonable» → Valor razonable | E19: hoja «Activos biológicos: clasificación y datos» | F19: —
A20: Costo acumulado | B20: '=IF('03_Activos'!R5="","",'03_Activos'!R5) | C20: Trae el costo acumulado del lote informado en la hoja 03 (Activos biológicos: clasificación y datos); en blanco si no se informó. | D20: Fila 1: IF((vacío)=""; ""; (vacío)) → (en blanco) | E20: hoja «Activos biológicos: clasificación y datos» | F20: —
A21: Depreciación acumulada | B21: '=IF('03_Activos'!S5="","",'03_Activos'!S5) | C21: Trae la depreciación acumulada del lote informada en la hoja 03 (Activos biológicos: clasificación y datos); en blanco si no se informó. | D21: Fila 1: IF((vacío)=""; ""; (vacío)) → (en blanco) | E21: hoja «Activos biológicos: clasificación y datos» | F21: —
A22: Deterioro registrado | B22: '=IF('03_Activos'!T5="","",'03_Activos'!T5) | C22: Trae el deterioro acumulado que registró el cliente para el lote en la hoja 03 (Activos biológicos: clasificación y datos); en blanco si falta. | D22: Fila 1: IF((vacío)=""; ""; (vacío)) → (en blanco) | E22: hoja «Activos biológicos: clasificación y datos» | F22: —
A23: Valor neto al costo | B23: '=IF(OR(B5<>"Costo",C5=""),"",C5-IF(D5="",0,D5)-IF(E5="",0,E5)) | C23: Para lotes al costo, resta al costo acumulado la depreciación y el deterioro registrados (cero si están en blanco); en otros modelos o sin costo, queda en blanco. | D23: Fila 1: IF(OR(«Valor razonable»<>"Costo"; (vacío)=""); ""; (vacío)-IF((vacío)=""; 0; (vacío))-IF((vacío)=""; 0; (vacío))) → (en blanco) | E23: «Modelo auditado» (esta hoja), «Costo acumulado» (esta hoja), «Depreciación acumulada» (esta hoja), «Deterioro registrado» (esta hoja) | F23: —
A24: Importe recuperable | B24: '=IF('03_Activos'!U5="","",'03_Activos'!U5) | C24: Trae el importe recuperable del lote informado en la hoja 03 (Activos biológicos: clasificación y datos); en blanco si no se informó. | D24: Fila 1: IF((vacío)=""; ""; (vacío)) → (en blanco) | E24: hoja «Activos biológicos: clasificación y datos» | F24: —
