Workbook

Sheet 00_Inicio
B2: AuditConsulting Auditores Cía. Ltda. · AUDIT-IA
B4: Arrendamientos
B6: Cliente | C6: Cliente de muestra S.A. | D6: RUC | E6: 1790000000001
B7: Marco contable | C7: NIIF completas | D7: Fecha de corte | E7: 2025-12-31
B8: Preparó | C8: Ejercicio modelo | D8: Revisó | E8: Pendiente
B10: INDICADORES CLAVE
B11: Ajuste propuesto al pasivo | C11: Problemas encontrados
B12: 87220.64 | C12: 25
B15: IR A LA CÉDULA
B16: Carátula | C16: Programa | D16: Base técnica | E16: Resumen
B17: Parámetros | C17: Universo de contratos | D17: Identificación, clasificación y exenciones | E17: Plazo y opciones
B18: Medición inicial: pasivo y activo | C18: Pago base, componente indexado y pagos variables | D18: Remedición y modificaciones | E18: Tabla de amortización
B19: Pasivo al corte: corriente y no corriente | C19: Depreciación y deterioro del activo | D19: Gasto lineal: exentos y operativos | E19: Venta con arrendamiento posterior: medición inicial
B20: Venta con arrendamiento posterior: medición posterior | C20: Conciliación y ajuste | D20: Problemas encontrados | E20: Conclusión
B21: Control de revisión
B23: PANORAMA | N23: Datos de los gráficos (fórmulas a las cédulas)
N24: Cifras del resumen | O24: Importe (USD)
N25: ='01_Resumen'!A5 | O25: ='01_Resumen'!B5
N26: ='01_Resumen'!A6 | O26: ='01_Resumen'!B6
N27: ='01_Resumen'!A7 | O27: ='01_Resumen'!B7
N28: ='01_Resumen'!A8 | O28: ='01_Resumen'!B8
N29: ='01_Resumen'!A9 | O29: ='01_Resumen'!B9
N30: ='01_Resumen'!A10 | O30: ='01_Resumen'!B10
N31: ='01_Resumen'!A11 | O31: ='01_Resumen'!B11
N32: ='01_Resumen'!A12 | O32: ='01_Resumen'!B12
N33: ='01_Resumen'!A13 | O33: ='01_Resumen'!B13
N34: ='01_Resumen'!A14 | O34: ='01_Resumen'!B14
N35: ='01_Resumen'!A15 | O35: ='01_Resumen'!B15
N36: ='01_Resumen'!A16 | O36: ='01_Resumen'!B16
... N38: ='01_Resumen'!A18 | O38: ='01_Resumen'!B18
N40: Hallazgos de mayor impacto | O40: Importe (USD)
N41: Venta ganancia | O41: =SUMIFS('16_Problemas'!$C$5:$C$29,'16_Problemas'!$A$5:$A$29,"VENTA_GANANCIA",'16_Problemas'!$C$5:$C$29,">0")-SUMIFS('16_Problemas'!$C$5:$C$29,'16_Problemas'!$A$5:$A$29,"VENTA_GANANCIA",'16_Problemas'!$C$5:$C$29,"<0")
N42: Activo diferencia (×6) | O42: =SUMIFS('16_Problemas'!$C$5:$C$29,'16_Problemas'!$A$5:$A$29,"ACTIVO_DIFERENCIA",'16_Problemas'!$C$5:$C$29,">0")-SUMIFS('16_Problemas'!$C$5:$C$29,'16_Problemas'!$A$5:$A$29,"ACTIVO_DIFERENCIA",'16_Problemas'!$C$5:$C$29,"<0")
N43: Pasivo diferencia (×5) | O43: =SUMIFS('16_Problemas'!$C$5:$C$29,'16_Problemas'!$A$5:$A$29,"PASIVO_DIFERENCIA",'16_Problemas'!$C$5:$C$29,">0")-SUMIFS('16_Problemas'!$C$5:$C$29,'16_Problemas'!$A$5:$A$29,"PASIVO_DIFERENCIA",'16_Problemas'!$C$5:$C$29,"<0")
N44: Deterioro | O44: =SUMIFS('16_Problemas'!$C$5:$C$29,'16_Problemas'!$A$5:$A$29,"DETERIORO",'16_Problemas'!$C$5:$C$29,">0")-SUMIFS('16_Problemas'!$C$5:$C$29,'16_Problemas'!$A$5:$A$29,"DETERIORO",'16_Problemas'!$C$5:$C$29,"<0")
N45: Bajo valor vehiculo | O45: =SUMIFS('16_Problemas'!$C$5:$C$29,'16_Problemas'!$A$5:$A$29,"BAJO_VALOR_VEHICULO",'16_Problemas'!$C$5:$C$29,">0")-SUMIFS('16_Problemas'!$C$5:$C$29,'16_Problemas'!$A$5:$A$29,"BAJO_VALOR_VEHICULO",'16_Problemas'!$C$5:$C$29,"<0")
N46: Exencion mal aplicada | O46: =SUMIFS('16_Problemas'!$C$5:$C$29,'16_Problemas'!$A$5:$A$29,"EXENCION_MAL_APLICADA",'16_Problemas'!$C$5:$C$29,">0")-SUMIFS('16_Problemas'!$C$5:$C$29,'16_Problemas'!$A$5:$A$29,"EXENCION_MAL_APLICADA",'16_Problemas'!$C$5:$C$29,"<0")
N47: Venta ganancia posterior | O47: =SUMIFS('16_Problemas'!$C$5:$C$29,'16_Problemas'!$A$5:$A$29,"VENTA_GANANCIA_POSTERIOR",'16_Problemas'!$C$5:$C$29,">0")-SUMIFS('16_Problemas'!$C$5:$C$29,'16_Problemas'!$A$5:$A$29,"VENTA_GANANCIA_POSTERIOR",'16_Problemas'!$C$5:$C$29,"<0")
N48: Otros (4 tipos) | O48: =SUMIF('16_Problemas'!$C$5:$C$29,">0")-SUMIF('16_Problemas'!$C$5:$C$29,"<0")-((SUMIFS('16_Problemas'!$C$5:$C$29,'16_Problemas'!$A$5:$A$29,"VENTA_GANANCIA",'16_Problemas'!$C$5:$C$29,">0")-SUMIFS('16_Problemas'!$C$5:$C$29,'16_Problemas'!$A$5:$A$29,"VENTA_GANANCIA",'16_Problemas'!$C$5:$C$29,"<0"))+(SUMIFS('16_Problemas'!$C$5:$C$29,'16_Problemas'!$A$5:$A$29,"ACTIVO_DIFERENCIA",'16_Problemas'!$C$5:$C$29,">0")-SUMIFS('16_Problemas'!$C$5:$C$29,'16_Problemas'!$A$5:$A$29,"ACTIVO_DIFERENCIA",'16_Problemas'!$C$5:$C$29,"<0"))+(SUMIFS('16_Problemas'!$C$5:$C$29,'16_Problemas'!$A$5:$A$29,"PASIVO_DIFERENCIA",'16_Problemas'!$C$5:$C$29,">0")-SUMIFS('16_Problemas'!$C$5:$C$29,'16_Problemas'!$A$5:$A$29,"PASIVO_DIFERENCIA",'16_Problemas'!$C$5:$C$29,"<0"))+(SUMIFS('16_Problemas'!$C$5:$C$29,'16_Problemas'!$A$5:$A$29,"DETERIORO",'16_Problemas'!$C$5:$C$29,">0")-SUMIFS('16_Problemas'!$C$5:$C$29,'16_Problemas'!$A$5:$A$29,"DETERIORO",'16_Problemas'!$C$5:$C$29,"<0"))+(SUMIFS('16_Problemas'!$C$5:$C$29,'16_Problemas'!$A$5:$A$29,"BAJO_VALOR_VEHICULO",'16_Problemas'!$C$5:$C$29,">0")-SUMIFS('16_Problemas'!$C$5:$C$29,'16_Problemas'!$A$5:$A$29,"BAJO_VALOR_VEHICULO",'16_Problemas'!$C$5:$C$29,"<0"))+(SUMIFS('16_Problemas'!$C$5:$C$29,'16_Problemas'!$A$5:$A$29,"EXENCION_MAL_APLICADA",'16_Problemas'!$C$5:$C$29,">0")-SUMIFS('16_Problemas'!$C$5:$C$29,'16_Problemas'!$A$5:$A$29,"EXENCION_MAL_APLICADA",'16_Problemas'!$C$5:$C$29,"<0"))+(SUMIFS('16_Problemas'!$C$5:$C$29,'16_Problemas'!$A$5:$A$29,"VENTA_GANANCIA_POSTERIOR",'16_Problemas'!$C$5:$C$29,">0")-SUMIFS('16_Problemas'!$C$5:$C$29,'16_Problemas'!$A$5:$A$29,"VENTA_GANANCIA_POSTERIOR",'16_Problemas'!$C$5:$C$29,"<0")))

Sheet 00_Caratula
A1: Carátula | H1: ⟵ Inicio | J1: Siguiente ▶
A2: Arrendamientos · Cliente de muestra S.A. · corte 2025-12-31
A4: Concepto | B4: Detalle
A5: Firma | B5: AuditConsulting Auditores Cía. Ltda.
A6: Cliente | B6: Cliente de muestra S.A.
A7: RUC | B7: 1790000000001
A8: Ejercicio | B8: 2025
A9: Fecha de corte | B9: 2025-12-31
A10: Marco contable | B10: NIIF completas
A11: Herramienta | B11: Arrendamientos
A12: Rubro | B12: Arrendamientos
A13: Motor | B13: arrendamientos 1.0
A14: Versión del papel | B14: v1
A15: Estado | B15: MUESTRA
... A17: Revisó | B17: Pendiente
A18: Aprobó
A19: Fecha de aprobación
A20: Huella de la ejecución (SHA-256)

Sheet 00_Programa
A1: Programa | H1: ⟵ Inicio | I1: ◀ Anterior | J1: Siguiente ▶
A2: Arrendamientos · Cliente de muestra S.A. · corte 2025-12-31
A4: Código | B4: Objetivo | C4: Afirmación | D4: Procedimiento | E4: Evidencia | F4: Criterio | G4: Referencia
A5: ARR-01 | B5: Integridad del universo de contratos | C5: Integridad | D5: Conciliar el anexo con el mayor; revisar contratos de servicios, actas y gastos de alquiler para identificar arrendamientos (9, B9–B31) | E5: Anexo de contratos, contratos firmados, mayor de gastos de alquiler | F5: Universo completo y conciliado | G5: NIIF 16 párr. 9 · NIA 500
A6: ARR-02 | B6: Exenciones y clasificación | C6: Presentación | D6: Evaluar plazo, opción de compra, valor del activo nuevo (B3) y las condiciones de B5 a B7 (uso independiente, no automóvil, sin subarriendo); en PYMES, los indicadores de 20.5 | E6: Contratos, cotizaciones del activo nuevo, contratos de subarriendo | F6: Tratamiento conforme a 5–8, B3–B8 / 20.4–20.8 | G6: NIIF 16 párr. 5–8, B3–B8 · Sección 20.4–20.8
A7: ARR-03 | B7: Plazo y opciones | C7: Valoración | D7: Evaluar incentivos económicos para renovar o comprar (mejoras, penalidades, importancia del activo) | E7: Contratos, presupuestos, historial de renovaciones | F7: Plazo conforme a 18–21 y B37 | G7: NIIF 16 párr. 18–21, 27 d, B34–B41
A8: ARR-04 | B8: Tasa de descuento | C8: Valoración | D8: Verificar la tasa implícita o la incremental con préstamos recientes y plazos comparables | E8: Contratos de préstamo, cotizaciones bancarias | F8: Tasa sustentada | G8: NIIF 16 párr. 26 · Sección 20.10 · NIA 540
A9: ARR-05 | B9: Medición del pasivo y del activo | C9: Valoración | D9: Recalcular VP, tabla de amortización, interés, depreciación y compararlos con lo registrado | E9: Cédulas 06, 08, 09 y 10 | F9: Diferencias cuantificadas | G9: NIIF 16 párr. 23–38 · Sección 20.9–20.12
A10: ARR-06 | B10: Presentación corriente / no corriente | C10: Presentación | D10: Recalcular el capital que se paga en los 12 meses siguientes al corte | E10: Tabla de amortización | F10: Clasificación conforme a NIC 1 párr. 69 | G10: NIIF 16 párr. 47 · NIC 1 párr. 69
A11: ARR-07 | B11: Modificaciones y remediciones | C11: Valoración | D11: Revisar adendas y cambios de índice; recalcular el pasivo remedido y el ajuste al derecho de uso | E11: Adendas, comunicaciones del arrendador | F11: Remedición conforme a 39–46 | G11: NIIF 16 párr. 39–46 · NIA 560
A12: ARR-08 | B12: Deterioro del activo | C12: Valoración | D12: Evaluar indicios y comparar el neto con el importe recuperable | E12: Evaluación de deterioro del cliente | F12: Deterioro reconocido | G12: NIIF 16 párr. 33 · NIC 36 · Sección 20.12 y 27
A13: ARR-09 | B13: Venta con arrendamiento posterior | C13: Ocurrencia | D13: Verificar que la transferencia es venta (NIIF 15), medir el derecho de uso conservado y la ganancia de los derechos transferidos | E13: Contrato de compraventa, tasación, contrato de arrendamiento | F13: Ganancia conforme a 99–103 / 20.32–20.34 | G13: NIIF 16 párr. 98–103 · Sección 20.32–20.34
A14: ARR-10 | B14: Pago base y componente ligado a un índice de inflación | C14: Valoración | D14: Separar en la factura o liquidación del período la renta base del reajuste por índice; comprobar que en NIIF completas el componente se midió con el índice de la fecha de comienzo y que en PYMES se cargó como gasto del período | E14: Facturas y liquidaciones de renta, cláusula de revisión del contrato, índice publicado (INEC u organismo oficial) | F14: Componente medido o expensado según el marco y revelado | G14: NIIF 16 párr. 27 b, 28, 38 b, 42 b y 43 · Sección 20.11, 20.13 c, 20.15 b y 20.16 c
A15: ARR-11 | B15: Medición posterior de la venta con arrendamiento posterior | C15: Valoración | D15: Recorrer el movimiento del pasivo (saldo inicial, interés, pagos fijos y variables, remedición, saldo final) y del derecho de uso conservado (costo, depreciación, neto); revisar los asientos posteriores a la venta que afecten resultados | E15: Mayor del pasivo y del derecho de uso, asientos de remedición, contrato de arrendamiento | F15: Sin ganancia ni pérdida sobre el derecho de uso conservado, salvo terminación (46 a) | G15: NIIF 16 párr. 102A, 29–35 y 36–46

Sheet 00_Fuentes
A1: Base técnica | H1: ⟵ Inicio | I1: ◀ Anterior | J1: Siguiente ▶
A2: Arrendamientos · Cliente de muestra S.A. · corte 2025-12-31
A4: Categoría | B4: Documento | C4: Párrafos | D4: URL | E4: Verificada
A5: NIA · NIA 540 (Revisada) | B5: Estimación contable: evaluar método (VP, tabla), datos (contratos) y supuestos (tasa incremental, plazo, opciones). | C5: párr. 13, 16–17, 18–27 y 28–30 (28: el recálculo del auditor es una estimación puntual propia; 30: NIA 500)
A6: NIA · NIA 500 | B6: Exactitud e integridad del anexo de contratos contra el mayor y los contratos firmados. | C6: párr. 9
A7: NIA · NIA 505 | B7: Confirmar con arrendadores condiciones y pagos cuando sea significativo. | C7: párr. 7 (decisión de confirmar: NIA 330 párr. 19)
A8: NIA · NIA 560 | B8: Modificaciones, renovaciones o terminaciones posteriores al cierre. | C8: párr. 6

Sheet 01_Resumen
A1: Resumen | H1: ⟵ Inicio | I1: ◀ Anterior | J1: Siguiente ▶
A2: Arrendamientos · Cliente de muestra S.A. · corte 2025-12-31
A4: Concepto | B4: Importe
A5: Pasivo por arrendamiento registrado (mayor) | B5: ='15_Conciliacion'!C16
A6: Pasivo por arrendamiento recalculado | B6: ='15_Conciliacion'!B16
A7: Ajuste propuesto al pasivo | B7: =B6-B5
A8: Pasivo corriente recalculado | B8: =SUM('10_Pasivo_corte'!O5:O15)
A9: Pasivo no corriente recalculado | B9: =SUM('10_Pasivo_corte'!P5:P15)
A10: Derecho de uso neto recalculado | B10: ='15_Conciliacion'!E16
A11: Activo registrado neto | B11: ='15_Conciliacion'!F16
A12: Ajuste propuesto al activo | B12: =B10-B11
A13: Depreciación del ejercicio | B13: ='15_Conciliacion'!H16
A14: Interés del ejercicio | B14: ='15_Conciliacion'!I16
A15: Deterioro del activo | B15: =SUM('11_Derecho_uso'!N5:N15)
A16: Gasto lineal (exentos / operativos) | B16: =SUM('12_Gasto_lineal'!F5:F15)
A17: Gasto del ejercicio por pagos variables (38 b / 20.11 y 20.15 b) | B17: =SUM('07_Pagos_variables'!L5:L15)
A18: Remedición del pasivo | B18: =SUM('08_Remedicion'!L5:L15)
A20: ⓘ Cómo se calcula esta hoja
A21: Columna | B21: Fórmula (Excel) | C21: Cómo se calcula (sencillo) | D21: Ejemplo con números reales | E21: De dónde viene | F21: Norma
A22: Importe | B22: '='15_Conciliacion'!C16 | C22: Trae cada importe de su hoja de origen, concepto por concepto: pasivo, activo, depreciación e interés de la fila TOTAL de la hoja 15 (Conciliación y ajuste); corriente y no corriente de la hoja 10; deterioro de la hoja 11; gasto lineal de la hoja 12; pagos variables de la hoja 07 y remedición de la hoja 08. Los ajustes son recalculado menos registrado. | D22: Fila 1: 1.594.538,08 → 1.594.538,08 | E22: hoja «Conciliación y ajuste» | F22: —

Sheet 02_Parametros
A1: Parámetros | H1: ⟵ Inicio | I1: ◀ Anterior | J1: Siguiente ▶
A2: Arrendamientos · Cliente de muestra S.A. · corte 2025-12-31
A4: Parámetro | B4: Valor | C4: Sustento
A5: Fecha de corte | B5: 46022 | C5: Ficha del encargo
A6: Tasa anual del contrato | B6: Efectiva anual | C6: Efectiva: (1 + r)^(meses/12) − 1 · Nominal: r × meses/12
A7: PYMES: plazo ≥ % de la vida económica | B7: 75 | C7: Indicador 20.5 c; umbral de juicio del auditor; la Sección 20 no fija porcentajes
A8: PYMES: VP de los pagos mínimos ≥ % del valor razonable | B8: 90 | C8: Indicador 20.5 d; umbral de juicio del auditor; la Sección 20 no fija porcentajes
A9: Límite de bajo valor del activo nuevo (USD) | B9: 5000 | C9: NIIF 16 B3–B8 no fija importe; el IASB pensó en activos de unos USD 5.000 o menos cuando son nuevos (Fundamentos BC100, no forman parte de la norma). Además de no pasar del límite, el bajo valor exige el valor del activo nuevo (B3), que el arrendatario pueda usarlo por sí solo o con recursos disponibles y que no dependa ni esté interrelacionado con otros activos (B5), que no sea un automóvil (coche nuevo, B6) y que no se subarriende (B7).
A10: Marco y ruta de cálculo | B10: NIIF completas · NIIF 16 (modelo único del arrendatario) | C10: NIIF 16 párr. 22–46

Sheet 03_Contratos
A1: Universo de contratos | H1: ⟵ Inicio | I1: ◀ Anterior | J1: Siguiente ▶
A2: Arrendamientos · Cliente de muestra S.A. · corte 2025-12-31
A4: Contrato | B4: Activo subyacente | C4: Fecha de comienzo | D4: Plazo no cancelable (meses) | E4: Meses de la opción de renovación | F4: Renovación razonablemente cierta (sí/no) | G4: Plazo usado por el cliente (meses) | H4: Pago periódico total del contrato (incluye el componente indexado) | I4: Periodicidad (mensual/trimestral/semestral/anual) | J4: Pago al inicio o al final del período | K4: El pago se ajusta por un índice de inflación (sí/no) | L4: Componente del pago ligado al índice (importe por período) | M4: Índice o referencia del ajuste | N4: Pago variable del período no ligado a un índice | O4: Tasa anual (%) | P4: Tipo de tasa (implícita/incremental) | Q4: Pagos anticipados antes del comienzo | R4: Costos directos iniciales | S4: Costo estimado de desmantelamiento | T4: Incentivos recibidos | U4: Precio de la opción de compra | V4: Compra razonablemente cierta (sí/no) | W4: Vida útil del activo (meses) | X4: Valor razonable del activo (nuevo) | Y4: Activo de bajo valor (sí/no) | Z4: Bajo valor: se usa por sí solo, no depende de otros activos y no se subarrienda (B5, B7) (sí/no) | AA4: El cliente aplicó la exención (sí/no) | AB4: Clasificación PYMES del cliente (financiero/operativo) | AC4: Pasivo por arrendamiento registrado al corte | AD4: Pasivo corriente registrado | AE4: Derecho de uso / activo registrado neto | AF4: Depreciación registrada del ejercicio | AG4: Interés registrado del ejercicio | AH4: Fecha de modificación o nueva evaluación | AI4: Tipo de evento (modificación/índice/plazo) | AJ4: Nuevo pago periódico | AK4: Tasa anual revisada (%) | AL4: Plazo total revisado (meses desde el comienzo) | AM4: El cliente remidió el pasivo (sí/no) | AN4: Importe recuperable del activo | AO4: Venta con arrendamiento posterior (sí/no) | AP4: Precio de venta | AQ4: Importe en libros antes de la venta | AR4: Ganancia registrada en la venta | AS4: Ganancia o pérdida reconocida después de la venta por la medición posterior del arrendamiento
A5: C-01 | B5: Local comercial matriz | C5: 45292 | D5: 36 | E5: 24 | F5: Sí | G5: 36 | H5: 1500 | I5: Mensual | J5: Final | O5: 12 | P5: Incremental | AB5: Operativo | AC5: 17000 | AD5: 17000 | AE5: 16500 | AG5: 2600
A6: C-02 | B6: Bodega norte | C6: 44927 | D6: 60 | H6: 10000 | I6: Anual | J6: Final | O6: 10 | P6: Incremental | R6: 500 | X6: 40000 | AB6: Operativo | AC6: 17355.37 | AD6: 10000 | AE6: 15363.15 | AF6: 7681.57 | AG6: 2486.85
A7: C-03 | B7: Vehículo de gerencia | C7: 45748 | D7: 36 | H7: 900 | I7: Mensual | J7: Inicio | O7: 11 | X7: 45000 | Y7: Sí | AA7: Sí | AB7: Operativo | AC7: 0 | AE7: 0
A8: C-04 | B8: Computadores portátiles | C8: 45658 | D8: 24 | H8: 80 | I8: Mensual | J8: Final | O8: 12 | X8: 1200 | Y8: Sí | AA8: Sí | AB8: Operativo | AC8: 0 | AE8: 0
A9: C-05 | B9: Parqueadero temporal | C9: 45839 | D9: 12 | H9: 300 | I9: Mensual | J9: Final | O9: 10 | AA9: Sí | AB9: Operativo | AC9: 0 | AE9: 0
A10: C-06 | B10: Montacargas con opción de compra | C10: 45474 | D10: 48 | H10: 6000 | I10: Trimestral | J10: Final | O10: 9 | P10: Implícita | U10: 5000 | V10: Sí | W10: 120 | X10: 85000 | AB10: Financiero | AC10: 57428.43 | AD10: 19626.9 | AE10: 71291.6 | AF10: 8387.25 | AG10: 5993.67
A11: C-07 | B11: Oficina sucursal | C11: 44927 | D11: 60 | H11: 12000 | I11: Anual | J11: Final | O11: 8 | AB11: Operativo | AC11: 19925.16 | AE11: 19165.01 | AG11: 2474.01 | AH11: 45658 | AI11: Modificación | AJ11: 13500 | AK11: 9 | AM11: No
A12: C-08 | B12: Edificio administrativo (venta con arrendamiento posterior) | C12: 45658 | D12: 216 | H12: 120000 | I12: Anual | J12: Final | O12: 4.5 | X12: 1800000 | AB12: Operativo | AC12: 1404863 | AE12: 660690.84 | AO12: Sí | AP12: 2000000 | AQ12: 1000000 | AR12: 800000 | AS12: 18500
A13: C-09 | B13: Local cerrado en centro comercial | C13: 45292 | D13: 60 | H13: 2500 | I13: Mensual | J13: Final | O13: 10 | AB13: Operativo | AC13: 77966.15 | AE13: 71307.75 | AN13: 50000
A14: C-10 | B14: Bodega sur con renta ajustada por inflación | C14: 45292 | D14: 36 | H14: 2000 | I14: Mensual | J14: Final | K14: Sí | L14: 200 | M14: IPC del INEC (Ecuador) | N14: 50 | O14: 12 | AB14: Operativo | AC14: 0 | AE14: 0
A15: C-11 | B15: Oficina regional con reajuste sin detalle | C15: 45658 | D15: 24 | H15: 1000 | I15: Mensual | J15: Final | K15: Sí | M15: Índice de precios del contrato | O15: 10 | AB15: Operativo | AC15: 0 | AE15: 0

Sheet 04_Identificacion
A1: Identificación, clasificación y exenciones | H1: ⟵ Inicio | I1: ◀ Anterior | J1: Siguiente ▶
A2: Arrendamientos · Cliente de muestra S.A. · corte 2025-12-31
A4: Contrato | B4: Activo | C4: Plazo (meses) | D4: Opción de compra | E4: Corto plazo (≤ 12 m, sin opción) | F4: Bajo valor declarado | G4: Valor del activo nuevo (B3) | H4: Automóvil (B6) | I4: Uso independiente y sin subarriendo (B5, B7) | J4: Bajo valor elegible (B3, B5–B7) | K4: Exención elegible (5) | L4: Exención aplicada por el cliente | M4: Reconoce pasivo | N4: Tipo de tasa (26)
A5: C-01 | B5: Local comercial matriz | C5: ='05_Plazo'!E5 | D5: =IF(N('03_Contratos'!U5)>0,"Sí","No") | E5: =IF(AND(C5<=12,D5="No"),"Sí","No") | F5: =IF('03_Contratos'!Y5="","No",'03_Contratos'!Y5) | G5: =IF('03_Contratos'!X5="","",'03_Contratos'!X5) | H5: =IF(OR(ISNUMBER(SEARCH("automovil",B5)),ISNUMBER(SEARCH("automóvil",B5)),ISNUMBER(SEARCH("vehiculo",B5)),ISNUMBER(SEARCH("vehículo",B5)),ISNUMBER(SEARCH("camioneta",B5)),ISNUMBER(SEARCH("coche",B5)),ISNUMBER(SEARCH("furgoneta",B5))),"Sí","No") | I5: =IF('03_Contratos'!Z5="","",'03_Contratos'!Z5) | J5: =IF(OR(F5="No",G5="",G5>'02_Parametros'!$B$9,H5="Sí",I5="No"),"No","Sí") | K5: =IF(OR(E5="Sí",J5="Sí"),"Sí","No") | L5: =IF('03_Contratos'!AA5="","No",'03_Contratos'!AA5) | M5: =IF(AND(L5="Sí",K5="Sí"),"No","Sí") | N5: =IF('03_Contratos'!P5="","",'03_Contratos'!P5)
A6: C-02 | B6: Bodega norte | C6: ='05_Plazo'!E6 | D6: =IF(N('03_Contratos'!U6)>0,"Sí","No") | E6: =IF(AND(C6<=12,D6="No"),"Sí","No") | F6: =IF('03_Contratos'!Y6="","No",'03_Contratos'!Y6) | G6: =IF('03_Contratos'!X6="","",'03_Contratos'!X6) | H6: =IF(OR(ISNUMBER(SEARCH("automovil",B6)),ISNUMBER(SEARCH("automóvil",B6)),ISNUMBER(SEARCH("vehiculo",B6)),ISNUMBER(SEARCH("vehículo",B6)),ISNUMBER(SEARCH("camioneta",B6)),ISNUMBER(SEARCH("coche",B6)),ISNUMBER(SEARCH("furgoneta",B6))),"Sí","No") | I6: =IF('03_Contratos'!Z6="","",'03_Contratos'!Z6) | J6: =IF(OR(F6="No",G6="",G6>'02_Parametros'!$B$9,H6="Sí",I6="No"),"No","Sí") | K6: =IF(OR(E6="Sí",J6="Sí"),"Sí","No") | L6: =IF('03_Contratos'!AA6="","No",'03_Contratos'!AA6) | M6: =IF(AND(L6="Sí",K6="Sí"),"No","Sí") | N6: =IF('03_Contratos'!P6="","",'03_Contratos'!P6)
A7: C-03 | B7: Vehículo de gerencia | C7: ='05_Plazo'!E7 | D7: =IF(N('03_Contratos'!U7)>0,"Sí","No") | E7: =IF(AND(C7<=12,D7="No"),"Sí","No") | F7: =IF('03_Contratos'!Y7="","No",'03_Contratos'!Y7) | G7: =IF('03_Contratos'!X7="","",'03_Contratos'!X7) | H7: =IF(OR(ISNUMBER(SEARCH("automovil",B7)),ISNUMBER(SEARCH("automóvil",B7)),ISNUMBER(SEARCH("vehiculo",B7)),ISNUMBER(SEARCH("vehículo",B7)),ISNUMBER(SEARCH("camioneta",B7)),ISNUMBER(SEARCH("coche",B7)),ISNUMBER(SEARCH("furgoneta",B7))),"Sí","No") | I7: =IF('03_Contratos'!Z7="","",'03_Contratos'!Z7) | J7: =IF(OR(F7="No",G7="",G7>'02_Parametros'!$B$9,H7="Sí",I7="No"),"No","Sí") | K7: =IF(OR(E7="Sí",J7="Sí"),"Sí","No") | L7: =IF('03_Contratos'!AA7="","No",'03_Contratos'!AA7) | M7: =IF(AND(L7="Sí",K7="Sí"),"No","Sí") | N7: =IF('03_Contratos'!P7="","",'03_Contratos'!P7)
A8: C-04 | B8: Computadores portátiles | C8: ='05_Plazo'!E8 | D8: =IF(N('03_Contratos'!U8)>0,"Sí","No") | E8: =IF(AND(C8<=12,D8="No"),"Sí","No") | F8: =IF('03_Contratos'!Y8="","No",'03_Contratos'!Y8) | G8: =IF('03_Contratos'!X8="","",'03_Contratos'!X8) | H8: =IF(OR(ISNUMBER(SEARCH("automovil",B8)),ISNUMBER(SEARCH("automóvil",B8)),ISNUMBER(SEARCH("vehiculo",B8)),ISNUMBER(SEARCH("vehículo",B8)),ISNUMBER(SEARCH("camioneta",B8)),ISNUMBER(SEARCH("coche",B8)),ISNUMBER(SEARCH("furgoneta",B8))),"Sí","No") | I8: =IF('03_Contratos'!Z8="","",'03_Contratos'!Z8) | J8: =IF(OR(F8="No",G8="",G8>'02_Parametros'!$B$9,H8="Sí",I8="No"),"No","Sí") | K8: =IF(OR(E8="Sí",J8="Sí"),"Sí","No") | L8: =IF('03_Contratos'!AA8="","No",'03_Contratos'!AA8) | M8: =IF(AND(L8="Sí",K8="Sí"),"No","Sí") | N8: =IF('03_Contratos'!P8="","",'03_Contratos'!P8)
A9: C-05 | B9: Parqueadero temporal | C9: ='05_Plazo'!E9 | D9: =IF(N('03_Contratos'!U9)>0,"Sí","No") | E9: =IF(AND(C9<=12,D9="No"),"Sí","No") | F9: =IF('03_Contratos'!Y9="","No",'03_Contratos'!Y9) | G9: =IF('03_Contratos'!X9="","",'03_Contratos'!X9) | H9: =IF(OR(ISNUMBER(SEARCH("automovil",B9)),ISNUMBER(SEARCH("automóvil",B9)),ISNUMBER(SEARCH("vehiculo",B9)),ISNUMBER(SEARCH("vehículo",B9)),ISNUMBER(SEARCH("camioneta",B9)),ISNUMBER(SEARCH("coche",B9)),ISNUMBER(SEARCH("furgoneta",B9))),"Sí","No") | I9: =IF('03_Contratos'!Z9="","",'03_Contratos'!Z9) | J9: =IF(OR(F9="No",G9="",G9>'02_Parametros'!$B$9,H9="Sí",I9="No"),"No","Sí") | K9: =IF(OR(E9="Sí",J9="Sí"),"Sí","No") | L9: =IF('03_Contratos'!AA9="","No",'03_Contratos'!AA9) | M9: =IF(AND(L9="Sí",K9="Sí"),"No","Sí") | N9: =IF('03_Contratos'!P9="","",'03_Contratos'!P9)
A10: C-06 | B10: Montacargas con opción de compra | C10: ='05_Plazo'!E10 | D10: =IF(N('03_Contratos'!U10)>0,"Sí","No") | E10: =IF(AND(C10<=12,D10="No"),"Sí","No") | F10: =IF('03_Contratos'!Y10="","No",'03_Contratos'!Y10) | G10: =IF('03_Contratos'!X10="","",'03_Contratos'!X10) | H10: =IF(OR(ISNUMBER(SEARCH("automovil",B10)),ISNUMBER(SEARCH("automóvil",B10)),ISNUMBER(SEARCH("vehiculo",B10)),ISNUMBER(SEARCH("vehículo",B10)),ISNUMBER(SEARCH("camioneta",B10)),ISNUMBER(SEARCH("coche",B10)),ISNUMBER(SEARCH("furgoneta",B10))),"Sí","No") | I10: =IF('03_Contratos'!Z10="","",'03_Contratos'!Z10) | J10: =IF(OR(F10="No",G10="",G10>'02_Parametros'!$B$9,H10="Sí",I10="No"),"No","Sí") | K10: =IF(OR(E10="Sí",J10="Sí"),"Sí","No") | L10: =IF('03_Contratos'!AA10="","No",'03_Contratos'!AA10) | M10: =IF(AND(L10="Sí",K10="Sí"),"No","Sí") | N10: =IF('03_Contratos'!P10="","",'03_Contratos'!P10)
A11: C-07 | B11: Oficina sucursal | C11: ='05_Plazo'!E11 | D11: =IF(N('03_Contratos'!U11)>0,"Sí","No") | E11: =IF(AND(C11<=12,D11="No"),"Sí","No") | F11: =IF('03_Contratos'!Y11="","No",'03_Contratos'!Y11) | G11: =IF('03_Contratos'!X11="","",'03_Contratos'!X11) | H11: =IF(OR(ISNUMBER(SEARCH("automovil",B11)),ISNUMBER(SEARCH("automóvil",B11)),ISNUMBER(SEARCH("vehiculo",B11)),ISNUMBER(SEARCH("vehículo",B11)),ISNUMBER(SEARCH("camioneta",B11)),ISNUMBER(SEARCH("coche",B11)),ISNUMBER(SEARCH("furgoneta",B11))),"Sí","No") | I11: =IF('03_Contratos'!Z11="","",'03_Contratos'!Z11) | J11: =IF(OR(F11="No",G11="",G11>'02_Parametros'!$B$9,H11="Sí",I11="No"),"No","Sí") | K11: =IF(OR(E11="Sí",J11="Sí"),"Sí","No") | L11: =IF('03_Contratos'!AA11="","No",'03_Contratos'!AA11) | M11: =IF(AND(L11="Sí",K11="Sí"),"No","Sí") | N11: =IF('03_Contratos'!P11="","",'03_Contratos'!P11)
A12: C-08 | B12: Edificio administrativo (venta con arrendamiento posterior) | C12: ='05_Plazo'!E12 | D12: =IF(N('03_Contratos'!U12)>0,"Sí","No") | E12: =IF(AND(C12<=12,D12="No"),"Sí","No") | F12: =IF('03_Contratos'!Y12="","No",'03_Contratos'!Y12) | G12: =IF('03_Contratos'!X12="","",'03_Contratos'!X12) | H12: =IF(OR(ISNUMBER(SEARCH("automovil",B12)),ISNUMBER(SEARCH("automóvil",B12)),ISNUMBER(SEARCH("vehiculo",B12)),ISNUMBER(SEARCH("vehículo",B12)),ISNUMBER(SEARCH("camioneta",B12)),ISNUMBER(SEARCH("coche",B12)),ISNUMBER(SEARCH("furgoneta",B12))),"Sí","No") | I12: =IF('03_Contratos'!Z12="","",'03_Contratos'!Z12) | J12: =IF(OR(F12="No",G12="",G12>'02_Parametros'!$B$9,H12="Sí",I12="No"),"No","Sí") | K12: =IF(OR(E12="Sí",J12="Sí"),"Sí","No") | L12: =IF('03_Contratos'!AA12="","No",'03_Contratos'!AA12) | M12: =IF(AND(L12="Sí",K12="Sí"),"No","Sí") | N12: =IF('03_Contratos'!P12="","",'03_Contratos'!P12)
A13: C-09 | B13: Local cerrado en centro comercial | C13: ='05_Plazo'!E13 | D13: =IF(N('03_Contratos'!U13)>0,"Sí","No") | E13: =IF(AND(C13<=12,D13="No"),"Sí","No") | F13: =IF('03_Contratos'!Y13="","No",'03_Contratos'!Y13) | G13: =IF('03_Contratos'!X13="","",'03_Contratos'!X13) | H13: =IF(OR(ISNUMBER(SEARCH("automovil",B13)),ISNUMBER(SEARCH("automóvil",B13)),ISNUMBER(SEARCH("vehiculo",B13)),ISNUMBER(SEARCH("vehículo",B13)),ISNUMBER(SEARCH("camioneta",B13)),ISNUMBER(SEARCH("coche",B13)),ISNUMBER(SEARCH("furgoneta",B13))),"Sí","No") | I13: =IF('03_Contratos'!Z13="","",'03_Contratos'!Z13) | J13: =IF(OR(F13="No",G13="",G13>'02_Parametros'!$B$9,H13="Sí",I13="No"),"No","Sí") | K13: =IF(OR(E13="Sí",J13="Sí"),"Sí","No") | L13: =IF('03_Contratos'!AA13="","No",'03_Contratos'!AA13) | M13: =IF(AND(L13="Sí",K13="Sí"),"No","Sí") | N13: =IF('03_Contratos'!P13="","",'03_Contratos'!P13)
A14: C-10 | B14: Bodega sur con renta ajustada por inflación | C14: ='05_Plazo'!E14 | D14: =IF(N('03_Contratos'!U14)>0,"Sí","No") | E14: =IF(AND(C14<=12,D14="No"),"Sí","No") | F14: =IF('03_Contratos'!Y14="","No",'03_Contratos'!Y14) | G14: =IF('03_Contratos'!X14="","",'03_Contratos'!X14) | H14: =IF(OR(ISNUMBER(SEARCH("automovil",B14)),ISNUMBER(SEARCH("automóvil",B14)),ISNUMBER(SEARCH("vehiculo",B14)),ISNUMBER(SEARCH("vehículo",B14)),ISNUMBER(SEARCH("camioneta",B14)),ISNUMBER(SEARCH("coche",B14)),ISNUMBER(SEARCH("furgoneta",B14))),"Sí","No") | I14: =IF('03_Contratos'!Z14="","",'03_Contratos'!Z14) | J14: =IF(OR(F14="No",G14="",G14>'02_Parametros'!$B$9,H14="Sí",I14="No"),"No","Sí") | K14: =IF(OR(E14="Sí",J14="Sí"),"Sí","No") | L14: =IF('03_Contratos'!AA14="","No",'03_Contratos'!AA14) | M14: =IF(AND(L14="Sí",K14="Sí"),"No","Sí") | N14: =IF('03_Contratos'!P14="","",'03_Contratos'!P14)
A15: C-11 | B15: Oficina regional con reajuste sin detalle | C15: ='05_Plazo'!E15 | D15: =IF(N('03_Contratos'!U15)>0,"Sí","No") | E15: =IF(AND(C15<=12,D15="No"),"Sí","No") | F15: =IF('03_Contratos'!Y15="","No",'03_Contratos'!Y15) | G15: =IF('03_Contratos'!X15="","",'03_Contratos'!X15) | H15: =IF(OR(ISNUMBER(SEARCH("automovil",B15)),ISNUMBER(SEARCH("automóvil",B15)),ISNUMBER(SEARCH("vehiculo",B15)),ISNUMBER(SEARCH("vehículo",B15)),ISNUMBER(SEARCH("camioneta",B15)),ISNUMBER(SEARCH("coche",B15)),ISNUMBER(SEARCH("furgoneta",B15))),"Sí","No") | I15: =IF('03_Contratos'!Z15="","",'03_Contratos'!Z15) | J15: =IF(OR(F15="No",G15="",G15>'02_Parametros'!$B$9,H15="Sí",I15="No"),"No","Sí") | K15: =IF(OR(E15="Sí",J15="Sí"),"Sí","No") | L15: =IF('03_Contratos'!AA15="","No",'03_Contratos'!AA15) | M15: =IF(AND(L15="Sí",K15="Sí"),"No","Sí") | N15: =IF('03_Contratos'!P15="","",'03_Contratos'!P15)
A17: ⓘ Cómo se calcula esta hoja
A18: Columna | B18: Fórmula (Excel) | C18: Cómo se calcula (sencillo) | D18: Ejemplo con números reales | E18: De dónde viene | F18: Norma
A19: Plazo (meses) | B19: '='05_Plazo'!E5 | C19: Trae el plazo del arrendamiento (plazo no cancelable más la renovación razonablemente cierta) calculado en la hoja 05 (Plazo y opciones). | D19: Fila 1: 60 → 60 | E19: hoja «Plazo y opciones» | F19: —
A20: Opción de compra | B20: '=IF(N('03_Contratos'!U5)>0,"Sí","No") | C20: Marca «Sí» si el contrato tiene un precio de opción de compra mayor que cero en la hoja 03 (Universo de contratos); si no, «No». | D20: Fila 1: IF(N((vacío))>0; "Sí"; "No") → No | E20: hoja «Universo de contratos» | F20: —
A21: Corto plazo (≤ 12 m, sin opción) | B21: '=IF(AND(C5<=12,D5="No"),"Sí","No") | C21: Marca «Sí» cuando el plazo del arrendamiento es de 12 meses o menos y el contrato no tiene opción de compra; de lo contrario, «No». | D21: Fila 1: IF(AND(60<=12; «No»="No"); "Sí"; "No") → No | E21: «Plazo (meses)» (esta hoja), «Opción de compra» (esta hoja) | F21: —
A22: Bajo valor declarado | B22: '=IF('03_Contratos'!Y5="","No",'03_Contratos'!Y5) | C22: Trae de la hoja 03 (Universo de contratos) si el cliente declaró el activo como de bajo valor; si no lo indicó, se toma «No». | D22: Fila 1: IF((vacío)=""; "No"; (vacío)) → No | E22: hoja «Universo de contratos» | F22: —
A23: Valor del activo nuevo (B3) | B23: '=IF('03_Contratos'!X5="","",'03_Contratos'!X5) | C23: Trae de la hoja 03 el valor del activo en estado nuevo; si falta queda en blanco y el contrato no puede calificar como de bajo valor. | D23: Fila 1: IF((vacío)=""; ""; (vacío)) → (en blanco) | E23: hoja «Universo de contratos» | F23: —
A24: Automóvil (B6) | B24: '=IF(OR(ISNUMBER(SEARCH("automovil",B5)),ISNUMBER(SEARCH("automóvil",B5)),ISNUMBER(SEARCH("vehiculo",B5)),ISNUMBER(SEARCH("vehículo",B5)),ISNUMBER(SEARCH("camioneta",B5)),ISNUMBER(SEARCH("coche",B5)),ISNUMBER(SEARCH("furgoneta",B5))),"Sí","No") | C24: Marca «Sí» si la descripción del activo contiene palabras como automóvil, vehículo, camioneta, coche o furgoneta; esos activos no califican como de bajo valor. | D24: Fila 1: IF(OR(ISNUMBER(SEARCH("automovil"; «Local comercial matriz»)); ISNUMBER(SEARCH("automóvil"; «Local comercial matriz»)); ISNUMBER(SEARCH("vehiculo"; «Local comercial matriz»)); ISNUMBER(SEARCH("vehículo"; «Local comercial matriz»)); ISNUMBER(SEARCH("camioneta"; «Local comercial matriz»)); ISNUMBER(SEARCH("coche"; «Local comercial matriz»)); ISNUMBER(SEARCH("furgoneta"; «Local comercial matriz»))); "Sí"; "No") → No | E24: «Activo» (esta hoja) | F24: —
A25: Uso independiente y sin subarriendo (B5, B7) | B25: '=IF('03_Contratos'!Z5="","",'03_Contratos'!Z5) | C25: Trae la respuesta del cliente en la hoja 03 sobre si el activo se usa por sí solo, sin depender de otros activos, y no se subarrienda; en blanco si no respondió. | D25: Fila 1: IF((vacío)=""; ""; (vacío)) → (en blanco) | E25: hoja «Universo de contratos» | F25: —
A26: Bajo valor elegible (B3, B5–B7) | B26: '=IF(OR(F5="No",G5="",G5>'02_Parametros'!$B$9,H5="Sí",I5="No"),"No","Sí") | C26: Es «Sí» solo si el cliente lo declaró de bajo valor, informó el valor del activo nuevo, ese valor no pasa del límite de la hoja 02 (Parámetros), no es un automóvil y el uso independiente no es «No». | D26: Fila 1: IF(OR(«No»="No"; (vacío)=""; (vacío)>5.000,00; «No»="Sí"; (vacío)="No"); "No"; "Sí") → No | E26: «Bajo valor declarado» (esta hoja), «Valor del activo nuevo (B3)» (esta hoja), «Automóvil (B6)» (esta hoja), «Uso independiente y sin subarriendo (B5, B7)» (esta hoja), hoja «Parámetros» | F26: —
A27: Exención elegible (5) | B27: '=IF(OR(E5="Sí",J5="Sí"),"Sí","No") | C27: Marca «Sí» si el contrato califica como de corto plazo o como de bajo valor elegible; si no califica por ninguna de las dos vías, «No». | D27: Fila 1: IF(OR(«No»="Sí"; «No»="Sí"); "Sí"; "No") → No | E27: «Corto plazo (≤ 12 m, sin opción)» (esta hoja), «Bajo valor elegible (B3, B5–B7)» (esta hoja) | F27: —
A28: Exención aplicada por el cliente | B28: '=IF('03_Contratos'!AA5="","No",'03_Contratos'!AA5) | C28: Trae de la hoja 03 (Universo de contratos) si el cliente aplicó la exención y no reconoció el arrendamiento; si no lo indicó, se toma «No». | D28: Fila 1: IF((vacío)=""; "No"; (vacío)) → No | E28: hoja «Universo de contratos» | F28: —
A29: Reconoce pasivo | B29: '=IF(AND(L5="Sí",K5="Sí"),"No","Sí") | C29: Solo es «No» cuando el cliente aplicó la exención y además es elegible; en cualquier otro caso el contrato debe reconocerse en balance («Sí»). | D29: Fila 1: IF(AND(«No»="Sí"; «No»="Sí"); "No"; "Sí") → Sí | E29: «Exención aplicada por el cliente» (esta hoja), «Exención elegible (5)» (esta hoja) | F29: —
A30: Tipo de tasa (26) | B30: '=IF('03_Contratos'!P5="","",'03_Contratos'!P5) | C30: Trae de la hoja 03 (Universo de contratos) si la tasa del contrato es implícita o incremental; en blanco si no se informó. | D30: Fila 1: IF(«Incremental»=""; ""; «Incremental») → Incremental | E30: hoja «Universo de contratos» | F30: —

Sheet 05_Plazo
A1: Plazo y opciones | H1: ⟵ Inicio | I1: ◀ Anterior | J1: Siguiente ▶
A2: Arrendamientos · Cliente de muestra S.A. · corte 2025-12-31
A4: Contrato | B4: Plazo no cancelable (meses) | C4: Renovación razonablemente cierta | D4: Meses de renovación | E4: Plazo del arrendamiento (18) | F4: Plazo usado por el cliente | G4: Meses por período | H4: Períodos | I4: Meses transcurridos al corte | J4: Meses de depreciación (32 / 20.12)
A5: C-01 | B5: ='03_Contratos'!D5 | C5: =IF('03_Contratos'!F5="","",'03_Contratos'!F5) | D5: =N('03_Contratos'!E5) | E5: =B5+IF(C5="Sí",D5,0) | F5: =IF('03_Contratos'!G5="","",'03_Contratos'!G5) | G5: =IF('03_Contratos'!I5="Mensual",1,IF('03_Contratos'!I5="Trimestral",3,IF('03_Contratos'!I5="Semestral",6,12))) | H5: =E5/G5 | I5: =DATEDIF('03_Contratos'!C5,'02_Parametros'!$B$5+1,"m") | J5: =IF('03_Contratos'!V5="Sí",IF('03_Contratos'!W5="",E5,'03_Contratos'!W5),IF('03_Contratos'!W5="",E5,MIN(E5,'03_Contratos'!W5)))
A6: C-02 | B6: ='03_Contratos'!D6 | C6: =IF('03_Contratos'!F6="","",'03_Contratos'!F6) | D6: =N('03_Contratos'!E6) | E6: =B6+IF(C6="Sí",D6,0) | F6: =IF('03_Contratos'!G6="","",'03_Contratos'!G6) | G6: =IF('03_Contratos'!I6="Mensual",1,IF('03_Contratos'!I6="Trimestral",3,IF('03_Contratos'!I6="Semestral",6,12))) | H6: =E6/G6 | I6: =DATEDIF('03_Contratos'!C6,'02_Parametros'!$B$5+1,"m") | J6: =IF('03_Contratos'!V6="Sí",IF('03_Contratos'!W6="",E6,'03_Contratos'!W6),IF('03_Contratos'!W6="",E6,MIN(E6,'03_Contratos'!W6)))
A7: C-03 | B7: ='03_Contratos'!D7 | C7: =IF('03_Contratos'!F7="","",'03_Contratos'!F7) | D7: =N('03_Contratos'!E7) | E7: =B7+IF(C7="Sí",D7,0) | F7: =IF('03_Contratos'!G7="","",'03_Contratos'!G7) | G7: =IF('03_Contratos'!I7="Mensual",1,IF('03_Contratos'!I7="Trimestral",3,IF('03_Contratos'!I7="Semestral",6,12))) | H7: =E7/G7 | I7: =DATEDIF('03_Contratos'!C7,'02_Parametros'!$B$5+1,"m") | J7: =IF('03_Contratos'!V7="Sí",IF('03_Contratos'!W7="",E7,'03_Contratos'!W7),IF('03_Contratos'!W7="",E7,MIN(E7,'03_Contratos'!W7)))
A8: C-04 | B8: ='03_Contratos'!D8 | C8: =IF('03_Contratos'!F8="","",'03_Contratos'!F8) | D8: =N('03_Contratos'!E8) | E8: =B8+IF(C8="Sí",D8,0) | F8: =IF('03_Contratos'!G8="","",'03_Contratos'!G8) | G8: =IF('03_Contratos'!I8="Mensual",1,IF('03_Contratos'!I8="Trimestral",3,IF('03_Contratos'!I8="Semestral",6,12))) | H8: =E8/G8 | I8: =DATEDIF('03_Contratos'!C8,'02_Parametros'!$B$5+1,"m") | J8: =IF('03_Contratos'!V8="Sí",IF('03_Contratos'!W8="",E8,'03_Contratos'!W8),IF('03_Contratos'!W8="",E8,MIN(E8,'03_Contratos'!W8)))
A9: C-05 | B9: ='03_Contratos'!D9 | C9: =IF('03_Contratos'!F9="","",'03_Contratos'!F9) | D9: =N('03_Contratos'!E9) | E9: =B9+IF(C9="Sí",D9,0) | F9: =IF('03_Contratos'!G9="","",'03_Contratos'!G9) | G9: =IF('03_Contratos'!I9="Mensual",1,IF('03_Contratos'!I9="Trimestral",3,IF('03_Contratos'!I9="Semestral",6,12))) | H9: =E9/G9 | I9: =DATEDIF('03_Contratos'!C9,'02_Parametros'!$B$5+1,"m") | J9: =IF('03_Contratos'!V9="Sí",IF('03_Contratos'!W9="",E9,'03_Contratos'!W9),IF('03_Contratos'!W9="",E9,MIN(E9,'03_Contratos'!W9)))
A10: C-06 | B10: ='03_Contratos'!D10 | C10: =IF('03_Contratos'!F10="","",'03_Contratos'!F10) | D10: =N('03_Contratos'!E10) | E10: =B10+IF(C10="Sí",D10,0) | F10: =IF('03_Contratos'!G10="","",'03_Contratos'!G10) | G10: =IF('03_Contratos'!I10="Mensual",1,IF('03_Contratos'!I10="Trimestral",3,IF('03_Contratos'!I10="Semestral",6,12))) | H10: =E10/G10 | I10: =DATEDIF('03_Contratos'!C10,'02_Parametros'!$B$5+1,"m") | J10: =IF('03_Contratos'!V10="Sí",IF('03_Contratos'!W10="",E10,'03_Contratos'!W10),IF('03_Contratos'!W10="",E10,MIN(E10,'03_Contratos'!W10)))
A11: C-07 | B11: ='03_Contratos'!D11 | C11: =IF('03_Contratos'!F11="","",'03_Contratos'!F11) | D11: =N('03_Contratos'!E11) | E11: =B11+IF(C11="Sí",D11,0) | F11: =IF('03_Contratos'!G11="","",'03_Contratos'!G11) | G11: =IF('03_Contratos'!I11="Mensual",1,IF('03_Contratos'!I11="Trimestral",3,IF('03_Contratos'!I11="Semestral",6,12))) | H11: =E11/G11 | I11: =DATEDIF('03_Contratos'!C11,'02_Parametros'!$B$5+1,"m") | J11: =IF('03_Contratos'!V11="Sí",IF('03_Contratos'!W11="",E11,'03_Contratos'!W11),IF('03_Contratos'!W11="",E11,MIN(E11,'03_Contratos'!W11)))
A12: C-08 | B12: ='03_Contratos'!D12 | C12: =IF('03_Contratos'!F12="","",'03_Contratos'!F12) | D12: =N('03_Contratos'!E12) | E12: =B12+IF(C12="Sí",D12,0) | F12: =IF('03_Contratos'!G12="","",'03_Contratos'!G12) | G12: =IF('03_Contratos'!I12="Mensual",1,IF('03_Contratos'!I12="Trimestral",3,IF('03_Contratos'!I12="Semestral",6,12))) | H12: =E12/G12 | I12: =DATEDIF('03_Contratos'!C12,'02_Parametros'!$B$5+1,"m") | J12: =IF('03_Contratos'!V12="Sí",IF('03_Contratos'!W12="",E12,'03_Contratos'!W12),IF('03_Contratos'!W12="",E12,MIN(E12,'03_Contratos'!W12)))
A13: C-09 | B13: ='03_Contratos'!D13 | C13: =IF('03_Contratos'!F13="","",'03_Contratos'!F13) | D13: =N('03_Contratos'!E13) | E13: =B13+IF(C13="Sí",D13,0) | F13: =IF('03_Contratos'!G13="","",'03_Contratos'!G13) | G13: =IF('03_Contratos'!I13="Mensual",1,IF('03_Contratos'!I13="Trimestral",3,IF('03_Contratos'!I13="Semestral",6,12))) | H13: =E13/G13 | I13: =DATEDIF('03_Contratos'!C13,'02_Parametros'!$B$5+1,"m") | J13: =IF('03_Contratos'!V13="Sí",IF('03_Contratos'!W13="",E13,'03_Contratos'!W13),IF('03_Contratos'!W13="",E13,MIN(E13,'03_Contratos'!W13)))
A14: C-10 | B14: ='03_Contratos'!D14 | C14: =IF('03_Contratos'!F14="","",'03_Contratos'!F14) | D14: =N('03_Contratos'!E14) | E14: =B14+IF(C14="Sí",D14,0) | F14: =IF('03_Contratos'!G14="","",'03_Contratos'!G14) | G14: =IF('03_Contratos'!I14="Mensual",1,IF('03_Contratos'!I14="Trimestral",3,IF('03_Contratos'!I14="Semestral",6,12))) | H14: =E14/G14 | I14: =DATEDIF('03_Contratos'!C14,'02_Parametros'!$B$5+1,"m") | J14: =IF('03_Contratos'!V14="Sí",IF('03_Contratos'!W14="",E14,'03_Contratos'!W14),IF('03_Contratos'!W14="",E14,MIN(E14,'03_Contratos'!W14)))
A15: C-11 | B15: ='03_Contratos'!D15 | C15: =IF('03_Contratos'!F15="","",'03_Contratos'!F15) | D15: =N('03_Contratos'!E15) | E15: =B15+IF(C15="Sí",D15,0) | F15: =IF('03_Contratos'!G15="","",'03_Contratos'!G15) | G15: =IF('03_Contratos'!I15="Mensual",1,IF('03_Contratos'!I15="Trimestral",3,IF('03_Contratos'!I15="Semestral",6,12))) | H15: =E15/G15 | I15: =DATEDIF('03_Contratos'!C15,'02_Parametros'!$B$5+1,"m") | J15: =IF('03_Contratos'!V15="Sí",IF('03_Contratos'!W15="",E15,'03_Contratos'!W15),IF('03_Contratos'!W15="",E15,MIN(E15,'03_Contratos'!W15)))
A17: ⓘ Cómo se calcula esta hoja
A18: Columna | B18: Fórmula (Excel) | C18: Cómo se calcula (sencillo) | D18: Ejemplo con números reales | E18: De dónde viene | F18: Norma
A19: Plazo no cancelable (meses) | B19: '='03_Contratos'!D5 | C19: Trae el plazo no cancelable del contrato, en meses, de la hoja 03 (Universo de contratos). | D19: Fila 1: 36,00 → 36 | E19: hoja «Universo de contratos» | F19: —
A20: Renovación razonablemente cierta | B20: '=IF('03_Contratos'!F5="","",'03_Contratos'!F5) | C20: Trae de la hoja 03 (Universo de contratos) si es razonablemente cierto que se ejercerá la renovación; en blanco si no se informó. | D20: Fila 1: IF(«Sí»=""; ""; «Sí») → Sí | E20: hoja «Universo de contratos» | F20: —
A21: Meses de renovación | B21: '=N('03_Contratos'!E5) | C21: Trae los meses de la opción de renovación de la hoja 03 (Universo de contratos); si no hay dato, cuenta cero. | D21: Fila 1: N(24,00) → 24 | E21: hoja «Universo de contratos» | F21: —
A22: Plazo del arrendamiento (18) | B22: '=B5+IF(C5="Sí",D5,0) | C22: Suma al plazo no cancelable los meses de renovación solo cuando la renovación es razonablemente cierta («Sí»); si no, el plazo es solo el no cancelable. | D22: Fila 1: 36+IF(«Sí»="Sí"; 24; 0) → 60 | E22: «Plazo no cancelable (meses)» (esta hoja), «Renovación razonablemente cierta» (esta hoja), «Meses de renovación» (esta hoja) | F22: —
A23: Plazo usado por el cliente | B23: '=IF('03_Contratos'!G5="","",'03_Contratos'!G5) | C23: Trae de la hoja 03 (Universo de contratos) el plazo en meses que usó el cliente, para compararlo con el recalculado; en blanco si no se informó. | D23: Fila 1: IF(36,00=""; ""; 36,00) → 36 | E23: hoja «Universo de contratos» | F23: —
A24: Meses por período | B24: '=IF('03_Contratos'!I5="Mensual",1,IF('03_Contratos'!I5="Trimestral",3,IF('03_Contratos'!I5="Semestral",6,12))) | C24: Convierte la periodicidad de pago de la hoja 03 en meses: mensual 1, trimestral 3, semestral 6 y cualquier otra (anual) 12. | D24: Fila 1: IF(«Mensual»="Mensual"; 1; IF(«Mensual»="Trimestral"; 3; IF(«Mensual»="Semestral"; 6; 12))) → 1 | E24: hoja «Universo de contratos» | F24: —
A25: Períodos | B25: '=E5/G5 | C25: Divide el plazo del arrendamiento entre los meses por período: es el número de cuotas del contrato. | D25: Fila 1: 60/1 → 60 | E25: «Plazo del arrendamiento (18)» (esta hoja), «Meses por período» (esta hoja) | F25: —
A26: Meses transcurridos al corte | B26: '=DATEDIF('03_Contratos'!C5,'02_Parametros'!$B$5+1,"m") | C26: Cuenta los meses completos desde la fecha de comienzo (hoja 03) hasta el día siguiente a la fecha de corte de la hoja 02 (Parámetros). | D26: Fila 1: DATEDIF(«2024-01-01»; «2025-12-31»+1; "m") → 24 | E26: hoja «Universo de contratos», hoja «Parámetros» | F26: —
A27: Meses de depreciación (32 / 20.12) | B27: '=IF('03_Contratos'!V5="Sí",IF('03_Contratos'!W5="",E5,'03_Contratos'!W5),IF('03_Contratos'!W5="",E5,MIN(E5,'03_Contratos'!W5))) | C27: Si la compra es razonablemente cierta, usa la vida útil del activo (o el plazo si falta); si no, el menor entre el plazo del arrendamiento y la vida útil (o el plazo si no hay vida útil). | D27: Fila 1: IF((vacío)="Sí"; IF((vacío)=""; 60; (vacío)); IF((vacío)=""; 60; MIN(60; (vacío)))) → 60 | E27: «Plazo del arrendamiento (18)» (esta hoja), hoja «Universo de contratos» | F27: —

Sheet 06_Medicion_inicial
A1: Medición inicial: pasivo y activo | H1: ⟵ Inicio | I1: ◀ Anterior | J1: Siguiente ▶
A2: Arrendamientos · Cliente de muestra S.A. · corte 2025-12-31
A4: Contrato | B4: Tipo de tasa | C4: Tasa anual (%) | D4: Tasa periódica | E4: Pago al inicio (1) / al final (0) | F4: Opción de compra incluida (27 d) | G4: VP de los pagos | H4: Valor razonable | I4: Base de medición (26) | J4: Tasa usada en la tabla | K4: Pago en el comienzo | L4: Pasivo inicial | M4: Pagos anticipados | N4: Costos directos iniciales | O4: Desmantelamiento | P4: Incentivos | Q4: Derecho de uso (24)
A5: C-01 | B5: =IF('03_Contratos'!P5="","",'03_Contratos'!P5) | C5: ='03_Contratos'!O5 | D5: =IF('02_Parametros'!$B$6="Nominal anual",C5/100*'05_Plazo'!G5/12,(1+C5/100)^('05_Plazo'!G5/12)-1) | E5: =IF('03_Contratos'!J5="Inicio",1,0) | F5: =IF('03_Contratos'!V5="Sí",N('03_Contratos'!U5),0) | G5: =PV(D5,'05_Plazo'!H5,-'07_Pagos_variables'!G5,-F5,E5) | H5: =IF('03_Contratos'!X5="","",'03_Contratos'!X5) | I5: =G5 | J5: =D5 | K5: =E5*'07_Pagos_variables'!G5 | L5: =I5-K5 | M5: =N('03_Contratos'!Q5) | N5: =N('03_Contratos'!R5) | O5: =N('03_Contratos'!S5) | P5: =N('03_Contratos'!T5) | Q5: =L5+K5+M5+N5+O5-P5
A6: C-02 | B6: =IF('03_Contratos'!P6="","",'03_Contratos'!P6) | C6: ='03_Contratos'!O6 | D6: =IF('02_Parametros'!$B$6="Nominal anual",C6/100*'05_Plazo'!G6/12,(1+C6/100)^('05_Plazo'!G6/12)-1) | E6: =IF('03_Contratos'!J6="Inicio",1,0) | F6: =IF('03_Contratos'!V6="Sí",N('03_Contratos'!U6),0) | G6: =PV(D6,'05_Plazo'!H6,-'07_Pagos_variables'!G6,-F6,E6) | H6: =IF('03_Contratos'!X6="","",'03_Contratos'!X6) | I6: =G6 | J6: =D6 | K6: =E6*'07_Pagos_variables'!G6 | L6: =I6-K6 | M6: =N('03_Contratos'!Q6) | N6: =N('03_Contratos'!R6) | O6: =N('03_Contratos'!S6) | P6: =N('03_Contratos'!T6) | Q6: =L6+K6+M6+N6+O6-P6
A7: C-03 | B7: =IF('03_Contratos'!P7="","",'03_Contratos'!P7) | C7: ='03_Contratos'!O7 | D7: =IF('02_Parametros'!$B$6="Nominal anual",C7/100*'05_Plazo'!G7/12,(1+C7/100)^('05_Plazo'!G7/12)-1) | E7: =IF('03_Contratos'!J7="Inicio",1,0) | F7: =IF('03_Contratos'!V7="Sí",N('03_Contratos'!U7),0) | G7: =PV(D7,'05_Plazo'!H7,-'07_Pagos_variables'!G7,-F7,E7) | H7: =IF('03_Contratos'!X7="","",'03_Contratos'!X7) | I7: =G7 | J7: =D7 | K7: =E7*'07_Pagos_variables'!G7 | L7: =I7-K7 | M7: =N('03_Contratos'!Q7) | N7: =N('03_Contratos'!R7) | O7: =N('03_Contratos'!S7) | P7: =N('03_Contratos'!T7) | Q7: =L7+K7+M7+N7+O7-P7
A8: C-04 | B8: =IF('03_Contratos'!P8="","",'03_Contratos'!P8) | C8: ='03_Contratos'!O8 | D8: =IF('02_Parametros'!$B$6="Nominal anual",C8/100*'05_Plazo'!G8/12,(1+C8/100)^('05_Plazo'!G8/12)-1) | E8: =IF('03_Contratos'!J8="Inicio",1,0) | F8: =IF('03_Contratos'!V8="Sí",N('03_Contratos'!U8),0) | G8: =PV(D8,'05_Plazo'!H8,-'07_Pagos_variables'!G8,-F8,E8) | H8: =IF('03_Contratos'!X8="","",'03_Contratos'!X8) | I8: =G8 | J8: =D8 | K8: =E8*'07_Pagos_variables'!G8 | L8: =I8-K8 | M8: =N('03_Contratos'!Q8) | N8: =N('03_Contratos'!R8) | O8: =N('03_Contratos'!S8) | P8: =N('03_Contratos'!T8) | Q8: =L8+K8+M8+N8+O8-P8
A9: C-05 | B9: =IF('03_Contratos'!P9="","",'03_Contratos'!P9) | C9: ='03_Contratos'!O9 | D9: =IF('02_Parametros'!$B$6="Nominal anual",C9/100*'05_Plazo'!G9/12,(1+C9/100)^('05_Plazo'!G9/12)-1) | E9: =IF('03_Contratos'!J9="Inicio",1,0) | F9: =IF('03_Contratos'!V9="Sí",N('03_Contratos'!U9),0) | G9: =PV(D9,'05_Plazo'!H9,-'07_Pagos_variables'!G9,-F9,E9) | H9: =IF('03_Contratos'!X9="","",'03_Contratos'!X9) | I9: =G9 | J9: =D9 | K9: =E9*'07_Pagos_variables'!G9 | L9: =I9-K9 | M9: =N('03_Contratos'!Q9) | N9: =N('03_Contratos'!R9) | O9: =N('03_Contratos'!S9) | P9: =N('03_Contratos'!T9) | Q9: =L9+K9+M9+N9+O9-P9
A10: C-06 | B10: =IF('03_Contratos'!P10="","",'03_Contratos'!P10) | C10: ='03_Contratos'!O10 | D10: =IF('02_Parametros'!$B$6="Nominal anual",C10/100*'05_Plazo'!G10/12,(1+C10/100)^('05_Plazo'!G10/12)-1) | E10: =IF('03_Contratos'!J10="Inicio",1,0) | F10: =IF('03_Contratos'!V10="Sí",N('03_Contratos'!U10),0) | G10: =PV(D10,'05_Plazo'!H10,-'07_Pagos_variables'!G10,-F10,E10) | H10: =IF('03_Contratos'!X10="","",'03_Contratos'!X10) | I10: =G10 | J10: =D10 | K10: =E10*'07_Pagos_variables'!G10 | L10: =I10-K10 | M10: =N('03_Contratos'!Q10) | N10: =N('03_Contratos'!R10) | O10: =N('03_Contratos'!S10) | P10: =N('03_Contratos'!T10) | Q10: =L10+K10+M10+N10+O10-P10
A11: C-07 | B11: =IF('03_Contratos'!P11="","",'03_Contratos'!P11) | C11: ='03_Contratos'!O11 | D11: =IF('02_Parametros'!$B$6="Nominal anual",C11/100*'05_Plazo'!G11/12,(1+C11/100)^('05_Plazo'!G11/12)-1) | E11: =IF('03_Contratos'!J11="Inicio",1,0) | F11: =IF('03_Contratos'!V11="Sí",N('03_Contratos'!U11),0) | G11: =PV(D11,'05_Plazo'!H11,-'07_Pagos_variables'!G11,-F11,E11) | H11: =IF('03_Contratos'!X11="","",'03_Contratos'!X11) | I11: =G11 | J11: =D11 | K11: =E11*'07_Pagos_variables'!G11 | L11: =I11-K11 | M11: =N('03_Contratos'!Q11) | N11: =N('03_Contratos'!R11) | O11: =N('03_Contratos'!S11) | P11: =N('03_Contratos'!T11) | Q11: =L11+K11+M11+N11+O11-P11
A12: C-08 | B12: =IF('03_Contratos'!P12="","",'03_Contratos'!P12) | C12: ='03_Contratos'!O12 | D12: =IF('02_Parametros'!$B$6="Nominal anual",C12/100*'05_Plazo'!G12/12,(1+C12/100)^('05_Plazo'!G12/12)-1) | E12: =IF('03_Contratos'!J12="Inicio",1,0) | F12: =IF('03_Contratos'!V12="Sí",N('03_Contratos'!U12),0) | G12: =PV(D12,'05_Plazo'!H12,-'07_Pagos_variables'!G12,-F12,E12) | H12: =IF('03_Contratos'!X12="","",'03_Contratos'!X12) | I12: =G12 | J12: =D12 | K12: =E12*'07_Pagos_variables'!G12 | L12: =I12-K12 | M12: =N('03_Contratos'!Q12) | N12: =N('03_Contratos'!R12) | O12: =N('03_Contratos'!S12) | P12: =N('03_Contratos'!T12) | Q12: ='13_Venta_arr_posterior'!I12
A13: C-09 | B13: =IF('03_Contratos'!P13="","",'03_Contratos'!P13) | C13: ='03_Contratos'!O13 | D13: =IF('02_Parametros'!$B$6="Nominal anual",C13/100*'05_Plazo'!G13/12,(1+C13/100)^('05_Plazo'!G13/12)-1) | E13: =IF('03_Contratos'!J13="Inicio",1,0) | F13: =IF('03_Contratos'!V13="Sí",N('03_Contratos'!U13),0) | G13: =PV(D13,'05_Plazo'!H13,-'07_Pagos_variables'!G13,-F13,E13) | H13: =IF('03_Contratos'!X13="","",'03_Contratos'!X13) | I13: =G13 | J13: =D13 | K13: =E13*'07_Pagos_variables'!G13 | L13: =I13-K13 | M13: =N('03_Contratos'!Q13) | N13: =N('03_Contratos'!R13) | O13: =N('03_Contratos'!S13) | P13: =N('03_Contratos'!T13) | Q13: =L13+K13+M13+N13+O13-P13
A14: C-10 | B14: =IF('03_Contratos'!P14="","",'03_Contratos'!P14) | C14: ='03_Contratos'!O14 | D14: =IF('02_Parametros'!$B$6="Nominal anual",C14/100*'05_Plazo'!G14/12,(1+C14/100)^('05_Plazo'!G14/12)-1) | E14: =IF('03_Contratos'!J14="Inicio",1,0) | F14: =IF('03_Contratos'!V14="Sí",N('03_Contratos'!U14),0) | G14: =PV(D14,'05_Plazo'!H14,-'07_Pagos_variables'!G14,-F14,E14) | H14: =IF('03_Contratos'!X14="","",'03_Contratos'!X14) | I14: =G14 | J14: =D14 | K14: =E14*'07_Pagos_variables'!G14 | L14: =I14-K14 | M14: =N('03_Contratos'!Q14) | N14: =N('03_Contratos'!R14) | O14: =N('03_Contratos'!S14) | P14: =N('03_Contratos'!T14) | Q14: =L14+K14+M14+N14+O14-P14
A15: C-11 | B15: =IF('03_Contratos'!P15="","",'03_Contratos'!P15) | C15: ='03_Contratos'!O15 | D15: =IF('02_Parametros'!$B$6="Nominal anual",C15/100*'05_Plazo'!G15/12,(1+C15/100)^('05_Plazo'!G15/12)-1) | E15: =IF('03_Contratos'!J15="Inicio",1,0) | F15: =IF('03_Contratos'!V15="Sí",N('03_Contratos'!U15),0) | G15: =PV(D15,'05_Plazo'!H15,-'07_Pagos_variables'!G15,-F15,E15) | H15: =IF('03_Contratos'!X15="","",'03_Contratos'!X15) | I15: =G15 | J15: =D15 | K15: =E15*'07_Pagos_variables'!G15 | L15: =I15-K15 | M15: =N('03_Contratos'!Q15) | N15: =N('03_Contratos'!R15) | O15: =N('03_Contratos'!S15) | P15: =N('03_Contratos'!T15) | Q15: =L15+K15+M15+N15+O15-P15
A16: TOTAL | G16: =SUM(G5:G15) | L16: =SUM(L5:L15) | Q16: =SUM(Q5:Q15)
A18: ⓘ Cómo se calcula esta hoja
A19: Columna | B19: Fórmula (Excel) | C19: Cómo se calcula (sencillo) | D19: Ejemplo con números reales | E19: De dónde viene | F19: Norma
A20: Tipo de tasa | B20: '=IF('03_Contratos'!P5="","",'03_Contratos'!P5) | C20: Trae de la hoja 03 (Universo de contratos) si la tasa del contrato es implícita o incremental; en blanco si no se informó. | D20: Fila 1: IF(«Incremental»=""; ""; «Incremental») → Incremental | E20: hoja «Universo de contratos» | F20: —
A21: Tasa anual (%) | B21: '='03_Contratos'!O5 | C21: Trae la tasa anual del contrato, en porcentaje, de la hoja 03 (Universo de contratos). | D21: Fila 1: 12,00 → 12,00 | E21: hoja «Universo de contratos» | F21: —
A22: Tasa periódica | B22: '=IF('02_Parametros'!$B$6="Nominal anual",C5/100*'05_Plazo'!G5/12,(1+C5/100)^('05_Plazo'!G5/12)-1) | C22: Convierte la tasa anual en la tasa de cada período de pago con la convención de la hoja 02: nominal = tasa × meses ÷ 12; efectiva = (1 + tasa)^(meses ÷ 12) − 1, con los meses por período de la hoja 05. | D22: Fila 1: IF(«Efectiva anual»="Nominal anual"; 12,00/100*1/12; (1+12,00/100)^(1/12)-1) → 0,95 % | E22: «Tasa anual (%)» (esta hoja), hoja «Parámetros», hoja «Plazo y opciones» | F22: —
A23: Pago al inicio (1) / al final (0) | B23: '=IF('03_Contratos'!J5="Inicio",1,0) | C23: Pone 1 si el contrato se paga al inicio de cada período, según la hoja 03 (Universo de contratos), y 0 si se paga al final. | D23: Fila 1: IF(«Final»="Inicio"; 1; 0) → 0 | E23: hoja «Universo de contratos» | F23: —
A24: Opción de compra incluida (27 d) | B24: '=IF('03_Contratos'!V5="Sí",N('03_Contratos'!U5),0) | C24: Si la compra es razonablemente cierta, incluye el precio de la opción de compra de la hoja 03 (Universo de contratos); si no, pone 0. | D24: Fila 1: IF((vacío)="Sí"; N((vacío)); 0) → 0,00 | E24: hoja «Universo de contratos» | F24: —
A25: VP de los pagos | B25: '=PV(D5,'05_Plazo'!H5,-'07_Pagos_variables'!G5,-F5,E5) | C25: Descuenta con la tasa periódica (función VA de Excel) el pago usado en la medición (hoja 07) durante los períodos de la hoja 05, más la opción de compra incluida, según se pague al inicio o al final. | D25: Fila 1: PV(0,95 %; 60; -1.500,00; -0,00; 0) → 68.381,69 | E25: «Tasa periódica» (esta hoja), «Opción de compra incluida (27 d)» (esta hoja), «Pago al inicio (1) / al final (0)» (esta hoja), hoja «Plazo y opciones», hoja «Pago base, componente indexado y pagos variables» | F25: —
A26: Valor razonable | B26: '=IF('03_Contratos'!X5="","",'03_Contratos'!X5) | C26: Trae el valor razonable del activo de la hoja 03 (Universo de contratos); en blanco si no se informó. | D26: Fila 1: IF((vacío)=""; ""; (vacío)) → (en blanco) | E26: hoja «Universo de contratos» | F26: —
A27: Base de medición (26) | B27: '=G5 | C27: En NIIF completas la base de medición es directamente el VP de los pagos calculado en esta misma hoja. | D27: Fila 1: 68.381,69 → 68.381,69 | E27: «VP de los pagos» (esta hoja) | F27: —
A28: Tasa usada en la tabla | B28: '=D5 | C28: Es la misma tasa periódica del contrato; con ella se calcula el interés en la hoja 09 (Tabla de amortización). | D28: Fila 1: 0,95 % → 0,95 % | E28: «Tasa periódica» (esta hoja) | F28: —
A29: Pago en el comienzo | B29: '=E5*'07_Pagos_variables'!G5 | C29: Si el pago es al inicio del período, es el primer pago (el usado en la medición, hoja 07), que se paga el mismo día del comienzo; si es al final, es 0. | D29: Fila 1: 0*1.500,00 → 0,00 | E29: «Pago al inicio (1) / al final (0)» (esta hoja), hoja «Pago base, componente indexado y pagos variables» | F29: —
A30: Pasivo inicial | B30: '=I5-K5 | C30: Resta a la base de medición el pago hecho en el comienzo: es el pasivo que queda por pagar al inicio del contrato. | D30: Fila 1: 68.381,69-0,00 → 68.381,69 | E30: «Base de medición (26)» (esta hoja), «Pago en el comienzo» (esta hoja) | F30: —
... A35: Derecho de uso (24) | B35: '=L5+K5+M5+N5+O5-P5 | C35: Pasivo inicial + pago en el comienzo + pagos anticipados + costos directos + desmantelamiento − incentivos. En una venta con arrendamiento posterior que se reconoce, trae en su lugar el derecho de uso conservado de la hoja 13. | D35: Fila 1: 68.381,69+0,00+0,00+0,00+0,00-0,00 → 68.381,69 | E35: «Pasivo inicial» (esta hoja), «Pago en el comienzo» (esta hoja), «Pagos anticipados» (esta hoja), «Costos directos iniciales» (esta hoja), «Desmantelamiento» (esta hoja), «Incentivos» (esta hoja) | F35: —

Sheet 07_Pagos_variables
A1: Pago base, componente indexado y pagos variables | H1: ⟵ Inicio | I1: ◀ Anterior | J1: Siguiente ▶
A2: Arrendamientos · Cliente de muestra S.A. · corte 2025-12-31
A4: Contrato | B4: Pago periódico total del contrato | C4: Ligado a un índice de inflación | D4: Índice o referencia | E4: Componente ligado al índice | F4: Pago base | G4: Pago usado en la medición del pasivo | H4: Tratamiento del componente indexado | I4: Marco que lo manda | J4: Pago variable no ligado a un índice (38 b) | K4: Períodos del ejercicio | L4: Gasto del ejercicio por pagos variables
A5: C-01 | B5: ='03_Contratos'!H5 | C5: =IF(OR('03_Contratos'!K5="Sí",'03_Contratos'!L5<>""),"Sí","No") | D5: =IF('03_Contratos'!M5="","",'03_Contratos'!M5) | E5: =IF(C5="No",0,IF('03_Contratos'!L5="","",'03_Contratos'!L5)) | F5: =IF(E5="","",B5-E5) | G5: =B5 | H5: Sin componente ligado a un índice | J5: =IF('03_Contratos'!N5="","",'03_Contratos'!N5) | K5: ='10_Pasivo_corte'!E5-'10_Pasivo_corte'!F5 | L5: =N(J5)*K5
A6: C-02 | B6: ='03_Contratos'!H6 | C6: =IF(OR('03_Contratos'!K6="Sí",'03_Contratos'!L6<>""),"Sí","No") | D6: =IF('03_Contratos'!M6="","",'03_Contratos'!M6) | E6: =IF(C6="No",0,IF('03_Contratos'!L6="","",'03_Contratos'!L6)) | F6: =IF(E6="","",B6-E6) | G6: =B6 | H6: Sin componente ligado a un índice | J6: =IF('03_Contratos'!N6="","",'03_Contratos'!N6) | K6: ='10_Pasivo_corte'!E6-'10_Pasivo_corte'!F6 | L6: =N(J6)*K6
A7: C-03 | B7: ='03_Contratos'!H7 | C7: =IF(OR('03_Contratos'!K7="Sí",'03_Contratos'!L7<>""),"Sí","No") | D7: =IF('03_Contratos'!M7="","",'03_Contratos'!M7) | E7: =IF(C7="No",0,IF('03_Contratos'!L7="","",'03_Contratos'!L7)) | F7: =IF(E7="","",B7-E7) | G7: =B7 | H7: Sin componente ligado a un índice | J7: =IF('03_Contratos'!N7="","",'03_Contratos'!N7) | K7: ='10_Pasivo_corte'!E7-'10_Pasivo_corte'!F7 | L7: =N(J7)*K7
A8: C-04 | B8: ='03_Contratos'!H8 | C8: =IF(OR('03_Contratos'!K8="Sí",'03_Contratos'!L8<>""),"Sí","No") | D8: =IF('03_Contratos'!M8="","",'03_Contratos'!M8) | E8: =IF(C8="No",0,IF('03_Contratos'!L8="","",'03_Contratos'!L8)) | F8: =IF(E8="","",B8-E8) | G8: =B8 | H8: Sin componente ligado a un índice | J8: =IF('03_Contratos'!N8="","",'03_Contratos'!N8) | K8: ='12_Gasto_lineal'!E8/'05_Plazo'!G8 | L8: =N(J8)*K8
A9: C-05 | B9: ='03_Contratos'!H9 | C9: =IF(OR('03_Contratos'!K9="Sí",'03_Contratos'!L9<>""),"Sí","No") | D9: =IF('03_Contratos'!M9="","",'03_Contratos'!M9) | E9: =IF(C9="No",0,IF('03_Contratos'!L9="","",'03_Contratos'!L9)) | F9: =IF(E9="","",B9-E9) | G9: =B9 | H9: Sin componente ligado a un índice | J9: =IF('03_Contratos'!N9="","",'03_Contratos'!N9) | K9: ='12_Gasto_lineal'!E9/'05_Plazo'!G9 | L9: =N(J9)*K9
A10: C-06 | B10: ='03_Contratos'!H10 | C10: =IF(OR('03_Contratos'!K10="Sí",'03_Contratos'!L10<>""),"Sí","No") | D10: =IF('03_Contratos'!M10="","",'03_Contratos'!M10) | E10: =IF(C10="No",0,IF('03_Contratos'!L10="","",'03_Contratos'!L10)) | F10: =IF(E10="","",B10-E10) | G10: =B10 | H10: Sin componente ligado a un índice | J10: =IF('03_Contratos'!N10="","",'03_Contratos'!N10) | K10: ='10_Pasivo_corte'!E10-'10_Pasivo_corte'!F10 | L10: =N(J10)*K10
A11: C-07 | B11: ='03_Contratos'!H11 | C11: =IF(OR('03_Contratos'!K11="Sí",'03_Contratos'!L11<>""),"Sí","No") | D11: =IF('03_Contratos'!M11="","",'03_Contratos'!M11) | E11: =IF(C11="No",0,IF('03_Contratos'!L11="","",'03_Contratos'!L11)) | F11: =IF(E11="","",B11-E11) | G11: =B11 | H11: Sin componente ligado a un índice | J11: =IF('03_Contratos'!N11="","",'03_Contratos'!N11) | K11: ='10_Pasivo_corte'!E11-'10_Pasivo_corte'!F11 | L11: =N(J11)*K11
A12: C-08 | B12: ='03_Contratos'!H12 | C12: =IF(OR('03_Contratos'!K12="Sí",'03_Contratos'!L12<>""),"Sí","No") | D12: =IF('03_Contratos'!M12="","",'03_Contratos'!M12) | E12: =IF(C12="No",0,IF('03_Contratos'!L12="","",'03_Contratos'!L12)) | F12: =IF(E12="","",B12-E12) | G12: =B12 | H12: Sin componente ligado a un índice | J12: =IF('03_Contratos'!N12="","",'03_Contratos'!N12) | K12: ='10_Pasivo_corte'!E12-'10_Pasivo_corte'!F12 | L12: =N(J12)*K12
