Workbook

Sheet 00_Inicio
B2: AuditConsulting Auditores Cía. Ltda. · AUDIT-IA
B4: Gastos · análisis global, verificación del soporte, corte, devengo, clasificación y partes relacionadas
B6: Cliente | C6: Cliente de muestra S.A. | D6: RUC | E6: 1790000000001
B7: Marco contable | C7: NIIF completas | D7: Fecha de corte | E7: 2025-12-31
B8: Preparó | C8: Ejercicio modelo | D8: Revisó | E8: Pendiente
B10: INDICADORES CLAVE
B11: Ajuste propuesto al gasto (neto) | C11: Problemas encontrados
B12: -7075.8 | C12: 21
B15: IR A LA CÉDULA
B16: Carátula | C16: Programa | D16: Base técnica | E16: Resumen
B17: Parámetros | C17: Análisis global por cuenta (NIA 520) | D17: Presentación en el estado de resultados | E17: Transacciones de la muestra
B18: Verificación del soporte documental | C18: Corte de gastos | D18: Devengo y gastos anticipados | E18: Reclasificaciones
B19: Partes relacionadas | C19: Integridad de la revelación de partes relacionadas | D19: Partidas inusuales | E19: Referencia tributaria (Ecuador)
B20: Ajustes y conciliación | C20: Asientos propuestos | D20: Problemas encontrados | E20: Conclusión
B21: Control de revisión
B23: PANORAMA | N23: Datos de los gráficos (fórmulas a las cédulas)
N24: Cifras del resumen | O24: Importe (USD)
N25: ='01_Resumen'!A5 | O25: ='01_Resumen'!B5
N26: ='01_Resumen'!A6 | O26: ='01_Resumen'!B6
N27: ='01_Resumen'!A7 | O27: ='01_Resumen'!B7
N28: ='01_Resumen'!A8 | O28: ='01_Resumen'!B8
N29: ='01_Resumen'!A9 | O29: ='01_Resumen'!B9
N30: ='01_Resumen'!A10 | O30: ='01_Resumen'!B10
N31: ='01_Resumen'!A11 | O31: ='01_Resumen'!B11
N32: ='01_Resumen'!A12 | O32: ='01_Resumen'!B12
N33: ='01_Resumen'!A13 | O33: ='01_Resumen'!B13
N34: ='01_Resumen'!A14 | O34: ='01_Resumen'!B14
N35: ='01_Resumen'!A15 | O35: ='01_Resumen'!B15
N36: ='01_Resumen'!A16 | O36: ='01_Resumen'!B16
... N39: ='01_Resumen'!A19 | O39: ='01_Resumen'!B19
N41: Hallazgos de mayor impacto | O41: Importe (USD)
N42: Naturaleza no revelada | O42: =SUMIFS('16_Problemas'!$C$5:$C$25,'16_Problemas'!$A$5:$A$25,"NATURALEZA_NO_REVELADA",'16_Problemas'!$C$5:$C$25,">0")-SUMIFS('16_Problemas'!$C$5:$C$25,'16_Problemas'!$A$5:$A$25,"NATURALEZA_NO_REVELADA",'16_Problemas'!$C$5:$C$25,"<0")
N43: Variacion sin explicar (×2) | O43: =SUMIFS('16_Problemas'!$C$5:$C$25,'16_Problemas'!$A$5:$A$25,"VARIACION_SIN_EXPLICAR",'16_Problemas'!$C$5:$C$25,">0")-SUMIFS('16_Problemas'!$C$5:$C$25,'16_Problemas'!$A$5:$A$25,"VARIACION_SIN_EXPLICAR",'16_Problemas'!$C$5:$C$25,"<0")
N44: Partida inusual (×2) | O44: =SUMIFS('16_Problemas'!$C$5:$C$25,'16_Problemas'!$A$5:$A$25,"PARTIDA_INUSUAL",'16_Problemas'!$C$5:$C$25,">0")-SUMIFS('16_Problemas'!$C$5:$C$25,'16_Problemas'!$A$5:$A$25,"PARTIDA_INUSUAL",'16_Problemas'!$C$5:$C$25,"<0")
N45: Gasto no soportado | O45: =SUMIFS('16_Problemas'!$C$5:$C$25,'16_Problemas'!$A$5:$A$25,"GASTO_NO_SOPORTADO",'16_Problemas'!$C$5:$C$25,">0")-SUMIFS('16_Problemas'!$C$5:$C$25,'16_Problemas'!$A$5:$A$25,"GASTO_NO_SOPORTADO",'16_Problemas'!$C$5:$C$25,"<0")
N46: Gasto anticipado en resultados (×2) | O46: =SUMIFS('16_Problemas'!$C$5:$C$25,'16_Problemas'!$A$5:$A$25,"GASTO_ANTICIPADO_EN_RESULTADOS",'16_Problemas'!$C$5:$C$25,">0")-SUMIFS('16_Problemas'!$C$5:$C$25,'16_Problemas'!$A$5:$A$25,"GASTO_ANTICIPADO_EN_RESULTADOS",'16_Problemas'!$C$5:$C$25,"<0")
N47: Partida extraordinaria | O47: =SUMIFS('16_Problemas'!$C$5:$C$25,'16_Problemas'!$A$5:$A$25,"PARTIDA_EXTRAORDINARIA",'16_Problemas'!$C$5:$C$25,">0")-SUMIFS('16_Problemas'!$C$5:$C$25,'16_Problemas'!$A$5:$A$25,"PARTIDA_EXTRAORDINARIA",'16_Problemas'!$C$5:$C$25,"<0")
N48: Corte no registrado | O48: =SUMIFS('16_Problemas'!$C$5:$C$25,'16_Problemas'!$A$5:$A$25,"CORTE_NO_REGISTRADO",'16_Problemas'!$C$5:$C$25,">0")-SUMIFS('16_Problemas'!$C$5:$C$25,'16_Problemas'!$A$5:$A$25,"CORTE_NO_REGISTRADO",'16_Problemas'!$C$5:$C$25,"<0")
N49: Otros (11 tipos) | O49: =SUMIF('16_Problemas'!$C$5:$C$25,">0")-SUMIF('16_Problemas'!$C$5:$C$25,"<0")-((SUMIFS('16_Problemas'!$C$5:$C$25,'16_Problemas'!$A$5:$A$25,"NATURALEZA_NO_REVELADA",'16_Problemas'!$C$5:$C$25,">0")-SUMIFS('16_Problemas'!$C$5:$C$25,'16_Problemas'!$A$5:$A$25,"NATURALEZA_NO_REVELADA",'16_Problemas'!$C$5:$C$25,"<0"))+(SUMIFS('16_Problemas'!$C$5:$C$25,'16_Problemas'!$A$5:$A$25,"VARIACION_SIN_EXPLICAR",'16_Problemas'!$C$5:$C$25,">0")-SUMIFS('16_Problemas'!$C$5:$C$25,'16_Problemas'!$A$5:$A$25,"VARIACION_SIN_EXPLICAR",'16_Problemas'!$C$5:$C$25,"<0"))+(SUMIFS('16_Problemas'!$C$5:$C$25,'16_Problemas'!$A$5:$A$25,"PARTIDA_INUSUAL",'16_Problemas'!$C$5:$C$25,">0")-SUMIFS('16_Problemas'!$C$5:$C$25,'16_Problemas'!$A$5:$A$25,"PARTIDA_INUSUAL",'16_Problemas'!$C$5:$C$25,"<0"))+(SUMIFS('16_Problemas'!$C$5:$C$25,'16_Problemas'!$A$5:$A$25,"GASTO_NO_SOPORTADO",'16_Problemas'!$C$5:$C$25,">0")-SUMIFS('16_Problemas'!$C$5:$C$25,'16_Problemas'!$A$5:$A$25,"GASTO_NO_SOPORTADO",'16_Problemas'!$C$5:$C$25,"<0"))+(SUMIFS('16_Problemas'!$C$5:$C$25,'16_Problemas'!$A$5:$A$25,"GASTO_ANTICIPADO_EN_RESULTADOS",'16_Problemas'!$C$5:$C$25,">0")-SUMIFS('16_Problemas'!$C$5:$C$25,'16_Problemas'!$A$5:$A$25,"GASTO_ANTICIPADO_EN_RESULTADOS",'16_Problemas'!$C$5:$C$25,"<0"))+(SUMIFS('16_Problemas'!$C$5:$C$25,'16_Problemas'!$A$5:$A$25,"PARTIDA_EXTRAORDINARIA",'16_Problemas'!$C$5:$C$25,">0")-SUMIFS('16_Problemas'!$C$5:$C$25,'16_Problemas'!$A$5:$A$25,"PARTIDA_EXTRAORDINARIA",'16_Problemas'!$C$5:$C$25,"<0"))+(SUMIFS('16_Problemas'!$C$5:$C$25,'16_Problemas'!$A$5:$A$25,"CORTE_NO_REGISTRADO",'16_Problemas'!$C$5:$C$25,">0")-SUMIFS('16_Problemas'!$C$5:$C$25,'16_Problemas'!$A$5:$A$25,"CORTE_NO_REGISTRADO",'16_Problemas'!$C$5:$C$25,"<0")))

Sheet 00_Caratula
A1: Carátula | H1: ⟵ Inicio | J1: Siguiente ▶
A2: Gastos · análisis global, verificación del soporte, corte, devengo, clasificación y partes relacionadas · Cliente de muestra S.A. · corte 2025-12-31
A4: Concepto | B4: Detalle
A5: Firma | B5: AuditConsulting Auditores Cía. Ltda.
A6: Cliente | B6: Cliente de muestra S.A.
A7: RUC | B7: 1790000000001
A8: Ejercicio | B8: 2025
A9: Fecha de corte | B9: 2025-12-31
A10: Marco contable | B10: NIIF completas
A11: Herramienta | B11: Gastos · análisis global, verificación del soporte, corte, devengo, clasificación y partes relacionadas
A12: Rubro | B12: Costos y gastos
A13: Motor | B13: gastos_analisis 1.0
A14: Versión del papel | B14: v1
A15: Estado | B15: MUESTRA
... A17: Revisó | B17: Pendiente
A18: Aprobó
A19: Fecha de aprobación
A20: Huella de la ejecución (SHA-256)

Sheet 00_Programa
A1: Programa | H1: ⟵ Inicio | I1: ◀ Anterior | J1: Siguiente ▶
A2: Gastos · análisis global, verificación del soporte, corte, devengo, clasificación y partes relacionadas · Cliente de muestra S.A. · corte 2025-12-31
A4: Código | B4: Objetivo | C4: Afirmación | D4: Procedimiento | E4: Evidencia | F4: Criterio | G4: Referencia
A5: GAS-01 | B5: Integridad de la sumaria de gastos | C5: Integridad | D5: Conciliar la sumaria por cuenta con el estado de resultados y el mayor | E5: Sumaria, balance de comprobación, mayor | F5: Diferencia nula o explicada | G5: NIA 500
A6: GAS-02 | B6: Análisis global | C6: Ocurrencia / Integridad | D6: Comparar cada cuenta con el año anterior y el presupuesto, fijar el umbral e investigar las variaciones que lo exceden | E6: Explicaciones de la gerencia corroboradas | F6: Toda variación sobre el umbral explicada | G6: NIA 520
A7: GAS-03 | B7: Verificación del soporte documental | C7: Ocurrencia / Exactitud | D7: Cotejar la muestra con facturas, contratos, aprobaciones y pagos | E7: Comprobantes de venta y de pago | F7: Todo gasto de la muestra soportado | G7: NIA 500 · NIA 330
A8: GAS-04 | B8: Corte y devengo | C8: Corte | D8: Comparar fecha de documento, registro y período del servicio alrededor del cierre; buscar facturas posteriores con causa anterior | E8: Facturas y pagos posteriores, contratos de servicios | F8: Gasto en el período del devengo | G8: NIC 1 párr. 27–28 · PYMES 2.36 · NIA 330
A9: GAS-05 | B9: Clasificación y presentación | C9: Clasificación / Presentación | D9: Revisar la cuenta de cada gasto de la muestra y el desglose del estado de resultados | E9: Plan de cuentas, estado de resultados | F9: Desglose conforme; sin partidas extraordinarias | G9: NIC 1 párr. 87, 97–105 · PYMES 5.10–5.11
A10: GAS-06 | B10: Partes relacionadas: identificación, integridad de la población y revelación | C10: Integridad / Presentación | D10: Obtener el maestro COMPLETO de partes relacionadas (nombre, relación y período), preguntar a la dirección por la identidad de las partes relacionadas y sus cambios (NIA 550 párr. 13), cruzar los proveedores de la muestra con ese maestro, clasificar por categoría y comparar con la nota; obtener la manifestación escrita de la administración (NIA 550 párr. 26) antes de concluir sobre la integridad de la revelación | E10: Maestro completo de partes relacionadas, manifestación escrita de la administración, nota de revelación | F10: Población completa evidenciada y todo lo del período revelado por categoría; sin la manifestación escrita o el corte certificado del maestro, la integridad queda no concluida | G10: NIC 24 párr. 18–19 · PYMES 33.9–33.10 · NIA 550 párr. 13, 25 y 26
A11: GAS-07 | B11: Partidas inusuales y referencia tributaria | C11: Presentación / Cumplimiento | D11: Identificar partidas inusuales y verificar comprobante válido y bancarización | E11: Comprobantes SRI, estados de cuenta bancarios | F11: Revelación separada; no deducibles identificados | G11: NIC 1 párr. 97 (partidas materiales por separado) · LRTI art. 10 num. 1 y Reglamento LRTI art. 27 (Ecuador)

Sheet 00_Fuentes
A1: Base técnica | H1: ⟵ Inicio | I1: ◀ Anterior | J1: Siguiente ▶
A2: Gastos · análisis global, verificación del soporte, corte, devengo, clasificación y partes relacionadas · Cliente de muestra S.A. · corte 2025-12-31
A4: Categoría | B4: Documento | C4: Párrafos | D4: URL | E4: Verificada
A5: NIA · NIA 520 | B5: Procedimientos analíticos sustantivos: expectativa y umbral de diferencia aceptable (párr. 5) e investigación de las diferencias (párr. 7). | C5: párr. 5 y 7
A6: NIA · NIA 500 | B6: Evidencia suficiente y adecuada (párr. 6); exactitud e integridad de la información producida por la entidad —la sumaria contra el mayor— (párr. 9). | C6: párr. 6 y 9
A7: NIA · NIA 550 | B7: Preguntar a la dirección la identidad de las partes relacionadas (y sus cambios), la naturaleza de cada relación y si hubo transacciones en el período. | C7: párr. 13
A8: NIA · NIA 550 | B8: Transacciones con partes relacionadas: evaluación de su contabilización y revelación. | C8: párr. 25
A9: NIA · NIA 550 | B9: Manifestaciones escritas de la administración de que reveló la identidad de todas las partes relacionadas y todas las transacciones de las que tiene conocimiento, y de que las contabilizó y reveló conforme al marco. | C9: párr. 26
A10: NIA · NIA 330 | B10: Procedimientos sustantivos sobre transacciones materiales, incluido el corte. | C10: párr. 18
A11: NIA · NIA 450 | B11: Acumular las incorrecciones identificadas, salvo las claramente triviales (gastos no soportados, corte, devengo). | C11: párr. 5

Sheet 01_Resumen
A1: Resumen | H1: ⟵ Inicio | I1: ◀ Anterior | J1: Siguiente ▶
A2: Gastos · análisis global, verificación del soporte, corte, devengo, clasificación y partes relacionadas · Cliente de muestra S.A. · corte 2025-12-31
A4: Concepto | B4: Importe
A5: Gastos según la sumaria (año actual) | B5: ='14_Ajustes'!B15
A6: Gastos año anterior | B6: =SUM('03_Analisis_global'!$F$5:$F$14)
A7: Gastos del ejercicio no registrados (corte) | B7: ='14_Ajustes'!B5
A8: Gastos devengados no registrados | B8: ='14_Ajustes'!B6
A9: Gastos de otro período registrados (corte) | B9: ='14_Ajustes'!B7
A10: Gastos anticipados llevados a resultados | B10: ='14_Ajustes'!B8
A11: Ajuste propuesto al gasto (neto) | B11: ='14_Ajustes'!B9
A12: Gastos no soportados | B12: ='14_Ajustes'!B10
A13: Reclasificaciones entre cuentas | B13: ='14_Ajustes'!B11
A14: Transacciones con partes relacionadas | B14: ='14_Ajustes'!B12
A15: Partes relacionadas no reveladas | B15: ='14_Ajustes'!B14
A16: Partes relacionadas marcadas como no incluidas en la nota | B16: ='11_RP_Integridad'!H8
A17: Partidas inusuales | B17: ='14_Ajustes'!B19
A18: No deducible (referencia tributaria) | B18: ='14_Ajustes'!B18
A19: Diferencia sumaria vs estado de resultados | B19: ='14_Ajustes'!B17
A21: ⓘ Cómo se calcula esta hoja
A22: Columna | B22: Fórmula (Excel) | C22: Cómo se calcula (sencillo) | D22: Ejemplo con números reales | E22: De dónde viene | F22: Norma
A23: Importe | B23: '='14_Ajustes'!B15 | C23: Trae cada importe de la hoja 14 (Ajustes y conciliación), concepto por concepto; los gastos del año anterior suman la columna «Saldo anterior» de la hoja 03 (Análisis global) y las partes relacionadas marcadas como no incluidas salen del total de la hoja 11 (Integridad de la revelación). | D23: Fila 1: 1.008.000,00 → 1.008.000,00 | E23: hoja «Ajustes y conciliación» | F23: —

Sheet 02_Parametros
A1: Parámetros | H1: ⟵ Inicio | I1: ◀ Anterior | J1: Siguiente ▶
A2: Gastos · análisis global, verificación del soporte, corte, devengo, clasificación y partes relacionadas · Cliente de muestra S.A. · corte 2025-12-31
A4: Parámetro | B4: Valor | C4: Sustento
A5: Corte del ejercicio | B5: 46022 | C5: Ficha del encargo
A6: Marco contable | B6: NIIF completas | C6: Ficha del encargo: enruta el requisito de desglose y las categorías de partes relacionadas
A7: Método de desglose del estado de resultados | B7: Función | C7: NIC 1 párr. 99 / PYMES 5.11
A8: Requisito de desglose que aplica | B8: Revelar el costo de ventas por separado (NIC 1 párr. 103) e información por naturaleza: amortización y retribuciones a los empleados (NIC 1 párr. 104) | C8: Enrutado por marco y método
A9: Umbral de variación (%) | B9: 10 | C9: NIA 520 párr. 5 d) y 7 — juicio del auditor
A10: Umbral de variación (importe) | B10: 5000 | C10: NIA 520 — vacío: se usa la materialidad de ejecución
A11: Materialidad de ejecución | B11: 20000 | C11: NIA 320; revelación separada de partidas materiales: se usa la materialidad de ejecución como aproximación (NIC 1.97 se refiere a la importancia relativa)
A12: Umbral absoluto aplicado | B12: =IF(B10<>"",B10,B11) | C12: Umbral de variación o, si falta, materialidad de ejecución
A13: Umbral de bancarización (USD) | B13: 500 | C13: Por caso entendido (contrato), Reglamento LRTI art. 27 (reforma de 15-7-2025) — confirmar que sigue vigente al corte
A14: Gastos según el estado de resultados / mayor | B14: 1005000 | C14: Estado de resultados o balance de comprobación
A15: Partes relacionadas reveladas en notas | B15: 10000 | C15: Nota de partes relacionadas (NIC 24 párr. 18 / PYMES 33.9)
A16: Evidencia de integridad de la población de partes relacionadas | B16: MR-05 manifestación escrita de la administración del 15-01-2026 (NIA 550 párr. 26) y maestro de partes relacionadas certificado al 31-12-2025 | C16: Manifestación escrita de la administración (NIA 550 párr. 26) o corte certificado del maestro. Vacío: la integridad no se concluye
A18: ⓘ Cómo se calcula esta hoja
A19: Columna | B19: Fórmula (Excel) | C19: Cómo se calcula (sencillo) | D19: Ejemplo con números reales | E19: De dónde viene | F19: Norma
A20: Valor | B20: '=IF(B10<>"",B10,B11) | C20: Solo el «Umbral absoluto aplicado» se calcula: usa el umbral de variación en importe y, si está vacío, la materialidad de ejecución; los demás valores son datos de la ficha del encargo y del auditor. | D20: Fila 8: IF(5.000,00<>""; 5.000,00; 20.000,00) → 5.000,00 | E20: «Valor» (esta hoja) | F20: —

Sheet 03_Analisis_global
A1: Análisis global por cuenta (NIA 520) | H1: ⟵ Inicio | I1: ◀ Anterior | J1: Siguiente ▶
A2: Gastos · análisis global, verificación del soporte, corte, devengo, clasificación y partes relacionadas · Cliente de muestra S.A. · corte 2025-12-31
A4: Cuenta | B4: Nombre | C4: Línea del estado de resultados | D4: Naturaleza | E4: Saldo actual | F4: Saldo anterior | G4: Variación | H4: Variación % | I4: Excede umbral | J4: Presupuesto | K4: Variación vs presupuesto | L4: Variación vs presupuesto % | M4: Excede umbral (presupuesto) | N4: Explicación | O4: Variación sin explicar | P4: Muestra examinada | Q4: Cobertura de la muestra | R4: Presentada como extraordinaria
A5: 5101 | B5: Costo de ventas | C5: Costo de ventas | D5: Consumo de inventarios | E5: 600000 | F5: 550000 | G5: =IF(F5="","",E5-F5) | H5: =IF(F5="","",IF(F5=0,"",G5/F5)) | I5: =IF(G5="","",IF(ABS(G5)<='02_Parametros'!$B$12,"No",IF(F5=0,"Sí",IF(ABS(H5)>'02_Parametros'!$B$9/100,"Sí","No")))) | J5: 590000 | K5: =IF(J5="","",E5-J5) | L5: =IF(J5="","",IF(J5=0,"",K5/J5)) | M5: =IF(K5="","",IF(ABS(K5)<='02_Parametros'!$B$12,"No",IF(J5=0,"Sí",IF(ABS(L5)>'02_Parametros'!$B$9/100,"Sí","No")))) | N5: Mayor volumen de ventas (+9 %) | O5: =IF(AND(OR(I5="Sí",M5="Sí"),N5=""),"Sí","No") | P5: =SUMIFS('05_Transacciones'!$F$5:$F$19,'05_Transacciones'!$G$5:$G$19,A5,'05_Transacciones'!$P$5:$P$19,"Sí") | Q5: =IF(E5=0,"",P5/E5) | R5: =IF(OR(ISNUMBER(SEARCH("extraordinari",B5)),ISNUMBER(SEARCH("extraordinari",C5))),"Sí","No")
A6: 5201 | B6: Sueldos y beneficios administración | C6: Gastos de administración | D6: Beneficios a empleados | E6: 180000 | F6: 150000 | G6: =IF(F6="","",E6-F6) | H6: =IF(F6="","",IF(F6=0,"",G6/F6)) | I6: =IF(G6="","",IF(ABS(G6)<='02_Parametros'!$B$12,"No",IF(F6=0,"Sí",IF(ABS(H6)>'02_Parametros'!$B$9/100,"Sí","No")))) | J6: 175000 | K6: =IF(J6="","",E6-J6) | L6: =IF(J6="","",IF(J6=0,"",K6/J6)) | M6: =IF(K6="","",IF(ABS(K6)<='02_Parametros'!$B$12,"No",IF(J6=0,"Sí",IF(ABS(L6)>'02_Parametros'!$B$9/100,"Sí","No")))) | O6: =IF(AND(OR(I6="Sí",M6="Sí"),N6=""),"Sí","No") | P6: =SUMIFS('05_Transacciones'!$F$5:$F$19,'05_Transacciones'!$G$5:$G$19,A6,'05_Transacciones'!$P$5:$P$19,"Sí") | Q6: =IF(E6=0,"",P6/E6) | R6: =IF(OR(ISNUMBER(SEARCH("extraordinari",B6)),ISNUMBER(SEARCH("extraordinari",C6))),"Sí","No")
A7: 5202 | B7: Honorarios profesionales | C7: Gastos de administración | E7: 45000 | F7: 30000 | G7: =IF(F7="","",E7-F7) | H7: =IF(F7="","",IF(F7=0,"",G7/F7)) | I7: =IF(G7="","",IF(ABS(G7)<='02_Parametros'!$B$12,"No",IF(F7=0,"Sí",IF(ABS(H7)>'02_Parametros'!$B$9/100,"Sí","No")))) | J7: 32000 | K7: =IF(J7="","",E7-J7) | L7: =IF(J7="","",IF(J7=0,"",K7/J7)) | M7: =IF(K7="","",IF(ABS(K7)<='02_Parametros'!$B$12,"No",IF(J7=0,"Sí",IF(ABS(L7)>'02_Parametros'!$B$9/100,"Sí","No")))) | N7: Asesoría legal por litigio laboral | O7: =IF(AND(OR(I7="Sí",M7="Sí"),N7=""),"Sí","No") | P7: =SUMIFS('05_Transacciones'!$F$5:$F$19,'05_Transacciones'!$G$5:$G$19,A7,'05_Transacciones'!$P$5:$P$19,"Sí") | Q7: =IF(E7=0,"",P7/E7) | R7: =IF(OR(ISNUMBER(SEARCH("extraordinari",B7)),ISNUMBER(SEARCH("extraordinari",C7))),"Sí","No")
A8: 5203 | B8: Arriendos | C8: Gastos de administración | D8: Arrendamientos | E8: 36000 | F8: 36000 | G8: =IF(F8="","",E8-F8) | H8: =IF(F8="","",IF(F8=0,"",G8/F8)) | I8: =IF(G8="","",IF(ABS(G8)<='02_Parametros'!$B$12,"No",IF(F8=0,"Sí",IF(ABS(H8)>'02_Parametros'!$B$9/100,"Sí","No")))) | J8: 36000 | K8: =IF(J8="","",E8-J8) | L8: =IF(J8="","",IF(J8=0,"",K8/J8)) | M8: =IF(K8="","",IF(ABS(K8)<='02_Parametros'!$B$12,"No",IF(J8=0,"Sí",IF(ABS(L8)>'02_Parametros'!$B$9/100,"Sí","No")))) | O8: =IF(AND(OR(I8="Sí",M8="Sí"),N8=""),"Sí","No") | P8: =SUMIFS('05_Transacciones'!$F$5:$F$19,'05_Transacciones'!$G$5:$G$19,A8,'05_Transacciones'!$P$5:$P$19,"Sí") | Q8: =IF(E8=0,"",P8/E8) | R8: =IF(OR(ISNUMBER(SEARCH("extraordinari",B8)),ISNUMBER(SEARCH("extraordinari",C8))),"Sí","No")
A9: 5204 | B9: Depreciación | C9: Gastos de administración | D9: Depreciación | E9: 24000 | F9: 22000 | G9: =IF(F9="","",E9-F9) | H9: =IF(F9="","",IF(F9=0,"",G9/F9)) | I9: =IF(G9="","",IF(ABS(G9)<='02_Parametros'!$B$12,"No",IF(F9=0,"Sí",IF(ABS(H9)>'02_Parametros'!$B$9/100,"Sí","No")))) | K9: =IF(J9="","",E9-J9) | L9: =IF(J9="","",IF(J9=0,"",K9/J9)) | M9: =IF(K9="","",IF(ABS(K9)<='02_Parametros'!$B$12,"No",IF(J9=0,"Sí",IF(ABS(L9)>'02_Parametros'!$B$9/100,"Sí","No")))) | O9: =IF(AND(OR(I9="Sí",M9="Sí"),N9=""),"Sí","No") | P9: =SUMIFS('05_Transacciones'!$F$5:$F$19,'05_Transacciones'!$G$5:$G$19,A9,'05_Transacciones'!$P$5:$P$19,"Sí") | Q9: =IF(E9=0,"",P9/E9) | R9: =IF(OR(ISNUMBER(SEARCH("extraordinari",B9)),ISNUMBER(SEARCH("extraordinari",C9))),"Sí","No")
A10: 5301 | B10: Publicidad | C10: Gastos de ventas | D10: Publicidad | E10: 60000 | F10: 40000 | G10: =IF(F10="","",E10-F10) | H10: =IF(F10="","",IF(F10=0,"",G10/F10)) | I10: =IF(G10="","",IF(ABS(G10)<='02_Parametros'!$B$12,"No",IF(F10=0,"Sí",IF(ABS(H10)>'02_Parametros'!$B$9/100,"Sí","No")))) | J10: 45000 | K10: =IF(J10="","",E10-J10) | L10: =IF(J10="","",IF(J10=0,"",K10/J10)) | M10: =IF(K10="","",IF(ABS(K10)<='02_Parametros'!$B$12,"No",IF(J10=0,"Sí",IF(ABS(L10)>'02_Parametros'!$B$9/100,"Sí","No")))) | O10: =IF(AND(OR(I10="Sí",M10="Sí"),N10=""),"Sí","No") | P10: =SUMIFS('05_Transacciones'!$F$5:$F$19,'05_Transacciones'!$G$5:$G$19,A10,'05_Transacciones'!$P$5:$P$19,"Sí") | Q10: =IF(E10=0,"",P10/E10) | R10: =IF(OR(ISNUMBER(SEARCH("extraordinari",B10)),ISNUMBER(SEARCH("extraordinari",C10))),"Sí","No")
A11: 5302 | B11: Comisiones y gastos de distribución | C11: Gastos de ventas | D11: Comisiones | E11: 25000 | F11: 27000 | G11: =IF(F11="","",E11-F11) | H11: =IF(F11="","",IF(F11=0,"",G11/F11)) | I11: =IF(G11="","",IF(ABS(G11)<='02_Parametros'!$B$12,"No",IF(F11=0,"Sí",IF(ABS(H11)>'02_Parametros'!$B$9/100,"Sí","No")))) | J11: 26000 | K11: =IF(J11="","",E11-J11) | L11: =IF(J11="","",IF(J11=0,"",K11/J11)) | M11: =IF(K11="","",IF(ABS(K11)<='02_Parametros'!$B$12,"No",IF(J11=0,"Sí",IF(ABS(L11)>'02_Parametros'!$B$9/100,"Sí","No")))) | O11: =IF(AND(OR(I11="Sí",M11="Sí"),N11=""),"Sí","No") | P11: =SUMIFS('05_Transacciones'!$F$5:$F$19,'05_Transacciones'!$G$5:$G$19,A11,'05_Transacciones'!$P$5:$P$19,"Sí") | Q11: =IF(E11=0,"",P11/E11) | R11: =IF(OR(ISNUMBER(SEARCH("extraordinari",B11)),ISNUMBER(SEARCH("extraordinari",C11))),"Sí","No")
A12: 5401 | B12: Seguros | C12: Gastos de administración | D12: Seguros | E12: 12000 | F12: 11000 | G12: =IF(F12="","",E12-F12) | H12: =IF(F12="","",IF(F12=0,"",G12/F12)) | I12: =IF(G12="","",IF(ABS(G12)<='02_Parametros'!$B$12,"No",IF(F12=0,"Sí",IF(ABS(H12)>'02_Parametros'!$B$9/100,"Sí","No")))) | K12: =IF(J12="","",E12-J12) | L12: =IF(J12="","",IF(J12=0,"",K12/J12)) | M12: =IF(K12="","",IF(ABS(K12)<='02_Parametros'!$B$12,"No",IF(J12=0,"Sí",IF(ABS(L12)>'02_Parametros'!$B$9/100,"Sí","No")))) | O12: =IF(AND(OR(I12="Sí",M12="Sí"),N12=""),"Sí","No") | P12: =SUMIFS('05_Transacciones'!$F$5:$F$19,'05_Transacciones'!$G$5:$G$19,A12,'05_Transacciones'!$P$5:$P$19,"Sí") | Q12: =IF(E12=0,"",P12/E12) | R12: =IF(OR(ISNUMBER(SEARCH("extraordinari",B12)),ISNUMBER(SEARCH("extraordinari",C12))),"Sí","No")
A13: 5501 | B13: Intereses bancarios | C13: Gastos financieros | D13: Intereses | E13: 18000 | F13: 20000 | G13: =IF(F13="","",E13-F13) | H13: =IF(F13="","",IF(F13=0,"",G13/F13)) | I13: =IF(G13="","",IF(ABS(G13)<='02_Parametros'!$B$12,"No",IF(F13=0,"Sí",IF(ABS(H13)>'02_Parametros'!$B$9/100,"Sí","No")))) | K13: =IF(J13="","",E13-J13) | L13: =IF(J13="","",IF(J13=0,"",K13/J13)) | M13: =IF(K13="","",IF(ABS(K13)<='02_Parametros'!$B$12,"No",IF(J13=0,"Sí",IF(ABS(L13)>'02_Parametros'!$B$9/100,"Sí","No")))) | O13: =IF(AND(OR(I13="Sí",M13="Sí"),N13=""),"Sí","No") | P13: =SUMIFS('05_Transacciones'!$F$5:$F$19,'05_Transacciones'!$G$5:$G$19,A13,'05_Transacciones'!$P$5:$P$19,"Sí") | Q13: =IF(E13=0,"",P13/E13) | R13: =IF(OR(ISNUMBER(SEARCH("extraordinari",B13)),ISNUMBER(SEARCH("extraordinari",C13))),"Sí","No")
A14: 5601 | B14: Pérdida por siniestro | C14: Gastos extraordinarios | E14: 8000 | F14: 0 | G14: =IF(F14="","",E14-F14) | H14: =IF(F14="","",IF(F14=0,"",G14/F14)) | I14: =IF(G14="","",IF(ABS(G14)<='02_Parametros'!$B$12,"No",IF(F14=0,"Sí",IF(ABS(H14)>'02_Parametros'!$B$9/100,"Sí","No")))) | K14: =IF(J14="","",E14-J14) | L14: =IF(J14="","",IF(J14=0,"",K14/J14)) | M14: =IF(K14="","",IF(ABS(K14)<='02_Parametros'!$B$12,"No",IF(J14=0,"Sí",IF(ABS(L14)>'02_Parametros'!$B$9/100,"Sí","No")))) | N14: Incendio en bodega | O14: =IF(AND(OR(I14="Sí",M14="Sí"),N14=""),"Sí","No") | P14: =SUMIFS('05_Transacciones'!$F$5:$F$19,'05_Transacciones'!$G$5:$G$19,A14,'05_Transacciones'!$P$5:$P$19,"Sí") | Q14: =IF(E14=0,"",P14/E14) | R14: =IF(OR(ISNUMBER(SEARCH("extraordinari",B14)),ISNUMBER(SEARCH("extraordinari",C14))),"Sí","No")
A15: TOTAL | E15: =SUM(E5:E14) | F15: =SUM(F5:F14) | G15: =SUM(G5:G14) | J15: =SUM(J5:J14) | K15: =SUM(K5:K14) | P15: =SUM(P5:P14) | Q15: =IF(E15=0,"",P15/E15)
A17: ⓘ Cómo se calcula esta hoja
A18: Columna | B18: Fórmula (Excel) | C18: Cómo se calcula (sencillo) | D18: Ejemplo con números reales | E18: De dónde viene | F18: Norma
A19: Variación | B19: '=IF(F5="","",E5-F5) | C19: Resta el saldo del año anterior al saldo actual de la cuenta; si no hay saldo anterior, queda en blanco. | D19: Fila 1: IF(550.000,00=""; ""; 600.000,00-550.000,00) → 50.000,00 | E19: «Saldo anterior» (esta hoja), «Saldo actual» (esta hoja) | F19: —
A20: Variación % | B20: '=IF(F5="","",IF(F5=0,"",G5/F5)) | C20: Divide la variación para el saldo del año anterior; queda en blanco si no hay saldo anterior o si ese saldo es cero. | D20: Fila 1: IF(550.000,00=""; ""; IF(550.000,00=0; ""; 50.000,00/550.000,00)) → 9,09 % | E20: «Saldo anterior» (esta hoja), «Variación» (esta hoja) | F20: —
A21: Excede umbral | B21: '=IF(G5="","",IF(ABS(G5)<='02_Parametros'!$B$12,"No",IF(F5=0,"Sí",IF(ABS(H5)>'02_Parametros'!$B$9/100,"Sí","No")))) | C21: Compara la variación con los umbrales de la hoja 02 (Parámetros): si en valor absoluto no pasa el umbral absoluto aplicado es «No»; si lo pasa, es «Sí» cuando el saldo anterior es cero o la variación % supera el umbral en %. | D21: Fila 1: IF(50.000,00=""; ""; IF(ABS(50.000,00)<=5.000,00; "No"; IF(550.000,00=0; "Sí"; IF(ABS(9,09 %)>10,00/100; "Sí"; "No")))) → No | E21: «Variación» (esta hoja), «Saldo anterior» (esta hoja), «Variación %» (esta hoja), hoja «Parámetros» | F21: —
A22: Variación vs presupuesto | B22: '=IF(J5="","",E5-J5) | C22: Resta el presupuesto de la cuenta a su saldo actual; si la cuenta no tiene presupuesto, queda en blanco. | D22: Fila 1: IF(590.000,00=""; ""; 600.000,00-590.000,00) → 10.000,00 | E22: «Presupuesto» (esta hoja), «Saldo actual» (esta hoja) | F22: —
A23: Variación vs presupuesto % | B23: '=IF(J5="","",IF(J5=0,"",K5/J5)) | C23: Divide la variación contra el presupuesto para el presupuesto; queda en blanco si no hay presupuesto o si es cero. | D23: Fila 1: IF(590.000,00=""; ""; IF(590.000,00=0; ""; 10.000,00/590.000,00)) → 1,69 % | E23: «Presupuesto» (esta hoja), «Variación vs presupuesto» (esta hoja) | F23: —
A24: Excede umbral (presupuesto) | B24: '=IF(K5="","",IF(ABS(K5)<='02_Parametros'!$B$12,"No",IF(J5=0,"Sí",IF(ABS(L5)>'02_Parametros'!$B$9/100,"Sí","No")))) | C24: Aplica la misma prueba de umbrales de la hoja 02 (Parámetros) a la variación contra el presupuesto: «Sí» solo si supera el umbral absoluto y, además, el presupuesto es cero o la variación % supera el umbral en %. | D24: Fila 1: IF(10.000,00=""; ""; IF(ABS(10.000,00)<=5.000,00; "No"; IF(590.000,00=0; "Sí"; IF(ABS(1,69 %)>10,00/100; "Sí"; "No")))) → No | E24: «Variación vs presupuesto» (esta hoja), «Presupuesto» (esta hoja), «Variación vs presupuesto %» (esta hoja), hoja «Parámetros» | F24: —
A25: Variación sin explicar | B25: '=IF(AND(OR(I5="Sí",M5="Sí"),N5=""),"Sí","No") | C25: Marca «Sí» cuando la cuenta excede el umbral (contra el año anterior o contra el presupuesto) y la columna «Explicación» está vacía; en otro caso, «No». | D25: Fila 1: IF(AND(OR(«No»="Sí"; «No»="Sí"); «Mayor volumen de ventas (+9 %)»=""); "Sí"; "No") → No | E25: «Excede umbral» (esta hoja), «Excede umbral (presupuesto)» (esta hoja), «Explicación» (esta hoja) | F25: —
A26: Muestra examinada | B26: '=SUMIFS('05_Transacciones'!$F$5:$F$19,'05_Transacciones'!$G$5:$G$19,A5,'05_Transacciones'!$P$5:$P$19,"Sí") | C26: Suma los importes de las transacciones de la hoja 05 (Transacciones de la muestra) registradas en esta cuenta y dentro del ejercicio. | D26: Fila 1: SUMIFS([«Importe» de «Transacciones de la muestra», 15 filas]; [«Cuenta» de «Transacciones de la muestra», 15 filas]; «5101»; [«Registrado en el ejercicio» de «Transacciones de la muestra», 15 filas]; "Sí") → 0,00 | E26: «Cuenta» (esta hoja), hoja «Transacciones de la muestra» | F26: —
A27: Cobertura de la muestra | B27: '=IF(E5=0,"",P5/E5) | C27: Divide la muestra examinada para el saldo actual de la cuenta: indica qué parte del gasto se revisó con documentos; en blanco si el saldo es cero. | D27: Fila 1: IF(600.000,00=0; ""; 0,00/600.000,00) → 0,00 % | E27: «Saldo actual» (esta hoja), «Muestra examinada» (esta hoja) | F27: —
A28: Presentada como extraordinaria | B28: '=IF(OR(ISNUMBER(SEARCH("extraordinari",B5)),ISNUMBER(SEARCH("extraordinari",C5))),"Sí","No") | C28: Marca «Sí» si el nombre de la cuenta o su línea del estado de resultados contiene la palabra «extraordinario/a»; en otro caso, «No». | D28: Fila 1: IF(OR(ISNUMBER(SEARCH("extraordinari"; «Costo de ventas»)); ISNUMBER(SEARCH("extraordinari"; «Costo de ventas»))); "Sí"; "No") → No | E28: «Nombre» (esta hoja), «Línea del estado de resultados» (esta hoja) | F28: —

Sheet 04_Presentacion_ERI
A1: Presentación en el estado de resultados | H1: ⟵ Inicio | I1: ◀ Anterior | J1: Siguiente ▶
A2: Gastos · análisis global, verificación del soporte, corte, devengo, clasificación y partes relacionadas · Cliente de muestra S.A. · corte 2025-12-31
A4: Línea del estado de resultados | B4: Cuentas | C4: Año actual | D4: Año anterior | E4: Variación | F4: % del gasto total | G4: «Extraordinaria» (prohibido)
A5: Costo de ventas | B5: =COUNTIF('03_Analisis_global'!$C$5:$C$14,A5) | C5: =SUMIF('03_Analisis_global'!$C$5:$C$14,A5,'03_Analisis_global'!$E$5:$E$14) | D5: =SUMIF('03_Analisis_global'!$C$5:$C$14,A5,'03_Analisis_global'!$F$5:$F$14) | E5: =C5-D5 | F5: =IF(SUM('03_Analisis_global'!$E$5:$E$14)=0,"",C5/SUM('03_Analisis_global'!$E$5:$E$14)) | G5: =IF(ISNUMBER(SEARCH("extraordinari",A5)),"Sí","No")
A6: Gastos de administración | B6: =COUNTIF('03_Analisis_global'!$C$5:$C$14,A6) | C6: =SUMIF('03_Analisis_global'!$C$5:$C$14,A6,'03_Analisis_global'!$E$5:$E$14) | D6: =SUMIF('03_Analisis_global'!$C$5:$C$14,A6,'03_Analisis_global'!$F$5:$F$14) | E6: =C6-D6 | F6: =IF(SUM('03_Analisis_global'!$E$5:$E$14)=0,"",C6/SUM('03_Analisis_global'!$E$5:$E$14)) | G6: =IF(ISNUMBER(SEARCH("extraordinari",A6)),"Sí","No")
A7: Gastos de ventas | B7: =COUNTIF('03_Analisis_global'!$C$5:$C$14,A7) | C7: =SUMIF('03_Analisis_global'!$C$5:$C$14,A7,'03_Analisis_global'!$E$5:$E$14) | D7: =SUMIF('03_Analisis_global'!$C$5:$C$14,A7,'03_Analisis_global'!$F$5:$F$14) | E7: =C7-D7 | F7: =IF(SUM('03_Analisis_global'!$E$5:$E$14)=0,"",C7/SUM('03_Analisis_global'!$E$5:$E$14)) | G7: =IF(ISNUMBER(SEARCH("extraordinari",A7)),"Sí","No")
A8: Gastos financieros | B8: =COUNTIF('03_Analisis_global'!$C$5:$C$14,A8) | C8: =SUMIF('03_Analisis_global'!$C$5:$C$14,A8,'03_Analisis_global'!$E$5:$E$14) | D8: =SUMIF('03_Analisis_global'!$C$5:$C$14,A8,'03_Analisis_global'!$F$5:$F$14) | E8: =C8-D8 | F8: =IF(SUM('03_Analisis_global'!$E$5:$E$14)=0,"",C8/SUM('03_Analisis_global'!$E$5:$E$14)) | G8: =IF(ISNUMBER(SEARCH("extraordinari",A8)),"Sí","No")
A9: Gastos extraordinarios | B9: =COUNTIF('03_Analisis_global'!$C$5:$C$14,A9) | C9: =SUMIF('03_Analisis_global'!$C$5:$C$14,A9,'03_Analisis_global'!$E$5:$E$14) | D9: =SUMIF('03_Analisis_global'!$C$5:$C$14,A9,'03_Analisis_global'!$F$5:$F$14) | E9: =C9-D9 | F9: =IF(SUM('03_Analisis_global'!$E$5:$E$14)=0,"",C9/SUM('03_Analisis_global'!$E$5:$E$14)) | G9: =IF(ISNUMBER(SEARCH("extraordinari",A9)),"Sí","No")
A10: TOTAL | B10: =SUM(B5:B9) | C10: =SUM(C5:C9) | D10: =SUM(D5:D9) | E10: =SUM(E5:E9)
A12: ⓘ Cómo se calcula esta hoja
A13: Columna | B13: Fórmula (Excel) | C13: Cómo se calcula (sencillo) | D13: Ejemplo con números reales | E13: De dónde viene | F13: Norma
A14: Cuentas | B14: '=COUNTIF('03_Analisis_global'!$C$5:$C$14,A5) | C14: Cuenta cuántas cuentas de la hoja 03 (Análisis global) están asignadas a esta línea del estado de resultados. | D14: Fila 1: COUNTIF([«Línea del estado de resultados» de «Análisis global por cuenta (NIA 520)», 10 filas]; «Costo de ventas») → 1 | E14: «Línea del estado de resultados» (esta hoja), hoja «Análisis global por cuenta (NIA 520)» | F14: —
A15: Año actual | B15: '=SUMIF('03_Analisis_global'!$C$5:$C$14,A5,'03_Analisis_global'!$E$5:$E$14) | C15: Suma el saldo actual de las cuentas de la hoja 03 (Análisis global) asignadas a esta línea. | D15: Fila 1: SUMIF([«Línea del estado de resultados» de «Análisis global por cuenta (NIA 520)», 10 filas]; «Costo de ventas»; [«Saldo actual» de «Análisis global por cuenta (NIA 520)», 10 filas]) → 600.000,00 | E15: «Línea del estado de resultados» (esta hoja), hoja «Análisis global por cuenta (NIA 520)» | F15: —
A16: Año anterior | B16: '=SUMIF('03_Analisis_global'!$C$5:$C$14,A5,'03_Analisis_global'!$F$5:$F$14) | C16: Suma el saldo del año anterior de las cuentas de la hoja 03 (Análisis global) asignadas a esta línea. | D16: Fila 1: SUMIF([«Línea del estado de resultados» de «Análisis global por cuenta (NIA 520)», 10 filas]; «Costo de ventas»; [«Saldo anterior» de «Análisis global por cuenta (NIA 520)», 10 filas]) → 550.000,00 | E16: «Línea del estado de resultados» (esta hoja), hoja «Análisis global por cuenta (NIA 520)» | F16: —
A17: Variación | B17: '=C5-D5 | C17: Resta el importe del año anterior al del año actual de esta línea del estado de resultados. | D17: Fila 1: 600.000,00-550.000,00 → 50.000,00 | E17: «Año actual» (esta hoja), «Año anterior» (esta hoja) | F17: —
A18: % del gasto total | B18: '=IF(SUM('03_Analisis_global'!$E$5:$E$14)=0,"",C5/SUM('03_Analisis_global'!$E$5:$E$14)) | C18: Divide el gasto del año actual de la línea para el total de saldos actuales de la hoja 03 (Análisis global); en blanco si ese total es cero. | D18: Fila 1: IF(SUM([«Saldo actual» de «Análisis global por cuenta (NIA 520)», 10 filas])=0; ""; 600.000,00/SUM([«Saldo actual» de «Análisis global por cuenta (NIA 520)», 10 filas])) → 59,52 % | E18: «Año actual» (esta hoja), hoja «Análisis global por cuenta (NIA 520)» | F18: —
A19: «Extraordinaria» (prohibido) | B19: '=IF(ISNUMBER(SEARCH("extraordinari",A5)),"Sí","No") | C19: Marca «Sí» si el nombre de la línea del estado de resultados contiene la palabra «extraordinario/a»; en otro caso, «No». | D19: Fila 1: IF(ISNUMBER(SEARCH("extraordinari"; «Costo de ventas»)); "Sí"; "No") → No | E19: «Línea del estado de resultados» (esta hoja) | F19: —

Sheet 05_Transacciones
A1: Transacciones de la muestra | H1: ⟵ Inicio | I1: ◀ Anterior | J1: Siguiente ▶
A2: Gastos · análisis global, verificación del soporte, corte, devengo, clasificación y partes relacionadas · Cliente de muestra S.A. · corte 2025-12-31
A4: Comprobante | B4: Fecha documento | C4: Fecha registro | D4: Servicio desde | E4: Servicio hasta | F4: Importe | G4: Cuenta | H4: Proveedor | I4: Soporte | J4: Comprobante válido SRI | K4: Pagado por banco | L4: Parte relacionada | M4: Categoría parte relacionada | N4: Cuenta sugerida | O4: Inusual | P4: Registrado en el ejercicio | Q4: Con período de servicio
A5: FC-101 | B5: 45726 | C5: 45728 | F5: 12000 | G5: 5202 | H5: Estudio Jurídico Andrade | I5: Sí | J5: Sí | K5: Sí | L5: No | O5: No | P5: =IF(C5<='02_Parametros'!$B$5,"Sí","No") | Q5: =IF(AND(D5<>"",E5<>""),"Sí","No")
A6: FC-102 | B6: 45823 | C6: 45824 | F6: 18000 | G6: 5301 | H6: Medios Creativos S.A. | I6: No | J6: Sí | K6: Sí | L6: No | O6: No | P6: =IF(C6<='02_Parametros'!$B$5,"Sí","No") | Q6: =IF(AND(D6<>"",E6<>""),"Sí","No")
A7: FC-103 | B7: 45839 | C7: 45840 | D7: 45839 | E7: 46203 | F7: 7300 | G7: 5401 | H7: Aseguradora Sur | I7: Sí | J7: Sí | K7: Sí | L7: No | O7: No | P7: =IF(C7<='02_Parametros'!$B$5,"Sí","No") | Q7: =IF(AND(D7<>"",E7<>""),"Sí","No")
A8: FC-104 | B8: 46011 | C8: 46030 | F8: 4500 | G8: 5202 | H8: Consultores Delta | I8: Sí | J8: Sí | K8: Sí | L8: No | O8: No | P8: =IF(C8<='02_Parametros'!$B$5,"Sí","No") | Q8: =IF(AND(D8<>"",E8<>""),"Sí","No")
A9: FC-105 | B9: 46027 | C9: 46021 | F9: 3000 | G9: 5302 | H9: Comisionistas Unidos | I9: Sí | J9: Sí | K9: Sí | L9: No | O9: No | P9: =IF(C9<='02_Parametros'!$B$5,"Sí","No") | Q9: =IF(AND(D9<>"",E9<>""),"Sí","No")
A10: FC-106 | B10: 46037 | C10: 46038 | D10: 45992 | E10: 46022 | F10: 3000 | G10: 5203 | H10: Inmobiliaria Norte | I10: Sí | J10: Sí | K10: Sí | L10: Sí | M10: Otra | O10: No | P10: =IF(C10<='02_Parametros'!$B$5,"Sí","No") | Q10: =IF(AND(D10<>"",E10<>""),"Sí","No")
A11: FC-107 | B11: 45962 | C11: 45964 | D11: 45962 | E11: 46142 | F11: 12000 | G11: 5301 | H11: Radio Andina | I11: Sí | J11: Sí | K11: Sí | L11: No | O11: No | P11: =IF(C11<='02_Parametros'!$B$5,"Sí","No") | Q11: =IF(AND(D11<>"",E11<>""),"Sí","No")
A12: FC-108 | B12: 45910 | C12: 45912 | F12: 1500 | G12: 5202 | H12: Juan Pérez | I12: Sí | J12: No | K12: No | L12: No | O12: No | P12: =IF(C12<='02_Parametros'!$B$5,"Sí","No") | Q12: =IF(AND(D12<>"",E12<>""),"Sí","No")
A13: FC-109 | B13: 45935 | C13: 45936 | F13: 2500 | G13: 5301 | H13: Publicistas XYZ | I13: Sí | J13: Sí | K13: No | L13: No | O13: No | P13: =IF(C13<='02_Parametros'!$B$5,"Sí","No") | Q13: =IF(AND(D13<>"",E13<>""),"Sí","No")
A14: FC-110 | B14: 45889 | C14: 45890 | F14: 2200 | G14: 5201 | H14: Taller Mecánico Ruta | I14: Sí | J14: Sí | K14: Sí | L14: No | N14: 5302 | O14: No | P14: =IF(C14<='02_Parametros'!$B$5,"Sí","No") | Q14: =IF(AND(D14<>"",E14<>""),"Sí","No")
A15: FC-111 | B15: 45787 | C15: 45788 | F15: 9000 | G15: 5202 | H15: Holding Andes S.A. | I15: Sí | J15: Sí | K15: Sí | L15: Sí | M15: Dominante | O15: No | P15: =IF(C15<='02_Parametros'!$B$5,"Sí","No") | Q15: =IF(AND(D15<>"",E15<>""),"Sí","No")
A16: FC-112 | B16: 45749 | C16: 45750 | F16: 8000 | G16: 5601 | H16: Constructora Rápida | I16: Sí | J16: Sí | K16: Sí | L16: No | O16: Sí | P16: =IF(C16<='02_Parametros'!$B$5,"Sí","No") | Q16: =IF(AND(D16<>"",E16<>""),"Sí","No")
A17: FC-113 | B17: 45981 | C17: 45982 | F17: 22000 | G17: 5202 | H17: Acuerdo judicial ex trabajador | I17: Sí | J17: Sí | K17: Sí | L17: No | O17: Sí | P17: =IF(C17<='02_Parametros'!$B$5,"Sí","No") | Q17: =IF(AND(D17<>"",E17<>""),"Sí","No")
A18: FC-114 | B18: 45689 | C18: 45690 | F18: 3000 | G18: 5201 | H18: Gerente General | J18: Sí | K18: Sí | L18: Sí | M18: Personal clave | O18: No | P18: =IF(C18<='02_Parametros'!$B$5,"Sí","No") | Q18: =IF(AND(D18<>"",E18<>""),"Sí","No")
A19: FC-115 | B19: 45838 | C19: 45839 | F19: 1200 | G19: 5501 | H19: Banco Relacionado S.A. | I19: Sí | J19: Sí | K19: Sí | L19: Sí | O19: No | P19: =IF(C19<='02_Parametros'!$B$5,"Sí","No") | Q19: =IF(AND(D19<>"",E19<>""),"Sí","No")
A20: TOTAL | F20: =SUM(F5:F19)
A22: ⓘ Cómo se calcula esta hoja
A23: Columna | B23: Fórmula (Excel) | C23: Cómo se calcula (sencillo) | D23: Ejemplo con números reales | E23: De dónde viene | F23: Norma
A24: Registrado en el ejercicio | B24: '=IF(C5<='02_Parametros'!$B$5,"Sí","No") | C24: Marca «Sí» si la fecha de registro del comprobante es igual o anterior a la fecha de corte de la hoja 02 (Parámetros). | D24: Fila 1: IF(«2025-03-12»<=«2025-12-31»; "Sí"; "No") → Sí | E24: «Fecha registro» (esta hoja), hoja «Parámetros» | F24: —
A25: Con período de servicio | B25: '=IF(AND(D5<>"",E5<>""),"Sí","No") | C25: Marca «Sí» cuando el comprobante tiene fechas de inicio y de fin del servicio; esas partidas se analizan por devengo en la hoja 08 y las demás por corte en la hoja 07. | D25: Fila 1: IF(AND((vacío)<>""; (vacío)<>""); "Sí"; "No") → No | E25: «Servicio desde» (esta hoja), «Servicio hasta» (esta hoja) | F25: —

Sheet 06_Vouching
A1: Verificación del soporte documental | H1: ⟵ Inicio | I1: ◀ Anterior | J1: Siguiente ▶
A2: Gastos · análisis global, verificación del soporte, corte, devengo, clasificación y partes relacionadas · Cliente de muestra S.A. · corte 2025-12-31
A4: Comprobante | B4: Fecha documento | C4: Cuenta | D4: Proveedor | E4: Importe | F4: Tiene soporte | G4: Gasto no soportado | H4: Resultado
A5: FC-101 | B5: 45726 | C5: 5202 | D5: Estudio Jurídico Andrade | E5: ='05_Transacciones'!F5 | F5: Sí | G5: =IF(F5="No",E5,0) | H5: =IF(F5="Sí","Soportado",IF(F5="No","No soportado","Sin resultado informado"))
A6: FC-102 | B6: 45823 | C6: 5301 | D6: Medios Creativos S.A. | E6: ='05_Transacciones'!F6 | F6: No | G6: =IF(F6="No",E6,0) | H6: =IF(F6="Sí","Soportado",IF(F6="No","No soportado","Sin resultado informado"))
A7: FC-103 | B7: 45839 | C7: 5401 | D7: Aseguradora Sur | E7: ='05_Transacciones'!F7 | F7: Sí | G7: =IF(F7="No",E7,0) | H7: =IF(F7="Sí","Soportado",IF(F7="No","No soportado","Sin resultado informado"))
A8: FC-105 | B8: 46027 | C8: 5302 | D8: Comisionistas Unidos | E8: ='05_Transacciones'!F9 | F8: Sí | G8: =IF(F8="No",E8,0) | H8: =IF(F8="Sí","Soportado",IF(F8="No","No soportado","Sin resultado informado"))
A9: FC-107 | B9: 45962 | C9: 5301 | D9: Radio Andina | E9: ='05_Transacciones'!F11 | F9: Sí | G9: =IF(F9="No",E9,0) | H9: =IF(F9="Sí","Soportado",IF(F9="No","No soportado","Sin resultado informado"))
A10: FC-108 | B10: 45910 | C10: 5202 | D10: Juan Pérez | E10: ='05_Transacciones'!F12 | F10: Sí | G10: =IF(F10="No",E10,0) | H10: =IF(F10="Sí","Soportado",IF(F10="No","No soportado","Sin resultado informado"))
A11: FC-109 | B11: 45935 | C11: 5301 | D11: Publicistas XYZ | E11: ='05_Transacciones'!F13 | F11: Sí | G11: =IF(F11="No",E11,0) | H11: =IF(F11="Sí","Soportado",IF(F11="No","No soportado","Sin resultado informado"))
A12: FC-110 | B12: 45889 | C12: 5201 | D12: Taller Mecánico Ruta | E12: ='05_Transacciones'!F14 | F12: Sí | G12: =IF(F12="No",E12,0) | H12: =IF(F12="Sí","Soportado",IF(F12="No","No soportado","Sin resultado informado"))
A13: FC-111 | B13: 45787 | C13: 5202 | D13: Holding Andes S.A. | E13: ='05_Transacciones'!F15 | F13: Sí | G13: =IF(F13="No",E13,0) | H13: =IF(F13="Sí","Soportado",IF(F13="No","No soportado","Sin resultado informado"))
A14: FC-112 | B14: 45749 | C14: 5601 | D14: Constructora Rápida | E14: ='05_Transacciones'!F16 | F14: Sí | G14: =IF(F14="No",E14,0) | H14: =IF(F14="Sí","Soportado",IF(F14="No","No soportado","Sin resultado informado"))
A15: FC-113 | B15: 45981 | C15: 5202 | D15: Acuerdo judicial ex trabajador | E15: ='05_Transacciones'!F17 | F15: Sí | G15: =IF(F15="No",E15,0) | H15: =IF(F15="Sí","Soportado",IF(F15="No","No soportado","Sin resultado informado"))
A16: FC-114 | B16: 45689 | C16: 5201 | D16: Gerente General | E16: ='05_Transacciones'!F18 | G16: =IF(F16="No",E16,0) | H16: =IF(F16="Sí","Soportado",IF(F16="No","No soportado","Sin resultado informado"))
A17: FC-115 | B17: 45838 | C17: 5501 | D17: Banco Relacionado S.A. | E17: ='05_Transacciones'!F19 | F17: Sí | G17: =IF(F17="No",E17,0) | H17: =IF(F17="Sí","Soportado",IF(F17="No","No soportado","Sin resultado informado"))
A18: TOTAL | E18: =SUM(E5:E17) | G18: =SUM(G5:G17)
A20: ⓘ Cómo se calcula esta hoja
A21: Columna | B21: Fórmula (Excel) | C21: Cómo se calcula (sencillo) | D21: Ejemplo con números reales | E21: De dónde viene | F21: Norma
A22: Importe | B22: '='05_Transacciones'!F5 | C22: Trae el importe del comprobante desde la hoja 05 (Transacciones de la muestra); aquí solo aparecen los registrados en el ejercicio. | D22: Fila 1: 12.000,00 → 12.000,00 | E22: hoja «Transacciones de la muestra» | F22: —
A23: Gasto no soportado | B23: '=IF(F5="No",E5,0) | C23: Si la columna «Tiene soporte» dice «No», toma el importe completo del comprobante; si no, cero. | D23: Fila 1: IF(«Sí»="No"; 12.000,00; 0) → 0,00 | E23: «Tiene soporte» (esta hoja), «Importe» (esta hoja) | F23: —
A24: Resultado | B24: '=IF(F5="Sí","Soportado",IF(F5="No","No soportado","Sin resultado informado")) | C24: Traduce la columna «Tiene soporte»: «Sí» es «Soportado», «No» es «No soportado» y, si está vacía, «Sin resultado informado». | D24: Fila 1: IF(«Sí»="Sí"; "Soportado"; IF(«Sí»="No"; "No soportado"; "Sin resultado informado")) → Soportado | E24: «Tiene soporte» (esta hoja) | F24: —

Sheet 07_Corte
A1: Corte de gastos | H1: ⟵ Inicio | I1: ◀ Anterior | J1: Siguiente ▶
A2: Gastos · análisis global, verificación del soporte, corte, devengo, clasificación y partes relacionadas · Cliente de muestra S.A. · corte 2025-12-31
A4: Comprobante | B4: Proveedor | C4: Cuenta | D4: Fecha documento | E4: Fecha registro | F4: Importe | G4: Documento del ejercicio | H4: Registrado en el ejercicio | I4: Gasto de otro período registrado | J4: Gasto del ejercicio no registrado
A5: FC-101 | B5: Estudio Jurídico Andrade | C5: 5202 | D5: 45726 | E5: 45728 | F5: ='05_Transacciones'!F5 | G5: =IF(D5<='02_Parametros'!$B$5,"Sí","No") | H5: =IF(E5<='02_Parametros'!$B$5,"Sí","No") | I5: =IF(AND(G5="No",H5="Sí"),F5,0) | J5: =IF(AND(G5="Sí",H5="No"),F5,0)
A6: FC-102 | B6: Medios Creativos S.A. | C6: 5301 | D6: 45823 | E6: 45824 | F6: ='05_Transacciones'!F6 | G6: =IF(D6<='02_Parametros'!$B$5,"Sí","No") | H6: =IF(E6<='02_Parametros'!$B$5,"Sí","No") | I6: =IF(AND(G6="No",H6="Sí"),F6,0) | J6: =IF(AND(G6="Sí",H6="No"),F6,0)
A7: FC-104 | B7: Consultores Delta | C7: 5202 | D7: 46011 | E7: 46030 | F7: ='05_Transacciones'!F8 | G7: =IF(D7<='02_Parametros'!$B$5,"Sí","No") | H7: =IF(E7<='02_Parametros'!$B$5,"Sí","No") | I7: =IF(AND(G7="No",H7="Sí"),F7,0) | J7: =IF(AND(G7="Sí",H7="No"),F7,0)
A8: FC-105 | B8: Comisionistas Unidos | C8: 5302 | D8: 46027 | E8: 46021 | F8: ='05_Transacciones'!F9 | G8: =IF(D8<='02_Parametros'!$B$5,"Sí","No") | H8: =IF(E8<='02_Parametros'!$B$5,"Sí","No") | I8: =IF(AND(G8="No",H8="Sí"),F8,0) | J8: =IF(AND(G8="Sí",H8="No"),F8,0)
A9: FC-108 | B9: Juan Pérez | C9: 5202 | D9: 45910 | E9: 45912 | F9: ='05_Transacciones'!F12 | G9: =IF(D9<='02_Parametros'!$B$5,"Sí","No") | H9: =IF(E9<='02_Parametros'!$B$5,"Sí","No") | I9: =IF(AND(G9="No",H9="Sí"),F9,0) | J9: =IF(AND(G9="Sí",H9="No"),F9,0)
A10: FC-109 | B10: Publicistas XYZ | C10: 5301 | D10: 45935 | E10: 45936 | F10: ='05_Transacciones'!F13 | G10: =IF(D10<='02_Parametros'!$B$5,"Sí","No") | H10: =IF(E10<='02_Parametros'!$B$5,"Sí","No") | I10: =IF(AND(G10="No",H10="Sí"),F10,0) | J10: =IF(AND(G10="Sí",H10="No"),F10,0)
A11: FC-110 | B11: Taller Mecánico Ruta | C11: 5201 | D11: 45889 | E11: 45890 | F11: ='05_Transacciones'!F14 | G11: =IF(D11<='02_Parametros'!$B$5,"Sí","No") | H11: =IF(E11<='02_Parametros'!$B$5,"Sí","No") | I11: =IF(AND(G11="No",H11="Sí"),F11,0) | J11: =IF(AND(G11="Sí",H11="No"),F11,0)
A12: FC-111 | B12: Holding Andes S.A. | C12: 5202 | D12: 45787 | E12: 45788 | F12: ='05_Transacciones'!F15 | G12: =IF(D12<='02_Parametros'!$B$5,"Sí","No") | H12: =IF(E12<='02_Parametros'!$B$5,"Sí","No") | I12: =IF(AND(G12="No",H12="Sí"),F12,0) | J12: =IF(AND(G12="Sí",H12="No"),F12,0)
A13: FC-112 | B13: Constructora Rápida | C13: 5601 | D13: 45749 | E13: 45750 | F13: ='05_Transacciones'!F16 | G13: =IF(D13<='02_Parametros'!$B$5,"Sí","No") | H13: =IF(E13<='02_Parametros'!$B$5,"Sí","No") | I13: =IF(AND(G13="No",H13="Sí"),F13,0) | J13: =IF(AND(G13="Sí",H13="No"),F13,0)
A14: FC-113 | B14: Acuerdo judicial ex trabajador | C14: 5202 | D14: 45981 | E14: 45982 | F14: ='05_Transacciones'!F17 | G14: =IF(D14<='02_Parametros'!$B$5,"Sí","No") | H14: =IF(E14<='02_Parametros'!$B$5,"Sí","No") | I14: =IF(AND(G14="No",H14="Sí"),F14,0) | J14: =IF(AND(G14="Sí",H14="No"),F14,0)
A15: FC-114 | B15: Gerente General | C15: 5201 | D15: 45689 | E15: 45690 | F15: ='05_Transacciones'!F18 | G15: =IF(D15<='02_Parametros'!$B$5,"Sí","No") | H15: =IF(E15<='02_Parametros'!$B$5,"Sí","No") | I15: =IF(AND(G15="No",H15="Sí"),F15,0) | J15: =IF(AND(G15="Sí",H15="No"),F15,0)
A16: FC-115 | B16: Banco Relacionado S.A. | C16: 5501 | D16: 45838 | E16: 45839 | F16: ='05_Transacciones'!F19 | G16: =IF(D16<='02_Parametros'!$B$5,"Sí","No") | H16: =IF(E16<='02_Parametros'!$B$5,"Sí","No") | I16: =IF(AND(G16="No",H16="Sí"),F16,0) | J16: =IF(AND(G16="Sí",H16="No"),F16,0)
A17: TOTAL | F17: =SUM(F5:F16) | I17: =SUM(I5:I16) | J17: =SUM(J5:J16)
A19: ⓘ Cómo se calcula esta hoja
A20: Columna | B20: Fórmula (Excel) | C20: Cómo se calcula (sencillo) | D20: Ejemplo con números reales | E20: De dónde viene | F20: Norma
A21: Importe | B21: '='05_Transacciones'!F5 | C21: Trae el importe del comprobante desde la hoja 05 (Transacciones de la muestra); aquí solo aparecen los que no tienen período de servicio. | D21: Fila 1: 12.000,00 → 12.000,00 | E21: hoja «Transacciones de la muestra» | F21: —
A22: Documento del ejercicio | B22: '=IF(D5<='02_Parametros'!$B$5,"Sí","No") | C22: Marca «Sí» si la fecha del documento es igual o anterior al corte de la hoja 02 (Parámetros). | D22: Fila 1: IF(«2025-03-10»<=«2025-12-31»; "Sí"; "No") → Sí | E22: «Fecha documento» (esta hoja), hoja «Parámetros» | F22: —
A23: Registrado en el ejercicio | B23: '=IF(E5<='02_Parametros'!$B$5,"Sí","No") | C23: Marca «Sí» si la fecha de registro contable es igual o anterior al corte de la hoja 02 (Parámetros). | D23: Fila 1: IF(«2025-03-12»<=«2025-12-31»; "Sí"; "No") → Sí | E23: «Fecha registro» (esta hoja), hoja «Parámetros» | F23: —
A24: Gasto de otro período registrado | B24: '=IF(AND(G5="No",H5="Sí"),F5,0) | C24: Si el documento es posterior al corte pero se registró dentro del ejercicio, toma su importe: es gasto del año siguiente; si no, cero. | D24: Fila 1: IF(AND(«Sí»="No"; «Sí»="Sí"); 12.000,00; 0) → 0,00 | E24: «Documento del ejercicio» (esta hoja), «Registrado en el ejercicio» (esta hoja), «Importe» (esta hoja) | F24: —
A25: Gasto del ejercicio no registrado | B25: '=IF(AND(G5="Sí",H5="No"),F5,0) | C25: Si el documento es del ejercicio pero se registró después del corte, toma su importe: es gasto que faltó registrar; si no, cero. | D25: Fila 1: IF(AND(«Sí»="Sí"; «Sí»="No"); 12.000,00; 0) → 0,00 | E25: «Documento del ejercicio» (esta hoja), «Registrado en el ejercicio» (esta hoja), «Importe» (esta hoja) | F25: —

Sheet 08_Devengo
A1: Devengo y gastos anticipados | H1: ⟵ Inicio | I1: ◀ Anterior | J1: Siguiente ▶
A2: Gastos · análisis global, verificación del soporte, corte, devengo, clasificación y partes relacionadas · Cliente de muestra S.A. · corte 2025-12-31
A4: Comprobante | B4: Proveedor | C4: Cuenta | D4: Fecha registro | E4: Servicio desde | F4: Servicio hasta | G4: Importe | H4: Días del servicio | I4: Días hasta el corte | J4: Días posteriores | K4: Gasto del período | L4: Registrado en el ejercicio | M4: Anticipado llevado a resultados | N4: Devengado no registrado
A5: FC-103 | B5: Aseguradora Sur | C5: 5401 | D5: 45840 | E5: 45839 | F5: 46203 | G5: ='05_Transacciones'!F7 | H5: =F5-E5+1 | I5: =MAX(0,MIN(F5,'02_Parametros'!$B$5)-E5+1) | J5: =H5-I5 | K5: =G5*I5/H5 | L5: =IF(D5<='02_Parametros'!$B$5,"Sí","No") | M5: =IF(L5="Sí",G5*J5/H5,0) | N5: =IF(L5="No",K5,0)
A6: FC-106 | B6: Inmobiliaria Norte | C6: 5203 | D6: 46038 | E6: 45992 | F6: 46022 | G6: ='05_Transacciones'!F10 | H6: =F6-E6+1 | I6: =MAX(0,MIN(F6,'02_Parametros'!$B$5)-E6+1) | J6: =H6-I6 | K6: =G6*I6/H6 | L6: =IF(D6<='02_Parametros'!$B$5,"Sí","No") | M6: =IF(L6="Sí",G6*J6/H6,0) | N6: =IF(L6="No",K6,0)
A7: FC-107 | B7: Radio Andina | C7: 5301 | D7: 45964 | E7: 45962 | F7: 46142 | G7: ='05_Transacciones'!F11 | H7: =F7-E7+1 | I7: =MAX(0,MIN(F7,'02_Parametros'!$B$5)-E7+1) | J7: =H7-I7 | K7: =G7*I7/H7 | L7: =IF(D7<='02_Parametros'!$B$5,"Sí","No") | M7: =IF(L7="Sí",G7*J7/H7,0) | N7: =IF(L7="No",K7,0)
A8: TOTAL | G8: =SUM(G5:G7) | K8: =SUM(K5:K7) | M8: =SUM(M5:M7) | N8: =SUM(N5:N7)
A10: ⓘ Cómo se calcula esta hoja
A11: Columna | B11: Fórmula (Excel) | C11: Cómo se calcula (sencillo) | D11: Ejemplo con números reales | E11: De dónde viene | F11: Norma
A12: Importe | B12: '='05_Transacciones'!F7 | C12: Trae el importe del comprobante desde la hoja 05 (Transacciones de la muestra); aquí solo aparecen los que tienen período de servicio. | D12: Fila 1: 7.300,00 → 7.300,00 | E12: hoja «Transacciones de la muestra» | F12: —
A13: Días del servicio | B13: '=F5-E5+1 | C13: Cuenta los días del servicio, desde la fecha de inicio hasta la de fin, incluidos ambos días. | D13: Fila 1: «2026-06-30»-«2025-07-01»+1 → 365 | E13: «Servicio hasta» (esta hoja), «Servicio desde» (esta hoja) | F13: —
A14: Días hasta el corte | B14: '=MAX(0,MIN(F5,'02_Parametros'!$B$5)-E5+1) | C14: Cuenta los días del servicio desde su inicio hasta la fecha de fin o hasta el corte de la hoja 02 (Parámetros), lo que ocurra primero; nunca menos de cero. | D14: Fila 1: MAX(0; MIN(«2026-06-30»; «2025-12-31»)-«2025-07-01»+1) → 184 | E14: «Servicio hasta» (esta hoja), «Servicio desde» (esta hoja), hoja «Parámetros» | F14: —
A15: Días posteriores | B15: '=H5-I5 | C15: Resta los días hasta el corte a los días totales del servicio: son los días que corresponden al año siguiente. | D15: Fila 1: 365-184 → 181 | E15: «Días del servicio» (esta hoja), «Días hasta el corte» (esta hoja) | F15: —
A16: Gasto del período | B16: '=G5*I5/H5 | C16: Reparte el importe en proporción a los días: importe × días hasta el corte ÷ días del servicio. | D16: Fila 1: 7.300,00*184/365 → 3.680,00 | E16: «Importe» (esta hoja), «Días hasta el corte» (esta hoja), «Días del servicio» (esta hoja) | F16: —
A17: Registrado en el ejercicio | B17: '=IF(D5<='02_Parametros'!$B$5,"Sí","No") | C17: Marca «Sí» si la fecha de registro es igual o anterior al corte de la hoja 02 (Parámetros). | D17: Fila 1: IF(«2025-07-02»<=«2025-12-31»; "Sí"; "No") → Sí | E17: «Fecha registro» (esta hoja), hoja «Parámetros» | F17: —
A18: Anticipado llevado a resultados | B18: '=IF(L5="Sí",G5*J5/H5,0) | C18: Si el comprobante se registró en el ejercicio, calcula la parte del importe de los días posteriores al corte (importe × días posteriores ÷ días del servicio): es gasto pagado por anticipado; si no, cero. | D18: Fila 1: IF(«Sí»="Sí"; 7.300,00*181/365; 0) → 3.620,00 | E18: «Registrado en el ejercicio» (esta hoja), «Importe» (esta hoja), «Días posteriores» (esta hoja), «Días del servicio» (esta hoja) | F18: —
A19: Devengado no registrado | B19: '=IF(L5="No",K5,0) | C19: Si el comprobante se registró después del corte, toma el gasto del período: es servicio consumido en el año que no llegó a registrarse; si no, cero. | D19: Fila 1: IF(«Sí»="No"; 3.680,00; 0) → 0,00 | E19: «Registrado en el ejercicio» (esta hoja), «Gasto del período» (esta hoja) | F19: —

Sheet 09_Reclasificaciones
A1: Reclasificaciones | H1: ⟵ Inicio | I1: ◀ Anterior | J1: Siguiente ▶
A2: Gastos · análisis global, verificación del soporte, corte, devengo, clasificación y partes relacionadas · Cliente de muestra S.A. · corte 2025-12-31
A4: Comprobante | B4: Proveedor | C4: Cuenta registrada | D4: Cuenta correcta | E4: Importe | F4: Línea registrada | G4: Línea correcta | H4: Cambia la línea del estado de resultados
A5: FC-110 | B5: Taller Mecánico Ruta | C5: 5201 | D5: 5302 | E5: ='05_Transacciones'!F14 | F5: =IFERROR(INDEX('03_Analisis_global'!$C$5:$C$14,MATCH(C5,'03_Analisis_global'!$A$5:$A$14,0)),"(no en la sumaria)") | G5: =IFERROR(INDEX('03_Analisis_global'!$C$5:$C$14,MATCH(D5,'03_Analisis_global'!$A$5:$A$14,0)),"(no en la sumaria)") | H5: =IF(F5<>G5,"Sí","No")
A6: TOTAL | E6: =SUM(E5:E5)
A8: ⓘ Cómo se calcula esta hoja
A9: Columna | B9: Fórmula (Excel) | C9: Cómo se calcula (sencillo) | D9: Ejemplo con números reales | E9: De dónde viene | F9: Norma
A10: Importe | B10: '='05_Transacciones'!F14 | C10: Trae el importe del comprobante desde la hoja 05 (Transacciones de la muestra); aquí solo aparecen los registrados en una cuenta distinta de la cuenta sugerida. | D10: Fila 1: 2.200,00 → 2.200,00 | E10: hoja «Transacciones de la muestra» | F10: —
A11: Línea registrada | B11: '=IFERROR(INDEX('03_Analisis_global'!$C$5:$C$14,MATCH(C5,'03_Analisis_global'!$A$5:$A$14,0)),"(no en la sumaria)") | C11: Busca en la hoja 03 (Análisis global) la línea del estado de resultados de la cuenta donde se registró; si la cuenta no está en la sumaria, lo indica. | D11: Fila 1: IFERROR(INDEX([«Línea del estado de resultados» de «Análisis global por cuenta (NIA 520)», 10 filas]; MATCH(«5201»; [«Cuenta» de «Análisis global por cuenta (NIA 520)», 10 filas]; 0)); "(no en la sumaria)") → Gastos de administración | E11: «Cuenta registrada» (esta hoja), hoja «Análisis global por cuenta (NIA 520)» | F11: —
A12: Línea correcta | B12: '=IFERROR(INDEX('03_Analisis_global'!$C$5:$C$14,MATCH(D5,'03_Analisis_global'!$A$5:$A$14,0)),"(no en la sumaria)") | C12: Busca en la hoja 03 (Análisis global) la línea del estado de resultados de la cuenta correcta; si no está en la sumaria, lo indica. | D12: Fila 1: IFERROR(INDEX([«Línea del estado de resultados» de «Análisis global por cuenta (NIA 520)», 10 filas]; MATCH(«5302»; [«Cuenta» de «Análisis global por cuenta (NIA 520)», 10 filas]; 0)); "(no en la sumaria)") → Gastos de ventas | E12: «Cuenta correcta» (esta hoja), hoja «Análisis global por cuenta (NIA 520)» | F12: —
A13: Cambia la línea del estado de resultados | B13: '=IF(F5<>G5,"Sí","No") | C13: Marca «Sí» cuando la línea registrada y la correcta son distintas, es decir, cuando la reclasificación cambia la presentación en el estado de resultados. | D13: Fila 1: IF(«Gastos de administración»<>«Gastos de ventas»; "Sí"; "No") → Sí | E13: «Línea registrada» (esta hoja), «Línea correcta» (esta hoja) | F13: —

Sheet 10_Partes_relacionadas
A1: Partes relacionadas | H1: ⟵ Inicio | I1: ◀ Anterior | J1: Siguiente ▶
A2: Gastos · análisis global, verificación del soporte, corte, devengo, clasificación y partes relacionadas · Cliente de muestra S.A. · corte 2025-12-31
A4: Categoría | B4: Transacciones | C4: Importe del período | D4: Referencia
A5: Dominante | B5: =COUNTIFS('05_Transacciones'!$L$5:$L$19,"Sí",'05_Transacciones'!$P$5:$P$19,"Sí",'05_Transacciones'!$M$5:$M$19,A5) | C5: =SUMIFS('05_Transacciones'!$F$5:$F$19,'05_Transacciones'!$L$5:$L$19,"Sí",'05_Transacciones'!$P$5:$P$19,"Sí",'05_Transacciones'!$M$5:$M$19,A5) | D5: NIC 24 párr. 19
A6: Control conjunto o influencia significativa | B6: =COUNTIFS('05_Transacciones'!$L$5:$L$19,"Sí",'05_Transacciones'!$P$5:$P$19,"Sí",'05_Transacciones'!$M$5:$M$19,A6) | C6: =SUMIFS('05_Transacciones'!$F$5:$F$19,'05_Transacciones'!$L$5:$L$19,"Sí",'05_Transacciones'!$P$5:$P$19,"Sí",'05_Transacciones'!$M$5:$M$19,A6) | D6: NIC 24 párr. 19
A7: Dependiente | B7: =COUNTIFS('05_Transacciones'!$L$5:$L$19,"Sí",'05_Transacciones'!$P$5:$P$19,"Sí",'05_Transacciones'!$M$5:$M$19,A7) | C7: =SUMIFS('05_Transacciones'!$F$5:$F$19,'05_Transacciones'!$L$5:$L$19,"Sí",'05_Transacciones'!$P$5:$P$19,"Sí",'05_Transacciones'!$M$5:$M$19,A7) | D7: NIC 24 párr. 19
A8: Asociada | B8: =COUNTIFS('05_Transacciones'!$L$5:$L$19,"Sí",'05_Transacciones'!$P$5:$P$19,"Sí",'05_Transacciones'!$M$5:$M$19,A8) | C8: =SUMIFS('05_Transacciones'!$F$5:$F$19,'05_Transacciones'!$L$5:$L$19,"Sí",'05_Transacciones'!$P$5:$P$19,"Sí",'05_Transacciones'!$M$5:$M$19,A8) | D8: NIC 24 párr. 19
A9: Negocio conjunto | B9: =COUNTIFS('05_Transacciones'!$L$5:$L$19,"Sí",'05_Transacciones'!$P$5:$P$19,"Sí",'05_Transacciones'!$M$5:$M$19,A9) | C9: =SUMIFS('05_Transacciones'!$F$5:$F$19,'05_Transacciones'!$L$5:$L$19,"Sí",'05_Transacciones'!$P$5:$P$19,"Sí",'05_Transacciones'!$M$5:$M$19,A9) | D9: NIC 24 párr. 19
A10: Personal clave | B10: =COUNTIFS('05_Transacciones'!$L$5:$L$19,"Sí",'05_Transacciones'!$P$5:$P$19,"Sí",'05_Transacciones'!$M$5:$M$19,A10) | C10: =SUMIFS('05_Transacciones'!$F$5:$F$19,'05_Transacciones'!$L$5:$L$19,"Sí",'05_Transacciones'!$P$5:$P$19,"Sí",'05_Transacciones'!$M$5:$M$19,A10) | D10: NIC 24 párr. 19
A11: Otra | B11: =COUNTIFS('05_Transacciones'!$L$5:$L$19,"Sí",'05_Transacciones'!$P$5:$P$19,"Sí",'05_Transacciones'!$M$5:$M$19,A11) | C11: =SUMIFS('05_Transacciones'!$F$5:$F$19,'05_Transacciones'!$L$5:$L$19,"Sí",'05_Transacciones'!$P$5:$P$19,"Sí",'05_Transacciones'!$M$5:$M$19,A11) | D11: NIC 24 párr. 19
A12: Sin categoría válida | B12: =COUNTIFS('05_Transacciones'!$L$5:$L$19,"Sí",'05_Transacciones'!$P$5:$P$19,"Sí")-SUM(B5:B11) | C12: =SUMIFS('05_Transacciones'!$F$5:$F$19,'05_Transacciones'!$L$5:$L$19,"Sí",'05_Transacciones'!$P$5:$P$19,"Sí")-SUM(C5:C11) | D12: Categoría vacía o no prevista para el marco
A13: TOTAL | B13: =SUM(B5:B12) | C13: =SUM(C5:C12)
A15: ⓘ Cómo se calcula esta hoja
A16: Columna | B16: Fórmula (Excel) | C16: Cómo se calcula (sencillo) | D16: Ejemplo con números reales | E16: De dónde viene | F16: Norma
