Workbook

Sheet 00_Inicio
B2: AuditConsulting Auditores Cía. Ltda. · AUDIT-IA
B4: Impuesto corriente y diferido
B6: Cliente | C6: Cliente de muestra S.A. | D6: RUC | E6: 1790000000001
B7: Marco contable | C7: NIIF completas | D7: Fecha de corte | E7: 2025-12-31
B8: Preparó | C8: Ejercicio modelo | D8: Revisó | E8: Pendiente
B10: INDICADORES CLAVE
B11: Ajuste neto al gasto por impuesto en resultados (+ más gasto) | C11: Problemas encontrados
B12: 16412.5 | C12: 12
B15: IR A LA CÉDULA
B16: Carátula | C16: Programa | D16: Base técnica | E16: Resumen
B17: Parámetros | C17: Conciliación tributaria | D17: Impuesto corriente | E17: Pérdidas tributarias
B18: Diferencias temporarias y diferido | C18: Tasa de reversión | D18: Recuperabilidad del activo diferido | E18: Movimiento: resultados y ORI
B19: Compensación y presentación | C19: Tasa efectiva (NIC 12.81 c) | D19: Ajustes propuestos | E19: Participación atribuible a exentos
B20: Asientos propuestos | C20: Problemas encontrados | D20: Conclusión | E20: Control de revisión
B22: PANORAMA | N22: Datos de los gráficos (fórmulas a las cédulas)
N23: Cifras del resumen | O23: Importe (USD)
N24: ='01_Resumen'!A5 | O24: ='01_Resumen'!B5
N25: ='01_Resumen'!A6 | O25: ='01_Resumen'!B6
N26: ='01_Resumen'!A7 | O26: ='01_Resumen'!B7
N27: ='01_Resumen'!A8 | O27: ='01_Resumen'!B8
N28: ='01_Resumen'!A9 | O28: ='01_Resumen'!B9
N29: ='01_Resumen'!A10 | O29: ='01_Resumen'!B10
N30: ='01_Resumen'!A11 | O30: ='01_Resumen'!B11
N31: ='01_Resumen'!A12 | O31: ='01_Resumen'!B12
N32: ='01_Resumen'!A13 | O32: ='01_Resumen'!B13
N33: ='01_Resumen'!A14 | O33: ='01_Resumen'!B14
N34: ='01_Resumen'!A15 | O34: ='01_Resumen'!B15
N35: ='01_Resumen'!A16 | O35: ='01_Resumen'!B16
... N47: ='01_Resumen'!A28 | O47: ='01_Resumen'!B28
N48: ='01_Resumen'!A31 | O48: ='01_Resumen'!B31
N50: Hallazgos de mayor impacto | O50: Importe (USD)
N51: Falta compensar | O51: =SUMIFS('15_Problemas'!$C$5:$C$16,'15_Problemas'!$A$5:$A$16,"FALTA_COMPENSAR",'15_Problemas'!$C$5:$C$16,">0")-SUMIFS('15_Problemas'!$C$5:$C$16,'15_Problemas'!$A$5:$A$16,"FALTA_COMPENSAR",'15_Problemas'!$C$5:$C$16,"<0")
N52: Perdidas vencidas | O52: =SUMIFS('15_Problemas'!$C$5:$C$16,'15_Problemas'!$A$5:$A$16,"PERDIDAS_VENCIDAS",'15_Problemas'!$C$5:$C$16,">0")-SUMIFS('15_Problemas'!$C$5:$C$16,'15_Problemas'!$A$5:$A$16,"PERDIDAS_VENCIDAS",'15_Problemas'!$C$5:$C$16,"<0")
N53: No deducibles omitidos | O53: =SUMIFS('15_Problemas'!$C$5:$C$16,'15_Problemas'!$A$5:$A$16,"NO_DEDUCIBLES_OMITIDOS",'15_Problemas'!$C$5:$C$16,">0")-SUMIFS('15_Problemas'!$C$5:$C$16,'15_Problemas'!$A$5:$A$16,"NO_DEDUCIBLES_OMITIDOS",'15_Problemas'!$C$5:$C$16,"<0")
N54: Perdidas sobre limite | O54: =SUMIFS('15_Problemas'!$C$5:$C$16,'15_Problemas'!$A$5:$A$16,"PERDIDAS_SOBRE_LIMITE",'15_Problemas'!$C$5:$C$16,">0")-SUMIFS('15_Problemas'!$C$5:$C$16,'15_Problemas'!$A$5:$A$16,"PERDIDAS_SOBRE_LIMITE",'15_Problemas'!$C$5:$C$16,"<0")
N55: Diferido mal medido | O55: =SUMIFS('15_Problemas'!$C$5:$C$16,'15_Problemas'!$A$5:$A$16,"DIFERIDO_MAL_MEDIDO",'15_Problemas'!$C$5:$C$16,">0")-SUMIFS('15_Problemas'!$C$5:$C$16,'15_Problemas'!$A$5:$A$16,"DIFERIDO_MAL_MEDIDO",'15_Problemas'!$C$5:$C$16,"<0")
N56: Tasa efectiva inexplicada | O56: =SUMIFS('15_Problemas'!$C$5:$C$16,'15_Problemas'!$A$5:$A$16,"TASA_EFECTIVA_INEXPLICADA",'15_Problemas'!$C$5:$C$16,">0")-SUMIFS('15_Problemas'!$C$5:$C$16,'15_Problemas'!$A$5:$A$16,"TASA_EFECTIVA_INEXPLICADA",'15_Problemas'!$C$5:$C$16,"<0")
N57: Dta perdidas exceso | O57: =SUMIFS('15_Problemas'!$C$5:$C$16,'15_Problemas'!$A$5:$A$16,"DTA_PERDIDAS_EXCESO",'15_Problemas'!$C$5:$C$16,">0")-SUMIFS('15_Problemas'!$C$5:$C$16,'15_Problemas'!$A$5:$A$16,"DTA_PERDIDAS_EXCESO",'15_Problemas'!$C$5:$C$16,"<0")
N58: Otros (5 tipos) | O58: =SUMIF('15_Problemas'!$C$5:$C$16,">0")-SUMIF('15_Problemas'!$C$5:$C$16,"<0")-((SUMIFS('15_Problemas'!$C$5:$C$16,'15_Problemas'!$A$5:$A$16,"FALTA_COMPENSAR",'15_Problemas'!$C$5:$C$16,">0")-SUMIFS('15_Problemas'!$C$5:$C$16,'15_Problemas'!$A$5:$A$16,"FALTA_COMPENSAR",'15_Problemas'!$C$5:$C$16,"<0"))+(SUMIFS('15_Problemas'!$C$5:$C$16,'15_Problemas'!$A$5:$A$16,"PERDIDAS_VENCIDAS",'15_Problemas'!$C$5:$C$16,">0")-SUMIFS('15_Problemas'!$C$5:$C$16,'15_Problemas'!$A$5:$A$16,"PERDIDAS_VENCIDAS",'15_Problemas'!$C$5:$C$16,"<0"))+(SUMIFS('15_Problemas'!$C$5:$C$16,'15_Problemas'!$A$5:$A$16,"NO_DEDUCIBLES_OMITIDOS",'15_Problemas'!$C$5:$C$16,">0")-SUMIFS('15_Problemas'!$C$5:$C$16,'15_Problemas'!$A$5:$A$16,"NO_DEDUCIBLES_OMITIDOS",'15_Problemas'!$C$5:$C$16,"<0"))+(SUMIFS('15_Problemas'!$C$5:$C$16,'15_Problemas'!$A$5:$A$16,"PERDIDAS_SOBRE_LIMITE",'15_Problemas'!$C$5:$C$16,">0")-SUMIFS('15_Problemas'!$C$5:$C$16,'15_Problemas'!$A$5:$A$16,"PERDIDAS_SOBRE_LIMITE",'15_Problemas'!$C$5:$C$16,"<0"))+(SUMIFS('15_Problemas'!$C$5:$C$16,'15_Problemas'!$A$5:$A$16,"DIFERIDO_MAL_MEDIDO",'15_Problemas'!$C$5:$C$16,">0")-SUMIFS('15_Problemas'!$C$5:$C$16,'15_Problemas'!$A$5:$A$16,"DIFERIDO_MAL_MEDIDO",'15_Problemas'!$C$5:$C$16,"<0"))+(SUMIFS('15_Problemas'!$C$5:$C$16,'15_Problemas'!$A$5:$A$16,"TASA_EFECTIVA_INEXPLICADA",'15_Problemas'!$C$5:$C$16,">0")-SUMIFS('15_Problemas'!$C$5:$C$16,'15_Problemas'!$A$5:$A$16,"TASA_EFECTIVA_INEXPLICADA",'15_Problemas'!$C$5:$C$16,"<0"))+(SUMIFS('15_Problemas'!$C$5:$C$16,'15_Problemas'!$A$5:$A$16,"DTA_PERDIDAS_EXCESO",'15_Problemas'!$C$5:$C$16,">0")-SUMIFS('15_Problemas'!$C$5:$C$16,'15_Problemas'!$A$5:$A$16,"DTA_PERDIDAS_EXCESO",'15_Problemas'!$C$5:$C$16,"<0")))

Sheet 00_Caratula
A1: Carátula | H1: ⟵ Inicio | J1: Siguiente ▶
A2: Impuesto corriente y diferido · Cliente de muestra S.A. · corte 2025-12-31
A4: Concepto | B4: Detalle
A5: Firma | B5: AuditConsulting Auditores Cía. Ltda.
A6: Cliente | B6: Cliente de muestra S.A.
A7: RUC | B7: 1790000000001
A8: Ejercicio | B8: 2025
A9: Fecha de corte | B9: 2025-12-31
A10: Marco contable | B10: NIIF completas
A11: Herramienta | B11: Impuesto corriente y diferido
A12: Rubro | B12: Impuestos
A13: Motor | B13: impuesto_corriente_diferido 1.0
A14: Versión del papel | B14: v1
A15: Estado | B15: MUESTRA
... A17: Revisó | B17: Pendiente
A18: Aprobó
A19: Fecha de aprobación
A20: Huella de la ejecución (SHA-256)

Sheet 00_Programa
A1: Programa | H1: ⟵ Inicio | I1: ◀ Anterior | J1: Siguiente ▶
A2: Impuesto corriente y diferido · Cliente de muestra S.A. · corte 2025-12-31
A4: Código | B4: Objetivo | C4: Afirmación | D4: Procedimiento | E4: Evidencia | F4: Criterio | G4: Referencia
A5: TAX-01 | B5: Conciliación tributaria | C5: Exactitud / Integridad | D5: Cotejar la conciliación con el F-101 y el mayor; recalcular participación y revisar gastos no deducibles | E5: F-101, mayor, soporte de gastos | F5: Base imponible recalculada igual a la declarada o diferencia ajustada | G5: LRTI arts. 9, 10 · NIA 500
A6: TAX-02 | B6: Impuesto corriente | C6: Valoración | D6: Recalcular el impuesto causado con la tarifa vigente y el saldo por pagar neto de retenciones, anticipos y crédito | E6: F-101, comprobantes de retención | F6: Diferencia cero | G6: NIC 12.12, 46 · PYMES 29
A7: TAX-03 | B7: Pérdidas tributarias | C7: Exactitud | D7: Recalcular el límite anual, el plazo y el saldo por año de origen | E7: Declaraciones de años anteriores | F7: Amortización dentro del límite y del plazo | G7: LRTI art. 11 · NIC 12.34
A8: TAX-04 | B8: Bases fiscales y diferencias temporarias | C8: Valoración / Integridad | D8: Comparar libros NIIF con la base fiscal por partida y medir activo y pasivo diferidos | E8: Auxiliares NIIF y fiscales | F8: Diferido requerido igual al registrado | G8: NIC 12.5, 15, 24 · PYMES 29
A9: TAX-05 | B9: Recuperabilidad del activo diferido | C9: Valoración | D9: Evaluar proyecciones fiscales y el Reglamento LRTI, art. innumerado a continuación del art. 28 (num. 5: provisiones distintas de cuentas incobrables y desmantelamiento, utilizables cuando se paguen —jubilación y desahucio solo por la parte no deducible, interpretación: LRTI art. 10 num. 13—; num. 8: pérdidas tributarias); revisar el importe en libros al cierre | E9: Proyecciones, historial de resultados fiscales | F9: Activo diferido solo por lo probable y admitido | G9: NIC 12.24, 34–36, 56 · Reglamento LRTI, art. innumerado a continuación del art. 28 (num. 5: provisiones distintas de cuentas incobrables y desmantelamiento, utilizables cuando se paguen —jubilación y desahucio solo por la parte no deducible, interpretación: LRTI art. 10 num. 13—; num. 8: pérdidas tributarias)
A10: TAX-06 | B10: Tasa de reversión | C10: Valoración | D10: Comparar la tasa usada con la aprobada al cierre para el año de reversión | E10: Ley vigente y reformas publicadas | F10: Tasa esperada del año de reversión (aprobada + recargo del art. 37), sin descuento | G10: NIC 12.47, 49, 53 · LRTI art. 37
A11: TAX-07 | B11: Resultados frente a ORI y compensación | C11: Presentación | D11: Separar el movimiento por origen y probar la compensación de saldos | E11: Estados financieros | F11: Presentación conforme | G11: NIC 12.58, 61A, 71, 74
A12: TAX-08 | B12: Tasa efectiva | C12: Exactitud / Presentación | D12: Conciliar el gasto con el resultado contable × tasa aplicable | E12: Estado de resultados, nota de impuestos | F12: Diferencia dentro del umbral | G12: NIC 12.81 c)

Sheet 00_Fuentes
A1: Base técnica | H1: ⟵ Inicio | I1: ◀ Anterior | J1: Siguiente ▶
A2: Impuesto corriente y diferido · Cliente de muestra S.A. · corte 2025-12-31
A4: Categoría | B4: Documento | C4: Párrafos | D4: URL | E4: Verificada
A5: NIA · NIA 500 | B5: Exactitud e integridad de la conciliación tributaria frente al F-101 y al mayor. | C5: párr. 9
A6: NIA · NIA 540 (Revisada) | B6: La probabilidad de ganancias fiscales futuras y la tasa de reversión son supuestos de una estimación. | C6: párr. 13 y 24
A7: NIA · NIA 250 (Revisada) | B7: Cumplimiento de disposiciones legales tributarias (LRTI y Reglamento). | C7: párr. 14
A8: NIA · NIA 330 | B8: Procedimientos sustantivos sobre saldos y transacciones materiales. | C8: párr. 18
A9: NIA · NIA 450 | B9: Acumular las incorrecciones (ajustes propuestos) y comunicarlas. | C9: párr. 5 y 8

Sheet 01_Resumen
A1: Resumen | H1: ⟵ Inicio | I1: ◀ Anterior | J1: Siguiente ▶
A2: Impuesto corriente y diferido · Cliente de muestra S.A. · corte 2025-12-31
A4: Concepto | B4: Importe
A5: Base imponible según el cliente (total de control) | B5: ='04_Impuesto_corriente'!B17
A6: Base imponible auditada | B6: ='04_Impuesto_corriente'!C17
A7: Impuesto corriente recalculado | B7: ='12_Ajustes'!B5
A8: Impuesto corriente registrado | B8: ='12_Ajustes'!B6
A9: Ajuste al impuesto corriente | B9: ='12_Ajustes'!B7
A10: Impuesto por pagar (− saldo a favor) recalculado | B10: ='12_Ajustes'!B8
A11: Impuesto por pagar registrado | B11: ='12_Ajustes'!B9
A12: Ajuste al saldo de impuesto corriente | B12: ='12_Ajustes'!B10
A13: Amortización de pérdidas en exceso | B13: ='12_Ajustes'!B11
A14: Pérdidas vencidas sin amortizar | B14: ='12_Ajustes'!B12
A15: Activo por impuesto diferido requerido | B15: ='12_Ajustes'!B13
A16: Pasivo por impuesto diferido requerido | B16: ='12_Ajustes'!B14
A17: Activo diferido no reconocido (revelar, NIC 12.81 e) | B17: ='12_Ajustes'!B15
A18: Impuesto diferido neto requerido (+ activo) | B18: ='12_Ajustes'!B16
... A23: Gasto (ingreso) por impuesto diferido requerido en resultados | B23: ='12_Ajustes'!B21
A24: Gasto (ingreso) por impuesto diferido registrado | B24: ='12_Ajustes'!B23
A25: Gasto diferido llevado a resultados que corresponde a ORI u otro origen | B25: ='12_Ajustes'!B24
A26: Gasto total por impuesto requerido | B26: ='12_Ajustes'!B25
A27: Gasto total por impuesto registrado | B27: ='12_Ajustes'!B26
A28: Gasto registrado no explicado por la conciliación | B28: ='12_Ajustes'!B27
A29: Tasa efectiva requerida (%) | B29: ='11_Tasa_efectiva'!C18*100
A30: Tasa efectiva registrada (%) | B30: ='11_Tasa_efectiva'!C19*100
A31: Ajuste neto al gasto por impuesto en resultados (+ más gasto) | B31: ='12_Ajustes'!B28
A33: ⓘ Cómo se calcula esta hoja
A34: Columna | B34: Fórmula (Excel) | C34: Cómo se calcula (sencillo) | D34: Ejemplo con números reales | E34: De dónde viene | F34: Norma
A35: Importe | B35: '='04_Impuesto_corriente'!B17 | C35: Trae cada importe de la hoja 12 (Ajustes propuestos), concepto por concepto; las bases imponibles vienen de la hoja 04 (Impuesto corriente) y las tasas efectivas de la hoja 11 (Tasa efectiva), multiplicadas por 100 para mostrarlas en %. | D35: Fila 1: 624.550,00 → 624.550,00 | E35: hoja «Impuesto corriente» | F35: —

Sheet 02_Parametros
A1: Parámetros | H1: ⟵ Inicio | I1: ◀ Anterior | J1: Siguiente ▶
A2: Impuesto corriente y diferido · Cliente de muestra S.A. · corte 2025-12-31
A4: Parámetro | B4: Valor | C4: Sustento
A5: Corte del ejercicio | B5: 46022 | C5: Ficha del encargo
A6: Marco contable | B6: NIIF completas | C6: NIC 12 — mismo cálculo en ambos marcos; cambian las citas
A7: Tarifa general del impuesto a la renta (%) | B7: 25 | C7: LRTI art. 37 — vigente al corte
A8: Puntos adicionales (paraísos fiscales / composición societaria) | B8: 3 | C8: LRTI art. 37 — vigente al corte
A9: Composición societaria en paraísos fiscales o no informada (%) | B9: 0 | C9: Reglamento art. 51: el recargo grava esa misma proporción de la base y el 100 % cuando llega al 50 % — aplicada 0.0 %
A10: Participación de trabajadores (%) | B10: 15 | C10: Código del Trabajo art. 97 — vigente al corte
A11: Ingreso exento bruto del ejercicio (antes de gastos atribuibles) | B11: 60000 | C11: Reglamento LRTI art. 46 num. 5: «el 15% de tales ingresos» — vigente al corte; vacío: no se recalcula la participación atribuible
A12: Participación atribuible a exentos informada por el cliente | B12: 8550 | C12: Papel de trabajo del cliente / casillero del F-101
A13: Límite anual de amortización de pérdidas (%) | B13: 25 | C13: LRTI art. 11 — vigente al corte
A14: Plazo para amortizar pérdidas (años) | B14: 5 | C14: LRTI art. 11 — vigente al corte
A15: Tasa aprobada para años futuros (%) | C15: NIC 12.47, 53 — tasa aprobada o prácticamente aprobada al cierre
A16: Año desde el que rige la tasa futura | C16: Ley publicada al cierre
A17: Ley admite diferido por pérdidas | B17: Sí | C17: Reglamento LRTI, art. innumerado a continuación del art. 28 (num. 5: provisiones distintas de cuentas incobrables y desmantelamiento, utilizables cuando se paguen —jubilación y desahucio solo por la parte no deducible, interpretación: LRTI art. 10 num. 13—; num. 8: pérdidas tributarias)
A18: Probable ganancia fiscal para las pérdidas | B18: Sí | C18: NIC 12.35–36 — proyecciones fiscales
A19: Retenciones en la fuente del ejercicio | B19: 70000 | C19: Comprobantes de retención / F-101
A20: Anticipos pagados | B20: 10000 | C20: F-115 / F-101
A21: Crédito tributario de años anteriores | B21: 5000 | C21: F-101
A22: Gasto por impuesto corriente registrado | B22: 156137.5 | C22: Mayor
A23: Impuesto por pagar registrado (+) / saldo a favor (−) | B23: 71137.5 | C23: Estado de situación financiera
A24: Gasto (ingreso) por impuesto diferido registrado | B24: 19700 | C24: Estado de resultados
A25: Activo diferido por pérdidas al inicio | B25: 45000 | C25: Mayor
A26: Activo diferido por pérdidas al cierre | B26: 20000 | C26: Mayor
A27: Derecho legal de compensar (misma autoridad) | B27: Sí | C27: NIC 12.71, 74
A28: Activo por impuesto diferido presentado | B28: 76300 | C28: Estado de situación financiera
A29: Pasivo por impuesto diferido presentado | B29: 70000 | C29: Estado de situación financiera
A30: Diferencia tolerable en la tasa efectiva (p.p.) | B30: 1 | C30: Juicio del auditor (materialidad)

Sheet 03_Conciliacion
A1: Conciliación tributaria | H1: ⟵ Inicio | I1: ◀ Anterior | J1: Siguiente ▶
A2: Impuesto corriente y diferido · Cliente de muestra S.A. · corte 2025-12-31
A4: Renglón | B4: Concepto | C4: Tipo | D4: Signo exigido | E4: Importe según cliente | F4: Importe según auditor | G4: Importe auditado | H4: Diferencia
A5: 801 | B5: Utilidad del ejercicio | C5: utilidad | D5: ± según signo | E5: 1000000 | G5: =IF(F5<>"",F5,E5) | H5: =G5-E5
A6: 803 | B6: (-) Participación a trabajadores | C6: participacion | D6: − resta | E6: -150000 | G6: =IF(F6<>"",F6,E6) | H6: =G6-E6
A7: 804 | B7: (-) Dividendos exentos | C7: exentos | D7: − resta | E7: -60000 | G7: =IF(F7<>"",F7,E7) | H7: =G7-E7
A8: 806 | B8: (+) Gastos no deducibles locales (multas, intereses) | C8: no_deducibles | D8: '+ suma | E8: 45000 | G8: =IF(F8<>"",F8,E8) | H8: =G8-E8
A9: 807 | B9: (+) Gastos incurridos para generar ingresos exentos | C9: gastos_exentos | D9: '+ suma | E9: 3000 | G9: =IF(F9<>"",F9,E9) | H9: =G9-E9
A10: 808 | B10: (+) Participación atribuible a ingresos exentos | C10: participacion_exentos | D10: '+ suma | E10: 8550 | G10: =IF(F10<>"",F10,E10) | H10: =G10-E10
A11: 811 | B11: (-) Deducción por incremento neto de empleos | C11: deducciones | D11: − resta | E11: -12000 | G11: =IF(F11<>"",F11,E11) | H11: =G11-E11
A12: 814 | B12: (-) Amortización de pérdidas tributarias | C12: perdidas | D12: − resta | E12: -240000 | G12: =IF(F12<>"",F12,E12) | H12: =G12-E12
A13: 816 | B13: (+) Generación de diferencias temporarias (jubilación, garantías) | C13: otros | D13: ± según signo | E13: 30000 | G13: =IF(F13<>"",F13,E13) | H13: =G13-E13
A14: AUD-1 | B14: Gastos sin comprobante de venta válido (hallazgo) | C14: no_deducibles | D14: '+ suma | E14: 0 | F14: 20000 | G14: =IF(F14<>"",F14,E14) | H14: =G14-E14
A15: TOTAL | E15: =SUM(E5:E14) | G15: =SUM(G5:G14) | H15: =SUM(H5:H14)
A17: ⓘ Cómo se calcula esta hoja
A18: Columna | B18: Fórmula (Excel) | C18: Cómo se calcula (sencillo) | D18: Ejemplo con números reales | E18: De dónde viene | F18: Norma
A19: Importe auditado | B19: '=IF(F5<>"",F5,E5) | C19: Usa el importe según el auditor cuando lo hay y, si está vacío, conserva el importe según el cliente. | D19: Fila 1: IF((vacío)<>""; (vacío); 1.000.000,00) → 1.000.000,00 | E19: «Importe según auditor» (esta hoja), «Importe según cliente» (esta hoja) | F19: —
A20: Diferencia | B20: '=G5-E5 | C20: Resta el importe según el cliente al importe auditado: muestra cuánto cambió el auditor en cada renglón. | D20: Fila 1: 1.000.000,00-1.000.000,00 → 0,00 | E20: «Importe auditado» (esta hoja), «Importe según cliente» (esta hoja) | F20: —

Sheet 04_Impuesto_corriente
A1: Impuesto corriente | H1: ⟵ Inicio | I1: ◀ Anterior | J1: Siguiente ▶
A2: Impuesto corriente y diferido · Cliente de muestra S.A. · corte 2025-12-31
A4: Concepto | B4: Según cliente | C4: Auditado | D4: Diferencia | E4: Referencia
A5: Utilidad (pérdida) contable antes de participación e impuesto | B5: =SUMIF('03_Conciliacion'!$C$5:$C$14,"utilidad",'03_Conciliacion'!$E$5:$E$14) | C5: =SUMIF('03_Conciliacion'!$C$5:$C$14,"utilidad",'03_Conciliacion'!$G$5:$G$14) | D5: =C5-B5 | E5: 03_Conciliacion
A6: (−) Participación trabajadores | B6: =SUMIF('03_Conciliacion'!$C$5:$C$14,"participacion",'03_Conciliacion'!$E$5:$E$14) | C6: =-MAX(C5,0)*'02_Parametros'!$B$10/100 | D6: =C6-B6 | E6: Recalculada: % × utilidad
A7: (−) Ingresos exentos | B7: =SUMIF('03_Conciliacion'!$C$5:$C$14,"exentos",'03_Conciliacion'!$E$5:$E$14) | C7: =SUMIF('03_Conciliacion'!$C$5:$C$14,"exentos",'03_Conciliacion'!$G$5:$G$14) | D7: =C7-B7 | E7: LRTI art. 9 (texto oficial hasta 2-jul-2021: contrastar reformas posteriores)
A8: (+) Gastos no deducibles | B8: =SUMIF('03_Conciliacion'!$C$5:$C$14,"no_deducibles",'03_Conciliacion'!$E$5:$E$14) | C8: =SUMIF('03_Conciliacion'!$C$5:$C$14,"no_deducibles",'03_Conciliacion'!$G$5:$G$14) | D8: =C8-B8 | E8: LRTI art. 10
A9: (+) Gastos atribuibles a ingresos exentos | B9: =SUMIF('03_Conciliacion'!$C$5:$C$14,"gastos_exentos",'03_Conciliacion'!$E$5:$E$14) | C9: =SUMIF('03_Conciliacion'!$C$5:$C$14,"gastos_exentos",'03_Conciliacion'!$G$5:$G$14) | D9: =C9-B9 | E9: Reglamento LRTI art. 46 num. 4 (y art. 47, prorrateo)
A10: (+) Participación atribuible a ingresos exentos | B10: =SUMIF('03_Conciliacion'!$C$5:$C$14,"participacion_exentos",'03_Conciliacion'!$E$5:$E$14) | C10: =IF('13_Partic_exentos'!B8="",B10,'13_Partic_exentos'!B8) | D10: =C10-B10 | E10: Reglamento LRTI art. 46 num. 5: «el 15% de tales ingresos» (base bruta) — ver 13_Partic_exentos; sin el ingreso exento bruto informado el recálculo queda bloqueado y se conserva el importe del cliente
A11: (−) Deducciones adicionales | B11: =SUMIF('03_Conciliacion'!$C$5:$C$14,"deducciones",'03_Conciliacion'!$E$5:$E$14) | C11: =SUMIF('03_Conciliacion'!$C$5:$C$14,"deducciones",'03_Conciliacion'!$G$5:$G$14) | D11: =C11-B11 | E11: LRTI art. 10
A12: (±) Otras partidas de conciliación | B12: =SUMIF('03_Conciliacion'!$C$5:$C$14,"otros",'03_Conciliacion'!$E$5:$E$14) | C12: =SUMIF('03_Conciliacion'!$C$5:$C$14,"otros",'03_Conciliacion'!$G$5:$G$14) | D12: =C12-B12 | E12: 03_Conciliacion
A13: Utilidad gravable antes de amortizar pérdidas | B13: =SUM(B5:B12) | C13: =SUM(C5:C12) | D13: =C13-B13
A14: Límite de amortización de pérdidas | B14: =MAX(B13,0)*'02_Parametros'!$B$13/100 | C14: =MAX(C13,0)*'02_Parametros'!$B$13/100 | D14: =C14-B14 | E14: LRTI art. 11
A15: Pérdidas disponibles no vencidas | B15: =SUM('05_Perdidas'!$G$5:$G$8) | C15: =SUM('05_Perdidas'!$G$5:$G$8) | D15: =C15-B15 | E15: 05_Perdidas
A16: (−) Amortización de pérdidas | B16: =SUMIF('03_Conciliacion'!$C$5:$C$14,"perdidas",'03_Conciliacion'!$E$5:$E$14) | C16: =-MIN(-SUMIF('03_Conciliacion'!$C$5:$C$14,"perdidas",'03_Conciliacion'!$G$5:$G$14),C14,C15) | D16: =C16-B16 | E16: mín(solicitada, límite, disponible)
A17: Base imponible | B17: =B13+B16 | C17: =C13+C16 | D17: =C17-B17 | E17: Total de control = suma de 03_Conciliacion
A18: Tarifa aplicable (%) = general + puntos × proporción (100 % si ≥ 50 %) | B18: ='02_Parametros'!$B$7+'02_Parametros'!$B$8*IF('02_Parametros'!$B$9>=50,100,'02_Parametros'!$B$9)/100 | C18: ='02_Parametros'!$B$7+'02_Parametros'!$B$8*IF('02_Parametros'!$B$9>=50,100,'02_Parametros'!$B$9)/100 | D18: =C18-B18 | E18: LRTI art. 37; Reglamento art. 51
A19: Impuesto a la renta causado | B19: =MAX(B17,0)*B18/100 | C19: =MAX(C17,0)*C18/100 | D19: =C19-B19 | E19: NIC 12.12–14, 46
A20: (−) Retenciones en la fuente | B20: ='02_Parametros'!$B$19 | C20: ='02_Parametros'!$B$19 | D20: =C20-B20 | E20: Parámetros
A21: (−) Anticipos pagados | B21: ='02_Parametros'!$B$20 | C21: ='02_Parametros'!$B$20 | D21: =C21-B21 | E21: Parámetros
A22: (−) Crédito tributario de años anteriores | B22: ='02_Parametros'!$B$21 | C22: ='02_Parametros'!$B$21 | D22: =C22-B22 | E22: Parámetros
A23: Impuesto por pagar (− saldo a favor) | B23: =B19-B20-B21-B22 | C23: =C19-C20-C21-C22 | D23: =C23-B23 | E23: NIC 12.12–14, 46: pasivo o activo corriente
A24: Impuesto corriente registrado (B) frente a recalculado (C) | B24: =IF('02_Parametros'!$B$22="",B19,'02_Parametros'!$B$22) | C24: =C19 | D24: =C24-B24 | E24: Vacío: el de la conciliación del cliente
A25: Saldo corriente registrado (B) frente a recalculado (C) | B25: =IF('02_Parametros'!$B$23="",B23,'02_Parametros'!$B$23) | C25: =C23 | D25: =C25-B25 | E25: Vacío: el de la conciliación del cliente
A27: ⓘ Cómo se calcula esta hoja
A28: Columna | B28: Fórmula (Excel) | C28: Cómo se calcula (sencillo) | D28: Ejemplo con números reales | E28: De dónde viene | F28: Norma
A29: Según cliente | B29: '=SUMIF('03_Conciliacion'!$C$5:$C$14,"utilidad",'03_Conciliacion'!$E$5:$E$14) | C29: Arma la liquidación con los importes del cliente: cada renglón suma en la hoja 03 (Conciliación tributaria) el «Importe según cliente» de su tipo y luego calcula subtotales, límite de pérdidas, base, tarifa, impuesto y saldo con los parámetros de la hoja 02 y las pérdidas disponibles de la hoja 05; las dos últimas filas usan lo registrado en la hoja 02 y, si está vacío, lo calculado. | D29: Fila 1: SUMIF([«Tipo» de «Conciliación tributaria», 10 filas]; "utilidad"; [«Importe según cliente» de «Conciliación tributaria», 10 filas]) → 1.000.000,00 | E29: hoja «Conciliación tributaria» | F29: —
A30: Auditado | B30: '=SUMIF('03_Conciliacion'!$C$5:$C$14,"utilidad",'03_Conciliacion'!$G$5:$G$14) | C30: Hace la misma liquidación con el «Importe auditado» de la hoja 03, pero recalcula la participación trabajadores (% × utilidad), la participación atribuible a exentos (hoja 13, o la del cliente si no se puede recalcular) y la amortización de pérdidas como el menor entre la solicitada, el límite y lo disponible en la hoja 05. | D30: Fila 1: SUMIF([«Tipo» de «Conciliación tributaria», 10 filas]; "utilidad"; [«Importe auditado» de «Conciliación tributaria», 10 filas]) → 1.000.000,00 | E30: hoja «Conciliación tributaria» | F30: —
A31: Diferencia | B31: '=C5-B5 | C31: Resta el valor según cliente al valor auditado en cada renglón, para ver en qué punto cambia la liquidación. | D31: Fila 1: 1.000.000,00-1.000.000,00 → 0,00 | E31: «Auditado» (esta hoja), «Según cliente» (esta hoja) | F31: —

Sheet 05_Perdidas
A1: Pérdidas tributarias | H1: ⟵ Inicio | I1: ◀ Anterior | J1: Siguiente ▶
A2: Impuesto corriente y diferido · Cliente de muestra S.A. · corte 2025-12-31
A4: Año de origen | B4: Pérdida | C4: Amortizado años anteriores | D4: Último año | E4: Disponible | F4: Vencida | G4: Disponible no vencido | H4: Saldo vencido | I4: Amortización del año | J4: Remanente | K4: Arrastrable a años futuros | L4: Activo diferido requerido | M4: Activo diferido no reconocido
A5: 2019 | B5: 100000 | C5: 60000 | D5: =A5+'02_Parametros'!$B$14 | E5: =B5-C5 | F5: =IF(D5<YEAR('02_Parametros'!$B$5),"Sí","No") | G5: =IF(F5="No",E5,0) | H5: =IF(F5="Sí",E5,0) | I5: =MAX(0,MIN(G5,-'04_Impuesto_corriente'!$C$16-SUM(I$4:I4))) | J5: =G5-I5 | K5: =IF(D5>YEAR('02_Parametros'!$B$5),J5,0) | L5: =IF(AND('02_Parametros'!$B$17="Sí",'02_Parametros'!$B$18="Sí"),K5*'04_Impuesto_corriente'!$C$18/100,0) | M5: =K5*'04_Impuesto_corriente'!$C$18/100-L5
A6: 2020 | B6: 60000 | C6: 30000 | D6: =A6+'02_Parametros'!$B$14 | E6: =B6-C6 | F6: =IF(D6<YEAR('02_Parametros'!$B$5),"Sí","No") | G6: =IF(F6="No",E6,0) | H6: =IF(F6="Sí",E6,0) | I6: =MAX(0,MIN(G6,-'04_Impuesto_corriente'!$C$16-SUM(I$4:I5))) | J6: =G6-I6 | K6: =IF(D6>YEAR('02_Parametros'!$B$5),J6,0) | L6: =IF(AND('02_Parametros'!$B$17="Sí",'02_Parametros'!$B$18="Sí"),K6*'04_Impuesto_corriente'!$C$18/100,0) | M6: =K6*'04_Impuesto_corriente'!$C$18/100-L6
A7: 2021 | B7: 150000 | C7: 50000 | D7: =A7+'02_Parametros'!$B$14 | E7: =B7-C7 | F7: =IF(D7<YEAR('02_Parametros'!$B$5),"Sí","No") | G7: =IF(F7="No",E7,0) | H7: =IF(F7="Sí",E7,0) | I7: =MAX(0,MIN(G7,-'04_Impuesto_corriente'!$C$16-SUM(I$4:I6))) | J7: =G7-I7 | K7: =IF(D7>YEAR('02_Parametros'!$B$5),J7,0) | L7: =IF(AND('02_Parametros'!$B$17="Sí",'02_Parametros'!$B$18="Sí"),K7*'04_Impuesto_corriente'!$C$18/100,0) | M7: =K7*'04_Impuesto_corriente'!$C$18/100-L7
A8: 2023 | B8: 120000 | C8: 0 | D8: =A8+'02_Parametros'!$B$14 | E8: =B8-C8 | F8: =IF(D8<YEAR('02_Parametros'!$B$5),"Sí","No") | G8: =IF(F8="No",E8,0) | H8: =IF(F8="Sí",E8,0) | I8: =MAX(0,MIN(G8,-'04_Impuesto_corriente'!$C$16-SUM(I$4:I7))) | J8: =G8-I8 | K8: =IF(D8>YEAR('02_Parametros'!$B$5),J8,0) | L8: =IF(AND('02_Parametros'!$B$17="Sí",'02_Parametros'!$B$18="Sí"),K8*'04_Impuesto_corriente'!$C$18/100,0) | M8: =K8*'04_Impuesto_corriente'!$C$18/100-L8
A9: TOTAL | B9: =SUM(B5:B8) | C9: =SUM(C5:C8) | E9: =SUM(E5:E8) | G9: =SUM(G5:G8) | H9: =SUM(H5:H8) | I9: =SUM(I5:I8) | J9: =SUM(J5:J8) | K9: =SUM(K5:K8) | L9: =SUM(L5:L8) | M9: =SUM(M5:M8)
A11: ⓘ Cómo se calcula esta hoja
A12: Columna | B12: Fórmula (Excel) | C12: Cómo se calcula (sencillo) | D12: Ejemplo con números reales | E12: De dónde viene | F12: Norma
A13: Último año | B13: '=A5+'02_Parametros'!$B$14 | C13: Suma al año de origen de la pérdida el plazo para amortizarla de la hoja 02 (Parámetros); si el cliente informó el año de vencimiento, se usa ese dato. | D13: Fila 1: 2019+5,00 → 2024 | E13: «Año de origen» (esta hoja), hoja «Parámetros» | F13: —
A14: Disponible | B14: '=B5-C5 | C14: Resta a la pérdida lo ya amortizado en años anteriores: es lo que queda por amortizar. | D14: Fila 1: 100.000,00-60.000,00 → 40.000,00 | E14: «Pérdida» (esta hoja), «Amortizado años anteriores» (esta hoja) | F14: —
A15: Vencida | B15: '=IF(D5<YEAR('02_Parametros'!$B$5),"Sí","No") | C15: Marca «Sí» si el último año para amortizar es anterior al año del corte de la hoja 02 (Parámetros). | D15: Fila 1: IF(2024<YEAR(«2025-12-31»); "Sí"; "No") → Sí | E15: «Último año» (esta hoja), hoja «Parámetros» | F15: —
A16: Disponible no vencido | B16: '=IF(F5="No",E5,0) | C16: Si la pérdida no está vencida, toma su saldo disponible; si está vencida, cero. | D16: Fila 1: IF(«Sí»="No"; 40.000,00; 0) → 0,00 | E16: «Vencida» (esta hoja), «Disponible» (esta hoja) | F16: —
A17: Saldo vencido | B17: '=IF(F5="Sí",E5,0) | C17: Si la pérdida está vencida, toma su saldo disponible, que ya no se puede amortizar; si no, cero. | D17: Fila 1: IF(«Sí»="Sí"; 40.000,00; 0) → 40.000,00 | E17: «Vencida» (esta hoja), «Disponible» (esta hoja) | F17: —
A18: Amortización del año | B18: '=MAX(0,MIN(G5,-'04_Impuesto_corriente'!$C$16-SUM(I$4:I4))) | C18: Reparte la amortización auditada de la hoja 04 (Impuesto corriente) entre las pérdidas, de la más antigua a la más reciente, sin pasar del saldo no vencido de cada una. | D18: Fila 1: MAX(0; MIN(0,00; --221.250,00-SUM([«Amortización del año», 1 fila]))) → 0,00 | E18: «Disponible no vencido» (esta hoja), «Amortización del año» (esta hoja), hoja «Impuesto corriente» | F18: —
A19: Remanente | B19: '=G5-I5 | C19: Resta la amortización del año al disponible no vencido: es lo que sigue pendiente de cada pérdida. | D19: Fila 1: 0,00-0,00 → 0,00 | E19: «Disponible no vencido» (esta hoja), «Amortización del año» (esta hoja) | F19: —
A20: Arrastrable a años futuros | B20: '=IF(D5>YEAR('02_Parametros'!$B$5),J5,0) | C20: Si el último año para amortizar es posterior al año del corte, el remanente se puede usar en años futuros; si no, cero. | D20: Fila 1: IF(2024>YEAR(«2025-12-31»); 0,00; 0) → 0,00 | E20: «Último año» (esta hoja), «Remanente» (esta hoja), hoja «Parámetros» | F20: —
A21: Activo diferido requerido | B21: '=IF(AND('02_Parametros'!$B$17="Sí",'02_Parametros'!$B$18="Sí"),K5*'04_Impuesto_corriente'!$C$18/100,0) | C21: Si la ley admite diferido por pérdidas y hay probable ganancia fiscal (ambos «Sí» en la hoja 02), multiplica lo arrastrable por la tarifa aplicable de la hoja 04; si no, cero. | D21: Fila 1: IF(AND(«Sí»="Sí"; «Sí»="Sí"); 0,00*25,00/100; 0) → 0,00 | E21: «Arrastrable a años futuros» (esta hoja), hoja «Parámetros», hoja «Impuesto corriente» | F21: —
A22: Activo diferido no reconocido | B22: '=K5*'04_Impuesto_corriente'!$C$18/100-L5 | C22: Multiplica lo arrastrable por la tarifa aplicable de la hoja 04 y le resta el activo diferido requerido: es el activo que no se reconoce y se revela. | D22: Fila 1: 0,00*25,00/100-0,00 → 0,00 | E22: «Arrastrable a años futuros» (esta hoja), «Activo diferido requerido» (esta hoja), hoja «Impuesto corriente» | F22: —

Sheet 06_Diferencias_temp
A1: Diferencias temporarias y diferido | H1: ⟵ Inicio | I1: ◀ Anterior | J1: Siguiente ▶
A2: Impuesto corriente y diferido · Cliente de muestra S.A. · corte 2025-12-31
A4: Partida | B4: Naturaleza | C4: Libros NIIF | D4: Base fiscal | E4: Diferencia temporaria (+ imponible) | F4: Clase | G4: Año de reversión | H4: Tasa (%) | I4: Pasivo diferido | J4: Activo diferido bruto | K4: Permitido | L4: Probable | M4: Activo diferido reconocido | N4: Activo diferido no reconocido | O4: Diferido requerido (+ activo) | P4: Registrado al inicio | Q4: Registrado al cierre | R4: Ajuste | S4: ORI | T4: Movimiento requerido | U4: A resultados (+ gasto) | V4: A ORI (+ cargo)
A5: PPE — depreciación fiscal acelerada | B5: Activo | C5: 500000 | D5: 420000 | E5: =IF(B5="Activo",C5-D5,D5-C5) | F5: =IF(E5>0,"Imponible",IF(E5<0,"Deducible","Sin diferencia")) | G5: 2028 | H5: ='07_Tasa_reversion'!D5 | I5: =IF(E5>0,E5*H5/100,0) | J5: =IF(E5<0,-E5*H5/100,0) | K5: Sí | L5: Sí | M5: =IF(AND(K5="Sí",L5="Sí"),J5,0) | N5: =J5-M5 | O5: =M5-I5 | P5: -15000 | Q5: -20000 | R5: =O5-Q5 | S5: No | T5: =O5-P5 | U5: =IF(S5="No",-T5,0) | V5: =IF(S5="Sí",-T5,0)
A6: Provisión jubilación patronal | B6: Pasivo | C6: 120000 | D6: 0 | E6: =IF(B6="Activo",C6-D6,D6-C6) | F6: =IF(E6>0,"Imponible",IF(E6<0,"Deducible","Sin diferencia")) | G6: 2030 | H6: ='07_Tasa_reversion'!D6 | I6: =IF(E6>0,E6*H6/100,0) | J6: =IF(E6<0,-E6*H6/100,0) | K6: Sí | L6: Sí | M6: =IF(AND(K6="Sí",L6="Sí"),J6,0) | N6: =J6-M6 | O6: =M6-I6 | P6: 25000 | Q6: 30000 | R6: =O6-Q6 | S6: No | T6: =O6-P6 | U6: =IF(S6="No",-T6,0) | V6: =IF(S6="Sí",-T6,0)
A7: Provisión por garantías | B7: Pasivo | C7: 40000 | D7: 0 | E7: =IF(B7="Activo",C7-D7,D7-C7) | F7: =IF(E7>0,"Imponible",IF(E7<0,"Deducible","Sin diferencia")) | G7: 2026 | H7: ='07_Tasa_reversion'!D7 | I7: =IF(E7>0,E7*H7/100,0) | J7: =IF(E7<0,-E7*H7/100,0) | K7: Sí | L7: Sí | M7: =IF(AND(K7="Sí",L7="Sí"),J7,0) | N7: =J7-M7 | O7: =M7-I7 | P7: 6000 | Q7: 8800 | R7: =O7-Q7 | S7: No | T7: =O7-P7 | U7: =IF(S7="No",-T7,0) | V7: =IF(S7="Sí",-T7,0)
A8: Deterioro de inventarios (VNR) | B8: Activo | C8: 200000 | D8: 230000 | E8: =IF(B8="Activo",C8-D8,D8-C8) | F8: =IF(E8>0,"Imponible",IF(E8<0,"Deducible","Sin diferencia")) | G8: 2026 | H8: ='07_Tasa_reversion'!D8 | I8: =IF(E8>0,E8*H8/100,0) | J8: =IF(E8<0,-E8*H8/100,0) | K8: Sí | L8: Sí | M8: =IF(AND(K8="Sí",L8="Sí"),J8,0) | N8: =J8-M8 | O8: =M8-I8 | P8: 5000 | Q8: 7500 | R8: =O8-Q8 | S8: No | T8: =O8-P8 | U8: =IF(S8="No",-T8,0) | V8: =IF(S8="Sí",-T8,0)
A9: Deterioro de cartera sobre el límite fiscal | B9: Activo | C9: 300000 | D9: 315000 | E9: =IF(B9="Activo",C9-D9,D9-C9) | F9: =IF(E9>0,"Imponible",IF(E9<0,"Deducible","Sin diferencia")) | H9: ='07_Tasa_reversion'!D9 | I9: =IF(E9>0,E9*H9/100,0) | J9: =IF(E9<0,-E9*H9/100,0) | K9: Sí | L9: Sí | M9: =IF(AND(K9="Sí",L9="Sí"),J9,0) | N9: =J9-M9 | O9: =M9-I9 | P9: 0 | Q9: 3750 | R9: =O9-Q9 | S9: No | T9: =O9-P9 | U9: =IF(S9="No",-T9,0) | V9: =IF(S9="Sí",-T9,0)
A10: Revaluación de terrenos | B10: Activo | C10: 900000 | D10: 700000 | E10: =IF(B10="Activo",C10-D10,D10-C10) | F10: =IF(E10>0,"Imponible",IF(E10<0,"Deducible","Sin diferencia")) | H10: ='07_Tasa_reversion'!D10 | I10: =IF(E10>0,E10*H10/100,0) | J10: =IF(E10<0,-E10*H10/100,0) | K10: Sí | L10: Sí | M10: =IF(AND(K10="Sí",L10="Sí"),J10,0) | N10: =J10-M10 | O10: =M10-I10 | P10: -40000 | Q10: -50000 | R10: =O10-Q10 | S10: Sí | T10: =O10-P10 | U10: =IF(S10="No",-T10,0) | V10: =IF(S10="Sí",-T10,0)
A11: Activo por derecho de uso | B11: Activo | C11: 90000 | D11: 0 | E11: =IF(B11="Activo",C11-D11,D11-C11) | F11: =IF(E11>0,"Imponible",IF(E11<0,"Deducible","Sin diferencia")) | G11: 2027 | H11: ='07_Tasa_reversion'!D11 | I11: =IF(E11>0,E11*H11/100,0) | J11: =IF(E11<0,-E11*H11/100,0) | K11: Sí | L11: Sí | M11: =IF(AND(K11="Sí",L11="Sí"),J11,0) | N11: =J11-M11 | O11: =M11-I11 | P11: 0 | Q11: 0 | R11: =O11-Q11 | S11: No | T11: =O11-P11 | U11: =IF(S11="No",-T11,0) | V11: =IF(S11="Sí",-T11,0)
A12: Pasivo por arrendamiento | B12: Pasivo | C12: 95000 | D12: 0 | E12: =IF(B12="Activo",C12-D12,D12-C12) | F12: =IF(E12>0,"Imponible",IF(E12<0,"Deducible","Sin diferencia")) | G12: 2027 | H12: ='07_Tasa_reversion'!D12 | I12: =IF(E12>0,E12*H12/100,0) | J12: =IF(E12<0,-E12*H12/100,0) | K12: Sí | L12: Sí | M12: =IF(AND(K12="Sí",L12="Sí"),J12,0) | N12: =J12-M12 | O12: =M12-I12 | P12: 0 | Q12: 0 | R12: =O12-Q12 | S12: No | T12: =O12-P12 | U12: =IF(S12="No",-T12,0) | V12: =IF(S12="Sí",-T12,0)
A13: Provisión por litigio laboral | B13: Pasivo | C13: 25000 | D13: 0 | E13: =IF(B13="Activo",C13-D13,D13-C13) | F13: =IF(E13>0,"Imponible",IF(E13<0,"Deducible","Sin diferencia")) | H13: ='07_Tasa_reversion'!D13 | I13: =IF(E13>0,E13*H13/100,0) | J13: =IF(E13<0,-E13*H13/100,0) | K13: Sí | L13: No | M13: =IF(AND(K13="Sí",L13="Sí"),J13,0) | N13: =J13-M13 | O13: =M13-I13 | P13: 0 | Q13: 6250 | R13: =O13-Q13 | S13: No | T13: =O13-P13 | U13: =IF(S13="No",-T13,0) | V13: =IF(S13="Sí",-T13,0)
A14: TOTAL | C14: =SUM(C5:C13) | D14: =SUM(D5:D13) | E14: =SUM(E5:E13) | I14: =SUM(I5:I13) | J14: =SUM(J5:J13) | M14: =SUM(M5:M13) | N14: =SUM(N5:N13) | O14: =SUM(O5:O13) | P14: =SUM(P5:P13) | Q14: =SUM(Q5:Q13) | R14: =SUM(R5:R13) | T14: =SUM(T5:T13) | U14: =SUM(U5:U13) | V14: =SUM(V5:V13)
A16: ⓘ Cómo se calcula esta hoja
A17: Columna | B17: Fórmula (Excel) | C17: Cómo se calcula (sencillo) | D17: Ejemplo con números reales | E17: De dónde viene | F17: Norma
A18: Diferencia temporaria (+ imponible) | B18: '=IF(B5="Activo",C5-D5,D5-C5) | C18: En un activo resta la base fiscal al valor en libros; en un pasivo, resta el valor en libros a la base fiscal. Positiva es imponible y negativa, deducible. | D18: Fila 1: IF(«Activo»="Activo"; 500.000,00-420.000,00; 420.000,00-500.000,00) → 80.000,00 | E18: «Naturaleza» (esta hoja), «Libros NIIF» (esta hoja), «Base fiscal» (esta hoja) | F18: —
A19: Clase | B19: '=IF(E5>0,"Imponible",IF(E5<0,"Deducible","Sin diferencia")) | C19: Clasifica la diferencia: mayor que cero es «Imponible», menor que cero «Deducible» y cero «Sin diferencia». | D19: Fila 1: IF(80.000,00>0; "Imponible"; IF(80.000,00<0; "Deducible"; "Sin diferencia")) → Imponible | E19: «Diferencia temporaria (+ imponible)» (esta hoja) | F19: —
A20: Tasa (%) | B20: '='07_Tasa_reversion'!D5 | C20: Trae la tasa esperada para el año de reversión desde la hoja 07 (Tasa de reversión). | D20: Fila 1: 25,00 → 25,00 | E20: hoja «Tasa de reversión» | F20: —
A21: Pasivo diferido | B21: '=IF(E5>0,E5*H5/100,0) | C21: Si la diferencia es imponible, la multiplica por la tasa: es el pasivo por impuesto diferido; si no, cero. | D21: Fila 1: IF(80.000,00>0; 80.000,00*25,00/100; 0) → 20.000,00 | E21: «Diferencia temporaria (+ imponible)» (esta hoja), «Tasa (%)» (esta hoja) | F21: —
A22: Activo diferido bruto | B22: '=IF(E5<0,-E5*H5/100,0) | C22: Si la diferencia es deducible, multiplica su valor absoluto por la tasa: es el activo diferido antes de evaluar si se recupera; si no, cero. | D22: Fila 1: IF(80.000,00<0; -80.000,00*25,00/100; 0) → 0,00 | E22: «Diferencia temporaria (+ imponible)» (esta hoja), «Tasa (%)» (esta hoja) | F22: —
A23: Activo diferido reconocido | B23: '=IF(AND(K5="Sí",L5="Sí"),J5,0) | C23: Reconoce el activo diferido bruto solo si la ley lo permite y es probable recuperarlo (columnas «Permitido» y «Probable» en «Sí»); si no, cero. | D23: Fila 1: IF(AND(«Sí»="Sí"; «Sí»="Sí"); 0,00; 0) → 0,00 | E23: «Permitido» (esta hoja), «Probable» (esta hoja), «Activo diferido bruto» (esta hoja) | F23: —
A24: Activo diferido no reconocido | B24: '=J5-M5 | C24: Resta el activo reconocido al activo bruto: es la parte que no se registra y se revela. | D24: Fila 1: 0,00-0,00 → 0,00 | E24: «Activo diferido bruto» (esta hoja), «Activo diferido reconocido» (esta hoja) | F24: —
A25: Diferido requerido (+ activo) | B25: '=M5-I5 | C25: Resta el pasivo diferido al activo diferido reconocido: positivo es activo neto y negativo, pasivo neto. | D25: Fila 1: 0,00-20.000,00 → -20.000,00 | E25: «Activo diferido reconocido» (esta hoja), «Pasivo diferido» (esta hoja) | F25: —
A26: Ajuste | B26: '=O5-Q5 | C26: Resta el saldo registrado al cierre al diferido requerido: es lo que falta (+) o sobra (−) en los libros. | D26: Fila 1: -20.000,00--20.000,00 → 0,00 | E26: «Diferido requerido (+ activo)» (esta hoja), «Registrado al cierre» (esta hoja) | F26: —
A27: Movimiento requerido | B27: '=O5-P5 | C27: Resta el saldo registrado al inicio al diferido requerido: es cuánto debió moverse el diferido en el año. | D27: Fila 1: -20.000,00--15.000,00 → -5.000,00 | E27: «Diferido requerido (+ activo)» (esta hoja), «Registrado al inicio» (esta hoja) | F27: —
A28: A resultados (+ gasto) | B28: '=IF(S5="No",-T5,0) | C28: Si la partida no es de ORI, lleva el movimiento a resultados con el signo cambiado (un aumento del activo es ingreso y se muestra negativo); si es de ORI, cero. | D28: Fila 1: IF(«No»="No"; --5.000,00; 0) → 5.000,00 | E28: «ORI» (esta hoja), «Movimiento requerido» (esta hoja) | F28: —
A29: A ORI (+ cargo) | B29: '=IF(S5="Sí",-T5,0) | C29: Si la partida es de ORI, lleva el movimiento al otro resultado integral con el signo cambiado; si no, cero. | D29: Fila 1: IF(«No»="Sí"; --5.000,00; 0) → 0,00 | E29: «ORI» (esta hoja), «Movimiento requerido» (esta hoja) | F29: —

Sheet 07_Tasa_reversion
A1: Tasa de reversión | H1: ⟵ Inicio | I1: ◀ Anterior | J1: Siguiente ▶
A2: Impuesto corriente y diferido · Cliente de muestra S.A. · corte 2025-12-31
A4: Partida | B4: Año de reversión | C4: Tasa usada por el cliente (%) | D4: Tasa esperada = aprobada + recargo (%) | E4: Diferencia de tasa (p.p.) | F4: Diferencia temporaria | G4: Efecto en el diferido | H4: Fórmula de la tasa esperada
A5: PPE — depreciación fiscal acelerada | B5: =IF('06_Diferencias_temp'!G5="","",'06_Diferencias_temp'!G5) | C5: =D5 | D5: =IF(AND('02_Parametros'!$B$15<>"",'02_Parametros'!$B$16<>"",B5<>""),IF(B5>='02_Parametros'!$B$16,'02_Parametros'!$B$15+('04_Impuesto_corriente'!$C$18-'02_Parametros'!$B$7),'04_Impuesto_corriente'!$C$18),'04_Impuesto_corriente'!$C$18) | E5: =C5-D5 | F5: ='06_Diferencias_temp'!E5 | G5: =ABS(F5)*E5/100 | H5: Tasa esperada = tarifa del año de reversión + recargo = 25.0 % + 3.0 puntos × 0.0 % = 25.0 % (NIC 12.47, 49)
A6: Provisión jubilación patronal | B6: =IF('06_Diferencias_temp'!G6="","",'06_Diferencias_temp'!G6) | C6: =D6 | D6: =IF(AND('02_Parametros'!$B$15<>"",'02_Parametros'!$B$16<>"",B6<>""),IF(B6>='02_Parametros'!$B$16,'02_Parametros'!$B$15+('04_Impuesto_corriente'!$C$18-'02_Parametros'!$B$7),'04_Impuesto_corriente'!$C$18),'04_Impuesto_corriente'!$C$18) | E6: =C6-D6 | F6: ='06_Diferencias_temp'!E6 | G6: =ABS(F6)*E6/100 | H6: Tasa esperada = tarifa del año de reversión + recargo = 25.0 % + 3.0 puntos × 0.0 % = 25.0 % (NIC 12.47, 49)
A7: Provisión por garantías | B7: =IF('06_Diferencias_temp'!G7="","",'06_Diferencias_temp'!G7) | C7: 22 | D7: =IF(AND('02_Parametros'!$B$15<>"",'02_Parametros'!$B$16<>"",B7<>""),IF(B7>='02_Parametros'!$B$16,'02_Parametros'!$B$15+('04_Impuesto_corriente'!$C$18-'02_Parametros'!$B$7),'04_Impuesto_corriente'!$C$18),'04_Impuesto_corriente'!$C$18) | E7: =C7-D7 | F7: ='06_Diferencias_temp'!E7 | G7: =ABS(F7)*E7/100 | H7: Tasa esperada = tarifa del año de reversión + recargo = 25.0 % + 3.0 puntos × 0.0 % = 25.0 % (NIC 12.47, 49)
A8: Deterioro de inventarios (VNR) | B8: =IF('06_Diferencias_temp'!G8="","",'06_Diferencias_temp'!G8) | C8: =D8 | D8: =IF(AND('02_Parametros'!$B$15<>"",'02_Parametros'!$B$16<>"",B8<>""),IF(B8>='02_Parametros'!$B$16,'02_Parametros'!$B$15+('04_Impuesto_corriente'!$C$18-'02_Parametros'!$B$7),'04_Impuesto_corriente'!$C$18),'04_Impuesto_corriente'!$C$18) | E8: =C8-D8 | F8: ='06_Diferencias_temp'!E8 | G8: =ABS(F8)*E8/100 | H8: Tasa esperada = tarifa del año de reversión + recargo = 25.0 % + 3.0 puntos × 0.0 % = 25.0 % (NIC 12.47, 49)
A9: Deterioro de cartera sobre el límite fiscal | B9: =IF('06_Diferencias_temp'!G9="","",'06_Diferencias_temp'!G9) | C9: =D9 | D9: =IF(AND('02_Parametros'!$B$15<>"",'02_Parametros'!$B$16<>"",B9<>""),IF(B9>='02_Parametros'!$B$16,'02_Parametros'!$B$15+('04_Impuesto_corriente'!$C$18-'02_Parametros'!$B$7),'04_Impuesto_corriente'!$C$18),'04_Impuesto_corriente'!$C$18) | E9: =C9-D9 | F9: ='06_Diferencias_temp'!E9 | G9: =ABS(F9)*E9/100 | H9: Tasa esperada = tarifa del año de reversión + recargo = 25.0 % + 3.0 puntos × 0.0 % = 25.0 % (NIC 12.47, 49)
A10: Revaluación de terrenos | B10: =IF('06_Diferencias_temp'!G10="","",'06_Diferencias_temp'!G10) | C10: =D10 | D10: =IF(AND('02_Parametros'!$B$15<>"",'02_Parametros'!$B$16<>"",B10<>""),IF(B10>='02_Parametros'!$B$16,'02_Parametros'!$B$15+('04_Impuesto_corriente'!$C$18-'02_Parametros'!$B$7),'04_Impuesto_corriente'!$C$18),'04_Impuesto_corriente'!$C$18) | E10: =C10-D10 | F10: ='06_Diferencias_temp'!E10 | G10: =ABS(F10)*E10/100 | H10: Tasa esperada = tarifa del año de reversión + recargo = 25.0 % + 3.0 puntos × 0.0 % = 25.0 % (NIC 12.47, 49)
A11: Activo por derecho de uso | B11: =IF('06_Diferencias_temp'!G11="","",'06_Diferencias_temp'!G11) | C11: =D11 | D11: =IF(AND('02_Parametros'!$B$15<>"",'02_Parametros'!$B$16<>"",B11<>""),IF(B11>='02_Parametros'!$B$16,'02_Parametros'!$B$15+('04_Impuesto_corriente'!$C$18-'02_Parametros'!$B$7),'04_Impuesto_corriente'!$C$18),'04_Impuesto_corriente'!$C$18) | E11: =C11-D11 | F11: ='06_Diferencias_temp'!E11 | G11: =ABS(F11)*E11/100 | H11: Tasa esperada = tarifa del año de reversión + recargo = 25.0 % + 3.0 puntos × 0.0 % = 25.0 % (NIC 12.47, 49)
A12: Pasivo por arrendamiento | B12: =IF('06_Diferencias_temp'!G12="","",'06_Diferencias_temp'!G12) | C12: =D12 | D12: =IF(AND('02_Parametros'!$B$15<>"",'02_Parametros'!$B$16<>"",B12<>""),IF(B12>='02_Parametros'!$B$16,'02_Parametros'!$B$15+('04_Impuesto_corriente'!$C$18-'02_Parametros'!$B$7),'04_Impuesto_corriente'!$C$18),'04_Impuesto_corriente'!$C$18) | E12: =C12-D12 | F12: ='06_Diferencias_temp'!E12 | G12: =ABS(F12)*E12/100 | H12: Tasa esperada = tarifa del año de reversión + recargo = 25.0 % + 3.0 puntos × 0.0 % = 25.0 % (NIC 12.47, 49)
A13: Provisión por litigio laboral | B13: =IF('06_Diferencias_temp'!G13="","",'06_Diferencias_temp'!G13) | C13: =D13 | D13: =IF(AND('02_Parametros'!$B$15<>"",'02_Parametros'!$B$16<>"",B13<>""),IF(B13>='02_Parametros'!$B$16,'02_Parametros'!$B$15+('04_Impuesto_corriente'!$C$18-'02_Parametros'!$B$7),'04_Impuesto_corriente'!$C$18),'04_Impuesto_corriente'!$C$18) | E13: =C13-D13 | F13: ='06_Diferencias_temp'!E13 | G13: =ABS(F13)*E13/100 | H13: Tasa esperada = tarifa del año de reversión + recargo = 25.0 % + 3.0 puntos × 0.0 % = 25.0 % (NIC 12.47, 49)
A14: TOTAL | G14: =SUM(G5:G13)
A16: ⓘ Cómo se calcula esta hoja
A17: Columna | B17: Fórmula (Excel) | C17: Cómo se calcula (sencillo) | D17: Ejemplo con números reales | E17: De dónde viene | F17: Norma
A18: Año de reversión | B18: '=IF('06_Diferencias_temp'!G5="","",'06_Diferencias_temp'!G5) | C18: Trae el año en que se revierte la diferencia desde la hoja 06 (Diferencias temporarias); vacío si no se informó. | D18: Fila 1: IF(2028=""; ""; 2028) → 2.028,00 | E18: hoja «Diferencias temporarias y diferido» | F18: —
A19: Tasa usada por el cliente (%) | B19: '=D5 | C19: Es la tasa que informó el cliente; si no la informó, repite la tasa esperada, de modo que la diferencia de tasa queda en cero. | D19: Fila 1: 25,00 → 25,00 | E19: «Tasa esperada = aprobada + recargo (%)» (esta hoja) | F19: —
A20: Tasa esperada = aprobada + recargo (%) | B20: '=IF(AND('02_Parametros'!$B$15<>"",'02_Parametros'!$B$16<>"",B5<>""),IF(B5>='02_Parametros'!$B$16,'02_Parametros'!$B$15+('04_Impuesto_corriente'!$C$18-'02_Parametros'!$B$7),'04_Impuesto_corriente'!$C$18),'04_Impuesto_corriente'!$C$18) | C20: Si hay tasa futura aprobada, su año de inicio y año de reversión, y la reversión cae desde ese año, suma a la tasa futura el recargo (tarifa aplicable − tarifa general); en los demás casos usa la tarifa aplicable de la hoja 04 (Impuesto corriente). | D20: Fila 1: IF(AND((vacío)<>""; (vacío)<>""; 2.028,00<>""); IF(2.028,00>=(vacío); (vacío)+(25,00-25,00); 25,00); 25,00) → 25,00 | E20: «Año de reversión» (esta hoja), hoja «Parámetros», hoja «Impuesto corriente» | F20: —
A21: Diferencia de tasa (p.p.) | B21: '=C5-D5 | C21: Resta la tasa esperada a la tasa usada por el cliente, en puntos porcentuales. | D21: Fila 1: 25,00-25,00 → 0,00 | E21: «Tasa usada por el cliente (%)» (esta hoja), «Tasa esperada = aprobada + recargo (%)» (esta hoja) | F21: —
A22: Diferencia temporaria | B22: '='06_Diferencias_temp'!E5 | C22: Trae la diferencia temporaria de la partida desde la hoja 06 (Diferencias temporarias). | D22: Fila 1: 80.000,00 → 80.000,00 | E22: hoja «Diferencias temporarias y diferido» | F22: —
A23: Efecto en el diferido | B23: '=ABS(F5)*E5/100 | C23: Multiplica el valor absoluto de la diferencia temporaria por la diferencia de tasa: es el error en el diferido por usar una tasa distinta. | D23: Fila 1: ABS(80.000,00)*0,00/100 → 0,00 | E23: «Diferencia temporaria» (esta hoja), «Diferencia de tasa (p.p.)» (esta hoja) | F23: —

Sheet 08_Recuperabilidad
A1: Recuperabilidad del activo diferido | H1: ⟵ Inicio | I1: ◀ Anterior | J1: Siguiente ▶
A2: Impuesto corriente y diferido · Cliente de muestra S.A. · corte 2025-12-31
A4: Partida | B4: Activo diferido bruto | C4: Permitido | D4: Probable | E4: Reconocible | F4: Registrado al cierre | G4: Registrado en exceso | H4: Conclusión
A5: Provisión jubilación patronal | B5: ='06_Diferencias_temp'!J6 | C5: ='06_Diferencias_temp'!K6 | D5: ='06_Diferencias_temp'!L6 | E5: ='06_Diferencias_temp'!M6 | F5: =MAX('06_Diferencias_temp'!Q6,0) | G5: =MAX(F5-E5,0) | H5: =IF(C5="No","No admitido tributariamente",IF(D5="No","Sin probabilidad de ganancia fiscal","Reconocible"))
A6: Provisión por garantías | B6: ='06_Diferencias_temp'!J7 | C6: ='06_Diferencias_temp'!K7 | D6: ='06_Diferencias_temp'!L7 | E6: ='06_Diferencias_temp'!M7 | F6: =MAX('06_Diferencias_temp'!Q7,0) | G6: =MAX(F6-E6,0) | H6: =IF(C6="No","No admitido tributariamente",IF(D6="No","Sin probabilidad de ganancia fiscal","Reconocible"))
A7: Deterioro de inventarios (VNR) | B7: ='06_Diferencias_temp'!J8 | C7: ='06_Diferencias_temp'!K8 | D7: ='06_Diferencias_temp'!L8 | E7: ='06_Diferencias_temp'!M8 | F7: =MAX('06_Diferencias_temp'!Q8,0) | G7: =MAX(F7-E7,0) | H7: =IF(C7="No","No admitido tributariamente",IF(D7="No","Sin probabilidad de ganancia fiscal","Reconocible"))
A8: Deterioro de cartera sobre el límite fiscal | B8: ='06_Diferencias_temp'!J9 | C8: ='06_Diferencias_temp'!K9 | D8: ='06_Diferencias_temp'!L9 | E8: ='06_Diferencias_temp'!M9 | F8: =MAX('06_Diferencias_temp'!Q9,0) | G8: =MAX(F8-E8,0) | H8: =IF(C8="No","No admitido tributariamente",IF(D8="No","Sin probabilidad de ganancia fiscal","Reconocible"))
A9: Pasivo por arrendamiento | B9: ='06_Diferencias_temp'!J12 | C9: ='06_Diferencias_temp'!K12 | D9: ='06_Diferencias_temp'!L12 | E9: ='06_Diferencias_temp'!M12 | F9: =MAX('06_Diferencias_temp'!Q12,0) | G9: =MAX(F9-E9,0) | H9: =IF(C9="No","No admitido tributariamente",IF(D9="No","Sin probabilidad de ganancia fiscal","Reconocible"))
A10: Provisión por litigio laboral | B10: ='06_Diferencias_temp'!J13 | C10: ='06_Diferencias_temp'!K13 | D10: ='06_Diferencias_temp'!L13 | E10: ='06_Diferencias_temp'!M13 | F10: =MAX('06_Diferencias_temp'!Q13,0) | G10: =MAX(F10-E10,0) | H10: =IF(C10="No","No admitido tributariamente",IF(D10="No","Sin probabilidad de ganancia fiscal","Reconocible"))
A11: Pérdidas tributarias no utilizadas | B11: =SUM('05_Perdidas'!$K$5:$K$8)*'04_Impuesto_corriente'!$C$18/100 | C11: ='02_Parametros'!$B$17 | D11: ='02_Parametros'!$B$18 | E11: =SUM('05_Perdidas'!$L$5:$L$8) | F11: =MAX('02_Parametros'!$B$26,0) | G11: =MAX(F11-E11,0) | H11: =IF(C11="No","No admitido tributariamente",IF(D11="No","Sin probabilidad de ganancia fiscal","Reconocible"))
A12: TOTAL | B12: =SUM(B5:B11) | E12: =SUM(E5:E11) | F12: =SUM(F5:F11) | G12: =SUM(G5:G11)
A14: ⓘ Cómo se calcula esta hoja
A15: Columna | B15: Fórmula (Excel) | C15: Cómo se calcula (sencillo) | D15: Ejemplo con números reales | E15: De dónde viene | F15: Norma
A16: Activo diferido bruto | B16: '='06_Diferencias_temp'!J6 | C16: Trae el activo diferido bruto de la partida desde la hoja 06; en la fila de pérdidas, multiplica lo arrastrable de la hoja 05 por la tarifa aplicable. | D16: Fila 1: 30.000,00 → 30.000,00 | E16: hoja «Diferencias temporarias y diferido» | F16: —
A17: Permitido | B17: '='06_Diferencias_temp'!K6 | C17: Trae de la hoja 06 si la ley admite el diferido de la partida; en la fila de pérdidas, el parámetro de la hoja 02 (Parámetros). | D17: Fila 1: «Sí» → Sí | E17: hoja «Diferencias temporarias y diferido» | F17: —
A18: Probable | B18: '='06_Diferencias_temp'!L6 | C18: Trae de la hoja 06 si es probable recuperar el activo; en la fila de pérdidas, el parámetro de probable ganancia fiscal de la hoja 02. | D18: Fila 1: «Sí» → Sí | E18: hoja «Diferencias temporarias y diferido» | F18: —
A19: Reconocible | B19: '='06_Diferencias_temp'!M6 | C19: Trae el activo diferido reconocido de la hoja 06; en la fila de pérdidas, suma el activo diferido requerido de la hoja 05 (Pérdidas tributarias). | D19: Fila 1: 30.000,00 → 30.000,00 | E19: hoja «Diferencias temporarias y diferido» | F19: —
A20: Registrado al cierre | B20: '=MAX('06_Diferencias_temp'!Q6,0) | C20: Toma el saldo registrado al cierre de la hoja 06 (en pérdidas, el parámetro de la hoja 02) y lo deja en cero si es negativo, porque aquí solo cuenta el activo. | D20: Fila 1: MAX(30.000,00; 0) → 30.000,00 | E20: hoja «Diferencias temporarias y diferido» | F20: —
A21: Registrado en exceso | B21: '=MAX(F5-E5,0) | C21: Resta lo reconocible a lo registrado al cierre, sin bajar de cero: es el activo registrado que no se puede sostener. | D21: Fila 1: MAX(30.000,00-30.000,00; 0) → 0,00 | E21: «Registrado al cierre» (esta hoja), «Reconocible» (esta hoja) | F21: —
A22: Conclusión | B22: '=IF(C5="No","No admitido tributariamente",IF(D5="No","Sin probabilidad de ganancia fiscal","Reconocible")) | C22: Si la ley no lo admite, «No admitido tributariamente»; si no hay probable ganancia fiscal, «Sin probabilidad de ganancia fiscal»; en otro caso, «Reconocible». | D22: Fila 1: IF(«Sí»="No"; "No admitido tributariamente"; IF(«Sí»="No"; "Sin probabilidad de ganancia fiscal"; "Reconocible")) → Reconocible | E22: «Permitido» (esta hoja), «Probable» (esta hoja) | F22: —

Sheet 09_Movimiento
A1: Movimiento: resultados y ORI | H1: ⟵ Inicio | I1: ◀ Anterior | J1: Siguiente ▶
A2: Impuesto corriente y diferido · Cliente de muestra S.A. · corte 2025-12-31
A4: Concepto | B4: Registrado al inicio | C4: Requerido al cierre | D4: Movimiento | E4: A resultados (+ gasto) | F4: A ORI (+ cargo) | G4: Registrado al cierre | H4: Ajuste
A5: Diferencias temporarias con efecto en resultados | B5: =SUMIF('06_Diferencias_temp'!$S$5:$S$13,"No",'06_Diferencias_temp'!$P$5:$P$13) | C5: =SUMIF('06_Diferencias_temp'!$S$5:$S$13,"No",'06_Diferencias_temp'!$O$5:$O$13) | D5: =C5-B5 | E5: =-D5 | F5: =0 | G5: =SUMIF('06_Diferencias_temp'!$S$5:$S$13,"No",'06_Diferencias_temp'!$Q$5:$Q$13) | H5: =C5-G5
A6: Diferencias temporarias de partidas de ORI / patrimonio | B6: =SUMIF('06_Diferencias_temp'!$S$5:$S$13,"Sí",'06_Diferencias_temp'!$P$5:$P$13) | C6: =SUMIF('06_Diferencias_temp'!$S$5:$S$13,"Sí",'06_Diferencias_temp'!$O$5:$O$13) | D6: =C6-B6 | E6: =0 | F6: =-D6 | G6: =SUMIF('06_Diferencias_temp'!$S$5:$S$13,"Sí",'06_Diferencias_temp'!$Q$5:$Q$13) | H6: =C6-G6
A7: Pérdidas tributarias no utilizadas | B7: ='02_Parametros'!$B$25 | C7: =SUM('05_Perdidas'!$L$5:$L$8) | D7: =C7-B7 | E7: =-D7 | F7: =0 | G7: ='02_Parametros'!$B$26 | H7: =C7-G7
A8: TOTAL | B8: =SUM(B5:B7) | C8: =SUM(C5:C7) | D8: =SUM(D5:D7) | E8: =SUM(E5:E7) | F8: =SUM(F5:F7) | G8: =SUM(G5:G7) | H8: =SUM(H5:H7)
A10: ⓘ Cómo se calcula esta hoja
A11: Columna | B11: Fórmula (Excel) | C11: Cómo se calcula (sencillo) | D11: Ejemplo con números reales | E11: De dónde viene | F11: Norma
A12: Registrado al inicio | B12: '=SUMIF('06_Diferencias_temp'!$S$5:$S$13,"No",'06_Diferencias_temp'!$P$5:$P$13) | C12: Suma el saldo registrado al inicio de la hoja 06 para las partidas sin ORI (primera fila) o con ORI (segunda); la fila de pérdidas toma el activo por pérdidas al inicio de la hoja 02. | D12: Fila 1: SUMIF([«ORI» de «Diferencias temporarias y diferido», 9 filas]; "No"; [«Registrado al inicio» de «Diferencias temporarias y diferido», 9 filas]) → 21.000,00 | E12: hoja «Diferencias temporarias y diferido» | F12: —
A13: Requerido al cierre | B13: '=SUMIF('06_Diferencias_temp'!$S$5:$S$13,"No",'06_Diferencias_temp'!$O$5:$O$13) | C13: Suma el diferido requerido de la hoja 06 para las partidas sin ORI o con ORI; la fila de pérdidas suma el activo diferido requerido de la hoja 05 (Pérdidas tributarias). | D13: Fila 1: SUMIF([«ORI» de «Diferencias temporarias y diferido», 9 filas]; "No"; [«Diferido requerido (+ activo)» de «Diferencias temporarias y diferido», 9 filas]) → 32.500,00 | E13: hoja «Diferencias temporarias y diferido» | F13: —
A14: Movimiento | B14: '=C5-B5 | C14: Resta lo registrado al inicio a lo requerido al cierre: es el movimiento del diferido que corresponde al año. | D14: Fila 1: 32.500,00-21.000,00 → 11.500,00 | E14: «Requerido al cierre» (esta hoja), «Registrado al inicio» (esta hoja) | F14: —
A15: A resultados (+ gasto) | B15: '=-D5 | C15: Lleva el movimiento a resultados con el signo cambiado en la fila sin ORI y en la de pérdidas; en la fila de ORI, cero. | D15: Fila 1: -11.500,00 → -11.500,00 | E15: «Movimiento» (esta hoja) | F15: —
A16: A ORI (+ cargo) | B16: '=0 | C16: Lleva el movimiento al otro resultado integral con el signo cambiado solo en la fila de partidas de ORI; en las demás, cero. | D16: Fila 1: 0 → 0,00 | E16: datos cargados del cliente | F16: —
A17: Registrado al cierre | B17: '=SUMIF('06_Diferencias_temp'!$S$5:$S$13,"No",'06_Diferencias_temp'!$Q$5:$Q$13) | C17: Suma el saldo registrado al cierre de la hoja 06 para las partidas sin ORI o con ORI; la fila de pérdidas toma el activo por pérdidas al cierre de la hoja 02. | D17: Fila 1: SUMIF([«ORI» de «Diferencias temporarias y diferido», 9 filas]; "No"; [«Registrado al cierre» de «Diferencias temporarias y diferido», 9 filas]) → 36.300,00 | E17: hoja «Diferencias temporarias y diferido» | F17: —
A18: Ajuste | B18: '=C5-G5 | C18: Resta lo registrado al cierre a lo requerido al cierre: es la corrección que necesita el saldo del diferido (+ más activo o menos pasivo). | D18: Fila 1: 32.500,00-36.300,00 → -3.800,00 | E18: «Requerido al cierre» (esta hoja), «Registrado al cierre» (esta hoja) | F18: —

Sheet 10_Compensacion
A1: Compensación y presentación | H1: ⟵ Inicio | I1: ◀ Anterior | J1: Siguiente ▶
A2: Impuesto corriente y diferido · Cliente de muestra S.A. · corte 2025-12-31
A4: Concepto | B4: Importe | C4: Referencia
A5: Activo diferido bruto registrado | B5: =SUMIF('06_Diferencias_temp'!$Q$5:$Q$13,">0")+MAX('02_Parametros'!$B$26,0) | C5: 06_Diferencias_temp Q > 0 + pérdidas
A6: Pasivo diferido bruto registrado | B6: =-SUMIF('06_Diferencias_temp'!$Q$5:$Q$13,"<0") | C6: 06_Diferencias_temp Q < 0
A7: Derecho legal de compensar | B7: ='02_Parametros'!$B$27 | C7: NIC 12.71, 74
A8: Activo diferido a presentar (saldos registrados) | B8: =IF(B7="Sí",MAX(B5-B6,0),B5) | C8: Neto si hay derecho
A9: Pasivo diferido a presentar (saldos registrados) | B9: =IF(B7="Sí",MAX(B6-B5,0),B6) | C9: Neto si hay derecho
A10: Activo diferido presentado | B10: =IF('02_Parametros'!$B$28<>"",'02_Parametros'!$B$28,"") | C10: Parámetros
A11: Pasivo diferido presentado | B11: =IF('02_Parametros'!$B$29<>"",'02_Parametros'!$B$29,"") | C11: Parámetros
A12: Diferencia de presentación del activo | B12: =IF(B10="","",B10-B8) | C12: Compensación indebida o faltante
A13: Diferencia de presentación del pasivo | B13: =IF(B11="","",B11-B9)
A14: Activo diferido requerido (auditado, bruto) | B14: =SUM('06_Diferencias_temp'!$M$5:$M$13)+SUM('05_Perdidas'!$L$5:$L$8) | C14: 06 + 05
A15: Pasivo diferido requerido (auditado, bruto) | B15: =SUM('06_Diferencias_temp'!$I$5:$I$13) | C15: 06
A16: Activo diferido a presentar (auditado) | B16: =IF(B7="Sí",MAX(B14-B15,0),B14) | C16: NIC 12.71, 74
A17: Pasivo diferido a presentar (auditado) | B17: =IF(B7="Sí",MAX(B15-B14,0),B15) | C17: NIC 12.71, 74
A19: ⓘ Cómo se calcula esta hoja
A20: Columna | B20: Fórmula (Excel) | C20: Cómo se calcula (sencillo) | D20: Ejemplo con números reales | E20: De dónde viene | F20: Norma
A21: Importe | B21: '=SUMIF('06_Diferencias_temp'!$Q$5:$Q$13,">0")+MAX('02_Parametros'!$B$26,0) | C21: Suma los saldos registrados de la hoja 06 (activos, más el activo por pérdidas de la hoja 02, y pasivos por separado) y los requeridos de las hojas 06 y 05; con derecho legal de compensar presenta solo el neto, y compara lo presentado según la hoja 02 con lo que corresponde. | D21: Fila 1: SUMIF([«Registrado al cierre» de «Diferencias temporarias y diferido», 9 filas]; ">0")+MAX(20.000,00; 0) → 76.300,00 | E21: hoja «Diferencias temporarias y diferido», hoja «Parámetros» | F21: —

Sheet 11_Tasa_efectiva
A1: Tasa efectiva (NIC 12.81 c) | H1: ⟵ Inicio | I1: ◀ Anterior | J1: Siguiente ▶
A2: Impuesto corriente y diferido · Cliente de muestra S.A. · corte 2025-12-31
A4: Concepto | B4: Importe | C4: % del resultado
A5: Resultado contable antes del impuesto (utilidad − participación) | B5: ='04_Impuesto_corriente'!C5+'04_Impuesto_corriente'!C6
