Workbook

Sheet 00_Inicio
B2: AuditConsulting Auditores Cía. Ltda. · AUDIT-IA
B4: Inversiones e instrumentos financieros
B6: Cliente | C6: Cliente de muestra S.A. | D6: RUC | E6: 1790000000001
B7: Marco contable | C7: NIIF completas | D7: Fecha de corte | E7: 2025-12-31
B8: Preparó | C8: Ejercicio modelo | D8: Revisó | E8: Pendiente
B10: INDICADORES CLAVE
B11: Ajuste propuesto (importe neto) | C11: Problemas encontrados
B12: -1318.65 | C12: 27
B15: IR A LA CÉDULA
B16: Carátula | C16: Programa | D16: Base técnica | E16: Resumen
B17: Parámetros | C17: Inventario de inversiones | D17: Clasificación | E17: Costo amortizado y TIE
B18: Valor razonable y jerarquía | C18: Intereses y dividendos | D18: Deterioro | E18: Reclasificación
B19: Conciliación y ajuste | C19: Problemas encontrados | D19: Conclusión | E19: Control de revisión
B21: PANORAMA | N21: Datos de los gráficos (fórmulas a las cédulas)
N22: Cifras del resumen | O22: Importe (USD)
N23: ='01_Resumen'!A5 | O23: ='01_Resumen'!B5
N24: ='01_Resumen'!A6 | O24: ='01_Resumen'!B6
N25: ='01_Resumen'!A7 | O25: ='01_Resumen'!B7
N26: ='01_Resumen'!A8 | O26: ='01_Resumen'!B8
N27: ='01_Resumen'!A9 | O27: ='01_Resumen'!B9
N28: ='01_Resumen'!A10 | O28: ='01_Resumen'!B10
N29: ='01_Resumen'!A11 | O29: ='01_Resumen'!B11
N30: ='01_Resumen'!A12 | O30: ='01_Resumen'!B12
N32: Hallazgos de mayor impacto | O32: Importe (USD)
N33: Clasificacion inconsistente (×2) | O33: =SUMIFS('11_Problemas'!$C$5:$C$31,'11_Problemas'!$A$5:$A$31,"CLASIFICACION_INCONSISTENTE",'11_Problemas'!$C$5:$C$31,">0")-SUMIFS('11_Problemas'!$C$5:$C$31,'11_Problemas'!$A$5:$A$31,"CLASIFICACION_INCONSISTENTE",'11_Problemas'!$C$5:$C$31,"<0")
N34: Vr sin nivel | O34: =SUMIFS('11_Problemas'!$C$5:$C$31,'11_Problemas'!$A$5:$A$31,"VR_SIN_NIVEL",'11_Problemas'!$C$5:$C$31,">0")-SUMIFS('11_Problemas'!$C$5:$C$31,'11_Problemas'!$A$5:$A$31,"VR_SIN_NIVEL",'11_Problemas'!$C$5:$C$31,"<0")
N35: Reclasificacion no permitida | O35: =SUMIFS('11_Problemas'!$C$5:$C$31,'11_Problemas'!$A$5:$A$31,"RECLASIFICACION_NO_PERMITIDA",'11_Problemas'!$C$5:$C$31,">0")-SUMIFS('11_Problemas'!$C$5:$C$31,'11_Problemas'!$A$5:$A$31,"RECLASIFICACION_NO_PERMITIDA",'11_Problemas'!$C$5:$C$31,"<0")
N36: Vr nivel 3 | O36: =SUMIFS('11_Problemas'!$C$5:$C$31,'11_Problemas'!$A$5:$A$31,"VR_NIVEL_3",'11_Problemas'!$C$5:$C$31,">0")-SUMIFS('11_Problemas'!$C$5:$C$31,'11_Problemas'!$A$5:$A$31,"VR_NIVEL_3",'11_Problemas'!$C$5:$C$31,"<0")
N37: Calificacion baja sin indicio | O37: =SUMIFS('11_Problemas'!$C$5:$C$31,'11_Problemas'!$A$5:$A$31,"CALIFICACION_BAJA_SIN_INDICIO",'11_Problemas'!$C$5:$C$31,">0")-SUMIFS('11_Problemas'!$C$5:$C$31,'11_Problemas'!$A$5:$A$31,"CALIFICACION_BAJA_SIN_INDICIO",'11_Problemas'!$C$5:$C$31,"<0")
N38: Indicio deterioro | O38: =SUMIFS('11_Problemas'!$C$5:$C$31,'11_Problemas'!$A$5:$A$31,"INDICIO_DETERIORO",'11_Problemas'!$C$5:$C$31,">0")-SUMIFS('11_Problemas'!$C$5:$C$31,'11_Problemas'!$A$5:$A$31,"INDICIO_DETERIORO",'11_Problemas'!$C$5:$C$31,"<0")
N39: Diferencia deterioro (×6) | O39: =SUMIFS('11_Problemas'!$C$5:$C$31,'11_Problemas'!$A$5:$A$31,"DIFERENCIA_DETERIORO",'11_Problemas'!$C$5:$C$31,">0")-SUMIFS('11_Problemas'!$C$5:$C$31,'11_Problemas'!$A$5:$A$31,"DIFERENCIA_DETERIORO",'11_Problemas'!$C$5:$C$31,"<0")
N40: Otros (6 tipos) | O40: =SUMIF('11_Problemas'!$C$5:$C$31,">0")-SUMIF('11_Problemas'!$C$5:$C$31,"<0")-((SUMIFS('11_Problemas'!$C$5:$C$31,'11_Problemas'!$A$5:$A$31,"CLASIFICACION_INCONSISTENTE",'11_Problemas'!$C$5:$C$31,">0")-SUMIFS('11_Problemas'!$C$5:$C$31,'11_Problemas'!$A$5:$A$31,"CLASIFICACION_INCONSISTENTE",'11_Problemas'!$C$5:$C$31,"<0"))+(SUMIFS('11_Problemas'!$C$5:$C$31,'11_Problemas'!$A$5:$A$31,"VR_SIN_NIVEL",'11_Problemas'!$C$5:$C$31,">0")-SUMIFS('11_Problemas'!$C$5:$C$31,'11_Problemas'!$A$5:$A$31,"VR_SIN_NIVEL",'11_Problemas'!$C$5:$C$31,"<0"))+(SUMIFS('11_Problemas'!$C$5:$C$31,'11_Problemas'!$A$5:$A$31,"RECLASIFICACION_NO_PERMITIDA",'11_Problemas'!$C$5:$C$31,">0")-SUMIFS('11_Problemas'!$C$5:$C$31,'11_Problemas'!$A$5:$A$31,"RECLASIFICACION_NO_PERMITIDA",'11_Problemas'!$C$5:$C$31,"<0"))+(SUMIFS('11_Problemas'!$C$5:$C$31,'11_Problemas'!$A$5:$A$31,"VR_NIVEL_3",'11_Problemas'!$C$5:$C$31,">0")-SUMIFS('11_Problemas'!$C$5:$C$31,'11_Problemas'!$A$5:$A$31,"VR_NIVEL_3",'11_Problemas'!$C$5:$C$31,"<0"))+(SUMIFS('11_Problemas'!$C$5:$C$31,'11_Problemas'!$A$5:$A$31,"CALIFICACION_BAJA_SIN_INDICIO",'11_Problemas'!$C$5:$C$31,">0")-SUMIFS('11_Problemas'!$C$5:$C$31,'11_Problemas'!$A$5:$A$31,"CALIFICACION_BAJA_SIN_INDICIO",'11_Problemas'!$C$5:$C$31,"<0"))+(SUMIFS('11_Problemas'!$C$5:$C$31,'11_Problemas'!$A$5:$A$31,"INDICIO_DETERIORO",'11_Problemas'!$C$5:$C$31,">0")-SUMIFS('11_Problemas'!$C$5:$C$31,'11_Problemas'!$A$5:$A$31,"INDICIO_DETERIORO",'11_Problemas'!$C$5:$C$31,"<0"))+(SUMIFS('11_Problemas'!$C$5:$C$31,'11_Problemas'!$A$5:$A$31,"DIFERENCIA_DETERIORO",'11_Problemas'!$C$5:$C$31,">0")-SUMIFS('11_Problemas'!$C$5:$C$31,'11_Problemas'!$A$5:$A$31,"DIFERENCIA_DETERIORO",'11_Problemas'!$C$5:$C$31,"<0")))

Sheet 00_Caratula
A1: Carátula | H1: ⟵ Inicio | J1: Siguiente ▶
A2: Inversiones e instrumentos financieros · Cliente de muestra S.A. · corte 2025-12-31
A4: Concepto | B4: Detalle
A5: Firma | B5: AuditConsulting Auditores Cía. Ltda.
A6: Cliente | B6: Cliente de muestra S.A.
A7: RUC | B7: 1790000000001
A8: Ejercicio | B8: 2025
A9: Fecha de corte | B9: 2025-12-31
A10: Marco contable | B10: NIIF completas
A11: Herramienta | B11: Inversiones e instrumentos financieros
A12: Rubro | B12: Inversiones
A13: Motor | B13: inversiones_instrumentos 1.0
A14: Versión del papel | B14: v1
A15: Estado | B15: MUESTRA
... A17: Revisó | B17: Pendiente
A18: Aprobó
A19: Fecha de aprobación
A20: Huella de la ejecución (SHA-256)

Sheet 00_Programa
A1: Programa | H1: ⟵ Inicio | I1: ◀ Anterior | J1: Siguiente ▶
A2: Inversiones e instrumentos financieros · Cliente de muestra S.A. · corte 2025-12-31
A4: Código | B4: Objetivo | C4: Afirmación | D4: Procedimiento | E4: Evidencia | F4: Criterio | G4: Referencia
A5: INV-01 | B5: Existencia e integridad | C5: Existencia | D5: Conciliar el anexo por instrumento con el mayor y confirmar con custodios | E5: Anexo, mayor, confirmaciones | F5: Diferencias explicadas; tenencia confirmada | G5: NIA 500 párr. 9 · NIA 505
A6: INV-02 | B6: Clasificación de instrumentos | C6: Clasificación | D6: Evaluar modelo de negocio y SPPI (NIIF 9) o instrumento básico (PYMES) y comparar con la clasificación del cliente | E6: Políticas de inversión, actas, prospectos | F6: Clasificación consistente con la norma | G6: NIIF 9 4.1.1–4.1.5 · PYMES 11.8–11.9 (2025: y 11.9ZA), 11.14
A7: INV-03 | B7: Costo amortizado | C7: Valoración | D7: Recalcular la TIE y el costo amortizado al corte | E7: Prospectos, liquidaciones de compra | F7: Diferencia cuantificada | G7: NIIF 9 5.4.1, apéndice A · PYMES 11.15–11.20
A8: INV-04 | B8: Valor razonable | C8: Valoración | D8: Contrastar precios de cierre o valoraciones y el nivel de jerarquía; recalcular la ganancia o pérdida | E8: Vector de precios, bolsa, valuaciones | F8: Diferencia contra libros evaluada | G8: NIIF 13 72–90 · PYMES 2025 12.22–12.27 · PYMES 2015 11.27 · NIA 540
A9: INV-05 | B9: Intereses y dividendos | C9: Integridad | D9: Recalcular interés efectivo y dividendos decretados y comparar con lo registrado | E9: Estados de cuenta, actas de dividendos | F9: Diferencia cuantificada | G9: NIIF 9 5.4.1, 5.7.1A · PYMES 2025 11.14A y 11.55
A10: INV-06 | B10: Deterioro | C10: Valoración | D10: Evaluar indicios y calificaciones y recalcular el deterioro | E10: Calificaciones de riesgo, información del emisor | F10: Deterioro recalculado vs registrado | G10: NIIF 9 5.5.1–5.5.5, 5.5.17 · PYMES 11.21–11.26
A11: INV-07 | B11: Reclasificación | C11: Presentación | D11: Revisar cambios de categoría respecto del cierre anterior y su tratamiento | E11: Actas del directorio, políticas | F11: Solo por cambio de modelo, tratamiento 5.6 | G11: NIIF 9 4.4.1, 5.6.1–5.6.7, 5.7.5

Sheet 00_Fuentes
A1: Base técnica | H1: ⟵ Inicio | I1: ◀ Anterior | J1: Siguiente ▶
A2: Inversiones e instrumentos financieros · Cliente de muestra S.A. · corte 2025-12-31
A4: Categoría | B4: Documento | C4: Párrafos | D4: URL | E4: Verificada
A5: NIA · NIA 540 (Revisada) | B5: Valor razonable de nivel 2–3, TIE y pérdida esperada: evaluar método, datos y supuestos y el posible sesgo. | C5: párr. 13, 16–30 y 32
A6: NIA · NIA 500 | B6: Integridad y exactitud del anexo de inversiones contra el mayor. | C6: párr. 6 y 9
A7: NIA · NIA 505 | B7: Confirmar existencia y tenencia con custodios, casas de valores o emisores. | C7: párr. 7
A8: NIA · NIA 620 | B8: Uso de un experto para valoraciones de nivel 3 cuando corresponda. | C8: párr. 7

Sheet 01_Resumen
A1: Resumen | H1: ⟵ Inicio | I1: ◀ Anterior | J1: Siguiente ▶
A2: Inversiones e instrumentos financieros · Cliente de muestra S.A. · corte 2025-12-31
A4: Concepto | B4: Importe
A5: Saldo en libros (bruto) | B5: ='10_Conciliacion'!D16
A6: Medición según la norma | B6: ='10_Conciliacion'!C16
A7: Diferencia de medición | B7: ='10_Conciliacion'!E16
A8: Deterioro recalculado | B8: ='08_Deterioro'!I16
A9: Deterioro registrado | B9: ='08_Deterioro'!J16
A10: Intereses/dividendos no registrados | B10: ='07_Intereses_dividendos'!F16
A11: Diferencia de valor razonable | B11: ='06_Valor_razonable'!F12
A12: Ajuste propuesto (importe neto) | B12: ='10_Conciliacion'!I16
A14: ⓘ Cómo se calcula esta hoja
A15: Columna | B15: Fórmula (Excel) | C15: Cómo se calcula (sencillo) | D15: Ejemplo con números reales | E15: De dónde viene | F15: Norma
A16: Importe | B16: '='10_Conciliacion'!D16 | C16: Trae cada cifra de la fila TOTAL de su hoja: saldo, medición, diferencia y ajuste de la hoja 10 (Conciliación y ajuste), deterioro de la hoja 08, ingresos no registrados de la hoja 07 y diferencia de valor razonable de la hoja 06. | D16: Fila 1: 326.400,00 → 326.400,00 | E16: hoja «Conciliación y ajuste» | F16: —

Sheet 02_Parametros
A1: Parámetros | H1: ⟵ Inicio | I1: ◀ Anterior | J1: Siguiente ▶
A2: Inversiones e instrumentos financieros · Cliente de muestra S.A. · corte 2025-12-31
A4: Parámetro | B4: Valor | C4: Sustento
A5: Fecha de corte | B5: 46022 | C5: Ficha del encargo
A6: Inicio del ejercicio (un año antes del corte) | B6: 45657 | C6: Base del interés del ejercicio
A7: Marco contable | B7: NIIF completas | C7: Enruta clasificación y deterioro
A8: Pagos de cupón por año (por defecto) | B8: 1 | C8: Solo si el anexo no lo indica
A9: CA | B9: Costo amortizado | C9: NIIF 9 4.1.2 · PYMES 11.14 a
A10: VRORI | B10: VR con cambios en ORI | C10: NIIF 9 4.1.2A y 5.7.5 · no existe en PYMES
A11: VRR | B11: VR con cambios en resultados | C11: NIIF 9 4.1.4 · PYMES 2015 12.8 / 2025 11.54 y 11.14 c i
A12: COSTO | B12: Costo menos deterioro | C12: Solo PYMES 11.14 c ii

Sheet 03_Inventario
A1: Inventario de inversiones | H1: ⟵ Inicio | I1: ◀ Anterior | J1: Siguiente ▶
A2: Inversiones e instrumentos financieros · Cliente de muestra S.A. · corte 2025-12-31
A4: Instrumento | B4: Emisor | C4: Tipo | D4: Modelo de negocio | E4: SPPI / básico | F4: Clasificación del cliente | G4: Código cliente | H4: Adquisición | I4: Vencimiento | J4: Nominal | K4: Costo | L4: Cupón % | M4: Pagos por año | N4: Saldo en libros | O4: Valor razonable | P4: Nivel | Q4: Deterioro registrado | R4: Ingreso registrado | S4: Dividendos decretados | T4: Indicio | U4: Calificación | V4: PD % | W4: LGD % | X4: Clasificación anterior | Y4: Cambio de modelo | Z4: Básico 11.9 a)–d) (PYMES) | AA4: Estimación de venta al cierre (11.25 b)
A5: BONO-01 | B5: Bonos del Estado (ficticio) | C5: Deuda | D5: Mantener para cobrar | E5: Sí | F5: Costo amortizado | G5: CA | H5: 45473 | I5: 47299 | J5: 100000 | K5: 96000 | L5: 8 | M5: 2 | N5: 96500 | O5: 97200 | P5: 2 | Q5: 0 | R5: 8000 | T5: No | U5: AA | V5: 1 | W5: 45
A6: CDP-02 | B6: Banco del Litoral (ficticio) | C6: Deuda | D6: Mantener para cobrar | E6: Sí | F6: Costo amortizado | G6: CA | H6: 45853 | I6: 46218 | J6: 50000 | K6: 50000 | L6: 6 | M6: 1 | N6: 50000 | Q6: 100 | R6: 0 | T6: No | U6: AAA | V6: 0.5 | W6: 40
A7: OBL-03 | B7: Industrial Andina (ficticio) | C7: Deuda | D7: Cobrar y vender | E7: Sí | F7: Costo amortizado | G7: CA | H7: 45382 | I7: 46477 | J7: 30000 | K7: 30600 | L7: 9 | M7: 4 | N7: 30400 | O7: 29400 | P7: 2 | R7: 2500 | T7: No | U7: A | V7: 1 | W7: 45
A8: ACC-04 | B8: Comercial Andina (ficticio) | C8: Patrimonio | D8: Negociar | F8: VR con cambios en resultados | G8: VRR | K8: 40000 | M8: 1 | N8: 42000 | O8: 45000 | P8: 1 | R8: 1800 | S8: 1800
A9: ACC-05 | B9: Inmobiliaria Sur (ficticio) | C9: Patrimonio | D9: Mantener para cobrar | F9: VR con cambios en ORI | G9: VRORI | K9: 10000 | M9: 1 | N9: 12500 | O9: 12500 | P9: 3 | R9: 0 | S9: 500
A10: FND-06 | B10: Fondo Renta Fija (ficticio) | C10: Fondo | D10: Negociar | F10: VR con cambios en resultados | G10: VRR | K10: 19000 | M10: 1 | N10: 20000 | O10: 20500 | R10: 0
A11: PAG-07 | B11: Distribuidora Norte (ficticio) | C11: Deuda | D11: Mantener para cobrar | E11: Sí | F11: Costo amortizado | G11: CA | H11: 45565 | I11: 46295 | J11: 25000 | K11: 25000 | L11: 10 | M11: 2 | N11: 25000 | Q11: 3000 | R11: 2500 | T11: Sí | U11: C | V11: 60 | W11: 50
A12: BONO-08 | B12: Energía Convertible (ficticio) | C12: Deuda | D12: Mantener para cobrar | E12: No | F12: Costo amortizado | G12: CA | H12: 45688 | I12: 46783 | J12: 15000 | K12: 15000 | L12: 5 | M12: 1 | N12: 15000 | O12: 15800 | P12: 2 | R12: 687.5
A13: POL-09 | B13: Financiera Pacífico (ficticio) | C13: Deuda | D13: Mantener para cobrar | E13: Sí | F13: Costo amortizado | G13: CA | H13: 45961 | I13: 46142 | J13: 10000 | K13: 9800 | L13: 0 | M13: 2 | N13: 9800 | R13: 0 | T13: No | U13: BB | V13: 2 | W13: 40
A14: OBL-10 | B14: Eléctrica Costa (ficticio) | C14: Deuda | D14: Cobrar y vender | E14: Sí | F14: VR con cambios en ORI | G14: VRORI | H14: 45291 | I14: 47118 | J14: 20000 | K14: 20000 | L14: 8 | M14: 1 | N14: 20200 | O14: 20200 | P14: 2 | Q14: 0 | R14: 1600 | T14: No | U14: A | V14: 1.5 | W14: 45 | X14: CA | Y14: No
A15: BONO-11 | B15: Constructora Sierra (ficticio) | C15: Deuda | D15: Mantener para cobrar | E15: Sí | F15: Costo amortizado | G15: CA | H15: 45260 | I15: 45991 | J15: 5000 | K15: 5000 | L15: 7 | M15: 1 | N15: 5000 | R15: 350

Sheet 04_Clasificacion
A1: Clasificación | H1: ⟵ Inicio | I1: ◀ Anterior | J1: Siguiente ▶
A2: Inversiones e instrumentos financieros · Cliente de muestra S.A. · corte 2025-12-31
A4: Instrumento | B4: Tipo | C4: Modelo de negocio | D4: ¿Flujos solo principal e intereses? | E4: ¿Básico 11.9 a)–d)? (PYMES) | F4: Clasificación del cliente | G4: ¿VR medible? | H4: Clasificación según la norma | I4: ¿Consistente? | J4: Fundamento
A5: BONO-01 | B5: ='03_Inventario'!C5&"" | C5: ='03_Inventario'!D5&"" | D5: ='03_Inventario'!E5&"" | E5: ='03_Inventario'!Z5&"" | F5: ='03_Inventario'!G5&"" | G5: =IF('03_Inventario'!O5<>"","Sí","No") | H5: =IF(B5="Deuda",IF(D5="","",IF(D5="No","VRR",IF(C5="Mantener para cobrar","CA",IF(C5="Cobrar y vender","VRORI",IF(C5="Negociar","VRR",""))))),IF(B5="Patrimonio",IF(AND(F5="VRORI",C5<>"Negociar"),"VRORI","VRR"),"VRR")) | I5: =IF(H5="","",IF(H5=F5,"Sí","No")) | J5: SPPI y mantener para cobrar: costo amortizado (4.1.2).
A6: CDP-02 | B6: ='03_Inventario'!C6&"" | C6: ='03_Inventario'!D6&"" | D6: ='03_Inventario'!E6&"" | E6: ='03_Inventario'!Z6&"" | F6: ='03_Inventario'!G6&"" | G6: =IF('03_Inventario'!O6<>"","Sí","No") | H6: =IF(B6="Deuda",IF(D6="","",IF(D6="No","VRR",IF(C6="Mantener para cobrar","CA",IF(C6="Cobrar y vender","VRORI",IF(C6="Negociar","VRR",""))))),IF(B6="Patrimonio",IF(AND(F6="VRORI",C6<>"Negociar"),"VRORI","VRR"),"VRR")) | I6: =IF(H6="","",IF(H6=F6,"Sí","No")) | J6: SPPI y mantener para cobrar: costo amortizado (4.1.2).
A7: OBL-03 | B7: ='03_Inventario'!C7&"" | C7: ='03_Inventario'!D7&"" | D7: ='03_Inventario'!E7&"" | E7: ='03_Inventario'!Z7&"" | F7: ='03_Inventario'!G7&"" | G7: =IF('03_Inventario'!O7<>"","Sí","No") | H7: =IF(B7="Deuda",IF(D7="","",IF(D7="No","VRR",IF(C7="Mantener para cobrar","CA",IF(C7="Cobrar y vender","VRORI",IF(C7="Negociar","VRR",""))))),IF(B7="Patrimonio",IF(AND(F7="VRORI",C7<>"Negociar"),"VRORI","VRR"),"VRR")) | I7: =IF(H7="","",IF(H7=F7,"Sí","No")) | J7: SPPI y cobrar y vender: VR con cambios en ORI (4.1.2A).
A8: ACC-04 | B8: ='03_Inventario'!C8&"" | C8: ='03_Inventario'!D8&"" | D8: ='03_Inventario'!E8&"" | E8: ='03_Inventario'!Z8&"" | F8: ='03_Inventario'!G8&"" | G8: =IF('03_Inventario'!O8<>"","Sí","No") | H8: =IF(B8="Deuda",IF(D8="","",IF(D8="No","VRR",IF(C8="Mantener para cobrar","CA",IF(C8="Cobrar y vender","VRORI",IF(C8="Negociar","VRR",""))))),IF(B8="Patrimonio",IF(AND(F8="VRORI",C8<>"Negociar"),"VRORI","VRR"),"VRR")) | I8: =IF(H8="","",IF(H8=F8,"Sí","No")) | J8: Patrimonio: VR con cambios en resultados (4.1.4).
A9: ACC-05 | B9: ='03_Inventario'!C9&"" | C9: ='03_Inventario'!D9&"" | D9: ='03_Inventario'!E9&"" | E9: ='03_Inventario'!Z9&"" | F9: ='03_Inventario'!G9&"" | G9: =IF('03_Inventario'!O9<>"","Sí","No") | H9: =IF(B9="Deuda",IF(D9="","",IF(D9="No","VRR",IF(C9="Mantener para cobrar","CA",IF(C9="Cobrar y vender","VRORI",IF(C9="Negociar","VRR",""))))),IF(B9="Patrimonio",IF(AND(F9="VRORI",C9<>"Negociar"),"VRORI","VRR"),"VRR")) | I9: =IF(H9="","",IF(H9=F9,"Sí","No")) | J9: Elección irrevocable de ORI para patrimonio no mantenido para negociar (4.1.4, 5.7.5, B5.7.1); dividendos a resultados (5.7.6).
A10: FND-06 | B10: ='03_Inventario'!C10&"" | C10: ='03_Inventario'!D10&"" | D10: ='03_Inventario'!E10&"" | E10: ='03_Inventario'!Z10&"" | F10: ='03_Inventario'!G10&"" | G10: =IF('03_Inventario'!O10<>"","Sí","No") | H10: =IF(B10="Deuda",IF(D10="","",IF(D10="No","VRR",IF(C10="Mantener para cobrar","CA",IF(C10="Cobrar y vender","VRORI",IF(C10="Negociar","VRR",""))))),IF(B10="Patrimonio",IF(AND(F10="VRORI",C10<>"Negociar"),"VRORI","VRR"),"VRR")) | I10: =IF(H10="","",IF(H10=F10,"Sí","No")) | J10: Derivado o participación en fondo: VR con cambios en resultados (4.1.4; fondos: flujos no SPPI, revisar B4.1.7–B4.1.26).
A11: PAG-07 | B11: ='03_Inventario'!C11&"" | C11: ='03_Inventario'!D11&"" | D11: ='03_Inventario'!E11&"" | E11: ='03_Inventario'!Z11&"" | F11: ='03_Inventario'!G11&"" | G11: =IF('03_Inventario'!O11<>"","Sí","No") | H11: =IF(B11="Deuda",IF(D11="","",IF(D11="No","VRR",IF(C11="Mantener para cobrar","CA",IF(C11="Cobrar y vender","VRORI",IF(C11="Negociar","VRR",""))))),IF(B11="Patrimonio",IF(AND(F11="VRORI",C11<>"Negociar"),"VRORI","VRR"),"VRR")) | I11: =IF(H11="","",IF(H11=F11,"Sí","No")) | J11: SPPI y mantener para cobrar: costo amortizado (4.1.2).
A12: BONO-08 | B12: ='03_Inventario'!C12&"" | C12: ='03_Inventario'!D12&"" | D12: ='03_Inventario'!E12&"" | E12: ='03_Inventario'!Z12&"" | F12: ='03_Inventario'!G12&"" | G12: =IF('03_Inventario'!O12<>"","Sí","No") | H12: =IF(B12="Deuda",IF(D12="","",IF(D12="No","VRR",IF(C12="Mantener para cobrar","CA",IF(C12="Cobrar y vender","VRORI",IF(C12="Negociar","VRR",""))))),IF(B12="Patrimonio",IF(AND(F12="VRORI",C12<>"Negociar"),"VRORI","VRR"),"VRR")) | I12: =IF(H12="","",IF(H12=F12,"Sí","No")) | J12: No SPPI o modelo de negociación: VR con cambios en resultados (4.1.4); designación 4.1.5 solo si elimina una asimetría.
A13: POL-09 | B13: ='03_Inventario'!C13&"" | C13: ='03_Inventario'!D13&"" | D13: ='03_Inventario'!E13&"" | E13: ='03_Inventario'!Z13&"" | F13: ='03_Inventario'!G13&"" | G13: =IF('03_Inventario'!O13<>"","Sí","No") | H13: =IF(B13="Deuda",IF(D13="","",IF(D13="No","VRR",IF(C13="Mantener para cobrar","CA",IF(C13="Cobrar y vender","VRORI",IF(C13="Negociar","VRR",""))))),IF(B13="Patrimonio",IF(AND(F13="VRORI",C13<>"Negociar"),"VRORI","VRR"),"VRR")) | I13: =IF(H13="","",IF(H13=F13,"Sí","No")) | J13: SPPI y mantener para cobrar: costo amortizado (4.1.2).
A14: OBL-10 | B14: ='03_Inventario'!C14&"" | C14: ='03_Inventario'!D14&"" | D14: ='03_Inventario'!E14&"" | E14: ='03_Inventario'!Z14&"" | F14: ='03_Inventario'!G14&"" | G14: =IF('03_Inventario'!O14<>"","Sí","No") | H14: =IF(B14="Deuda",IF(D14="","",IF(D14="No","VRR",IF(C14="Mantener para cobrar","CA",IF(C14="Cobrar y vender","VRORI",IF(C14="Negociar","VRR",""))))),IF(B14="Patrimonio",IF(AND(F14="VRORI",C14<>"Negociar"),"VRORI","VRR"),"VRR")) | I14: =IF(H14="","",IF(H14=F14,"Sí","No")) | J14: SPPI y cobrar y vender: VR con cambios en ORI (4.1.2A).
A15: BONO-11 | B15: ='03_Inventario'!C15&"" | C15: ='03_Inventario'!D15&"" | D15: ='03_Inventario'!E15&"" | E15: ='03_Inventario'!Z15&"" | F15: ='03_Inventario'!G15&"" | G15: =IF('03_Inventario'!O15<>"","Sí","No") | H15: =IF(B15="Deuda",IF(D15="","",IF(D15="No","VRR",IF(C15="Mantener para cobrar","CA",IF(C15="Cobrar y vender","VRORI",IF(C15="Negociar","VRR",""))))),IF(B15="Patrimonio",IF(AND(F15="VRORI",C15<>"Negociar"),"VRORI","VRR"),"VRR")) | I15: =IF(H15="","",IF(H15=F15,"Sí","No")) | J15: SPPI y mantener para cobrar: costo amortizado (4.1.2).
A17: ⓘ Cómo se calcula esta hoja
A18: Columna | B18: Fórmula (Excel) | C18: Cómo se calcula (sencillo) | D18: Ejemplo con números reales | E18: De dónde viene | F18: Norma
A19: Tipo | B19: '='03_Inventario'!C5&"" | C19: Copia el tipo de instrumento (deuda, patrimonio u otro) del inventario de la hoja 03 (Inventario de inversiones). | D19: Fila 1: «Deuda»&"" → Deuda | E19: hoja «Inventario de inversiones» | F19: —
A20: Modelo de negocio | B20: '='03_Inventario'!D5&"" | C20: Copia el modelo de negocio informado por el cliente en la hoja 03 (Inventario de inversiones); si no se informó, queda en blanco. | D20: Fila 1: «Mantener para cobrar»&"" → Mantener para cobrar | E20: hoja «Inventario de inversiones» | F20: —
A21: ¿Flujos solo principal e intereses? | B21: '='03_Inventario'!E5&"" | C21: Copia de la hoja 03 (Inventario de inversiones) la respuesta a si los flujos del instrumento son solo pagos de principal e intereses (SPPI). | D21: Fila 1: «Sí»&"" → Sí | E21: hoja «Inventario de inversiones» | F21: —
A22: ¿Básico 11.9 a)–d)? (PYMES) | B22: '='03_Inventario'!Z5&"" | C22: Copia de la hoja 03 (Inventario de inversiones) si el instrumento cumple las condiciones de instrumento básico 11.9 a)–d); este dato solo lo usa la clasificación para PYMES. | D22: Fila 1: (vacío)&"" → (en blanco) | E22: hoja «Inventario de inversiones» | F22: —
A23: Clasificación del cliente | B23: '='03_Inventario'!G5&"" | C23: Copia el código de clasificación que el cliente dio al instrumento (CA, VRORI, VRR o COSTO) desde la hoja 03 (Inventario de inversiones). | D23: Fila 1: «CA»&"" → CA | E23: hoja «Inventario de inversiones» | F23: —
A24: ¿VR medible? | B24: '=IF('03_Inventario'!O5<>"","Sí","No") | C24: Responde «Sí» si en la hoja 03 (Inventario de inversiones) hay un valor razonable informado para el instrumento y «No» si esa celda está vacía. | D24: Fila 1: IF(97.200,00<>""; "Sí"; "No") → Sí | E24: hoja «Inventario de inversiones» | F24: —
A25: Clasificación según la norma | B25: '=IF(B5="Deuda",IF(D5="","",IF(D5="No","VRR",IF(C5="Mantener para cobrar","CA",IF(C5="Cobrar y vender","VRORI",IF(C5="Negociar","VRR",""))))),IF(B5="Patrimonio",IF(AND(F5="VRORI",C5<>"Negociar"),"VRORI","VRR"),"VRR")) | C25: Aplica la regla de NIIF 9: la deuda cuyos flujos no son solo principal e intereses va a VRR; si lo son, va a costo amortizado (CA) con el modelo «Mantener para cobrar», a VRORI con «Cobrar y vender» y a VRR con «Negociar». Las acciones van a VRORI solo si el cliente eligió VRORI y no se mantienen para negociar; si no, a VRR. Si falta el dato de flujos de la deuda, queda en blanco. | D25: Fila 1: IF(«Deuda»="Deuda"; IF(«Sí»=""; ""; IF(«Sí»="No"; "VRR"; IF(«Mantener para cobrar»="Mantener para cobrar"; "CA"; IF(«Mantener para cobrar»="Cobrar y vender"; "VRORI"; IF(«Mantener para cobrar»="Negociar"; "VRR"; ""))))); IF(«Deuda»="Patrimonio"; IF(AND(«CA»="VRORI"; «Mantener para cobrar»<>"Negociar"); "VRORI"; "VRR"); "VRR")) → CA | E25: «Tipo» (esta hoja), «¿Flujos solo principal e intereses?» (esta hoja), «Modelo de negocio» (esta hoja), «Clasificación del cliente» (esta hoja) | F25: —
A26: ¿Consistente? | B26: '=IF(H5="","",IF(H5=F5,"Sí","No")) | C26: Compara la clasificación según la norma con la del cliente: «Sí» si coinciden, «No» si difieren y en blanco si la norma no se pudo determinar por falta de datos. | D26: Fila 1: IF(«CA»=""; ""; IF(«CA»=«CA»; "Sí"; "No")) → Sí | E26: «Clasificación según la norma» (esta hoja), «Clasificación del cliente» (esta hoja) | F26: —

Sheet 05_Costo_amortizado
A1: Costo amortizado y TIE | H1: ⟵ Inicio | I1: ◀ Anterior | J1: Siguiente ▶
A2: Inversiones e instrumentos financieros · Cliente de muestra S.A. · corte 2025-12-31
A4: Instrumento | B4: Adquisición | C4: Vencimiento | D4: Nominal | E4: Costo | F4: Cupón % | G4: Pagos por año | H4: Meses por período | I4: Períodos totales | J4: Cupón por período | K4: TIE periódica | L4: TIE anual | M4: Control VA − costo | N4: Cupones cobrados al corte | O4: Fracción del período | P4: CA al último cupón | Q4: CA al corte (con cupón corrido) | R4: Cupón corrido | S4: CA al corte (limpio) | T4: Cupones cobrados al inicio | U4: CA al inicio del ejercicio | V4: Cupones cobrados en el ejercicio | W4: Interés efectivo del ejercicio
A5: BONO-01 | B5: 45473 | C5: 47299 | D5: ='03_Inventario'!J5 | E5: ='03_Inventario'!K5 | F5: ='03_Inventario'!L5 | G5: ='03_Inventario'!M5 | H5: =12/G5 | I5: =ROUND(DATEDIF(B5,C5,"m")/H5,0) | J5: =D5*F5/100/G5 | K5: =RATE(I5,J5,-E5,D5) | L5: =(1+K5)^G5-1 | M5: =PV(K5,I5,-J5,-D5)-E5 | N5: =INT(DATEDIF(B5,'02_Parametros'!$B$5,"m")/H5) | O5: =('02_Parametros'!$B$5-EDATE(B5,N5*H5))/(EDATE(B5,(N5+1)*H5)-EDATE(B5,N5*H5)) | P5: =PV(K5,I5-N5,-J5,-D5) | Q5: =P5*(1+K5*O5) | R5: =J5*O5 | S5: =Q5-R5 | T5: =IF(B5>'02_Parametros'!$B$6,0,INT(DATEDIF(B5,'02_Parametros'!$B$6,"m")/H5)) | U5: =IF(B5>'02_Parametros'!$B$6,E5,PV(K5,I5-T5,-J5,-D5)*(1+K5*('02_Parametros'!$B$6-EDATE(B5,T5*H5))/(EDATE(B5,(T5+1)*H5)-EDATE(B5,T5*H5)))) | V5: =J5*(N5-T5) | W5: =Q5-U5+V5
A6: CDP-02 | B6: 45853 | C6: 46218 | D6: ='03_Inventario'!J6 | E6: ='03_Inventario'!K6 | F6: ='03_Inventario'!L6 | G6: ='03_Inventario'!M6 | H6: =12/G6 | I6: =ROUND(DATEDIF(B6,C6,"m")/H6,0) | J6: =D6*F6/100/G6 | K6: =RATE(I6,J6,-E6,D6) | L6: =(1+K6)^G6-1 | M6: =PV(K6,I6,-J6,-D6)-E6 | N6: =INT(DATEDIF(B6,'02_Parametros'!$B$5,"m")/H6) | O6: =('02_Parametros'!$B$5-EDATE(B6,N6*H6))/(EDATE(B6,(N6+1)*H6)-EDATE(B6,N6*H6)) | P6: =PV(K6,I6-N6,-J6,-D6) | Q6: =P6*(1+K6*O6) | R6: =J6*O6 | S6: =Q6-R6 | T6: =IF(B6>'02_Parametros'!$B$6,0,INT(DATEDIF(B6,'02_Parametros'!$B$6,"m")/H6)) | U6: =IF(B6>'02_Parametros'!$B$6,E6,PV(K6,I6-T6,-J6,-D6)*(1+K6*('02_Parametros'!$B$6-EDATE(B6,T6*H6))/(EDATE(B6,(T6+1)*H6)-EDATE(B6,T6*H6)))) | V6: =J6*(N6-T6) | W6: =Q6-U6+V6
A7: OBL-03 | B7: 45382 | C7: 46477 | D7: ='03_Inventario'!J7 | E7: ='03_Inventario'!K7 | F7: ='03_Inventario'!L7 | G7: ='03_Inventario'!M7 | H7: =12/G7 | I7: =ROUND(DATEDIF(B7,C7,"m")/H7,0) | J7: =D7*F7/100/G7 | K7: =RATE(I7,J7,-E7,D7) | L7: =(1+K7)^G7-1 | M7: =PV(K7,I7,-J7,-D7)-E7 | N7: =INT(DATEDIF(B7,'02_Parametros'!$B$5,"m")/H7) | O7: =('02_Parametros'!$B$5-EDATE(B7,N7*H7))/(EDATE(B7,(N7+1)*H7)-EDATE(B7,N7*H7)) | P7: =PV(K7,I7-N7,-J7,-D7) | Q7: =P7*(1+K7*O7) | R7: =J7*O7 | S7: =Q7-R7 | T7: =IF(B7>'02_Parametros'!$B$6,0,INT(DATEDIF(B7,'02_Parametros'!$B$6,"m")/H7)) | U7: =IF(B7>'02_Parametros'!$B$6,E7,PV(K7,I7-T7,-J7,-D7)*(1+K7*('02_Parametros'!$B$6-EDATE(B7,T7*H7))/(EDATE(B7,(T7+1)*H7)-EDATE(B7,T7*H7)))) | V7: =J7*(N7-T7) | W7: =Q7-U7+V7
A8: PAG-07 | B8: 45565 | C8: 46295 | D8: ='03_Inventario'!J11 | E8: ='03_Inventario'!K11 | F8: ='03_Inventario'!L11 | G8: ='03_Inventario'!M11 | H8: =12/G8 | I8: =ROUND(DATEDIF(B8,C8,"m")/H8,0) | J8: =D8*F8/100/G8 | K8: =RATE(I8,J8,-E8,D8) | L8: =(1+K8)^G8-1 | M8: =PV(K8,I8,-J8,-D8)-E8 | N8: =INT(DATEDIF(B8,'02_Parametros'!$B$5,"m")/H8) | O8: =('02_Parametros'!$B$5-EDATE(B8,N8*H8))/(EDATE(B8,(N8+1)*H8)-EDATE(B8,N8*H8)) | P8: =PV(K8,I8-N8,-J8,-D8) | Q8: =P8*(1+K8*O8) | R8: =J8*O8 | S8: =Q8-R8 | T8: =IF(B8>'02_Parametros'!$B$6,0,INT(DATEDIF(B8,'02_Parametros'!$B$6,"m")/H8)) | U8: =IF(B8>'02_Parametros'!$B$6,E8,PV(K8,I8-T8,-J8,-D8)*(1+K8*('02_Parametros'!$B$6-EDATE(B8,T8*H8))/(EDATE(B8,(T8+1)*H8)-EDATE(B8,T8*H8)))) | V8: =J8*(N8-T8) | W8: =Q8-U8+V8
A9: BONO-08 | B9: 45688 | C9: 46783 | D9: ='03_Inventario'!J12 | E9: ='03_Inventario'!K12 | F9: ='03_Inventario'!L12 | G9: ='03_Inventario'!M12 | H9: =12/G9 | I9: =ROUND(DATEDIF(B9,C9,"m")/H9,0) | J9: =D9*F9/100/G9 | K9: =RATE(I9,J9,-E9,D9) | L9: =(1+K9)^G9-1 | M9: =PV(K9,I9,-J9,-D9)-E9 | N9: =INT(DATEDIF(B9,'02_Parametros'!$B$5,"m")/H9) | O9: =('02_Parametros'!$B$5-EDATE(B9,N9*H9))/(EDATE(B9,(N9+1)*H9)-EDATE(B9,N9*H9)) | P9: =PV(K9,I9-N9,-J9,-D9) | Q9: =P9*(1+K9*O9) | R9: =J9*O9 | S9: =Q9-R9 | T9: =IF(B9>'02_Parametros'!$B$6,0,INT(DATEDIF(B9,'02_Parametros'!$B$6,"m")/H9)) | U9: =IF(B9>'02_Parametros'!$B$6,E9,PV(K9,I9-T9,-J9,-D9)*(1+K9*('02_Parametros'!$B$6-EDATE(B9,T9*H9))/(EDATE(B9,(T9+1)*H9)-EDATE(B9,T9*H9)))) | V9: =J9*(N9-T9) | W9: =Q9-U9+V9
A10: POL-09 | B10: 45961 | C10: 46142 | D10: ='03_Inventario'!J13 | E10: ='03_Inventario'!K13 | F10: ='03_Inventario'!L13 | G10: ='03_Inventario'!M13 | H10: =12/G10 | I10: =ROUND(DATEDIF(B10,C10,"m")/H10,0) | J10: =D10*F10/100/G10 | K10: =RATE(I10,J10,-E10,D10) | L10: =(1+K10)^G10-1 | M10: =PV(K10,I10,-J10,-D10)-E10 | N10: =INT(DATEDIF(B10,'02_Parametros'!$B$5,"m")/H10) | O10: =('02_Parametros'!$B$5-EDATE(B10,N10*H10))/(EDATE(B10,(N10+1)*H10)-EDATE(B10,N10*H10)) | P10: =PV(K10,I10-N10,-J10,-D10) | Q10: =P10*(1+K10*O10) | R10: =J10*O10 | S10: =Q10-R10 | T10: =IF(B10>'02_Parametros'!$B$6,0,INT(DATEDIF(B10,'02_Parametros'!$B$6,"m")/H10)) | U10: =IF(B10>'02_Parametros'!$B$6,E10,PV(K10,I10-T10,-J10,-D10)*(1+K10*('02_Parametros'!$B$6-EDATE(B10,T10*H10))/(EDATE(B10,(T10+1)*H10)-EDATE(B10,T10*H10)))) | V10: =J10*(N10-T10) | W10: =Q10-U10+V10
A11: OBL-10 | B11: 45291 | C11: 47118 | D11: ='03_Inventario'!J14 | E11: ='03_Inventario'!K14 | F11: ='03_Inventario'!L14 | G11: ='03_Inventario'!M14 | H11: =12/G11 | I11: =ROUND(DATEDIF(B11,C11,"m")/H11,0) | J11: =D11*F11/100/G11 | K11: =RATE(I11,J11,-E11,D11) | L11: =(1+K11)^G11-1 | M11: =PV(K11,I11,-J11,-D11)-E11 | N11: =INT(DATEDIF(B11,'02_Parametros'!$B$5,"m")/H11) | O11: =('02_Parametros'!$B$5-EDATE(B11,N11*H11))/(EDATE(B11,(N11+1)*H11)-EDATE(B11,N11*H11)) | P11: =PV(K11,I11-N11,-J11,-D11) | Q11: =P11*(1+K11*O11) | R11: =J11*O11 | S11: =Q11-R11 | T11: =IF(B11>'02_Parametros'!$B$6,0,INT(DATEDIF(B11,'02_Parametros'!$B$6,"m")/H11)) | U11: =IF(B11>'02_Parametros'!$B$6,E11,PV(K11,I11-T11,-J11,-D11)*(1+K11*('02_Parametros'!$B$6-EDATE(B11,T11*H11))/(EDATE(B11,(T11+1)*H11)-EDATE(B11,T11*H11)))) | V11: =J11*(N11-T11) | W11: =Q11-U11+V11
A12: TOTAL | D12: =SUM(D5:D11) | E12: =SUM(E5:E11) | Q12: =SUM(Q5:Q11) | R12: =SUM(R5:R11) | S12: =SUM(S5:S11) | U12: =SUM(U5:U11) | V12: =SUM(V5:V11) | W12: =SUM(W5:W11)
A14: ⓘ Cómo se calcula esta hoja
A15: Columna | B15: Fórmula (Excel) | C15: Cómo se calcula (sencillo) | D15: Ejemplo con números reales | E15: De dónde viene | F15: Norma
A16: Nominal | B16: '='03_Inventario'!J5 | C16: Trae el valor nominal (lo que se cobrará al vencimiento) del instrumento desde la hoja 03 (Inventario de inversiones). | D16: Fila 1: 100.000,00 → 100.000,00 | E16: hoja «Inventario de inversiones» | F16: —
A17: Costo | B17: '='03_Inventario'!K5 | C17: Trae el costo de adquisición pagado por el instrumento desde la hoja 03 (Inventario de inversiones). | D17: Fila 1: 96.000,00 → 96.000,00 | E17: hoja «Inventario de inversiones» | F17: —
A18: Cupón % | B18: '='03_Inventario'!L5 | C18: Trae la tasa de cupón anual del instrumento, en porcentaje, desde la hoja 03 (Inventario de inversiones). | D18: Fila 1: 8,00 → 8,00 | E18: hoja «Inventario de inversiones» | F18: —
A19: Pagos por año | B19: '='03_Inventario'!M5 | C19: Trae cuántas veces al año paga cupón el instrumento desde la hoja 03 (Inventario de inversiones), que ya aplica el valor por defecto de la hoja 02 si el anexo no lo indicaba. | D19: Fila 1: 2 → 2 | E19: hoja «Inventario de inversiones» | F19: —
A20: Meses por período | B20: '=12/G5 | C20: Divide los 12 meses del año para los pagos por año: son los meses que hay entre un cupón y el siguiente. | D20: Fila 1: 12/2 → 6 | E20: «Pagos por año» (esta hoja) | F20: —
A21: Períodos totales | B21: '=ROUND(DATEDIF(B5,C5,"m")/H5,0) | C21: Cuenta los meses completos entre la adquisición y el vencimiento y los divide para los meses por período, redondeando: es el número total de cupones que paga el instrumento. | D21: Fila 1: ROUND(DATEDIF(«2024-06-30»; «2029-06-30»; "m")/6; 0) → 10 | E21: «Adquisición» (esta hoja), «Vencimiento» (esta hoja), «Meses por período» (esta hoja) | F21: —
A22: Cupón por período | B22: '=D5*F5/100/G5 | C22: Multiplica el nominal por la tasa de cupón (en %) y lo divide para los pagos por año: es el importe que se cobra en cada cupón. | D22: Fila 1: 100.000,00*8,00/100/2 → 4.000,00 | E22: «Nominal» (esta hoja), «Cupón %» (esta hoja), «Pagos por año» (esta hoja) | F22: —
A23: TIE periódica | B23: '=RATE(I5,J5,-E5,D5) | C23: Calcula con TASA de Excel la tasa por período que iguala el costo pagado con el valor actual de todos los cupones más el nominal al vencimiento: es la tasa de interés efectiva de cada período. | D23: Fila 1: RATE(10; 4.000,00; -96.000,00; 100.000,00) → 4,51 % | E23: «Períodos totales» (esta hoja), «Cupón por período» (esta hoja), «Costo» (esta hoja), «Nominal» (esta hoja) | F23: —
A24: TIE anual | B24: '=(1+K5)^G5-1 | C24: Convierte la TIE periódica en tasa anual compuesta: (1 + TIE periódica) elevado a los pagos por año, menos 1. | D24: Fila 1: (1+4,51 %)^2-1 → 9,21 % | E24: «TIE periódica» (esta hoja), «Pagos por año» (esta hoja) | F24: —
A25: Control VA − costo | B25: '=PV(K5,I5,-J5,-D5)-E5 | C25: Descuenta todos los cupones y el nominal a la TIE periódica y le resta el costo; debe dar cero, lo que confirma que la TIE está bien calculada. | D25: Fila 1: PV(4,51 %; 10; -4.000,00; -100.000,00)-96.000,00 → 0,00 | E25: «TIE periódica» (esta hoja), «Períodos totales» (esta hoja), «Cupón por período» (esta hoja), «Nominal» (esta hoja), «Costo» (esta hoja) | F25: —
A26: Cupones cobrados al corte | B26: '=INT(DATEDIF(B5,'02_Parametros'!$B$5,"m")/H5) | C26: Cuenta los meses completos entre la adquisición y la fecha de corte de la hoja 02 (Parámetros) y los divide para los meses por período, sin decimales: son los cupones ya cobrados al corte. | D26: Fila 1: INT(DATEDIF(«2024-06-30»; «2025-12-31»; "m")/6) → 3 | E26: «Adquisición» (esta hoja), «Meses por período» (esta hoja), hoja «Parámetros» | F26: —
... A35: Interés efectivo del ejercicio | B35: '=Q5-U5+V5 | C35: Costo amortizado al corte con cupón corrido, menos el costo amortizado al inicio, más los cupones cobrados en el ejercicio: es el ingreso por intereses que debió registrarse. | D35: Fila 1: 97.044,96-96.349,28+8.000,00 → 8.695,68 | E35: «CA al corte (con cupón corrido)» (esta hoja), «CA al inicio del ejercicio» (esta hoja), «Cupones cobrados en el ejercicio» (esta hoja) | F35: —

Sheet 06_Valor_razonable
A1: Valor razonable y jerarquía | H1: ⟵ Inicio | I1: ◀ Anterior | J1: Siguiente ▶
A2: Inversiones e instrumentos financieros · Cliente de muestra S.A. · corte 2025-12-31
A4: Instrumento | B4: Clasificación según la norma | C4: Nivel | D4: Valor razonable al corte | E4: Saldo en libros | F4: Diferencia (ganancia/pérdida no registrada) | G4: Se reconoce en | H4: ¿Nivel informado?
A5: BONO-01 | B5: ='04_Clasificacion'!H5 | C5: 2 | D5: 97200 | E5: ='03_Inventario'!N5 | F5: =IF(OR(B5="VRR",B5="VRORI"),IF(D5="","",D5-E5),"") | G5: =IF(B5="VRR","Resultados",IF(B5="VRORI","ORI; intereses y deterioro a resultados (4.1.2A, 5.7.10)","Solo revelación (NIIF 7 25)")) | H5: =IF(OR(B5="VRR",B5="VRORI"),IF(C5="","Falta nivel",IF(C5=3,"Nivel 3: revisar supuestos (NIIF 13 86, 93)","Sí")),"")
A6: OBL-03 | B6: ='04_Clasificacion'!H7 | C6: 2 | D6: 29400 | E6: ='03_Inventario'!N7 | F6: =IF(OR(B6="VRR",B6="VRORI"),IF(D6="","",D6-E6),"") | G6: =IF(B6="VRR","Resultados",IF(B6="VRORI","ORI; intereses y deterioro a resultados (4.1.2A, 5.7.10)","Solo revelación (NIIF 7 25)")) | H6: =IF(OR(B6="VRR",B6="VRORI"),IF(C6="","Falta nivel",IF(C6=3,"Nivel 3: revisar supuestos (NIIF 13 86, 93)","Sí")),"")
A7: ACC-04 | B7: ='04_Clasificacion'!H8 | C7: 1 | D7: 45000 | E7: ='03_Inventario'!N8 | F7: =IF(OR(B7="VRR",B7="VRORI"),IF(D7="","",D7-E7),"") | G7: =IF(B7="VRR","Resultados",IF(B7="VRORI","ORI sin reciclaje (5.7.5, B5.7.1)","Solo revelación (NIIF 7 25)")) | H7: =IF(OR(B7="VRR",B7="VRORI"),IF(C7="","Falta nivel",IF(C7=3,"Nivel 3: revisar supuestos (NIIF 13 86, 93)","Sí")),"")
A8: ACC-05 | B8: ='04_Clasificacion'!H9 | C8: 3 | D8: 12500 | E8: ='03_Inventario'!N9 | F8: =IF(OR(B8="VRR",B8="VRORI"),IF(D8="","",D8-E8),"") | G8: =IF(B8="VRR","Resultados",IF(B8="VRORI","ORI sin reciclaje (5.7.5, B5.7.1)","Solo revelación (NIIF 7 25)")) | H8: =IF(OR(B8="VRR",B8="VRORI"),IF(C8="","Falta nivel",IF(C8=3,"Nivel 3: revisar supuestos (NIIF 13 86, 93)","Sí")),"")
A9: FND-06 | B9: ='04_Clasificacion'!H10 | D9: 20500 | E9: ='03_Inventario'!N10 | F9: =IF(OR(B9="VRR",B9="VRORI"),IF(D9="","",D9-E9),"") | G9: =IF(B9="VRR","Resultados",IF(B9="VRORI","ORI; intereses y deterioro a resultados (4.1.2A, 5.7.10)","Solo revelación (NIIF 7 25)")) | H9: =IF(OR(B9="VRR",B9="VRORI"),IF(C9="","Falta nivel",IF(C9=3,"Nivel 3: revisar supuestos (NIIF 13 86, 93)","Sí")),"")
A10: BONO-08 | B10: ='04_Clasificacion'!H12 | C10: 2 | D10: 15800 | E10: ='03_Inventario'!N12 | F10: =IF(OR(B10="VRR",B10="VRORI"),IF(D10="","",D10-E10),"") | G10: =IF(B10="VRR","Resultados",IF(B10="VRORI","ORI; intereses y deterioro a resultados (4.1.2A, 5.7.10)","Solo revelación (NIIF 7 25)")) | H10: =IF(OR(B10="VRR",B10="VRORI"),IF(C10="","Falta nivel",IF(C10=3,"Nivel 3: revisar supuestos (NIIF 13 86, 93)","Sí")),"")
A11: OBL-10 | B11: ='04_Clasificacion'!H14 | C11: 2 | D11: 20200 | E11: ='03_Inventario'!N14 | F11: =IF(OR(B11="VRR",B11="VRORI"),IF(D11="","",D11-E11),"") | G11: =IF(B11="VRR","Resultados",IF(B11="VRORI","ORI; intereses y deterioro a resultados (4.1.2A, 5.7.10)","Solo revelación (NIIF 7 25)")) | H11: =IF(OR(B11="VRR",B11="VRORI"),IF(C11="","Falta nivel",IF(C11=3,"Nivel 3: revisar supuestos (NIIF 13 86, 93)","Sí")),"")
A12: TOTAL | D12: =SUM(D5:D11) | E12: =SUM(E5:E11) | F12: =SUM(F5:F11)
A14: ⓘ Cómo se calcula esta hoja
A15: Columna | B15: Fórmula (Excel) | C15: Cómo se calcula (sencillo) | D15: Ejemplo con números reales | E15: De dónde viene | F15: Norma
A16: Clasificación según la norma | B16: '='04_Clasificacion'!H5 | C16: Trae la clasificación que corresponde según la norma, calculada en la hoja 04 (Clasificación). | D16: Fila 1: «CA» → CA | E16: hoja «Clasificación» | F16: —
A17: Saldo en libros | B17: '='03_Inventario'!N5 | C17: Trae el saldo en libros del instrumento desde la hoja 03 (Inventario de inversiones). | D17: Fila 1: 96.500,00 → 96.500,00 | E17: hoja «Inventario de inversiones» | F17: —
A18: Diferencia (ganancia/pérdida no registrada) | B18: '=IF(OR(B5="VRR",B5="VRORI"),IF(D5="","",D5-E5),"") | C18: Solo para instrumentos a valor razonable (VRR o VRORI): valor razonable al corte menos saldo en libros. Queda en blanco si no hay valor razonable o si el instrumento no se mide a valor razonable. | D18: Fila 1: IF(OR(«CA»="VRR"; «CA»="VRORI"); IF(97.200,00=""; ""; 97.200,00-96.500,00); "") → (en blanco) | E18: «Clasificación según la norma» (esta hoja), «Valor razonable al corte» (esta hoja), «Saldo en libros» (esta hoja) | F18: —
A19: Se reconoce en | B19: '=IF(B5="VRR","Resultados",IF(B5="VRORI","ORI; intereses y deterioro a resultados (4.1.2A, 5.7.10)","Solo revelación (NIIF 7 25)")) | C19: Indica dónde va la diferencia de valor razonable: en resultados si es VRR, en ORI si es VRORI (con el matiz según sea deuda o patrimonio) y, en las demás clasificaciones, solo se revela. | D19: Fila 1: IF(«CA»="VRR"; "Resultados"; IF(«CA»="VRORI"; "ORI; intereses y deterioro a resultados (4.1.2A, 5.7.10)"; "Solo revelación (NIIF 7 25)")) → Solo revelación (NIIF 7 25) | E19: «Clasificación según la norma» (esta hoja) | F19: —
A20: ¿Nivel informado? | B20: '=IF(OR(B5="VRR",B5="VRORI"),IF(C5="","Falta nivel",IF(C5=3,"Nivel 3: revisar supuestos (NIIF 13 86, 93)","Sí")),"") | C20: Para instrumentos a valor razonable revisa el nivel de jerarquía: avisa «Falta nivel» si está vacío, pide revisar supuestos si es nivel 3 y pone «Sí» en otro caso; en las demás clasificaciones queda vacío. | D20: Fila 1: IF(OR(«CA»="VRR"; «CA»="VRORI"); IF(2=""; "Falta nivel"; IF(2=3; "Nivel 3: revisar supuestos (NIIF 13 86, 93)"; "Sí")); "") → (en blanco) | E20: «Clasificación según la norma» (esta hoja), «Nivel» (esta hoja) | F20: —

Sheet 07_Intereses_dividendos
A1: Intereses y dividendos | H1: ⟵ Inicio | I1: ◀ Anterior | J1: Siguiente ▶
A2: Inversiones e instrumentos financieros · Cliente de muestra S.A. · corte 2025-12-31
A4: Instrumento | B4: Tipo | C4: Clasificación según la norma | D4: Ingreso según la norma | E4: Ingreso registrado | F4: Diferencia
A5: BONO-01 | B5: ='03_Inventario'!C5&"" | C5: ='04_Clasificacion'!H5 | D5: =IF(OR(C5="CA",C5="VRORI"),'05_Costo_amortizado'!W5,"") | E5: ='03_Inventario'!R5 | F5: =IF(D5="","",D5-E5)
A6: CDP-02 | B6: ='03_Inventario'!C6&"" | C6: ='04_Clasificacion'!H6 | D6: =IF(OR(C6="CA",C6="VRORI"),'05_Costo_amortizado'!W6,"") | E6: ='03_Inventario'!R6 | F6: =IF(D6="","",D6-E6)
A7: OBL-03 | B7: ='03_Inventario'!C7&"" | C7: ='04_Clasificacion'!H7 | D7: =IF(OR(C7="CA",C7="VRORI"),'05_Costo_amortizado'!W7,"") | E7: ='03_Inventario'!R7 | F7: =IF(D7="","",D7-E7)
A8: ACC-04 | B8: ='03_Inventario'!C8&"" | C8: ='04_Clasificacion'!H8 | D8: =IF('03_Inventario'!S8="","",'03_Inventario'!S8) | E8: ='03_Inventario'!R8 | F8: =IF(D8="","",D8-E8)
A9: ACC-05 | B9: ='03_Inventario'!C9&"" | C9: ='04_Clasificacion'!H9 | D9: =IF('03_Inventario'!S9="","",'03_Inventario'!S9) | E9: ='03_Inventario'!R9 | F9: =IF(D9="","",D9-E9)
A10: FND-06 | B10: ='03_Inventario'!C10&"" | C10: ='04_Clasificacion'!H10 | D10: ="" | E10: ='03_Inventario'!R10 | F10: =IF(D10="","",D10-E10)
A11: PAG-07 | B11: ='03_Inventario'!C11&"" | C11: ='04_Clasificacion'!H11 | D11: =IF(OR(C11="CA",C11="VRORI"),'05_Costo_amortizado'!W8,"") | E11: ='03_Inventario'!R11 | F11: =IF(D11="","",D11-E11)
A12: BONO-08 | B12: ='03_Inventario'!C12&"" | C12: ='04_Clasificacion'!H12 | D12: =IF(OR(C12="CA",C12="VRORI"),'05_Costo_amortizado'!W9,"") | E12: ='03_Inventario'!R12 | F12: =IF(D12="","",D12-E12)
A13: POL-09 | B13: ='03_Inventario'!C13&"" | C13: ='04_Clasificacion'!H13 | D13: =IF(OR(C13="CA",C13="VRORI"),'05_Costo_amortizado'!W10,"") | E13: ='03_Inventario'!R13 | F13: =IF(D13="","",D13-E13)
A14: OBL-10 | B14: ='03_Inventario'!C14&"" | C14: ='04_Clasificacion'!H14 | D14: =IF(OR(C14="CA",C14="VRORI"),'05_Costo_amortizado'!W11,"") | E14: ='03_Inventario'!R14 | F14: =IF(D14="","",D14-E14)
A15: BONO-11 | B15: ='03_Inventario'!C15&"" | C15: ='04_Clasificacion'!H15 | D15: ="" | E15: ='03_Inventario'!R15 | F15: =IF(D15="","",D15-E15)
A16: TOTAL | D16: =SUM(D5:D15) | E16: =SUM(E5:E15) | F16: =SUM(F5:F15)
A18: ⓘ Cómo se calcula esta hoja
A19: Columna | B19: Fórmula (Excel) | C19: Cómo se calcula (sencillo) | D19: Ejemplo con números reales | E19: De dónde viene | F19: Norma
A20: Tipo | B20: '='03_Inventario'!C5&"" | C20: Copia el tipo de instrumento (deuda o patrimonio) desde la hoja 03 (Inventario de inversiones). | D20: Fila 1: «Deuda»&"" → Deuda | E20: hoja «Inventario de inversiones» | F20: —
A21: Clasificación según la norma | B21: '='04_Clasificacion'!H5 | C21: Trae la clasificación que corresponde según la norma desde la hoja 04 (Clasificación). | D21: Fila 1: «CA» → CA | E21: hoja «Clasificación» | F21: —
A22: Ingreso según la norma | B22: '=IF(OR(C5="CA",C5="VRORI"),'05_Costo_amortizado'!W5,"") | C22: Para la deuda a costo amortizado o VRORI trae el interés efectivo del ejercicio de la hoja 05 (Costo amortizado y TIE); para acciones trae los dividendos decretados de la hoja 03 (Inventario de inversiones); en los demás casos queda en blanco. | D22: Fila 1: IF(OR(«CA»="CA"; «CA»="VRORI"); 8.695,68; "") → 8.695,68 | E22: «Clasificación según la norma» (esta hoja), hoja «Costo amortizado y TIE» | F22: —
A23: Ingreso registrado | B23: '='03_Inventario'!R5 | C23: Trae el ingreso por intereses o dividendos que el cliente registró en el año, desde la hoja 03 (Inventario de inversiones). | D23: Fila 1: 8.000,00 → 8.000,00 | E23: hoja «Inventario de inversiones» | F23: —
A24: Diferencia | B24: '=IF(D5="","",D5-E5) | C24: Ingreso según la norma menos ingreso registrado: si es positivo falta registrar ingreso. Queda en blanco cuando no hay ingreso según la norma. | D24: Fila 1: IF(8.695,68=""; ""; 8.695,68-8.000,00) → 695,68 | E24: «Ingreso según la norma» (esta hoja), «Ingreso registrado» (esta hoja) | F24: —

Sheet 08_Deterioro
A1: Deterioro | H1: ⟵ Inicio | I1: ◀ Anterior | J1: Siguiente ▶
A2: Inversiones e instrumentos financieros · Cliente de muestra S.A. · corte 2025-12-31
A4: Instrumento | B4: Clasificación según la norma | C4: Indicio | D4: Enfoque | E4: Base (CA con cupón corrido / costo) | F4: PD % | G4: LGD / no recuperable % | H4: Estimación de venta al cierre (11.25 b) | I4: Deterioro recalculado | J4: Deterioro registrado | K4: Diferencia
A5: BONO-01 | B5: ='04_Clasificacion'!H5 | C5: No | D5: =IF(OR(B5="CA",AND(B5="VRORI",'03_Inventario'!C5="Deuda")),IF(C5="Sí","Vida entera (5.5.3)","12 meses (5.5.5)"),"No aplica") | E5: =IF(OR(B5="CA",AND(B5="VRORI",'03_Inventario'!C5="Deuda")),'05_Costo_amortizado'!Q5,"") | F5: 1 | G5: 45 | I5: =IF(OR(B5="CA",AND(B5="VRORI",'03_Inventario'!C5="Deuda")),IF(OR(E5="",F5="",G5=""),"",E5*F5/100*G5/100),"") | J5: ='03_Inventario'!Q5 | K5: =IF(I5="","",I5-J5)
A6: CDP-02 | B6: ='04_Clasificacion'!H6 | C6: No | D6: =IF(OR(B6="CA",AND(B6="VRORI",'03_Inventario'!C6="Deuda")),IF(C6="Sí","Vida entera (5.5.3)","12 meses (5.5.5)"),"No aplica") | E6: =IF(OR(B6="CA",AND(B6="VRORI",'03_Inventario'!C6="Deuda")),'05_Costo_amortizado'!Q6,"") | F6: 0.5 | G6: 40 | I6: =IF(OR(B6="CA",AND(B6="VRORI",'03_Inventario'!C6="Deuda")),IF(OR(E6="",F6="",G6=""),"",E6*F6/100*G6/100),"") | J6: ='03_Inventario'!Q6 | K6: =IF(I6="","",I6-J6)
A7: OBL-03 | B7: ='04_Clasificacion'!H7 | C7: No | D7: =IF(OR(B7="CA",AND(B7="VRORI",'03_Inventario'!C7="Deuda")),IF(C7="Sí","Vida entera (5.5.3)","12 meses (5.5.5)"),"No aplica") | E7: =IF(OR(B7="CA",AND(B7="VRORI",'03_Inventario'!C7="Deuda")),'05_Costo_amortizado'!Q7,"") | F7: 1 | G7: 45 | I7: =IF(OR(B7="CA",AND(B7="VRORI",'03_Inventario'!C7="Deuda")),IF(OR(E7="",F7="",G7=""),"",E7*F7/100*G7/100),"") | J7: ='03_Inventario'!Q7 | K7: =IF(I7="","",I7-J7)
A8: ACC-04 | B8: ='04_Clasificacion'!H8 | D8: =IF(OR(B8="CA",AND(B8="VRORI",'03_Inventario'!C8="Deuda")),IF(C8="Sí","Vida entera (5.5.3)","12 meses (5.5.5)"),"No aplica") | E8: ="" | I8: =IF(OR(B8="CA",AND(B8="VRORI",'03_Inventario'!C8="Deuda")),IF(OR(E8="",F8="",G8=""),"",E8*F8/100*G8/100),"") | J8: ='03_Inventario'!Q8 | K8: =IF(I8="","",I8-J8)
A9: ACC-05 | B9: ='04_Clasificacion'!H9 | D9: =IF(OR(B9="CA",AND(B9="VRORI",'03_Inventario'!C9="Deuda")),IF(C9="Sí","Vida entera (5.5.3)","12 meses (5.5.5)"),"No aplica") | E9: ="" | I9: =IF(OR(B9="CA",AND(B9="VRORI",'03_Inventario'!C9="Deuda")),IF(OR(E9="",F9="",G9=""),"",E9*F9/100*G9/100),"") | J9: ='03_Inventario'!Q9 | K9: =IF(I9="","",I9-J9)
A10: FND-06 | B10: ='04_Clasificacion'!H10 | D10: =IF(OR(B10="CA",AND(B10="VRORI",'03_Inventario'!C10="Deuda")),IF(C10="Sí","Vida entera (5.5.3)","12 meses (5.5.5)"),"No aplica") | E10: ="" | I10: =IF(OR(B10="CA",AND(B10="VRORI",'03_Inventario'!C10="Deuda")),IF(OR(E10="",F10="",G10=""),"",E10*F10/100*G10/100),"") | J10: ='03_Inventario'!Q10 | K10: =IF(I10="","",I10-J10)
A11: PAG-07 | B11: ='04_Clasificacion'!H11 | C11: Sí | D11: =IF(OR(B11="CA",AND(B11="VRORI",'03_Inventario'!C11="Deuda")),IF(C11="Sí","Vida entera (5.5.3)","12 meses (5.5.5)"),"No aplica") | E11: =IF(OR(B11="CA",AND(B11="VRORI",'03_Inventario'!C11="Deuda")),'05_Costo_amortizado'!Q8,"") | F11: 60 | G11: 50 | I11: =IF(OR(B11="CA",AND(B11="VRORI",'03_Inventario'!C11="Deuda")),IF(OR(E11="",F11="",G11=""),"",E11*F11/100*G11/100),"") | J11: ='03_Inventario'!Q11 | K11: =IF(I11="","",I11-J11)
A12: BONO-08 | B12: ='04_Clasificacion'!H12 | D12: =IF(OR(B12="CA",AND(B12="VRORI",'03_Inventario'!C12="Deuda")),IF(C12="Sí","Vida entera (5.5.3)","12 meses (5.5.5)"),"No aplica") | E12: =IF(OR(B12="CA",AND(B12="VRORI",'03_Inventario'!C12="Deuda")),'05_Costo_amortizado'!Q9,"") | I12: =IF(OR(B12="CA",AND(B12="VRORI",'03_Inventario'!C12="Deuda")),IF(OR(E12="",F12="",G12=""),"",E12*F12/100*G12/100),"") | J12: ='03_Inventario'!Q12 | K12: =IF(I12="","",I12-J12)
A13: POL-09 | B13: ='04_Clasificacion'!H13 | C13: No | D13: =IF(OR(B13="CA",AND(B13="VRORI",'03_Inventario'!C13="Deuda")),IF(C13="Sí","Vida entera (5.5.3)","12 meses (5.5.5)"),"No aplica") | E13: =IF(OR(B13="CA",AND(B13="VRORI",'03_Inventario'!C13="Deuda")),'05_Costo_amortizado'!Q10,"") | F13: 2 | G13: 40 | I13: =IF(OR(B13="CA",AND(B13="VRORI",'03_Inventario'!C13="Deuda")),IF(OR(E13="",F13="",G13=""),"",E13*F13/100*G13/100),"") | J13: ='03_Inventario'!Q13 | K13: =IF(I13="","",I13-J13)
A14: OBL-10 | B14: ='04_Clasificacion'!H14 | C14: No | D14: =IF(OR(B14="CA",AND(B14="VRORI",'03_Inventario'!C14="Deuda")),IF(C14="Sí","Vida entera (5.5.3)","12 meses (5.5.5)"),"No aplica") | E14: =IF(OR(B14="CA",AND(B14="VRORI",'03_Inventario'!C14="Deuda")),'05_Costo_amortizado'!Q11,"") | F14: 1.5 | G14: 45 | I14: =IF(OR(B14="CA",AND(B14="VRORI",'03_Inventario'!C14="Deuda")),IF(OR(E14="",F14="",G14=""),"",E14*F14/100*G14/100),"") | J14: ='03_Inventario'!Q14 | K14: =IF(I14="","",I14-J14)
A15: BONO-11 | B15: ='04_Clasificacion'!H15 | D15: =IF(OR(B15="CA",AND(B15="VRORI",'03_Inventario'!C15="Deuda")),IF(C15="Sí","Vida entera (5.5.3)","12 meses (5.5.5)"),"No aplica") | E15: ="" | I15: =IF(OR(B15="CA",AND(B15="VRORI",'03_Inventario'!C15="Deuda")),IF(OR(E15="",F15="",G15=""),"",E15*F15/100*G15/100),"") | J15: ='03_Inventario'!Q15 | K15: =IF(I15="","",I15-J15)
A16: TOTAL | I16: =SUM(I5:I15) | J16: =SUM(J5:J15) | K16: =SUM(K5:K15)
A18: ⓘ Cómo se calcula esta hoja
A19: Columna | B19: Fórmula (Excel) | C19: Cómo se calcula (sencillo) | D19: Ejemplo con números reales | E19: De dónde viene | F19: Norma
A20: Clasificación según la norma | B20: '='04_Clasificacion'!H5 | C20: Trae la clasificación según la norma de la hoja 04 (Clasificación), que decide si se mide deterioro y con qué enfoque. | D20: Fila 1: «CA» → CA | E20: hoja «Clasificación» | F20: —
A21: Enfoque | B21: '=IF(OR(B5="CA",AND(B5="VRORI",'03_Inventario'!C5="Deuda")),IF(C5="Sí","Vida entera (5.5.3)","12 meses (5.5.5)"),"No aplica") | C21: Solo para deuda a costo amortizado o VRORI: con indicio de aumento significativo del riesgo usa pérdida esperada de vida entera y, sin él, de 12 meses; las demás clasificaciones dicen «No aplica». | D21: Fila 1: IF(OR(«CA»="CA"; AND(«CA»="VRORI"; «Deuda»="Deuda")); IF(«No»="Sí"; "Vida entera (5.5.3)"; "12 meses (5.5.5)"); "No aplica") → 12 meses (5.5.5) | E21: «Clasificación según la norma» (esta hoja), «Indicio» (esta hoja), hoja «Inventario de inversiones» | F21: —
A22: Base (CA con cupón corrido / costo) | B22: '=IF(OR(B5="CA",AND(B5="VRORI",'03_Inventario'!C5="Deuda")),'05_Costo_amortizado'!Q5,"") | C22: Para deuda a costo amortizado o VRORI trae el costo amortizado al corte con cupón corrido de la hoja 05 (Costo amortizado y TIE); en los demás casos queda en blanco. | D22: Fila 1: IF(OR(«CA»="CA"; AND(«CA»="VRORI"; «Deuda»="Deuda")); 97.044,96; "") → 97.044,96 | E22: «Clasificación según la norma» (esta hoja), hoja «Inventario de inversiones», hoja «Costo amortizado y TIE» | F22: —
A23: Deterioro recalculado | B23: '=IF(OR(B5="CA",AND(B5="VRORI",'03_Inventario'!C5="Deuda")),IF(OR(E5="",F5="",G5=""),"",E5*F5/100*G5/100),"") | C23: Pérdida esperada = base × PD % × LGD %, solo para deuda a costo amortizado o VRORI. Si falta la base, la PD o la LGD, queda en blanco. | D23: Fila 1: IF(OR(«CA»="CA"; AND(«CA»="VRORI"; «Deuda»="Deuda")); IF(OR(97.044,96=""; 1,00=""; 45,00=""); ""; 97.044,96*1,00/100*45,00/100); "") → 436,70 | E23: «Clasificación según la norma» (esta hoja), «Base (CA con cupón corrido / costo)» (esta hoja), «PD %» (esta hoja), «LGD / no recuperable %» (esta hoja), hoja «Inventario de inversiones» | F23: —
A24: Deterioro registrado | B24: '='03_Inventario'!Q5 | C24: Trae la provisión por deterioro que el cliente tiene registrada, desde la hoja 03 (Inventario de inversiones). | D24: Fila 1: 0,00 → 0,00 | E24: hoja «Inventario de inversiones» | F24: —
A25: Diferencia | B25: '=IF(I5="","",I5-J5) | C25: Deterioro recalculado menos deterioro registrado: si es positivo falta provisión. Queda en blanco si el deterioro no se pudo recalcular. | D25: Fila 1: IF(436,70=""; ""; 436,70-0,00) → 436,70 | E25: «Deterioro recalculado» (esta hoja), «Deterioro registrado» (esta hoja) | F25: —

Sheet 09_Reclasificacion
A1: Reclasificación | H1: ⟵ Inicio | I1: ◀ Anterior | J1: Siguiente ▶
A2: Inversiones e instrumentos financieros · Cliente de muestra S.A. · corte 2025-12-31
A4: Instrumento | B4: Tipo | C4: Clasificación anterior | D4: Clasificación actual (cliente) | E4: Cambio de modelo | F4: Clasificación según la norma | G4: ¿Permitida? | H4: Tratamiento
A5: OBL-10 | B5: ='03_Inventario'!C14&"" | C5: ='03_Inventario'!X14 | D5: ='03_Inventario'!G14 | E5: No | F5: ='04_Clasificacion'!H14 | G5: =IF(C5=D5,"Sin cambio",IF(AND(B5="Patrimonio",C5="VRORI"),"No: elección irrevocable (5.7.5)",IF(AND(B5="Deuda",E5="Sí"),"Sí: cambio de modelo de negocio (4.4.1)","No: sin cambio de modelo de negocio (4.4.1)"))) | H5: VR a la fecha de reclasificación; diferencia a ORI; TIE y pérdida esperada no cambian (5.6.4).
A7: ⓘ Cómo se calcula esta hoja
A8: Columna | B8: Fórmula (Excel) | C8: Cómo se calcula (sencillo) | D8: Ejemplo con números reales | E8: De dónde viene | F8: Norma
A9: Tipo | B9: '='03_Inventario'!C14&"" | C9: Copia el tipo de instrumento (deuda o patrimonio) desde la hoja 03 (Inventario de inversiones), para este instrumento reclasificado. | D9: Fila 1: «Deuda»&"" → Deuda | E9: hoja «Inventario de inversiones» | F9: —
A10: Clasificación anterior | B10: '='03_Inventario'!X14 | C10: Trae la clasificación que el instrumento tenía antes del cambio, informada en la hoja 03 (Inventario de inversiones). | D10: Fila 1: «CA» → CA | E10: hoja «Inventario de inversiones» | F10: —
A11: Clasificación actual (cliente) | B11: '='03_Inventario'!G14 | C11: Trae la clasificación que el cliente usa hoy para el instrumento, desde la hoja 03 (Inventario de inversiones). | D11: Fila 1: «VRORI» → VRORI | E11: hoja «Inventario de inversiones» | F11: —
A12: Clasificación según la norma | B12: '='04_Clasificacion'!H14 | C12: Trae la clasificación que corresponde según la norma, calculada en la hoja 04 (Clasificación). | D12: Fila 1: «VRORI» → VRORI | E12: hoja «Clasificación» | F12: —
A13: ¿Permitida? | B13: '=IF(C5=D5,"Sin cambio",IF(AND(B5="Patrimonio",C5="VRORI"),"No: elección irrevocable (5.7.5)",IF(AND(B5="Deuda",E5="Sí"),"Sí: cambio de modelo de negocio (4.4.1)","No: sin cambio de modelo de negocio (4.4.1)"))) | C13: Si la clasificación anterior y la actual son iguales dice «Sin cambio»; unas acciones que estaban en VRORI no pueden salir (elección irrevocable); la deuda solo se puede reclasificar si hubo cambio de modelo de negocio. | D13: Fila 1: IF(«CA»=«VRORI»; "Sin cambio"; IF(AND(«Deuda»="Patrimonio"; «CA»="VRORI"); "No: elección irrevocable (5.7.5)"; IF(AND(«Deuda»="Deuda"; «No»="Sí"); "Sí: cambio de modelo de negocio (4.4.1)"; "No: sin cambio de modelo de negocio (4.4.1)"))) → No: sin cambio de modelo de negocio (4.4.1) | E13: «Clasificación anterior» (esta hoja), «Clasificación actual (cliente)» (esta hoja), «Tipo» (esta hoja), «Cambio de modelo» (esta hoja) | F13: —

Sheet 10_Conciliacion
A1: Conciliación y ajuste | H1: ⟵ Inicio | I1: ◀ Anterior | J1: Siguiente ▶
A2: Inversiones e instrumentos financieros · Cliente de muestra S.A. · corte 2025-12-31
A4: Instrumento | B4: Clasificación según la norma | C4: Medición según la norma | D4: Saldo en libros | E4: Diferencia de medición | F4: Deterioro recalculado | G4: Deterioro registrado | H4: Ajuste de deterioro | I4: Ajuste propuesto (importe neto)
A5: BONO-01 | B5: ='04_Clasificacion'!H5 | C5: =IF(B5="CA",'05_Costo_amortizado'!S5,IF(OR(B5="VRR",B5="VRORI"),IF('06_Valor_razonable'!D5="","",'06_Valor_razonable'!D5),IF(B5="COSTO",IF('03_Inventario'!K5="","",'03_Inventario'!K5),""))) | D5: ='03_Inventario'!N5 | E5: =IF(C5="","",C5-D5) | F5: ='08_Deterioro'!I5 | G5: ='08_Deterioro'!J5 | H5: =IF(OR(B5="CA",B5="COSTO"),IF(F5="","",F5-G5),0) | I5: =IF(OR(E5="",H5=""),"",E5-H5)
A6: CDP-02 | B6: ='04_Clasificacion'!H6 | C6: =IF(B6="CA",'05_Costo_amortizado'!S6,IF(OR(B6="VRR",B6="VRORI"),"",IF(B6="COSTO",IF('03_Inventario'!K6="","",'03_Inventario'!K6),""))) | D6: ='03_Inventario'!N6 | E6: =IF(C6="","",C6-D6) | F6: ='08_Deterioro'!I6 | G6: ='08_Deterioro'!J6 | H6: =IF(OR(B6="CA",B6="COSTO"),IF(F6="","",F6-G6),0) | I6: =IF(OR(E6="",H6=""),"",E6-H6)
A7: OBL-03 | B7: ='04_Clasificacion'!H7 | C7: =IF(B7="CA",'05_Costo_amortizado'!S7,IF(OR(B7="VRR",B7="VRORI"),IF('06_Valor_razonable'!D6="","",'06_Valor_razonable'!D6),IF(B7="COSTO",IF('03_Inventario'!K7="","",'03_Inventario'!K7),""))) | D7: ='03_Inventario'!N7 | E7: =IF(C7="","",C7-D7) | F7: ='08_Deterioro'!I7 | G7: ='08_Deterioro'!J7 | H7: =IF(OR(B7="CA",B7="COSTO"),IF(F7="","",F7-G7),0) | I7: =IF(OR(E7="",H7=""),"",E7-H7)
A8: ACC-04 | B8: ='04_Clasificacion'!H8 | C8: =IF(B8="CA","",IF(OR(B8="VRR",B8="VRORI"),IF('06_Valor_razonable'!D7="","",'06_Valor_razonable'!D7),IF(B8="COSTO",IF('03_Inventario'!K8="","",'03_Inventario'!K8),""))) | D8: ='03_Inventario'!N8 | E8: =IF(C8="","",C8-D8) | F8: ='08_Deterioro'!I8 | G8: ='08_Deterioro'!J8 | H8: =IF(OR(B8="CA",B8="COSTO"),IF(F8="","",F8-G8),0) | I8: =IF(OR(E8="",H8=""),"",E8-H8)
A9: ACC-05 | B9: ='04_Clasificacion'!H9 | C9: =IF(B9="CA","",IF(OR(B9="VRR",B9="VRORI"),IF('06_Valor_razonable'!D8="","",'06_Valor_razonable'!D8),IF(B9="COSTO",IF('03_Inventario'!K9="","",'03_Inventario'!K9),""))) | D9: ='03_Inventario'!N9 | E9: =IF(C9="","",C9-D9) | F9: ='08_Deterioro'!I9 | G9: ='08_Deterioro'!J9 | H9: =IF(OR(B9="CA",B9="COSTO"),IF(F9="","",F9-G9),0) | I9: =IF(OR(E9="",H9=""),"",E9-H9)
A10: FND-06 | B10: ='04_Clasificacion'!H10 | C10: =IF(B10="CA","",IF(OR(B10="VRR",B10="VRORI"),IF('06_Valor_razonable'!D9="","",'06_Valor_razonable'!D9),IF(B10="COSTO",IF('03_Inventario'!K10="","",'03_Inventario'!K10),""))) | D10: ='03_Inventario'!N10 | E10: =IF(C10="","",C10-D10) | F10: ='08_Deterioro'!I10 | G10: ='08_Deterioro'!J10 | H10: =IF(OR(B10="CA",B10="COSTO"),IF(F10="","",F10-G10),0) | I10: =IF(OR(E10="",H10=""),"",E10-H10)
A11: PAG-07 | B11: ='04_Clasificacion'!H11 | C11: =IF(B11="CA",'05_Costo_amortizado'!S8,IF(OR(B11="VRR",B11="VRORI"),"",IF(B11="COSTO",IF('03_Inventario'!K11="","",'03_Inventario'!K11),""))) | D11: ='03_Inventario'!N11 | E11: =IF(C11="","",C11-D11) | F11: ='08_Deterioro'!I11 | G11: ='08_Deterioro'!J11 | H11: =IF(OR(B11="CA",B11="COSTO"),IF(F11="","",F11-G11),0) | I11: =IF(OR(E11="",H11=""),"",E11-H11)
A12: BONO-08 | B12: ='04_Clasificacion'!H12 | C12: =IF(B12="CA",'05_Costo_amortizado'!S9,IF(OR(B12="VRR",B12="VRORI"),IF('06_Valor_razonable'!D10="","",'06_Valor_razonable'!D10),IF(B12="COSTO",IF('03_Inventario'!K12="","",'03_Inventario'!K12),""))) | D12: ='03_Inventario'!N12 | E12: =IF(C12="","",C12-D12) | F12: ='08_Deterioro'!I12 | G12: ='08_Deterioro'!J12 | H12: =IF(OR(B12="CA",B12="COSTO"),IF(F12="","",F12-G12),0) | I12: =IF(OR(E12="",H12=""),"",E12-H12)
A13: POL-09 | B13: ='04_Clasificacion'!H13 | C13: =IF(B13="CA",'05_Costo_amortizado'!S10,IF(OR(B13="VRR",B13="VRORI"),"",IF(B13="COSTO",IF('03_Inventario'!K13="","",'03_Inventario'!K13),""))) | D13: ='03_Inventario'!N13 | E13: =IF(C13="","",C13-D13) | F13: ='08_Deterioro'!I13 | G13: ='08_Deterioro'!J13 | H13: =IF(OR(B13="CA",B13="COSTO"),IF(F13="","",F13-G13),0) | I13: =IF(OR(E13="",H13=""),"",E13-H13)
