Workbook

Sheet 00_Inicio
B2: AuditConsulting Auditores Cía. Ltda. · AUDIT-IA
B4: Inventarios, producción y costo de ventas
B6: Cliente | C6: Cliente de muestra S.A. | D6: RUC | E6: 1790000000001
B7: Marco contable | C7: NIIF completas | D7: Fecha de corte | E7: 2025-12-31
B8: Preparó | C8: Ejercicio modelo | D8: Revisó | E8: Pendiente
B10: INDICADORES CLAVE
B11: Ajuste propuesto (neto) | C11: Problemas encontrados
B12: -3459 | C12: 19
B15: IR A LA CÉDULA
B16: Carátula | C16: Programa | D16: Base técnica | E16: Resumen y ajuste propuesto
B17: Parámetros | C17: Inventario valorado por ítem | D17: Existencia: conteo vs kardex | E17: Prueba de costo
B18: Conciliación kardex–mayor | C18: Costo de producción | D18: Costo de ventas | E18: Valor realizable neto
B19: Obsolescencia y lenta rotación | C19: Materias primas: excepción de NIC 2.32 | D19: Prueba de corte | E19: Problemas encontrados
B20: Conclusión | C20: Control de revisión
B22: PANORAMA | N22: Datos de los gráficos (fórmulas a las cédulas)
N23: Cifras del resumen | O23: Importe (USD)
N24: ='01_Resumen'!A5 | O24: ='01_Resumen'!B5
N25: ='01_Resumen'!A6 | O25: ='01_Resumen'!B6
N26: ='01_Resumen'!A7 | O26: ='01_Resumen'!B7
N27: ='01_Resumen'!A8 | O27: ='01_Resumen'!B8
N28: ='01_Resumen'!A9 | O28: ='01_Resumen'!B9
N29: ='01_Resumen'!A10 | O29: ='01_Resumen'!B10
N30: ='01_Resumen'!A11 | O30: ='01_Resumen'!B11
N31: ='01_Resumen'!A12 | O31: ='01_Resumen'!B12
N32: ='01_Resumen'!A13 | O32: ='01_Resumen'!B13
N33: ='01_Resumen'!A14 | O33: ='01_Resumen'!B14
N34: ='01_Resumen'!A15 | O34: ='01_Resumen'!B15
N35: ='01_Resumen'!A16 | O35: ='01_Resumen'!B16
... N41: ='01_Resumen'!A22 | O41: ='01_Resumen'!B22
N43: Hallazgos de mayor impacto | O43: Importe (USD)
N44: Corte | O44: =SUMIFS('13_Problemas'!$C$5:$C$23,'13_Problemas'!$A$5:$A$23,"CORTE",'13_Problemas'!$C$5:$C$23,">0")-SUMIFS('13_Problemas'!$C$5:$C$23,'13_Problemas'!$A$5:$A$23,"CORTE",'13_Problemas'!$C$5:$C$23,"<0")
N45: Vnr bajo costo | O45: =SUMIFS('13_Problemas'!$C$5:$C$23,'13_Problemas'!$A$5:$A$23,"VNR_BAJO_COSTO",'13_Problemas'!$C$5:$C$23,">0")-SUMIFS('13_Problemas'!$C$5:$C$23,'13_Problemas'!$A$5:$A$23,"VNR_BAJO_COSTO",'13_Problemas'!$C$5:$C$23,"<0")
N46: Ajuste | O46: =SUMIFS('13_Problemas'!$C$5:$C$23,'13_Problemas'!$A$5:$A$23,"AJUSTE",'13_Problemas'!$C$5:$C$23,">0")-SUMIFS('13_Problemas'!$C$5:$C$23,'13_Problemas'!$A$5:$A$23,"AJUSTE",'13_Problemas'!$C$5:$C$23,"<0")
N47: Lenta rotacion sin provision | O47: =SUMIFS('13_Problemas'!$C$5:$C$23,'13_Problemas'!$A$5:$A$23,"LENTA_ROTACION_SIN_PROVISION",'13_Problemas'!$C$5:$C$23,">0")-SUMIFS('13_Problemas'!$C$5:$C$23,'13_Problemas'!$A$5:$A$23,"LENTA_ROTACION_SIN_PROVISION",'13_Problemas'!$C$5:$C$23,"<0")
N48: Cif no absorbido capitalizado | O48: =SUMIFS('13_Problemas'!$C$5:$C$23,'13_Problemas'!$A$5:$A$23,"CIF_NO_ABSORBIDO_CAPITALIZADO",'13_Problemas'!$C$5:$C$23,">0")-SUMIFS('13_Problemas'!$C$5:$C$23,'13_Problemas'!$A$5:$A$23,"CIF_NO_ABSORBIDO_CAPITALIZADO",'13_Problemas'!$C$5:$C$23,"<0")
N49: Cif no absorbido | O49: =SUMIFS('13_Problemas'!$C$5:$C$23,'13_Problemas'!$A$5:$A$23,"CIF_NO_ABSORBIDO",'13_Problemas'!$C$5:$C$23,">0")-SUMIFS('13_Problemas'!$C$5:$C$23,'13_Problemas'!$A$5:$A$23,"CIF_NO_ABSORBIDO",'13_Problemas'!$C$5:$C$23,"<0")
N50: Produccion no conciliada | O50: =SUMIFS('13_Problemas'!$C$5:$C$23,'13_Problemas'!$A$5:$A$23,"PRODUCCION_NO_CONCILIADA",'13_Problemas'!$C$5:$C$23,">0")-SUMIFS('13_Problemas'!$C$5:$C$23,'13_Problemas'!$A$5:$A$23,"PRODUCCION_NO_CONCILIADA",'13_Problemas'!$C$5:$C$23,"<0")
N51: Otros (11 tipos) | O51: =SUMIF('13_Problemas'!$C$5:$C$23,">0")-SUMIF('13_Problemas'!$C$5:$C$23,"<0")-((SUMIFS('13_Problemas'!$C$5:$C$23,'13_Problemas'!$A$5:$A$23,"CORTE",'13_Problemas'!$C$5:$C$23,">0")-SUMIFS('13_Problemas'!$C$5:$C$23,'13_Problemas'!$A$5:$A$23,"CORTE",'13_Problemas'!$C$5:$C$23,"<0"))+(SUMIFS('13_Problemas'!$C$5:$C$23,'13_Problemas'!$A$5:$A$23,"VNR_BAJO_COSTO",'13_Problemas'!$C$5:$C$23,">0")-SUMIFS('13_Problemas'!$C$5:$C$23,'13_Problemas'!$A$5:$A$23,"VNR_BAJO_COSTO",'13_Problemas'!$C$5:$C$23,"<0"))+(SUMIFS('13_Problemas'!$C$5:$C$23,'13_Problemas'!$A$5:$A$23,"AJUSTE",'13_Problemas'!$C$5:$C$23,">0")-SUMIFS('13_Problemas'!$C$5:$C$23,'13_Problemas'!$A$5:$A$23,"AJUSTE",'13_Problemas'!$C$5:$C$23,"<0"))+(SUMIFS('13_Problemas'!$C$5:$C$23,'13_Problemas'!$A$5:$A$23,"LENTA_ROTACION_SIN_PROVISION",'13_Problemas'!$C$5:$C$23,">0")-SUMIFS('13_Problemas'!$C$5:$C$23,'13_Problemas'!$A$5:$A$23,"LENTA_ROTACION_SIN_PROVISION",'13_Problemas'!$C$5:$C$23,"<0"))+(SUMIFS('13_Problemas'!$C$5:$C$23,'13_Problemas'!$A$5:$A$23,"CIF_NO_ABSORBIDO_CAPITALIZADO",'13_Problemas'!$C$5:$C$23,">0")-SUMIFS('13_Problemas'!$C$5:$C$23,'13_Problemas'!$A$5:$A$23,"CIF_NO_ABSORBIDO_CAPITALIZADO",'13_Problemas'!$C$5:$C$23,"<0"))+(SUMIFS('13_Problemas'!$C$5:$C$23,'13_Problemas'!$A$5:$A$23,"CIF_NO_ABSORBIDO",'13_Problemas'!$C$5:$C$23,">0")-SUMIFS('13_Problemas'!$C$5:$C$23,'13_Problemas'!$A$5:$A$23,"CIF_NO_ABSORBIDO",'13_Problemas'!$C$5:$C$23,"<0"))+(SUMIFS('13_Problemas'!$C$5:$C$23,'13_Problemas'!$A$5:$A$23,"PRODUCCION_NO_CONCILIADA",'13_Problemas'!$C$5:$C$23,">0")-SUMIFS('13_Problemas'!$C$5:$C$23,'13_Problemas'!$A$5:$A$23,"PRODUCCION_NO_CONCILIADA",'13_Problemas'!$C$5:$C$23,"<0")))

Sheet 00_Caratula
A1: Carátula | H1: ⟵ Inicio | J1: Siguiente ▶
A2: Inventarios, producción y costo de ventas · Cliente de muestra S.A. · corte 2025-12-31
A4: Concepto | B4: Detalle
A5: Firma | B5: AuditConsulting Auditores Cía. Ltda.
A6: Cliente | B6: Cliente de muestra S.A.
A7: RUC | B7: 1790000000001
A8: Ejercicio | B8: 2025
A9: Fecha de corte | B9: 2025-12-31
A10: Marco contable | B10: NIIF completas
A11: Herramienta | B11: Inventarios, producción y costo de ventas
A12: Rubro | B12: Inventarios
A13: Motor | B13: inventarios_costos 1.0
A14: Versión del papel | B14: v1
A15: Estado | B15: MUESTRA
... A17: Revisó | B17: Pendiente
A18: Aprobó
A19: Fecha de aprobación
A20: Huella de la ejecución (SHA-256)

Sheet 00_Programa
A1: Programa | H1: ⟵ Inicio | I1: ◀ Anterior | J1: Siguiente ▶
A2: Inventarios, producción y costo de ventas · Cliente de muestra S.A. · corte 2025-12-31
A4: Código | B4: Objetivo | C4: Afirmación | D4: Procedimiento | E4: Evidencia | F4: Criterio | G4: Referencia
A5: INV-01 | B5: Existencia | C5: Existencia | D5: Presenciar el recuento y comparar cantidades contadas con el kardex | E5: Hojas de conteo, acta e instrucciones | F5: Diferencias valorizadas y ajustadas | G5: NIA 501
A6: INV-02 | B6: Conciliación kardex–mayor | C6: Integridad | D6: Conciliar el valor del kardex con el mayor y probar su extensión | E6: Kardex valorado y mayor | F6: Diferencia explicada o ajustada | G6: NIA 500
A7: INV-03 | B7: Prueba de costo | C7: Valoración | D7: Cotejar el costo unitario con facturas o el costeo (FIFO / promedio) | E7: Facturas de compra, hojas de costeo | F7: Costo soportado = registrado | G7: NIC 2.10-2.11, 2.25 · PYMES 13.5-13.6, 13.18, INV-08
A8: INV-04 | B8: Costo de producción | C8: Valoración | D8: Recalcular la absorción del CIF fijo sobre la capacidad normal y el costo capitalizable | E8: Costeo de producción, capacidad normal | F8: Solo el CIF absorbido va al inventario | G8: NIC 2.12-2.13, 2.16(a) · PYMES 13.8-13.9, 13.13(a), INV-07, INV-17
A9: INV-05 | B9: Costo de ventas | C9: Exactitud | D9: Recalcular el costo de ventas con inventarios, compras y producción | E9: Movimiento del inventario, mayor | F9: Diferencia explicada | G9: NIC 2.34 · PYMES 13.20
A10: INV-06 | B10: Valor realizable neto | C10: Valoración | D10: Comparar costo con VNR partida por partida con precios posteriores | E10: Ventas y listas de precios posteriores, costos de terminación y venta | F10: Rebaja a VNR registrada | G10: NIC 2.9, 2.28-2.33 · PYMES 27.2-27.4
A11: INV-07 | B11: Obsolescencia y lenta rotación | C11: Valoración | D11: Clasificar por días sin movimiento y aplicar los % de la política | E11: Kardex con fechas de último movimiento, política | F11: Provisión suficiente | G11: NIC 2.28 · PYMES 27.2
A12: INV-09 | B12: Materias primas: excepción de NIC 2.32 | C12: Valoración | D12: Para cada materia prima con VNR bajo el costo, obtener el costeo del producto terminado asociado y su precio de venta esperado, recalcular el margen y aplicar la excepción solo si el producto terminado se venderá al costo o por encima | E12: Costeo estándar del producto terminado, lista de precios y pedidos en firme; costo de reposición de los materiales | F12: Excepción aplicada solo con margen demostrado; en caso contrario, rebaja a VNR registrada | G12: NIC 2.32 · PYMES: sin equivalente (13.19, 27.2-27.4), la excepción no se aplica
A13: INV-08 | B13: Corte | C13: Corte | D13: Comparar la fecha de recepción o despacho con la de registro alrededor del cierre | E13: Guías, facturas y asientos antes y después del corte | F13: Sin errores de corte o ajustados | G13: NIA 330, INV-04

Sheet 00_Fuentes
A1: Base técnica | H1: ⟵ Inicio | I1: ◀ Anterior | J1: Siguiente ▶
A2: Inventarios, producción y costo de ventas · Cliente de muestra S.A. · corte 2025-12-31
A4: Categoría | B4: Documento | C4: Párrafos | D4: URL | E4: Verificada
A5: NIA · NIA 501 | B5: Presenciar el recuento físico de existencias materiales y probar sus resultados finales. | C5: párr. 4 y 7
A6: NIA · NIA 500 | B6: Evaluar exactitud e integridad del kardex y los anexos contra el mayor. | C6: párr. 9
A7: NIA · NIA 540 (Revisada) | B7: VNR, obsolescencia y capacidad normal son estimaciones: evaluar método, datos y supuestos. | C7: párr. 13, 16-17, 18-30 y 32
A8: NIA · NIA 330 | B8: Procedimientos sustantivos de corte y de conciliación con los registros. | C8: párr. 6-7, 18 y 20
A9: NIA · NIA 560 | B9: Precios de venta posteriores al cierre como evidencia del VNR (NIC 2.30). | C9: párr. 6 · NIA 540 párr. 21

Sheet 01_Resumen
A1: Resumen y ajuste propuesto | H1: ⟵ Inicio | I1: ◀ Anterior | J1: Siguiente ▶
A2: Inventarios, producción y costo de ventas · Cliente de muestra S.A. · corte 2025-12-31
A4: Concepto | B4: Importe
A5: Inventario al costo auditado | B5: =SUM('03_Inventario'!$O$5:$O$17)
A6: Provisión estimada (rebaja a VNR; tramo solo sin precio; neta de la excepción NIC 2.32) | B6: =SUM('10_Obsolescencia'!$J$5:$J$17)
A7: Inventario neto auditado | B7: =B5-B6
A8: Inventario según el mayor | B8: =IF('02_Parametros'!$B$13="",SUM('03_Inventario'!$G$5:$G$17),'02_Parametros'!$B$13)
A9: Provisión registrada | B9: =IF('02_Parametros'!$B$14="",0,'02_Parametros'!$B$14)
A10: Inventario neto en libros | B10: =B8-B9
A11: Ajuste propuesto (neto) | B11: =B7-B10
A12: Diferencias físicas valorizadas | B12: =SUM('04_Conteo'!$H$5:$H$17)
A13: Diferencia de extensión (cantidad × costo − kardex) | B13: =SUM('05_Prueba_costo'!$G$5:$G$17)
A14: Diferencia de costo unitario | B14: =SUM('05_Prueba_costo'!$J$5:$J$17)
A15: Diferencia kardex − mayor | B15: =SUM('03_Inventario'!$G$5:$G$17)-B8
A16: Rebaja a VNR | B16: =SUM('09_VNR'!$I$5:$I$17)
A17: Provisión no reconocida por la excepción de NIC 2.32 (materias primas) | B17: =SUM('11_Excepcion_MP'!$K$5:$K$17)
A18: Provisión por obsolescencia (tramos) | B18: =SUM('10_Obsolescencia'!$G$5:$G$17)
A19: CIF fijo no absorbido (gasto) | B19: =SUM('07_Costo_produccion'!$K$5:$K$7)
A20: CIF no absorbido capitalizado por la entidad | B20: =SUM('07_Costo_produccion'!$O$5:$O$7)
A21: Diferencia en costo de ventas | B21: =SUM('08_Costo_ventas'!$M$5:$M$6)
A22: Importe con error de corte | B22: =SUM('12_Corte'!$I$5:$I$9)
A24: ⓘ Cómo se calcula esta hoja
A25: Columna | B25: Fórmula (Excel) | C25: Cómo se calcula (sencillo) | D25: Ejemplo con números reales | E25: De dónde viene | F25: Norma
A26: Importe | B26: '=SUM('03_Inventario'!$O$5:$O$17) | C26: Trae cada concepto de su hoja de origen: el costo auditado de la hoja 03, la provisión estimada y la de obsolescencia de la hoja 10, el mayor y la provisión registrada de la hoja 02 (Parámetros), y las diferencias de las hojas 04, 05, 07, 08, 09, 11 y 12; los netos y el ajuste se calculan con esas filas. | D26: Fila 1: SUM([«Costo auditado» de «Inventario valorado por ítem», 13 filas]) → 41.016,00 | E26: hoja «Inventario valorado por ítem» | F26: —

Sheet 02_Parametros
A1: Parámetros | H1: ⟵ Inicio | I1: ◀ Anterior | J1: Siguiente ▶
A2: Inventarios, producción y costo de ventas · Cliente de muestra S.A. · corte 2025-12-31
A4: Parámetro | B4: Valor | C4: Sustento
A5: Corte del ejercicio | B5: 46022 | C5: Ficha del encargo
A6: Marco y ruta de cálculo | B6: NIIF completas · NIC 2 | C6: La medición base es la misma en ambos marcos (menor entre costo y VNR / precio de venta menos costos de terminación y venta); cambian las citas. Ruta por marco: la excepción de NIC 2.32 para materias primas solo existe en NIIF completas; PYMES 13.19 y 27.2-27.4 no la recogen, así que en PYMES la cédula 11 la deniega siempre. PYMES 27.3 agrupa solo si es impracticable; costos por préstamos a gasto (Secc. 25)
A7: Tramo 1: días sin movimiento (más de) | B7: 180 | C7: Política de la entidad o juicio del auditor (NIC 2.28; PYMES 27.2). Los % solo estiman el VNR de los ítems SIN precio de venta (NIC 2.30): con precio informado manda la rebaja a VNR (NIC 2.9; PYMES 13.4)
A8: Tramo 1: % de provisión | B8: 25 | C8: Juicio del auditor con sustento
A9: Tramo 2: días sin movimiento (más de) | B9: 365 | C9: Ídem tramo 1
A10: Tramo 2: % de provisión | B10: 50 | C10: Ídem tramo 1
A11: Tramo 3: días sin movimiento (más de) | B11: 730 | C11: Ídem tramo 1
A12: Tramo 3: % de provisión | B12: 100 | C12: Ídem tramo 1
A13: Saldo del inventario según el mayor | B13: 41300 | C13: Mayor contable (en blanco: se toma el kardex)
A14: Provisión registrada (VNR / obsolescencia) | B14: 1000 | C14: Mayor contable (en blanco: 0)

Sheet 03_Inventario
A1: Inventario valorado por ítem | H1: ⟵ Inicio | I1: ◀ Anterior | J1: Siguiente ▶
A2: Inventarios, producción y costo de ventas · Cliente de muestra S.A. · corte 2025-12-31
A4: Código | B4: Descripción | C4: Bodega | D4: Cantidad kardex | E4: Cantidad contada | F4: Costo unitario | G4: Valor kardex | H4: Costo unitario soportado | I4: Último movimiento | J4: Precio de venta | K4: Costos de terminación | L4: Costos de venta | M4: Cantidad auditada | N4: Costo unitario auditado | O4: Costo auditado | P4: ¿Materia prima? | Q4: Producto terminado asociado | R4: Costo esperado del producto terminado | S4: Precio esperado del producto terminado | T4: Margen esperado del producto terminado
A5: A-001 | B5: Tornillo 1/4 | C5: BOD1 | D5: 1000 | E5: 1000 | F5: 2.5 | G5: 2500 | I5: 46001 | J5: 4 | L5: 0.3 | M5: =IF(E5<>"",E5,D5) | N5: =IF(H5<>"",H5,F5) | O5: =M5*N5 | P5: No | T5: =IF(OR(R5="",S5=""),"",S5-R5)
A6: A-002 | B6: Tuerca 1/4 | C6: BOD1 | D6: 500 | E6: 480 | F6: 1.2 | G6: 600 | I6: 45991 | J6: 2 | L6: 0.1 | M6: =IF(E6<>"",E6,D6) | N6: =IF(H6<>"",H6,F6) | O6: =M6*N6 | P6: No | T6: =IF(OR(R6="",S6=""),"",S6-R6)
A7: A-003 | B7: Arandela | C7: BOD1 | D7: 2000 | E7: 2000 | F7: 0.5 | G7: 1000 | H7: 0.55 | I7: 46011 | J7: 0.9 | M7: =IF(E7<>"",E7,D7) | N7: =IF(H7<>"",H7,F7) | O7: =M7*N7 | P7: No | T7: =IF(OR(R7="",S7=""),"",S7-R7)
A8: B-010 | B8: Motor 2 HP | C8: BOD2 | D8: 10 | E8: 10 | F8: 350 | G8: 3600 | I8: 45945 | J8: 300 | K8: 20 | L8: 15 | M8: =IF(E8<>"",E8,D8) | N8: =IF(H8<>"",H8,F8) | O8: =M8*N8 | P8: No | T8: =IF(OR(R8="",S8=""),"",S8-R8)
A9: B-011 | B9: Bomba centrífuga | C9: BOD2 | D9: 4 | E9: 4 | F9: 800 | G9: 3200 | I9: 45717 | J9: 1200 | L9: 50 | M9: =IF(E9<>"",E9,D9) | N9: =IF(H9<>"",H9,F9) | O9: =M9*N9 | P9: No | T9: =IF(OR(R9="",S9=""),"",S9-R9)
A10: B-012 | B10: Válvula 2" | C10: BOD2 | D10: 20 | F10: 45 | G10: 900 | I10: 45473 | J10: 70 | M10: =IF(E10<>"",E10,D10) | N10: =IF(H10<>"",H10,F10) | O10: =M10*N10 | P10: No | T10: =IF(OR(R10="",S10=""),"",S10-R10)
A11: C-100 | B11: Repuesto modelo descontinuado | C11: BOD3 | D11: 15 | E11: 15 | F11: 120 | G11: 1800 | I11: 45077 | M11: =IF(E11<>"",E11,D11) | N11: =IF(H11<>"",H11,F11) | O11: =M11*N11 | P11: No | T11: =IF(OR(R11="",S11=""),"",S11-R11)
A12: C-101 | B12: Producto terminado X | C12: BOD3 | D12: 300 | E12: 305 | F12: 18 | G12: 5400 | I12: 46019 | J12: 25 | L12: 2 | M12: =IF(E12<>"",E12,D12) | N12: =IF(H12<>"",H12,F12) | O12: =M12*N12 | P12: No | T12: =IF(OR(R12="",S12=""),"",S12-R12)
A13: C-102 | B13: Producto terminado Y | C13: BOD3 | D13: 150 | E13: 150 | F13: 30 | G13: 4500 | I13: 46006 | J13: 28 | L13: 1.5 | M13: =IF(E13<>"",E13,D13) | N13: =IF(H13<>"",H13,F13) | O13: =M13*N13 | P13: No | T13: =IF(OR(R13="",S13=""),"",S13-R13)
A14: D-200 | B14: Materia prima Z | C14: BOD4 | D14: 800 | E14: 790 | F14: 5 | G14: 4000 | I14: 45996 | J14: 7 | K14: 1.5 | M14: =IF(E14<>"",E14,D14) | N14: =IF(H14<>"",H14,F14) | O14: =M14*N14 | P14: Sí | Q14: Ensamble Z-1 | R14: 60 | S14: 72 | T14: =IF(OR(R14="",S14=""),"",S14-R14)
A15: E-300 | B15: Lámina de acero | C15: BOD4 | D15: 200 | E15: 200 | F15: 40 | G15: 8000 | I15: 45981 | J15: 34 | L15: 1 | M15: =IF(E15<>"",E15,D15) | N15: =IF(H15<>"",H15,F15) | O15: =M15*N15 | P15: Sí | Q15: Tanque 200 L | R15: 300 | S15: 330 | T15: =IF(OR(R15="",S15=""),"",S15-R15)
A16: E-301 | B16: Perfil de aluminio | C16: BOD4 | D16: 100 | E16: 100 | F16: 25 | G16: 2500 | I16: 45992 | J16: 20 | M16: =IF(E16<>"",E16,D16) | N16: =IF(H16<>"",H16,F16) | O16: =M16*N16 | P16: Sí | Q16: Estructura AL-2 | R16: 600 | S16: 560 | T16: =IF(OR(R16="",S16=""),"",S16-R16)
A17: E-302 | B17: Resina industrial | C17: BOD4 | D17: 50 | E17: 50 | F17: 60 | G17: 3000 | I17: 45999 | J17: 52 | L17: 2 | M17: =IF(E17<>"",E17,D17) | N17: =IF(H17<>"",H17,F17) | O17: =M17*N17 | P17: Sí | Q17: Envase EX-9 | T17: =IF(OR(R17="",S17=""),"",S17-R17)
A18: TOTAL | G18: =SUM(G5:G17) | O18: =SUM(O5:O17)
A20: ⓘ Cómo se calcula esta hoja
A21: Columna | B21: Fórmula (Excel) | C21: Cómo se calcula (sencillo) | D21: Ejemplo con números reales | E21: De dónde viene | F21: Norma
A22: Cantidad auditada | B22: '=IF(E5<>"",E5,D5) | C22: Usa la cantidad contada por el auditor; si el ítem no se contó (celda vacía), toma la cantidad del kardex. | D22: Fila 1: IF(1.000,00<>""; 1.000,00; 1.000,00) → 1.000,00 | E22: «Cantidad contada» (esta hoja), «Cantidad kardex» (esta hoja) | F22: —
A23: Costo unitario auditado | B23: '=IF(H5<>"",H5,F5) | C23: Usa el costo unitario soportado por el auditor (factura o costeo); si no hay soporte, toma el costo unitario registrado en el kardex. | D23: Fila 1: IF((vacío)<>""; (vacío); 2,50) → 2,50 | E23: «Costo unitario soportado» (esta hoja), «Costo unitario» (esta hoja) | F23: —
A24: Costo auditado | B24: '=M5*N5 | C24: Multiplica la cantidad auditada por el costo unitario auditado: es el valor del ítem que el auditor acepta. | D24: Fila 1: 1.000,00*2,50 → 2.500,00 | E24: «Cantidad auditada» (esta hoja), «Costo unitario auditado» (esta hoja) | F24: —
A25: Margen esperado del producto terminado | B25: '=IF(OR(R5="",S5=""),"",S5-R5) | C25: Precio esperado menos costo esperado del producto terminado al que se incorpora la materia prima; queda en blanco si falta alguno de los dos datos. | D25: Fila 1: IF(OR((vacío)=""; (vacío)=""); ""; (vacío)-(vacío)) → (en blanco) | E25: «Costo esperado del producto terminado» (esta hoja), «Precio esperado del producto terminado» (esta hoja) | F25: —

Sheet 04_Conteo
A1: Existencia: conteo vs kardex | H1: ⟵ Inicio | I1: ◀ Anterior | J1: Siguiente ▶
A2: Inventarios, producción y costo de ventas · Cliente de muestra S.A. · corte 2025-12-31
A4: Código | B4: Descripción | C4: Bodega | D4: Cantidad kardex | E4: Cantidad contada | F4: Diferencia (unidades) | G4: Costo unitario | H4: Diferencia valorizada
A5: A-001 | B5: Tornillo 1/4 | C5: BOD1 | D5: ='03_Inventario'!D5 | E5: =IF('03_Inventario'!E5="","",'03_Inventario'!E5) | F5: =IF(E5="","",E5-D5) | G5: ='03_Inventario'!F5 | H5: =IF(F5="","",F5*G5)
A6: A-002 | B6: Tuerca 1/4 | C6: BOD1 | D6: ='03_Inventario'!D6 | E6: =IF('03_Inventario'!E6="","",'03_Inventario'!E6) | F6: =IF(E6="","",E6-D6) | G6: ='03_Inventario'!F6 | H6: =IF(F6="","",F6*G6)
A7: A-003 | B7: Arandela | C7: BOD1 | D7: ='03_Inventario'!D7 | E7: =IF('03_Inventario'!E7="","",'03_Inventario'!E7) | F7: =IF(E7="","",E7-D7) | G7: ='03_Inventario'!F7 | H7: =IF(F7="","",F7*G7)
A8: B-010 | B8: Motor 2 HP | C8: BOD2 | D8: ='03_Inventario'!D8 | E8: =IF('03_Inventario'!E8="","",'03_Inventario'!E8) | F8: =IF(E8="","",E8-D8) | G8: ='03_Inventario'!F8 | H8: =IF(F8="","",F8*G8)
A9: B-011 | B9: Bomba centrífuga | C9: BOD2 | D9: ='03_Inventario'!D9 | E9: =IF('03_Inventario'!E9="","",'03_Inventario'!E9) | F9: =IF(E9="","",E9-D9) | G9: ='03_Inventario'!F9 | H9: =IF(F9="","",F9*G9)
A10: B-012 | B10: Válvula 2" | C10: BOD2 | D10: ='03_Inventario'!D10 | E10: =IF('03_Inventario'!E10="","",'03_Inventario'!E10) | F10: =IF(E10="","",E10-D10) | G10: ='03_Inventario'!F10 | H10: =IF(F10="","",F10*G10)
A11: C-100 | B11: Repuesto modelo descontinuado | C11: BOD3 | D11: ='03_Inventario'!D11 | E11: =IF('03_Inventario'!E11="","",'03_Inventario'!E11) | F11: =IF(E11="","",E11-D11) | G11: ='03_Inventario'!F11 | H11: =IF(F11="","",F11*G11)
A12: C-101 | B12: Producto terminado X | C12: BOD3 | D12: ='03_Inventario'!D12 | E12: =IF('03_Inventario'!E12="","",'03_Inventario'!E12) | F12: =IF(E12="","",E12-D12) | G12: ='03_Inventario'!F12 | H12: =IF(F12="","",F12*G12)
A13: C-102 | B13: Producto terminado Y | C13: BOD3 | D13: ='03_Inventario'!D13 | E13: =IF('03_Inventario'!E13="","",'03_Inventario'!E13) | F13: =IF(E13="","",E13-D13) | G13: ='03_Inventario'!F13 | H13: =IF(F13="","",F13*G13)
A14: D-200 | B14: Materia prima Z | C14: BOD4 | D14: ='03_Inventario'!D14 | E14: =IF('03_Inventario'!E14="","",'03_Inventario'!E14) | F14: =IF(E14="","",E14-D14) | G14: ='03_Inventario'!F14 | H14: =IF(F14="","",F14*G14)
A15: E-300 | B15: Lámina de acero | C15: BOD4 | D15: ='03_Inventario'!D15 | E15: =IF('03_Inventario'!E15="","",'03_Inventario'!E15) | F15: =IF(E15="","",E15-D15) | G15: ='03_Inventario'!F15 | H15: =IF(F15="","",F15*G15)
A16: E-301 | B16: Perfil de aluminio | C16: BOD4 | D16: ='03_Inventario'!D16 | E16: =IF('03_Inventario'!E16="","",'03_Inventario'!E16) | F16: =IF(E16="","",E16-D16) | G16: ='03_Inventario'!F16 | H16: =IF(F16="","",F16*G16)
A17: E-302 | B17: Resina industrial | C17: BOD4 | D17: ='03_Inventario'!D17 | E17: =IF('03_Inventario'!E17="","",'03_Inventario'!E17) | F17: =IF(E17="","",E17-D17) | G17: ='03_Inventario'!F17 | H17: =IF(F17="","",F17*G17)
A18: TOTAL | H18: =SUM(H5:H17)
A20: ⓘ Cómo se calcula esta hoja
A21: Columna | B21: Fórmula (Excel) | C21: Cómo se calcula (sencillo) | D21: Ejemplo con números reales | E21: De dónde viene | F21: Norma
A22: Cantidad kardex | B22: '='03_Inventario'!D5 | C22: Trae la cantidad registrada en el kardex para este ítem desde la hoja 03 (Inventario valorado por ítem). | D22: Fila 1: 1.000,00 → 1.000,00 | E22: hoja «Inventario valorado por ítem» | F22: —
A23: Cantidad contada | B23: '=IF('03_Inventario'!E5="","",'03_Inventario'!E5) | C23: Trae la cantidad contada en la toma física desde la hoja 03 (Inventario valorado por ítem); si el ítem no se contó, queda en blanco. | D23: Fila 1: IF(1.000,00=""; ""; 1.000,00) → 1.000,00 | E23: hoja «Inventario valorado por ítem» | F23: —
A24: Diferencia (unidades) | B24: '=IF(E5="","",E5-D5) | C24: Cantidad contada menos cantidad del kardex: positivo es sobrante y negativo faltante. En blanco si el ítem no se contó. | D24: Fila 1: IF(1.000,00=""; ""; 1.000,00-1.000,00) → 0,00 | E24: «Cantidad contada» (esta hoja), «Cantidad kardex» (esta hoja) | F24: —
A25: Costo unitario | B25: '='03_Inventario'!F5 | C25: Trae el costo unitario registrado en el kardex desde la hoja 03 (Inventario valorado por ítem). | D25: Fila 1: 2,50 → 2,50 | E25: hoja «Inventario valorado por ítem» | F25: —
A26: Diferencia valorizada | B26: '=IF(F5="","",F5*G5) | C26: Multiplica la diferencia en unidades por el costo unitario del kardex: es el efecto en dólares del sobrante o faltante. En blanco si el ítem no se contó. | D26: Fila 1: IF(0,00=""; ""; 0,00*2,50) → 0,00 | E26: «Diferencia (unidades)» (esta hoja), «Costo unitario» (esta hoja) | F26: —

Sheet 05_Prueba_costo
A1: Prueba de costo | H1: ⟵ Inicio | I1: ◀ Anterior | J1: Siguiente ▶
A2: Inventarios, producción y costo de ventas · Cliente de muestra S.A. · corte 2025-12-31
A4: Código | B4: Descripción | C4: Cantidad kardex | D4: Costo unitario | E4: Valor recalculado | F4: Valor kardex | G4: Diferencia de extensión | H4: Costo unitario soportado | I4: Diferencia unitaria | J4: Efecto en el costo auditado
A5: A-001 | B5: Tornillo 1/4 | C5: ='03_Inventario'!D5 | D5: ='03_Inventario'!F5 | E5: =C5*D5 | F5: ='03_Inventario'!G5 | G5: =E5-F5 | H5: =IF('03_Inventario'!H5="","",'03_Inventario'!H5) | I5: =IF(H5="","",H5-D5) | J5: =IF(I5="","",I5*'03_Inventario'!M5)
A6: A-002 | B6: Tuerca 1/4 | C6: ='03_Inventario'!D6 | D6: ='03_Inventario'!F6 | E6: =C6*D6 | F6: ='03_Inventario'!G6 | G6: =E6-F6 | H6: =IF('03_Inventario'!H6="","",'03_Inventario'!H6) | I6: =IF(H6="","",H6-D6) | J6: =IF(I6="","",I6*'03_Inventario'!M6)
A7: A-003 | B7: Arandela | C7: ='03_Inventario'!D7 | D7: ='03_Inventario'!F7 | E7: =C7*D7 | F7: ='03_Inventario'!G7 | G7: =E7-F7 | H7: =IF('03_Inventario'!H7="","",'03_Inventario'!H7) | I7: =IF(H7="","",H7-D7) | J7: =IF(I7="","",I7*'03_Inventario'!M7)
A8: B-010 | B8: Motor 2 HP | C8: ='03_Inventario'!D8 | D8: ='03_Inventario'!F8 | E8: =C8*D8 | F8: ='03_Inventario'!G8 | G8: =E8-F8 | H8: =IF('03_Inventario'!H8="","",'03_Inventario'!H8) | I8: =IF(H8="","",H8-D8) | J8: =IF(I8="","",I8*'03_Inventario'!M8)
A9: B-011 | B9: Bomba centrífuga | C9: ='03_Inventario'!D9 | D9: ='03_Inventario'!F9 | E9: =C9*D9 | F9: ='03_Inventario'!G9 | G9: =E9-F9 | H9: =IF('03_Inventario'!H9="","",'03_Inventario'!H9) | I9: =IF(H9="","",H9-D9) | J9: =IF(I9="","",I9*'03_Inventario'!M9)
A10: B-012 | B10: Válvula 2" | C10: ='03_Inventario'!D10 | D10: ='03_Inventario'!F10 | E10: =C10*D10 | F10: ='03_Inventario'!G10 | G10: =E10-F10 | H10: =IF('03_Inventario'!H10="","",'03_Inventario'!H10) | I10: =IF(H10="","",H10-D10) | J10: =IF(I10="","",I10*'03_Inventario'!M10)
A11: C-100 | B11: Repuesto modelo descontinuado | C11: ='03_Inventario'!D11 | D11: ='03_Inventario'!F11 | E11: =C11*D11 | F11: ='03_Inventario'!G11 | G11: =E11-F11 | H11: =IF('03_Inventario'!H11="","",'03_Inventario'!H11) | I11: =IF(H11="","",H11-D11) | J11: =IF(I11="","",I11*'03_Inventario'!M11)
A12: C-101 | B12: Producto terminado X | C12: ='03_Inventario'!D12 | D12: ='03_Inventario'!F12 | E12: =C12*D12 | F12: ='03_Inventario'!G12 | G12: =E12-F12 | H12: =IF('03_Inventario'!H12="","",'03_Inventario'!H12) | I12: =IF(H12="","",H12-D12) | J12: =IF(I12="","",I12*'03_Inventario'!M12)
A13: C-102 | B13: Producto terminado Y | C13: ='03_Inventario'!D13 | D13: ='03_Inventario'!F13 | E13: =C13*D13 | F13: ='03_Inventario'!G13 | G13: =E13-F13 | H13: =IF('03_Inventario'!H13="","",'03_Inventario'!H13) | I13: =IF(H13="","",H13-D13) | J13: =IF(I13="","",I13*'03_Inventario'!M13)
A14: D-200 | B14: Materia prima Z | C14: ='03_Inventario'!D14 | D14: ='03_Inventario'!F14 | E14: =C14*D14 | F14: ='03_Inventario'!G14 | G14: =E14-F14 | H14: =IF('03_Inventario'!H14="","",'03_Inventario'!H14) | I14: =IF(H14="","",H14-D14) | J14: =IF(I14="","",I14*'03_Inventario'!M14)
A15: E-300 | B15: Lámina de acero | C15: ='03_Inventario'!D15 | D15: ='03_Inventario'!F15 | E15: =C15*D15 | F15: ='03_Inventario'!G15 | G15: =E15-F15 | H15: =IF('03_Inventario'!H15="","",'03_Inventario'!H15) | I15: =IF(H15="","",H15-D15) | J15: =IF(I15="","",I15*'03_Inventario'!M15)
A16: E-301 | B16: Perfil de aluminio | C16: ='03_Inventario'!D16 | D16: ='03_Inventario'!F16 | E16: =C16*D16 | F16: ='03_Inventario'!G16 | G16: =E16-F16 | H16: =IF('03_Inventario'!H16="","",'03_Inventario'!H16) | I16: =IF(H16="","",H16-D16) | J16: =IF(I16="","",I16*'03_Inventario'!M16)
A17: E-302 | B17: Resina industrial | C17: ='03_Inventario'!D17 | D17: ='03_Inventario'!F17 | E17: =C17*D17 | F17: ='03_Inventario'!G17 | G17: =E17-F17 | H17: =IF('03_Inventario'!H17="","",'03_Inventario'!H17) | I17: =IF(H17="","",H17-D17) | J17: =IF(I17="","",I17*'03_Inventario'!M17)
A18: TOTAL | E18: =SUM(E5:E17) | F18: =SUM(F5:F17) | G18: =SUM(G5:G17) | J18: =SUM(J5:J17)
A20: ⓘ Cómo se calcula esta hoja
A21: Columna | B21: Fórmula (Excel) | C21: Cómo se calcula (sencillo) | D21: Ejemplo con números reales | E21: De dónde viene | F21: Norma
A22: Cantidad kardex | B22: '='03_Inventario'!D5 | C22: Trae la cantidad del kardex del ítem desde la hoja 03 (Inventario valorado por ítem). | D22: Fila 1: 1.000,00 → 1.000,00 | E22: hoja «Inventario valorado por ítem» | F22: —
A23: Costo unitario | B23: '='03_Inventario'!F5 | C23: Trae el costo unitario que registró el cliente en el kardex, desde la hoja 03 (Inventario valorado por ítem). | D23: Fila 1: 2,50 → 2,50 | E23: hoja «Inventario valorado por ítem» | F23: —
A24: Valor recalculado | B24: '=C5*D5 | C24: Multiplica la cantidad del kardex por su costo unitario, para comprobar la extensión del valor. | D24: Fila 1: 1.000,00*2,50 → 2.500,00 | E24: «Cantidad kardex» (esta hoja), «Costo unitario» (esta hoja) | F24: —
A25: Valor kardex | B25: '='03_Inventario'!G5 | C25: Trae el valor total que el kardex del cliente muestra para el ítem, desde la hoja 03 (Inventario valorado por ítem). | D25: Fila 1: 2.500,00 → 2.500,00 | E25: hoja «Inventario valorado por ítem» | F25: —
A26: Diferencia de extensión | B26: '=E5-F5 | C26: Valor recalculado menos valor del kardex: si no es cero, el kardex tiene un error de multiplicación. | D26: Fila 1: 2.500,00-2.500,00 → 0,00 | E26: «Valor recalculado» (esta hoja), «Valor kardex» (esta hoja) | F26: —
A27: Costo unitario soportado | B27: '=IF('03_Inventario'!H5="","",'03_Inventario'!H5) | C27: Trae el costo unitario que el auditor verificó con factura o costeo, desde la hoja 03; si no hay soporte, queda en blanco. | D27: Fila 1: IF((vacío)=""; ""; (vacío)) → (en blanco) | E27: hoja «Inventario valorado por ítem» | F27: —
A28: Diferencia unitaria | B28: '=IF(H5="","",H5-D5) | C28: Costo unitario soportado menos costo unitario del kardex; en blanco si no hay costo soportado. | D28: Fila 1: IF((vacío)=""; ""; (vacío)-2,50) → (en blanco) | E28: «Costo unitario soportado» (esta hoja), «Costo unitario» (esta hoja) | F28: —
A29: Efecto en el costo auditado | B29: '=IF(I5="","",I5*'03_Inventario'!M5) | C29: Multiplica la diferencia unitaria por la cantidad auditada de la hoja 03: es cuánto cambia el valor del ítem por el costo soportado. En blanco si no hay soporte. | D29: Fila 1: IF((vacío)=""; ""; (vacío)*1.000,00) → (en blanco) | E29: «Diferencia unitaria» (esta hoja), hoja «Inventario valorado por ítem» | F29: —

Sheet 06_Conciliacion
A1: Conciliación kardex–mayor | H1: ⟵ Inicio | I1: ◀ Anterior | J1: Siguiente ▶
A2: Inventarios, producción y costo de ventas · Cliente de muestra S.A. · corte 2025-12-31
A4: Concepto | B4: Importe
A5: Valor según kardex (inventario valorado) | B5: =SUM('03_Inventario'!$G$5:$G$17)
A6: Saldo según el mayor | B6: =IF('02_Parametros'!$B$13="",SUM('03_Inventario'!$G$5:$G$17),'02_Parametros'!$B$13)
A7: Diferencia kardex − mayor | B7: =B5-B6
A8: (+) Diferencia de extensión (recalculado − kardex) | B8: =SUM('05_Prueba_costo'!$G$5:$G$17)
A9: (+) Diferencias físicas valorizadas | B9: =SUM('04_Conteo'!$H$5:$H$17)
A10: (+) Diferencias de costo unitario | B10: =SUM('05_Prueba_costo'!$J$5:$J$17)
A11: Inventario al costo auditado (puente desde el mayor) | B11: =B6+B7+B8+B9+B10
A12: Control: costo auditado según el detalle | B12: =SUM('03_Inventario'!$O$5:$O$17)
A13: Diferencia de control (debe ser 0) | B13: =B11-B12
A14: Costo de producción capitalizable recalculado (07) | B14: =SUM('07_Costo_produccion'!$L$5:$L$7)
A15: Costos de manufactura registrados (08) | B15: =SUM('08_Costo_ventas'!$G$5:$G$6)
A16: Producción no conciliada (registrado − recalculado) | B16: =B15-B14
A18: ⓘ Cómo se calcula esta hoja
A19: Columna | B19: Fórmula (Excel) | C19: Cómo se calcula (sencillo) | D19: Ejemplo con números reales | E19: De dónde viene | F19: Norma
A20: Importe | B20: '=SUM('03_Inventario'!$G$5:$G$17) | C20: Parte del valor del kardex (suma de la hoja 03) y del mayor (hoja 02; si está vacío, el kardex), suma las diferencias de extensión y de costo de la hoja 05 y las físicas de la hoja 04 para llegar al costo auditado, lo controla contra la hoja 03 y compara la producción de las hojas 07 y 08. | D20: Fila 1: SUM([«Valor kardex» de «Inventario valorado por ítem», 13 filas]) → 41.000,00 | E20: hoja «Inventario valorado por ítem» | F20: —

Sheet 07_Costo_produccion
A1: Costo de producción | H1: ⟵ Inicio | I1: ◀ Anterior | J1: Siguiente ▶
A2: Inventarios, producción y costo de ventas · Cliente de muestra S.A. · corte 2025-12-31
A4: Período / orden | B4: Materia prima | C4: MOD | D4: CIF variable | E4: CIF fijo | F4: Unidades producidas | G4: Capacidad normal | H4: Desperdicio anormal | I4: Tasa CIF fijo | J4: CIF fijo absorbido | K4: CIF fijo no absorbido (gasto) | L4: Costo capitalizable | M4: Costo unitario | N4: CIF fijo capitalizado (entidad) | O4: No absorbido capitalizado
A5: OP-01 | B5: 20000 | C5: 8000 | D5: 3000 | E5: 12000 | F5: 800 | G5: 1000 | I5: =IF(OR(G5="",G5=0),"",E5/G5) | J5: =IF(I5="","",MIN(E5,I5*F5)) | K5: =IF(J5="","",E5-J5) | L5: =IF(J5="","",B5+C5+D5+J5-H5) | M5: =IF(OR(L5="",F5=0),"",L5/F5) | N5: 12000 | O5: =IF(OR(N5="",J5=""),"",MAX(0,N5-J5))
A6: OP-02 | B6: 25000 | C6: 10000 | D6: 3750 | E6: 12000 | F6: 1000 | G6: 1000 | H6: 500 | I6: =IF(OR(G6="",G6=0),"",E6/G6) | J6: =IF(I6="","",MIN(E6,I6*F6)) | K6: =IF(J6="","",E6-J6) | L6: =IF(J6="","",B6+C6+D6+J6-H6) | M6: =IF(OR(L6="",F6=0),"",L6/F6) | N6: 12000 | O6: =IF(OR(N6="",J6=""),"",MAX(0,N6-J6))
A7: OP-03 | B7: 30000 | C7: 12000 | D7: 4500 | E7: 12000 | F7: 1200 | G7: 1000 | I7: =IF(OR(G7="",G7=0),"",E7/G7) | J7: =IF(I7="","",MIN(E7,I7*F7)) | K7: =IF(J7="","",E7-J7) | L7: =IF(J7="","",B7+C7+D7+J7-H7) | M7: =IF(OR(L7="",F7=0),"",L7/F7) | N7: 12000 | O7: =IF(OR(N7="",J7=""),"",MAX(0,N7-J7))
A8: TOTAL | B8: =SUM(B5:B7) | C8: =SUM(C5:C7) | D8: =SUM(D5:D7) | E8: =SUM(E5:E7) | J8: =SUM(J5:J7) | K8: =SUM(K5:K7) | L8: =SUM(L5:L7) | O8: =SUM(O5:O7)
A10: ⓘ Cómo se calcula esta hoja
A11: Columna | B11: Fórmula (Excel) | C11: Cómo se calcula (sencillo) | D11: Ejemplo con números reales | E11: De dónde viene | F11: Norma
A12: Tasa CIF fijo | B12: '=IF(OR(G5="",G5=0),"",E5/G5) | C12: Divide el CIF fijo del período para la capacidad normal: es el CIF fijo que corresponde a cada unidad. En blanco si no hay capacidad normal. | D12: Fila 1: IF(OR(1.000,00=""; 1.000,00=0); ""; 12.000,00/1.000,00) → 12,00 | E12: «Capacidad normal» (esta hoja), «CIF fijo» (esta hoja) | F12: —
A13: CIF fijo absorbido | B13: '=IF(I5="","",MIN(E5,I5*F5)) | C13: Multiplica la tasa de CIF fijo por las unidades producidas, sin pasar del CIF fijo total: es la parte que puede ir al costo del inventario. | D13: Fila 1: IF(12,00=""; ""; MIN(12.000,00; 12,00*800,00)) → 9.600,00 | E13: «Tasa CIF fijo» (esta hoja), «CIF fijo» (esta hoja), «Unidades producidas» (esta hoja) | F13: —
A14: CIF fijo no absorbido (gasto) | B14: '=IF(J5="","",E5-J5) | C14: CIF fijo total menos el absorbido: es el costo de la capacidad ociosa, que va a gasto del período y no al inventario. | D14: Fila 1: IF(9.600,00=""; ""; 12.000,00-9.600,00) → 2.400,00 | E14: «CIF fijo absorbido» (esta hoja), «CIF fijo» (esta hoja) | F14: —
A15: Costo capitalizable | B15: '=IF(J5="","",B5+C5+D5+J5-H5) | C15: Suma materia prima, mano de obra directa, CIF variable y CIF fijo absorbido, y resta el desperdicio anormal: es el costo que puede quedar en el inventario (en blanco si no hay tasa de CIF fijo). | D15: Fila 1: IF(9.600,00=""; ""; 20.000,00+8.000,00+3.000,00+9.600,00-(vacío)) → 40.600,00 | E15: «CIF fijo absorbido» (esta hoja), «Materia prima» (esta hoja), «MOD» (esta hoja), «CIF variable» (esta hoja), «Desperdicio anormal» (esta hoja) | F15: —
A16: Costo unitario | B16: '=IF(OR(L5="",F5=0),"",L5/F5) | C16: Divide el costo capitalizable para las unidades producidas; en blanco si no hubo producción. | D16: Fila 1: IF(OR(40.600,00=""; 800,00=0); ""; 40.600,00/800,00) → 50,75 | E16: «Costo capitalizable» (esta hoja), «Unidades producidas» (esta hoja) | F16: —
A17: No absorbido capitalizado | B17: '=IF(OR(N5="",J5=""),"",MAX(0,N5-J5)) | C17: Compara el CIF fijo que la entidad capitalizó con el absorbido recalculado: el exceso (nunca negativo) es CIF que debió ir a gasto. En blanco si falta el dato de la entidad. | D17: Fila 1: IF(OR(12.000,00=""; 9.600,00=""); ""; MAX(0; 12.000,00-9.600,00)) → 2.400,00 | E17: «CIF fijo capitalizado (entidad)» (esta hoja), «CIF fijo absorbido» (esta hoja) | F17: —

Sheet 08_Costo_ventas
A1: Costo de ventas | H1: ⟵ Inicio | I1: ◀ Anterior | J1: Siguiente ▶
A2: Inventarios, producción y costo de ventas · Cliente de muestra S.A. · corte 2025-12-31
A4: Línea | B4: Inventario inicial | C4: Cierre auditado anterior | D4: Diferencia de apertura | E4: Compras netas | F4: WIP inicial | G4: Costos de manufactura | H4: WIP final | I4: Costo de producción terminada (COGM) | J4: Inventario final | K4: Costo de ventas recalculado | L4: Costo de ventas contable | M4: Diferencia
A5: Mercaderías | B5: 10000 | C5: 10000 | D5: =IF(C5="","",B5-C5) | E5: 60000 | I5: =IF(G5="","",F5+G5-H5) | J5: 12000 | K5: =B5+E5+IF(I5="",0,I5)-J5 | L5: 58000 | M5: =K5-L5
A6: Productos terminados | B6: 9000 | C6: 8500 | D6: =IF(C6="","",B6-C6) | E6: 0 | F6: 3000 | G6: 151750 | H6: 4000 | I6: =IF(G6="","",F6+G6-H6) | J6: 9900 | K6: =B6+E6+IF(I6="",0,I6)-J6 | L6: 148000 | M6: =K6-L6
A7: TOTAL | K7: =SUM(K5:K6) | L7: =SUM(L5:L6) | M7: =SUM(M5:M6)
A9: ⓘ Cómo se calcula esta hoja
A10: Columna | B10: Fórmula (Excel) | C10: Cómo se calcula (sencillo) | D10: Ejemplo con números reales | E10: De dónde viene | F10: Norma
A11: Diferencia de apertura | B11: '=IF(C5="","",B5-C5) | C11: Inventario inicial menos el cierre auditado del año anterior: debe ser cero. En blanco si no se informó el cierre anterior. | D11: Fila 1: IF(10.000,00=""; ""; 10.000,00-10.000,00) → 0,00 | E11: «Cierre auditado anterior» (esta hoja), «Inventario inicial» (esta hoja) | F11: —
A12: Costo de producción terminada (COGM) | B12: '=IF(G5="","",F5+G5-H5) | C12: WIP inicial más costos de manufactura menos WIP final: es el costo de lo que se terminó de producir. En blanco si no hay costos de manufactura. | D12: Fila 1: IF((vacío)=""; ""; (vacío)+(vacío)-(vacío)) → (en blanco) | E12: «Costos de manufactura» (esta hoja), «WIP inicial» (esta hoja), «WIP final» (esta hoja) | F12: —
A13: Costo de ventas recalculado | B13: '=B5+E5+IF(I5="",0,I5)-J5 | C13: Inventario inicial más compras netas más el costo de producción terminada (cero si no hay) menos inventario final. | D13: Fila 1: 10.000,00+60.000,00+IF((vacío)=""; 0; (vacío))-12.000,00 → 58.000,00 | E13: «Inventario inicial» (esta hoja), «Compras netas» (esta hoja), «Costo de producción terminada (COGM)» (esta hoja), «Inventario final» (esta hoja) | F13: —
A14: Diferencia | B14: '=K5-L5 | C14: Costo de ventas recalculado menos el costo de ventas contable del cliente para la misma línea. | D14: Fila 1: 58.000,00-58.000,00 → 0,00 | E14: «Costo de ventas recalculado» (esta hoja), «Costo de ventas contable» (esta hoja) | F14: —

Sheet 09_VNR
A1: Valor realizable neto | H1: ⟵ Inicio | I1: ◀ Anterior | J1: Siguiente ▶
A2: Inventarios, producción y costo de ventas · Cliente de muestra S.A. · corte 2025-12-31
A4: Código | B4: Descripción | C4: Cantidad auditada | D4: Costo unitario auditado | E4: Precio estimado de venta | F4: Costos de terminación | G4: Costos de venta | H4: VNR unitario | I4: Rebaja a VNR | J4: Medición
A5: A-001 | B5: Tornillo 1/4 | C5: ='03_Inventario'!M5 | D5: ='03_Inventario'!N5 | E5: =IF('03_Inventario'!J5="","",'03_Inventario'!J5) | F5: ='03_Inventario'!K5 | G5: ='03_Inventario'!L5 | H5: =IF(E5="","",E5-F5-G5) | I5: =IF(H5="","",MIN(C5*D5,MAX(0,D5-H5)*C5)) | J5: =IF(H5="","Sin precio",IF(H5<D5,"VNR","Costo"))
A6: A-002 | B6: Tuerca 1/4 | C6: ='03_Inventario'!M6 | D6: ='03_Inventario'!N6 | E6: =IF('03_Inventario'!J6="","",'03_Inventario'!J6) | F6: ='03_Inventario'!K6 | G6: ='03_Inventario'!L6 | H6: =IF(E6="","",E6-F6-G6) | I6: =IF(H6="","",MIN(C6*D6,MAX(0,D6-H6)*C6)) | J6: =IF(H6="","Sin precio",IF(H6<D6,"VNR","Costo"))
A7: A-003 | B7: Arandela | C7: ='03_Inventario'!M7 | D7: ='03_Inventario'!N7 | E7: =IF('03_Inventario'!J7="","",'03_Inventario'!J7) | F7: ='03_Inventario'!K7 | G7: ='03_Inventario'!L7 | H7: =IF(E7="","",E7-F7-G7) | I7: =IF(H7="","",MIN(C7*D7,MAX(0,D7-H7)*C7)) | J7: =IF(H7="","Sin precio",IF(H7<D7,"VNR","Costo"))
A8: B-010 | B8: Motor 2 HP | C8: ='03_Inventario'!M8 | D8: ='03_Inventario'!N8 | E8: =IF('03_Inventario'!J8="","",'03_Inventario'!J8) | F8: ='03_Inventario'!K8 | G8: ='03_Inventario'!L8 | H8: =IF(E8="","",E8-F8-G8) | I8: =IF(H8="","",MIN(C8*D8,MAX(0,D8-H8)*C8)) | J8: =IF(H8="","Sin precio",IF(H8<D8,"VNR","Costo"))
A9: B-011 | B9: Bomba centrífuga | C9: ='03_Inventario'!M9 | D9: ='03_Inventario'!N9 | E9: =IF('03_Inventario'!J9="","",'03_Inventario'!J9) | F9: ='03_Inventario'!K9 | G9: ='03_Inventario'!L9 | H9: =IF(E9="","",E9-F9-G9) | I9: =IF(H9="","",MIN(C9*D9,MAX(0,D9-H9)*C9)) | J9: =IF(H9="","Sin precio",IF(H9<D9,"VNR","Costo"))
A10: B-012 | B10: Válvula 2" | C10: ='03_Inventario'!M10 | D10: ='03_Inventario'!N10 | E10: =IF('03_Inventario'!J10="","",'03_Inventario'!J10) | F10: ='03_Inventario'!K10 | G10: ='03_Inventario'!L10 | H10: =IF(E10="","",E10-F10-G10) | I10: =IF(H10="","",MIN(C10*D10,MAX(0,D10-H10)*C10)) | J10: =IF(H10="","Sin precio",IF(H10<D10,"VNR","Costo"))
A11: C-100 | B11: Repuesto modelo descontinuado | C11: ='03_Inventario'!M11 | D11: ='03_Inventario'!N11 | E11: =IF('03_Inventario'!J11="","",'03_Inventario'!J11) | F11: ='03_Inventario'!K11 | G11: ='03_Inventario'!L11 | H11: =IF(E11="","",E11-F11-G11) | I11: =IF(H11="","",MIN(C11*D11,MAX(0,D11-H11)*C11)) | J11: =IF(H11="","Sin precio",IF(H11<D11,"VNR","Costo"))
A12: C-101 | B12: Producto terminado X | C12: ='03_Inventario'!M12 | D12: ='03_Inventario'!N12 | E12: =IF('03_Inventario'!J12="","",'03_Inventario'!J12) | F12: ='03_Inventario'!K12 | G12: ='03_Inventario'!L12 | H12: =IF(E12="","",E12-F12-G12) | I12: =IF(H12="","",MIN(C12*D12,MAX(0,D12-H12)*C12)) | J12: =IF(H12="","Sin precio",IF(H12<D12,"VNR","Costo"))
A13: C-102 | B13: Producto terminado Y | C13: ='03_Inventario'!M13 | D13: ='03_Inventario'!N13 | E13: =IF('03_Inventario'!J13="","",'03_Inventario'!J13) | F13: ='03_Inventario'!K13 | G13: ='03_Inventario'!L13 | H13: =IF(E13="","",E13-F13-G13) | I13: =IF(H13="","",MIN(C13*D13,MAX(0,D13-H13)*C13)) | J13: =IF(H13="","Sin precio",IF(H13<D13,"VNR","Costo"))
A14: D-200 | B14: Materia prima Z | C14: ='03_Inventario'!M14 | D14: ='03_Inventario'!N14 | E14: =IF('03_Inventario'!J14="","",'03_Inventario'!J14) | F14: ='03_Inventario'!K14 | G14: ='03_Inventario'!L14 | H14: =IF(E14="","",E14-F14-G14) | I14: =IF(H14="","",MIN(C14*D14,MAX(0,D14-H14)*C14)) | J14: =IF(H14="","Sin precio",IF(H14<D14,"VNR","Costo"))
A15: E-300 | B15: Lámina de acero | C15: ='03_Inventario'!M15 | D15: ='03_Inventario'!N15 | E15: =IF('03_Inventario'!J15="","",'03_Inventario'!J15) | F15: ='03_Inventario'!K15 | G15: ='03_Inventario'!L15 | H15: =IF(E15="","",E15-F15-G15) | I15: =IF(H15="","",MIN(C15*D15,MAX(0,D15-H15)*C15)) | J15: =IF(H15="","Sin precio",IF(H15<D15,"VNR","Costo"))
A16: E-301 | B16: Perfil de aluminio | C16: ='03_Inventario'!M16 | D16: ='03_Inventario'!N16 | E16: =IF('03_Inventario'!J16="","",'03_Inventario'!J16) | F16: ='03_Inventario'!K16 | G16: ='03_Inventario'!L16 | H16: =IF(E16="","",E16-F16-G16) | I16: =IF(H16="","",MIN(C16*D16,MAX(0,D16-H16)*C16)) | J16: =IF(H16="","Sin precio",IF(H16<D16,"VNR","Costo"))
A17: E-302 | B17: Resina industrial | C17: ='03_Inventario'!M17 | D17: ='03_Inventario'!N17 | E17: =IF('03_Inventario'!J17="","",'03_Inventario'!J17) | F17: ='03_Inventario'!K17 | G17: ='03_Inventario'!L17 | H17: =IF(E17="","",E17-F17-G17) | I17: =IF(H17="","",MIN(C17*D17,MAX(0,D17-H17)*C17)) | J17: =IF(H17="","Sin precio",IF(H17<D17,"VNR","Costo"))
A18: TOTAL | I18: =SUM(I5:I17)
A20: ⓘ Cómo se calcula esta hoja
A21: Columna | B21: Fórmula (Excel) | C21: Cómo se calcula (sencillo) | D21: Ejemplo con números reales | E21: De dónde viene | F21: Norma
A22: Cantidad auditada | B22: '='03_Inventario'!M5 | C22: Trae la cantidad auditada del ítem (contada o, si no se contó, la del kardex) desde la hoja 03. | D22: Fila 1: 1.000,00 → 1.000,00 | E22: hoja «Inventario valorado por ítem» | F22: —
A23: Costo unitario auditado | B23: '='03_Inventario'!N5 | C23: Trae el costo unitario auditado (soportado o, sin soporte, el del kardex) desde la hoja 03. | D23: Fila 1: 2,50 → 2,50 | E23: hoja «Inventario valorado por ítem» | F23: —
A24: Precio estimado de venta | B24: '=IF('03_Inventario'!J5="","",'03_Inventario'!J5) | C24: Trae el precio de venta unitario informado en la hoja 03 (Inventario valorado por ítem); si no se informó, queda en blanco. | D24: Fila 1: IF(4,00=""; ""; 4,00) → 4,00 | E24: hoja «Inventario valorado por ítem» | F24: —
A25: Costos de terminación | B25: '='03_Inventario'!K5 | C25: Trae los costos unitarios que faltan para terminar el producto, desde la hoja 03 (Inventario valorado por ítem). | D25: Fila 1: (vacío) → 0,00 | E25: hoja «Inventario valorado por ítem» | F25: —
A26: Costos de venta | B26: '='03_Inventario'!L5 | C26: Trae los costos unitarios necesarios para vender el producto, desde la hoja 03 (Inventario valorado por ítem). | D26: Fila 1: 0,30 → 0,30 | E26: hoja «Inventario valorado por ítem» | F26: —
A27: VNR unitario | B27: '=IF(E5="","",E5-F5-G5) | C27: Precio estimado de venta menos costos de terminación y de venta; en blanco si no hay precio de venta. | D27: Fila 1: IF(4,00=""; ""; 4,00-0,00-0,30) → 3,70 | E27: «Precio estimado de venta» (esta hoja), «Costos de terminación» (esta hoja), «Costos de venta» (esta hoja) | F27: —
A28: Rebaja a VNR | B28: '=IF(H5="","",MIN(C5*D5,MAX(0,D5-H5)*C5)) | C28: Si el VNR unitario es menor que el costo unitario auditado, multiplica la diferencia por la cantidad auditada, sin pasar del costo total del ítem; si no, es cero. En blanco si no hay precio. | D28: Fila 1: IF(3,70=""; ""; MIN(1.000,00*2,50; MAX(0; 2,50-3,70)*1.000,00)) → 0,00 | E28: «VNR unitario» (esta hoja), «Cantidad auditada» (esta hoja), «Costo unitario auditado» (esta hoja) | F28: —
A29: Medición | B29: '=IF(H5="","Sin precio",IF(H5<D5,"VNR","Costo")) | C29: Indica con qué valor queda el ítem: «VNR» si el VNR es menor que el costo, «Costo» si no lo es y «Sin precio» si no se informó precio de venta. | D29: Fila 1: IF(3,70=""; "Sin precio"; IF(3,70<2,50; "VNR"; "Costo")) → Costo | E29: «VNR unitario» (esta hoja), «Costo unitario auditado» (esta hoja) | F29: —

Sheet 10_Obsolescencia
A1: Obsolescencia y lenta rotación | H1: ⟵ Inicio | I1: ◀ Anterior | J1: Siguiente ▶
A2: Inventarios, producción y costo de ventas · Cliente de muestra S.A. · corte 2025-12-31
A4: Código | B4: Descripción | C4: Costo auditado | D4: Último movimiento | E4: Días sin movimiento | F4: % de provisión | G4: Provisión por obsolescencia | H4: Rebaja a VNR | I4: Provisión antes de la excepción (VNR; el tramo solo si no hay precio) | J4: Provisión estimada (neta de la excepción NIC 2.32)
A5: A-001 | B5: Tornillo 1/4 | C5: ='03_Inventario'!O5 | D5: 46001 | E5: =IF(D5="","",'02_Parametros'!$B$5-D5) | F5: =IF(E5="","",IF(E5>'02_Parametros'!$B$11,'02_Parametros'!$B$12/100,IF(E5>'02_Parametros'!$B$9,'02_Parametros'!$B$10/100,IF(E5>'02_Parametros'!$B$7,'02_Parametros'!$B$8/100,0)))) | G5: =IF(F5="","",C5*F5) | H5: =IF('09_VNR'!I5="","",'09_VNR'!I5) | I5: =IF(H5<>"",H5,G5) | J5: =IF('11_Excepcion_MP'!H5="Sí",0,IF(I5="","",I5))
A6: A-002 | B6: Tuerca 1/4 | C6: ='03_Inventario'!O6 | D6: 45991 | E6: =IF(D6="","",'02_Parametros'!$B$5-D6) | F6: =IF(E6="","",IF(E6>'02_Parametros'!$B$11,'02_Parametros'!$B$12/100,IF(E6>'02_Parametros'!$B$9,'02_Parametros'!$B$10/100,IF(E6>'02_Parametros'!$B$7,'02_Parametros'!$B$8/100,0)))) | G6: =IF(F6="","",C6*F6) | H6: =IF('09_VNR'!I6="","",'09_VNR'!I6) | I6: =IF(H6<>"",H6,G6) | J6: =IF('11_Excepcion_MP'!H6="Sí",0,IF(I6="","",I6))
A7: A-003 | B7: Arandela | C7: ='03_Inventario'!O7 | D7: 46011 | E7: =IF(D7="","",'02_Parametros'!$B$5-D7) | F7: =IF(E7="","",IF(E7>'02_Parametros'!$B$11,'02_Parametros'!$B$12/100,IF(E7>'02_Parametros'!$B$9,'02_Parametros'!$B$10/100,IF(E7>'02_Parametros'!$B$7,'02_Parametros'!$B$8/100,0)))) | G7: =IF(F7="","",C7*F7) | H7: =IF('09_VNR'!I7="","",'09_VNR'!I7) | I7: =IF(H7<>"",H7,G7) | J7: =IF('11_Excepcion_MP'!H7="Sí",0,IF(I7="","",I7))
A8: B-010 | B8: Motor 2 HP | C8: ='03_Inventario'!O8 | D8: 45945 | E8: =IF(D8="","",'02_Parametros'!$B$5-D8) | F8: =IF(E8="","",IF(E8>'02_Parametros'!$B$11,'02_Parametros'!$B$12/100,IF(E8>'02_Parametros'!$B$9,'02_Parametros'!$B$10/100,IF(E8>'02_Parametros'!$B$7,'02_Parametros'!$B$8/100,0)))) | G8: =IF(F8="","",C8*F8) | H8: =IF('09_VNR'!I8="","",'09_VNR'!I8) | I8: =IF(H8<>"",H8,G8) | J8: =IF('11_Excepcion_MP'!H8="Sí",0,IF(I8="","",I8))
A9: B-011 | B9: Bomba centrífuga | C9: ='03_Inventario'!O9 | D9: 45717 | E9: =IF(D9="","",'02_Parametros'!$B$5-D9) | F9: =IF(E9="","",IF(E9>'02_Parametros'!$B$11,'02_Parametros'!$B$12/100,IF(E9>'02_Parametros'!$B$9,'02_Parametros'!$B$10/100,IF(E9>'02_Parametros'!$B$7,'02_Parametros'!$B$8/100,0)))) | G9: =IF(F9="","",C9*F9) | H9: =IF('09_VNR'!I9="","",'09_VNR'!I9) | I9: =IF(H9<>"",H9,G9) | J9: =IF('11_Excepcion_MP'!H9="Sí",0,IF(I9="","",I9))
A10: B-012 | B10: Válvula 2" | C10: ='03_Inventario'!O10 | D10: 45473 | E10: =IF(D10="","",'02_Parametros'!$B$5-D10) | F10: =IF(E10="","",IF(E10>'02_Parametros'!$B$11,'02_Parametros'!$B$12/100,IF(E10>'02_Parametros'!$B$9,'02_Parametros'!$B$10/100,IF(E10>'02_Parametros'!$B$7,'02_Parametros'!$B$8/100,0)))) | G10: =IF(F10="","",C10*F10) | H10: =IF('09_VNR'!I10="","",'09_VNR'!I10) | I10: =IF(H10<>"",H10,G10) | J10: =IF('11_Excepcion_MP'!H10="Sí",0,IF(I10="","",I10))
A11: C-100 | B11: Repuesto modelo descontinuado | C11: ='03_Inventario'!O11 | D11: 45077 | E11: =IF(D11="","",'02_Parametros'!$B$5-D11) | F11: =IF(E11="","",IF(E11>'02_Parametros'!$B$11,'02_Parametros'!$B$12/100,IF(E11>'02_Parametros'!$B$9,'02_Parametros'!$B$10/100,IF(E11>'02_Parametros'!$B$7,'02_Parametros'!$B$8/100,0)))) | G11: =IF(F11="","",C11*F11) | H11: =IF('09_VNR'!I11="","",'09_VNR'!I11) | I11: =IF(H11<>"",H11,G11) | J11: =IF('11_Excepcion_MP'!H11="Sí",0,IF(I11="","",I11))
A12: C-101 | B12: Producto terminado X | C12: ='03_Inventario'!O12 | D12: 46019 | E12: =IF(D12="","",'02_Parametros'!$B$5-D12) | F12: =IF(E12="","",IF(E12>'02_Parametros'!$B$11,'02_Parametros'!$B$12/100,IF(E12>'02_Parametros'!$B$9,'02_Parametros'!$B$10/100,IF(E12>'02_Parametros'!$B$7,'02_Parametros'!$B$8/100,0)))) | G12: =IF(F12="","",C12*F12) | H12: =IF('09_VNR'!I12="","",'09_VNR'!I12) | I12: =IF(H12<>"",H12,G12) | J12: =IF('11_Excepcion_MP'!H12="Sí",0,IF(I12="","",I12))
A13: C-102 | B13: Producto terminado Y | C13: ='03_Inventario'!O13 | D13: 46006 | E13: =IF(D13="","",'02_Parametros'!$B$5-D13) | F13: =IF(E13="","",IF(E13>'02_Parametros'!$B$11,'02_Parametros'!$B$12/100,IF(E13>'02_Parametros'!$B$9,'02_Parametros'!$B$10/100,IF(E13>'02_Parametros'!$B$7,'02_Parametros'!$B$8/100,0)))) | G13: =IF(F13="","",C13*F13) | H13: =IF('09_VNR'!I13="","",'09_VNR'!I13) | I13: =IF(H13<>"",H13,G13) | J13: =IF('11_Excepcion_MP'!H13="Sí",0,IF(I13="","",I13))
A14: D-200 | B14: Materia prima Z | C14: ='03_Inventario'!O14 | D14: 45996 | E14: =IF(D14="","",'02_Parametros'!$B$5-D14) | F14: =IF(E14="","",IF(E14>'02_Parametros'!$B$11,'02_Parametros'!$B$12/100,IF(E14>'02_Parametros'!$B$9,'02_Parametros'!$B$10/100,IF(E14>'02_Parametros'!$B$7,'02_Parametros'!$B$8/100,0)))) | G14: =IF(F14="","",C14*F14) | H14: =IF('09_VNR'!I14="","",'09_VNR'!I14) | I14: =IF(H14<>"",H14,G14) | J14: =IF('11_Excepcion_MP'!H14="Sí",0,IF(I14="","",I14))
A15: E-300 | B15: Lámina de acero | C15: ='03_Inventario'!O15 | D15: 45981 | E15: =IF(D15="","",'02_Parametros'!$B$5-D15) | F15: =IF(E15="","",IF(E15>'02_Parametros'!$B$11,'02_Parametros'!$B$12/100,IF(E15>'02_Parametros'!$B$9,'02_Parametros'!$B$10/100,IF(E15>'02_Parametros'!$B$7,'02_Parametros'!$B$8/100,0)))) | G15: =IF(F15="","",C15*F15) | H15: =IF('09_VNR'!I15="","",'09_VNR'!I15) | I15: =IF(H15<>"",H15,G15) | J15: =IF('11_Excepcion_MP'!H15="Sí",0,IF(I15="","",I15))
A16: E-301 | B16: Perfil de aluminio | C16: ='03_Inventario'!O16 | D16: 45992 | E16: =IF(D16="","",'02_Parametros'!$B$5-D16) | F16: =IF(E16="","",IF(E16>'02_Parametros'!$B$11,'02_Parametros'!$B$12/100,IF(E16>'02_Parametros'!$B$9,'02_Parametros'!$B$10/100,IF(E16>'02_Parametros'!$B$7,'02_Parametros'!$B$8/100,0)))) | G16: =IF(F16="","",C16*F16) | H16: =IF('09_VNR'!I16="","",'09_VNR'!I16) | I16: =IF(H16<>"",H16,G16) | J16: =IF('11_Excepcion_MP'!H16="Sí",0,IF(I16="","",I16))
A17: E-302 | B17: Resina industrial | C17: ='03_Inventario'!O17 | D17: 45999 | E17: =IF(D17="","",'02_Parametros'!$B$5-D17) | F17: =IF(E17="","",IF(E17>'02_Parametros'!$B$11,'02_Parametros'!$B$12/100,IF(E17>'02_Parametros'!$B$9,'02_Parametros'!$B$10/100,IF(E17>'02_Parametros'!$B$7,'02_Parametros'!$B$8/100,0)))) | G17: =IF(F17="","",C17*F17) | H17: =IF('09_VNR'!I17="","",'09_VNR'!I17) | I17: =IF(H17<>"",H17,G17) | J17: =IF('11_Excepcion_MP'!H17="Sí",0,IF(I17="","",I17))
A18: TOTAL | C18: =SUM(C5:C17) | G18: =SUM(G5:G17) | H18: =SUM(H5:H17) | I18: =SUM(I5:I17) | J18: =SUM(J5:J17)
A20: ⓘ Cómo se calcula esta hoja
A21: Columna | B21: Fórmula (Excel) | C21: Cómo se calcula (sencillo) | D21: Ejemplo con números reales | E21: De dónde viene | F21: Norma
A22: Costo auditado | B22: '='03_Inventario'!O5 | C22: Trae el costo auditado del ítem (cantidad × costo unitario auditados) desde la hoja 03. | D22: Fila 1: 2.500,00 → 2.500,00 | E22: hoja «Inventario valorado por ítem» | F22: —
A23: Días sin movimiento | B23: '=IF(D5="","",'02_Parametros'!$B$5-D5) | C23: Resta la fecha del último movimiento de la fecha de corte de la hoja 02 (Parámetros); en blanco si no hay fecha de movimiento. | D23: Fila 1: IF(«2025-12-10»=""; ""; «2025-12-31»-«2025-12-10») → 21 | E23: «Último movimiento» (esta hoja), hoja «Parámetros» | F23: —
A24: % de provisión | B24: '=IF(E5="","",IF(E5>'02_Parametros'!$B$11,'02_Parametros'!$B$12/100,IF(E5>'02_Parametros'!$B$9,'02_Parametros'!$B$10/100,IF(E5>'02_Parametros'!$B$7,'02_Parametros'!$B$8/100,0)))) | C24: Busca en la hoja 02 (Parámetros) el tramo de días sin movimiento que supera el ítem y toma su porcentaje (el tramo más alto que alcanza); si no pasa del primer tramo, es 0 %. | D24: Fila 1: IF(21=""; ""; IF(21>730,00; 100,00/100; IF(21>365,00; 50,00/100; IF(21>180,00; 25,00/100; 0)))) → 0,00 % | E24: «Días sin movimiento» (esta hoja), hoja «Parámetros» | F24: —
A25: Provisión por obsolescencia | B25: '=IF(F5="","",C5*F5) | C25: Multiplica el costo auditado por el % de provisión del tramo; en blanco si no hay fecha de movimiento. | D25: Fila 1: IF(0,00 %=""; ""; 2.500,00*0,00 %) → 0,00 | E25: «% de provisión» (esta hoja), «Costo auditado» (esta hoja) | F25: —
A26: Rebaja a VNR | B26: '=IF('09_VNR'!I5="","",'09_VNR'!I5) | C26: Trae la rebaja a VNR del ítem desde la hoja 09 (Valor realizable neto); en blanco si el ítem no tiene precio de venta. | D26: Fila 1: IF(0,00=""; ""; 0,00) → 0,00 | E26: hoja «Valor realizable neto» | F26: —
A27: Provisión antes de la excepción (VNR; el tramo solo si no hay precio) | B27: '=IF(H5<>"",H5,G5) | C27: Si el ítem tiene precio de venta usa la rebaja a VNR; solo cuando no hay precio usa la provisión por obsolescencia del tramo como estimación. | D27: Fila 1: IF(0,00<>""; 0,00; 0,00) → 0,00 | E27: «Rebaja a VNR» (esta hoja), «Provisión por obsolescencia» (esta hoja) | F27: —
A28: Provisión estimada (neta de la excepción NIC 2.32) | B28: '=IF('11_Excepcion_MP'!H5="Sí",0,IF(I5="","",I5)) | C28: Toma la provisión antes de la excepción, salvo que la hoja 11 (Materias primas) diga que aplica la excepción de NIC 2.32: en ese caso pone cero. | D28: Fila 1: IF(«No»="Sí"; 0; IF(0,00=""; ""; 0,00)) → 0,00 | E28: «Provisión antes de la excepción (VNR; el tramo solo si no hay precio)» (esta hoja), hoja «Materias primas: excepción de NIC 2.32» | F28: —

Sheet 11_Excepcion_MP
A1: Materias primas: excepción de NIC 2.32 | H1: ⟵ Inicio | I1: ◀ Anterior | J1: Siguiente ▶
A2: Inventarios, producción y costo de ventas · Cliente de muestra S.A. · corte 2025-12-31
A4: Código | B4: Descripción | C4: ¿Materia prima? | D4: Producto terminado asociado | E4: Costo esperado del producto terminado | F4: Precio esperado del producto terminado | G4: Margen esperado | H4: ¿Aplica la excepción de NIC 2.32? | I4: Motivo | J4: Provisión antes de la excepción | K4: Efecto: provisión no reconocida
A5: A-001 | B5: Tornillo 1/4 | C5: =IF('03_Inventario'!P5="Sí","Sí","No") | D5: =IF('03_Inventario'!Q5="","",'03_Inventario'!Q5) | E5: =IF('03_Inventario'!R5="","",'03_Inventario'!R5) | F5: =IF('03_Inventario'!S5="","",'03_Inventario'!S5) | G5: =IF('03_Inventario'!T5="","",'03_Inventario'!T5) | H5: =IF(AND(C5="Sí",NOT(ISNUMBER(SEARCH("PYMES",'02_Parametros'!$B$6))),G5<>"",G5>=0),"Sí","No") | I5: =IF(C5<>"Sí","No es materia prima",IF(ISNUMBER(SEARCH("PYMES",'02_Parametros'!$B$6)),"La NIIF para las PYMES no recoge la excepción de la NIC 2.32: se mide al menor entre costo y precio de venta menos costos (27.2)",IF(G5="","Faltan el costo o el precio esperados del producto terminado",IF(G5>=0,"El producto terminado se vendería al costo o por encima (NIC 2.32)","Margen esperado negativo: el costo del producto terminado excedería su valor realizable neto (NIC 2.32)")))) | J5: =IF('10_Obsolescencia'!I5="","",'10_Obsolescencia'!I5) | K5: =IF(AND(H5="Sí",J5<>""),J5,0)
A6: A-002 | B6: Tuerca 1/4 | C6: =IF('03_Inventario'!P6="Sí","Sí","No") | D6: =IF('03_Inventario'!Q6="","",'03_Inventario'!Q6) | E6: =IF('03_Inventario'!R6="","",'03_Inventario'!R6) | F6: =IF('03_Inventario'!S6="","",'03_Inventario'!S6) | G6: =IF('03_Inventario'!T6="","",'03_Inventario'!T6) | H6: =IF(AND(C6="Sí",NOT(ISNUMBER(SEARCH("PYMES",'02_Parametros'!$B$6))),G6<>"",G6>=0),"Sí","No") | I6: =IF(C6<>"Sí","No es materia prima",IF(ISNUMBER(SEARCH("PYMES",'02_Parametros'!$B$6)),"La NIIF para las PYMES no recoge la excepción de la NIC 2.32: se mide al menor entre costo y precio de venta menos costos (27.2)",IF(G6="","Faltan el costo o el precio esperados del producto terminado",IF(G6>=0,"El producto terminado se vendería al costo o por encima (NIC 2.32)","Margen esperado negativo: el costo del producto terminado excedería su valor realizable neto (NIC 2.32)")))) | J6: =IF('10_Obsolescencia'!I6="","",'10_Obsolescencia'!I6) | K6: =IF(AND(H6="Sí",J6<>""),J6,0)
A7: A-003 | B7: Arandela | C7: =IF('03_Inventario'!P7="Sí","Sí","No") | D7: =IF('03_Inventario'!Q7="","",'03_Inventario'!Q7) | E7: =IF('03_Inventario'!R7="","",'03_Inventario'!R7) | F7: =IF('03_Inventario'!S7="","",'03_Inventario'!S7) | G7: =IF('03_Inventario'!T7="","",'03_Inventario'!T7) | H7: =IF(AND(C7="Sí",NOT(ISNUMBER(SEARCH("PYMES",'02_Parametros'!$B$6))),G7<>"",G7>=0),"Sí","No") | I7: =IF(C7<>"Sí","No es materia prima",IF(ISNUMBER(SEARCH("PYMES",'02_Parametros'!$B$6)),"La NIIF para las PYMES no recoge la excepción de la NIC 2.32: se mide al menor entre costo y precio de venta menos costos (27.2)",IF(G7="","Faltan el costo o el precio esperados del producto terminado",IF(G7>=0,"El producto terminado se vendería al costo o por encima (NIC 2.32)","Margen esperado negativo: el costo del producto terminado excedería su valor realizable neto (NIC 2.32)")))) | J7: =IF('10_Obsolescencia'!I7="","",'10_Obsolescencia'!I7) | K7: =IF(AND(H7="Sí",J7<>""),J7,0)
