Workbook

Sheet 00_Inicio
B2: AuditConsulting Auditores Cía. Ltda. · AUDIT-IA
B4: Beneficios sociales y nómina
B6: Cliente | C6: Cliente de muestra S.A. | D6: RUC | E6: 1790000000001
B7: Marco contable | C7: NIIF completas | D7: Fecha de corte | E7: 2025-12-31
B8: Preparó | C8: Ejercicio modelo | D8: Revisó | E8: Pendiente
B10: INDICADORES CLAVE
B11: Ajuste propuesto a pasivos laborales (+ aumenta el pasivo) | C11: Problemas encontrados
B12: 8536.47 | C12: 21
B15: IR A LA CÉDULA
B16: Carátula | C16: Programa | D16: Base técnica | E16: Resumen
B17: Parámetros | C17: Empleados (datos del cliente) | D17: Informe actuarial (datos del cliente) | E17: Tiempo de servicio
B18: Recálculo de nómina: bruto y neto | C18: Aportes IESS y planillas | D18: Décimo tercero | E18: Décimo cuarto
B19: Vacaciones | C19: Fondo de reserva | D19: Jubilación patronal y desahucio: DBO | E19: Costo post-empleo: resultados y ORI
B20: Censo actuarial y desahucio legal | C20: Conciliación nómina–mayor | D20: Ajustes propuestos | E20: Problemas encontrados
B21: Conclusión | C21: Control de revisión
B23: PANORAMA | N23: Datos de los gráficos (fórmulas a las cédulas)
N24: Cifras del resumen | O24: Importe (USD)
N25: ='01_Resumen'!A5 | O25: ='01_Resumen'!B5
N26: ='01_Resumen'!A6 | O26: ='01_Resumen'!B6
N27: ='01_Resumen'!A7 | O27: ='01_Resumen'!B7
N28: ='01_Resumen'!A8 | O28: ='01_Resumen'!B8
N29: ='01_Resumen'!A9 | O29: ='01_Resumen'!B9
N30: ='01_Resumen'!A10 | O30: ='01_Resumen'!B10
N31: ='01_Resumen'!A11 | O31: ='01_Resumen'!B11
N32: ='01_Resumen'!A12 | O32: ='01_Resumen'!B12
N33: ='01_Resumen'!A13 | O33: ='01_Resumen'!B13
N34: ='01_Resumen'!A14 | O34: ='01_Resumen'!B14
N35: ='01_Resumen'!A15 | O35: ='01_Resumen'!B15
N36: ='01_Resumen'!A16 | O36: ='01_Resumen'!B16
... N40: ='01_Resumen'!A20 | O40: ='01_Resumen'!B20
N42: Hallazgos de mayor impacto | O42: Importe (USD)
N43: Provision actuarial | O43: =SUMIFS('17_Problemas'!$C$5:$C$25,'17_Problemas'!$A$5:$A$25,"PROVISION_ACTUARIAL",'17_Problemas'!$C$5:$C$25,">0")-SUMIFS('17_Problemas'!$C$5:$C$25,'17_Problemas'!$A$5:$A$25,"PROVISION_ACTUARIAL",'17_Problemas'!$C$5:$C$25,"<0")
N44: Nuevas mediciones en resultados | O44: =SUMIFS('17_Problemas'!$C$5:$C$25,'17_Problemas'!$A$5:$A$25,"NUEVAS_MEDICIONES_EN_RESULTADOS",'17_Problemas'!$C$5:$C$25,">0")-SUMIFS('17_Problemas'!$C$5:$C$25,'17_Problemas'!$A$5:$A$25,"NUEVAS_MEDICIONES_EN_RESULTADOS",'17_Problemas'!$C$5:$C$25,"<0")
N45: Vacaciones diferencia | O45: =SUMIFS('17_Problemas'!$C$5:$C$25,'17_Problemas'!$A$5:$A$25,"VACACIONES_DIFERENCIA",'17_Problemas'!$C$5:$C$25,">0")-SUMIFS('17_Problemas'!$C$5:$C$25,'17_Problemas'!$A$5:$A$25,"VACACIONES_DIFERENCIA",'17_Problemas'!$C$5:$C$25,"<0")
N46: Fondo reserva no pagado (×2) | O46: =SUMIFS('17_Problemas'!$C$5:$C$25,'17_Problemas'!$A$5:$A$25,"FONDO_RESERVA_NO_PAGADO",'17_Problemas'!$C$5:$C$25,">0")-SUMIFS('17_Problemas'!$C$5:$C$25,'17_Problemas'!$A$5:$A$25,"FONDO_RESERVA_NO_PAGADO",'17_Problemas'!$C$5:$C$25,"<0")
N47: Vacaciones no provisionadas (×2) | O47: =SUMIFS('17_Problemas'!$C$5:$C$25,'17_Problemas'!$A$5:$A$25,"VACACIONES_NO_PROVISIONADAS",'17_Problemas'!$C$5:$C$25,">0")-SUMIFS('17_Problemas'!$C$5:$C$25,'17_Problemas'!$A$5:$A$25,"VACACIONES_NO_PROVISIONADAS",'17_Problemas'!$C$5:$C$25,"<0")
N48: Dbo rollforward | O48: =SUMIFS('17_Problemas'!$C$5:$C$25,'17_Problemas'!$A$5:$A$25,"DBO_ROLLFORWARD",'17_Problemas'!$C$5:$C$25,">0")-SUMIFS('17_Problemas'!$C$5:$C$25,'17_Problemas'!$A$5:$A$25,"DBO_ROLLFORWARD",'17_Problemas'!$C$5:$C$25,"<0")
N49: Recalculo nomina | O49: =SUMIFS('17_Problemas'!$C$5:$C$25,'17_Problemas'!$A$5:$A$25,"RECALCULO_NOMINA",'17_Problemas'!$C$5:$C$25,">0")-SUMIFS('17_Problemas'!$C$5:$C$25,'17_Problemas'!$A$5:$A$25,"RECALCULO_NOMINA",'17_Problemas'!$C$5:$C$25,"<0")
N50: Otros (7 tipos) | O50: =SUMIF('17_Problemas'!$C$5:$C$25,">0")-SUMIF('17_Problemas'!$C$5:$C$25,"<0")-((SUMIFS('17_Problemas'!$C$5:$C$25,'17_Problemas'!$A$5:$A$25,"PROVISION_ACTUARIAL",'17_Problemas'!$C$5:$C$25,">0")-SUMIFS('17_Problemas'!$C$5:$C$25,'17_Problemas'!$A$5:$A$25,"PROVISION_ACTUARIAL",'17_Problemas'!$C$5:$C$25,"<0"))+(SUMIFS('17_Problemas'!$C$5:$C$25,'17_Problemas'!$A$5:$A$25,"NUEVAS_MEDICIONES_EN_RESULTADOS",'17_Problemas'!$C$5:$C$25,">0")-SUMIFS('17_Problemas'!$C$5:$C$25,'17_Problemas'!$A$5:$A$25,"NUEVAS_MEDICIONES_EN_RESULTADOS",'17_Problemas'!$C$5:$C$25,"<0"))+(SUMIFS('17_Problemas'!$C$5:$C$25,'17_Problemas'!$A$5:$A$25,"VACACIONES_DIFERENCIA",'17_Problemas'!$C$5:$C$25,">0")-SUMIFS('17_Problemas'!$C$5:$C$25,'17_Problemas'!$A$5:$A$25,"VACACIONES_DIFERENCIA",'17_Problemas'!$C$5:$C$25,"<0"))+(SUMIFS('17_Problemas'!$C$5:$C$25,'17_Problemas'!$A$5:$A$25,"FONDO_RESERVA_NO_PAGADO",'17_Problemas'!$C$5:$C$25,">0")-SUMIFS('17_Problemas'!$C$5:$C$25,'17_Problemas'!$A$5:$A$25,"FONDO_RESERVA_NO_PAGADO",'17_Problemas'!$C$5:$C$25,"<0"))+(SUMIFS('17_Problemas'!$C$5:$C$25,'17_Problemas'!$A$5:$A$25,"VACACIONES_NO_PROVISIONADAS",'17_Problemas'!$C$5:$C$25,">0")-SUMIFS('17_Problemas'!$C$5:$C$25,'17_Problemas'!$A$5:$A$25,"VACACIONES_NO_PROVISIONADAS",'17_Problemas'!$C$5:$C$25,"<0"))+(SUMIFS('17_Problemas'!$C$5:$C$25,'17_Problemas'!$A$5:$A$25,"DBO_ROLLFORWARD",'17_Problemas'!$C$5:$C$25,">0")-SUMIFS('17_Problemas'!$C$5:$C$25,'17_Problemas'!$A$5:$A$25,"DBO_ROLLFORWARD",'17_Problemas'!$C$5:$C$25,"<0"))+(SUMIFS('17_Problemas'!$C$5:$C$25,'17_Problemas'!$A$5:$A$25,"RECALCULO_NOMINA",'17_Problemas'!$C$5:$C$25,">0")-SUMIFS('17_Problemas'!$C$5:$C$25,'17_Problemas'!$A$5:$A$25,"RECALCULO_NOMINA",'17_Problemas'!$C$5:$C$25,"<0")))

Sheet 00_Caratula
A1: Carátula | H1: ⟵ Inicio | J1: Siguiente ▶
A2: Beneficios sociales y nómina · Cliente de muestra S.A. · corte 2025-12-31
A4: Concepto | B4: Detalle
A5: Firma | B5: AuditConsulting Auditores Cía. Ltda.
A6: Cliente | B6: Cliente de muestra S.A.
A7: RUC | B7: 1790000000001
A8: Ejercicio | B8: 2025
A9: Fecha de corte | B9: 2025-12-31
A10: Marco contable | B10: NIIF completas
A11: Herramienta | B11: Beneficios sociales y nómina
A12: Rubro | B12: Nómina
A13: Motor | B13: nomina_beneficios 1.0
A14: Versión del papel | B14: v1
A15: Estado | B15: MUESTRA
... A17: Revisó | B17: Pendiente
A18: Aprobó
A19: Fecha de aprobación
A20: Huella de la ejecución (SHA-256)

Sheet 00_Programa
A1: Programa | H1: ⟵ Inicio | I1: ◀ Anterior | J1: Siguiente ▶
A2: Beneficios sociales y nómina · Cliente de muestra S.A. · corte 2025-12-31
A4: Código | B4: Objetivo | C4: Afirmación | D4: Procedimiento | E4: Evidencia | F4: Criterio | G4: Referencia
A5: PAY-01 | B5: Sumaria nómina–mayor–EEFF | C5: Integridad / Exactitud | D5: Conciliar remuneraciones, aportes, décimos, vacaciones, fondo de reserva y provisión actuarial con el mayor | E5: Nómina anual, mayor | F5: Diferencia dentro de tolerancia | G5: NIA 500 · NIA 330
A6: PAY-02 | B6: Recálculo de sueldos y neto | C6: Exactitud / Ocurrencia | D6: Recalcular bruto y neto por empleado con sueldo, días, horas extras y comisiones | E6: Roles de pago, contratos | F6: Registrada = recalculada | G6: NIC 19.11 · PYMES 28.3
A7: PAY-03 | B7: Horas extras | C7: Exactitud | D7: Recalcular con valor hora y recargos 50 %/100 % | E7: Marcaciones, autorizaciones | F7: Valor recalculado | G7: CT art. 55
A8: PAY-05 | B8: Aportes IESS | C8: Exactitud / Integridad | D8: Recalcular aportes personal y patronal (con IECE y SECAP) y cruzar la base con las planillas IESS | E8: Planillas y comprobantes IESS | F8: Registrado = recalculado; base planilla = nómina | G8: Ley de Seguridad Social · tabla oficial de tasas de aportación del IESS (9,45 % / 11,15 %)
A9: PAY-07 | B9: Décimo tercero y décimo cuarto | C9: Valoración / Integridad | D9: Recalcular la parte devengada al corte por empleado, período y región | E9: Nómina, formularios de pago de décimos | F9: Provisión = recalculada | G9: CT arts. 111 y 113 · NIC 19.9, 11 · PYMES 28.3–28.6
A10: PAY-09 | B10: Vacaciones | C10: Integridad / Valoración | D10: Recalcular el saldo de días y valorarlo con la remuneración diaria | E10: Registro de vacaciones | F10: Provisión = saldo × valor día | G10: CT art. 69 · NIC 19.13–16 · PYMES 28.6
A11: PAY-10 | B11: Fondo de reserva | C11: Integridad | D11: Recalcular el fondo debido desde el 13.º mes y compararlo con lo pagado o depositado | E11: Planillas IESS de fondos de reserva | F11: Pagado = debido | G11: CT art. 196
A12: PAY-13 | B12: Jubilación patronal y desahucio | C12: Valoración | D12: Comparar la provisión registrada con el DBO del informe por plan | E12: Informe actuarial | F12: Registrada = DBO | G12: NIC 19.57, 67 · PYMES 28.18 · CT arts. 185, 216
A13: PAY-15 | B13: Censo actuarial | C13: Integridad | D13: Cruzar los activos de la nómina con el censo del actuario | E13: Censo enviado al actuario | F13: Mismo número y empleados | G13: NIA 500 (experto de la dirección) · NIA 540
A14: PAY-16 | B14: DBO y movimiento del año | C14: Valoración | D14: Recalcular DBO final = inicial + servicio + intereses + pasados + nuevas mediciones − pagos | E14: Informe actuarial | F14: Recalculado = informe | G14: NIC 19.120, 140–141 · PYMES 28.41
A15: PAY-17 | B15: Supuestos actuariales | C15: Valoración | D15: Revisar tasa de descuento, incremento salarial, rotación y mortalidad | E15: Informe actuarial | F15: Supuestos sustentados | G15: NIC 19.75–98 · PYMES 28.17 (tasa) y 28.18 (supuestos actuariales) · NIA 540
A16: PAY-18 | B16: Resultados y ORI por marco | C16: Presentación | D16: Verificar el destino de las nuevas mediciones según el marco y la política | E16: Asientos del cierre | F16: Completas: ORI; PYMES: política 28.24 | G16: NIC 19.120 c, 127–130 · PYMES 28.24

Sheet 00_Fuentes
A1: Base técnica | H1: ⟵ Inicio | I1: ◀ Anterior | J1: Siguiente ▶
A2: Beneficios sociales y nómina · Cliente de muestra S.A. · corte 2025-12-31
A4: Categoría | B4: Documento | C4: Párrafos | D4: URL | E4: Verificada
A5: NIA · NIA 500 | B5: Exactitud e integridad del anexo de empleados contra roles, planillas IESS y mayor. | C5: párr. 9
A6: NIA · NIA 500 A23 (recálculo) · NIA 330 | B6: Recálculo sustantivo de la nómina y de las provisiones laborales. | C6: párr. 18
A7: NIA · NIA 540 (Revisada) | B7: Estimación actuarial: método, datos (censo) y supuestos. | C7: párr. 13, 18
A8: NIA · NIA 500 | B8: Uso del trabajo del actuario (experto de la dirección): competencia, objetividad, datos fuente. | C8: párr. 8 (experto de la dirección; NIA 620 solo si lo contrata el auditor)
A9: NIA · NIA 330 | B9: Procedimientos sustantivos sobre gasto y pasivos laborales materiales. | C9: párr. 18

Sheet 01_Resumen
A1: Resumen | H1: ⟵ Inicio | I1: ◀ Anterior | J1: Siguiente ▶
A2: Beneficios sociales y nómina · Cliente de muestra S.A. · corte 2025-12-31
A4: Concepto | B4: Importe
A5: Remuneraciones registradas en la nómina | B5: ='15_Conciliacion_GL'!B5
A6: Remuneraciones recalculadas | B6: ='15_Conciliacion_GL'!C5
A7: Diferencia registrada − recalculada | B7: ='15_Conciliacion_GL'!F5
A8: Diferencia nómina − mayor (remuneraciones) | B8: ='15_Conciliacion_GL'!E5
A9: Diferencia aporte personal IESS (registrado − recalculado) | B9: =SUM('07_IESS'!$G$5:$G$12)
A10: Aporte patronal IESS recalculado | B10: ='15_Conciliacion_GL'!C6
A11: Décimo tercero por pagar recalculado | B11: ='15_Conciliacion_GL'!C7
A12: Décimo cuarto por pagar recalculado | B12: ='15_Conciliacion_GL'!C8
A13: Provisión de vacaciones recalculada | B13: ='15_Conciliacion_GL'!C9
A14: Fondo de reserva debido en el ejercicio | B14: ='15_Conciliacion_GL'!C10
A15: Obligación post-empleo según informe actuarial | B15: ='15_Conciliacion_GL'!C11
A16: Provisión post-empleo registrada | B16: ='15_Conciliacion_GL'!B11
A17: Gasto post-empleo en resultados | B17: =SUM('13_Resultados_ORI'!$B$5:$B$6)
A18: Nuevas mediciones en ORI | B18: =SUM('13_Resultados_ORI'!$C$5:$C$6)
A19: Desahucio legal referencial de los activos (no es el DBO; base: última remuneración mensual = sueldo + promedio mensual de horas extras y comisiones, CT arts. 185 y 95) | B19: =SUM('14_Censo_actuarial'!$H$5:$H$11)
A20: Ajuste propuesto a pasivos laborales (+ aumenta el pasivo) | B20: ='16_Ajustes'!B11
A22: ⓘ Cómo se calcula esta hoja
A23: Columna | B23: Fórmula (Excel) | C23: Cómo se calcula (sencillo) | D23: Ejemplo con números reales | E23: De dónde viene | F23: Norma
A24: Importe | B24: '='15_Conciliacion_GL'!B5 | C24: Trae cada total de la hoja donde se calcula, concepto por concepto: remuneraciones, aportes, décimos, vacaciones, fondo de reserva y obligación actuarial salen de la hoja 15 (Conciliación nómina–mayor); la diferencia de aporte personal suma la hoja 07 (Aportes IESS), el gasto y el ORI suman la hoja 13, el desahucio referencial suma la hoja 14 y el ajuste es el total de la hoja 16 (Ajustes propuestos). | D24: Fila 1: 95.300,00 → 95.300,00 | E24: hoja «Conciliación nómina–mayor» | F24: —

Sheet 02_Parametros
A1: Parámetros | H1: ⟵ Inicio | I1: ◀ Anterior | J1: Siguiente ▶
A2: Beneficios sociales y nómina · Cliente de muestra S.A. · corte 2025-12-31
A4: Parámetro | B4: Valor | C4: Sustento
A5: Corte del ejercicio | B5: 46022 | C5: Ficha del encargo
A6: Inicio del ejercicio | B6: 45658 | C6: 1 de enero del año del corte
A7: Marco contable | B7: NIIF completas | C7: Enruta el destino de las nuevas mediciones actuariales
A8: Edición PYMES | C8: Sección 28: igual en 28.3–28.18 y 28.24; cambian 28.19 (2025 añade supuesto de terminación a la fecha y sin descuento) y 28.41 e) (conciliación por componentes)
A9: Nuevas mediciones van a | B9: ORI | C9: NIC 19.120 c y 127–130: ORI
A10: SBU (USD) | B10: 470 | C10: SBU 2025 = 470,00 (Acuerdo Ministerial MDT-2024-300, desde el 1-1-2025) y 2026 = 482,00 (MDT-2025-195, desde el 1-1-2026). Décimo cuarto, CT art. 113: 1/12 de la RBU por mes; pago acumulado hasta el 15-mar (Costa e Insular) o 15-ago (Sierra y Amazónica). La regla «se paga con el SBU vigente a la fecha de pago» es práctica ministerial, no consta en el art. 113 — confirmar que sigue vigente al corte
A11: SBU vigente a la fecha de pago del décimo cuarto (USD) | C11: Opcional. Si se informa, la provisión del décimo cuarto se mide con este SBU (NIC 19.11 · PYMES 28.5: importe sin descontar que se espera pagar); si se deja vacío se usa el SBU del corte y se emite un problema — confirmar que sigue vigente al corte
A12: SBU aplicado al décimo cuarto | B12: =IF('02_Parametros'!$B$11="",'02_Parametros'!$B$10,'02_Parametros'!$B$11) | C12: El de la fecha de pago si se informó; si no, el del corte
A13: Aporte personal IESS (%) | B13: 9.45 | C13: Tabla oficial de tasas de aportación del IESS: 9,45 % del sector privado — confirmar que sigue vigente al corte
A14: Aporte patronal IESS (%) | B14: 11.15 | C14: Tabla oficial de tasas de aportación del IESS: 11,15 % del sector privado — confirmar que sigue vigente al corte
A15: 0,5 % ex IECE (%) | B15: 0.5 | C15: COMF, disposición general décima primera: 1 % de las planillas del IESS (0,5 % IECE + 0,5 % SECAP) — confirmar que sigue vigente al corte
A16: SECAP (%) | B16: 0.5 | C16: COMF, disposición general décima primera: el 0,5 % del SECAP va a la Cuenta Única del Tesoro desde el 1-1-2015 — confirmar que sigue vigente al corte
A17: Fondo de reserva (%) | B17: 8.33 | C17: CT arts. 196 y 201; R.O. Suplemento 644 de 29-07-2009 — confirmar que sigue vigente al corte
A18: Días de vacaciones por año | B18: 15 | C18: CT art. 69 — confirmar que sigue vigente al corte
A19: Años para día adicional | B19: 5 | C19: CT art. 69 — confirmar que sigue vigente al corte
A20: Máximo días adicionales | B20: 15 | C20: CT art. 69 — confirmar que sigue vigente al corte
A21: Horas del mes (valor hora) | B21: 240 | C21: 240 = 8 h × 30 días (jornada CT art. 47; cifra expresa en CT art. 224 num. 5) — confirmar que sigue vigente al corte
A22: Recargo suplementarias (%) | B22: 50 | C22: CT art. 55 — confirmar que sigue vigente al corte
A23: Recargo extraordinarias (%) | B23: 100 | C23: CT art. 55 — confirmar que sigue vigente al corte
A24: Desahucio (% por año) | B24: 25 | C24: 25 % × última remuneración mensual × años (CT art. 185; remuneración según art. 95) — confirmar que sigue vigente al corte
A25: Región por defecto | B25: Sierra/Oriente | C25: Para empleados sin región
A26: Mes de inicio décimo tercero | B26: 12 | C26: CT art. 111: doceava parte de lo percibido en el año calendario; pago acumulado hasta el 24 de diciembre. El período dic–nov es práctica ministerial — confirmar que sigue vigente al corte
A27: Inicio del período décimo tercero | B27: 45992 | C27: Derivado del corte y del mes de inicio
A28: Mes de inicio décimo cuarto Sierra/Oriente | B28: 8 | C28: CT art. 113: pago acumulado hasta el 15 de agosto (Sierra y Amazónica); el período ago–jul es práctica ministerial — confirmar que sigue vigente al corte
A29: Inicio del período décimo cuarto Sierra/Oriente | B29: 45870 | C29: Derivado del corte y del mes de inicio
A30: Mes de inicio décimo cuarto Costa/Galápagos | B30: 3 | C30: CT art. 113: pago acumulado hasta el 15 de marzo (Costa e Insular); el período mar–feb es práctica ministerial — confirmar que sigue vigente al corte
A31: Inicio del período décimo cuarto Costa/Galápagos | B31: 45717 | C31: Derivado del corte y del mes de inicio
A32: PYMES: actuariales en | B32: ORI | C32: Política contable (Sección 28.24); en NIIF completas no aplica
A33: Tolerancia (importe) | B33: 1 | C33: Materialidad de ejecución
A34: Mayor: gasto de remuneraciones (sueldos, horas extras, comisiones) | B34: 95300 | C34: Mayor contable
A35: Mayor: gasto aporte patronal IESS | B35: 11578.96 | C35: Mayor contable
A36: Mayor: décimo tercero por pagar | B36: 600 | C36: Mayor contable
A37: Mayor: décimo cuarto por pagar | B37: 1566.66 | C37: Mayor contable
A38: Mayor: provisión de vacaciones | B38: 5286.34 | C38: Mayor contable
A39: Mayor: gasto fondo de reserva | C39: Mayor contable
A40: Mayor: provisión jubilación patronal y desahucio | C40: Mayor contable
A42: ⓘ Cómo se calcula esta hoja
...

Sheet 03_Empleados
A1: Empleados (datos del cliente) | H1: ⟵ Inicio | I1: ◀ Anterior | J1: Siguiente ▶
A2: Beneficios sociales y nómina · Cliente de muestra S.A. · corte 2025-12-31
A4: Cédula/código | B4: Nombre | C4: Ingreso | D4: Salida | E4: Región | F4: Sueldo mensual | G4: Horas 50 % | H4: Horas 100 % | I4: Horas extras registradas | J4: Comisiones y bonos | K4: Remuneración anual registrada | L4: Otras deducciones | M4: Neto pagado | N4: Base planillas IESS | O4: Aporte personal registrado | P4: Aporte patronal registrado | Q4: D13 mensualizado | R4: D14 mensualizado | S4: D13 provisionado | T4: D14 provisionado | U4: Saldo inicial días vacaciones | V4: Días gozados | W4: Vacaciones provisionadas | X4: Fondo de reserva pagado | Y4: En estudio actuarial
A5: E01 | B5: Ana Pérez | C5: 42064 | E5: Sierra/Oriente | F5: 1200 | G5: 20 | H5: 10 | I5: 250 | K5: 14650 | L5: 300 | M5: 12965.58 | N5: 14650 | O5: 1384.43 | P5: 1779.98 | Q5: No | R5: No | S5: 101.74 | T5: 195.83 | U5: 10 | V5: 15 | W5: 610.42 | X5: 1220.35 | Y5: Sí
A6: E02 | B6: Bruno Salazar | C6: 43997 | E6: Costa/Galápagos | F6: 800 | I6: 120 | J6: 600 | K6: 10320 | O6: 900 | P6: 1253.88 | Q6: No | R6: No | S6: 71.67 | T6: 195.83 | U6: 5 | V6: 15 | W6: 0 | X6: 859.66 | Y6: Sí
A7: E03 | B7: Carla Mora | C7: 45748 | E7: Sierra/Oriente | F7: 600 | K7: 5400 | O7: 510.3 | P7: 656.1 | Q7: No | R7: No | S7: 50 | T7: 195.83 | U7: 0 | V7: 0 | W7: 225 | X7: 0 | Y7: No
A8: E04 | B8: Diego Ruiz | C8: 43110 | D8: 45838 | E8: Sierra/Oriente | F8: 1000 | K8: 6000 | O8: 567 | P8: 729 | Q8: No | R8: No | S8: 0 | T8: 0 | W8: 0 | X8: 0
A9: E05 | B9: Elena Vásquez | C9: 40210 | E9: Sierra/Oriente | F9: 2000 | J9: 3000 | K9: 27000 | O9: 2551.5 | P9: 3280.5 | Q9: No | R9: Sí | S9: 150 | T9: 0 | U9: 30 | V9: 25 | W9: 2250 | X9: 2249.1 | Y9: Sí
A10: E06 | B10: Fabián Torres | C10: 44805 | E10: Costa/Galápagos | F10: 700 | G10: 16 | I10: 90 | K10: 8290 | L10: 100 | M10: 7400 | N10: 8490 | O10: 783.41 | P10: 1007.24 | Q10: Sí | R10: No | S10: 0 | T10: 391.67 | U10: 12 | V10: 10 | W10: 400.92 | X10: 707.22 | Y10: Sí
A11: E07 | B11: Gabriela León | C11: 45611 | E11: Sierra/Oriente | F11: 470 | K11: 5640 | O11: 532.98 | P11: 685.26 | Q11: No | R11: No | S11: 39.17 | T11: 195.83 | U11: 2 | V11: 0 | X11: 0 | Y11: Sí
A12: E08 | B12: Hugo Cedeño | C12: 41091 | E12: Costa/Galápagos | F12: 1500 | K12: 18000 | O12: 1701 | P12: 2187 | Q12: No | R12: No | S12: 125 | T12: 391.67 | U12: 40 | V12: 15 | W12: 1800 | X12: 1499.4 | Y12: Sí
A13: TOTAL | K13: =SUM(K5:K12)

Sheet 04_Actuarial
A1: Informe actuarial (datos del cliente) | H1: ⟵ Inicio | I1: ◀ Anterior | J1: Siguiente ▶
A2: Beneficios sociales y nómina · Cliente de muestra S.A. · corte 2025-12-31
A4: Plan | B4: Tipo | C4: DBO inicial | D4: Costo del servicio | E4: Costo por intereses | F4: Servicios pasados | G4: Nuevas mediciones | H4: Beneficios pagados | I4: DBO final (informe) | J4: Provisión registrada | K4: Nuevas mediciones registradas en | L4: Empleados en el estudio | M4: Tasa de descuento % | N4: Incremento salarial % | O4: Fecha del informe
A5: JUB | B5: Jubilación patronal | C5: 85000 | D5: 9500 | E5: 6800 | G5: 3200 | H5: 2500 | I5: 102000 | J5: 95000 | K5: Resultados | L5: 6 | M5: 7.5 | N5: 2.5 | O5: 46042
A6: DES | B6: Desahucio | C6: 30000 | D6: 4200 | E6: 2400 | G6: -1500 | H6: 3000 | I6: 32500 | J6: 32500 | K6: ORI | L6: 6 | N6: 2.5 | O6: 46042

Sheet 05_Tiempo_servicio
A1: Tiempo de servicio | H1: ⟵ Inicio | I1: ◀ Anterior | J1: Siguiente ▶
A2: Beneficios sociales y nómina · Cliente de muestra S.A. · corte 2025-12-31
A4: Cédula/código | B4: Desde (en el ejercicio) | C4: Hasta | D4: Días trabajados (30/360) | E4: Activo al corte | F4: Años de servicio | G4: Derecho a fondo de reserva desde (13.º mes) | H4: Días con derecho a fondo de reserva
A5: E01 | B5: 45658 | C5: 46022 | D5: =IF(MIN(IF('03_Empleados'!D5="",'02_Parametros'!$B$5,'03_Empleados'!D5),'02_Parametros'!$B$5)<MAX('03_Empleados'!C5,'02_Parametros'!$B$6),0,DAYS360(MAX('03_Empleados'!C5,'02_Parametros'!$B$6),MIN(IF('03_Empleados'!D5="",'02_Parametros'!$B$5,'03_Empleados'!D5),'02_Parametros'!$B$5)+1,TRUE)) | E5: =IF(AND('03_Empleados'!C5<='02_Parametros'!$B$5,OR('03_Empleados'!D5="",'03_Empleados'!D5>'02_Parametros'!$B$5)),"Sí","No") | F5: =IF(MIN(IF('03_Empleados'!D5="",'02_Parametros'!$B$5,'03_Empleados'!D5),'02_Parametros'!$B$5)<'03_Empleados'!C5,0,INT(DAYS360('03_Empleados'!C5,MIN(IF('03_Empleados'!D5="",'02_Parametros'!$B$5,'03_Empleados'!D5),'02_Parametros'!$B$5)+1,TRUE)/360)) | G5: 42430 | H5: =IF(MIN(IF('03_Empleados'!D5="",'02_Parametros'!$B$5,'03_Empleados'!D5),'02_Parametros'!$B$5)<MAX(EDATE('03_Empleados'!C5,12),'02_Parametros'!$B$6),0,DAYS360(MAX(EDATE('03_Empleados'!C5,12),'02_Parametros'!$B$6),MIN(IF('03_Empleados'!D5="",'02_Parametros'!$B$5,'03_Empleados'!D5),'02_Parametros'!$B$5)+1,TRUE))
A6: E02 | B6: 45658 | C6: 46022 | D6: =IF(MIN(IF('03_Empleados'!D6="",'02_Parametros'!$B$5,'03_Empleados'!D6),'02_Parametros'!$B$5)<MAX('03_Empleados'!C6,'02_Parametros'!$B$6),0,DAYS360(MAX('03_Empleados'!C6,'02_Parametros'!$B$6),MIN(IF('03_Empleados'!D6="",'02_Parametros'!$B$5,'03_Empleados'!D6),'02_Parametros'!$B$5)+1,TRUE)) | E6: =IF(AND('03_Empleados'!C6<='02_Parametros'!$B$5,OR('03_Empleados'!D6="",'03_Empleados'!D6>'02_Parametros'!$B$5)),"Sí","No") | F6: =IF(MIN(IF('03_Empleados'!D6="",'02_Parametros'!$B$5,'03_Empleados'!D6),'02_Parametros'!$B$5)<'03_Empleados'!C6,0,INT(DAYS360('03_Empleados'!C6,MIN(IF('03_Empleados'!D6="",'02_Parametros'!$B$5,'03_Empleados'!D6),'02_Parametros'!$B$5)+1,TRUE)/360)) | G6: 44362 | H6: =IF(MIN(IF('03_Empleados'!D6="",'02_Parametros'!$B$5,'03_Empleados'!D6),'02_Parametros'!$B$5)<MAX(EDATE('03_Empleados'!C6,12),'02_Parametros'!$B$6),0,DAYS360(MAX(EDATE('03_Empleados'!C6,12),'02_Parametros'!$B$6),MIN(IF('03_Empleados'!D6="",'02_Parametros'!$B$5,'03_Empleados'!D6),'02_Parametros'!$B$5)+1,TRUE))
A7: E03 | B7: 45748 | C7: 46022 | D7: =IF(MIN(IF('03_Empleados'!D7="",'02_Parametros'!$B$5,'03_Empleados'!D7),'02_Parametros'!$B$5)<MAX('03_Empleados'!C7,'02_Parametros'!$B$6),0,DAYS360(MAX('03_Empleados'!C7,'02_Parametros'!$B$6),MIN(IF('03_Empleados'!D7="",'02_Parametros'!$B$5,'03_Empleados'!D7),'02_Parametros'!$B$5)+1,TRUE)) | E7: =IF(AND('03_Empleados'!C7<='02_Parametros'!$B$5,OR('03_Empleados'!D7="",'03_Empleados'!D7>'02_Parametros'!$B$5)),"Sí","No") | F7: =IF(MIN(IF('03_Empleados'!D7="",'02_Parametros'!$B$5,'03_Empleados'!D7),'02_Parametros'!$B$5)<'03_Empleados'!C7,0,INT(DAYS360('03_Empleados'!C7,MIN(IF('03_Empleados'!D7="",'02_Parametros'!$B$5,'03_Empleados'!D7),'02_Parametros'!$B$5)+1,TRUE)/360)) | G7: 46113 | H7: =IF(MIN(IF('03_Empleados'!D7="",'02_Parametros'!$B$5,'03_Empleados'!D7),'02_Parametros'!$B$5)<MAX(EDATE('03_Empleados'!C7,12),'02_Parametros'!$B$6),0,DAYS360(MAX(EDATE('03_Empleados'!C7,12),'02_Parametros'!$B$6),MIN(IF('03_Empleados'!D7="",'02_Parametros'!$B$5,'03_Empleados'!D7),'02_Parametros'!$B$5)+1,TRUE))
A8: E04 | B8: 45658 | C8: 45838 | D8: =IF(MIN(IF('03_Empleados'!D8="",'02_Parametros'!$B$5,'03_Empleados'!D8),'02_Parametros'!$B$5)<MAX('03_Empleados'!C8,'02_Parametros'!$B$6),0,DAYS360(MAX('03_Empleados'!C8,'02_Parametros'!$B$6),MIN(IF('03_Empleados'!D8="",'02_Parametros'!$B$5,'03_Empleados'!D8),'02_Parametros'!$B$5)+1,TRUE)) | E8: =IF(AND('03_Empleados'!C8<='02_Parametros'!$B$5,OR('03_Empleados'!D8="",'03_Empleados'!D8>'02_Parametros'!$B$5)),"Sí","No") | F8: =IF(MIN(IF('03_Empleados'!D8="",'02_Parametros'!$B$5,'03_Empleados'!D8),'02_Parametros'!$B$5)<'03_Empleados'!C8,0,INT(DAYS360('03_Empleados'!C8,MIN(IF('03_Empleados'!D8="",'02_Parametros'!$B$5,'03_Empleados'!D8),'02_Parametros'!$B$5)+1,TRUE)/360)) | G8: 43475 | H8: =IF(MIN(IF('03_Empleados'!D8="",'02_Parametros'!$B$5,'03_Empleados'!D8),'02_Parametros'!$B$5)<MAX(EDATE('03_Empleados'!C8,12),'02_Parametros'!$B$6),0,DAYS360(MAX(EDATE('03_Empleados'!C8,12),'02_Parametros'!$B$6),MIN(IF('03_Empleados'!D8="",'02_Parametros'!$B$5,'03_Empleados'!D8),'02_Parametros'!$B$5)+1,TRUE))
A9: E05 | B9: 45658 | C9: 46022 | D9: =IF(MIN(IF('03_Empleados'!D9="",'02_Parametros'!$B$5,'03_Empleados'!D9),'02_Parametros'!$B$5)<MAX('03_Empleados'!C9,'02_Parametros'!$B$6),0,DAYS360(MAX('03_Empleados'!C9,'02_Parametros'!$B$6),MIN(IF('03_Empleados'!D9="",'02_Parametros'!$B$5,'03_Empleados'!D9),'02_Parametros'!$B$5)+1,TRUE)) | E9: =IF(AND('03_Empleados'!C9<='02_Parametros'!$B$5,OR('03_Empleados'!D9="",'03_Empleados'!D9>'02_Parametros'!$B$5)),"Sí","No") | F9: =IF(MIN(IF('03_Empleados'!D9="",'02_Parametros'!$B$5,'03_Empleados'!D9),'02_Parametros'!$B$5)<'03_Empleados'!C9,0,INT(DAYS360('03_Empleados'!C9,MIN(IF('03_Empleados'!D9="",'02_Parametros'!$B$5,'03_Empleados'!D9),'02_Parametros'!$B$5)+1,TRUE)/360)) | G9: 40575 | H9: =IF(MIN(IF('03_Empleados'!D9="",'02_Parametros'!$B$5,'03_Empleados'!D9),'02_Parametros'!$B$5)<MAX(EDATE('03_Empleados'!C9,12),'02_Parametros'!$B$6),0,DAYS360(MAX(EDATE('03_Empleados'!C9,12),'02_Parametros'!$B$6),MIN(IF('03_Empleados'!D9="",'02_Parametros'!$B$5,'03_Empleados'!D9),'02_Parametros'!$B$5)+1,TRUE))
A10: E06 | B10: 45658 | C10: 46022 | D10: =IF(MIN(IF('03_Empleados'!D10="",'02_Parametros'!$B$5,'03_Empleados'!D10),'02_Parametros'!$B$5)<MAX('03_Empleados'!C10,'02_Parametros'!$B$6),0,DAYS360(MAX('03_Empleados'!C10,'02_Parametros'!$B$6),MIN(IF('03_Empleados'!D10="",'02_Parametros'!$B$5,'03_Empleados'!D10),'02_Parametros'!$B$5)+1,TRUE)) | E10: =IF(AND('03_Empleados'!C10<='02_Parametros'!$B$5,OR('03_Empleados'!D10="",'03_Empleados'!D10>'02_Parametros'!$B$5)),"Sí","No") | F10: =IF(MIN(IF('03_Empleados'!D10="",'02_Parametros'!$B$5,'03_Empleados'!D10),'02_Parametros'!$B$5)<'03_Empleados'!C10,0,INT(DAYS360('03_Empleados'!C10,MIN(IF('03_Empleados'!D10="",'02_Parametros'!$B$5,'03_Empleados'!D10),'02_Parametros'!$B$5)+1,TRUE)/360)) | G10: 45170 | H10: =IF(MIN(IF('03_Empleados'!D10="",'02_Parametros'!$B$5,'03_Empleados'!D10),'02_Parametros'!$B$5)<MAX(EDATE('03_Empleados'!C10,12),'02_Parametros'!$B$6),0,DAYS360(MAX(EDATE('03_Empleados'!C10,12),'02_Parametros'!$B$6),MIN(IF('03_Empleados'!D10="",'02_Parametros'!$B$5,'03_Empleados'!D10),'02_Parametros'!$B$5)+1,TRUE))
A11: E07 | B11: 45658 | C11: 46022 | D11: =IF(MIN(IF('03_Empleados'!D11="",'02_Parametros'!$B$5,'03_Empleados'!D11),'02_Parametros'!$B$5)<MAX('03_Empleados'!C11,'02_Parametros'!$B$6),0,DAYS360(MAX('03_Empleados'!C11,'02_Parametros'!$B$6),MIN(IF('03_Empleados'!D11="",'02_Parametros'!$B$5,'03_Empleados'!D11),'02_Parametros'!$B$5)+1,TRUE)) | E11: =IF(AND('03_Empleados'!C11<='02_Parametros'!$B$5,OR('03_Empleados'!D11="",'03_Empleados'!D11>'02_Parametros'!$B$5)),"Sí","No") | F11: =IF(MIN(IF('03_Empleados'!D11="",'02_Parametros'!$B$5,'03_Empleados'!D11),'02_Parametros'!$B$5)<'03_Empleados'!C11,0,INT(DAYS360('03_Empleados'!C11,MIN(IF('03_Empleados'!D11="",'02_Parametros'!$B$5,'03_Empleados'!D11),'02_Parametros'!$B$5)+1,TRUE)/360)) | G11: 45976 | H11: =IF(MIN(IF('03_Empleados'!D11="",'02_Parametros'!$B$5,'03_Empleados'!D11),'02_Parametros'!$B$5)<MAX(EDATE('03_Empleados'!C11,12),'02_Parametros'!$B$6),0,DAYS360(MAX(EDATE('03_Empleados'!C11,12),'02_Parametros'!$B$6),MIN(IF('03_Empleados'!D11="",'02_Parametros'!$B$5,'03_Empleados'!D11),'02_Parametros'!$B$5)+1,TRUE))
A12: E08 | B12: 45658 | C12: 46022 | D12: =IF(MIN(IF('03_Empleados'!D12="",'02_Parametros'!$B$5,'03_Empleados'!D12),'02_Parametros'!$B$5)<MAX('03_Empleados'!C12,'02_Parametros'!$B$6),0,DAYS360(MAX('03_Empleados'!C12,'02_Parametros'!$B$6),MIN(IF('03_Empleados'!D12="",'02_Parametros'!$B$5,'03_Empleados'!D12),'02_Parametros'!$B$5)+1,TRUE)) | E12: =IF(AND('03_Empleados'!C12<='02_Parametros'!$B$5,OR('03_Empleados'!D12="",'03_Empleados'!D12>'02_Parametros'!$B$5)),"Sí","No") | F12: =IF(MIN(IF('03_Empleados'!D12="",'02_Parametros'!$B$5,'03_Empleados'!D12),'02_Parametros'!$B$5)<'03_Empleados'!C12,0,INT(DAYS360('03_Empleados'!C12,MIN(IF('03_Empleados'!D12="",'02_Parametros'!$B$5,'03_Empleados'!D12),'02_Parametros'!$B$5)+1,TRUE)/360)) | G12: 41456 | H12: =IF(MIN(IF('03_Empleados'!D12="",'02_Parametros'!$B$5,'03_Empleados'!D12),'02_Parametros'!$B$5)<MAX(EDATE('03_Empleados'!C12,12),'02_Parametros'!$B$6),0,DAYS360(MAX(EDATE('03_Empleados'!C12,12),'02_Parametros'!$B$6),MIN(IF('03_Empleados'!D12="",'02_Parametros'!$B$5,'03_Empleados'!D12),'02_Parametros'!$B$5)+1,TRUE))
A14: ⓘ Cómo se calcula esta hoja
A15: Columna | B15: Fórmula (Excel) | C15: Cómo se calcula (sencillo) | D15: Ejemplo con números reales | E15: De dónde viene | F15: Norma
A16: Días trabajados (30/360) | B16: '=IF(MIN(IF('03_Empleados'!D5="",'02_Parametros'!$B$5,'03_Empleados'!D5),'02_Parametros'!$B$5)<MAX('03_Empleados'!C5,'02_Parametros'!$B$6),0,DAYS360(MAX('03_Empleados'!C5,'02_Parametros'!$B$6),MIN(IF('03_Empleados'!D5="",'02_Parametros'!$B$5,'03_Empleados'!D5),'02_Parametros'!$B$5)+1,TRUE)) | C16: Cuenta los días trabajados en el ejercicio en base comercial 30/360: desde la fecha de ingreso (hoja 03, Empleados) o el 1 de enero si ingresó antes, hasta la fecha de salida o el corte (hoja 02, Parámetros), lo que ocurra primero. Si no trabajó en el año, da cero. | D16: Fila 1: IF(MIN(IF((vacío)=""; «2025-12-31»; (vacío)); «2025-12-31»)<MAX(«2015-03-01»; «2025-01-01»); 0; D(vacío)(MAX(«2015-03-01»; «2025-01-01»); MIN(IF((vacío)=""; «2025-12-31»; (vacío)); «2025-12-31»)+1; TRUE)) → 360 | E16: hoja «Empleados (datos del cliente)», hoja «Parámetros» | F16: —
A17: Activo al corte | B17: '=IF(AND('03_Empleados'!C5<='02_Parametros'!$B$5,OR('03_Empleados'!D5="",'03_Empleados'!D5>'02_Parametros'!$B$5)),"Sí","No") | C17: Marca «Sí» cuando el empleado ya había ingresado al corte y no tiene fecha de salida o salió después del corte (fechas de la hoja 03, Empleados); en otro caso marca «No». | D17: Fila 1: IF(AND(«2015-03-01»<=«2025-12-31»; OR((vacío)=""; (vacío)>«2025-12-31»)); "Sí"; "No") → Sí | E17: hoja «Empleados (datos del cliente)», hoja «Parámetros» | F17: —
A18: Años de servicio | B18: '=IF(MIN(IF('03_Empleados'!D5="",'02_Parametros'!$B$5,'03_Empleados'!D5),'02_Parametros'!$B$5)<'03_Empleados'!C5,0,INT(DAYS360('03_Empleados'!C5,MIN(IF('03_Empleados'!D5="",'02_Parametros'!$B$5,'03_Empleados'!D5),'02_Parametros'!$B$5)+1,TRUE)/360)) | C18: Cuenta los años completos de servicio en base 30/360, desde la fecha de ingreso (hoja 03) hasta la fecha de salida o el corte (hoja 02), lo que ocurra primero; las fracciones de año no se cuentan. | D18: Fila 1: IF(MIN(IF((vacío)=""; «2025-12-31»; (vacío)); «2025-12-31»)<«2015-03-01»; 0; INT(D(vacío)(«2015-03-01»; MIN(IF((vacío)=""; «2025-12-31»; (vacío)); «2025-12-31»)+1; TRUE)/360)) → 10 | E18: hoja «Empleados (datos del cliente)», hoja «Parámetros» | F18: —
A19: Días con derecho a fondo de reserva | B19: '=IF(MIN(IF('03_Empleados'!D5="",'02_Parametros'!$B$5,'03_Empleados'!D5),'02_Parametros'!$B$5)<MAX(EDATE('03_Empleados'!C5,12),'02_Parametros'!$B$6),0,DAYS360(MAX(EDATE('03_Empleados'!C5,12),'02_Parametros'!$B$6),MIN(IF('03_Empleados'!D5="",'02_Parametros'!$B$5,'03_Empleados'!D5),'02_Parametros'!$B$5)+1,TRUE)) | C19: Cuenta los días del ejercicio, en base 30/360, desde que el empleado cumplió su 13.º mes (ingreso de la hoja 03 más 12 meses) o desde el 1 de enero si ya lo había cumplido, hasta la salida o el corte; cero si todavía no llega al 13.º mes. | D19: Fila 1: IF(MIN(IF((vacío)=""; «2025-12-31»; (vacío)); «2025-12-31»)<MAX(EDATE(«2015-03-01»; 12); «2025-01-01»); 0; D(vacío)(MAX(EDATE(«2015-03-01»; 12); «2025-01-01»); MIN(IF((vacío)=""; «2025-12-31»; (vacío)); «2025-12-31»)+1; TRUE)) → 360 | E19: hoja «Empleados (datos del cliente)», hoja «Parámetros» | F19: —

Sheet 06_Recalculo_nomina
A1: Recálculo de nómina: bruto y neto | H1: ⟵ Inicio | I1: ◀ Anterior | J1: Siguiente ▶
A2: Beneficios sociales y nómina · Cliente de muestra S.A. · corte 2025-12-31
A4: Cédula/código | B4: Sueldo mensual | C4: Días | D4: Sueldo del período | E4: Valor hora | F4: Horas 50 % | G4: Horas 100 % | H4: Horas extras recalculadas | I4: Horas extras registradas | J4: Dif. horas extras | K4: Comisiones y bonos | L4: Bruto recalculado | M4: Remuneración registrada | N4: Registrada − recalculada | O4: Aporte personal s/ bruto | P4: Otras deducciones | Q4: Neto recalculado | R4: Neto pagado | S4: Dif. neto
A5: E01 | B5: ='03_Empleados'!F5 | C5: ='05_Tiempo_servicio'!D5 | D5: =B5*C5/30 | E5: =B5/'02_Parametros'!$B$21 | F5: =IF('03_Empleados'!G5="","",'03_Empleados'!G5) | G5: =IF('03_Empleados'!H5="","",'03_Empleados'!H5) | H5: =IF(AND(F5="",G5=""),"",E5*(IF(F5="",0,F5)*(1+'02_Parametros'!$B$22/100)+IF(G5="",0,G5)*(1+'02_Parametros'!$B$23/100))) | I5: =IF('03_Empleados'!I5="",0,'03_Empleados'!I5) | J5: =IF(H5="","",I5-H5) | K5: =IF('03_Empleados'!J5="",0,'03_Empleados'!J5) | L5: =D5+I5+K5 | M5: ='03_Empleados'!K5 | N5: =M5-L5 | O5: =L5*'02_Parametros'!$B$13/100 | P5: =IF('03_Empleados'!L5="",0,'03_Empleados'!L5) | Q5: =L5-O5-P5 | R5: =IF('03_Empleados'!M5="","",'03_Empleados'!M5) | S5: =IF(R5="","",R5-Q5)
A6: E02 | B6: ='03_Empleados'!F6 | C6: ='05_Tiempo_servicio'!D6 | D6: =B6*C6/30 | E6: =B6/'02_Parametros'!$B$21 | F6: =IF('03_Empleados'!G6="","",'03_Empleados'!G6) | G6: =IF('03_Empleados'!H6="","",'03_Empleados'!H6) | H6: =IF(AND(F6="",G6=""),"",E6*(IF(F6="",0,F6)*(1+'02_Parametros'!$B$22/100)+IF(G6="",0,G6)*(1+'02_Parametros'!$B$23/100))) | I6: =IF('03_Empleados'!I6="",0,'03_Empleados'!I6) | J6: =IF(H6="","",I6-H6) | K6: =IF('03_Empleados'!J6="",0,'03_Empleados'!J6) | L6: =D6+I6+K6 | M6: ='03_Empleados'!K6 | N6: =M6-L6 | O6: =L6*'02_Parametros'!$B$13/100 | P6: =IF('03_Empleados'!L6="",0,'03_Empleados'!L6) | Q6: =L6-O6-P6 | R6: =IF('03_Empleados'!M6="","",'03_Empleados'!M6) | S6: =IF(R6="","",R6-Q6)
A7: E03 | B7: ='03_Empleados'!F7 | C7: ='05_Tiempo_servicio'!D7 | D7: =B7*C7/30 | E7: =B7/'02_Parametros'!$B$21 | F7: =IF('03_Empleados'!G7="","",'03_Empleados'!G7) | G7: =IF('03_Empleados'!H7="","",'03_Empleados'!H7) | H7: =IF(AND(F7="",G7=""),"",E7*(IF(F7="",0,F7)*(1+'02_Parametros'!$B$22/100)+IF(G7="",0,G7)*(1+'02_Parametros'!$B$23/100))) | I7: =IF('03_Empleados'!I7="",0,'03_Empleados'!I7) | J7: =IF(H7="","",I7-H7) | K7: =IF('03_Empleados'!J7="",0,'03_Empleados'!J7) | L7: =D7+I7+K7 | M7: ='03_Empleados'!K7 | N7: =M7-L7 | O7: =L7*'02_Parametros'!$B$13/100 | P7: =IF('03_Empleados'!L7="",0,'03_Empleados'!L7) | Q7: =L7-O7-P7 | R7: =IF('03_Empleados'!M7="","",'03_Empleados'!M7) | S7: =IF(R7="","",R7-Q7)
A8: E04 | B8: ='03_Empleados'!F8 | C8: ='05_Tiempo_servicio'!D8 | D8: =B8*C8/30 | E8: =B8/'02_Parametros'!$B$21 | F8: =IF('03_Empleados'!G8="","",'03_Empleados'!G8) | G8: =IF('03_Empleados'!H8="","",'03_Empleados'!H8) | H8: =IF(AND(F8="",G8=""),"",E8*(IF(F8="",0,F8)*(1+'02_Parametros'!$B$22/100)+IF(G8="",0,G8)*(1+'02_Parametros'!$B$23/100))) | I8: =IF('03_Empleados'!I8="",0,'03_Empleados'!I8) | J8: =IF(H8="","",I8-H8) | K8: =IF('03_Empleados'!J8="",0,'03_Empleados'!J8) | L8: =D8+I8+K8 | M8: ='03_Empleados'!K8 | N8: =M8-L8 | O8: =L8*'02_Parametros'!$B$13/100 | P8: =IF('03_Empleados'!L8="",0,'03_Empleados'!L8) | Q8: =L8-O8-P8 | R8: =IF('03_Empleados'!M8="","",'03_Empleados'!M8) | S8: =IF(R8="","",R8-Q8)
A9: E05 | B9: ='03_Empleados'!F9 | C9: ='05_Tiempo_servicio'!D9 | D9: =B9*C9/30 | E9: =B9/'02_Parametros'!$B$21 | F9: =IF('03_Empleados'!G9="","",'03_Empleados'!G9) | G9: =IF('03_Empleados'!H9="","",'03_Empleados'!H9) | H9: =IF(AND(F9="",G9=""),"",E9*(IF(F9="",0,F9)*(1+'02_Parametros'!$B$22/100)+IF(G9="",0,G9)*(1+'02_Parametros'!$B$23/100))) | I9: =IF('03_Empleados'!I9="",0,'03_Empleados'!I9) | J9: =IF(H9="","",I9-H9) | K9: =IF('03_Empleados'!J9="",0,'03_Empleados'!J9) | L9: =D9+I9+K9 | M9: ='03_Empleados'!K9 | N9: =M9-L9 | O9: =L9*'02_Parametros'!$B$13/100 | P9: =IF('03_Empleados'!L9="",0,'03_Empleados'!L9) | Q9: =L9-O9-P9 | R9: =IF('03_Empleados'!M9="","",'03_Empleados'!M9) | S9: =IF(R9="","",R9-Q9)
A10: E06 | B10: ='03_Empleados'!F10 | C10: ='05_Tiempo_servicio'!D10 | D10: =B10*C10/30 | E10: =B10/'02_Parametros'!$B$21 | F10: =IF('03_Empleados'!G10="","",'03_Empleados'!G10) | G10: =IF('03_Empleados'!H10="","",'03_Empleados'!H10) | H10: =IF(AND(F10="",G10=""),"",E10*(IF(F10="",0,F10)*(1+'02_Parametros'!$B$22/100)+IF(G10="",0,G10)*(1+'02_Parametros'!$B$23/100))) | I10: =IF('03_Empleados'!I10="",0,'03_Empleados'!I10) | J10: =IF(H10="","",I10-H10) | K10: =IF('03_Empleados'!J10="",0,'03_Empleados'!J10) | L10: =D10+I10+K10 | M10: ='03_Empleados'!K10 | N10: =M10-L10 | O10: =L10*'02_Parametros'!$B$13/100 | P10: =IF('03_Empleados'!L10="",0,'03_Empleados'!L10) | Q10: =L10-O10-P10 | R10: =IF('03_Empleados'!M10="","",'03_Empleados'!M10) | S10: =IF(R10="","",R10-Q10)
A11: E07 | B11: ='03_Empleados'!F11 | C11: ='05_Tiempo_servicio'!D11 | D11: =B11*C11/30 | E11: =B11/'02_Parametros'!$B$21 | F11: =IF('03_Empleados'!G11="","",'03_Empleados'!G11) | G11: =IF('03_Empleados'!H11="","",'03_Empleados'!H11) | H11: =IF(AND(F11="",G11=""),"",E11*(IF(F11="",0,F11)*(1+'02_Parametros'!$B$22/100)+IF(G11="",0,G11)*(1+'02_Parametros'!$B$23/100))) | I11: =IF('03_Empleados'!I11="",0,'03_Empleados'!I11) | J11: =IF(H11="","",I11-H11) | K11: =IF('03_Empleados'!J11="",0,'03_Empleados'!J11) | L11: =D11+I11+K11 | M11: ='03_Empleados'!K11 | N11: =M11-L11 | O11: =L11*'02_Parametros'!$B$13/100 | P11: =IF('03_Empleados'!L11="",0,'03_Empleados'!L11) | Q11: =L11-O11-P11 | R11: =IF('03_Empleados'!M11="","",'03_Empleados'!M11) | S11: =IF(R11="","",R11-Q11)
A12: E08 | B12: ='03_Empleados'!F12 | C12: ='05_Tiempo_servicio'!D12 | D12: =B12*C12/30 | E12: =B12/'02_Parametros'!$B$21 | F12: =IF('03_Empleados'!G12="","",'03_Empleados'!G12) | G12: =IF('03_Empleados'!H12="","",'03_Empleados'!H12) | H12: =IF(AND(F12="",G12=""),"",E12*(IF(F12="",0,F12)*(1+'02_Parametros'!$B$22/100)+IF(G12="",0,G12)*(1+'02_Parametros'!$B$23/100))) | I12: =IF('03_Empleados'!I12="",0,'03_Empleados'!I12) | J12: =IF(H12="","",I12-H12) | K12: =IF('03_Empleados'!J12="",0,'03_Empleados'!J12) | L12: =D12+I12+K12 | M12: ='03_Empleados'!K12 | N12: =M12-L12 | O12: =L12*'02_Parametros'!$B$13/100 | P12: =IF('03_Empleados'!L12="",0,'03_Empleados'!L12) | Q12: =L12-O12-P12 | R12: =IF('03_Empleados'!M12="","",'03_Empleados'!M12) | S12: =IF(R12="","",R12-Q12)
A13: TOTAL | L13: =SUM(L5:L12) | M13: =SUM(M5:M12) | N13: =SUM(N5:N12)
A15: ⓘ Cómo se calcula esta hoja
A16: Columna | B16: Fórmula (Excel) | C16: Cómo se calcula (sencillo) | D16: Ejemplo con números reales | E16: De dónde viene | F16: Norma
A17: Sueldo mensual | B17: '='03_Empleados'!F5 | C17: Trae el sueldo mensual del empleado tal como lo informó el cliente en la hoja 03 (Empleados). | D17: Fila 1: 1.200,00 → 1.200,00 | E17: hoja «Empleados (datos del cliente)» | F17: —
A18: Días | B18: '='05_Tiempo_servicio'!D5 | C18: Trae los días trabajados en el ejercicio (base 30/360) calculados en la hoja 05 (Tiempo de servicio). | D18: Fila 1: 360 → 360 | E18: hoja «Tiempo de servicio» | F18: —
A19: Sueldo del período | B19: '=B5*C5/30 | C19: Multiplica el sueldo mensual por los días trabajados y divide para 30: es el sueldo que corresponde al tiempo trabajado en el año. | D19: Fila 1: 1.200,00*360/30 → 14.400,00 | E19: «Sueldo mensual» (esta hoja), «Días» (esta hoja) | F19: —
A20: Valor hora | B20: '=B5/'02_Parametros'!$B$21 | C20: Divide el sueldo mensual para las horas del mes de la hoja 02 (Parámetros), normalmente 240, para obtener el valor de una hora ordinaria. | D20: Fila 1: 1.200,00/240,00 → 5,00 | E20: «Sueldo mensual» (esta hoja), hoja «Parámetros» | F20: —
A21: Horas 50 % | B21: '=IF('03_Empleados'!G5="","",'03_Empleados'!G5) | C21: Trae las horas suplementarias del año informadas en la hoja 03 (Empleados); queda en blanco si el cliente no las informó. | D21: Fila 1: IF(20,00=""; ""; 20,00) → 20,00 | E21: hoja «Empleados (datos del cliente)» | F21: —
A22: Horas 100 % | B22: '=IF('03_Empleados'!H5="","",'03_Empleados'!H5) | C22: Trae las horas extraordinarias del año informadas en la hoja 03 (Empleados); queda en blanco si el cliente no las informó. | D22: Fila 1: IF(10,00=""; ""; 10,00) → 10,00 | E22: hoja «Empleados (datos del cliente)» | F22: —
A23: Horas extras recalculadas | B23: '=IF(AND(F5="",G5=""),"",E5*(IF(F5="",0,F5)*(1+'02_Parametros'!$B$22/100)+IF(G5="",0,G5)*(1+'02_Parametros'!$B$23/100))) | C23: Valora las horas del año con el valor hora: las suplementarias con su recargo y las extraordinarias con el suyo (recargos de la hoja 02). Si no se informó ninguna hora, queda en blanco. | D23: Fila 1: IF(AND(20,00=""; 10,00=""); ""; 5,00*(IF(20,00=""; 0; 20,00)*(1+50,00/100)+IF(10,00=""; 0; 10,00)*(1+100,00/100))) → 250,00 | E23: «Horas 50 %» (esta hoja), «Horas 100 %» (esta hoja), «Valor hora» (esta hoja), hoja «Parámetros» | F23: —
A24: Horas extras registradas | B24: '=IF('03_Empleados'!I5="",0,'03_Empleados'!I5) | C24: Trae el valor de horas extras que registró el cliente en la hoja 03 (Empleados); si lo dejó vacío se toma cero. | D24: Fila 1: IF(250,00=""; 0; 250,00) → 250,00 | E24: hoja «Empleados (datos del cliente)» | F24: —
A25: Dif. horas extras | B25: '=IF(H5="","",I5-H5) | C25: Resta las horas extras recalculadas del valor registrado por el cliente; queda en blanco cuando no hubo horas para recalcular. | D25: Fila 1: IF(250,00=""; ""; 250,00-250,00) → 0,00 | E25: «Horas extras recalculadas» (esta hoja), «Horas extras registradas» (esta hoja) | F25: —
A26: Comisiones y bonos | B26: '=IF('03_Empleados'!J5="",0,'03_Empleados'!J5) | C26: Trae las comisiones y bonos del año de la hoja 03 (Empleados); si están vacíos se toma cero. | D26: Fila 1: IF((vacío)=""; 0; (vacío)) → 0,00 | E26: hoja «Empleados (datos del cliente)» | F26: —
A27: Bruto recalculado | B27: '=D5+I5+K5 | C27: Suma el sueldo del período, las horas extras REGISTRADAS por el cliente (no las recalculadas) y las comisiones y bonos: es la remuneración bruta del año según el auditor. | D27: Fila 1: 14.400,00+250,00+0,00 → 14.650,00 | E27: «Sueldo del período» (esta hoja), «Horas extras registradas» (esta hoja), «Comisiones y bonos» (esta hoja) | F27: —
... A34: Dif. neto | B34: '=IF(R5="","",R5-Q5) | C34: Resta el neto recalculado del neto pagado por el cliente; queda en blanco cuando el neto pagado no fue informado. | D34: Fila 1: IF(12.965,58=""; ""; 12.965,58-12.965,58) → 0,00 | E34: «Neto pagado» (esta hoja), «Neto recalculado» (esta hoja) | F34: —

Sheet 07_IESS
A1: Aportes IESS y planillas | H1: ⟵ Inicio | I1: ◀ Anterior | J1: Siguiente ▶
A2: Beneficios sociales y nómina · Cliente de muestra S.A. · corte 2025-12-31
A4: Cédula/código | B4: Base (remuneración registrada) | C4: Base planillas IESS | D4: Dif. planilla − nómina | E4: Aporte personal recalculado | F4: Aporte personal registrado | G4: Dif. personal | H4: Tasa patronal total | I4: Aporte patronal recalculado | J4: Aporte patronal registrado | K4: Dif. patronal
A5: E01 | B5: ='03_Empleados'!K5 | C5: =IF('03_Empleados'!N5="","",'03_Empleados'!N5) | D5: =IF(C5="","",C5-B5) | E5: =B5*'02_Parametros'!$B$13/100 | F5: =IF('03_Empleados'!O5="","",'03_Empleados'!O5) | G5: =IF(F5="","",F5-E5) | H5: =('02_Parametros'!$B$14+'02_Parametros'!$B$15+'02_Parametros'!$B$16)/100 | I5: =B5*H5 | J5: =IF('03_Empleados'!P5="","",'03_Empleados'!P5) | K5: =IF(J5="","",J5-I5)
A6: E02 | B6: ='03_Empleados'!K6 | C6: =IF('03_Empleados'!N6="","",'03_Empleados'!N6) | D6: =IF(C6="","",C6-B6) | E6: =B6*'02_Parametros'!$B$13/100 | F6: =IF('03_Empleados'!O6="","",'03_Empleados'!O6) | G6: =IF(F6="","",F6-E6) | H6: =('02_Parametros'!$B$14+'02_Parametros'!$B$15+'02_Parametros'!$B$16)/100 | I6: =B6*H6 | J6: =IF('03_Empleados'!P6="","",'03_Empleados'!P6) | K6: =IF(J6="","",J6-I6)
A7: E03 | B7: ='03_Empleados'!K7 | C7: =IF('03_Empleados'!N7="","",'03_Empleados'!N7) | D7: =IF(C7="","",C7-B7) | E7: =B7*'02_Parametros'!$B$13/100 | F7: =IF('03_Empleados'!O7="","",'03_Empleados'!O7) | G7: =IF(F7="","",F7-E7) | H7: =('02_Parametros'!$B$14+'02_Parametros'!$B$15+'02_Parametros'!$B$16)/100 | I7: =B7*H7 | J7: =IF('03_Empleados'!P7="","",'03_Empleados'!P7) | K7: =IF(J7="","",J7-I7)
A8: E04 | B8: ='03_Empleados'!K8 | C8: =IF('03_Empleados'!N8="","",'03_Empleados'!N8) | D8: =IF(C8="","",C8-B8) | E8: =B8*'02_Parametros'!$B$13/100 | F8: =IF('03_Empleados'!O8="","",'03_Empleados'!O8) | G8: =IF(F8="","",F8-E8) | H8: =('02_Parametros'!$B$14+'02_Parametros'!$B$15+'02_Parametros'!$B$16)/100 | I8: =B8*H8 | J8: =IF('03_Empleados'!P8="","",'03_Empleados'!P8) | K8: =IF(J8="","",J8-I8)
A9: E05 | B9: ='03_Empleados'!K9 | C9: =IF('03_Empleados'!N9="","",'03_Empleados'!N9) | D9: =IF(C9="","",C9-B9) | E9: =B9*'02_Parametros'!$B$13/100 | F9: =IF('03_Empleados'!O9="","",'03_Empleados'!O9) | G9: =IF(F9="","",F9-E9) | H9: =('02_Parametros'!$B$14+'02_Parametros'!$B$15+'02_Parametros'!$B$16)/100 | I9: =B9*H9 | J9: =IF('03_Empleados'!P9="","",'03_Empleados'!P9) | K9: =IF(J9="","",J9-I9)
A10: E06 | B10: ='03_Empleados'!K10 | C10: =IF('03_Empleados'!N10="","",'03_Empleados'!N10) | D10: =IF(C10="","",C10-B10) | E10: =B10*'02_Parametros'!$B$13/100 | F10: =IF('03_Empleados'!O10="","",'03_Empleados'!O10) | G10: =IF(F10="","",F10-E10) | H10: =('02_Parametros'!$B$14+'02_Parametros'!$B$15+'02_Parametros'!$B$16)/100 | I10: =B10*H10 | J10: =IF('03_Empleados'!P10="","",'03_Empleados'!P10) | K10: =IF(J10="","",J10-I10)
A11: E07 | B11: ='03_Empleados'!K11 | C11: =IF('03_Empleados'!N11="","",'03_Empleados'!N11) | D11: =IF(C11="","",C11-B11) | E11: =B11*'02_Parametros'!$B$13/100 | F11: =IF('03_Empleados'!O11="","",'03_Empleados'!O11) | G11: =IF(F11="","",F11-E11) | H11: =('02_Parametros'!$B$14+'02_Parametros'!$B$15+'02_Parametros'!$B$16)/100 | I11: =B11*H11 | J11: =IF('03_Empleados'!P11="","",'03_Empleados'!P11) | K11: =IF(J11="","",J11-I11)
A12: E08 | B12: ='03_Empleados'!K12 | C12: =IF('03_Empleados'!N12="","",'03_Empleados'!N12) | D12: =IF(C12="","",C12-B12) | E12: =B12*'02_Parametros'!$B$13/100 | F12: =IF('03_Empleados'!O12="","",'03_Empleados'!O12) | G12: =IF(F12="","",F12-E12) | H12: =('02_Parametros'!$B$14+'02_Parametros'!$B$15+'02_Parametros'!$B$16)/100 | I12: =B12*H12 | J12: =IF('03_Empleados'!P12="","",'03_Empleados'!P12) | K12: =IF(J12="","",J12-I12)
A13: TOTAL | E13: =SUM(E5:E12) | G13: =SUM(G5:G12) | I13: =SUM(I5:I12) | K13: =SUM(K5:K12)
A15: ⓘ Cómo se calcula esta hoja
A16: Columna | B16: Fórmula (Excel) | C16: Cómo se calcula (sencillo) | D16: Ejemplo con números reales | E16: De dónde viene | F16: Norma
A17: Base (remuneración registrada) | B17: '='03_Empleados'!K5 | C17: Trae la remuneración anual registrada del empleado de la hoja 03 (Empleados); es la base sobre la que se recalculan los aportes. | D17: Fila 1: 14.650,00 → 14.650,00 | E17: hoja «Empleados (datos del cliente)» | F17: —
A18: Base planillas IESS | B18: '=IF('03_Empleados'!N5="","",'03_Empleados'!N5) | C18: Trae la base de aportación que figura en las planillas del IESS (hoja 03); queda en blanco si no se informó. | D18: Fila 1: IF(14.650,00=""; ""; 14.650,00) → 14.650,00 | E18: hoja «Empleados (datos del cliente)» | F18: —
A19: Dif. planilla − nómina | B19: '=IF(C5="","",C5-B5) | C19: Resta la remuneración de la nómina de la base declarada en las planillas del IESS; queda en blanco si falta la base de planillas. | D19: Fila 1: IF(14.650,00=""; ""; 14.650,00-14.650,00) → 0,00 | E19: «Base planillas IESS» (esta hoja), «Base (remuneración registrada)» (esta hoja) | F19: —
A20: Aporte personal recalculado | B20: '=B5*'02_Parametros'!$B$13/100 | C20: Multiplica la base (remuneración registrada) por el porcentaje de aporte personal de la hoja 02 (Parámetros). | D20: Fila 1: 14.650,00*9,45/100 → 1.384,42 | E20: «Base (remuneración registrada)» (esta hoja), hoja «Parámetros» | F20: —
A21: Aporte personal registrado | B21: '=IF('03_Empleados'!O5="","",'03_Empleados'!O5) | C21: Trae el aporte personal al IESS que registró el cliente en la hoja 03; queda en blanco si no lo informó. | D21: Fila 1: IF(1.384,43=""; ""; 1.384,43) → 1.384,43 | E21: hoja «Empleados (datos del cliente)» | F21: —
A22: Dif. personal | B22: '=IF(F5="","",F5-E5) | C22: Resta el aporte personal recalculado del registrado por el cliente; queda en blanco si el cliente no informó su aporte. | D22: Fila 1: IF(1.384,43=""; ""; 1.384,43-1.384,42) → 0,01 | E22: «Aporte personal registrado» (esta hoja), «Aporte personal recalculado» (esta hoja) | F22: —
A23: Tasa patronal total | B23: '=('02_Parametros'!$B$14+'02_Parametros'!$B$15+'02_Parametros'!$B$16)/100 | C23: Suma los porcentajes de aporte patronal, ex IECE y SECAP de la hoja 02 (Parámetros) y los expresa como tasa única. | D23: Fila 1: (11,15+0,50+0,50)/100 → 12,15 % | E23: hoja «Parámetros» | F23: —
A24: Aporte patronal recalculado | B24: '=B5*H5 | C24: Multiplica la base (remuneración registrada) por la tasa patronal total de esta hoja. | D24: Fila 1: 14.650,00*12,15 % → 1.779,97 | E24: «Base (remuneración registrada)» (esta hoja), «Tasa patronal total» (esta hoja) | F24: —
A25: Aporte patronal registrado | B25: '=IF('03_Empleados'!P5="","",'03_Empleados'!P5) | C25: Trae el aporte patronal (con IECE y SECAP) que registró el cliente en la hoja 03; queda en blanco si no se informó. | D25: Fila 1: IF(1.779,98=""; ""; 1.779,98) → 1.779,98 | E25: hoja «Empleados (datos del cliente)» | F25: —
A26: Dif. patronal | B26: '=IF(J5="","",J5-I5) | C26: Resta el aporte patronal recalculado del registrado por el cliente; queda en blanco si el cliente no informó su aporte patronal. | D26: Fila 1: IF(1.779,98=""; ""; 1.779,98-1.779,97) → 0,01 | E26: «Aporte patronal registrado» (esta hoja), «Aporte patronal recalculado» (esta hoja) | F26: —

Sheet 08_Decimo_tercero
A1: Décimo tercero | H1: ⟵ Inicio | I1: ◀ Anterior | J1: Siguiente ▶
A2: Beneficios sociales y nómina · Cliente de muestra S.A. · corte 2025-12-31
A4: Cédula/código | B4: Activo | C4: Mensualizado | D4: Días del período al corte | E4: Remuneración diaria | F4: Provisión recalculada (1/12) | G4: Provisionado | H4: Provisionado − recalculado
A5: E01 | B5: ='05_Tiempo_servicio'!E5 | C5: No | D5: =IF(OR(B5="No",C5="Sí"),0,DAYS360(MAX('03_Empleados'!C5,'02_Parametros'!$B$27),'02_Parametros'!$B$5+1,TRUE)) | E5: =IF('05_Tiempo_servicio'!D5=0,0,'06_Recalculo_nomina'!L5/'05_Tiempo_servicio'!D5) | F5: =E5*D5/12 | G5: =IF('03_Empleados'!S5="","",'03_Empleados'!S5) | H5: =IF(G5="","",G5-F5)
A6: E02 | B6: ='05_Tiempo_servicio'!E6 | C6: No | D6: =IF(OR(B6="No",C6="Sí"),0,DAYS360(MAX('03_Empleados'!C6,'02_Parametros'!$B$27),'02_Parametros'!$B$5+1,TRUE)) | E6: =IF('05_Tiempo_servicio'!D6=0,0,'06_Recalculo_nomina'!L6/'05_Tiempo_servicio'!D6) | F6: =E6*D6/12 | G6: =IF('03_Empleados'!S6="","",'03_Empleados'!S6) | H6: =IF(G6="","",G6-F6)
A7: E03 | B7: ='05_Tiempo_servicio'!E7 | C7: No | D7: =IF(OR(B7="No",C7="Sí"),0,DAYS360(MAX('03_Empleados'!C7,'02_Parametros'!$B$27),'02_Parametros'!$B$5+1,TRUE)) | E7: =IF('05_Tiempo_servicio'!D7=0,0,'06_Recalculo_nomina'!L7/'05_Tiempo_servicio'!D7) | F7: =E7*D7/12 | G7: =IF('03_Empleados'!S7="","",'03_Empleados'!S7) | H7: =IF(G7="","",G7-F7)
A8: E04 | B8: ='05_Tiempo_servicio'!E8 | C8: No | D8: =IF(OR(B8="No",C8="Sí"),0,DAYS360(MAX('03_Empleados'!C8,'02_Parametros'!$B$27),'02_Parametros'!$B$5+1,TRUE)) | E8: =IF('05_Tiempo_servicio'!D8=0,0,'06_Recalculo_nomina'!L8/'05_Tiempo_servicio'!D8) | F8: =E8*D8/12 | G8: =IF('03_Empleados'!S8="","",'03_Empleados'!S8) | H8: =IF(G8="","",G8-F8)
A9: E05 | B9: ='05_Tiempo_servicio'!E9 | C9: No | D9: =IF(OR(B9="No",C9="Sí"),0,DAYS360(MAX('03_Empleados'!C9,'02_Parametros'!$B$27),'02_Parametros'!$B$5+1,TRUE)) | E9: =IF('05_Tiempo_servicio'!D9=0,0,'06_Recalculo_nomina'!L9/'05_Tiempo_servicio'!D9) | F9: =E9*D9/12 | G9: =IF('03_Empleados'!S9="","",'03_Empleados'!S9) | H9: =IF(G9="","",G9-F9)
A10: E06 | B10: ='05_Tiempo_servicio'!E10 | C10: Sí | D10: =IF(OR(B10="No",C10="Sí"),0,DAYS360(MAX('03_Empleados'!C10,'02_Parametros'!$B$27),'02_Parametros'!$B$5+1,TRUE)) | E10: =IF('05_Tiempo_servicio'!D10=0,0,'06_Recalculo_nomina'!L10/'05_Tiempo_servicio'!D10) | F10: =E10*D10/12 | G10: =IF('03_Empleados'!S10="","",'03_Empleados'!S10) | H10: =IF(G10="","",G10-F10)
A11: E07 | B11: ='05_Tiempo_servicio'!E11 | C11: No | D11: =IF(OR(B11="No",C11="Sí"),0,DAYS360(MAX('03_Empleados'!C11,'02_Parametros'!$B$27),'02_Parametros'!$B$5+1,TRUE)) | E11: =IF('05_Tiempo_servicio'!D11=0,0,'06_Recalculo_nomina'!L11/'05_Tiempo_servicio'!D11) | F11: =E11*D11/12 | G11: =IF('03_Empleados'!S11="","",'03_Empleados'!S11) | H11: =IF(G11="","",G11-F11)
A12: E08 | B12: ='05_Tiempo_servicio'!E12 | C12: No | D12: =IF(OR(B12="No",C12="Sí"),0,DAYS360(MAX('03_Empleados'!C12,'02_Parametros'!$B$27),'02_Parametros'!$B$5+1,TRUE)) | E12: =IF('05_Tiempo_servicio'!D12=0,0,'06_Recalculo_nomina'!L12/'05_Tiempo_servicio'!D12) | F12: =E12*D12/12 | G12: =IF('03_Empleados'!S12="","",'03_Empleados'!S12) | H12: =IF(G12="","",G12-F12)
A13: TOTAL | F13: =SUM(F5:F12) | H13: =SUM(H5:H12)
A15: ⓘ Cómo se calcula esta hoja
A16: Columna | B16: Fórmula (Excel) | C16: Cómo se calcula (sencillo) | D16: Ejemplo con números reales | E16: De dónde viene | F16: Norma
A17: Activo | B17: '='05_Tiempo_servicio'!E5 | C17: Trae si el empleado está activo al corte, según la hoja 05 (Tiempo de servicio). | D17: Fila 1: «Sí» → Sí | E17: hoja «Tiempo de servicio» | F17: —
A18: Días del período al corte | B18: '=IF(OR(B5="No",C5="Sí"),0,DAYS360(MAX('03_Empleados'!C5,'02_Parametros'!$B$27),'02_Parametros'!$B$5+1,TRUE)) | C18: Cuenta los días, en base 30/360, desde el inicio del período del décimo tercero (hoja 02) o desde el ingreso si fue posterior, hasta el corte. Da cero si el empleado ya no está activo o si cobra el décimo mensualizado. | D18: Fila 1: IF(OR(«Sí»="No"; «No»="Sí"); 0; D(vacío)(MAX(«2015-03-01»; «2025-12-01»); «2025-12-31»+1; TRUE)) → 30 | E18: «Activo» (esta hoja), «Mensualizado» (esta hoja), hoja «Empleados (datos del cliente)», hoja «Parámetros» | F18: —
A19: Remuneración diaria | B19: '=IF('05_Tiempo_servicio'!D5=0,0,'06_Recalculo_nomina'!L5/'05_Tiempo_servicio'!D5) | C19: Divide el bruto recalculado de la hoja 06 (Recálculo de nómina) para los días trabajados de la hoja 05; cero si no trabajó días en el año. | D19: Fila 1: IF(360=0; 0; 14.650,00/360) → 40,69 | E19: hoja «Tiempo de servicio», hoja «Recálculo de nómina: bruto y neto» | F19: —
A20: Provisión recalculada (1/12) | B20: '=E5*D5/12 | C20: Multiplica la remuneración diaria por los días del período al corte y divide para 12: es la doceava parte de lo ganado en el período, lo que debería estar provisionado. | D20: Fila 1: 40,69*30/12 → 101,74 | E20: «Remuneración diaria» (esta hoja), «Días del período al corte» (esta hoja) | F20: —
A21: Provisionado | B21: '=IF('03_Empleados'!S5="","",'03_Empleados'!S5) | C21: Trae el décimo tercero que el cliente tiene provisionado al corte (hoja 03); queda en blanco si no lo informó. | D21: Fila 1: IF(101,74=""; ""; 101,74) → 101,74 | E21: hoja «Empleados (datos del cliente)» | F21: —
A22: Provisionado − recalculado | B22: '=IF(G5="","",G5-F5) | C22: Resta la provisión recalculada de la provisionada por el cliente: negativa significa que falta provisión; queda en blanco si no hay dato del cliente. | D22: Fila 1: IF(101,74=""; ""; 101,74-101,74) → 0,00 | E22: «Provisionado» (esta hoja), «Provisión recalculada (1/12)» (esta hoja) | F22: —

Sheet 09_Decimo_cuarto
A1: Décimo cuarto | H1: ⟵ Inicio | I1: ◀ Anterior | J1: Siguiente ▶
A2: Beneficios sociales y nómina · Cliente de muestra S.A. · corte 2025-12-31
A4: Cédula/código | B4: Activo | C4: Mensualizado | D4: Región | E4: Inicio del período | F4: Días del período al corte | G4: Provisión recalculada (SBU × días ÷ 360) | H4: Provisionado | I4: Provisionado − recalculado
A5: E01 | B5: ='05_Tiempo_servicio'!E5 | C5: No | D5: Sierra/Oriente | E5: 45870 | F5: =IF(OR(B5="No",C5="Sí"),0,DAYS360(MAX('03_Empleados'!C5,IF(D5="Costa/Galápagos",'02_Parametros'!$B$31,'02_Parametros'!$B$29)),'02_Parametros'!$B$5+1,TRUE)) | G5: ='02_Parametros'!$B$12*F5/360 | H5: =IF('03_Empleados'!T5="","",'03_Empleados'!T5) | I5: =IF(H5="","",H5-G5)
A6: E02 | B6: ='05_Tiempo_servicio'!E6 | C6: No | D6: Costa/Galápagos | E6: 45717 | F6: =IF(OR(B6="No",C6="Sí"),0,DAYS360(MAX('03_Empleados'!C6,IF(D6="Costa/Galápagos",'02_Parametros'!$B$31,'02_Parametros'!$B$29)),'02_Parametros'!$B$5+1,TRUE)) | G6: ='02_Parametros'!$B$12*F6/360 | H6: =IF('03_Empleados'!T6="","",'03_Empleados'!T6) | I6: =IF(H6="","",H6-G6)
A7: E03 | B7: ='05_Tiempo_servicio'!E7 | C7: No | D7: Sierra/Oriente | E7: 45870 | F7: =IF(OR(B7="No",C7="Sí"),0,DAYS360(MAX('03_Empleados'!C7,IF(D7="Costa/Galápagos",'02_Parametros'!$B$31,'02_Parametros'!$B$29)),'02_Parametros'!$B$5+1,TRUE)) | G7: ='02_Parametros'!$B$12*F7/360 | H7: =IF('03_Empleados'!T7="","",'03_Empleados'!T7) | I7: =IF(H7="","",H7-G7)
A8: E04 | B8: ='05_Tiempo_servicio'!E8 | C8: No | D8: Sierra/Oriente | E8: 45870 | F8: =IF(OR(B8="No",C8="Sí"),0,DAYS360(MAX('03_Empleados'!C8,IF(D8="Costa/Galápagos",'02_Parametros'!$B$31,'02_Parametros'!$B$29)),'02_Parametros'!$B$5+1,TRUE)) | G8: ='02_Parametros'!$B$12*F8/360 | H8: =IF('03_Empleados'!T8="","",'03_Empleados'!T8) | I8: =IF(H8="","",H8-G8)
A9: E05 | B9: ='05_Tiempo_servicio'!E9 | C9: Sí | D9: Sierra/Oriente | E9: 45870 | F9: =IF(OR(B9="No",C9="Sí"),0,DAYS360(MAX('03_Empleados'!C9,IF(D9="Costa/Galápagos",'02_Parametros'!$B$31,'02_Parametros'!$B$29)),'02_Parametros'!$B$5+1,TRUE)) | G9: ='02_Parametros'!$B$12*F9/360 | H9: =IF('03_Empleados'!T9="","",'03_Empleados'!T9) | I9: =IF(H9="","",H9-G9)
A10: E06 | B10: ='05_Tiempo_servicio'!E10 | C10: No | D10: Costa/Galápagos | E10: 45717 | F10: =IF(OR(B10="No",C10="Sí"),0,DAYS360(MAX('03_Empleados'!C10,IF(D10="Costa/Galápagos",'02_Parametros'!$B$31,'02_Parametros'!$B$29)),'02_Parametros'!$B$5+1,TRUE)) | G10: ='02_Parametros'!$B$12*F10/360 | H10: =IF('03_Empleados'!T10="","",'03_Empleados'!T10) | I10: =IF(H10="","",H10-G10)
A11: E07 | B11: ='05_Tiempo_servicio'!E11 | C11: No | D11: Sierra/Oriente | E11: 45870 | F11: =IF(OR(B11="No",C11="Sí"),0,DAYS360(MAX('03_Empleados'!C11,IF(D11="Costa/Galápagos",'02_Parametros'!$B$31,'02_Parametros'!$B$29)),'02_Parametros'!$B$5+1,TRUE)) | G11: ='02_Parametros'!$B$12*F11/360 | H11: =IF('03_Empleados'!T11="","",'03_Empleados'!T11) | I11: =IF(H11="","",H11-G11)
