Workbook

Sheet 00_Inicio
B2: AuditConsulting Auditores Cía. Ltda. · AUDIT-IA
B4: Propiedad, planta y equipo
B6: Cliente | C6: Cliente de muestra S.A. | D6: RUC | E6: 1790000000001
B7: Marco contable | C7: NIIF completas | D7: Fecha de corte | E7: 2025-12-31
B8: Preparó | C8: Ejercicio modelo | D8: Revisó | E8: Pendiente
B10: INDICADORES CLAVE
B11: Efecto neto de los ajustes en resultados | C11: Problemas encontrados
B12: -2852.73 | C12: 16
B15: IR A LA CÉDULA
B16: Carátula | C16: Programa | D16: Base técnica | E16: Resumen
B17: Parámetros | C17: Auxiliar de activos (datos del cliente) | D17: Recálculo de depreciación y VNL | E17: Vidas útiles, residual y método
B18: Componentes | C18: Bajas | D18: Revaluación | E18: Deterioro
B19: Adiciones y costos por préstamos | C19: Préstamos para la construcción | D19: Capitalización de costos por préstamos por activo | E19: Desmantelamiento
B20: Movimiento del año y conciliación auxiliar-mayor | C20: Ajustes propuestos | D20: Problemas encontrados | E20: Conclusión
B21: Control de revisión
B23: PANORAMA | N23: Datos de los gráficos (fórmulas a las cédulas)
N24: Cifras del resumen | O24: Importe (USD)
N25: ='01_Resumen'!A5 | O25: ='01_Resumen'!B5
N26: ='01_Resumen'!A6 | O26: ='01_Resumen'!B6
N27: ='01_Resumen'!A7 | O27: ='01_Resumen'!B7
N28: ='01_Resumen'!A8 | O28: ='01_Resumen'!B8
N29: ='01_Resumen'!A9 | O29: ='01_Resumen'!B9
N30: ='01_Resumen'!A10 | O30: ='01_Resumen'!B10
N31: ='01_Resumen'!A11 | O31: ='01_Resumen'!B11
N32: ='01_Resumen'!A12 | O32: ='01_Resumen'!B12
N33: ='01_Resumen'!A13 | O33: ='01_Resumen'!B13
N34: ='01_Resumen'!A14 | O34: ='01_Resumen'!B14
N35: ='01_Resumen'!A15 | O35: ='01_Resumen'!B15
N36: ='01_Resumen'!A16 | O36: ='01_Resumen'!B16
... N46: ='01_Resumen'!A26 | O46: ='01_Resumen'!B26
N48: Hallazgos de mayor impacto | O48: Importe (USD)
N49: Revaluacion sin decremento previo | O49: =SUMIFS('16_Problemas'!$C$5:$C$20,'16_Problemas'!$A$5:$A$20,"REVALUACION_SIN_DECREMENTO_PREVIO",'16_Problemas'!$C$5:$C$20,">0")-SUMIFS('16_Problemas'!$C$5:$C$20,'16_Problemas'!$A$5:$A$20,"REVALUACION_SIN_DECREMENTO_PREVIO",'16_Problemas'!$C$5:$C$20,"<0")
N50: Totalmente depreciado en uso | O50: =SUMIFS('16_Problemas'!$C$5:$C$20,'16_Problemas'!$A$5:$A$20,"TOTALMENTE_DEPRECIADO_EN_USO",'16_Problemas'!$C$5:$C$20,">0")-SUMIFS('16_Problemas'!$C$5:$C$20,'16_Problemas'!$A$5:$A$20,"TOTALMENTE_DEPRECIADO_EN_USO",'16_Problemas'!$C$5:$C$20,"<0")
N51: Desmantelamiento no reconocido | O51: =SUMIFS('16_Problemas'!$C$5:$C$20,'16_Problemas'!$A$5:$A$20,"DESMANTELAMIENTO_NO_RECONOCIDO",'16_Problemas'!$C$5:$C$20,">0")-SUMIFS('16_Problemas'!$C$5:$C$20,'16_Problemas'!$A$5:$A$20,"DESMANTELAMIENTO_NO_RECONOCIDO",'16_Problemas'!$C$5:$C$20,"<0")
N52: Deterioro | O52: =SUMIFS('16_Problemas'!$C$5:$C$20,'16_Problemas'!$A$5:$A$20,"DETERIORO",'16_Problemas'!$C$5:$C$20,">0")-SUMIFS('16_Problemas'!$C$5:$C$20,'16_Problemas'!$A$5:$A$20,"DETERIORO",'16_Problemas'!$C$5:$C$20,"<0")
N53: Adicion gasto capitalizado | O53: =SUMIFS('16_Problemas'!$C$5:$C$20,'16_Problemas'!$A$5:$A$20,"ADICION_GASTO_CAPITALIZADO",'16_Problemas'!$C$5:$C$20,">0")-SUMIFS('16_Problemas'!$C$5:$C$20,'16_Problemas'!$A$5:$A$20,"ADICION_GASTO_CAPITALIZADO",'16_Problemas'!$C$5:$C$20,"<0")
N54: Intereses diferencia | O54: =SUMIFS('16_Problemas'!$C$5:$C$20,'16_Problemas'!$A$5:$A$20,"INTERESES_DIFERENCIA",'16_Problemas'!$C$5:$C$20,">0")-SUMIFS('16_Problemas'!$C$5:$C$20,'16_Problemas'!$A$5:$A$20,"INTERESES_DIFERENCIA",'16_Problemas'!$C$5:$C$20,"<0")
N55: Depreciacion diferente (×3) | O55: =SUMIFS('16_Problemas'!$C$5:$C$20,'16_Problemas'!$A$5:$A$20,"DEPRECIACION_DIFERENTE",'16_Problemas'!$C$5:$C$20,">0")-SUMIFS('16_Problemas'!$C$5:$C$20,'16_Problemas'!$A$5:$A$20,"DEPRECIACION_DIFERENTE",'16_Problemas'!$C$5:$C$20,"<0")
N56: Otros (3 tipos) | O56: =SUMIF('16_Problemas'!$C$5:$C$20,">0")-SUMIF('16_Problemas'!$C$5:$C$20,"<0")-((SUMIFS('16_Problemas'!$C$5:$C$20,'16_Problemas'!$A$5:$A$20,"REVALUACION_SIN_DECREMENTO_PREVIO",'16_Problemas'!$C$5:$C$20,">0")-SUMIFS('16_Problemas'!$C$5:$C$20,'16_Problemas'!$A$5:$A$20,"REVALUACION_SIN_DECREMENTO_PREVIO",'16_Problemas'!$C$5:$C$20,"<0"))+(SUMIFS('16_Problemas'!$C$5:$C$20,'16_Problemas'!$A$5:$A$20,"TOTALMENTE_DEPRECIADO_EN_USO",'16_Problemas'!$C$5:$C$20,">0")-SUMIFS('16_Problemas'!$C$5:$C$20,'16_Problemas'!$A$5:$A$20,"TOTALMENTE_DEPRECIADO_EN_USO",'16_Problemas'!$C$5:$C$20,"<0"))+(SUMIFS('16_Problemas'!$C$5:$C$20,'16_Problemas'!$A$5:$A$20,"DESMANTELAMIENTO_NO_RECONOCIDO",'16_Problemas'!$C$5:$C$20,">0")-SUMIFS('16_Problemas'!$C$5:$C$20,'16_Problemas'!$A$5:$A$20,"DESMANTELAMIENTO_NO_RECONOCIDO",'16_Problemas'!$C$5:$C$20,"<0"))+(SUMIFS('16_Problemas'!$C$5:$C$20,'16_Problemas'!$A$5:$A$20,"DETERIORO",'16_Problemas'!$C$5:$C$20,">0")-SUMIFS('16_Problemas'!$C$5:$C$20,'16_Problemas'!$A$5:$A$20,"DETERIORO",'16_Problemas'!$C$5:$C$20,"<0"))+(SUMIFS('16_Problemas'!$C$5:$C$20,'16_Problemas'!$A$5:$A$20,"ADICION_GASTO_CAPITALIZADO",'16_Problemas'!$C$5:$C$20,">0")-SUMIFS('16_Problemas'!$C$5:$C$20,'16_Problemas'!$A$5:$A$20,"ADICION_GASTO_CAPITALIZADO",'16_Problemas'!$C$5:$C$20,"<0"))+(SUMIFS('16_Problemas'!$C$5:$C$20,'16_Problemas'!$A$5:$A$20,"INTERESES_DIFERENCIA",'16_Problemas'!$C$5:$C$20,">0")-SUMIFS('16_Problemas'!$C$5:$C$20,'16_Problemas'!$A$5:$A$20,"INTERESES_DIFERENCIA",'16_Problemas'!$C$5:$C$20,"<0"))+(SUMIFS('16_Problemas'!$C$5:$C$20,'16_Problemas'!$A$5:$A$20,"DEPRECIACION_DIFERENTE",'16_Problemas'!$C$5:$C$20,">0")-SUMIFS('16_Problemas'!$C$5:$C$20,'16_Problemas'!$A$5:$A$20,"DEPRECIACION_DIFERENTE",'16_Problemas'!$C$5:$C$20,"<0")))

Sheet 00_Caratula
A1: Carátula | H1: ⟵ Inicio | J1: Siguiente ▶
A2: Propiedad, planta y equipo · Cliente de muestra S.A. · corte 2025-12-31
A4: Concepto | B4: Detalle
A5: Firma | B5: AuditConsulting Auditores Cía. Ltda.
A6: Cliente | B6: Cliente de muestra S.A.
A7: RUC | B7: 1790000000001
A8: Ejercicio | B8: 2025
A9: Fecha de corte | B9: 2025-12-31
A10: Marco contable | B10: NIIF completas
A11: Herramienta | B11: Propiedad, planta y equipo
A12: Rubro | B12: Propiedad, planta y equipo
A13: Motor | B13: ppe_propiedad_planta 1.0
A14: Versión del papel | B14: v1
A15: Estado | B15: MUESTRA
... A17: Revisó | B17: Pendiente
A18: Aprobó
A19: Fecha de aprobación
A20: Huella de la ejecución (SHA-256)

Sheet 00_Programa
A1: Programa | H1: ⟵ Inicio | I1: ◀ Anterior | J1: Siguiente ▶
A2: Propiedad, planta y equipo · Cliente de muestra S.A. · corte 2025-12-31
A4: Código | B4: Objetivo | C4: Afirmación | D4: Procedimiento | E4: Evidencia | F4: Criterio | G4: Referencia
A5: PPE-01 | B5: Conciliación auxiliar-mayor | C5: Integridad | D5: Movimiento del año del costo y la depreciación acumulada y conciliación con el mayor | E5: Auxiliar y mayor | F5: Diferencia dentro de tolerancia o explicada | G5: NIA 500 · NIA 510
A6: PPE-02 | B6: Adiciones | C6: Existencia / Clasificación | D6: Examinar las adiciones y separar capital de gasto (reparación y mantenimiento) | E6: Facturas, contratos, actas de recepción | F6: Solo costos que cumplen NIC 16.7 y 16.16 | G6: NIC 16.12, 16 · PYMES 17.6, 17.10, 17.15
A7: PPE-03 | B7: Depreciación | C7: Valoración | D7: Recalcular la depreciación por activo desde la fecha disponible para uso | E7: Auxiliar | F7: Diferencias dentro de tolerancia | G7: NIC 16.50–62 · PYMES 17.18–17.23
A8: PPE-04 | B8: Vidas útiles, residual, método y componentes | C8: Valoración | D8: Revisar activos totalmente depreciados en uso, residuales y partes significativas | E8: Política contable, informes técnicos | F8: NIIF: revisadas al cierre (NIC 16.51, 61); PYMES: si hay indicios (17.19) | G8: NIC 16.43–47, 51, 61 · PYMES 17.16, 17.19
A9: PPE-05 | B9: Bajas | C9: Exactitud | D9: Recalcular el valor neto en libros a la baja y la ganancia o pérdida | E9: Facturas de venta, actas de baja | F9: Resultado recalculado igual al registrado | G9: NIC 16.67–72 · PYMES 17.27–17.30
A10: PPE-06 | B10: Revaluación | C10: Valoración | D10: Comparar el valor revaluado con el VNL y distribuir entre ORI y resultados | E10: Informe del perito | F10: Tratamiento según NIC 16.39–40 | G10: NIC 16.31–42 · PYMES 17.15–17.15D · NIA 620
A11: PPE-07 | B11: Deterioro | C11: Valoración | D11: Comparar el importe en libros con el importe recuperable | E11: Cálculo de valor en uso o valor razonable | F11: Pérdida reconocida | G11: NIC 36.59–61 · PYMES 27.5–27.6 (si el activo está revaluado, primero contra el superávit) · NIA 540
A12: PPE-08 | B12: Costos por préstamos | C12: Valoración / Clasificación | D12: Separar préstamos específicos y generales; recalcular por activo el capitalizable (específico: costo real menos los rendimientos de la inversión temporal; generales: tasa de capitalización) y comprobar el tope de los costos incurridos en el período (NIIF completas); en PYMES reversar lo capitalizado | E12: Contratos de préstamo, tablas de amortización, mayor de gasto financiero y de rendimientos de inversiones temporales | F12: NIC 23.12, 14 (incluido el tope) / Sección 25.2 | G12: NIC 23 · PYMES 25
A13: PPE-09 | B13: Desmantelamiento | C13: Integridad / Valoración | D13: Recalcular el valor presente de la obligación y compararlo con la provisión | E13: Contratos, permisos ambientales, estimación técnica | F13: Provisión igual al valor presente | G13: NIC 16.16 c · NIC 37.45–47 · CINIIF 1 · Sección 21 (21.7 b)

Sheet 00_Fuentes
A1: Base técnica | H1: ⟵ Inicio | I1: ◀ Anterior | J1: Siguiente ▶
A2: Propiedad, planta y equipo · Cliente de muestra S.A. · corte 2025-12-31
A4: Categoría | B4: Documento | C4: Párrafos | D4: URL | E4: Verificada
A5: NIA · NIA 500 | B5: Evidencia suficiente y adecuada sobre existencia, integridad y valoración del auxiliar. | C5: párr. 6–9
A6: NIA · NIA 510 | B6: Saldos iniciales: el costo y la depreciación acumulada iniciales se concilian con el cierre anterior; aplica en encargos iniciales; en recurrentes NIA 500/330. | C6: párr. 6
A7: NIA · NIA 540 (Revisada) | B7: Estimaciones: vidas útiles, residuales, importe recuperable, valor razonable y desmantelamiento. | C7: párr. 13–30 y 32
A8: NIA · NIA 500 | B8: Inspección física de activos tangibles. | C8: párr. A18 y A20
A9: NIA · NIA 500 | B9: Perito de la dirección (NIA 620 solo si lo contrata el auditor): evaluar su trabajo en revaluaciones y deterioro. | C9: párr. 8

Sheet 01_Resumen
A1: Resumen | H1: ⟵ Inicio | I1: ◀ Anterior | J1: Siguiente ▶
A2: Propiedad, planta y equipo · Cliente de muestra S.A. · corte 2025-12-31
A4: Concepto | B4: Importe
A5: Costo al cierre (auxiliar) | B5: ='14_Roll_forward'!B8
A6: Depreciación del año recalculada | B6: =SUM('04_Depreciacion'!$E$5:$E$14)
A7: Depreciación del año registrada | B7: ='14_Roll_forward'!B12
A8: Diferencia de depreciación (recalculada − registrada) | B8: ='15_Ajustes'!B5
A9: Valor neto en libros recalculado (activos medidos) | B9: ='14_Roll_forward'!B18
A10: Pérdida por deterioro adicional | B10: =SUM('09_Deterioro'!$E$5:$E$5)
A11: Deterioro contra el superávit de revaluación (ORI) | B11: ='15_Ajustes'!B11
A12: Deterioro a resultados | B12: ='15_Ajustes'!B6
A13: Diferencia en resultado de bajas | B13: ='15_Ajustes'!B7
A14: Capitalizable de préstamos específicos (NIC 23.12) | B14: ='12_Capitalizacion'!E6
A15: Capitalizable de préstamos generales (NIC 23.14) | B15: ='12_Capitalizacion'!I6
A16: Costos por préstamos incurridos en el período (tope NIC 23.14) | B16: ='11_Prestamos'!G8
A17: Costos por préstamos capitalizables del período (después del tope) | B17: ='12_Capitalizacion'!L6
A18: Ajuste de intereses capitalizados | B18: ='15_Ajustes'!B8
A19: Revaluación a otro resultado integral | B19: ='15_Ajustes'!B9
A20: Revaluación a resultados | B20: ='15_Ajustes'!B10
A21: Provisión de desmantelamiento (valor presente) | B21: ='13_Desmantelamiento'!B8
A22: Desmantelamiento: cambio de estimación (contra el costo del activo) | B22: ='15_Ajustes'!B12
A23: Desmantelamiento: actualización financiera del período (costo financiero) | B23: ='15_Ajustes'!B13
A24: Diferencia auxiliar − mayor (costo) | B24: ='14_Roll_forward'!B10
A25: Diferencia auxiliar − mayor (depreciación acumulada) | B25: ='14_Roll_forward'!B16
A26: Efecto neto de los ajustes en resultados | B26: ='15_Ajustes'!B14
A28: ⓘ Cómo se calcula esta hoja
A29: Columna | B29: Fórmula (Excel) | C29: Cómo se calcula (sencillo) | D29: Ejemplo con números reales | E29: De dónde viene | F29: Norma
A30: Importe | B30: '='14_Roll_forward'!B8 | C30: Trae cada concepto de su hoja: costo y diferencias con el mayor de la hoja 14 (Movimiento del año), depreciación de las hojas 04 y 14, ajustes de la hoja 15 (Ajustes propuestos), deterioro de la hoja 09, costos por préstamos de las hojas 11 y 12 y desmantelamiento de la hoja 13. | D30: Fila 1: 1.297.000,00 → 1.297.000,00 | E30: hoja «Movimiento del año y conciliación auxiliar-mayor» | F30: —

Sheet 02_Parametros
A1: Parámetros | H1: ⟵ Inicio | I1: ◀ Anterior | J1: Siguiente ▶
A2: Propiedad, planta y equipo · Cliente de muestra S.A. · corte 2025-12-31
A4: Parámetro | B4: Valor | C4: Sustento
A5: Corte del ejercicio | B5: 46022 | C5: Ficha del encargo
A6: Inicio del ejercicio | B6: 45658 | C6: Un año antes del corte + 1 día
A7: Días del ejercicio | B7: =B5-B6+1 | C7: Base de la fracción de tiempo
A8: Marco contable | B8: NIIF completas | C8: NIC 23: capitaliza en activos aptos
A9: Edición PYMES | C9: 2015 y 2025: mismo tratamiento (resumen oficial de cambios 2025: Secc. 25 editorial; Secc. 27 consecuencial; Secc. 17 sin cambios en revaluación, componentes ni bajas); la 3.ª edición rige desde el 1-1-2027
A10: Tolerancia por activo (importe) | B10: 1 | C10: Juicio del auditor (materialidad de ejecución)
A11: Tasa de capitalización (% anual) | B11: 8 | C11: NIC 23.14: media ponderada de los préstamos genéricos
A12: Parte significativa desde (% del elemento) | B12: 10 | C12: NIC 16.43; juicio del auditor
A13: Revisar componentes desde (costo) | B13: 400000 | C13: NIC 16.44; en blanco: no se revisa
A14: Desmantelamiento: costo estimado futuro | B14: 50000 | C14: NIC 16.16 c; PYMES 17.10 c
A15: Desmantelamiento: años hasta el desembolso | B15: 10 | C15: Estimación técnica
A16: Desmantelamiento: tasa antes de impuestos (%) | B16: 6 | C16: NIC 37.47
A17: Provisión de desmantelamiento registrada (cierre) | C17: Mayor contable
A18: Provisión de desmantelamiento registrada al inicio | C18: Mayor contable: base de la actualización financiera del período (CINIIF 1.8; NIC 37.60; PYMES 21.11). En blanco y sin provisión al cierre: 0
A19: Mayor: costo al cierre | B19: 1297000 | C19: Mayor contable
A20: Mayor: depreciación acumulada al cierre | B20: 253000 | C20: Mayor contable
A22: ⓘ Cómo se calcula esta hoja
A23: Columna | B23: Fórmula (Excel) | C23: Cómo se calcula (sencillo) | D23: Ejemplo con números reales | E23: De dónde viene | F23: Norma
A24: Valor | B24: '=B5-B6+1 | C24: Son los datos de la ficha del encargo y del mayor; la única fila calculada es «Días del ejercicio»: fecha de corte menos fecha de inicio, más un día. | D24: Fila 3: «2025-12-31»-«2025-01-01»+1 → 365,00 | E24: «Valor» (esta hoja) | F24: —

Sheet 03_Auxiliar
A1: Auxiliar de activos (datos del cliente) | H1: ⟵ Inicio | I1: ◀ Anterior | J1: Siguiente ▶
A2: Propiedad, planta y equipo · Cliente de muestra S.A. · corte 2025-12-31
A4: Código | B4: Descripción | C4: Clase | D4: Elemento | E4: Disponible para uso | F4: Costo inicial | G4: Adiciones | H4: Valor residual | I4: Vida útil (meses) | J4: Método | K4: Dep. acum. inicial | L4: Dep. del año registrada | M4: Deterioro acumulado | N4: Importe recuperable | O4: Valor revaluado | P4: Superávit previo | Q4: Decremento previo en resultados | R4: Fecha de baja | S4: Producto de la baja | T4: Resultado de baja registrado
A5: EDIF-01 | B5: Edificio administrativo | C5: Edificios | E5: 42005 | F5: 500000 | H5: 50000 | I5: 480 | J5: Lineal | K5: 112500 | L5: 11250
A6: TERR-01 | B6: Terreno planta | C6: Terrenos | E6: 42005 | F6: 300000 | L6: 0 | O6: 360000
A7: TERR-02 | B7: Terreno bodega | C7: Terrenos | E7: 43221 | F7: 80000 | L7: 0
A8: VEH-01 | B8: Camioneta 4x4 | C8: Vehículos | E8: 45108 | F8: 40000 | H8: 4000 | I8: 60 | J8: Lineal | K8: 10800 | L8: 6000
A9: VEH-02 | B9: Camión de reparto | C9: Vehículos | E9: 44197 | F9: 30000 | H9: 3000 | I9: 60 | J9: Lineal | K9: 21600 | L9: 2700 | R9: 45838 | S9: 9000 | T9: 1500
A10: MAQ-01 | B10: Línea de envasado | C10: Maquinaria | E10: 43831 | F10: 120000 | I10: 120 | J10: Lineal | K10: 60000 | L10: 12000 | N10: 40000
A11: MAQ-01-M | B11: Motor de la línea de envasado | C11: Maquinaria | D11: MAQ-01 | E11: 43831 | F11: 30000 | I11: 60 | J11: Lineal | K11: 30000 | L11: 0
A12: EQC-01 | B12: Servidores | C12: Equipo de cómputo | E12: 45292 | F12: 15000 | I12: 36 | J12: Unidades producidas | K12: 5000 | L12: 4000
A13: OBRA-01 | B13: Nave industrial en construcción | C13: Construcciones en curso | F13: 0 | G13: 200000 | L13: 1000
A14: MOB-01 | B14: Mobiliario de oficinas | C14: Muebles y enseres | E14: 45748 | F14: 0 | G14: 12000 | I14: 120 | J14: Lineal | L14: 904.11

Sheet 04_Depreciacion
A1: Recálculo de depreciación y VNL | H1: ⟵ Inicio | I1: ◀ Anterior | J1: Siguiente ▶
A2: Propiedad, planta y equipo · Cliente de muestra S.A. · corte 2025-12-31
A4: Código | B4: Costo | C4: Importe depreciable | D4: Días en uso | E4: Depreciación recalculada | F4: Depreciación registrada | G4: Diferencia | H4: Dep. acumulada recalculada | I4: Deterioro acumulado | J4: Valor neto en libros | K4: Totalmente depreciado | L4: Estado
A5: EDIF-01 | B5: ='03_Auxiliar'!F5+'03_Auxiliar'!G5 | C5: =MAX(B5-'03_Auxiliar'!H5,0) | D5: =IF('03_Auxiliar'!E5="",0,MAX(IF('03_Auxiliar'!R5<>"",MIN('03_Auxiliar'!R5,'02_Parametros'!$B$5),'02_Parametros'!$B$5)-MAX('03_Auxiliar'!E5,'02_Parametros'!$B$6)+1,0)) | E5: =IF(NOT(OR('03_Auxiliar'!J5="",ISNUMBER(SEARCH("lineal",'03_Auxiliar'!J5)))),"",IF(OR('03_Auxiliar'!I5="",D5=0),0,MIN(C5/'03_Auxiliar'!I5*12*D5/'02_Parametros'!$B$7,MAX(C5-'03_Auxiliar'!K5,0)))) | F5: =IF('03_Auxiliar'!L5="","",'03_Auxiliar'!L5) | G5: =IF(OR(E5="",F5=""),"",E5-F5) | H5: =IF(E5="","",'03_Auxiliar'!K5+E5) | I5: ='03_Auxiliar'!M5 | J5: =IF(H5="","",B5-H5-I5) | K5: =IF(H5="","",IF(AND(C5>0,H5>=C5-0.005),"Sí","No")) | L5: =IF('03_Auxiliar'!R5<>"","Baja",IF('03_Auxiliar'!E5="","En construcción","En uso"))
A6: TERR-01 | B6: ='03_Auxiliar'!F6+'03_Auxiliar'!G6 | C6: =MAX(B6-'03_Auxiliar'!H6,0) | D6: =IF('03_Auxiliar'!E6="",0,MAX(IF('03_Auxiliar'!R6<>"",MIN('03_Auxiliar'!R6,'02_Parametros'!$B$5),'02_Parametros'!$B$5)-MAX('03_Auxiliar'!E6,'02_Parametros'!$B$6)+1,0)) | E6: =IF(NOT(OR('03_Auxiliar'!J6="",ISNUMBER(SEARCH("lineal",'03_Auxiliar'!J6)))),"",IF(OR('03_Auxiliar'!I6="",D6=0),0,MIN(C6/'03_Auxiliar'!I6*12*D6/'02_Parametros'!$B$7,MAX(C6-'03_Auxiliar'!K6,0)))) | F6: =IF('03_Auxiliar'!L6="","",'03_Auxiliar'!L6) | G6: =IF(OR(E6="",F6=""),"",E6-F6) | H6: =IF(E6="","",'03_Auxiliar'!K6+E6) | I6: ='03_Auxiliar'!M6 | J6: =IF(H6="","",B6-H6-I6) | K6: =IF(H6="","",IF(AND(C6>0,H6>=C6-0.005),"Sí","No")) | L6: =IF('03_Auxiliar'!R6<>"","Baja",IF('03_Auxiliar'!E6="","En construcción","En uso"))
A7: TERR-02 | B7: ='03_Auxiliar'!F7+'03_Auxiliar'!G7 | C7: =MAX(B7-'03_Auxiliar'!H7,0) | D7: =IF('03_Auxiliar'!E7="",0,MAX(IF('03_Auxiliar'!R7<>"",MIN('03_Auxiliar'!R7,'02_Parametros'!$B$5),'02_Parametros'!$B$5)-MAX('03_Auxiliar'!E7,'02_Parametros'!$B$6)+1,0)) | E7: =IF(NOT(OR('03_Auxiliar'!J7="",ISNUMBER(SEARCH("lineal",'03_Auxiliar'!J7)))),"",IF(OR('03_Auxiliar'!I7="",D7=0),0,MIN(C7/'03_Auxiliar'!I7*12*D7/'02_Parametros'!$B$7,MAX(C7-'03_Auxiliar'!K7,0)))) | F7: =IF('03_Auxiliar'!L7="","",'03_Auxiliar'!L7) | G7: =IF(OR(E7="",F7=""),"",E7-F7) | H7: =IF(E7="","",'03_Auxiliar'!K7+E7) | I7: ='03_Auxiliar'!M7 | J7: =IF(H7="","",B7-H7-I7) | K7: =IF(H7="","",IF(AND(C7>0,H7>=C7-0.005),"Sí","No")) | L7: =IF('03_Auxiliar'!R7<>"","Baja",IF('03_Auxiliar'!E7="","En construcción","En uso"))
A8: VEH-01 | B8: ='03_Auxiliar'!F8+'03_Auxiliar'!G8 | C8: =MAX(B8-'03_Auxiliar'!H8,0) | D8: =IF('03_Auxiliar'!E8="",0,MAX(IF('03_Auxiliar'!R8<>"",MIN('03_Auxiliar'!R8,'02_Parametros'!$B$5),'02_Parametros'!$B$5)-MAX('03_Auxiliar'!E8,'02_Parametros'!$B$6)+1,0)) | E8: =IF(NOT(OR('03_Auxiliar'!J8="",ISNUMBER(SEARCH("lineal",'03_Auxiliar'!J8)))),"",IF(OR('03_Auxiliar'!I8="",D8=0),0,MIN(C8/'03_Auxiliar'!I8*12*D8/'02_Parametros'!$B$7,MAX(C8-'03_Auxiliar'!K8,0)))) | F8: =IF('03_Auxiliar'!L8="","",'03_Auxiliar'!L8) | G8: =IF(OR(E8="",F8=""),"",E8-F8) | H8: =IF(E8="","",'03_Auxiliar'!K8+E8) | I8: ='03_Auxiliar'!M8 | J8: =IF(H8="","",B8-H8-I8) | K8: =IF(H8="","",IF(AND(C8>0,H8>=C8-0.005),"Sí","No")) | L8: =IF('03_Auxiliar'!R8<>"","Baja",IF('03_Auxiliar'!E8="","En construcción","En uso"))
A9: VEH-02 | B9: ='03_Auxiliar'!F9+'03_Auxiliar'!G9 | C9: =MAX(B9-'03_Auxiliar'!H9,0) | D9: =IF('03_Auxiliar'!E9="",0,MAX(IF('03_Auxiliar'!R9<>"",MIN('03_Auxiliar'!R9,'02_Parametros'!$B$5),'02_Parametros'!$B$5)-MAX('03_Auxiliar'!E9,'02_Parametros'!$B$6)+1,0)) | E9: =IF(NOT(OR('03_Auxiliar'!J9="",ISNUMBER(SEARCH("lineal",'03_Auxiliar'!J9)))),"",IF(OR('03_Auxiliar'!I9="",D9=0),0,MIN(C9/'03_Auxiliar'!I9*12*D9/'02_Parametros'!$B$7,MAX(C9-'03_Auxiliar'!K9,0)))) | F9: =IF('03_Auxiliar'!L9="","",'03_Auxiliar'!L9) | G9: =IF(OR(E9="",F9=""),"",E9-F9) | H9: =IF(E9="","",'03_Auxiliar'!K9+E9) | I9: ='03_Auxiliar'!M9 | J9: =IF(H9="","",B9-H9-I9) | K9: =IF(H9="","",IF(AND(C9>0,H9>=C9-0.005),"Sí","No")) | L9: =IF('03_Auxiliar'!R9<>"","Baja",IF('03_Auxiliar'!E9="","En construcción","En uso"))
A10: MAQ-01 | B10: ='03_Auxiliar'!F10+'03_Auxiliar'!G10 | C10: =MAX(B10-'03_Auxiliar'!H10,0) | D10: =IF('03_Auxiliar'!E10="",0,MAX(IF('03_Auxiliar'!R10<>"",MIN('03_Auxiliar'!R10,'02_Parametros'!$B$5),'02_Parametros'!$B$5)-MAX('03_Auxiliar'!E10,'02_Parametros'!$B$6)+1,0)) | E10: =IF(NOT(OR('03_Auxiliar'!J10="",ISNUMBER(SEARCH("lineal",'03_Auxiliar'!J10)))),"",IF(OR('03_Auxiliar'!I10="",D10=0),0,MIN(C10/'03_Auxiliar'!I10*12*D10/'02_Parametros'!$B$7,MAX(C10-'03_Auxiliar'!K10,0)))) | F10: =IF('03_Auxiliar'!L10="","",'03_Auxiliar'!L10) | G10: =IF(OR(E10="",F10=""),"",E10-F10) | H10: =IF(E10="","",'03_Auxiliar'!K10+E10) | I10: ='03_Auxiliar'!M10 | J10: =IF(H10="","",B10-H10-I10) | K10: =IF(H10="","",IF(AND(C10>0,H10>=C10-0.005),"Sí","No")) | L10: =IF('03_Auxiliar'!R10<>"","Baja",IF('03_Auxiliar'!E10="","En construcción","En uso"))
A11: MAQ-01-M | B11: ='03_Auxiliar'!F11+'03_Auxiliar'!G11 | C11: =MAX(B11-'03_Auxiliar'!H11,0) | D11: =IF('03_Auxiliar'!E11="",0,MAX(IF('03_Auxiliar'!R11<>"",MIN('03_Auxiliar'!R11,'02_Parametros'!$B$5),'02_Parametros'!$B$5)-MAX('03_Auxiliar'!E11,'02_Parametros'!$B$6)+1,0)) | E11: =IF(NOT(OR('03_Auxiliar'!J11="",ISNUMBER(SEARCH("lineal",'03_Auxiliar'!J11)))),"",IF(OR('03_Auxiliar'!I11="",D11=0),0,MIN(C11/'03_Auxiliar'!I11*12*D11/'02_Parametros'!$B$7,MAX(C11-'03_Auxiliar'!K11,0)))) | F11: =IF('03_Auxiliar'!L11="","",'03_Auxiliar'!L11) | G11: =IF(OR(E11="",F11=""),"",E11-F11) | H11: =IF(E11="","",'03_Auxiliar'!K11+E11) | I11: ='03_Auxiliar'!M11 | J11: =IF(H11="","",B11-H11-I11) | K11: =IF(H11="","",IF(AND(C11>0,H11>=C11-0.005),"Sí","No")) | L11: =IF('03_Auxiliar'!R11<>"","Baja",IF('03_Auxiliar'!E11="","En construcción","En uso"))
A12: EQC-01 | B12: ='03_Auxiliar'!F12+'03_Auxiliar'!G12 | C12: =MAX(B12-'03_Auxiliar'!H12,0) | D12: =IF('03_Auxiliar'!E12="",0,MAX(IF('03_Auxiliar'!R12<>"",MIN('03_Auxiliar'!R12,'02_Parametros'!$B$5),'02_Parametros'!$B$5)-MAX('03_Auxiliar'!E12,'02_Parametros'!$B$6)+1,0)) | E12: =IF(NOT(OR('03_Auxiliar'!J12="",ISNUMBER(SEARCH("lineal",'03_Auxiliar'!J12)))),"",IF(OR('03_Auxiliar'!I12="",D12=0),0,MIN(C12/'03_Auxiliar'!I12*12*D12/'02_Parametros'!$B$7,MAX(C12-'03_Auxiliar'!K12,0)))) | F12: =IF('03_Auxiliar'!L12="","",'03_Auxiliar'!L12) | G12: =IF(OR(E12="",F12=""),"",E12-F12) | H12: =IF(E12="","",'03_Auxiliar'!K12+E12) | I12: ='03_Auxiliar'!M12 | J12: =IF(H12="","",B12-H12-I12) | K12: =IF(H12="","",IF(AND(C12>0,H12>=C12-0.005),"Sí","No")) | L12: =IF('03_Auxiliar'!R12<>"","Baja",IF('03_Auxiliar'!E12="","En construcción","En uso"))
A13: OBRA-01 | B13: ='03_Auxiliar'!F13+'03_Auxiliar'!G13 | C13: =MAX(B13-'03_Auxiliar'!H13,0) | D13: =IF('03_Auxiliar'!E13="",0,MAX(IF('03_Auxiliar'!R13<>"",MIN('03_Auxiliar'!R13,'02_Parametros'!$B$5),'02_Parametros'!$B$5)-MAX('03_Auxiliar'!E13,'02_Parametros'!$B$6)+1,0)) | E13: =IF(NOT(OR('03_Auxiliar'!J13="",ISNUMBER(SEARCH("lineal",'03_Auxiliar'!J13)))),"",IF(OR('03_Auxiliar'!I13="",D13=0),0,MIN(C13/'03_Auxiliar'!I13*12*D13/'02_Parametros'!$B$7,MAX(C13-'03_Auxiliar'!K13,0)))) | F13: =IF('03_Auxiliar'!L13="","",'03_Auxiliar'!L13) | G13: =IF(OR(E13="",F13=""),"",E13-F13) | H13: =IF(E13="","",'03_Auxiliar'!K13+E13) | I13: ='03_Auxiliar'!M13 | J13: =IF(H13="","",B13-H13-I13) | K13: =IF(H13="","",IF(AND(C13>0,H13>=C13-0.005),"Sí","No")) | L13: =IF('03_Auxiliar'!R13<>"","Baja",IF('03_Auxiliar'!E13="","En construcción","En uso"))
A14: MOB-01 | B14: ='03_Auxiliar'!F14+'03_Auxiliar'!G14 | C14: =MAX(B14-'03_Auxiliar'!H14,0) | D14: =IF('03_Auxiliar'!E14="",0,MAX(IF('03_Auxiliar'!R14<>"",MIN('03_Auxiliar'!R14,'02_Parametros'!$B$5),'02_Parametros'!$B$5)-MAX('03_Auxiliar'!E14,'02_Parametros'!$B$6)+1,0)) | E14: =IF(NOT(OR('03_Auxiliar'!J14="",ISNUMBER(SEARCH("lineal",'03_Auxiliar'!J14)))),"",IF(OR('03_Auxiliar'!I14="",D14=0),0,MIN(C14/'03_Auxiliar'!I14*12*D14/'02_Parametros'!$B$7,MAX(C14-'03_Auxiliar'!K14,0)))) | F14: =IF('03_Auxiliar'!L14="","",'03_Auxiliar'!L14) | G14: =IF(OR(E14="",F14=""),"",E14-F14) | H14: =IF(E14="","",'03_Auxiliar'!K14+E14) | I14: ='03_Auxiliar'!M14 | J14: =IF(H14="","",B14-H14-I14) | K14: =IF(H14="","",IF(AND(C14>0,H14>=C14-0.005),"Sí","No")) | L14: =IF('03_Auxiliar'!R14<>"","Baja",IF('03_Auxiliar'!E14="","En construcción","En uso"))
A15: TOTAL | B15: =SUM(B5:B14) | E15: =SUM(E5:E14) | F15: =SUM(F5:F14) | G15: =SUM(G5:G14)
A17: ⓘ Cómo se calcula esta hoja
A18: Columna | B18: Fórmula (Excel) | C18: Cómo se calcula (sencillo) | D18: Ejemplo con números reales | E18: De dónde viene | F18: Norma
A19: Costo | B19: '='03_Auxiliar'!F5+'03_Auxiliar'!G5 | C19: Suma el costo inicial y las adiciones del año del activo, tomados de la hoja 03 (Auxiliar de activos). | D19: Fila 1: 500.000,00+(vacío) → 500.000,00 | E19: hoja «Auxiliar de activos (datos del cliente)» | F19: —
A20: Importe depreciable | B20: '=MAX(B5-'03_Auxiliar'!H5,0) | C20: Costo menos el valor residual de la hoja 03 (Auxiliar de activos), sin bajar de cero: es lo que se reparte durante la vida útil. | D20: Fila 1: MAX(500.000,00-50.000,00; 0) → 450.000,00 | E20: «Costo» (esta hoja), hoja «Auxiliar de activos (datos del cliente)» | F20: —
A21: Días en uso | B21: '=IF('03_Auxiliar'!E5="",0,MAX(IF('03_Auxiliar'!R5<>"",MIN('03_Auxiliar'!R5,'02_Parametros'!$B$5),'02_Parametros'!$B$5)-MAX('03_Auxiliar'!E5,'02_Parametros'!$B$6)+1,0)) | C21: Cuenta los días del ejercicio en que el activo estuvo disponible: desde su fecha de disponibilidad (o el inicio del ejercicio) hasta el corte o la fecha de baja. Si no tiene fecha de disponibilidad (en construcción), es cero. | D21: Fila 1: IF(«2015-01-01»=""; 0; MAX(IF((vacío)<>""; MIN((vacío); «2025-12-31»); «2025-12-31»)-MAX(«2015-01-01»; «2025-01-01»)+1; 0)) → 365 | E21: hoja «Auxiliar de activos (datos del cliente)», hoja «Parámetros» | F21: —
A22: Depreciación recalculada | B22: '=IF(NOT(OR('03_Auxiliar'!J5="",ISNUMBER(SEARCH("lineal",'03_Auxiliar'!J5)))),"",IF(OR('03_Auxiliar'!I5="",D5=0),0,MIN(C5/'03_Auxiliar'!I5*12*D5/'02_Parametros'!$B$7,MAX(C5-'03_Auxiliar'!K5,0)))) | C22: Solo para el método lineal: importe depreciable ÷ vida útil en meses × 12 × días en uso ÷ días del ejercicio, sin pasar de lo que queda por depreciar. Otros métodos quedan en blanco; sin vida útil o sin días en uso da cero. | D22: Fila 1: IF(NOT(OR(«Lineal»=""; ISNUMBER(SEARCH("lineal"; «Lineal»)))); ""; IF(OR(480=""; 365=0); 0; MIN(450.000,00/480*12*365/365,00; MAX(450.000,00-112.500,00; 0)))) → 11.250,00 | E22: «Días en uso» (esta hoja), «Importe depreciable» (esta hoja), hoja «Auxiliar de activos (datos del cliente)», hoja «Parámetros» | F22: —
A23: Depreciación registrada | B23: '=IF('03_Auxiliar'!L5="","",'03_Auxiliar'!L5) | C23: Trae la depreciación del año que registró el cliente, desde la hoja 03 (Auxiliar de activos); en blanco si no la informó. | D23: Fila 1: IF(11.250,00=""; ""; 11.250,00) → 11.250,00 | E23: hoja «Auxiliar de activos (datos del cliente)» | F23: —
A24: Diferencia | B24: '=IF(OR(E5="",F5=""),"",E5-F5) | C24: Depreciación recalculada menos registrada; en blanco si falta alguna de las dos. | D24: Fila 1: IF(OR(11.250,00=""; 11.250,00=""); ""; 11.250,00-11.250,00) → 0,00 | E24: «Depreciación recalculada» (esta hoja), «Depreciación registrada» (esta hoja) | F24: —
A25: Dep. acumulada recalculada | B25: '=IF(E5="","",'03_Auxiliar'!K5+E5) | C25: Suma la depreciación acumulada al inicio de la hoja 03 (Auxiliar de activos) y la depreciación recalculada del año; en blanco si no se recalculó. | D25: Fila 1: IF(11.250,00=""; ""; 112.500,00+11.250,00) → 123.750,00 | E25: «Depreciación recalculada» (esta hoja), hoja «Auxiliar de activos (datos del cliente)» | F25: —
A26: Deterioro acumulado | B26: '='03_Auxiliar'!M5 | C26: Trae el deterioro acumulado que registró el cliente para el activo, desde la hoja 03 (Auxiliar de activos). | D26: Fila 1: (vacío) → 0,00 | E26: hoja «Auxiliar de activos (datos del cliente)» | F26: —
A27: Valor neto en libros | B27: '=IF(H5="","",B5-H5-I5) | C27: Costo menos depreciación acumulada recalculada menos deterioro acumulado; en blanco si la depreciación no se recalculó. | D27: Fila 1: IF(123.750,00=""; ""; 500.000,00-123.750,00-0,00) → 376.250,00 | E27: «Dep. acumulada recalculada» (esta hoja), «Costo» (esta hoja), «Deterioro acumulado» (esta hoja) | F27: —
A28: Totalmente depreciado | B28: '=IF(H5="","",IF(AND(C5>0,H5>=C5-0.005),"Sí","No")) | C28: «Sí» cuando la depreciación acumulada recalculada ya cubre todo el importe depreciable; «No» si no; en blanco si no se recalculó. | D28: Fila 1: IF(123.750,00=""; ""; IF(AND(450.000,00>0; 123.750,00>=450.000,00-0.005); "Sí"; "No")) → No | E28: «Dep. acumulada recalculada» (esta hoja), «Importe depreciable» (esta hoja) | F28: —
A29: Estado | B29: '=IF('03_Auxiliar'!R5<>"","Baja",IF('03_Auxiliar'!E5="","En construcción","En uso")) | C29: «Baja» si el activo tiene fecha de baja en la hoja 03, «En construcción» si aún no tiene fecha de disponibilidad para uso y «En uso» en los demás casos. | D29: Fila 1: IF((vacío)<>""; "Baja"; IF(«2015-01-01»=""; "En construcción"; "En uso")) → En uso | E29: hoja «Auxiliar de activos (datos del cliente)» | F29: —

Sheet 05_Vidas_residual
A1: Vidas útiles, residual y método | H1: ⟵ Inicio | I1: ◀ Anterior | J1: Siguiente ▶
A2: Propiedad, planta y equipo · Cliente de muestra S.A. · corte 2025-12-31
A4: Código | B4: Clase | C4: Método | D4: Vida útil (meses) | E4: Valor residual | F4: Costo | G4: Residual % del costo | H4: Dep. acumulada recalculada | I4: Vida remanente (meses) | J4: Totalmente depreciado en uso | K4: Residual mayor que el costo
A5: EDIF-01 | B5: Edificios | C5: Lineal | D5: =IF('03_Auxiliar'!I5="","",'03_Auxiliar'!I5) | E5: ='03_Auxiliar'!H5 | F5: ='04_Depreciacion'!B5 | G5: =IF(F5=0,"",E5/F5) | H5: =IF('04_Depreciacion'!H5="","",'04_Depreciacion'!H5) | I5: =IF(OR(D5="",H5="",'04_Depreciacion'!C5=0),"",MAX('04_Depreciacion'!C5-H5,0)/'04_Depreciacion'!C5*D5) | J5: =IF(AND('04_Depreciacion'!K5="Sí",'04_Depreciacion'!L5="En uso"),"Sí","No") | K5: =IF(E5>F5,"Sí","No")
A6: TERR-01 | B6: Terrenos | D6: =IF('03_Auxiliar'!I6="","",'03_Auxiliar'!I6) | E6: ='03_Auxiliar'!H6 | F6: ='04_Depreciacion'!B6 | G6: =IF(F6=0,"",E6/F6) | H6: =IF('04_Depreciacion'!H6="","",'04_Depreciacion'!H6) | I6: =IF(OR(D6="",H6="",'04_Depreciacion'!C6=0),"",MAX('04_Depreciacion'!C6-H6,0)/'04_Depreciacion'!C6*D6) | J6: =IF(AND('04_Depreciacion'!K6="Sí",'04_Depreciacion'!L6="En uso"),"Sí","No") | K6: =IF(E6>F6,"Sí","No")
A7: TERR-02 | B7: Terrenos | D7: =IF('03_Auxiliar'!I7="","",'03_Auxiliar'!I7) | E7: ='03_Auxiliar'!H7 | F7: ='04_Depreciacion'!B7 | G7: =IF(F7=0,"",E7/F7) | H7: =IF('04_Depreciacion'!H7="","",'04_Depreciacion'!H7) | I7: =IF(OR(D7="",H7="",'04_Depreciacion'!C7=0),"",MAX('04_Depreciacion'!C7-H7,0)/'04_Depreciacion'!C7*D7) | J7: =IF(AND('04_Depreciacion'!K7="Sí",'04_Depreciacion'!L7="En uso"),"Sí","No") | K7: =IF(E7>F7,"Sí","No")
A8: VEH-01 | B8: Vehículos | C8: Lineal | D8: =IF('03_Auxiliar'!I8="","",'03_Auxiliar'!I8) | E8: ='03_Auxiliar'!H8 | F8: ='04_Depreciacion'!B8 | G8: =IF(F8=0,"",E8/F8) | H8: =IF('04_Depreciacion'!H8="","",'04_Depreciacion'!H8) | I8: =IF(OR(D8="",H8="",'04_Depreciacion'!C8=0),"",MAX('04_Depreciacion'!C8-H8,0)/'04_Depreciacion'!C8*D8) | J8: =IF(AND('04_Depreciacion'!K8="Sí",'04_Depreciacion'!L8="En uso"),"Sí","No") | K8: =IF(E8>F8,"Sí","No")
A9: VEH-02 | B9: Vehículos | C9: Lineal | D9: =IF('03_Auxiliar'!I9="","",'03_Auxiliar'!I9) | E9: ='03_Auxiliar'!H9 | F9: ='04_Depreciacion'!B9 | G9: =IF(F9=0,"",E9/F9) | H9: =IF('04_Depreciacion'!H9="","",'04_Depreciacion'!H9) | I9: =IF(OR(D9="",H9="",'04_Depreciacion'!C9=0),"",MAX('04_Depreciacion'!C9-H9,0)/'04_Depreciacion'!C9*D9) | J9: =IF(AND('04_Depreciacion'!K9="Sí",'04_Depreciacion'!L9="En uso"),"Sí","No") | K9: =IF(E9>F9,"Sí","No")
A10: MAQ-01 | B10: Maquinaria | C10: Lineal | D10: =IF('03_Auxiliar'!I10="","",'03_Auxiliar'!I10) | E10: ='03_Auxiliar'!H10 | F10: ='04_Depreciacion'!B10 | G10: =IF(F10=0,"",E10/F10) | H10: =IF('04_Depreciacion'!H10="","",'04_Depreciacion'!H10) | I10: =IF(OR(D10="",H10="",'04_Depreciacion'!C10=0),"",MAX('04_Depreciacion'!C10-H10,0)/'04_Depreciacion'!C10*D10) | J10: =IF(AND('04_Depreciacion'!K10="Sí",'04_Depreciacion'!L10="En uso"),"Sí","No") | K10: =IF(E10>F10,"Sí","No")
A11: MAQ-01-M | B11: Maquinaria | C11: Lineal | D11: =IF('03_Auxiliar'!I11="","",'03_Auxiliar'!I11) | E11: ='03_Auxiliar'!H11 | F11: ='04_Depreciacion'!B11 | G11: =IF(F11=0,"",E11/F11) | H11: =IF('04_Depreciacion'!H11="","",'04_Depreciacion'!H11) | I11: =IF(OR(D11="",H11="",'04_Depreciacion'!C11=0),"",MAX('04_Depreciacion'!C11-H11,0)/'04_Depreciacion'!C11*D11) | J11: =IF(AND('04_Depreciacion'!K11="Sí",'04_Depreciacion'!L11="En uso"),"Sí","No") | K11: =IF(E11>F11,"Sí","No")
A12: EQC-01 | B12: Equipo de cómputo | C12: Unidades producidas | D12: =IF('03_Auxiliar'!I12="","",'03_Auxiliar'!I12) | E12: ='03_Auxiliar'!H12 | F12: ='04_Depreciacion'!B12 | G12: =IF(F12=0,"",E12/F12) | H12: =IF('04_Depreciacion'!H12="","",'04_Depreciacion'!H12) | I12: =IF(OR(D12="",H12="",'04_Depreciacion'!C12=0),"",MAX('04_Depreciacion'!C12-H12,0)/'04_Depreciacion'!C12*D12) | J12: =IF(AND('04_Depreciacion'!K12="Sí",'04_Depreciacion'!L12="En uso"),"Sí","No") | K12: =IF(E12>F12,"Sí","No")
A13: OBRA-01 | B13: Construcciones en curso | D13: =IF('03_Auxiliar'!I13="","",'03_Auxiliar'!I13) | E13: ='03_Auxiliar'!H13 | F13: ='04_Depreciacion'!B13 | G13: =IF(F13=0,"",E13/F13) | H13: =IF('04_Depreciacion'!H13="","",'04_Depreciacion'!H13) | I13: =IF(OR(D13="",H13="",'04_Depreciacion'!C13=0),"",MAX('04_Depreciacion'!C13-H13,0)/'04_Depreciacion'!C13*D13) | J13: =IF(AND('04_Depreciacion'!K13="Sí",'04_Depreciacion'!L13="En uso"),"Sí","No") | K13: =IF(E13>F13,"Sí","No")
A14: MOB-01 | B14: Muebles y enseres | C14: Lineal | D14: =IF('03_Auxiliar'!I14="","",'03_Auxiliar'!I14) | E14: ='03_Auxiliar'!H14 | F14: ='04_Depreciacion'!B14 | G14: =IF(F14=0,"",E14/F14) | H14: =IF('04_Depreciacion'!H14="","",'04_Depreciacion'!H14) | I14: =IF(OR(D14="",H14="",'04_Depreciacion'!C14=0),"",MAX('04_Depreciacion'!C14-H14,0)/'04_Depreciacion'!C14*D14) | J14: =IF(AND('04_Depreciacion'!K14="Sí",'04_Depreciacion'!L14="En uso"),"Sí","No") | K14: =IF(E14>F14,"Sí","No")
A16: ⓘ Cómo se calcula esta hoja
A17: Columna | B17: Fórmula (Excel) | C17: Cómo se calcula (sencillo) | D17: Ejemplo con números reales | E17: De dónde viene | F17: Norma
A18: Vida útil (meses) | B18: '=IF('03_Auxiliar'!I5="","",'03_Auxiliar'!I5) | C18: Trae la vida útil en meses informada en la hoja 03 (Auxiliar de activos); en blanco si no se informó. | D18: Fila 1: IF(480=""; ""; 480) → 480 | E18: hoja «Auxiliar de activos (datos del cliente)» | F18: —
A19: Valor residual | B19: '='03_Auxiliar'!H5 | C19: Trae el valor residual del activo desde la hoja 03 (Auxiliar de activos); si está vacío, cero. | D19: Fila 1: 50.000,00 → 50.000,00 | E19: hoja «Auxiliar de activos (datos del cliente)» | F19: —
A20: Costo | B20: '='04_Depreciacion'!B5 | C20: Trae el costo del activo (costo inicial más adiciones) desde la hoja 04 (Recálculo de depreciación y VNL). | D20: Fila 1: 500.000,00 → 500.000,00 | E20: hoja «Recálculo de depreciación y VNL» | F20: —
A21: Residual % del costo | B21: '=IF(F5=0,"",E5/F5) | C21: Divide el valor residual para el costo, para ver si el residual es razonable; en blanco si el costo es cero. | D21: Fila 1: IF(500.000,00=0; ""; 50.000,00/500.000,00) → 10,00 % | E21: «Costo» (esta hoja), «Valor residual» (esta hoja) | F21: —
A22: Dep. acumulada recalculada | B22: '=IF('04_Depreciacion'!H5="","",'04_Depreciacion'!H5) | C22: Trae la depreciación acumulada recalculada desde la hoja 04 (Recálculo de depreciación y VNL); en blanco si allí no se recalculó. | D22: Fila 1: IF(123.750,00=""; ""; 123.750,00) → 123.750,00 | E22: hoja «Recálculo de depreciación y VNL» | F22: —
A23: Vida remanente (meses) | B23: '=IF(OR(D5="",H5="",'04_Depreciacion'!C5=0),"",MAX('04_Depreciacion'!C5-H5,0)/'04_Depreciacion'!C5*D5) | C23: Parte de la vida útil que queda: importe depreciable pendiente (hoja 04) sobre el importe depreciable total, por la vida útil en meses. En blanco si falta la vida útil o la depreciación. | D23: Fila 1: IF(OR(480=""; 123.750,00=""; 450.000,00=0); ""; MAX(450.000,00-123.750,00; 0)/450.000,00*480) → 348,00 | E23: «Vida útil (meses)» (esta hoja), «Dep. acumulada recalculada» (esta hoja), hoja «Recálculo de depreciación y VNL» | F23: —
A24: Totalmente depreciado en uso | B24: '=IF(AND('04_Depreciacion'!K5="Sí",'04_Depreciacion'!L5="En uso"),"Sí","No") | C24: «Sí» cuando en la hoja 04 el activo figura totalmente depreciado y sigue en uso: señal de que la vida útil estimada fue corta. | D24: Fila 1: IF(AND(«No»="Sí"; «En uso»="En uso"); "Sí"; "No") → No | E24: hoja «Recálculo de depreciación y VNL» | F24: —
A25: Residual mayor que el costo | B25: '=IF(E5>F5,"Sí","No") | C25: «Sí» si el valor residual supera al costo del activo, lo que no es razonable; «No» en caso contrario. | D25: Fila 1: IF(50.000,00>500.000,00; "Sí"; "No") → No | E25: «Valor residual» (esta hoja), «Costo» (esta hoja) | F25: —

Sheet 06_Componentes
A1: Componentes | H1: ⟵ Inicio | I1: ◀ Anterior | J1: Siguiente ▶
A2: Propiedad, planta y equipo · Cliente de muestra S.A. · corte 2025-12-31
A4: Código | B4: Elemento | C4: Costo de la parte | D4: Costo del elemento | E4: % del elemento | F4: Parte significativa | G4: Vida útil (meses) | H4: Método
A5: MAQ-01 | B5: MAQ-01 | C5: ='04_Depreciacion'!B10 | D5: =SUMIF($B$5:$B$6,B5,$C$5:$C$6) | E5: =IF(D5=0,"",C5/D5) | F5: =IF(E5="","",IF(E5>='02_Parametros'!$B$12/100,"Sí","No")) | G5: =IF('03_Auxiliar'!I10="","",'03_Auxiliar'!I10) | H5: Lineal
A6: MAQ-01-M | B6: MAQ-01 | C6: ='04_Depreciacion'!B11 | D6: =SUMIF($B$5:$B$6,B6,$C$5:$C$6) | E6: =IF(D6=0,"",C6/D6) | F6: =IF(E6="","",IF(E6>='02_Parametros'!$B$12/100,"Sí","No")) | G6: =IF('03_Auxiliar'!I11="","",'03_Auxiliar'!I11) | H6: Lineal
A8: ⓘ Cómo se calcula esta hoja
A9: Columna | B9: Fórmula (Excel) | C9: Cómo se calcula (sencillo) | D9: Ejemplo con números reales | E9: De dónde viene | F9: Norma
A10: Costo de la parte | B10: '='04_Depreciacion'!B10 | C10: Trae el costo de esta parte (componente) desde la hoja 04 (Recálculo de depreciación y VNL). | D10: Fila 1: 120.000,00 → 120.000,00 | E10: hoja «Recálculo de depreciación y VNL» | F10: —
A11: Costo del elemento | B11: '=SUMIF($B$5:$B$6,B5,$C$5:$C$6) | C11: Suma el costo de todas las partes de esta hoja que pertenecen al mismo elemento: es el costo total del elemento. | D11: Fila 1: SUMIF([«Elemento», 2 filas]; «MAQ-01»; [«Costo de la parte», 2 filas]) → 150.000,00 | E11: «Elemento» (esta hoja), «Costo de la parte» (esta hoja) | F11: —
A12: % del elemento | B12: '=IF(D5=0,"",C5/D5) | C12: Divide el costo de la parte para el costo total del elemento; en blanco si el elemento no tiene costo. | D12: Fila 1: IF(150.000,00=0; ""; 120.000,00/150.000,00) → 80,00 % | E12: «Costo del elemento» (esta hoja), «Costo de la parte» (esta hoja) | F12: —
A13: Parte significativa | B13: '=IF(E5="","",IF(E5>='02_Parametros'!$B$12/100,"Sí","No")) | C13: «Sí» si el % del elemento alcanza el umbral de parte significativa de la hoja 02 (Parámetros), por lo que debe depreciarse por separado; «No» si no llega. | D13: Fila 1: IF(80,00 %=""; ""; IF(80,00 %>=10,00/100; "Sí"; "No")) → Sí | E13: «% del elemento» (esta hoja), hoja «Parámetros» | F13: —
A14: Vida útil (meses) | B14: '=IF('03_Auxiliar'!I10="","",'03_Auxiliar'!I10) | C14: Trae la vida útil en meses de la parte desde la hoja 03 (Auxiliar de activos); en blanco si no se informó. | D14: Fila 1: IF(120=""; ""; 120) → 120 | E14: hoja «Auxiliar de activos (datos del cliente)» | F14: —

Sheet 07_Bajas
A1: Bajas | H1: ⟵ Inicio | I1: ◀ Anterior | J1: Siguiente ▶
A2: Propiedad, planta y equipo · Cliente de muestra S.A. · corte 2025-12-31
A4: Código | B4: Fecha de baja | C4: Costo | D4: Dep. acumulada a la baja | E4: Deterioro | F4: VNL a la baja | G4: Producto | H4: Resultado recalculado | I4: Resultado registrado | J4: Diferencia
A5: VEH-02 | B5: 45838 | C5: ='04_Depreciacion'!B9 | D5: =IF('04_Depreciacion'!H9="","",'04_Depreciacion'!H9) | E5: ='03_Auxiliar'!M9 | F5: =IF(D5="","",C5-D5-E5) | G5: ='03_Auxiliar'!S9 | H5: =IF(F5="","",G5-F5) | I5: =IF('03_Auxiliar'!T9="","",'03_Auxiliar'!T9) | J5: =IF(OR(H5="",I5=""),"",H5-I5)
A6: TOTAL | J6: =SUM(J5:J5)
A8: ⓘ Cómo se calcula esta hoja
A9: Columna | B9: Fórmula (Excel) | C9: Cómo se calcula (sencillo) | D9: Ejemplo con números reales | E9: De dónde viene | F9: Norma
A10: Costo | B10: '='04_Depreciacion'!B9 | C10: Trae el costo del activo dado de baja desde la hoja 04 (Recálculo de depreciación y VNL). | D10: Fila 1: 30.000,00 → 30.000,00 | E10: hoja «Recálculo de depreciación y VNL» | F10: —
A11: Dep. acumulada a la baja | B11: '=IF('04_Depreciacion'!H9="","",'04_Depreciacion'!H9) | C11: Trae la depreciación acumulada recalculada hasta la fecha de baja, desde la hoja 04; en blanco si no se pudo recalcular. | D11: Fila 1: IF(24.277,81=""; ""; 24.277,81) → 24.277,81 | E11: hoja «Recálculo de depreciación y VNL» | F11: —
A12: Deterioro | B12: '='03_Auxiliar'!M9 | C12: Trae el deterioro acumulado del activo desde la hoja 03 (Auxiliar de activos). | D12: Fila 1: (vacío) → 0,00 | E12: hoja «Auxiliar de activos (datos del cliente)» | F12: —
A13: VNL a la baja | B13: '=IF(D5="","",C5-D5-E5) | C13: Costo menos depreciación acumulada a la baja menos deterioro: es el valor en libros que sale con la baja (en blanco si falta la depreciación acumulada). | D13: Fila 1: IF(24.277,81=""; ""; 30.000,00-24.277,81-0,00) → 5.722,19 | E13: «Dep. acumulada a la baja» (esta hoja), «Costo» (esta hoja), «Deterioro» (esta hoja) | F13: —
A14: Producto | B14: '='03_Auxiliar'!S9 | C14: Trae lo que se cobró por la baja (venta o indemnización) desde la hoja 03 (Auxiliar de activos); si está vacío, cero. | D14: Fila 1: 9.000,00 → 9.000,00 | E14: hoja «Auxiliar de activos (datos del cliente)» | F14: —
A15: Resultado recalculado | B15: '=IF(F5="","",G5-F5) | C15: Producto de la baja menos el valor neto en libros a la baja: positivo es ganancia y negativo pérdida. | D15: Fila 1: IF(5.722,19=""; ""; 9.000,00-5.722,19) → 3.277,81 | E15: «VNL a la baja» (esta hoja), «Producto» (esta hoja) | F15: —
A16: Resultado registrado | B16: '=IF('03_Auxiliar'!T9="","",'03_Auxiliar'!T9) | C16: Trae la ganancia o pérdida en la baja que registró el cliente, desde la hoja 03; en blanco si no la informó. | D16: Fila 1: IF(1.500,00=""; ""; 1.500,00) → 1.500,00 | E16: hoja «Auxiliar de activos (datos del cliente)» | F16: —
A17: Diferencia | B17: '=IF(OR(H5="",I5=""),"",H5-I5) | C17: Resultado recalculado menos resultado registrado; en blanco si falta alguno de los dos. | D17: Fila 1: IF(OR(3.277,81=""; 1.500,00=""); ""; 3.277,81-1.500,00) → 1.777,81 | E17: «Resultado recalculado» (esta hoja), «Resultado registrado» (esta hoja) | F17: —

Sheet 08_Revaluacion
A1: Revaluación | H1: ⟵ Inicio | I1: ◀ Anterior | J1: Siguiente ▶
A2: Propiedad, planta y equipo · Cliente de muestra S.A. · corte 2025-12-31
A4: Código | B4: Clase | C4: VNL al corte | D4: Valor revaluado | E4: Diferencia | F4: Superávit previo | G4: Decremento previo en resultados | H4: A otro resultado integral | I4: A resultados
A5: TERR-01 | B5: Terrenos | C5: ='04_Depreciacion'!J6 | D5: ='03_Auxiliar'!O6 | E5: =D5-C5 | F5: ='03_Auxiliar'!P6 | G5: =IF('03_Auxiliar'!Q6="","",'03_Auxiliar'!Q6) | H5: =IF(E5>=0,IF(G5="",E5,E5-MIN(E5,G5)),-MIN(-E5,F5)) | I5: =IF(E5>=0,IF(G5="",0,MIN(E5,G5)),E5+MIN(-E5,F5))
A6: TOTAL | H6: =SUM(H5:H5) | I6: =SUM(I5:I5)
A8: ⓘ Cómo se calcula esta hoja
A9: Columna | B9: Fórmula (Excel) | C9: Cómo se calcula (sencillo) | D9: Ejemplo con números reales | E9: De dónde viene | F9: Norma
A10: VNL al corte | B10: '='04_Depreciacion'!J6 | C10: Trae el valor neto en libros recalculado al corte desde la hoja 04 (Recálculo de depreciación y VNL). | D10: Fila 1: 300.000,00 → 300.000,00 | E10: hoja «Recálculo de depreciación y VNL» | F10: —
A11: Valor revaluado | B11: '='03_Auxiliar'!O6 | C11: Trae el valor revaluado del activo (según el perito) desde la hoja 03 (Auxiliar de activos). | D11: Fila 1: 360.000,00 → 360.000,00 | E11: hoja «Auxiliar de activos (datos del cliente)» | F11: —
A12: Diferencia | B12: '=D5-C5 | C12: Valor revaluado menos valor neto en libros: positivo es aumento y negativo disminución por revaluación. | D12: Fila 1: 360.000,00-300.000,00 → 60.000,00 | E12: «Valor revaluado» (esta hoja), «VNL al corte» (esta hoja) | F12: —
A13: Superávit previo | B13: '='03_Auxiliar'!P6 | C13: Trae el superávit de revaluación que ya tenía el activo, desde la hoja 03 (Auxiliar de activos). | D13: Fila 1: (vacío) → 0,00 | E13: hoja «Auxiliar de activos (datos del cliente)» | F13: —
A14: Decremento previo en resultados | B14: '=IF('03_Auxiliar'!Q6="","",'03_Auxiliar'!Q6) | C14: Trae la disminución por revaluación que se llevó antes a resultados, desde la hoja 03; en blanco si no se informó. | D14: Fila 1: IF((vacío)=""; ""; (vacío)) → (en blanco) | E14: hoja «Auxiliar de activos (datos del cliente)» | F14: —
A15: A otro resultado integral | B15: '=IF(E5>=0,IF(G5="",E5,E5-MIN(E5,G5)),-MIN(-E5,F5)) | C15: Si es aumento, va a ORI lo que excede al decremento previo llevado a resultados (todo, si ese dato está vacío). Si es disminución, se carga a ORI solo hasta el superávit previo. | D15: Fila 1: IF(60.000,00>=0; IF((vacío)=""; 60.000,00; 60.000,00-MIN(60.000,00; (vacío))); -MIN(-60.000,00; 0,00)) → 60.000,00 | E15: «Diferencia» (esta hoja), «Decremento previo en resultados» (esta hoja), «Superávit previo» (esta hoja) | F15: —
A16: A resultados | B16: '=IF(E5>=0,IF(G5="",0,MIN(E5,G5)),E5+MIN(-E5,F5)) | C16: Si es aumento, va a resultados solo lo que revierte el decremento previo (cero si ese dato está vacío). Si es disminución, va a resultados lo que excede al superávit previo. | D16: Fila 1: IF(60.000,00>=0; IF((vacío)=""; 0; MIN(60.000,00; (vacío))); 60.000,00+MIN(-60.000,00; 0,00)) → 0,00 | E16: «Diferencia» (esta hoja), «Decremento previo en resultados» (esta hoja), «Superávit previo» (esta hoja) | F16: —

Sheet 09_Deterioro
A1: Deterioro | H1: ⟵ Inicio | I1: ◀ Anterior | J1: Siguiente ▶
A2: Propiedad, planta y equipo · Cliente de muestra S.A. · corte 2025-12-31
A4: Código | B4: Clase | C4: Importe en libros | D4: Importe recuperable | E4: Pérdida adicional | F4: Superávit previo | G4: Revaluación del año a ORI | H4: Superávit disponible | I4: Contra el superávit (ORI) | J4: A resultados
A5: MAQ-01 | B5: Maquinaria | C5: =IF('03_Auxiliar'!O10<>"",'03_Auxiliar'!O10,'04_Depreciacion'!J10) | D5: ='03_Auxiliar'!N10 | E5: =IF(C5="","",MAX(C5-D5,0)) | F5: =IF('03_Auxiliar'!P10="",0,'03_Auxiliar'!P10) | G5: =0 | H5: =MAX(F5+G5,0) | I5: =IF(E5="","",IF(AND('03_Auxiliar'!O10="",'03_Auxiliar'!P10=""),0,IF('03_Auxiliar'!P10="","",MIN(E5,H5)))) | J5: =IF(E5="","",IF(I5="",E5,E5-I5))
A6: TOTAL | E6: =SUM(E5:E5) | I6: =SUM(I5:I5) | J6: =SUM(J5:J5)
A8: ⓘ Cómo se calcula esta hoja
A9: Columna | B9: Fórmula (Excel) | C9: Cómo se calcula (sencillo) | D9: Ejemplo con números reales | E9: De dónde viene | F9: Norma
A10: Importe en libros | B10: '=IF('03_Auxiliar'!O10<>"",'03_Auxiliar'!O10,'04_Depreciacion'!J10) | C10: Usa el valor revaluado de la hoja 03 si el activo se revaluó; si no, el valor neto en libros de la hoja 04 (Recálculo de depreciación y VNL). | D10: Fila 1: IF((vacío)<>""; (vacío); 48.000,00) → 48.000,00 | E10: hoja «Auxiliar de activos (datos del cliente)», hoja «Recálculo de depreciación y VNL» | F10: —
A11: Importe recuperable | B11: '='03_Auxiliar'!N10 | C11: Trae el importe recuperable estimado del activo desde la hoja 03 (Auxiliar de activos). | D11: Fila 1: 40.000,00 → 40.000,00 | E11: hoja «Auxiliar de activos (datos del cliente)» | F11: —
A12: Pérdida adicional | B12: '=IF(C5="","",MAX(C5-D5,0)) | C12: Importe en libros menos importe recuperable, sin bajar de cero: es la pérdida por deterioro. En blanco si no hay importe en libros. | D12: Fila 1: IF(48.000,00=""; ""; MAX(48.000,00-40.000,00; 0)) → 8.000,00 | E12: «Importe en libros» (esta hoja), «Importe recuperable» (esta hoja) | F12: —
A13: Superávit previo | B13: '=IF('03_Auxiliar'!P10="",0,'03_Auxiliar'!P10) | C13: Trae el superávit de revaluación previo del activo desde la hoja 03 (Auxiliar de activos); si está vacío, cero. | D13: Fila 1: IF((vacío)=""; 0; (vacío)) → 0,00 | E13: hoja «Auxiliar de activos (datos del cliente)» | F13: —
A14: Revaluación del año a ORI | B14: '=0 | C14: Trae lo que la revaluación del año llevó a ORI en la hoja 08 (Revaluación); cero si el activo no se revaluó este año. | D14: Fila 1: 0 → 0,00 | E14: datos cargados del cliente | F14: —
A15: Superávit disponible | B15: '=MAX(F5+G5,0) | C15: Suma el superávit previo y la revaluación del año a ORI, sin bajar de cero: es el colchón contra el que se carga primero el deterioro. | D15: Fila 1: MAX(0,00+0,00; 0) → 0,00 | E15: «Superávit previo» (esta hoja), «Revaluación del año a ORI» (esta hoja) | F15: —
A16: Contra el superávit (ORI) | B16: '=IF(E5="","",IF(AND('03_Auxiliar'!O10="",'03_Auxiliar'!P10=""),0,IF('03_Auxiliar'!P10="","",MIN(E5,H5)))) | C16: Carga la pérdida contra el superávit disponible, hasta agotarlo. Si el activo no está revaluado ni tiene superávit, es cero; si está revaluado pero falta el superávit, queda en blanco. | D16: Fila 1: IF(8.000,00=""; ""; IF(AND((vacío)=""; (vacío)=""); 0; IF((vacío)=""; ""; MIN(8.000,00; 0,00)))) → 0,00 | E16: «Pérdida adicional» (esta hoja), «Superávit disponible» (esta hoja), hoja «Auxiliar de activos (datos del cliente)» | F16: —
A17: A resultados | B17: '=IF(E5="","",IF(I5="",E5,E5-I5)) | C17: La pérdida que no se cargó al superávit va a resultados; si no se pudo repartir (celda anterior en blanco), va toda la pérdida. | D17: Fila 1: IF(8.000,00=""; ""; IF(0,00=""; 8.000,00; 8.000,00-0,00)) → 8.000,00 | E17: «Pérdida adicional» (esta hoja), «Contra el superávit (ORI)» (esta hoja) | F17: —

Sheet 10_Adiciones
A1: Adiciones y costos por préstamos | H1: ⟵ Inicio | I1: ◀ Anterior | J1: Siguiente ▶
A2: Propiedad, planta y equipo · Cliente de muestra S.A. · corte 2025-12-31
A4: Documento | B4: Activo | C4: Fecha | D4: Descripción | E4: Tipo | F4: Importe | G4: Apto | H4: Intereses capitalizados | I4: Días de capitalización | J4: Intereses capitalizables | K4: Diferencia | L4: Capitalizable
A5: AD-01 | B5: OBRA-01 | C5: 45717 | D5: Avance de obra 1 | E5: Capitalizable | F5: 150000 | G5: Sí | H5: 9000 | I5: =IF(OR('02_Parametros'!$B$8="NIIF para las PYMES",NOT(OR(G5="Sí",G5="Si"))),0,MAX(IF(ISNA(MATCH(B5,'03_Auxiliar'!$A$5:$A$14,0)),'02_Parametros'!$B$5,IF(INDEX('03_Auxiliar'!$E$5:$E$14,MATCH(B5,'03_Auxiliar'!$A$5:$A$14,0))="",'02_Parametros'!$B$5,MIN(INDEX('03_Auxiliar'!$E$5:$E$14,MATCH(B5,'03_Auxiliar'!$A$5:$A$14,0)),'02_Parametros'!$B$5)))-MAX(C5,'02_Parametros'!$B$6),0)) | J5: ="" | K5: =IF(J5="","",J5-H5) | L5: =IF(OR(ISNUMBER(SEARCH("repar",E5)),ISNUMBER(SEARCH("manten",E5))),"No: gasto (NIC 16.12)","Sí")
A6: AD-02 | B6: OBRA-01 | C6: 45901 | D6: Avance de obra 2 | E6: Capitalizable | F6: 45000 | G6: Sí | H6: 0 | I6: =IF(OR('02_Parametros'!$B$8="NIIF para las PYMES",NOT(OR(G6="Sí",G6="Si"))),0,MAX(IF(ISNA(MATCH(B6,'03_Auxiliar'!$A$5:$A$14,0)),'02_Parametros'!$B$5,IF(INDEX('03_Auxiliar'!$E$5:$E$14,MATCH(B6,'03_Auxiliar'!$A$5:$A$14,0))="",'02_Parametros'!$B$5,MIN(INDEX('03_Auxiliar'!$E$5:$E$14,MATCH(B6,'03_Auxiliar'!$A$5:$A$14,0)),'02_Parametros'!$B$5)))-MAX(C6,'02_Parametros'!$B$6),0)) | J6: ="" | K6: =IF(J6="","",J6-H6) | L6: =IF(OR(ISNUMBER(SEARCH("repar",E6)),ISNUMBER(SEARCH("manten",E6))),"No: gasto (NIC 16.12)","Sí")
A7: AD-03 | B7: OBRA-01 | C7: 45945 | D7: Cubierta provisional | E7: Reparación | F7: 5000 | G7: No | I7: =IF(OR('02_Parametros'!$B$8="NIIF para las PYMES",NOT(OR(G7="Sí",G7="Si"))),0,MAX(IF(ISNA(MATCH(B7,'03_Auxiliar'!$A$5:$A$14,0)),'02_Parametros'!$B$5,IF(INDEX('03_Auxiliar'!$E$5:$E$14,MATCH(B7,'03_Auxiliar'!$A$5:$A$14,0))="",'02_Parametros'!$B$5,MIN(INDEX('03_Auxiliar'!$E$5:$E$14,MATCH(B7,'03_Auxiliar'!$A$5:$A$14,0)),'02_Parametros'!$B$5)))-MAX(C7,'02_Parametros'!$B$6),0)) | J7: ="" | K7: =IF(J7="","",J7-H7) | L7: =IF(OR(ISNUMBER(SEARCH("repar",E7)),ISNUMBER(SEARCH("manten",E7))),"No: gasto (NIC 16.12)","Sí")
A8: AD-04 | B8: MOB-01 | C8: 45748 | D8: Escritorios y sillas | E8: Capitalizable | F8: 12000 | G8: No | I8: =IF(OR('02_Parametros'!$B$8="NIIF para las PYMES",NOT(OR(G8="Sí",G8="Si"))),0,MAX(IF(ISNA(MATCH(B8,'03_Auxiliar'!$A$5:$A$14,0)),'02_Parametros'!$B$5,IF(INDEX('03_Auxiliar'!$E$5:$E$14,MATCH(B8,'03_Auxiliar'!$A$5:$A$14,0))="",'02_Parametros'!$B$5,MIN(INDEX('03_Auxiliar'!$E$5:$E$14,MATCH(B8,'03_Auxiliar'!$A$5:$A$14,0)),'02_Parametros'!$B$5)))-MAX(C8,'02_Parametros'!$B$6),0)) | J8: ="" | K8: =IF(J8="","",J8-H8) | L8: =IF(OR(ISNUMBER(SEARCH("repar",E8)),ISNUMBER(SEARCH("manten",E8))),"No: gasto (NIC 16.12)","Sí")
A9: TOTAL | F9: =SUM(F5:F8) | H9: =SUM(H5:H8) | K9: =SUM(K5:K8)
A11: ⓘ Cómo se calcula esta hoja
A12: Columna | B12: Fórmula (Excel) | C12: Cómo se calcula (sencillo) | D12: Ejemplo con números reales | E12: De dónde viene | F12: Norma
A13: Días de capitalización | B13: '=IF(OR('02_Parametros'!$B$8="NIIF para las PYMES",NOT(OR(G5="Sí",G5="Si"))),0,MAX(IF(ISNA(MATCH(B5,'03_Auxiliar'!$A$5:$A$14,0)),'02_Parametros'!$B$5,IF(INDEX('03_Auxiliar'!$E$5:$E$14,MATCH(B5,'03_Auxiliar'!$A$5:$A$14,0))="",'02_Parametros'!$B$5,MIN(INDEX('03_Auxiliar'!$E$5:$E$14,MATCH(B5,'03_Auxiliar'!$A$5:$A$14,0)),'02_Parametros'!$B$5)))-MAX(C5,'02_Parametros'!$B$6),0)) | C13: Para adiciones de activos aptos (y solo en NIIF completas): días desde la fecha de la adición (o el inicio del ejercicio) hasta que el activo está disponible para uso según la hoja 03, o hasta el corte. Si no, cero. | D13: Fila 1: IF(OR(«NIIF completas»="NIIF para las PYMES"; NOT(OR(«Sí»="Sí"; «Sí»="Si"))); 0; MAX(IF(ISNA(MATCH(«OBRA-01»; [«Código» de «Auxiliar de activos (datos del cliente)», 10 filas]; 0)); «2025-12-31»; IF(INDEX([«Disponible para uso» de «Auxiliar de activos (datos del cliente)», 10 filas]; MATCH(«OBRA-01»; [«Código» de «Auxiliar de activos (datos del cliente)», 10 filas]; 0))=""; «2025-12-31»; MIN(INDEX([«Disponible para uso» de «Auxiliar de activos (datos del cliente)», 10 filas]; MATCH(«OBRA-01»; [«Código» de «Auxiliar de activos (datos del cliente)», 10 filas]; 0)); «2025-12-31»)))-MAX(«2025-03-01»; «2025-01-01»); 0)) → 305 | E13: «Apto» (esta hoja), «Activo» (esta hoja), «Fecha» (esta hoja), hoja «Parámetros», hoja «Auxiliar de activos (datos del cliente)» | F13: —
A14: Intereses capitalizables | B14: '="" | C14: Con el anexo de préstamos los intereses capitalizables se miden por activo en la hoja 12 (Capitalización de costos por préstamos), por eso aquí quedan en blanco. | D14: Fila 1: "" → (en blanco) | E14: datos cargados del cliente | F14: —
A15: Diferencia | B15: '=IF(J5="","",J5-H5) | C15: Intereses capitalizables menos intereses capitalizados por el cliente; con el anexo de préstamos queda en blanco porque la comparación se hace en la hoja 12. | D15: Fila 1: IF((vacío)=""; ""; (vacío)-9.000,00) → (en blanco) | E15: «Intereses capitalizables» (esta hoja), «Intereses capitalizados» (esta hoja) | F15: —
A16: Capitalizable | B16: '=IF(OR(ISNUMBER(SEARCH("repar",E5)),ISNUMBER(SEARCH("manten",E5))),"No: gasto (NIC 16.12)","Sí") | C16: «No: gasto» si el tipo de adición es una reparación o un mantenimiento, que no se capitalizan; «Sí» en los demás casos. | D16: Fila 1: IF(OR(ISNUMBER(SEARCH("repar"; «Capitalizable»)); ISNUMBER(SEARCH("manten"; «Capitalizable»))); "No: gasto (NIC 16.12)"; "Sí") → Sí | E16: «Tipo» (esta hoja) | F16: —

Sheet 11_Prestamos
A1: Préstamos para la construcción | H1: ⟵ Inicio | I1: ◀ Anterior | J1: Siguiente ▶
A2: Propiedad, planta y equipo · Cliente de muestra S.A. · corte 2025-12-31
A4: Préstamo | B4: Tipo | C4: Activo u obra | D4: Descripción | E4: Importe del préstamo | F4: Tasa nominal anual (%) | G4: Costo financiero del período | H4: (−) Rendimientos de la inversión temporal | I4: Capitalizable del específico (NIC 23.12)
A5: PR-01 | B5: Específico | C5: OBRA-01 | D5: Banco del Pacífico · nave industrial | E5: 120000 | F5: 9 | G5: 9000 | H5: 1200 | I5: =IF(B5<>"Específico","",IF(OR(G5="",H5=""),"",G5-H5))
A6: PR-02 | B6: General | D6: Banco Pichincha · capital de trabajo | E6: 400000 | F6: 8 | G6: 32000 | I6: =IF(B6<>"Específico","",IF(OR(G6="",H6=""),"",G6-H6))
A7: PR-03 | B7: General | D7: Produbanco · línea de crédito | E7: 100000 | F7: 12 | G7: 12000 | I7: =IF(B7<>"Específico","",IF(OR(G7="",H7=""),"",G7-H7))
A8: TOTAL | E8: =SUM(E5:E7) | G8: =SUM(G5:G7) | H8: =SUM(H5:H7) | I8: =SUM(I5:I7)
A10: ⓘ Cómo se calcula esta hoja
A11: Columna | B11: Fórmula (Excel) | C11: Cómo se calcula (sencillo) | D11: Ejemplo con números reales | E11: De dónde viene | F11: Norma
A12: Capitalizable del específico (NIC 23.12) | B12: '=IF(B5<>"Específico","",IF(OR(G5="",H5=""),"",G5-H5)) | C12: Solo para préstamos específicos: costo financiero del período menos los rendimientos de la inversión temporal de esos fondos. En blanco para préstamos generales o si falta un dato. | D12: Fila 1: IF(«Específico»<>"Específico"; ""; IF(OR(9.000,00=""; 1.200,00=""); ""; 9.000,00-1.200,00)) → 7.800,00 | E12: «Tipo» (esta hoja), «Costo financiero del período» (esta hoja), «(−) Rendimientos de la inversión temporal» (esta hoja) | F12: —

Sheet 12_Capitalizacion
A1: Capitalización de costos por préstamos por activo | H1: ⟵ Inicio | I1: ◀ Anterior | J1: Siguiente ▶
A2: Propiedad, planta y equipo · Cliente de muestra S.A. · corte 2025-12-31
A4: Activo | B4: Desembolsos aptos del período | C4: Base ponderada por tiempo | D4: Préstamo específico: importe | E4: Capitalizable del específico (NIC 23.12) | F4: % financiado con préstamos generales | G4: Base financiada con generales | H4: Tasa de capitalización (NIC 23.14) | I4: Capitalizable de los generales | J4: Capitalizable antes del tope | K4: Factor del tope (NIC 23.14) | L4: Capitalizable del período | M4: Intereses capitalizados registrados | N4: Diferencia
