Workbook

Sheet 00_Inicio
B2: AuditConsulting Auditores Cía. Ltda. · AUDIT-IA
B4: Préstamos y obligaciones financieras
B6: Cliente | C6: Cliente de muestra S.A. | D6: RUC | E6: 1790000000001
B7: Marco contable | C7: NIIF completas | D7: Fecha de corte | E7: 2025-12-31
B8: Preparó | C8: Ejercicio modelo | D8: Revisó | E8: Pendiente
B10: INDICADORES CLAVE
B11: Ajuste propuesto al pasivo | C11: Problemas encontrados
B12: 5075.37 | C12: 24
B15: IR A LA CÉDULA
B16: Carátula | C16: Programa | D16: Base técnica | E16: Resumen
B17: Parámetros | C17: Universo de préstamos | D17: Condiciones y tasa de interés efectiva | E17: Tabla de amortización
B18: Costo amortizado al corte y del ejercicio | C18: Comisiones y costos de transacción | D18: Recálculo de intereses | E18: Confirmación bancaria y pagos
B19: Covenants y dispensas | C19: Clasificación corriente / no corriente | D19: Endeudamiento y ratios de covenants (analítica, no requisito NIIF) | E19: Conciliación y ajuste
B20: Flujos de la modificación (adenda) descontados a la TIE original | C20: Prueba del 10 % (NIIF 9 3.3.2 y B3.3.6) | D20: Problemas encontrados | E20: Conclusión
B21: Control de revisión
B23: PANORAMA | N23: Datos de los gráficos (fórmulas a las cédulas)
N24: Cifras del resumen | O24: Importe (USD)
N25: ='01_Resumen'!A5 | O25: ='01_Resumen'!B5
N26: ='01_Resumen'!A6 | O26: ='01_Resumen'!B6
N27: ='01_Resumen'!A7 | O27: ='01_Resumen'!B7
N28: ='01_Resumen'!A8 | O28: ='01_Resumen'!B8
N29: ='01_Resumen'!A9 | O29: ='01_Resumen'!B9
N30: ='01_Resumen'!A10 | O30: ='01_Resumen'!B10
N31: ='01_Resumen'!A11 | O31: ='01_Resumen'!B11
N32: ='01_Resumen'!A12 | O32: ='01_Resumen'!B12
N33: ='01_Resumen'!A13 | O33: ='01_Resumen'!B13
N34: ='01_Resumen'!A14 | O34: ='01_Resumen'!B14
N35: ='01_Resumen'!A15 | O35: ='01_Resumen'!B15
N36: ='01_Resumen'!A16 | O36: ='01_Resumen'!B16
N38: Hallazgos de mayor impacto | O38: Importe (USD)
N39: Revelacion incumplimiento (×3) | O39: =SUMIFS('16_Problemas'!$C$5:$C$28,'16_Problemas'!$A$5:$A$28,"REVELACION_INCUMPLIMIENTO",'16_Problemas'!$C$5:$C$28,">0")-SUMIFS('16_Problemas'!$C$5:$C$28,'16_Problemas'!$A$5:$A$28,"REVELACION_INCUMPLIMIENTO",'16_Problemas'!$C$5:$C$28,"<0")
N40: Clasificacion cp lp (×2) | O40: =SUMIFS('16_Problemas'!$C$5:$C$28,'16_Problemas'!$A$5:$A$28,"CLASIFICACION_CP_LP",'16_Problemas'!$C$5:$C$28,">0")-SUMIFS('16_Problemas'!$C$5:$C$28,'16_Problemas'!$A$5:$A$28,"CLASIFICACION_CP_LP",'16_Problemas'!$C$5:$C$28,"<0")
N41: Covenant sin dispensa | O41: =SUMIFS('16_Problemas'!$C$5:$C$28,'16_Problemas'!$A$5:$A$28,"COVENANT_SIN_DISPENSA",'16_Problemas'!$C$5:$C$28,">0")-SUMIFS('16_Problemas'!$C$5:$C$28,'16_Problemas'!$A$5:$A$28,"COVENANT_SIN_DISPENSA",'16_Problemas'!$C$5:$C$28,"<0")
N42: Covenant posterior al corte | O42: =SUMIFS('16_Problemas'!$C$5:$C$28,'16_Problemas'!$A$5:$A$28,"COVENANT_POSTERIOR_AL_CORTE",'16_Problemas'!$C$5:$C$28,">0")-SUMIFS('16_Problemas'!$C$5:$C$28,'16_Problemas'!$A$5:$A$28,"COVENANT_POSTERIOR_AL_CORTE",'16_Problemas'!$C$5:$C$28,"<0")
N43: Modificacion sustancial | O43: =SUMIFS('16_Problemas'!$C$5:$C$28,'16_Problemas'!$A$5:$A$28,"MODIFICACION_SUSTANCIAL",'16_Problemas'!$C$5:$C$28,">0")-SUMIFS('16_Problemas'!$C$5:$C$28,'16_Problemas'!$A$5:$A$28,"MODIFICACION_SUSTANCIAL",'16_Problemas'!$C$5:$C$28,"<0")
N44: Pasivo diferencia (×4) | O44: =SUMIFS('16_Problemas'!$C$5:$C$28,'16_Problemas'!$A$5:$A$28,"PASIVO_DIFERENCIA",'16_Problemas'!$C$5:$C$28,">0")-SUMIFS('16_Problemas'!$C$5:$C$28,'16_Problemas'!$A$5:$A$28,"PASIVO_DIFERENCIA",'16_Problemas'!$C$5:$C$28,"<0")
N45: Confirmacion diferencia | O45: =SUMIFS('16_Problemas'!$C$5:$C$28,'16_Problemas'!$A$5:$A$28,"CONFIRMACION_DIFERENCIA",'16_Problemas'!$C$5:$C$28,">0")-SUMIFS('16_Problemas'!$C$5:$C$28,'16_Problemas'!$A$5:$A$28,"CONFIRMACION_DIFERENCIA",'16_Problemas'!$C$5:$C$28,"<0")
N46: Otros (4 tipos) | O46: =SUMIF('16_Problemas'!$C$5:$C$28,">0")-SUMIF('16_Problemas'!$C$5:$C$28,"<0")-((SUMIFS('16_Problemas'!$C$5:$C$28,'16_Problemas'!$A$5:$A$28,"REVELACION_INCUMPLIMIENTO",'16_Problemas'!$C$5:$C$28,">0")-SUMIFS('16_Problemas'!$C$5:$C$28,'16_Problemas'!$A$5:$A$28,"REVELACION_INCUMPLIMIENTO",'16_Problemas'!$C$5:$C$28,"<0"))+(SUMIFS('16_Problemas'!$C$5:$C$28,'16_Problemas'!$A$5:$A$28,"CLASIFICACION_CP_LP",'16_Problemas'!$C$5:$C$28,">0")-SUMIFS('16_Problemas'!$C$5:$C$28,'16_Problemas'!$A$5:$A$28,"CLASIFICACION_CP_LP",'16_Problemas'!$C$5:$C$28,"<0"))+(SUMIFS('16_Problemas'!$C$5:$C$28,'16_Problemas'!$A$5:$A$28,"COVENANT_SIN_DISPENSA",'16_Problemas'!$C$5:$C$28,">0")-SUMIFS('16_Problemas'!$C$5:$C$28,'16_Problemas'!$A$5:$A$28,"COVENANT_SIN_DISPENSA",'16_Problemas'!$C$5:$C$28,"<0"))+(SUMIFS('16_Problemas'!$C$5:$C$28,'16_Problemas'!$A$5:$A$28,"COVENANT_POSTERIOR_AL_CORTE",'16_Problemas'!$C$5:$C$28,">0")-SUMIFS('16_Problemas'!$C$5:$C$28,'16_Problemas'!$A$5:$A$28,"COVENANT_POSTERIOR_AL_CORTE",'16_Problemas'!$C$5:$C$28,"<0"))+(SUMIFS('16_Problemas'!$C$5:$C$28,'16_Problemas'!$A$5:$A$28,"MODIFICACION_SUSTANCIAL",'16_Problemas'!$C$5:$C$28,">0")-SUMIFS('16_Problemas'!$C$5:$C$28,'16_Problemas'!$A$5:$A$28,"MODIFICACION_SUSTANCIAL",'16_Problemas'!$C$5:$C$28,"<0"))+(SUMIFS('16_Problemas'!$C$5:$C$28,'16_Problemas'!$A$5:$A$28,"PASIVO_DIFERENCIA",'16_Problemas'!$C$5:$C$28,">0")-SUMIFS('16_Problemas'!$C$5:$C$28,'16_Problemas'!$A$5:$A$28,"PASIVO_DIFERENCIA",'16_Problemas'!$C$5:$C$28,"<0"))+(SUMIFS('16_Problemas'!$C$5:$C$28,'16_Problemas'!$A$5:$A$28,"CONFIRMACION_DIFERENCIA",'16_Problemas'!$C$5:$C$28,">0")-SUMIFS('16_Problemas'!$C$5:$C$28,'16_Problemas'!$A$5:$A$28,"CONFIRMACION_DIFERENCIA",'16_Problemas'!$C$5:$C$28,"<0")))

Sheet 00_Caratula
A1: Carátula | H1: ⟵ Inicio | J1: Siguiente ▶
A2: Préstamos y obligaciones financieras · Cliente de muestra S.A. · corte 2025-12-31
A4: Concepto | B4: Detalle
A5: Firma | B5: AuditConsulting Auditores Cía. Ltda.
A6: Cliente | B6: Cliente de muestra S.A.
A7: RUC | B7: 1790000000001
A8: Ejercicio | B8: 2025
A9: Fecha de corte | B9: 2025-12-31
A10: Marco contable | B10: NIIF completas
A11: Herramienta | B11: Préstamos y obligaciones financieras
A12: Rubro | B12: Préstamos y obligaciones financieras
A13: Motor | B13: prestamos_obligaciones 1.0
A14: Versión del papel | B14: v1
A15: Estado | B15: MUESTRA
... A17: Revisó | B17: Pendiente
A18: Aprobó
A19: Fecha de aprobación
A20: Huella de la ejecución (SHA-256)

Sheet 00_Programa
A1: Programa | H1: ⟵ Inicio | I1: ◀ Anterior | J1: Siguiente ▶
A2: Préstamos y obligaciones financieras · Cliente de muestra S.A. · corte 2025-12-31
A4: Código | B4: Objetivo | C4: Afirmación | D4: Procedimiento | E4: Evidencia | F4: Criterio | G4: Referencia
A5: DEU-01 | B5: Existencia e integridad de la deuda | C5: Existencia / Integridad | D5: Confirmar con cada banco saldo, tasa, garantías y covenants; conciliar confirmado vs registrado y vs tabla | E5: Confirmaciones bancarias, cédula 09 | F5: Diferencias explicadas | G5: NIA 505 · NIIF 9 3.1.1
A6: DEU-02 | B6: Tabla de amortización e intereses | C6: Valoración / Corte | D6: Rehacer la tabla contractual, recalcular el interés del ejercicio y el devengado al corte | E6: Contratos, tablas del banco, cédulas 05, 06 y 08 | F6: Diferencias cuantificadas | G6: NIIF 9 4.2.1, 5.3.1 y Apéndice A (método del interés efectivo) · PYMES 11.15–11.20
A7: DEU-03 | B7: Tasa de interés efectiva y comisiones | C7: Valoración | D7: Calcular la TIE con los costos de transacción y comparar el costo amortizado con lo registrado | E7: Liquidaciones de desembolso, cédulas 04 y 07 | F7: Costo amortizado a la TIE | G7: NIIF 9 5.1.1 y Apéndice A · PYMES 11.13
A8: DEU-04 | B8: Covenants y dispensas | C8: Presentación | D8: Recalcular los ratios pactados, verificar la fecha de medición de cada condición, los incumplimientos y la fecha y alcance de las dispensas | E8: Contratos, cartas de dispensa, cédulas 10 y 12 | F8: NIC 1 72B (solo inciden las condiciones a cumplir al cierre o antes), 74–75 y 76ZA (revelación de las condiciones futuras) | G8: NIC 1 69–76 y 76ZA · PYMES 4.7 (NIC 1 72B por analogía, 10.6)
A9: DEU-08 | B9: Revelación de impagos e incumplimientos | C9: Presentación / Revelación | D9: Identificar impagos e infracciones no subsanados al cierre y verificar su revelación en las notas | E9: Contratos, estados de cuenta, cartas del banco, notas a los estados financieros | F9: Detalle del incumplimiento, importe en libros y si se subsanó o renegoció antes de la autorización | G9: NIIF 7 párr. 18–19 · PYMES 11.47 · NIA 560
A10: DEU-05 | B10: Clasificación corriente / no corriente | C10: Presentación | D10: Recalcular lo que vence en 12 meses y aplicar el efecto de los covenants | E10: Cédula 11 | F10: NIC 1 69 c), 72B y 74 | G10: NIC 1 69–76 · PYMES 4.7
A11: DEU-06 | B11: Endeudamiento y capacidad de pago | C11: Presentación / Revelación | D11: Analizar deuda/activos, deuda/patrimonio, deuda/EBITDA y cobertura (analítica, no requisito NIIF). Para el DSCR, obtener del contrato su definición (numerador y denominador) y usarla; sin definición contractual el DSCR se presenta como «DSCR analítico de la firma», como indicador | E11: Estados financieros, contratos de préstamo, cédula 12 | F11: El contrato manda: el «DSCR analítico de la firma» no concluye incumplimiento del covenant | G11: NIA 520 párr. 5–6 · NIA 570 · NIIF 7 18–19
A12: DEU-07 | B12: Modificaciones y refinanciaciones | C12: Valoración | D12: Obtener la adenda con sus flujos, cargar en el anexo de flujos los contractuales originales restantes y los modificados y resolver la prueba del 10 % descontando a la tasa de interés efectiva original | E12: Adendas con su tabla de flujos, liquidaciones de comisiones, confirmaciones, cédulas 14 y 15 | F12: Sin flujos comparables la prueba no concluye: «dato insuficiente: conclusión bloqueada»; nunca se presume «no sustancial» | G12: NIIF 9 3.3.2 y B3.3.6 · PYMES 11.37 (sin umbral; el 10 % por analogía, 10.6) · NIA 560

Sheet 00_Fuentes
A1: Base técnica | H1: ⟵ Inicio | I1: ◀ Anterior | J1: Siguiente ▶
A2: Préstamos y obligaciones financieras · Cliente de muestra S.A. · corte 2025-12-31
A4: Categoría | B4: Documento | C4: Párrafos | D4: URL | E4: Verificada
A5: NIA · NIA 505 | B5: Confirmación externa de saldos, tasas, garantías y covenants con los bancos. | C5: párr. 7 y 14
A6: NIA · NIA 500 | B6: Exactitud e integridad del anexo de préstamos contra el mayor y los contratos. | C6: párr. 9
A7: NIA · NIA 540 (Revisada) | B7: Método (TIE), datos (contratos) y supuestos del costo amortizado. | C7: párr. 13, 18–30 (22–25: métodos, supuestos significativos y datos)
A8: NIA · NIA 560 | B8: Dispensas, refinanciaciones y pagos posteriores al cierre. | C8: párr. 6
A9: NIA · NIA 570 (Revisada) | B9: Incumplimientos de covenants y capacidad de pago como indicios de empresa en marcha. La NIA 570 (Revisada 2024) rige para períodos desde el 15-12-2026. | C9: párr. 10–16

Sheet 01_Resumen
A1: Resumen | H1: ⟵ Inicio | I1: ◀ Anterior | J1: Siguiente ▶
A2: Préstamos y obligaciones financieras · Cliente de muestra S.A. · corte 2025-12-31
A4: Concepto | B4: Importe
A5: Obligaciones financieras registradas (capital + intereses) | B5: ='13_Conciliacion'!E12
A6: Costo amortizado recalculado (con interés devengado) | B6: ='13_Conciliacion'!B12
A7: Ajuste propuesto al pasivo | B7: =B6-B5
A8: Capital contractual según tablas | B8: =SUM('06_Costo_amortizado'!E5:E11)
A9: Interés contractual devengado al corte | B9: =SUM('06_Costo_amortizado'!F5:F11)
A10: Intereses por pagar registrados | B10: ='13_Conciliacion'!D12
A11: Pasivo corriente auditado | B11: ='13_Conciliacion'!G12
A12: Pasivo no corriente auditado | B12: ='13_Conciliacion'!H12
A13: Reclasificación a corriente por covenants | B13: =SUM('11_Clasificacion'!G5:G11)-SUM('11_Clasificacion'!E5:E11)
A14: Gasto financiero del ejercicio (TIE) | B14: ='13_Conciliacion'!I12
A15: Diferencia de gasto financiero (préstamos con gasto registrado) | B15: =SUM('08_Intereses'!G5:G11)
A16: Costos de transacción por amortizar al corte | B16: =SUM('07_Comisiones'!G5:G11)
A18: ⓘ Cómo se calcula esta hoja
A19: Columna | B19: Fórmula (Excel) | C19: Cómo se calcula (sencillo) | D19: Ejemplo con números reales | E19: De dónde viene | F19: Norma
A20: Importe | B20: '='13_Conciliacion'!E12 | C20: Trae cada importe de la cédula donde se calcula, concepto por concepto: los saldos auditados, registrados, el ajuste, la clasificación y el gasto salen de los totales de la hoja 13 (Conciliación y ajuste); el capital y el interés devengado, de la hoja 06 (Costo amortizado); la diferencia de gasto, de la hoja 08; los costos por amortizar, de la hoja 07; la reclasificación por covenants, de la hoja 11. El ajuste es el pasivo recalculado menos el registrado de este mismo resumen. | D20: Fila 1: 654.889,82 → 654.889,82 | E20: hoja «Conciliación y ajuste» | F20: —

Sheet 02_Parametros
A1: Parámetros | H1: ⟵ Inicio | I1: ◀ Anterior | J1: Siguiente ▶
A2: Préstamos y obligaciones financieras · Cliente de muestra S.A. · corte 2025-12-31
A4: Parámetro | B4: Valor | C4: Sustento
A5: Fecha de corte | B5: 46022 | C5: Ficha del encargo
A6: Inicio del ejercicio (corte − 12 meses) | B6: 45657 | C6: Base del gasto financiero del ejercicio
A7: Marco y ruta de cálculo | B7: NIIF completas · NIIF 9 (5.1.1, 4.2.1, 5.3.1 y Apéndice A) y NIC 1 69–76 (modificaciones 2020/2022, vigentes desde 2024) | C7: El modelo de costo amortizado es el mismo en ambos marcos; cambian las citas
A8: Total de activos de la entidad al corte | B8: 2500000 | C8: Estados financieros al corte
A9: Patrimonio de la entidad al corte | B9: 800000 | C9: Estados financieros al corte (admite negativo)
A10: EBITDA del ejercicio | B10: 300000 | C10: Estado de resultados; use la definición del contrato, que manda sobre cualquier otra
A11: EBIT (utilidad operativa) del ejercicio | B11: 220000 | C11: Estado de resultados
A12: Efectivo disponible para el servicio de la deuda | B12: 200000 | C12: Use la definición del contrato de préstamo, que manda sobre cualquier otra
A13: Base de la cobertura de intereses (EBITDA / EBIT) | B13: EBITDA | C13: EBITDA o EBIT, según el contrato
A14: Límite máximo deuda / activos (veces) | B14: 0.6 | C14: Contrato de préstamo
A15: Límite máximo deuda / patrimonio (veces) | B15: 1.2 | C15: Contrato de préstamo
A16: Límite máximo deuda / EBITDA (veces) | B16: 1.8 | C16: Contrato de préstamo
A17: Límite mínimo de cobertura de intereses (veces) | B17: 3 | C17: Contrato de préstamo
A18: Límite mínimo DSCR (veces) | B18: 1.25 | C18: Contrato de préstamo
A19: Definición contractual del DSCR (numerador ÷ denominador, según el contrato) | B19: Flujo de caja operativo antes de intereses ÷ servicio de la deuda del ejercicio (cláusula 8.2 del contrato) | C19: Transcriba la definición del contrato (numerador ÷ denominador). El contrato manda: sin esta definición el DSCR se muestra como «DSCR analítico de la firma» y no concluye incumplimiento del covenant
A20: Servicio de la deuda del DSCR según el contrato | C20: Contrato de préstamo; vacío = servicio de la deuda del ejercicio según las tablas (cédula 12)

Sheet 03_Prestamos
A1: Universo de préstamos | H1: ⟵ Inicio | I1: ◀ Anterior | J1: Siguiente ▶
A2: Préstamos y obligaciones financieras · Cliente de muestra S.A. · corte 2025-12-31
A4: Operación | B4: Banco / acreedor | C4: Fecha de desembolso | D4: Monto desembolsado | E4: Plazo (meses) | F4: Tasa nominal anual (%) | G4: Periodicidad de pago (mensual/trimestral/semestral/anual) | H4: Sistema de amortización (francés/alemán/bullet) | I4: Comisiones y costos de transacción | J4: Tratamiento de las comisiones por el cliente (TIE/gasto) | K4: Pagos realizados en el año (capital + interés) | L4: Saldo de capital confirmado por el banco | M4: Saldo de capital registrado | N4: Intereses por pagar registrados | O4: Gasto financiero registrado del año | P4: Porción corriente registrada | Q4: Covenant (deuda/activos, deuda/patrimonio, deuda/EBITDA, cobertura de intereses, DSCR) | R4: Incumplimiento de covenant declarado (sí/no) | S4: Fecha de la dispensa del banco | T4: Fin del período de gracia de la dispensa | U4: Fecha de medición del covenant | V4: Modificación de condiciones en el ejercicio (sí/no) | W4: Fecha de la modificación (adenda) | X4: Comisiones pagadas al prestamista netas de las recibidas por la modificación
A5: OP-101 | B5: Banco Pichincha | C5: 45306 | D5: 120000 | E5: 36 | F5: 11 | G5: Mensual | H5: Francés | I5: 2400 | J5: Gasto | K5: 47143.75 | L5: 47940.12 | M5: 47940.12 | N5: 226.81 | O5: 7478.25 | V5: No
A6: OP-102 | B6: Produbanco | C6: 45717 | D6: 200000 | E6: 60 | F6: 10 | G6: Trimestral | H6: Alemán | I6: 3000 | J6: TIE | K6: 44250 | L6: 170000 | M6: 167760.65 | O6: 15010.65 | P6: 41494.17 | Q6: Deuda / EBITDA | R6: Sí | S6: 46042 | T6: 46568 | U6: 46022 | V6: No
A7: OP-103 | B7: Banco Guayaquil | C7: 45108 | D7: 300000 | E7: 48 | F7: 9.5 | G7: Semestral | H7: Francés | K7: 91897.18 | L7: 163882.07 | M7: 163882.07 | N7: 7742.09 | O7: 17317.78 | P7: 70000 | Q7: Cobertura de intereses | R7: No | V7: Sí | W7: 45992 | X7: 1500
A8: OP-104 | B8: Banco del Pacífico | C8: 45838 | D8: 150000 | E8: 24 | F8: 12 | G8: Semestral | H8: Bullet | I8: 1500 | J8: TIE | K8: 9000 | L8: 150000 | M8: 145000 | N8: 49.45 | O8: 9392.86 | V8: No
A9: OP-105 | B9: Corporación Financiera Nacional | C9: 44562 | D9: 80000 | E9: 60 | F9: 8 | G9: Mensual | H9: Francés | K9: 19465.34 | L9: 20135.32 | M9: 20135.32 | N9: 129.91 | O9: 2250.69 | P9: 18653.85 | Q9: Deuda / patrimonio | R9: Sí | S9: 46006 | T9: 46477 | U9: 46022 | V9: Sí
A10: OP-106 | B10: Banco Internacional | C10: 45931 | D10: 50000 | E10: 12 | F10: 13 | G10: Mensual | H10: Francés | K10: 8931.73 | L10: 42109.09 | M10: 42109.09 | N10: 441.47 | O10: 1482.29 | P10: 42550.56 | V10: No
A11: OP-107 | B11: Banco Bolivariano | C11: 45474 | D11: 100000 | E11: 36 | F11: 10.5 | G11: Trimestral | H11: Alemán | I11: 1000 | J11: TIE | K11: 40000 | L11: 58333.33 | M11: 57958.23 | N11: 1514.61 | O11: 7881.2 | P11: 34938.2 | Q11: DSCR | U11: 46203 | V11: No

Sheet 04_Condiciones_TIE
A1: Condiciones y tasa de interés efectiva | H1: ⟵ Inicio | I1: ◀ Anterior | J1: Siguiente ▶
A2: Préstamos y obligaciones financieras · Cliente de muestra S.A. · corte 2025-12-31
A4: Operación | B4: Sistema | C4: Monto | D4: Comisiones y costos | E4: Importe neto recibido (5.1.1 / 11.13) | F4: Plazo (meses) | G4: Meses por período | H4: Períodos | I4: Tasa nominal anual (%) | J4: Tasa periódica nominal | K4: Cuota fija (francés) | L4: TIE periódica (TIR de los flujos) | M4: TIE anual efectiva | N4: Tasa efectiva anual contractual | O4: Efecto de las comisiones en la tasa
A5: OP-101 | B5: ='03_Prestamos'!H5 | C5: ='03_Prestamos'!D5 | D5: =N('03_Prestamos'!I5) | E5: =C5-D5 | F5: ='03_Prestamos'!E5 | G5: =IF('03_Prestamos'!G5="Mensual",1,IF('03_Prestamos'!G5="Trimestral",3,IF('03_Prestamos'!G5="Semestral",6,12))) | H5: =F5/G5 | I5: ='03_Prestamos'!F5 | J5: =I5/100*G5/12 | K5: =IF(B5="Francés",PMT(J5,H5,-C5),"") | L5: =IRR('05_Tabla_amortizacion'!I5:I41,J5) | M5: =(1+L5)^(12/G5)-1 | N5: =(1+J5)^(12/G5)-1 | O5: =M5-N5
A6: OP-102 | B6: ='03_Prestamos'!H6 | C6: ='03_Prestamos'!D6 | D6: =N('03_Prestamos'!I6) | E6: =C6-D6 | F6: ='03_Prestamos'!E6 | G6: =IF('03_Prestamos'!G6="Mensual",1,IF('03_Prestamos'!G6="Trimestral",3,IF('03_Prestamos'!G6="Semestral",6,12))) | H6: =F6/G6 | I6: ='03_Prestamos'!F6 | J6: =I6/100*G6/12 | K6: =IF(B6="Francés",PMT(J6,H6,-C6),"") | L6: =IRR('05_Tabla_amortizacion'!I42:I62,J6) | M6: =(1+L6)^(12/G6)-1 | N6: =(1+J6)^(12/G6)-1 | O6: =M6-N6
A7: OP-103 | B7: ='03_Prestamos'!H7 | C7: ='03_Prestamos'!D7 | D7: =N('03_Prestamos'!I7) | E7: =C7-D7 | F7: ='03_Prestamos'!E7 | G7: =IF('03_Prestamos'!G7="Mensual",1,IF('03_Prestamos'!G7="Trimestral",3,IF('03_Prestamos'!G7="Semestral",6,12))) | H7: =F7/G7 | I7: ='03_Prestamos'!F7 | J7: =I7/100*G7/12 | K7: =IF(B7="Francés",PMT(J7,H7,-C7),"") | L7: =IRR('05_Tabla_amortizacion'!I63:I71,J7) | M7: =(1+L7)^(12/G7)-1 | N7: =(1+J7)^(12/G7)-1 | O7: =M7-N7
A8: OP-104 | B8: ='03_Prestamos'!H8 | C8: ='03_Prestamos'!D8 | D8: =N('03_Prestamos'!I8) | E8: =C8-D8 | F8: ='03_Prestamos'!E8 | G8: =IF('03_Prestamos'!G8="Mensual",1,IF('03_Prestamos'!G8="Trimestral",3,IF('03_Prestamos'!G8="Semestral",6,12))) | H8: =F8/G8 | I8: ='03_Prestamos'!F8 | J8: =I8/100*G8/12 | K8: =IF(B8="Francés",PMT(J8,H8,-C8),"") | L8: =IRR('05_Tabla_amortizacion'!I72:I76,J8) | M8: =(1+L8)^(12/G8)-1 | N8: =(1+J8)^(12/G8)-1 | O8: =M8-N8
A9: OP-105 | B9: ='03_Prestamos'!H9 | C9: ='03_Prestamos'!D9 | D9: =N('03_Prestamos'!I9) | E9: =C9-D9 | F9: ='03_Prestamos'!E9 | G9: =IF('03_Prestamos'!G9="Mensual",1,IF('03_Prestamos'!G9="Trimestral",3,IF('03_Prestamos'!G9="Semestral",6,12))) | H9: =F9/G9 | I9: ='03_Prestamos'!F9 | J9: =I9/100*G9/12 | K9: =IF(B9="Francés",PMT(J9,H9,-C9),"") | L9: =IRR('05_Tabla_amortizacion'!I77:I137,J9) | M9: =(1+L9)^(12/G9)-1 | N9: =(1+J9)^(12/G9)-1 | O9: =M9-N9
A10: OP-106 | B10: ='03_Prestamos'!H10 | C10: ='03_Prestamos'!D10 | D10: =N('03_Prestamos'!I10) | E10: =C10-D10 | F10: ='03_Prestamos'!E10 | G10: =IF('03_Prestamos'!G10="Mensual",1,IF('03_Prestamos'!G10="Trimestral",3,IF('03_Prestamos'!G10="Semestral",6,12))) | H10: =F10/G10 | I10: ='03_Prestamos'!F10 | J10: =I10/100*G10/12 | K10: =IF(B10="Francés",PMT(J10,H10,-C10),"") | L10: =IRR('05_Tabla_amortizacion'!I138:I150,J10) | M10: =(1+L10)^(12/G10)-1 | N10: =(1+J10)^(12/G10)-1 | O10: =M10-N10
A11: OP-107 | B11: ='03_Prestamos'!H11 | C11: ='03_Prestamos'!D11 | D11: =N('03_Prestamos'!I11) | E11: =C11-D11 | F11: ='03_Prestamos'!E11 | G11: =IF('03_Prestamos'!G11="Mensual",1,IF('03_Prestamos'!G11="Trimestral",3,IF('03_Prestamos'!G11="Semestral",6,12))) | H11: =F11/G11 | I11: ='03_Prestamos'!F11 | J11: =I11/100*G11/12 | K11: =IF(B11="Francés",PMT(J11,H11,-C11),"") | L11: =IRR('05_Tabla_amortizacion'!I151:I163,J11) | M11: =(1+L11)^(12/G11)-1 | N11: =(1+J11)^(12/G11)-1 | O11: =M11-N11
A12: TOTAL | C12: =SUM(C5:C11) | D12: =SUM(D5:D11) | E12: =SUM(E5:E11)
A14: ⓘ Cómo se calcula esta hoja
A15: Columna | B15: Fórmula (Excel) | C15: Cómo se calcula (sencillo) | D15: Ejemplo con números reales | E15: De dónde viene | F15: Norma
A16: Sistema | B16: '='03_Prestamos'!H5 | C16: Copia el sistema de amortización del préstamo (francés, alemán o bullet) tal como quedó en la hoja 03 (Universo de préstamos). | D16: Fila 1: «Francés» → Francés | E16: hoja «Universo de préstamos» | F16: —
A17: Monto | B17: '='03_Prestamos'!D5 | C17: Copia el monto desembolsado por el banco para esta operación desde la hoja 03 (Universo de préstamos). | D17: Fila 1: 120.000,00 → 120.000,00 | E17: hoja «Universo de préstamos» | F17: —
A18: Comisiones y costos | B18: '=N('03_Prestamos'!I5) | C18: Trae las comisiones y costos de transacción pagados al obtener el préstamo desde la hoja 03 (Universo de préstamos); si el cliente no los informó, se toman como cero. | D18: Fila 1: N(2.400,00) → 2.400,00 | E18: hoja «Universo de préstamos» | F18: —
A19: Importe neto recibido (5.1.1 / 11.13) | B19: '=C5-D5 | C19: Resta al monto desembolsado las comisiones y costos de transacción: es el dinero que realmente recibió la entidad y el punto de partida del costo amortizado. | D19: Fila 1: 120.000,00-2.400,00 → 117.600,00 | E19: «Monto» (esta hoja), «Comisiones y costos» (esta hoja) | F19: —
A20: Plazo (meses) | B20: '='03_Prestamos'!E5 | C20: Copia el plazo total del préstamo, en meses, informado en la hoja 03 (Universo de préstamos). | D20: Fila 1: 36,00 → 36 | E20: hoja «Universo de préstamos» | F20: —
A21: Meses por período | B21: '=IF('03_Prestamos'!G5="Mensual",1,IF('03_Prestamos'!G5="Trimestral",3,IF('03_Prestamos'!G5="Semestral",6,12))) | C21: Convierte la periodicidad de pago de la hoja 03 en meses: mensual = 1, trimestral = 3, semestral = 6 y cualquier otra (anual) = 12. | D21: Fila 1: IF(«Mensual»="Mensual"; 1; IF(«Mensual»="Trimestral"; 3; IF(«Mensual»="Semestral"; 6; 12))) → 1 | E21: hoja «Universo de préstamos» | F21: —
A22: Períodos | B22: '=F5/G5 | C22: Divide el plazo en meses para los meses de cada período: es el número de cuotas que tiene el préstamo. | D22: Fila 1: 36/1 → 36 | E22: «Plazo (meses)» (esta hoja), «Meses por período» (esta hoja) | F22: —
A23: Tasa nominal anual (%) | B23: '='03_Prestamos'!F5 | C23: Copia la tasa de interés nominal anual pactada en el contrato, tal como figura en la hoja 03 (Universo de préstamos). | D23: Fila 1: 11,00 → 11,00 | E23: hoja «Universo de préstamos» | F23: —
A24: Tasa periódica nominal | B24: '=I5/100*G5/12 | C24: Pasa la tasa nominal anual a la tasa de cada período: la divide para 100 y la multiplica por los meses del período sobre 12. | D24: Fila 1: 11,00/100*1/12 → 0,92 % | E24: «Tasa nominal anual (%)» (esta hoja), «Meses por período» (esta hoja) | F24: —
A25: Cuota fija (francés) | B25: '=IF(B5="Francés",PMT(J5,H5,-C5),"") | C25: Solo para el sistema francés: calcula con la función PAGO la cuota constante que amortiza el monto en el número de períodos a la tasa periódica nominal. En alemán o bullet queda en blanco. | D25: Fila 1: IF(«Francés»="Francés"; PMT(0,92 %; 36; -120.000,00); "") → 3.928,65 | E25: «Sistema» (esta hoja), «Tasa periódica nominal» (esta hoja), «Períodos» (esta hoja), «Monto» (esta hoja) | F25: —
A26: TIE periódica (TIR de los flujos) | B26: '=IRR('05_Tabla_amortizacion'!I5:I41,J5) | C26: Calcula la TIR de los flujos de esta operación en la hoja 05 (Tabla de amortización): el importe neto recibido en negativo y luego cada pago. Es la tasa que iguala los pagos con lo recibido, e incluye el efecto de las comisiones. | D26: Fila 1: IRR([«Flujo para la TIE» de «Tabla de amortización», 37 filas]; 0,92 %) → 1,03 % | E26: «Tasa periódica nominal» (esta hoja), hoja «Tabla de amortización» | F26: —
... A29: Efecto de las comisiones en la tasa | B29: '=M5-N5 | C29: Resta la tasa efectiva anual contractual de la TIE anual efectiva: muestra cuántos puntos de tasa suman las comisiones y costos de transacción. | D29: Fila 1: 13,13 %-11,57 % → 1,56 % | E29: «TIE anual efectiva» (esta hoja), «Tasa efectiva anual contractual» (esta hoja) | F29: —

Sheet 05_Tabla_amortizacion
A1: Tabla de amortización | H1: ⟵ Inicio | I1: ◀ Anterior | J1: Siguiente ▶
A2: Préstamos y obligaciones financieras · Cliente de muestra S.A. · corte 2025-12-31
A4: Operación | B4: Período | C4: Vencimiento | D4: Pago contractual | E4: Capital inicial | F4: Interés nominal | G4: Capital amortizado | H4: Capital final | I4: Flujo para la TIE | J4: Costo amortizado inicial | K4: Interés a la TIE (Apéndice A) | L4: Amortización (pago − interés) | M4: Costo amortizado final
A5: OP-101 | B5: 0 | C5: 45306 | H5: ='04_Condiciones_TIE'!C5 | I5: =-'04_Condiciones_TIE'!E5 | M5: ='04_Condiciones_TIE'!E5
A6: OP-101 | B6: 1 | C6: 45337 | D6: =IF('04_Condiciones_TIE'!B5="Francés",'04_Condiciones_TIE'!K5,IF('04_Condiciones_TIE'!B5="Alemán",'04_Condiciones_TIE'!C5/'04_Condiciones_TIE'!H5+F6,IF(B6<'04_Condiciones_TIE'!H5,F6,F6+E6))) | E6: =H5 | F6: =E6*'04_Condiciones_TIE'!J5 | G6: =D6-F6 | H6: =E6-G6 | I6: =D6 | J6: =M5 | K6: =J6*'04_Condiciones_TIE'!L5 | L6: =D6-K6 | M6: =J6-L6
A7: OP-101 | B7: 2 | C7: 45366 | D7: =IF('04_Condiciones_TIE'!B5="Francés",'04_Condiciones_TIE'!K5,IF('04_Condiciones_TIE'!B5="Alemán",'04_Condiciones_TIE'!C5/'04_Condiciones_TIE'!H5+F7,IF(B7<'04_Condiciones_TIE'!H5,F7,F7+E7))) | E7: =H6 | F7: =E7*'04_Condiciones_TIE'!J5 | G7: =D7-F7 | H7: =E7-G7 | I7: =D7 | J7: =M6 | K7: =J7*'04_Condiciones_TIE'!L5 | L7: =D7-K7 | M7: =J7-L7
A8: OP-101 | B8: 3 | C8: 45397 | D8: =IF('04_Condiciones_TIE'!B5="Francés",'04_Condiciones_TIE'!K5,IF('04_Condiciones_TIE'!B5="Alemán",'04_Condiciones_TIE'!C5/'04_Condiciones_TIE'!H5+F8,IF(B8<'04_Condiciones_TIE'!H5,F8,F8+E8))) | E8: =H7 | F8: =E8*'04_Condiciones_TIE'!J5 | G8: =D8-F8 | H8: =E8-G8 | I8: =D8 | J8: =M7 | K8: =J8*'04_Condiciones_TIE'!L5 | L8: =D8-K8 | M8: =J8-L8
A9: OP-101 | B9: 4 | C9: 45427 | D9: =IF('04_Condiciones_TIE'!B5="Francés",'04_Condiciones_TIE'!K5,IF('04_Condiciones_TIE'!B5="Alemán",'04_Condiciones_TIE'!C5/'04_Condiciones_TIE'!H5+F9,IF(B9<'04_Condiciones_TIE'!H5,F9,F9+E9))) | E9: =H8 | F9: =E9*'04_Condiciones_TIE'!J5 | G9: =D9-F9 | H9: =E9-G9 | I9: =D9 | J9: =M8 | K9: =J9*'04_Condiciones_TIE'!L5 | L9: =D9-K9 | M9: =J9-L9
A10: OP-101 | B10: 5 | C10: 45458 | D10: =IF('04_Condiciones_TIE'!B5="Francés",'04_Condiciones_TIE'!K5,IF('04_Condiciones_TIE'!B5="Alemán",'04_Condiciones_TIE'!C5/'04_Condiciones_TIE'!H5+F10,IF(B10<'04_Condiciones_TIE'!H5,F10,F10+E10))) | E10: =H9 | F10: =E10*'04_Condiciones_TIE'!J5 | G10: =D10-F10 | H10: =E10-G10 | I10: =D10 | J10: =M9 | K10: =J10*'04_Condiciones_TIE'!L5 | L10: =D10-K10 | M10: =J10-L10
A11: OP-101 | B11: 6 | C11: 45488 | D11: =IF('04_Condiciones_TIE'!B5="Francés",'04_Condiciones_TIE'!K5,IF('04_Condiciones_TIE'!B5="Alemán",'04_Condiciones_TIE'!C5/'04_Condiciones_TIE'!H5+F11,IF(B11<'04_Condiciones_TIE'!H5,F11,F11+E11))) | E11: =H10 | F11: =E11*'04_Condiciones_TIE'!J5 | G11: =D11-F11 | H11: =E11-G11 | I11: =D11 | J11: =M10 | K11: =J11*'04_Condiciones_TIE'!L5 | L11: =D11-K11 | M11: =J11-L11
A12: OP-101 | B12: 7 | C12: 45519 | D12: =IF('04_Condiciones_TIE'!B5="Francés",'04_Condiciones_TIE'!K5,IF('04_Condiciones_TIE'!B5="Alemán",'04_Condiciones_TIE'!C5/'04_Condiciones_TIE'!H5+F12,IF(B12<'04_Condiciones_TIE'!H5,F12,F12+E12))) | E12: =H11 | F12: =E12*'04_Condiciones_TIE'!J5 | G12: =D12-F12 | H12: =E12-G12 | I12: =D12 | J12: =M11 | K12: =J12*'04_Condiciones_TIE'!L5 | L12: =D12-K12 | M12: =J12-L12
A13: OP-101 | B13: 8 | C13: 45550 | D13: =IF('04_Condiciones_TIE'!B5="Francés",'04_Condiciones_TIE'!K5,IF('04_Condiciones_TIE'!B5="Alemán",'04_Condiciones_TIE'!C5/'04_Condiciones_TIE'!H5+F13,IF(B13<'04_Condiciones_TIE'!H5,F13,F13+E13))) | E13: =H12 | F13: =E13*'04_Condiciones_TIE'!J5 | G13: =D13-F13 | H13: =E13-G13 | I13: =D13 | J13: =M12 | K13: =J13*'04_Condiciones_TIE'!L5 | L13: =D13-K13 | M13: =J13-L13
A14: OP-101 | B14: 9 | C14: 45580 | D14: =IF('04_Condiciones_TIE'!B5="Francés",'04_Condiciones_TIE'!K5,IF('04_Condiciones_TIE'!B5="Alemán",'04_Condiciones_TIE'!C5/'04_Condiciones_TIE'!H5+F14,IF(B14<'04_Condiciones_TIE'!H5,F14,F14+E14))) | E14: =H13 | F14: =E14*'04_Condiciones_TIE'!J5 | G14: =D14-F14 | H14: =E14-G14 | I14: =D14 | J14: =M13 | K14: =J14*'04_Condiciones_TIE'!L5 | L14: =D14-K14 | M14: =J14-L14
A15: OP-101 | B15: 10 | C15: 45611 | D15: =IF('04_Condiciones_TIE'!B5="Francés",'04_Condiciones_TIE'!K5,IF('04_Condiciones_TIE'!B5="Alemán",'04_Condiciones_TIE'!C5/'04_Condiciones_TIE'!H5+F15,IF(B15<'04_Condiciones_TIE'!H5,F15,F15+E15))) | E15: =H14 | F15: =E15*'04_Condiciones_TIE'!J5 | G15: =D15-F15 | H15: =E15-G15 | I15: =D15 | J15: =M14 | K15: =J15*'04_Condiciones_TIE'!L5 | L15: =D15-K15 | M15: =J15-L15
A16: OP-101 | B16: 11 | C16: 45641 | D16: =IF('04_Condiciones_TIE'!B5="Francés",'04_Condiciones_TIE'!K5,IF('04_Condiciones_TIE'!B5="Alemán",'04_Condiciones_TIE'!C5/'04_Condiciones_TIE'!H5+F16,IF(B16<'04_Condiciones_TIE'!H5,F16,F16+E16))) | E16: =H15 | F16: =E16*'04_Condiciones_TIE'!J5 | G16: =D16-F16 | H16: =E16-G16 | I16: =D16 | J16: =M15 | K16: =J16*'04_Condiciones_TIE'!L5 | L16: =D16-K16 | M16: =J16-L16
A17: OP-101 | B17: 12 | C17: 45672 | D17: =IF('04_Condiciones_TIE'!B5="Francés",'04_Condiciones_TIE'!K5,IF('04_Condiciones_TIE'!B5="Alemán",'04_Condiciones_TIE'!C5/'04_Condiciones_TIE'!H5+F17,IF(B17<'04_Condiciones_TIE'!H5,F17,F17+E17))) | E17: =H16 | F17: =E17*'04_Condiciones_TIE'!J5 | G17: =D17-F17 | H17: =E17-G17 | I17: =D17 | J17: =M16 | K17: =J17*'04_Condiciones_TIE'!L5 | L17: =D17-K17 | M17: =J17-L17
A18: OP-101 | B18: 13 | C18: 45703 | D18: =IF('04_Condiciones_TIE'!B5="Francés",'04_Condiciones_TIE'!K5,IF('04_Condiciones_TIE'!B5="Alemán",'04_Condiciones_TIE'!C5/'04_Condiciones_TIE'!H5+F18,IF(B18<'04_Condiciones_TIE'!H5,F18,F18+E18))) | E18: =H17 | F18: =E18*'04_Condiciones_TIE'!J5 | G18: =D18-F18 | H18: =E18-G18 | I18: =D18 | J18: =M17 | K18: =J18*'04_Condiciones_TIE'!L5 | L18: =D18-K18 | M18: =J18-L18
A19: OP-101 | B19: 14 | C19: 45731 | D19: =IF('04_Condiciones_TIE'!B5="Francés",'04_Condiciones_TIE'!K5,IF('04_Condiciones_TIE'!B5="Alemán",'04_Condiciones_TIE'!C5/'04_Condiciones_TIE'!H5+F19,IF(B19<'04_Condiciones_TIE'!H5,F19,F19+E19))) | E19: =H18 | F19: =E19*'04_Condiciones_TIE'!J5 | G19: =D19-F19 | H19: =E19-G19 | I19: =D19 | J19: =M18 | K19: =J19*'04_Condiciones_TIE'!L5 | L19: =D19-K19 | M19: =J19-L19
A20: OP-101 | B20: 15 | C20: 45762 | D20: =IF('04_Condiciones_TIE'!B5="Francés",'04_Condiciones_TIE'!K5,IF('04_Condiciones_TIE'!B5="Alemán",'04_Condiciones_TIE'!C5/'04_Condiciones_TIE'!H5+F20,IF(B20<'04_Condiciones_TIE'!H5,F20,F20+E20))) | E20: =H19 | F20: =E20*'04_Condiciones_TIE'!J5 | G20: =D20-F20 | H20: =E20-G20 | I20: =D20 | J20: =M19 | K20: =J20*'04_Condiciones_TIE'!L5 | L20: =D20-K20 | M20: =J20-L20
A21: OP-101 | B21: 16 | C21: 45792 | D21: =IF('04_Condiciones_TIE'!B5="Francés",'04_Condiciones_TIE'!K5,IF('04_Condiciones_TIE'!B5="Alemán",'04_Condiciones_TIE'!C5/'04_Condiciones_TIE'!H5+F21,IF(B21<'04_Condiciones_TIE'!H5,F21,F21+E21))) | E21: =H20 | F21: =E21*'04_Condiciones_TIE'!J5 | G21: =D21-F21 | H21: =E21-G21 | I21: =D21 | J21: =M20 | K21: =J21*'04_Condiciones_TIE'!L5 | L21: =D21-K21 | M21: =J21-L21
A22: OP-101 | B22: 17 | C22: 45823 | D22: =IF('04_Condiciones_TIE'!B5="Francés",'04_Condiciones_TIE'!K5,IF('04_Condiciones_TIE'!B5="Alemán",'04_Condiciones_TIE'!C5/'04_Condiciones_TIE'!H5+F22,IF(B22<'04_Condiciones_TIE'!H5,F22,F22+E22))) | E22: =H21 | F22: =E22*'04_Condiciones_TIE'!J5 | G22: =D22-F22 | H22: =E22-G22 | I22: =D22 | J22: =M21 | K22: =J22*'04_Condiciones_TIE'!L5 | L22: =D22-K22 | M22: =J22-L22
A23: OP-101 | B23: 18 | C23: 45853 | D23: =IF('04_Condiciones_TIE'!B5="Francés",'04_Condiciones_TIE'!K5,IF('04_Condiciones_TIE'!B5="Alemán",'04_Condiciones_TIE'!C5/'04_Condiciones_TIE'!H5+F23,IF(B23<'04_Condiciones_TIE'!H5,F23,F23+E23))) | E23: =H22 | F23: =E23*'04_Condiciones_TIE'!J5 | G23: =D23-F23 | H23: =E23-G23 | I23: =D23 | J23: =M22 | K23: =J23*'04_Condiciones_TIE'!L5 | L23: =D23-K23 | M23: =J23-L23
A24: OP-101 | B24: 19 | C24: 45884 | D24: =IF('04_Condiciones_TIE'!B5="Francés",'04_Condiciones_TIE'!K5,IF('04_Condiciones_TIE'!B5="Alemán",'04_Condiciones_TIE'!C5/'04_Condiciones_TIE'!H5+F24,IF(B24<'04_Condiciones_TIE'!H5,F24,F24+E24))) | E24: =H23 | F24: =E24*'04_Condiciones_TIE'!J5 | G24: =D24-F24 | H24: =E24-G24 | I24: =D24 | J24: =M23 | K24: =J24*'04_Condiciones_TIE'!L5 | L24: =D24-K24 | M24: =J24-L24
A25: OP-101 | B25: 20 | C25: 45915 | D25: =IF('04_Condiciones_TIE'!B5="Francés",'04_Condiciones_TIE'!K5,IF('04_Condiciones_TIE'!B5="Alemán",'04_Condiciones_TIE'!C5/'04_Condiciones_TIE'!H5+F25,IF(B25<'04_Condiciones_TIE'!H5,F25,F25+E25))) | E25: =H24 | F25: =E25*'04_Condiciones_TIE'!J5 | G25: =D25-F25 | H25: =E25-G25 | I25: =D25 | J25: =M24 | K25: =J25*'04_Condiciones_TIE'!L5 | L25: =D25-K25 | M25: =J25-L25
A26: OP-101 | B26: 21 | C26: 45945 | D26: =IF('04_Condiciones_TIE'!B5="Francés",'04_Condiciones_TIE'!K5,IF('04_Condiciones_TIE'!B5="Alemán",'04_Condiciones_TIE'!C5/'04_Condiciones_TIE'!H5+F26,IF(B26<'04_Condiciones_TIE'!H5,F26,F26+E26))) | E26: =H25 | F26: =E26*'04_Condiciones_TIE'!J5 | G26: =D26-F26 | H26: =E26-G26 | I26: =D26 | J26: =M25 | K26: =J26*'04_Condiciones_TIE'!L5 | L26: =D26-K26 | M26: =J26-L26
A27: OP-101 | B27: 22 | C27: 45976 | D27: =IF('04_Condiciones_TIE'!B5="Francés",'04_Condiciones_TIE'!K5,IF('04_Condiciones_TIE'!B5="Alemán",'04_Condiciones_TIE'!C5/'04_Condiciones_TIE'!H5+F27,IF(B27<'04_Condiciones_TIE'!H5,F27,F27+E27))) | E27: =H26 | F27: =E27*'04_Condiciones_TIE'!J5 | G27: =D27-F27 | H27: =E27-G27 | I27: =D27 | J27: =M26 | K27: =J27*'04_Condiciones_TIE'!L5 | L27: =D27-K27 | M27: =J27-L27
A28: OP-101 | B28: 23 | C28: 46006 | D28: =IF('04_Condiciones_TIE'!B5="Francés",'04_Condiciones_TIE'!K5,IF('04_Condiciones_TIE'!B5="Alemán",'04_Condiciones_TIE'!C5/'04_Condiciones_TIE'!H5+F28,IF(B28<'04_Condiciones_TIE'!H5,F28,F28+E28))) | E28: =H27 | F28: =E28*'04_Condiciones_TIE'!J5 | G28: =D28-F28 | H28: =E28-G28 | I28: =D28 | J28: =M27 | K28: =J28*'04_Condiciones_TIE'!L5 | L28: =D28-K28 | M28: =J28-L28
A29: OP-101 | B29: 24 | C29: 46037 | D29: =IF('04_Condiciones_TIE'!B5="Francés",'04_Condiciones_TIE'!K5,IF('04_Condiciones_TIE'!B5="Alemán",'04_Condiciones_TIE'!C5/'04_Condiciones_TIE'!H5+F29,IF(B29<'04_Condiciones_TIE'!H5,F29,F29+E29))) | E29: =H28 | F29: =E29*'04_Condiciones_TIE'!J5 | G29: =D29-F29 | H29: =E29-G29 | I29: =D29 | J29: =M28 | K29: =J29*'04_Condiciones_TIE'!L5 | L29: =D29-K29 | M29: =J29-L29
A30: OP-101 | B30: 25 | C30: 46068 | D30: =IF('04_Condiciones_TIE'!B5="Francés",'04_Condiciones_TIE'!K5,IF('04_Condiciones_TIE'!B5="Alemán",'04_Condiciones_TIE'!C5/'04_Condiciones_TIE'!H5+F30,IF(B30<'04_Condiciones_TIE'!H5,F30,F30+E30))) | E30: =H29 | F30: =E30*'04_Condiciones_TIE'!J5 | G30: =D30-F30 | H30: =E30-G30 | I30: =D30 | J30: =M29 | K30: =J30*'04_Condiciones_TIE'!L5 | L30: =D30-K30 | M30: =J30-L30
A31: OP-101 | B31: 26 | C31: 46096 | D31: =IF('04_Condiciones_TIE'!B5="Francés",'04_Condiciones_TIE'!K5,IF('04_Condiciones_TIE'!B5="Alemán",'04_Condiciones_TIE'!C5/'04_Condiciones_TIE'!H5+F31,IF(B31<'04_Condiciones_TIE'!H5,F31,F31+E31))) | E31: =H30 | F31: =E31*'04_Condiciones_TIE'!J5 | G31: =D31-F31 | H31: =E31-G31 | I31: =D31 | J31: =M30 | K31: =J31*'04_Condiciones_TIE'!L5 | L31: =D31-K31 | M31: =J31-L31
A32: OP-101 | B32: 27 | C32: 46127 | D32: =IF('04_Condiciones_TIE'!B5="Francés",'04_Condiciones_TIE'!K5,IF('04_Condiciones_TIE'!B5="Alemán",'04_Condiciones_TIE'!C5/'04_Condiciones_TIE'!H5+F32,IF(B32<'04_Condiciones_TIE'!H5,F32,F32+E32))) | E32: =H31 | F32: =E32*'04_Condiciones_TIE'!J5 | G32: =D32-F32 | H32: =E32-G32 | I32: =D32 | J32: =M31 | K32: =J32*'04_Condiciones_TIE'!L5 | L32: =D32-K32 | M32: =J32-L32
A33: OP-101 | B33: 28 | C33: 46157 | D33: =IF('04_Condiciones_TIE'!B5="Francés",'04_Condiciones_TIE'!K5,IF('04_Condiciones_TIE'!B5="Alemán",'04_Condiciones_TIE'!C5/'04_Condiciones_TIE'!H5+F33,IF(B33<'04_Condiciones_TIE'!H5,F33,F33+E33))) | E33: =H32 | F33: =E33*'04_Condiciones_TIE'!J5 | G33: =D33-F33 | H33: =E33-G33 | I33: =D33 | J33: =M32 | K33: =J33*'04_Condiciones_TIE'!L5 | L33: =D33-K33 | M33: =J33-L33
A34: OP-101 | B34: 29 | C34: 46188 | D34: =IF('04_Condiciones_TIE'!B5="Francés",'04_Condiciones_TIE'!K5,IF('04_Condiciones_TIE'!B5="Alemán",'04_Condiciones_TIE'!C5/'04_Condiciones_TIE'!H5+F34,IF(B34<'04_Condiciones_TIE'!H5,F34,F34+E34))) | E34: =H33 | F34: =E34*'04_Condiciones_TIE'!J5 | G34: =D34-F34 | H34: =E34-G34 | I34: =D34 | J34: =M33 | K34: =J34*'04_Condiciones_TIE'!L5 | L34: =D34-K34 | M34: =J34-L34
A35: OP-101 | B35: 30 | C35: 46218 | D35: =IF('04_Condiciones_TIE'!B5="Francés",'04_Condiciones_TIE'!K5,IF('04_Condiciones_TIE'!B5="Alemán",'04_Condiciones_TIE'!C5/'04_Condiciones_TIE'!H5+F35,IF(B35<'04_Condiciones_TIE'!H5,F35,F35+E35))) | E35: =H34 | F35: =E35*'04_Condiciones_TIE'!J5 | G35: =D35-F35 | H35: =E35-G35 | I35: =D35 | J35: =M34 | K35: =J35*'04_Condiciones_TIE'!L5 | L35: =D35-K35 | M35: =J35-L35
A36: OP-101 | B36: 31 | C36: 46249 | D36: =IF('04_Condiciones_TIE'!B5="Francés",'04_Condiciones_TIE'!K5,IF('04_Condiciones_TIE'!B5="Alemán",'04_Condiciones_TIE'!C5/'04_Condiciones_TIE'!H5+F36,IF(B36<'04_Condiciones_TIE'!H5,F36,F36+E36))) | E36: =H35 | F36: =E36*'04_Condiciones_TIE'!J5 | G36: =D36-F36 | H36: =E36-G36 | I36: =D36 | J36: =M35 | K36: =J36*'04_Condiciones_TIE'!L5 | L36: =D36-K36 | M36: =J36-L36
A37: OP-101 | B37: 32 | C37: 46280 | D37: =IF('04_Condiciones_TIE'!B5="Francés",'04_Condiciones_TIE'!K5,IF('04_Condiciones_TIE'!B5="Alemán",'04_Condiciones_TIE'!C5/'04_Condiciones_TIE'!H5+F37,IF(B37<'04_Condiciones_TIE'!H5,F37,F37+E37))) | E37: =H36 | F37: =E37*'04_Condiciones_TIE'!J5 | G37: =D37-F37 | H37: =E37-G37 | I37: =D37 | J37: =M36 | K37: =J37*'04_Condiciones_TIE'!L5 | L37: =D37-K37 | M37: =J37-L37
A38: OP-101 | B38: 33 | C38: 46310 | D38: =IF('04_Condiciones_TIE'!B5="Francés",'04_Condiciones_TIE'!K5,IF('04_Condiciones_TIE'!B5="Alemán",'04_Condiciones_TIE'!C5/'04_Condiciones_TIE'!H5+F38,IF(B38<'04_Condiciones_TIE'!H5,F38,F38+E38))) | E38: =H37 | F38: =E38*'04_Condiciones_TIE'!J5 | G38: =D38-F38 | H38: =E38-G38 | I38: =D38 | J38: =M37 | K38: =J38*'04_Condiciones_TIE'!L5 | L38: =D38-K38 | M38: =J38-L38
A39: OP-101 | B39: 34 | C39: 46341 | D39: =IF('04_Condiciones_TIE'!B5="Francés",'04_Condiciones_TIE'!K5,IF('04_Condiciones_TIE'!B5="Alemán",'04_Condiciones_TIE'!C5/'04_Condiciones_TIE'!H5+F39,IF(B39<'04_Condiciones_TIE'!H5,F39,F39+E39))) | E39: =H38 | F39: =E39*'04_Condiciones_TIE'!J5 | G39: =D39-F39 | H39: =E39-G39 | I39: =D39 | J39: =M38 | K39: =J39*'04_Condiciones_TIE'!L5 | L39: =D39-K39 | M39: =J39-L39
A40: OP-101 | B40: 35 | C40: 46371 | D40: =IF('04_Condiciones_TIE'!B5="Francés",'04_Condiciones_TIE'!K5,IF('04_Condiciones_TIE'!B5="Alemán",'04_Condiciones_TIE'!C5/'04_Condiciones_TIE'!H5+F40,IF(B40<'04_Condiciones_TIE'!H5,F40,F40+E40))) | E40: =H39 | F40: =E40*'04_Condiciones_TIE'!J5 | G40: =D40-F40 | H40: =E40-G40 | I40: =D40 | J40: =M39 | K40: =J40*'04_Condiciones_TIE'!L5 | L40: =D40-K40 | M40: =J40-L40
A41: OP-101 | B41: 36 | C41: 46402 | D41: =IF('04_Condiciones_TIE'!B5="Francés",'04_Condiciones_TIE'!K5,IF('04_Condiciones_TIE'!B5="Alemán",'04_Condiciones_TIE'!C5/'04_Condiciones_TIE'!H5+F41,IF(B41<'04_Condiciones_TIE'!H5,F41,F41+E41))) | E41: =H40 | F41: =E41*'04_Condiciones_TIE'!J5 | G41: =D41-F41 | H41: =E41-G41 | I41: =D41 | J41: =M40 | K41: =J41*'04_Condiciones_TIE'!L5 | L41: =D41-K41 | M41: =J41-L41
...

Sheet 06_Costo_amortizado
A1: Costo amortizado al corte y del ejercicio | H1: ⟵ Inicio | I1: ◀ Anterior | J1: Siguiente ▶
A2: Préstamos y obligaciones financieras · Cliente de muestra S.A. · corte 2025-12-31
A4: Operación | B4: Meses al corte | C4: Períodos vencidos al corte | D4: Fracción del período en curso | E4: Capital contractual al corte | F4: Interés nominal devengado | G4: Costo amortizado al último vencimiento | H4: Interés a la TIE devengado | I4: Costo amortizado al corte | J4: Meses al inicio del ejercicio | K4: Períodos vencidos al inicio | L4: Fracción al inicio | M4: Capital contractual al inicio | N4: Interés nominal devengado al inicio | O4: Costo amortizado al vencimiento previo al inicio | P4: Interés a la TIE devengado al inicio | Q4: Costo amortizado al inicio | R4: Desembolso neto del ejercicio | S4: Pagos del ejercicio | T4: Interés nominal del ejercicio | U4: Gasto financiero a la TIE del ejercicio | V4: Comprobación del movimiento (0)
A5: OP-101 | B5: =DATEDIF('03_Prestamos'!C5,'02_Parametros'!$B$5,"m") | C5: =MIN('04_Condiciones_TIE'!H5,INT(B5/'04_Condiciones_TIE'!G5)) | D5: =IF(C5>='04_Condiciones_TIE'!H5,0,('02_Parametros'!$B$5-EDATE('03_Prestamos'!C5,C5*'04_Condiciones_TIE'!G5))/(EDATE('03_Prestamos'!C5,(C5+1)*'04_Condiciones_TIE'!G5)-EDATE('03_Prestamos'!C5,C5*'04_Condiciones_TIE'!G5))) | E5: =SUMIFS('05_Tabla_amortizacion'!$H$5:$H$163,'05_Tabla_amortizacion'!$A$5:$A$163,A5,'05_Tabla_amortizacion'!$B$5:$B$163,C5) | F5: =E5*'04_Condiciones_TIE'!J5*D5 | G5: =SUMIFS('05_Tabla_amortizacion'!$M$5:$M$163,'05_Tabla_amortizacion'!$A$5:$A$163,A5,'05_Tabla_amortizacion'!$B$5:$B$163,C5) | H5: =G5*'04_Condiciones_TIE'!L5*D5 | I5: =G5+H5 | J5: =IF('03_Prestamos'!C5>'02_Parametros'!$B$6,-1,DATEDIF('03_Prestamos'!C5,'02_Parametros'!$B$6,"m")) | K5: =IF(J5<0,0,MIN('04_Condiciones_TIE'!H5,INT(J5/'04_Condiciones_TIE'!G5))) | L5: =IF(OR(J5<0,K5>='04_Condiciones_TIE'!H5),0,('02_Parametros'!$B$6-EDATE('03_Prestamos'!C5,K5*'04_Condiciones_TIE'!G5))/(EDATE('03_Prestamos'!C5,(K5+1)*'04_Condiciones_TIE'!G5)-EDATE('03_Prestamos'!C5,K5*'04_Condiciones_TIE'!G5))) | M5: =IF(J5<0,0,SUMIFS('05_Tabla_amortizacion'!$H$5:$H$163,'05_Tabla_amortizacion'!$A$5:$A$163,A5,'05_Tabla_amortizacion'!$B$5:$B$163,K5)) | N5: =M5*'04_Condiciones_TIE'!J5*L5 | O5: =IF(J5<0,0,SUMIFS('05_Tabla_amortizacion'!$M$5:$M$163,'05_Tabla_amortizacion'!$A$5:$A$163,A5,'05_Tabla_amortizacion'!$B$5:$B$163,K5)) | P5: =O5*'04_Condiciones_TIE'!L5*L5 | Q5: =O5+P5 | R5: =IF(J5<0,'04_Condiciones_TIE'!E5,0) | S5: =SUMIFS('05_Tabla_amortizacion'!$D$5:$D$163,'05_Tabla_amortizacion'!$A$5:$A$163,A5,'05_Tabla_amortizacion'!$B$5:$B$163,">"&K5,'05_Tabla_amortizacion'!$B$5:$B$163,"<="&C5) | T5: =SUMIFS('05_Tabla_amortizacion'!$F$5:$F$163,'05_Tabla_amortizacion'!$A$5:$A$163,A5,'05_Tabla_amortizacion'!$B$5:$B$163,">"&K5,'05_Tabla_amortizacion'!$B$5:$B$163,"<="&C5)+F5-N5 | U5: =SUMIFS('05_Tabla_amortizacion'!$K$5:$K$163,'05_Tabla_amortizacion'!$A$5:$A$163,A5,'05_Tabla_amortizacion'!$B$5:$B$163,">"&K5,'05_Tabla_amortizacion'!$B$5:$B$163,"<="&C5)+H5-P5 | V5: =Q5+R5+U5-S5-I5
A6: OP-102 | B6: =DATEDIF('03_Prestamos'!C6,'02_Parametros'!$B$5,"m") | C6: =MIN('04_Condiciones_TIE'!H6,INT(B6/'04_Condiciones_TIE'!G6)) | D6: =IF(C6>='04_Condiciones_TIE'!H6,0,('02_Parametros'!$B$5-EDATE('03_Prestamos'!C6,C6*'04_Condiciones_TIE'!G6))/(EDATE('03_Prestamos'!C6,(C6+1)*'04_Condiciones_TIE'!G6)-EDATE('03_Prestamos'!C6,C6*'04_Condiciones_TIE'!G6))) | E6: =SUMIFS('05_Tabla_amortizacion'!$H$5:$H$163,'05_Tabla_amortizacion'!$A$5:$A$163,A6,'05_Tabla_amortizacion'!$B$5:$B$163,C6) | F6: =E6*'04_Condiciones_TIE'!J6*D6 | G6: =SUMIFS('05_Tabla_amortizacion'!$M$5:$M$163,'05_Tabla_amortizacion'!$A$5:$A$163,A6,'05_Tabla_amortizacion'!$B$5:$B$163,C6) | H6: =G6*'04_Condiciones_TIE'!L6*D6 | I6: =G6+H6 | J6: =IF('03_Prestamos'!C6>'02_Parametros'!$B$6,-1,DATEDIF('03_Prestamos'!C6,'02_Parametros'!$B$6,"m")) | K6: =IF(J6<0,0,MIN('04_Condiciones_TIE'!H6,INT(J6/'04_Condiciones_TIE'!G6))) | L6: =IF(OR(J6<0,K6>='04_Condiciones_TIE'!H6),0,('02_Parametros'!$B$6-EDATE('03_Prestamos'!C6,K6*'04_Condiciones_TIE'!G6))/(EDATE('03_Prestamos'!C6,(K6+1)*'04_Condiciones_TIE'!G6)-EDATE('03_Prestamos'!C6,K6*'04_Condiciones_TIE'!G6))) | M6: =IF(J6<0,0,SUMIFS('05_Tabla_amortizacion'!$H$5:$H$163,'05_Tabla_amortizacion'!$A$5:$A$163,A6,'05_Tabla_amortizacion'!$B$5:$B$163,K6)) | N6: =M6*'04_Condiciones_TIE'!J6*L6 | O6: =IF(J6<0,0,SUMIFS('05_Tabla_amortizacion'!$M$5:$M$163,'05_Tabla_amortizacion'!$A$5:$A$163,A6,'05_Tabla_amortizacion'!$B$5:$B$163,K6)) | P6: =O6*'04_Condiciones_TIE'!L6*L6 | Q6: =O6+P6 | R6: =IF(J6<0,'04_Condiciones_TIE'!E6,0) | S6: =SUMIFS('05_Tabla_amortizacion'!$D$5:$D$163,'05_Tabla_amortizacion'!$A$5:$A$163,A6,'05_Tabla_amortizacion'!$B$5:$B$163,">"&K6,'05_Tabla_amortizacion'!$B$5:$B$163,"<="&C6) | T6: =SUMIFS('05_Tabla_amortizacion'!$F$5:$F$163,'05_Tabla_amortizacion'!$A$5:$A$163,A6,'05_Tabla_amortizacion'!$B$5:$B$163,">"&K6,'05_Tabla_amortizacion'!$B$5:$B$163,"<="&C6)+F6-N6 | U6: =SUMIFS('05_Tabla_amortizacion'!$K$5:$K$163,'05_Tabla_amortizacion'!$A$5:$A$163,A6,'05_Tabla_amortizacion'!$B$5:$B$163,">"&K6,'05_Tabla_amortizacion'!$B$5:$B$163,"<="&C6)+H6-P6 | V6: =Q6+R6+U6-S6-I6
A7: OP-103 | B7: =DATEDIF('03_Prestamos'!C7,'02_Parametros'!$B$5,"m") | C7: =MIN('04_Condiciones_TIE'!H7,INT(B7/'04_Condiciones_TIE'!G7)) | D7: =IF(C7>='04_Condiciones_TIE'!H7,0,('02_Parametros'!$B$5-EDATE('03_Prestamos'!C7,C7*'04_Condiciones_TIE'!G7))/(EDATE('03_Prestamos'!C7,(C7+1)*'04_Condiciones_TIE'!G7)-EDATE('03_Prestamos'!C7,C7*'04_Condiciones_TIE'!G7))) | E7: =SUMIFS('05_Tabla_amortizacion'!$H$5:$H$163,'05_Tabla_amortizacion'!$A$5:$A$163,A7,'05_Tabla_amortizacion'!$B$5:$B$163,C7) | F7: =E7*'04_Condiciones_TIE'!J7*D7 | G7: =SUMIFS('05_Tabla_amortizacion'!$M$5:$M$163,'05_Tabla_amortizacion'!$A$5:$A$163,A7,'05_Tabla_amortizacion'!$B$5:$B$163,C7) | H7: =G7*'04_Condiciones_TIE'!L7*D7 | I7: =G7+H7 | J7: =IF('03_Prestamos'!C7>'02_Parametros'!$B$6,-1,DATEDIF('03_Prestamos'!C7,'02_Parametros'!$B$6,"m")) | K7: =IF(J7<0,0,MIN('04_Condiciones_TIE'!H7,INT(J7/'04_Condiciones_TIE'!G7))) | L7: =IF(OR(J7<0,K7>='04_Condiciones_TIE'!H7),0,('02_Parametros'!$B$6-EDATE('03_Prestamos'!C7,K7*'04_Condiciones_TIE'!G7))/(EDATE('03_Prestamos'!C7,(K7+1)*'04_Condiciones_TIE'!G7)-EDATE('03_Prestamos'!C7,K7*'04_Condiciones_TIE'!G7))) | M7: =IF(J7<0,0,SUMIFS('05_Tabla_amortizacion'!$H$5:$H$163,'05_Tabla_amortizacion'!$A$5:$A$163,A7,'05_Tabla_amortizacion'!$B$5:$B$163,K7)) | N7: =M7*'04_Condiciones_TIE'!J7*L7 | O7: =IF(J7<0,0,SUMIFS('05_Tabla_amortizacion'!$M$5:$M$163,'05_Tabla_amortizacion'!$A$5:$A$163,A7,'05_Tabla_amortizacion'!$B$5:$B$163,K7)) | P7: =O7*'04_Condiciones_TIE'!L7*L7 | Q7: =O7+P7 | R7: =IF(J7<0,'04_Condiciones_TIE'!E7,0) | S7: =SUMIFS('05_Tabla_amortizacion'!$D$5:$D$163,'05_Tabla_amortizacion'!$A$5:$A$163,A7,'05_Tabla_amortizacion'!$B$5:$B$163,">"&K7,'05_Tabla_amortizacion'!$B$5:$B$163,"<="&C7) | T7: =SUMIFS('05_Tabla_amortizacion'!$F$5:$F$163,'05_Tabla_amortizacion'!$A$5:$A$163,A7,'05_Tabla_amortizacion'!$B$5:$B$163,">"&K7,'05_Tabla_amortizacion'!$B$5:$B$163,"<="&C7)+F7-N7 | U7: =SUMIFS('05_Tabla_amortizacion'!$K$5:$K$163,'05_Tabla_amortizacion'!$A$5:$A$163,A7,'05_Tabla_amortizacion'!$B$5:$B$163,">"&K7,'05_Tabla_amortizacion'!$B$5:$B$163,"<="&C7)+H7-P7 | V7: =Q7+R7+U7-S7-I7
A8: OP-104 | B8: =DATEDIF('03_Prestamos'!C8,'02_Parametros'!$B$5,"m") | C8: =MIN('04_Condiciones_TIE'!H8,INT(B8/'04_Condiciones_TIE'!G8)) | D8: =IF(C8>='04_Condiciones_TIE'!H8,0,('02_Parametros'!$B$5-EDATE('03_Prestamos'!C8,C8*'04_Condiciones_TIE'!G8))/(EDATE('03_Prestamos'!C8,(C8+1)*'04_Condiciones_TIE'!G8)-EDATE('03_Prestamos'!C8,C8*'04_Condiciones_TIE'!G8))) | E8: =SUMIFS('05_Tabla_amortizacion'!$H$5:$H$163,'05_Tabla_amortizacion'!$A$5:$A$163,A8,'05_Tabla_amortizacion'!$B$5:$B$163,C8) | F8: =E8*'04_Condiciones_TIE'!J8*D8 | G8: =SUMIFS('05_Tabla_amortizacion'!$M$5:$M$163,'05_Tabla_amortizacion'!$A$5:$A$163,A8,'05_Tabla_amortizacion'!$B$5:$B$163,C8) | H8: =G8*'04_Condiciones_TIE'!L8*D8 | I8: =G8+H8 | J8: =IF('03_Prestamos'!C8>'02_Parametros'!$B$6,-1,DATEDIF('03_Prestamos'!C8,'02_Parametros'!$B$6,"m")) | K8: =IF(J8<0,0,MIN('04_Condiciones_TIE'!H8,INT(J8/'04_Condiciones_TIE'!G8))) | L8: =IF(OR(J8<0,K8>='04_Condiciones_TIE'!H8),0,('02_Parametros'!$B$6-EDATE('03_Prestamos'!C8,K8*'04_Condiciones_TIE'!G8))/(EDATE('03_Prestamos'!C8,(K8+1)*'04_Condiciones_TIE'!G8)-EDATE('03_Prestamos'!C8,K8*'04_Condiciones_TIE'!G8))) | M8: =IF(J8<0,0,SUMIFS('05_Tabla_amortizacion'!$H$5:$H$163,'05_Tabla_amortizacion'!$A$5:$A$163,A8,'05_Tabla_amortizacion'!$B$5:$B$163,K8)) | N8: =M8*'04_Condiciones_TIE'!J8*L8 | O8: =IF(J8<0,0,SUMIFS('05_Tabla_amortizacion'!$M$5:$M$163,'05_Tabla_amortizacion'!$A$5:$A$163,A8,'05_Tabla_amortizacion'!$B$5:$B$163,K8)) | P8: =O8*'04_Condiciones_TIE'!L8*L8 | Q8: =O8+P8 | R8: =IF(J8<0,'04_Condiciones_TIE'!E8,0) | S8: =SUMIFS('05_Tabla_amortizacion'!$D$5:$D$163,'05_Tabla_amortizacion'!$A$5:$A$163,A8,'05_Tabla_amortizacion'!$B$5:$B$163,">"&K8,'05_Tabla_amortizacion'!$B$5:$B$163,"<="&C8) | T8: =SUMIFS('05_Tabla_amortizacion'!$F$5:$F$163,'05_Tabla_amortizacion'!$A$5:$A$163,A8,'05_Tabla_amortizacion'!$B$5:$B$163,">"&K8,'05_Tabla_amortizacion'!$B$5:$B$163,"<="&C8)+F8-N8 | U8: =SUMIFS('05_Tabla_amortizacion'!$K$5:$K$163,'05_Tabla_amortizacion'!$A$5:$A$163,A8,'05_Tabla_amortizacion'!$B$5:$B$163,">"&K8,'05_Tabla_amortizacion'!$B$5:$B$163,"<="&C8)+H8-P8 | V8: =Q8+R8+U8-S8-I8
A9: OP-105 | B9: =DATEDIF('03_Prestamos'!C9,'02_Parametros'!$B$5,"m") | C9: =MIN('04_Condiciones_TIE'!H9,INT(B9/'04_Condiciones_TIE'!G9)) | D9: =IF(C9>='04_Condiciones_TIE'!H9,0,('02_Parametros'!$B$5-EDATE('03_Prestamos'!C9,C9*'04_Condiciones_TIE'!G9))/(EDATE('03_Prestamos'!C9,(C9+1)*'04_Condiciones_TIE'!G9)-EDATE('03_Prestamos'!C9,C9*'04_Condiciones_TIE'!G9))) | E9: =SUMIFS('05_Tabla_amortizacion'!$H$5:$H$163,'05_Tabla_amortizacion'!$A$5:$A$163,A9,'05_Tabla_amortizacion'!$B$5:$B$163,C9) | F9: =E9*'04_Condiciones_TIE'!J9*D9 | G9: =SUMIFS('05_Tabla_amortizacion'!$M$5:$M$163,'05_Tabla_amortizacion'!$A$5:$A$163,A9,'05_Tabla_amortizacion'!$B$5:$B$163,C9) | H9: =G9*'04_Condiciones_TIE'!L9*D9 | I9: =G9+H9 | J9: =IF('03_Prestamos'!C9>'02_Parametros'!$B$6,-1,DATEDIF('03_Prestamos'!C9,'02_Parametros'!$B$6,"m")) | K9: =IF(J9<0,0,MIN('04_Condiciones_TIE'!H9,INT(J9/'04_Condiciones_TIE'!G9))) | L9: =IF(OR(J9<0,K9>='04_Condiciones_TIE'!H9),0,('02_Parametros'!$B$6-EDATE('03_Prestamos'!C9,K9*'04_Condiciones_TIE'!G9))/(EDATE('03_Prestamos'!C9,(K9+1)*'04_Condiciones_TIE'!G9)-EDATE('03_Prestamos'!C9,K9*'04_Condiciones_TIE'!G9))) | M9: =IF(J9<0,0,SUMIFS('05_Tabla_amortizacion'!$H$5:$H$163,'05_Tabla_amortizacion'!$A$5:$A$163,A9,'05_Tabla_amortizacion'!$B$5:$B$163,K9)) | N9: =M9*'04_Condiciones_TIE'!J9*L9 | O9: =IF(J9<0,0,SUMIFS('05_Tabla_amortizacion'!$M$5:$M$163,'05_Tabla_amortizacion'!$A$5:$A$163,A9,'05_Tabla_amortizacion'!$B$5:$B$163,K9)) | P9: =O9*'04_Condiciones_TIE'!L9*L9 | Q9: =O9+P9 | R9: =IF(J9<0,'04_Condiciones_TIE'!E9,0) | S9: =SUMIFS('05_Tabla_amortizacion'!$D$5:$D$163,'05_Tabla_amortizacion'!$A$5:$A$163,A9,'05_Tabla_amortizacion'!$B$5:$B$163,">"&K9,'05_Tabla_amortizacion'!$B$5:$B$163,"<="&C9) | T9: =SUMIFS('05_Tabla_amortizacion'!$F$5:$F$163,'05_Tabla_amortizacion'!$A$5:$A$163,A9,'05_Tabla_amortizacion'!$B$5:$B$163,">"&K9,'05_Tabla_amortizacion'!$B$5:$B$163,"<="&C9)+F9-N9 | U9: =SUMIFS('05_Tabla_amortizacion'!$K$5:$K$163,'05_Tabla_amortizacion'!$A$5:$A$163,A9,'05_Tabla_amortizacion'!$B$5:$B$163,">"&K9,'05_Tabla_amortizacion'!$B$5:$B$163,"<="&C9)+H9-P9 | V9: =Q9+R9+U9-S9-I9
A10: OP-106 | B10: =DATEDIF('03_Prestamos'!C10,'02_Parametros'!$B$5,"m") | C10: =MIN('04_Condiciones_TIE'!H10,INT(B10/'04_Condiciones_TIE'!G10)) | D10: =IF(C10>='04_Condiciones_TIE'!H10,0,('02_Parametros'!$B$5-EDATE('03_Prestamos'!C10,C10*'04_Condiciones_TIE'!G10))/(EDATE('03_Prestamos'!C10,(C10+1)*'04_Condiciones_TIE'!G10)-EDATE('03_Prestamos'!C10,C10*'04_Condiciones_TIE'!G10))) | E10: =SUMIFS('05_Tabla_amortizacion'!$H$5:$H$163,'05_Tabla_amortizacion'!$A$5:$A$163,A10,'05_Tabla_amortizacion'!$B$5:$B$163,C10) | F10: =E10*'04_Condiciones_TIE'!J10*D10 | G10: =SUMIFS('05_Tabla_amortizacion'!$M$5:$M$163,'05_Tabla_amortizacion'!$A$5:$A$163,A10,'05_Tabla_amortizacion'!$B$5:$B$163,C10) | H10: =G10*'04_Condiciones_TIE'!L10*D10 | I10: =G10+H10 | J10: =IF('03_Prestamos'!C10>'02_Parametros'!$B$6,-1,DATEDIF('03_Prestamos'!C10,'02_Parametros'!$B$6,"m")) | K10: =IF(J10<0,0,MIN('04_Condiciones_TIE'!H10,INT(J10/'04_Condiciones_TIE'!G10))) | L10: =IF(OR(J10<0,K10>='04_Condiciones_TIE'!H10),0,('02_Parametros'!$B$6-EDATE('03_Prestamos'!C10,K10*'04_Condiciones_TIE'!G10))/(EDATE('03_Prestamos'!C10,(K10+1)*'04_Condiciones_TIE'!G10)-EDATE('03_Prestamos'!C10,K10*'04_Condiciones_TIE'!G10))) | M10: =IF(J10<0,0,SUMIFS('05_Tabla_amortizacion'!$H$5:$H$163,'05_Tabla_amortizacion'!$A$5:$A$163,A10,'05_Tabla_amortizacion'!$B$5:$B$163,K10)) | N10: =M10*'04_Condiciones_TIE'!J10*L10 | O10: =IF(J10<0,0,SUMIFS('05_Tabla_amortizacion'!$M$5:$M$163,'05_Tabla_amortizacion'!$A$5:$A$163,A10,'05_Tabla_amortizacion'!$B$5:$B$163,K10)) | P10: =O10*'04_Condiciones_TIE'!L10*L10 | Q10: =O10+P10 | R10: =IF(J10<0,'04_Condiciones_TIE'!E10,0) | S10: =SUMIFS('05_Tabla_amortizacion'!$D$5:$D$163,'05_Tabla_amortizacion'!$A$5:$A$163,A10,'05_Tabla_amortizacion'!$B$5:$B$163,">"&K10,'05_Tabla_amortizacion'!$B$5:$B$163,"<="&C10) | T10: =SUMIFS('05_Tabla_amortizacion'!$F$5:$F$163,'05_Tabla_amortizacion'!$A$5:$A$163,A10,'05_Tabla_amortizacion'!$B$5:$B$163,">"&K10,'05_Tabla_amortizacion'!$B$5:$B$163,"<="&C10)+F10-N10 | U10: =SUMIFS('05_Tabla_amortizacion'!$K$5:$K$163,'05_Tabla_amortizacion'!$A$5:$A$163,A10,'05_Tabla_amortizacion'!$B$5:$B$163,">"&K10,'05_Tabla_amortizacion'!$B$5:$B$163,"<="&C10)+H10-P10 | V10: =Q10+R10+U10-S10-I10
A11: OP-107 | B11: =DATEDIF('03_Prestamos'!C11,'02_Parametros'!$B$5,"m") | C11: =MIN('04_Condiciones_TIE'!H11,INT(B11/'04_Condiciones_TIE'!G11)) | D11: =IF(C11>='04_Condiciones_TIE'!H11,0,('02_Parametros'!$B$5-EDATE('03_Prestamos'!C11,C11*'04_Condiciones_TIE'!G11))/(EDATE('03_Prestamos'!C11,(C11+1)*'04_Condiciones_TIE'!G11)-EDATE('03_Prestamos'!C11,C11*'04_Condiciones_TIE'!G11))) | E11: =SUMIFS('05_Tabla_amortizacion'!$H$5:$H$163,'05_Tabla_amortizacion'!$A$5:$A$163,A11,'05_Tabla_amortizacion'!$B$5:$B$163,C11) | F11: =E11*'04_Condiciones_TIE'!J11*D11 | G11: =SUMIFS('05_Tabla_amortizacion'!$M$5:$M$163,'05_Tabla_amortizacion'!$A$5:$A$163,A11,'05_Tabla_amortizacion'!$B$5:$B$163,C11) | H11: =G11*'04_Condiciones_TIE'!L11*D11 | I11: =G11+H11 | J11: =IF('03_Prestamos'!C11>'02_Parametros'!$B$6,-1,DATEDIF('03_Prestamos'!C11,'02_Parametros'!$B$6,"m")) | K11: =IF(J11<0,0,MIN('04_Condiciones_TIE'!H11,INT(J11/'04_Condiciones_TIE'!G11))) | L11: =IF(OR(J11<0,K11>='04_Condiciones_TIE'!H11),0,('02_Parametros'!$B$6-EDATE('03_Prestamos'!C11,K11*'04_Condiciones_TIE'!G11))/(EDATE('03_Prestamos'!C11,(K11+1)*'04_Condiciones_TIE'!G11)-EDATE('03_Prestamos'!C11,K11*'04_Condiciones_TIE'!G11))) | M11: =IF(J11<0,0,SUMIFS('05_Tabla_amortizacion'!$H$5:$H$163,'05_Tabla_amortizacion'!$A$5:$A$163,A11,'05_Tabla_amortizacion'!$B$5:$B$163,K11)) | N11: =M11*'04_Condiciones_TIE'!J11*L11 | O11: =IF(J11<0,0,SUMIFS('05_Tabla_amortizacion'!$M$5:$M$163,'05_Tabla_amortizacion'!$A$5:$A$163,A11,'05_Tabla_amortizacion'!$B$5:$B$163,K11)) | P11: =O11*'04_Condiciones_TIE'!L11*L11 | Q11: =O11+P11 | R11: =IF(J11<0,'04_Condiciones_TIE'!E11,0) | S11: =SUMIFS('05_Tabla_amortizacion'!$D$5:$D$163,'05_Tabla_amortizacion'!$A$5:$A$163,A11,'05_Tabla_amortizacion'!$B$5:$B$163,">"&K11,'05_Tabla_amortizacion'!$B$5:$B$163,"<="&C11) | T11: =SUMIFS('05_Tabla_amortizacion'!$F$5:$F$163,'05_Tabla_amortizacion'!$A$5:$A$163,A11,'05_Tabla_amortizacion'!$B$5:$B$163,">"&K11,'05_Tabla_amortizacion'!$B$5:$B$163,"<="&C11)+F11-N11 | U11: =SUMIFS('05_Tabla_amortizacion'!$K$5:$K$163,'05_Tabla_amortizacion'!$A$5:$A$163,A11,'05_Tabla_amortizacion'!$B$5:$B$163,">"&K11,'05_Tabla_amortizacion'!$B$5:$B$163,"<="&C11)+H11-P11 | V11: =Q11+R11+U11-S11-I11
A12: TOTAL | E12: =SUM(E5:E11) | F12: =SUM(F5:F11) | I12: =SUM(I5:I11) | Q12: =SUM(Q5:Q11) | R12: =SUM(R5:R11) | S12: =SUM(S5:S11) | T12: =SUM(T5:T11) | U12: =SUM(U5:U11)
A14: ⓘ Cómo se calcula esta hoja
A15: Columna | B15: Fórmula (Excel) | C15: Cómo se calcula (sencillo) | D15: Ejemplo con números reales | E15: De dónde viene | F15: Norma
A16: Meses al corte | B16: '=DATEDIF('03_Prestamos'!C5,'02_Parametros'!$B$5,"m") | C16: Cuenta los meses completos transcurridos entre la fecha de desembolso (hoja 03) y la fecha de corte (hoja 02). | D16: Fila 1: DATEDIF(«2024-01-15»; «2025-12-31»; "m") → 23 | E16: hoja «Universo de préstamos», hoja «Parámetros» | F16: —
A17: Períodos vencidos al corte | B17: '=MIN('04_Condiciones_TIE'!H5,INT(B5/'04_Condiciones_TIE'!G5)) | C17: Divide los meses al corte para los meses de cada período (hoja 04) y toma la parte entera, sin pasar del número total de períodos: son las cuotas ya vencidas al corte. | D17: Fila 1: MIN(36; INT(23/1)) → 23 | E17: «Meses al corte» (esta hoja), hoja «Condiciones y tasa de interés efectiva» | F17: —
A18: Fracción del período en curso | B18: '=IF(C5>='04_Condiciones_TIE'!H5,0,('02_Parametros'!$B$5-EDATE('03_Prestamos'!C5,C5*'04_Condiciones_TIE'!G5))/(EDATE('03_Prestamos'!C5,(C5+1)*'04_Condiciones_TIE'!G5)-EDATE('03_Prestamos'!C5,C5*'04_Condiciones_TIE'!G5))) | C18: Mide qué parte del período en curso ya pasó al corte: días desde el último vencimiento hasta el corte divididos para los días del período. Si el préstamo ya venció por completo, es cero. | D18: Fila 1: IF(23>=36; 0; («2025-12-31»-EDATE(«2024-01-15»; 23*1))/(EDATE(«2024-01-15»; (23+1)*1)-EDATE(«2024-01-15»; 23*1))) → 51,61 % | E18: «Períodos vencidos al corte» (esta hoja), hoja «Condiciones y tasa de interés efectiva», hoja «Parámetros», hoja «Universo de préstamos» | F18: —
A19: Capital contractual al corte | B19: '=SUMIFS('05_Tabla_amortizacion'!$H$5:$H$163,'05_Tabla_amortizacion'!$A$5:$A$163,A5,'05_Tabla_amortizacion'!$B$5:$B$163,C5) | C19: Busca en la hoja 05 (Tabla de amortización) el capital final de esta operación en el último período vencido al corte. | D19: Fila 1: SUMIFS([«Capital final» de «Tabla de amortización», 159 filas]; [«Operación» de «Tabla de amortización», 159 filas]; «OP-101»; [«Período» de «Tabla de amortización», 159 filas]; 23) → 47.940,12 | E19: «Operación» (esta hoja), «Períodos vencidos al corte» (esta hoja), hoja «Tabla de amortización» | F19: —
A20: Interés nominal devengado | B20: '=E5*'04_Condiciones_TIE'!J5*D5 | C20: Multiplica el capital contractual al corte por la tasa periódica nominal (hoja 04) y por la fracción del período en curso: es el interés del contrato devengado y aún no vencido. | D20: Fila 1: 47.940,12*0,92 %*51,61 % → 226,81 | E20: «Capital contractual al corte» (esta hoja), «Fracción del período en curso» (esta hoja), hoja «Condiciones y tasa de interés efectiva» | F20: —
