Workbook

Sheet 00_Inicio
B2: AuditConsulting Auditores Cía. Ltda. · AUDIT-IA
B4: Provisiones y contingencias
B6: Cliente | C6: Cliente de muestra S.A. | D6: RUC | E6: 1790000000001
B7: Marco contable | C7: NIIF completas | D7: Fecha de corte | E7: 2025-12-31
B8: Preparó | C8: Ejercicio modelo | D8: Revisó | E8: Pendiente
B10: INDICADORES CLAVE
B11: Ajuste propuesto (requerida − libros) | C11: Problemas encontrados
B12: 38758.9 | C12: 21
B15: IR A LA CÉDULA
B16: Carátula | C16: Programa | D16: Base técnica | E16: Resumen
B17: Parámetros | C17: Provisiones y contingencias (datos del cliente) | D17: Garantías (datos del cliente) | E17: Obligación presente y probabilidad
B18: Mejor estimación | C18: Valor presente (descuento) | D18: Actualización financiera (reversión del descuento) | E18: Litigios y cartas de abogados
B19: Garantías: cálculo | C19: Contratos onerosos | D19: Desmantelamiento | E19: Provisión requerida vs libros
B20: Contingencias a revelar | C20: Ajustes propuestos y conciliación | D20: Problemas encontrados | E20: Conclusión
B21: Control de revisión
B23: PANORAMA | N23: Datos de los gráficos (fórmulas a las cédulas)
N24: Cifras del resumen | O24: Importe (USD)
N25: ='01_Resumen'!A5 | O25: ='01_Resumen'!B5
N26: ='01_Resumen'!A6 | O26: ='01_Resumen'!B6
N27: ='01_Resumen'!A7 | O27: ='01_Resumen'!B7
N28: ='01_Resumen'!A8 | O28: ='01_Resumen'!B8
N29: ='01_Resumen'!A9 | O29: ='01_Resumen'!B9
N30: ='01_Resumen'!A10 | O30: ='01_Resumen'!B10
N31: ='01_Resumen'!A11 | O31: ='01_Resumen'!B11
N32: ='01_Resumen'!A12 | O32: ='01_Resumen'!B12
N33: ='01_Resumen'!A13 | O33: ='01_Resumen'!B13
N34: ='01_Resumen'!A14 | O34: ='01_Resumen'!B14
N35: ='01_Resumen'!A15 | O35: ='01_Resumen'!B15
N36: ='01_Resumen'!A16 | O36: ='01_Resumen'!B16
N37: ='01_Resumen'!A17 | O37: ='01_Resumen'!B17
N39: Hallazgos de mayor impacto | O39: Importe (USD)
N40: Diferencia provision (×5) | O40: =SUMIFS('16_Problemas'!$C$5:$C$25,'16_Problemas'!$A$5:$A$25,"DIFERENCIA_PROVISION",'16_Problemas'!$C$5:$C$25,">0")-SUMIFS('16_Problemas'!$C$5:$C$25,'16_Problemas'!$A$5:$A$25,"DIFERENCIA_PROVISION",'16_Problemas'!$C$5:$C$25,"<0")
N41: Diferencia carta abogado (×2) | O41: =SUMIFS('16_Problemas'!$C$5:$C$25,'16_Problemas'!$A$5:$A$25,"DIFERENCIA_CARTA_ABOGADO",'16_Problemas'!$C$5:$C$25,">0")-SUMIFS('16_Problemas'!$C$5:$C$25,'16_Problemas'!$A$5:$A$25,"DIFERENCIA_CARTA_ABOGADO",'16_Problemas'!$C$5:$C$25,"<0")
N42: Descuento no aplicado | O42: =SUMIFS('16_Problemas'!$C$5:$C$25,'16_Problemas'!$A$5:$A$25,"DESCUENTO_NO_APLICADO",'16_Problemas'!$C$5:$C$25,">0")-SUMIFS('16_Problemas'!$C$5:$C$25,'16_Problemas'!$A$5:$A$25,"DESCUENTO_NO_APLICADO",'16_Problemas'!$C$5:$C$25,"<0")
N43: Provision no registrada | O43: =SUMIFS('16_Problemas'!$C$5:$C$25,'16_Problemas'!$A$5:$A$25,"PROVISION_NO_REGISTRADA",'16_Problemas'!$C$5:$C$25,">0")-SUMIFS('16_Problemas'!$C$5:$C$25,'16_Problemas'!$A$5:$A$25,"PROVISION_NO_REGISTRADA",'16_Problemas'!$C$5:$C$25,"<0")
N44: Activo contingente reconocido | O44: =SUMIFS('16_Problemas'!$C$5:$C$25,'16_Problemas'!$A$5:$A$25,"ACTIVO_CONTINGENTE_RECONOCIDO",'16_Problemas'!$C$5:$C$25,">0")-SUMIFS('16_Problemas'!$C$5:$C$25,'16_Problemas'!$A$5:$A$25,"ACTIVO_CONTINGENTE_RECONOCIDO",'16_Problemas'!$C$5:$C$25,"<0")
N45: Activo contingente sin revelar | O45: =SUMIFS('16_Problemas'!$C$5:$C$25,'16_Problemas'!$A$5:$A$25,"ACTIVO_CONTINGENTE_SIN_REVELAR",'16_Problemas'!$C$5:$C$25,">0")-SUMIFS('16_Problemas'!$C$5:$C$25,'16_Problemas'!$A$5:$A$25,"ACTIVO_CONTINGENTE_SIN_REVELAR",'16_Problemas'!$C$5:$C$25,"<0")
N46: Provision posible o remota | O46: =SUMIFS('16_Problemas'!$C$5:$C$25,'16_Problemas'!$A$5:$A$25,"PROVISION_POSIBLE_O_REMOTA",'16_Problemas'!$C$5:$C$25,">0")-SUMIFS('16_Problemas'!$C$5:$C$25,'16_Problemas'!$A$5:$A$25,"PROVISION_POSIBLE_O_REMOTA",'16_Problemas'!$C$5:$C$25,"<0")
N47: Otros (7 tipos) | O47: =SUMIF('16_Problemas'!$C$5:$C$25,">0")-SUMIF('16_Problemas'!$C$5:$C$25,"<0")-((SUMIFS('16_Problemas'!$C$5:$C$25,'16_Problemas'!$A$5:$A$25,"DIFERENCIA_PROVISION",'16_Problemas'!$C$5:$C$25,">0")-SUMIFS('16_Problemas'!$C$5:$C$25,'16_Problemas'!$A$5:$A$25,"DIFERENCIA_PROVISION",'16_Problemas'!$C$5:$C$25,"<0"))+(SUMIFS('16_Problemas'!$C$5:$C$25,'16_Problemas'!$A$5:$A$25,"DIFERENCIA_CARTA_ABOGADO",'16_Problemas'!$C$5:$C$25,">0")-SUMIFS('16_Problemas'!$C$5:$C$25,'16_Problemas'!$A$5:$A$25,"DIFERENCIA_CARTA_ABOGADO",'16_Problemas'!$C$5:$C$25,"<0"))+(SUMIFS('16_Problemas'!$C$5:$C$25,'16_Problemas'!$A$5:$A$25,"DESCUENTO_NO_APLICADO",'16_Problemas'!$C$5:$C$25,">0")-SUMIFS('16_Problemas'!$C$5:$C$25,'16_Problemas'!$A$5:$A$25,"DESCUENTO_NO_APLICADO",'16_Problemas'!$C$5:$C$25,"<0"))+(SUMIFS('16_Problemas'!$C$5:$C$25,'16_Problemas'!$A$5:$A$25,"PROVISION_NO_REGISTRADA",'16_Problemas'!$C$5:$C$25,">0")-SUMIFS('16_Problemas'!$C$5:$C$25,'16_Problemas'!$A$5:$A$25,"PROVISION_NO_REGISTRADA",'16_Problemas'!$C$5:$C$25,"<0"))+(SUMIFS('16_Problemas'!$C$5:$C$25,'16_Problemas'!$A$5:$A$25,"ACTIVO_CONTINGENTE_RECONOCIDO",'16_Problemas'!$C$5:$C$25,">0")-SUMIFS('16_Problemas'!$C$5:$C$25,'16_Problemas'!$A$5:$A$25,"ACTIVO_CONTINGENTE_RECONOCIDO",'16_Problemas'!$C$5:$C$25,"<0"))+(SUMIFS('16_Problemas'!$C$5:$C$25,'16_Problemas'!$A$5:$A$25,"ACTIVO_CONTINGENTE_SIN_REVELAR",'16_Problemas'!$C$5:$C$25,">0")-SUMIFS('16_Problemas'!$C$5:$C$25,'16_Problemas'!$A$5:$A$25,"ACTIVO_CONTINGENTE_SIN_REVELAR",'16_Problemas'!$C$5:$C$25,"<0"))+(SUMIFS('16_Problemas'!$C$5:$C$25,'16_Problemas'!$A$5:$A$25,"PROVISION_POSIBLE_O_REMOTA",'16_Problemas'!$C$5:$C$25,">0")-SUMIFS('16_Problemas'!$C$5:$C$25,'16_Problemas'!$A$5:$A$25,"PROVISION_POSIBLE_O_REMOTA",'16_Problemas'!$C$5:$C$25,"<0")))

Sheet 00_Caratula
A1: Carátula | H1: ⟵ Inicio | J1: Siguiente ▶
A2: Provisiones y contingencias · Cliente de muestra S.A. · corte 2025-12-31
A4: Concepto | B4: Detalle
A5: Firma | B5: AuditConsulting Auditores Cía. Ltda.
A6: Cliente | B6: Cliente de muestra S.A.
A7: RUC | B7: 1790000000001
A8: Ejercicio | B8: 2025
A9: Fecha de corte | B9: 2025-12-31
A10: Marco contable | B10: NIIF completas
A11: Herramienta | B11: Provisiones y contingencias
A12: Rubro | B12: Provisiones
A13: Motor | B13: provisiones_contingencias 1.0
A14: Versión del papel | B14: v1
A15: Estado | B15: MUESTRA
... A17: Revisó | B17: Pendiente
A18: Aprobó
A19: Fecha de aprobación
A20: Huella de la ejecución (SHA-256)

Sheet 00_Programa
A1: Programa | H1: ⟵ Inicio | I1: ◀ Anterior | J1: Siguiente ▶
A2: Provisiones y contingencias · Cliente de muestra S.A. · corte 2025-12-31
A4: Código | B4: Objetivo | C4: Afirmación | D4: Procedimiento | E4: Evidencia | F4: Criterio | G4: Referencia
A5: PROV-01 | B5: Obligación presente | C5: Existencia | D5: Revisar el suceso que origina cada partida y la existencia de obligación legal o implícita | E5: Contratos, demandas, actas | F5: NIC 37.14–16; PYMES 21.4–21.6 | G5: NIC 37 · Sección 21
A6: PROV-02 | B6: Probabilidad | C6: Existencia / Integridad | D6: Comparar la evaluación del abogado y de la gerencia y clasificar (probable/posible/remota) | E6: Cartas de abogados, informe de gerencia | F6: Probable = más probable que no (NIC 37.23) | G6: NIC 37.23 · NIA 501
A7: PROV-03 | B7: Mejor estimación | C7: Valoración | D7: Recalcular valor esperado, desenlace más probable o punto medio y comparar con libros | E7: Escenarios, rango, cálculo de la gerencia | F7: NIC 37.36–40; PYMES 21.7 | G7: NIC 37 · NIA 540
A8: PROV-04 | B8: Cartas de abogados y litigios | C8: Integridad | D8: Enviar cartas a los abogados, obtener respuesta posterior al corte y conciliar importes con libros | E8: Respuestas de abogados | F8: Respuesta recibida y concordante | G8: NIA 501 · NIA 560
A9: PROV-05 | B9: Garantías | C9: Valoración | D9: Recalcular unidades con garantía × % de reclamos × costo medio | E9: Ventas con garantía, reclamos históricos | F9: NIC 37.24, 39; PYMES 21A.4 | G9: NIC 37 · Sección 21
A10: PROV-06 | B10: Contratos onerosos | C10: Integridad / Valoración | D10: Restar los beneficios esperados del costo de cumplir, comparar con la penalización y provisionar el menor (previo deterioro de activos, NIC 37.69) | E10: Contratos, presupuestos, ingresos esperados del contrato | F10: NIC 37.66–69; PYMES 21A.2 | G10: NIC 37
A11: PROV-07 | B11: Desmantelamiento y descuento | C11: Valoración / Presentación | D11: Recalcular el valor presente a la tasa antes de impuestos y la reversión del descuento del período | E11: Estudio técnico, tasas | F11: NIC 37.45–47, 60; CINIIF 1; PYMES 21.7, 21.11 | G11: NIC 37 · CINIIF 1
A12: PROV-08 | B12: Contingencias y revelación | C12: Presentación y revelación | D12: Listar pasivos y activos contingentes y verificar su revelación; obtener manifestaciones escritas | E12: Notas, carta de manifestaciones | F12: NIC 37.86, 89; PYMES 21.15–21.16 | G12: NIC 37 · NIA 580

Sheet 00_Fuentes
A1: Base técnica | H1: ⟵ Inicio | I1: ◀ Anterior | J1: Siguiente ▶
A2: Provisiones y contingencias · Cliente de muestra S.A. · corte 2025-12-31
A4: Categoría | B4: Documento | C4: Párrafos | D4: URL | E4: Verificada
A5: NIA · NIA 501 | B5: Litigios y reclamaciones: indagación y carta a los abogados externos; negativa o falta de respuesta → opinión modificada (NIA 705). | C5: párr. 9–12
A6: NIA · NIA 540 (Revisada) | B6: Estimaciones contables: método, supuestos (probabilidades, tasa) y datos; rango del auditor. | C6: párr. 13, 22–26, 28–29 y 37
A7: NIA · NIA 560 | B7: Hechos posteriores: sentencias o acuerdos después del corte que confirman la obligación. | C7: párr. 6–9
A8: NIA · NIA 501 y NIA 580 | B8: Manifestaciones escritas sobre litigios, reclamaciones y contingencias conocidas. | C8: NIA 501 párr. 12; NIA 580 párr. 13
A9: NIA · NIA 500 | B9: Exactitud e integridad del detalle de provisiones frente al mayor. | C9: párr. 9

Sheet 01_Resumen
A1: Resumen | H1: ⟵ Inicio | I1: ◀ Anterior | J1: Siguiente ▶
A2: Provisiones y contingencias · Cliente de muestra S.A. · corte 2025-12-31
A4: Concepto | B4: Importe
A5: Provisiones registradas en libros | B5: ='15_Ajustes'!B5
A6: Provisión requerida (NIC 37 · Secc. 21) | B6: ='15_Ajustes'!B6
A7: Ajuste propuesto (requerida − libros) | B7: ='15_Ajustes'!B7
A8: Efecto del descuento a valor presente | B8: ='15_Ajustes'!B8
A9: Reversión del descuento calculada | B9: ='15_Ajustes'!B9
A10: Reversión del descuento registrada | B10: ='15_Ajustes'!B10
A11: Reversión: calculada − registrada (reclasificación) | B11: ='15_Ajustes'!B11
A12: Garantías calculadas | B12: ='15_Ajustes'!B12
A13: Pasivos contingentes a revelar (efecto estimado) | B13: ='15_Ajustes'!B13
A14: Pasivos contingentes sin revelar | B14: ='15_Ajustes'!B14
A15: Activo contingente reconocido indebidamente | B15: ='15_Ajustes'!B15
A16: Ajuste del activo contingente | B16: ='15_Ajustes'!B16
A17: Diferencia detalle − mayor | B17: ='15_Ajustes'!B18
A19: ⓘ Cómo se calcula esta hoja
A20: Columna | B20: Fórmula (Excel) | C20: Cómo se calcula (sencillo) | D20: Ejemplo con números reales | E20: De dónde viene | F20: Norma
A21: Importe | B21: '='15_Ajustes'!B5 | C21: Trae cada importe de la hoja 15 (Ajustes propuestos y conciliación), concepto por concepto, para que el resumen y el detalle coincidan siempre. | D21: Fila 1: 725.000,00 → 725.000,00 | E21: hoja «Ajustes propuestos y conciliación» | F21: —

Sheet 02_Parametros
A1: Parámetros | H1: ⟵ Inicio | I1: ◀ Anterior | J1: Siguiente ▶
A2: Provisiones y contingencias · Cliente de muestra S.A. · corte 2025-12-31
A4: Parámetro | B4: Valor | C4: Sustento
A5: Corte del ejercicio | B5: 46022 | C5: Ficha del encargo
A6: Marco contable | B6: NIIF completas | C6: Mismo cálculo en NIIF completas (NIC 37) y PYMES (Sección 21): no se enruta
A7: Edición PYMES | C7: 2015 y 2025: misma numeración en los párrafos citados y sin diferencias de cálculo (leído en PYMES 2015 ES y 2025 EN)
A8: Tasa de descuento por defecto (%) | B8: 8 | C8: Tasa antes de impuestos, riesgos específicos (NIC 37.47; PYMES 21.7)
A9: Descontar si el plazo supera (años) | B9: 1 | C9: Efecto material del valor temporal (NIC 37.45–46): juicio del auditor
A10: Materialidad (importe) | B10: 50000 | C10: Plan de auditoría (NIA 320)
A11: Tolerancia (importe) | B11: 1 | C11: Materialidad de ejecución / diferencias triviales
A12: Mayor: provisiones al corte | B12: 730000 | C12: Mayor contable

Sheet 03_Provisiones
A1: Provisiones y contingencias (datos del cliente) | H1: ⟵ Inicio | I1: ◀ Anterior | J1: Siguiente ▶
A2: Provisiones y contingencias · Cliente de muestra S.A. · corte 2025-12-31
A4: Código de la provisión o contingencia | B4: Descripción | C4: Tipo (Litigio/Garantía/Oneroso/Desmantelamiento/Reestructuración/Otro/Activo contingente) | D4: ¿Existe obligación presente? (Sí/No) | E4: Probabilidad según el abogado (Probable/Posible/Remota) | F4: Probabilidad según la gerencia (Probable/Posible/Remota) | G4: Importe según la carta del abogado | H4: Estimación de la gerencia (sin descontar) | I4: Importe mínimo del rango | J4: Importe máximo del rango | K4: Escenario 1: importe | L4: Escenario 1: probabilidad (%) | M4: Escenario 2: importe | N4: Escenario 2: probabilidad (%) | O4: Escenario 3: importe | P4: Escenario 3: probabilidad (%) | Q4: Método para escenarios (Valor esperado/Más probable) | R4: Oneroso: costo de cumplir | S4: Oneroso: penalización por incumplir | T4: Oneroso: beneficios económicos esperados del contrato | U4: Importe fijado después del corte (sentencia o acuerdo) | V4: Plazo esperado de salida (años) | W4: Tasa de descuento antes de impuestos (%) | X4: Saldo registrado en libros al corte | Y4: Saldo inicial del período | Z4: Reversión del descuento registrada en el período | AA4: ¿Se recibió respuesta del abogado? (Sí/No) | AB4: Fecha de la carta del abogado | AC4: ¿Revelado en notas? (Sí/No)
A5: LIT-01 | B5: Demanda laboral ex gerente | C5: Litigio | D5: Sí | E5: Probable | F5: Probable | G5: 120000 | K5: 150000 | L5: 60 | M5: 80000 | N5: 30 | O5: 0 | P5: 10 | V5: 1 | X5: 100000 | AA5: Sí | AB5: 46063 | AC5: Sí
A6: LIT-02 | B6: Juicio de impugnación tributaria | C6: Litigio | D6: Sí | E6: Probable | F6: Posible | G6: 85000 | I6: 60000 | J6: 100000 | V6: 2.5 | X6: 0 | AA6: Sí | AB6: 46006 | AC6: No
A7: LIT-03 | B7: Demanda civil de proveedor | C7: Litigio | D7: Sí | E7: Posible | G7: 40000 | V7: 1 | X7: 40000 | AA7: Sí | AB7: 46065 | AC7: Sí
A8: LIT-04 | B8: Reclamo de cliente por entrega tardía | C8: Litigio | D8: No | F8: Posible | I8: 10000 | J8: 30000 | X8: 0 | AA8: No | AC8: No
A9: GAR-01 | B9: Garantías de electrodomésticos | C9: Garantía | D9: Sí | F9: Probable | V9: 1 | X9: 30000
A10: ONE-01 | B10: Contrato de suministro con pérdida | C10: Oneroso | D10: Sí | F10: Probable | R10: 75000 | S10: 45000 | T10: 40000 | V10: 0.5 | X10: 0
A11: DES-01 | B11: Desmantelamiento de planta en terreno arrendado | C11: Desmantelamiento | D11: Sí | F11: Probable | H11: 500000 | V11: 10 | W11: 7 | X11: 240000 | Y11: 225000
A12: REE-01 | B12: Reestructuración de la línea textil (plan comunicado) | C12: Reestructuración | D12: Sí | F12: Probable | H12: 60000 | V12: 0.5 | X12: 60000
A13: AMB-01 | B13: Remediación ambiental de relaves | C13: Otro | D13: Sí | F13: Probable | H13: 200000 | V13: 5 | W13: 9 | X13: 200000 | Y13: 190000 | Z13: 5000
A14: LIT-05 | B14: Juicio laboral de operario | C14: Litigio | D14: Sí | E14: Probable | G14: 25000 | U14: 32000 | V14: 0.25 | X14: 25000 | AA14: Sí | AB14: 46063
A15: LIT-06 | B15: Demanda por uso de marca | C15: Litigio | D15: No | E15: Remota | X15: 0 | AA15: Sí | AB15: 46063
A16: OTR-01 | B16: Multa de la autoridad ambiental | C16: Otro | D16: Sí | F16: Probable | K16: 30000 | L16: 50 | M16: 60000 | N16: 30 | O16: 90000 | P16: 20 | Q16: Más probable | V16: 1 | X16: 30000
A17: ACT-01 | B17: Demanda a la aseguradora por siniestro | C17: Activo contingente | E17: Probable | G17: 50000 | X17: 50000 | AA17: Sí | AB17: 46063 | AC17: No

Sheet 04_Garantias
A1: Garantías (datos del cliente) | H1: ⟵ Inicio | I1: ◀ Anterior | J1: Siguiente ▶
A2: Provisiones y contingencias · Cliente de muestra S.A. · corte 2025-12-31
A4: Línea | B4: Provisión | C4: Descripción | D4: Unidades con garantía | E4: % reclamos | F4: Costo medio
A5: GA-A | B5: GAR-01 | C5: Refrigeradoras | D5: 12000 | E5: 3 | F5: 85
A6: GA-B | B6: GAR-01 | C6: Lavadoras | D6: 5000 | E6: 2 | F6: 120
A7: GA-C | B7: GAR-09 | C7: Microondas | D7: 2000 | E7: 5 | F7: 50

Sheet 05_Obligacion_prob
A1: Obligación presente y probabilidad | H1: ⟵ Inicio | I1: ◀ Anterior | J1: Siguiente ▶
A2: Provisiones y contingencias · Cliente de muestra S.A. · corte 2025-12-31
A4: Código | B4: Tipo | C4: Obligación presente | D4: Prob. abogado | E4: Prob. gerencia | F4: Probabilidad usada | G4: Clasificación (NIC 37.14, 23, 27–35) | H4: Discrepancia
A5: LIT-01 | B5: ='03_Provisiones'!C5 | C5: =IF('03_Provisiones'!D5="","",'03_Provisiones'!D5) | D5: =IF('03_Provisiones'!E5="","",'03_Provisiones'!E5) | E5: =IF('03_Provisiones'!F5="","",'03_Provisiones'!F5) | F5: =IF(D5<>"",D5,E5) | G5: =IF(B5="Activo contingente",IF(F5="","Sin evaluación",IF(F5="Prácticamente cierta","Activo reconocible",IF(F5="Probable","Activo contingente: revelar","Activo contingente: no revelar"))),IF(OR(F5="",C5=""),"Sin evaluación",IF(F5="Remota","Remota: no revelar",IF(AND(C5="Sí",OR(F5="Probable",F5="Prácticamente cierta")),"Reconocer provisión","Pasivo contingente: revelar")))) | H5: =IF(AND(D5<>"",E5<>"",D5<>E5),"Discrepancia","")
A6: LIT-02 | B6: ='03_Provisiones'!C6 | C6: =IF('03_Provisiones'!D6="","",'03_Provisiones'!D6) | D6: =IF('03_Provisiones'!E6="","",'03_Provisiones'!E6) | E6: =IF('03_Provisiones'!F6="","",'03_Provisiones'!F6) | F6: =IF(D6<>"",D6,E6) | G6: =IF(B6="Activo contingente",IF(F6="","Sin evaluación",IF(F6="Prácticamente cierta","Activo reconocible",IF(F6="Probable","Activo contingente: revelar","Activo contingente: no revelar"))),IF(OR(F6="",C6=""),"Sin evaluación",IF(F6="Remota","Remota: no revelar",IF(AND(C6="Sí",OR(F6="Probable",F6="Prácticamente cierta")),"Reconocer provisión","Pasivo contingente: revelar")))) | H6: =IF(AND(D6<>"",E6<>"",D6<>E6),"Discrepancia","")
A7: LIT-03 | B7: ='03_Provisiones'!C7 | C7: =IF('03_Provisiones'!D7="","",'03_Provisiones'!D7) | D7: =IF('03_Provisiones'!E7="","",'03_Provisiones'!E7) | E7: =IF('03_Provisiones'!F7="","",'03_Provisiones'!F7) | F7: =IF(D7<>"",D7,E7) | G7: =IF(B7="Activo contingente",IF(F7="","Sin evaluación",IF(F7="Prácticamente cierta","Activo reconocible",IF(F7="Probable","Activo contingente: revelar","Activo contingente: no revelar"))),IF(OR(F7="",C7=""),"Sin evaluación",IF(F7="Remota","Remota: no revelar",IF(AND(C7="Sí",OR(F7="Probable",F7="Prácticamente cierta")),"Reconocer provisión","Pasivo contingente: revelar")))) | H7: =IF(AND(D7<>"",E7<>"",D7<>E7),"Discrepancia","")
A8: LIT-04 | B8: ='03_Provisiones'!C8 | C8: =IF('03_Provisiones'!D8="","",'03_Provisiones'!D8) | D8: =IF('03_Provisiones'!E8="","",'03_Provisiones'!E8) | E8: =IF('03_Provisiones'!F8="","",'03_Provisiones'!F8) | F8: =IF(D8<>"",D8,E8) | G8: =IF(B8="Activo contingente",IF(F8="","Sin evaluación",IF(F8="Prácticamente cierta","Activo reconocible",IF(F8="Probable","Activo contingente: revelar","Activo contingente: no revelar"))),IF(OR(F8="",C8=""),"Sin evaluación",IF(F8="Remota","Remota: no revelar",IF(AND(C8="Sí",OR(F8="Probable",F8="Prácticamente cierta")),"Reconocer provisión","Pasivo contingente: revelar")))) | H8: =IF(AND(D8<>"",E8<>"",D8<>E8),"Discrepancia","")
A9: GAR-01 | B9: ='03_Provisiones'!C9 | C9: =IF('03_Provisiones'!D9="","",'03_Provisiones'!D9) | D9: =IF('03_Provisiones'!E9="","",'03_Provisiones'!E9) | E9: =IF('03_Provisiones'!F9="","",'03_Provisiones'!F9) | F9: =IF(D9<>"",D9,E9) | G9: =IF(B9="Activo contingente",IF(F9="","Sin evaluación",IF(F9="Prácticamente cierta","Activo reconocible",IF(F9="Probable","Activo contingente: revelar","Activo contingente: no revelar"))),IF(OR(F9="",C9=""),"Sin evaluación",IF(F9="Remota","Remota: no revelar",IF(AND(C9="Sí",OR(F9="Probable",F9="Prácticamente cierta")),"Reconocer provisión","Pasivo contingente: revelar")))) | H9: =IF(AND(D9<>"",E9<>"",D9<>E9),"Discrepancia","")
A10: ONE-01 | B10: ='03_Provisiones'!C10 | C10: =IF('03_Provisiones'!D10="","",'03_Provisiones'!D10) | D10: =IF('03_Provisiones'!E10="","",'03_Provisiones'!E10) | E10: =IF('03_Provisiones'!F10="","",'03_Provisiones'!F10) | F10: =IF(D10<>"",D10,E10) | G10: =IF(B10="Activo contingente",IF(F10="","Sin evaluación",IF(F10="Prácticamente cierta","Activo reconocible",IF(F10="Probable","Activo contingente: revelar","Activo contingente: no revelar"))),IF(OR(F10="",C10=""),"Sin evaluación",IF(F10="Remota","Remota: no revelar",IF(AND(C10="Sí",OR(F10="Probable",F10="Prácticamente cierta")),"Reconocer provisión","Pasivo contingente: revelar")))) | H10: =IF(AND(D10<>"",E10<>"",D10<>E10),"Discrepancia","")
A11: DES-01 | B11: ='03_Provisiones'!C11 | C11: =IF('03_Provisiones'!D11="","",'03_Provisiones'!D11) | D11: =IF('03_Provisiones'!E11="","",'03_Provisiones'!E11) | E11: =IF('03_Provisiones'!F11="","",'03_Provisiones'!F11) | F11: =IF(D11<>"",D11,E11) | G11: =IF(B11="Activo contingente",IF(F11="","Sin evaluación",IF(F11="Prácticamente cierta","Activo reconocible",IF(F11="Probable","Activo contingente: revelar","Activo contingente: no revelar"))),IF(OR(F11="",C11=""),"Sin evaluación",IF(F11="Remota","Remota: no revelar",IF(AND(C11="Sí",OR(F11="Probable",F11="Prácticamente cierta")),"Reconocer provisión","Pasivo contingente: revelar")))) | H11: =IF(AND(D11<>"",E11<>"",D11<>E11),"Discrepancia","")
A12: REE-01 | B12: ='03_Provisiones'!C12 | C12: =IF('03_Provisiones'!D12="","",'03_Provisiones'!D12) | D12: =IF('03_Provisiones'!E12="","",'03_Provisiones'!E12) | E12: =IF('03_Provisiones'!F12="","",'03_Provisiones'!F12) | F12: =IF(D12<>"",D12,E12) | G12: =IF(B12="Activo contingente",IF(F12="","Sin evaluación",IF(F12="Prácticamente cierta","Activo reconocible",IF(F12="Probable","Activo contingente: revelar","Activo contingente: no revelar"))),IF(OR(F12="",C12=""),"Sin evaluación",IF(F12="Remota","Remota: no revelar",IF(AND(C12="Sí",OR(F12="Probable",F12="Prácticamente cierta")),"Reconocer provisión","Pasivo contingente: revelar")))) | H12: =IF(AND(D12<>"",E12<>"",D12<>E12),"Discrepancia","")
A13: AMB-01 | B13: ='03_Provisiones'!C13 | C13: =IF('03_Provisiones'!D13="","",'03_Provisiones'!D13) | D13: =IF('03_Provisiones'!E13="","",'03_Provisiones'!E13) | E13: =IF('03_Provisiones'!F13="","",'03_Provisiones'!F13) | F13: =IF(D13<>"",D13,E13) | G13: =IF(B13="Activo contingente",IF(F13="","Sin evaluación",IF(F13="Prácticamente cierta","Activo reconocible",IF(F13="Probable","Activo contingente: revelar","Activo contingente: no revelar"))),IF(OR(F13="",C13=""),"Sin evaluación",IF(F13="Remota","Remota: no revelar",IF(AND(C13="Sí",OR(F13="Probable",F13="Prácticamente cierta")),"Reconocer provisión","Pasivo contingente: revelar")))) | H13: =IF(AND(D13<>"",E13<>"",D13<>E13),"Discrepancia","")
A14: LIT-05 | B14: ='03_Provisiones'!C14 | C14: =IF('03_Provisiones'!D14="","",'03_Provisiones'!D14) | D14: =IF('03_Provisiones'!E14="","",'03_Provisiones'!E14) | E14: =IF('03_Provisiones'!F14="","",'03_Provisiones'!F14) | F14: =IF(D14<>"",D14,E14) | G14: =IF(B14="Activo contingente",IF(F14="","Sin evaluación",IF(F14="Prácticamente cierta","Activo reconocible",IF(F14="Probable","Activo contingente: revelar","Activo contingente: no revelar"))),IF(OR(F14="",C14=""),"Sin evaluación",IF(F14="Remota","Remota: no revelar",IF(AND(C14="Sí",OR(F14="Probable",F14="Prácticamente cierta")),"Reconocer provisión","Pasivo contingente: revelar")))) | H14: =IF(AND(D14<>"",E14<>"",D14<>E14),"Discrepancia","")
A15: LIT-06 | B15: ='03_Provisiones'!C15 | C15: =IF('03_Provisiones'!D15="","",'03_Provisiones'!D15) | D15: =IF('03_Provisiones'!E15="","",'03_Provisiones'!E15) | E15: =IF('03_Provisiones'!F15="","",'03_Provisiones'!F15) | F15: =IF(D15<>"",D15,E15) | G15: =IF(B15="Activo contingente",IF(F15="","Sin evaluación",IF(F15="Prácticamente cierta","Activo reconocible",IF(F15="Probable","Activo contingente: revelar","Activo contingente: no revelar"))),IF(OR(F15="",C15=""),"Sin evaluación",IF(F15="Remota","Remota: no revelar",IF(AND(C15="Sí",OR(F15="Probable",F15="Prácticamente cierta")),"Reconocer provisión","Pasivo contingente: revelar")))) | H15: =IF(AND(D15<>"",E15<>"",D15<>E15),"Discrepancia","")
A16: OTR-01 | B16: ='03_Provisiones'!C16 | C16: =IF('03_Provisiones'!D16="","",'03_Provisiones'!D16) | D16: =IF('03_Provisiones'!E16="","",'03_Provisiones'!E16) | E16: =IF('03_Provisiones'!F16="","",'03_Provisiones'!F16) | F16: =IF(D16<>"",D16,E16) | G16: =IF(B16="Activo contingente",IF(F16="","Sin evaluación",IF(F16="Prácticamente cierta","Activo reconocible",IF(F16="Probable","Activo contingente: revelar","Activo contingente: no revelar"))),IF(OR(F16="",C16=""),"Sin evaluación",IF(F16="Remota","Remota: no revelar",IF(AND(C16="Sí",OR(F16="Probable",F16="Prácticamente cierta")),"Reconocer provisión","Pasivo contingente: revelar")))) | H16: =IF(AND(D16<>"",E16<>"",D16<>E16),"Discrepancia","")
A17: ACT-01 | B17: ='03_Provisiones'!C17 | C17: =IF('03_Provisiones'!D17="","",'03_Provisiones'!D17) | D17: =IF('03_Provisiones'!E17="","",'03_Provisiones'!E17) | E17: =IF('03_Provisiones'!F17="","",'03_Provisiones'!F17) | F17: =IF(D17<>"",D17,E17) | G17: =IF(B17="Activo contingente",IF(F17="","Sin evaluación",IF(F17="Prácticamente cierta","Activo reconocible",IF(F17="Probable","Activo contingente: revelar","Activo contingente: no revelar"))),IF(OR(F17="",C17=""),"Sin evaluación",IF(F17="Remota","Remota: no revelar",IF(AND(C17="Sí",OR(F17="Probable",F17="Prácticamente cierta")),"Reconocer provisión","Pasivo contingente: revelar")))) | H17: =IF(AND(D17<>"",E17<>"",D17<>E17),"Discrepancia","")
A19: ⓘ Cómo se calcula esta hoja
A20: Columna | B20: Fórmula (Excel) | C20: Cómo se calcula (sencillo) | D20: Ejemplo con números reales | E20: De dónde viene | F20: Norma
A21: Tipo | B21: '='03_Provisiones'!C5 | C21: Copia el tipo de la partida (litigio, garantía, oneroso, etc.) desde la hoja 03 (datos del cliente), en la misma fila. | D21: Fila 1: «Litigio» → Litigio | E21: hoja «Provisiones y contingencias (datos del cliente)» | F21: —
A22: Obligación presente | B22: '=IF('03_Provisiones'!D5="","",'03_Provisiones'!D5) | C22: Copia de la hoja 03 (datos del cliente) si existe obligación presente (Sí/No); si el cliente la dejó vacía, queda en blanco. | D22: Fila 1: IF(«Sí»=""; ""; «Sí») → Sí | E22: hoja «Provisiones y contingencias (datos del cliente)» | F22: —
A23: Prob. abogado | B23: '=IF('03_Provisiones'!E5="","",'03_Provisiones'!E5) | C23: Copia la probabilidad que asigna el abogado desde la hoja 03 (datos del cliente); si no la informó, queda en blanco. | D23: Fila 1: IF(«Probable»=""; ""; «Probable») → Probable | E23: hoja «Provisiones y contingencias (datos del cliente)» | F23: —
A24: Prob. gerencia | B24: '=IF('03_Provisiones'!F5="","",'03_Provisiones'!F5) | C24: Copia la probabilidad que asigna la gerencia desde la hoja 03 (datos del cliente); si no la informó, queda en blanco. | D24: Fila 1: IF(«Probable»=""; ""; «Probable») → Probable | E24: hoja «Provisiones y contingencias (datos del cliente)» | F24: —
A25: Probabilidad usada | B25: '=IF(D5<>"",D5,E5) | C25: Usa la probabilidad del abogado y, si no la hay, la probabilidad de la gerencia. | D25: Fila 1: IF(«Probable»<>""; «Probable»; «Probable») → Probable | E25: «Prob. abogado» (esta hoja), «Prob. gerencia» (esta hoja) | F25: —
A26: Clasificación (NIC 37.14, 23, 27–35) | B26: '=IF(B5="Activo contingente",IF(F5="","Sin evaluación",IF(F5="Prácticamente cierta","Activo reconocible",IF(F5="Probable","Activo contingente: revelar","Activo contingente: no revelar"))),IF(OR(F5="",C5=""),"Sin evaluación",IF(F5="Remota","Remota: no revelar",IF(AND(C5="Sí",OR(F5="Probable",F5="Prácticamente cierta")),"Reconocer provisión","Pasivo contingente: revelar")))) | C26: En un activo contingente: prácticamente cierto → reconocible, probable → revelar y lo demás → no revelar. En el resto: sin obligación o sin probabilidad queda «Sin evaluación»; remota → no revelar; obligación presente y probable (o prácticamente cierta) → reconocer provisión; si no, pasivo contingente a revelar. | D26: Fila 1: IF(«Litigio»="Activo contingente"; IF(«Probable»=""; "Sin evaluación"; IF(«Probable»="Prácticamente cierta"; "Activo reconocible"; IF(«Probable»="Probable"; "Activo contingente: revelar"; "Activo contingente: no revelar"))); IF(OR(«Probable»=""; «Sí»=""); "Sin evaluación"; IF(«Probable»="Remota"; "Remota: no revelar"; IF(AND(«Sí»="Sí"; OR(«Probable»="Probable"; «Probable»="Prácticamente cierta")); "Reconocer provisión"; "Pasivo contingente: revelar")))) → Reconocer provisión | E26: «Tipo» (esta hoja), «Probabilidad usada» (esta hoja), «Obligación presente» (esta hoja) | F26: —
A27: Discrepancia | B27: '=IF(AND(D5<>"",E5<>"",D5<>E5),"Discrepancia","") | C27: Marca «Discrepancia» cuando el abogado y la gerencia informaron probabilidades distintas; si coinciden o falta alguna, queda vacío. | D27: Fila 1: IF(AND(«Probable»<>""; «Probable»<>""; «Probable»<>«Probable»); "Discrepancia"; "") → (en blanco) | E27: «Prob. abogado» (esta hoja), «Prob. gerencia» (esta hoja) | F27: —

Sheet 06_Mejor_estimacion
A1: Mejor estimación | H1: ⟵ Inicio | I1: ◀ Anterior | J1: Siguiente ▶
A2: Provisiones y contingencias · Cliente de muestra S.A. · corte 2025-12-31
A4: Código | B4: Hecho posterior | C4: Oneroso: mín(costo neto, penalización) | D4: Garantías | E4: Σ probabilidades % | F4: Valor esperado | G4: Más probable | H4: Punto medio del rango | I4: Carta del abogado | J4: Estimación gerencia | K4: Base usada | L4: Mejor estimación
A5: LIT-01 | B5: =IF('03_Provisiones'!U5="","",'03_Provisiones'!U5) | C5: =IF('03_Provisiones'!C5<>"Oneroso","",IF(AND('03_Provisiones'!R5="",'03_Provisiones'!S5=""),"",IF('03_Provisiones'!R5="",'03_Provisiones'!S5,IF('03_Provisiones'!S5="",MAX('03_Provisiones'!R5-N('03_Provisiones'!T5),0),MIN(MAX('03_Provisiones'!R5-N('03_Provisiones'!T5),0),'03_Provisiones'!S5))))) | D5: =IF('03_Provisiones'!C5="Garantía",IF(COUNTIF('04_Garantias'!$B$5:$B$7,A5)=0,"",SUMIF('04_Garantias'!$B$5:$B$7,A5,'10_Garantias_calculo'!$F$5:$F$7)),"") | E5: =N('03_Provisiones'!L5)+N('03_Provisiones'!N5)+N('03_Provisiones'!P5) | F5: =IF(E5=0,"",(N('03_Provisiones'!K5)*N('03_Provisiones'!L5)+N('03_Provisiones'!M5)*N('03_Provisiones'!N5)+N('03_Provisiones'!O5)*N('03_Provisiones'!P5))/(N('03_Provisiones'!L5)+N('03_Provisiones'!N5)+N('03_Provisiones'!P5))) | G5: =IF(E5=0,"",IF(AND(N('03_Provisiones'!L5)>=N('03_Provisiones'!N5),N('03_Provisiones'!L5)>=N('03_Provisiones'!P5)),'03_Provisiones'!K5,IF(N('03_Provisiones'!N5)>=N('03_Provisiones'!P5),'03_Provisiones'!M5,'03_Provisiones'!O5))) | H5: =IF(AND('03_Provisiones'!I5<>"",'03_Provisiones'!J5<>""),('03_Provisiones'!I5+'03_Provisiones'!J5)/2,"") | I5: =IF('03_Provisiones'!G5="","",'03_Provisiones'!G5) | J5: =IF('03_Provisiones'!H5="","",'03_Provisiones'!H5) | K5: =IF(B5<>"","Hecho posterior (NIC 10.9 a)",IF(C5<>"","Oneroso: menor costo (37.68)",IF(D5<>"","Garantías: valor esperado (37.39)",IF(E5>0,IF('03_Provisiones'!Q5="Más probable","Desenlace más probable (37.40)","Valor esperado (37.39)"),IF(H5<>"","Punto medio del rango (37.39)",IF(I5<>"","Carta del abogado",IF(J5<>"","Estimación de la gerencia","Sin estimación"))))))) | L5: =IF(B5<>"",B5,IF(C5<>"",C5,IF(D5<>"",D5,IF(E5>0,IF('03_Provisiones'!Q5="Más probable",G5,F5),IF(H5<>"",H5,IF(I5<>"",I5,IF(J5<>"",J5,"")))))))
A6: LIT-02 | B6: =IF('03_Provisiones'!U6="","",'03_Provisiones'!U6) | C6: =IF('03_Provisiones'!C6<>"Oneroso","",IF(AND('03_Provisiones'!R6="",'03_Provisiones'!S6=""),"",IF('03_Provisiones'!R6="",'03_Provisiones'!S6,IF('03_Provisiones'!S6="",MAX('03_Provisiones'!R6-N('03_Provisiones'!T6),0),MIN(MAX('03_Provisiones'!R6-N('03_Provisiones'!T6),0),'03_Provisiones'!S6))))) | D6: =IF('03_Provisiones'!C6="Garantía",IF(COUNTIF('04_Garantias'!$B$5:$B$7,A6)=0,"",SUMIF('04_Garantias'!$B$5:$B$7,A6,'10_Garantias_calculo'!$F$5:$F$7)),"") | E6: =N('03_Provisiones'!L6)+N('03_Provisiones'!N6)+N('03_Provisiones'!P6) | F6: =IF(E6=0,"",(N('03_Provisiones'!K6)*N('03_Provisiones'!L6)+N('03_Provisiones'!M6)*N('03_Provisiones'!N6)+N('03_Provisiones'!O6)*N('03_Provisiones'!P6))/(N('03_Provisiones'!L6)+N('03_Provisiones'!N6)+N('03_Provisiones'!P6))) | G6: =IF(E6=0,"",IF(AND(N('03_Provisiones'!L6)>=N('03_Provisiones'!N6),N('03_Provisiones'!L6)>=N('03_Provisiones'!P6)),'03_Provisiones'!K6,IF(N('03_Provisiones'!N6)>=N('03_Provisiones'!P6),'03_Provisiones'!M6,'03_Provisiones'!O6))) | H6: =IF(AND('03_Provisiones'!I6<>"",'03_Provisiones'!J6<>""),('03_Provisiones'!I6+'03_Provisiones'!J6)/2,"") | I6: =IF('03_Provisiones'!G6="","",'03_Provisiones'!G6) | J6: =IF('03_Provisiones'!H6="","",'03_Provisiones'!H6) | K6: =IF(B6<>"","Hecho posterior (NIC 10.9 a)",IF(C6<>"","Oneroso: menor costo (37.68)",IF(D6<>"","Garantías: valor esperado (37.39)",IF(E6>0,IF('03_Provisiones'!Q6="Más probable","Desenlace más probable (37.40)","Valor esperado (37.39)"),IF(H6<>"","Punto medio del rango (37.39)",IF(I6<>"","Carta del abogado",IF(J6<>"","Estimación de la gerencia","Sin estimación"))))))) | L6: =IF(B6<>"",B6,IF(C6<>"",C6,IF(D6<>"",D6,IF(E6>0,IF('03_Provisiones'!Q6="Más probable",G6,F6),IF(H6<>"",H6,IF(I6<>"",I6,IF(J6<>"",J6,"")))))))
A7: LIT-03 | B7: =IF('03_Provisiones'!U7="","",'03_Provisiones'!U7) | C7: =IF('03_Provisiones'!C7<>"Oneroso","",IF(AND('03_Provisiones'!R7="",'03_Provisiones'!S7=""),"",IF('03_Provisiones'!R7="",'03_Provisiones'!S7,IF('03_Provisiones'!S7="",MAX('03_Provisiones'!R7-N('03_Provisiones'!T7),0),MIN(MAX('03_Provisiones'!R7-N('03_Provisiones'!T7),0),'03_Provisiones'!S7))))) | D7: =IF('03_Provisiones'!C7="Garantía",IF(COUNTIF('04_Garantias'!$B$5:$B$7,A7)=0,"",SUMIF('04_Garantias'!$B$5:$B$7,A7,'10_Garantias_calculo'!$F$5:$F$7)),"") | E7: =N('03_Provisiones'!L7)+N('03_Provisiones'!N7)+N('03_Provisiones'!P7) | F7: =IF(E7=0,"",(N('03_Provisiones'!K7)*N('03_Provisiones'!L7)+N('03_Provisiones'!M7)*N('03_Provisiones'!N7)+N('03_Provisiones'!O7)*N('03_Provisiones'!P7))/(N('03_Provisiones'!L7)+N('03_Provisiones'!N7)+N('03_Provisiones'!P7))) | G7: =IF(E7=0,"",IF(AND(N('03_Provisiones'!L7)>=N('03_Provisiones'!N7),N('03_Provisiones'!L7)>=N('03_Provisiones'!P7)),'03_Provisiones'!K7,IF(N('03_Provisiones'!N7)>=N('03_Provisiones'!P7),'03_Provisiones'!M7,'03_Provisiones'!O7))) | H7: =IF(AND('03_Provisiones'!I7<>"",'03_Provisiones'!J7<>""),('03_Provisiones'!I7+'03_Provisiones'!J7)/2,"") | I7: =IF('03_Provisiones'!G7="","",'03_Provisiones'!G7) | J7: =IF('03_Provisiones'!H7="","",'03_Provisiones'!H7) | K7: =IF(B7<>"","Hecho posterior (NIC 10.9 a)",IF(C7<>"","Oneroso: menor costo (37.68)",IF(D7<>"","Garantías: valor esperado (37.39)",IF(E7>0,IF('03_Provisiones'!Q7="Más probable","Desenlace más probable (37.40)","Valor esperado (37.39)"),IF(H7<>"","Punto medio del rango (37.39)",IF(I7<>"","Carta del abogado",IF(J7<>"","Estimación de la gerencia","Sin estimación"))))))) | L7: =IF(B7<>"",B7,IF(C7<>"",C7,IF(D7<>"",D7,IF(E7>0,IF('03_Provisiones'!Q7="Más probable",G7,F7),IF(H7<>"",H7,IF(I7<>"",I7,IF(J7<>"",J7,"")))))))
A8: LIT-04 | B8: =IF('03_Provisiones'!U8="","",'03_Provisiones'!U8) | C8: =IF('03_Provisiones'!C8<>"Oneroso","",IF(AND('03_Provisiones'!R8="",'03_Provisiones'!S8=""),"",IF('03_Provisiones'!R8="",'03_Provisiones'!S8,IF('03_Provisiones'!S8="",MAX('03_Provisiones'!R8-N('03_Provisiones'!T8),0),MIN(MAX('03_Provisiones'!R8-N('03_Provisiones'!T8),0),'03_Provisiones'!S8))))) | D8: =IF('03_Provisiones'!C8="Garantía",IF(COUNTIF('04_Garantias'!$B$5:$B$7,A8)=0,"",SUMIF('04_Garantias'!$B$5:$B$7,A8,'10_Garantias_calculo'!$F$5:$F$7)),"") | E8: =N('03_Provisiones'!L8)+N('03_Provisiones'!N8)+N('03_Provisiones'!P8) | F8: =IF(E8=0,"",(N('03_Provisiones'!K8)*N('03_Provisiones'!L8)+N('03_Provisiones'!M8)*N('03_Provisiones'!N8)+N('03_Provisiones'!O8)*N('03_Provisiones'!P8))/(N('03_Provisiones'!L8)+N('03_Provisiones'!N8)+N('03_Provisiones'!P8))) | G8: =IF(E8=0,"",IF(AND(N('03_Provisiones'!L8)>=N('03_Provisiones'!N8),N('03_Provisiones'!L8)>=N('03_Provisiones'!P8)),'03_Provisiones'!K8,IF(N('03_Provisiones'!N8)>=N('03_Provisiones'!P8),'03_Provisiones'!M8,'03_Provisiones'!O8))) | H8: =IF(AND('03_Provisiones'!I8<>"",'03_Provisiones'!J8<>""),('03_Provisiones'!I8+'03_Provisiones'!J8)/2,"") | I8: =IF('03_Provisiones'!G8="","",'03_Provisiones'!G8) | J8: =IF('03_Provisiones'!H8="","",'03_Provisiones'!H8) | K8: =IF(B8<>"","Hecho posterior (NIC 10.9 a)",IF(C8<>"","Oneroso: menor costo (37.68)",IF(D8<>"","Garantías: valor esperado (37.39)",IF(E8>0,IF('03_Provisiones'!Q8="Más probable","Desenlace más probable (37.40)","Valor esperado (37.39)"),IF(H8<>"","Punto medio del rango (37.39)",IF(I8<>"","Carta del abogado",IF(J8<>"","Estimación de la gerencia","Sin estimación"))))))) | L8: =IF(B8<>"",B8,IF(C8<>"",C8,IF(D8<>"",D8,IF(E8>0,IF('03_Provisiones'!Q8="Más probable",G8,F8),IF(H8<>"",H8,IF(I8<>"",I8,IF(J8<>"",J8,"")))))))
A9: GAR-01 | B9: =IF('03_Provisiones'!U9="","",'03_Provisiones'!U9) | C9: =IF('03_Provisiones'!C9<>"Oneroso","",IF(AND('03_Provisiones'!R9="",'03_Provisiones'!S9=""),"",IF('03_Provisiones'!R9="",'03_Provisiones'!S9,IF('03_Provisiones'!S9="",MAX('03_Provisiones'!R9-N('03_Provisiones'!T9),0),MIN(MAX('03_Provisiones'!R9-N('03_Provisiones'!T9),0),'03_Provisiones'!S9))))) | D9: =IF('03_Provisiones'!C9="Garantía",IF(COUNTIF('04_Garantias'!$B$5:$B$7,A9)=0,"",SUMIF('04_Garantias'!$B$5:$B$7,A9,'10_Garantias_calculo'!$F$5:$F$7)),"") | E9: =N('03_Provisiones'!L9)+N('03_Provisiones'!N9)+N('03_Provisiones'!P9) | F9: =IF(E9=0,"",(N('03_Provisiones'!K9)*N('03_Provisiones'!L9)+N('03_Provisiones'!M9)*N('03_Provisiones'!N9)+N('03_Provisiones'!O9)*N('03_Provisiones'!P9))/(N('03_Provisiones'!L9)+N('03_Provisiones'!N9)+N('03_Provisiones'!P9))) | G9: =IF(E9=0,"",IF(AND(N('03_Provisiones'!L9)>=N('03_Provisiones'!N9),N('03_Provisiones'!L9)>=N('03_Provisiones'!P9)),'03_Provisiones'!K9,IF(N('03_Provisiones'!N9)>=N('03_Provisiones'!P9),'03_Provisiones'!M9,'03_Provisiones'!O9))) | H9: =IF(AND('03_Provisiones'!I9<>"",'03_Provisiones'!J9<>""),('03_Provisiones'!I9+'03_Provisiones'!J9)/2,"") | I9: =IF('03_Provisiones'!G9="","",'03_Provisiones'!G9) | J9: =IF('03_Provisiones'!H9="","",'03_Provisiones'!H9) | K9: =IF(B9<>"","Hecho posterior (NIC 10.9 a)",IF(C9<>"","Oneroso: menor costo (37.68)",IF(D9<>"","Garantías: valor esperado (37.39)",IF(E9>0,IF('03_Provisiones'!Q9="Más probable","Desenlace más probable (37.40)","Valor esperado (37.39)"),IF(H9<>"","Punto medio del rango (37.39)",IF(I9<>"","Carta del abogado",IF(J9<>"","Estimación de la gerencia","Sin estimación"))))))) | L9: =IF(B9<>"",B9,IF(C9<>"",C9,IF(D9<>"",D9,IF(E9>0,IF('03_Provisiones'!Q9="Más probable",G9,F9),IF(H9<>"",H9,IF(I9<>"",I9,IF(J9<>"",J9,"")))))))
A10: ONE-01 | B10: =IF('03_Provisiones'!U10="","",'03_Provisiones'!U10) | C10: =IF('03_Provisiones'!C10<>"Oneroso","",IF(AND('03_Provisiones'!R10="",'03_Provisiones'!S10=""),"",IF('03_Provisiones'!R10="",'03_Provisiones'!S10,IF('03_Provisiones'!S10="",MAX('03_Provisiones'!R10-N('03_Provisiones'!T10),0),MIN(MAX('03_Provisiones'!R10-N('03_Provisiones'!T10),0),'03_Provisiones'!S10))))) | D10: =IF('03_Provisiones'!C10="Garantía",IF(COUNTIF('04_Garantias'!$B$5:$B$7,A10)=0,"",SUMIF('04_Garantias'!$B$5:$B$7,A10,'10_Garantias_calculo'!$F$5:$F$7)),"") | E10: =N('03_Provisiones'!L10)+N('03_Provisiones'!N10)+N('03_Provisiones'!P10) | F10: =IF(E10=0,"",(N('03_Provisiones'!K10)*N('03_Provisiones'!L10)+N('03_Provisiones'!M10)*N('03_Provisiones'!N10)+N('03_Provisiones'!O10)*N('03_Provisiones'!P10))/(N('03_Provisiones'!L10)+N('03_Provisiones'!N10)+N('03_Provisiones'!P10))) | G10: =IF(E10=0,"",IF(AND(N('03_Provisiones'!L10)>=N('03_Provisiones'!N10),N('03_Provisiones'!L10)>=N('03_Provisiones'!P10)),'03_Provisiones'!K10,IF(N('03_Provisiones'!N10)>=N('03_Provisiones'!P10),'03_Provisiones'!M10,'03_Provisiones'!O10))) | H10: =IF(AND('03_Provisiones'!I10<>"",'03_Provisiones'!J10<>""),('03_Provisiones'!I10+'03_Provisiones'!J10)/2,"") | I10: =IF('03_Provisiones'!G10="","",'03_Provisiones'!G10) | J10: =IF('03_Provisiones'!H10="","",'03_Provisiones'!H10) | K10: =IF(B10<>"","Hecho posterior (NIC 10.9 a)",IF(C10<>"","Oneroso: menor costo (37.68)",IF(D10<>"","Garantías: valor esperado (37.39)",IF(E10>0,IF('03_Provisiones'!Q10="Más probable","Desenlace más probable (37.40)","Valor esperado (37.39)"),IF(H10<>"","Punto medio del rango (37.39)",IF(I10<>"","Carta del abogado",IF(J10<>"","Estimación de la gerencia","Sin estimación"))))))) | L10: =IF(B10<>"",B10,IF(C10<>"",C10,IF(D10<>"",D10,IF(E10>0,IF('03_Provisiones'!Q10="Más probable",G10,F10),IF(H10<>"",H10,IF(I10<>"",I10,IF(J10<>"",J10,"")))))))
A11: DES-01 | B11: =IF('03_Provisiones'!U11="","",'03_Provisiones'!U11) | C11: =IF('03_Provisiones'!C11<>"Oneroso","",IF(AND('03_Provisiones'!R11="",'03_Provisiones'!S11=""),"",IF('03_Provisiones'!R11="",'03_Provisiones'!S11,IF('03_Provisiones'!S11="",MAX('03_Provisiones'!R11-N('03_Provisiones'!T11),0),MIN(MAX('03_Provisiones'!R11-N('03_Provisiones'!T11),0),'03_Provisiones'!S11))))) | D11: =IF('03_Provisiones'!C11="Garantía",IF(COUNTIF('04_Garantias'!$B$5:$B$7,A11)=0,"",SUMIF('04_Garantias'!$B$5:$B$7,A11,'10_Garantias_calculo'!$F$5:$F$7)),"") | E11: =N('03_Provisiones'!L11)+N('03_Provisiones'!N11)+N('03_Provisiones'!P11) | F11: =IF(E11=0,"",(N('03_Provisiones'!K11)*N('03_Provisiones'!L11)+N('03_Provisiones'!M11)*N('03_Provisiones'!N11)+N('03_Provisiones'!O11)*N('03_Provisiones'!P11))/(N('03_Provisiones'!L11)+N('03_Provisiones'!N11)+N('03_Provisiones'!P11))) | G11: =IF(E11=0,"",IF(AND(N('03_Provisiones'!L11)>=N('03_Provisiones'!N11),N('03_Provisiones'!L11)>=N('03_Provisiones'!P11)),'03_Provisiones'!K11,IF(N('03_Provisiones'!N11)>=N('03_Provisiones'!P11),'03_Provisiones'!M11,'03_Provisiones'!O11))) | H11: =IF(AND('03_Provisiones'!I11<>"",'03_Provisiones'!J11<>""),('03_Provisiones'!I11+'03_Provisiones'!J11)/2,"") | I11: =IF('03_Provisiones'!G11="","",'03_Provisiones'!G11) | J11: =IF('03_Provisiones'!H11="","",'03_Provisiones'!H11) | K11: =IF(B11<>"","Hecho posterior (NIC 10.9 a)",IF(C11<>"","Oneroso: menor costo (37.68)",IF(D11<>"","Garantías: valor esperado (37.39)",IF(E11>0,IF('03_Provisiones'!Q11="Más probable","Desenlace más probable (37.40)","Valor esperado (37.39)"),IF(H11<>"","Punto medio del rango (37.39)",IF(I11<>"","Carta del abogado",IF(J11<>"","Estimación de la gerencia","Sin estimación"))))))) | L11: =IF(B11<>"",B11,IF(C11<>"",C11,IF(D11<>"",D11,IF(E11>0,IF('03_Provisiones'!Q11="Más probable",G11,F11),IF(H11<>"",H11,IF(I11<>"",I11,IF(J11<>"",J11,"")))))))
A12: REE-01 | B12: =IF('03_Provisiones'!U12="","",'03_Provisiones'!U12) | C12: =IF('03_Provisiones'!C12<>"Oneroso","",IF(AND('03_Provisiones'!R12="",'03_Provisiones'!S12=""),"",IF('03_Provisiones'!R12="",'03_Provisiones'!S12,IF('03_Provisiones'!S12="",MAX('03_Provisiones'!R12-N('03_Provisiones'!T12),0),MIN(MAX('03_Provisiones'!R12-N('03_Provisiones'!T12),0),'03_Provisiones'!S12))))) | D12: =IF('03_Provisiones'!C12="Garantía",IF(COUNTIF('04_Garantias'!$B$5:$B$7,A12)=0,"",SUMIF('04_Garantias'!$B$5:$B$7,A12,'10_Garantias_calculo'!$F$5:$F$7)),"") | E12: =N('03_Provisiones'!L12)+N('03_Provisiones'!N12)+N('03_Provisiones'!P12) | F12: =IF(E12=0,"",(N('03_Provisiones'!K12)*N('03_Provisiones'!L12)+N('03_Provisiones'!M12)*N('03_Provisiones'!N12)+N('03_Provisiones'!O12)*N('03_Provisiones'!P12))/(N('03_Provisiones'!L12)+N('03_Provisiones'!N12)+N('03_Provisiones'!P12))) | G12: =IF(E12=0,"",IF(AND(N('03_Provisiones'!L12)>=N('03_Provisiones'!N12),N('03_Provisiones'!L12)>=N('03_Provisiones'!P12)),'03_Provisiones'!K12,IF(N('03_Provisiones'!N12)>=N('03_Provisiones'!P12),'03_Provisiones'!M12,'03_Provisiones'!O12))) | H12: =IF(AND('03_Provisiones'!I12<>"",'03_Provisiones'!J12<>""),('03_Provisiones'!I12+'03_Provisiones'!J12)/2,"") | I12: =IF('03_Provisiones'!G12="","",'03_Provisiones'!G12) | J12: =IF('03_Provisiones'!H12="","",'03_Provisiones'!H12) | K12: =IF(B12<>"","Hecho posterior (NIC 10.9 a)",IF(C12<>"","Oneroso: menor costo (37.68)",IF(D12<>"","Garantías: valor esperado (37.39)",IF(E12>0,IF('03_Provisiones'!Q12="Más probable","Desenlace más probable (37.40)","Valor esperado (37.39)"),IF(H12<>"","Punto medio del rango (37.39)",IF(I12<>"","Carta del abogado",IF(J12<>"","Estimación de la gerencia","Sin estimación"))))))) | L12: =IF(B12<>"",B12,IF(C12<>"",C12,IF(D12<>"",D12,IF(E12>0,IF('03_Provisiones'!Q12="Más probable",G12,F12),IF(H12<>"",H12,IF(I12<>"",I12,IF(J12<>"",J12,"")))))))
A13: AMB-01 | B13: =IF('03_Provisiones'!U13="","",'03_Provisiones'!U13) | C13: =IF('03_Provisiones'!C13<>"Oneroso","",IF(AND('03_Provisiones'!R13="",'03_Provisiones'!S13=""),"",IF('03_Provisiones'!R13="",'03_Provisiones'!S13,IF('03_Provisiones'!S13="",MAX('03_Provisiones'!R13-N('03_Provisiones'!T13),0),MIN(MAX('03_Provisiones'!R13-N('03_Provisiones'!T13),0),'03_Provisiones'!S13))))) | D13: =IF('03_Provisiones'!C13="Garantía",IF(COUNTIF('04_Garantias'!$B$5:$B$7,A13)=0,"",SUMIF('04_Garantias'!$B$5:$B$7,A13,'10_Garantias_calculo'!$F$5:$F$7)),"") | E13: =N('03_Provisiones'!L13)+N('03_Provisiones'!N13)+N('03_Provisiones'!P13) | F13: =IF(E13=0,"",(N('03_Provisiones'!K13)*N('03_Provisiones'!L13)+N('03_Provisiones'!M13)*N('03_Provisiones'!N13)+N('03_Provisiones'!O13)*N('03_Provisiones'!P13))/(N('03_Provisiones'!L13)+N('03_Provisiones'!N13)+N('03_Provisiones'!P13))) | G13: =IF(E13=0,"",IF(AND(N('03_Provisiones'!L13)>=N('03_Provisiones'!N13),N('03_Provisiones'!L13)>=N('03_Provisiones'!P13)),'03_Provisiones'!K13,IF(N('03_Provisiones'!N13)>=N('03_Provisiones'!P13),'03_Provisiones'!M13,'03_Provisiones'!O13))) | H13: =IF(AND('03_Provisiones'!I13<>"",'03_Provisiones'!J13<>""),('03_Provisiones'!I13+'03_Provisiones'!J13)/2,"") | I13: =IF('03_Provisiones'!G13="","",'03_Provisiones'!G13) | J13: =IF('03_Provisiones'!H13="","",'03_Provisiones'!H13) | K13: =IF(B13<>"","Hecho posterior (NIC 10.9 a)",IF(C13<>"","Oneroso: menor costo (37.68)",IF(D13<>"","Garantías: valor esperado (37.39)",IF(E13>0,IF('03_Provisiones'!Q13="Más probable","Desenlace más probable (37.40)","Valor esperado (37.39)"),IF(H13<>"","Punto medio del rango (37.39)",IF(I13<>"","Carta del abogado",IF(J13<>"","Estimación de la gerencia","Sin estimación"))))))) | L13: =IF(B13<>"",B13,IF(C13<>"",C13,IF(D13<>"",D13,IF(E13>0,IF('03_Provisiones'!Q13="Más probable",G13,F13),IF(H13<>"",H13,IF(I13<>"",I13,IF(J13<>"",J13,"")))))))
A14: LIT-05 | B14: =IF('03_Provisiones'!U14="","",'03_Provisiones'!U14) | C14: =IF('03_Provisiones'!C14<>"Oneroso","",IF(AND('03_Provisiones'!R14="",'03_Provisiones'!S14=""),"",IF('03_Provisiones'!R14="",'03_Provisiones'!S14,IF('03_Provisiones'!S14="",MAX('03_Provisiones'!R14-N('03_Provisiones'!T14),0),MIN(MAX('03_Provisiones'!R14-N('03_Provisiones'!T14),0),'03_Provisiones'!S14))))) | D14: =IF('03_Provisiones'!C14="Garantía",IF(COUNTIF('04_Garantias'!$B$5:$B$7,A14)=0,"",SUMIF('04_Garantias'!$B$5:$B$7,A14,'10_Garantias_calculo'!$F$5:$F$7)),"") | E14: =N('03_Provisiones'!L14)+N('03_Provisiones'!N14)+N('03_Provisiones'!P14) | F14: =IF(E14=0,"",(N('03_Provisiones'!K14)*N('03_Provisiones'!L14)+N('03_Provisiones'!M14)*N('03_Provisiones'!N14)+N('03_Provisiones'!O14)*N('03_Provisiones'!P14))/(N('03_Provisiones'!L14)+N('03_Provisiones'!N14)+N('03_Provisiones'!P14))) | G14: =IF(E14=0,"",IF(AND(N('03_Provisiones'!L14)>=N('03_Provisiones'!N14),N('03_Provisiones'!L14)>=N('03_Provisiones'!P14)),'03_Provisiones'!K14,IF(N('03_Provisiones'!N14)>=N('03_Provisiones'!P14),'03_Provisiones'!M14,'03_Provisiones'!O14))) | H14: =IF(AND('03_Provisiones'!I14<>"",'03_Provisiones'!J14<>""),('03_Provisiones'!I14+'03_Provisiones'!J14)/2,"") | I14: =IF('03_Provisiones'!G14="","",'03_Provisiones'!G14) | J14: =IF('03_Provisiones'!H14="","",'03_Provisiones'!H14) | K14: =IF(B14<>"","Hecho posterior (NIC 10.9 a)",IF(C14<>"","Oneroso: menor costo (37.68)",IF(D14<>"","Garantías: valor esperado (37.39)",IF(E14>0,IF('03_Provisiones'!Q14="Más probable","Desenlace más probable (37.40)","Valor esperado (37.39)"),IF(H14<>"","Punto medio del rango (37.39)",IF(I14<>"","Carta del abogado",IF(J14<>"","Estimación de la gerencia","Sin estimación"))))))) | L14: =IF(B14<>"",B14,IF(C14<>"",C14,IF(D14<>"",D14,IF(E14>0,IF('03_Provisiones'!Q14="Más probable",G14,F14),IF(H14<>"",H14,IF(I14<>"",I14,IF(J14<>"",J14,"")))))))
A15: LIT-06 | B15: =IF('03_Provisiones'!U15="","",'03_Provisiones'!U15) | C15: =IF('03_Provisiones'!C15<>"Oneroso","",IF(AND('03_Provisiones'!R15="",'03_Provisiones'!S15=""),"",IF('03_Provisiones'!R15="",'03_Provisiones'!S15,IF('03_Provisiones'!S15="",MAX('03_Provisiones'!R15-N('03_Provisiones'!T15),0),MIN(MAX('03_Provisiones'!R15-N('03_Provisiones'!T15),0),'03_Provisiones'!S15))))) | D15: =IF('03_Provisiones'!C15="Garantía",IF(COUNTIF('04_Garantias'!$B$5:$B$7,A15)=0,"",SUMIF('04_Garantias'!$B$5:$B$7,A15,'10_Garantias_calculo'!$F$5:$F$7)),"") | E15: =N('03_Provisiones'!L15)+N('03_Provisiones'!N15)+N('03_Provisiones'!P15) | F15: =IF(E15=0,"",(N('03_Provisiones'!K15)*N('03_Provisiones'!L15)+N('03_Provisiones'!M15)*N('03_Provisiones'!N15)+N('03_Provisiones'!O15)*N('03_Provisiones'!P15))/(N('03_Provisiones'!L15)+N('03_Provisiones'!N15)+N('03_Provisiones'!P15))) | G15: =IF(E15=0,"",IF(AND(N('03_Provisiones'!L15)>=N('03_Provisiones'!N15),N('03_Provisiones'!L15)>=N('03_Provisiones'!P15)),'03_Provisiones'!K15,IF(N('03_Provisiones'!N15)>=N('03_Provisiones'!P15),'03_Provisiones'!M15,'03_Provisiones'!O15))) | H15: =IF(AND('03_Provisiones'!I15<>"",'03_Provisiones'!J15<>""),('03_Provisiones'!I15+'03_Provisiones'!J15)/2,"") | I15: =IF('03_Provisiones'!G15="","",'03_Provisiones'!G15) | J15: =IF('03_Provisiones'!H15="","",'03_Provisiones'!H15) | K15: =IF(B15<>"","Hecho posterior (NIC 10.9 a)",IF(C15<>"","Oneroso: menor costo (37.68)",IF(D15<>"","Garantías: valor esperado (37.39)",IF(E15>0,IF('03_Provisiones'!Q15="Más probable","Desenlace más probable (37.40)","Valor esperado (37.39)"),IF(H15<>"","Punto medio del rango (37.39)",IF(I15<>"","Carta del abogado",IF(J15<>"","Estimación de la gerencia","Sin estimación"))))))) | L15: =IF(B15<>"",B15,IF(C15<>"",C15,IF(D15<>"",D15,IF(E15>0,IF('03_Provisiones'!Q15="Más probable",G15,F15),IF(H15<>"",H15,IF(I15<>"",I15,IF(J15<>"",J15,"")))))))
A16: OTR-01 | B16: =IF('03_Provisiones'!U16="","",'03_Provisiones'!U16) | C16: =IF('03_Provisiones'!C16<>"Oneroso","",IF(AND('03_Provisiones'!R16="",'03_Provisiones'!S16=""),"",IF('03_Provisiones'!R16="",'03_Provisiones'!S16,IF('03_Provisiones'!S16="",MAX('03_Provisiones'!R16-N('03_Provisiones'!T16),0),MIN(MAX('03_Provisiones'!R16-N('03_Provisiones'!T16),0),'03_Provisiones'!S16))))) | D16: =IF('03_Provisiones'!C16="Garantía",IF(COUNTIF('04_Garantias'!$B$5:$B$7,A16)=0,"",SUMIF('04_Garantias'!$B$5:$B$7,A16,'10_Garantias_calculo'!$F$5:$F$7)),"") | E16: =N('03_Provisiones'!L16)+N('03_Provisiones'!N16)+N('03_Provisiones'!P16) | F16: =IF(E16=0,"",(N('03_Provisiones'!K16)*N('03_Provisiones'!L16)+N('03_Provisiones'!M16)*N('03_Provisiones'!N16)+N('03_Provisiones'!O16)*N('03_Provisiones'!P16))/(N('03_Provisiones'!L16)+N('03_Provisiones'!N16)+N('03_Provisiones'!P16))) | G16: =IF(E16=0,"",IF(AND(N('03_Provisiones'!L16)>=N('03_Provisiones'!N16),N('03_Provisiones'!L16)>=N('03_Provisiones'!P16)),'03_Provisiones'!K16,IF(N('03_Provisiones'!N16)>=N('03_Provisiones'!P16),'03_Provisiones'!M16,'03_Provisiones'!O16))) | H16: =IF(AND('03_Provisiones'!I16<>"",'03_Provisiones'!J16<>""),('03_Provisiones'!I16+'03_Provisiones'!J16)/2,"") | I16: =IF('03_Provisiones'!G16="","",'03_Provisiones'!G16) | J16: =IF('03_Provisiones'!H16="","",'03_Provisiones'!H16) | K16: =IF(B16<>"","Hecho posterior (NIC 10.9 a)",IF(C16<>"","Oneroso: menor costo (37.68)",IF(D16<>"","Garantías: valor esperado (37.39)",IF(E16>0,IF('03_Provisiones'!Q16="Más probable","Desenlace más probable (37.40)","Valor esperado (37.39)"),IF(H16<>"","Punto medio del rango (37.39)",IF(I16<>"","Carta del abogado",IF(J16<>"","Estimación de la gerencia","Sin estimación"))))))) | L16: =IF(B16<>"",B16,IF(C16<>"",C16,IF(D16<>"",D16,IF(E16>0,IF('03_Provisiones'!Q16="Más probable",G16,F16),IF(H16<>"",H16,IF(I16<>"",I16,IF(J16<>"",J16,"")))))))
A17: ACT-01 | B17: =IF('03_Provisiones'!U17="","",'03_Provisiones'!U17) | C17: =IF('03_Provisiones'!C17<>"Oneroso","",IF(AND('03_Provisiones'!R17="",'03_Provisiones'!S17=""),"",IF('03_Provisiones'!R17="",'03_Provisiones'!S17,IF('03_Provisiones'!S17="",MAX('03_Provisiones'!R17-N('03_Provisiones'!T17),0),MIN(MAX('03_Provisiones'!R17-N('03_Provisiones'!T17),0),'03_Provisiones'!S17))))) | D17: =IF('03_Provisiones'!C17="Garantía",IF(COUNTIF('04_Garantias'!$B$5:$B$7,A17)=0,"",SUMIF('04_Garantias'!$B$5:$B$7,A17,'10_Garantias_calculo'!$F$5:$F$7)),"") | E17: =N('03_Provisiones'!L17)+N('03_Provisiones'!N17)+N('03_Provisiones'!P17) | F17: =IF(E17=0,"",(N('03_Provisiones'!K17)*N('03_Provisiones'!L17)+N('03_Provisiones'!M17)*N('03_Provisiones'!N17)+N('03_Provisiones'!O17)*N('03_Provisiones'!P17))/(N('03_Provisiones'!L17)+N('03_Provisiones'!N17)+N('03_Provisiones'!P17))) | G17: =IF(E17=0,"",IF(AND(N('03_Provisiones'!L17)>=N('03_Provisiones'!N17),N('03_Provisiones'!L17)>=N('03_Provisiones'!P17)),'03_Provisiones'!K17,IF(N('03_Provisiones'!N17)>=N('03_Provisiones'!P17),'03_Provisiones'!M17,'03_Provisiones'!O17))) | H17: =IF(AND('03_Provisiones'!I17<>"",'03_Provisiones'!J17<>""),('03_Provisiones'!I17+'03_Provisiones'!J17)/2,"") | I17: =IF('03_Provisiones'!G17="","",'03_Provisiones'!G17) | J17: =IF('03_Provisiones'!H17="","",'03_Provisiones'!H17) | K17: =IF(B17<>"","Hecho posterior (NIC 10.9 a)",IF(C17<>"","Oneroso: menor costo (37.68)",IF(D17<>"","Garantías: valor esperado (37.39)",IF(E17>0,IF('03_Provisiones'!Q17="Más probable","Desenlace más probable (37.40)","Valor esperado (37.39)"),IF(H17<>"","Punto medio del rango (37.39)",IF(I17<>"","Carta del abogado",IF(J17<>"","Estimación de la gerencia","Sin estimación"))))))) | L17: =IF(B17<>"",B17,IF(C17<>"",C17,IF(D17<>"",D17,IF(E17>0,IF('03_Provisiones'!Q17="Más probable",G17,F17),IF(H17<>"",H17,IF(I17<>"",I17,IF(J17<>"",J17,"")))))))
A19: ⓘ Cómo se calcula esta hoja
A20: Columna | B20: Fórmula (Excel) | C20: Cómo se calcula (sencillo) | D20: Ejemplo con números reales | E20: De dónde viene | F20: Norma
A21: Hecho posterior | B21: '=IF('03_Provisiones'!U5="","",'03_Provisiones'!U5) | C21: Copia de la hoja 03 (datos del cliente) el importe fijado después del corte por sentencia o acuerdo; vacío si no lo hay. | D21: Fila 1: IF((vacío)=""; ""; (vacío)) → (en blanco) | E21: hoja «Provisiones y contingencias (datos del cliente)» | F21: —
A22: Oneroso: mín(costo neto, penalización) | B22: '=IF('03_Provisiones'!C5<>"Oneroso","",IF(AND('03_Provisiones'!R5="",'03_Provisiones'!S5=""),"",IF('03_Provisiones'!R5="",'03_Provisiones'!S5,IF('03_Provisiones'!S5="",MAX('03_Provisiones'!R5-N('03_Provisiones'!T5),0),MIN(MAX('03_Provisiones'!R5-N('03_Provisiones'!T5),0),'03_Provisiones'!S5))))) | C22: Solo en contratos onerosos, con datos de la hoja 03 (datos del cliente): costo de cumplir menos beneficios esperados (nunca negativo) y, si hay penalización, el menor entre ese costo neto y la penalización; si falta uno, usa el otro. | D22: Fila 1: IF(«Litigio»<>"Oneroso"; ""; IF(AND((vacío)=""; (vacío)=""); ""; IF((vacío)=""; (vacío); IF((vacío)=""; MAX((vacío)-N((vacío)); 0); MIN(MAX((vacío)-N((vacío)); 0); (vacío)))))) → (en blanco) | E22: hoja «Provisiones y contingencias (datos del cliente)» | F22: —
A23: Garantías | B23: '=IF('03_Provisiones'!C5="Garantía",IF(COUNTIF('04_Garantias'!$B$5:$B$7,A5)=0,"",SUMIF('04_Garantias'!$B$5:$B$7,A5,'10_Garantias_calculo'!$F$5:$F$7)),"") | C23: Solo en provisiones de tipo garantía: suma la provisión calculada en la hoja 10 (Garantías: cálculo) de las líneas de la hoja 04 vinculadas a este código; vacío si no tiene líneas. | D23: Fila 1: IF(«Litigio»="Garantía"; IF(COUNTIF([«Provisión» de «Garantías (datos del cliente)», 3 filas]; «LIT-01»)=0; ""; SUMIF([«Provisión» de «Garantías (datos del cliente)», 3 filas]; «LIT-01»; [«Provisión calculada» de «Garantías: cálculo», 3 filas])); "") → (en blanco) | E23: «Código» (esta hoja), hoja «Provisiones y contingencias (datos del cliente)», hoja «Garantías (datos del cliente)», hoja «Garantías: cálculo» | F23: —
A24: Σ probabilidades % | B24: '=N('03_Provisiones'!L5)+N('03_Provisiones'!N5)+N('03_Provisiones'!P5) | C24: Suma las probabilidades (%) de los tres escenarios informados en la hoja 03 (datos del cliente); las vacías cuentan como cero. | D24: Fila 1: N(60,00)+N(30,00)+N(10,00) → 100,00 | E24: hoja «Provisiones y contingencias (datos del cliente)» | F24: —
A25: Valor esperado | B25: '=IF(E5=0,"",(N('03_Provisiones'!K5)*N('03_Provisiones'!L5)+N('03_Provisiones'!M5)*N('03_Provisiones'!N5)+N('03_Provisiones'!O5)*N('03_Provisiones'!P5))/(N('03_Provisiones'!L5)+N('03_Provisiones'!N5)+N('03_Provisiones'!P5))) | C25: Pondera el importe de cada escenario de la hoja 03 por su probabilidad y divide para la suma de probabilidades; en blanco si ningún escenario tiene probabilidad. | D25: Fila 1: IF(100,00=0; ""; (N(150.000,00)*N(60,00)+N(80.000,00)*N(30,00)+N(0,00)*N(10,00))/(N(60,00)+N(30,00)+N(10,00))) → 114.000,00 | E25: «Σ probabilidades %» (esta hoja), hoja «Provisiones y contingencias (datos del cliente)» | F25: —
A26: Más probable | B26: '=IF(E5=0,"",IF(AND(N('03_Provisiones'!L5)>=N('03_Provisiones'!N5),N('03_Provisiones'!L5)>=N('03_Provisiones'!P5)),'03_Provisiones'!K5,IF(N('03_Provisiones'!N5)>=N('03_Provisiones'!P5),'03_Provisiones'!M5,'03_Provisiones'!O5))) | C26: Toma el importe del escenario con mayor probabilidad (en empate gana el de menor número); en blanco si ningún escenario tiene probabilidad. | D26: Fila 1: IF(100,00=0; ""; IF(AND(N(60,00)>=N(30,00); N(60,00)>=N(10,00)); 150.000,00; IF(N(30,00)>=N(10,00); 80.000,00; 0,00))) → 150.000,00 | E26: «Σ probabilidades %» (esta hoja), hoja «Provisiones y contingencias (datos del cliente)» | F26: —
A27: Punto medio del rango | B27: '=IF(AND('03_Provisiones'!I5<>"",'03_Provisiones'!J5<>""),('03_Provisiones'!I5+'03_Provisiones'!J5)/2,"") | C27: Promedia el importe mínimo y el máximo del rango informado en la hoja 03; en blanco si falta alguno de los dos. | D27: Fila 1: IF(AND((vacío)<>""; (vacío)<>""); ((vacío)+(vacío))/2; "") → (en blanco) | E27: hoja «Provisiones y contingencias (datos del cliente)» | F27: —
A28: Carta del abogado | B28: '=IF('03_Provisiones'!G5="","",'03_Provisiones'!G5) | C28: Copia el importe que indica la carta del abogado en la hoja 03 (datos del cliente); vacío si no lo informó. | D28: Fila 1: IF(120.000,00=""; ""; 120.000,00) → 120.000,00 | E28: hoja «Provisiones y contingencias (datos del cliente)» | F28: —
A29: Estimación gerencia | B29: '=IF('03_Provisiones'!H5="","",'03_Provisiones'!H5) | C29: Copia la estimación de la gerencia (sin descontar) de la hoja 03 (datos del cliente); vacío si no la informó. | D29: Fila 1: IF((vacío)=""; ""; (vacío)) → (en blanco) | E29: hoja «Provisiones y contingencias (datos del cliente)» | F29: —
