Workbook

Sheet 00_Inicio
B2: AuditConsulting Auditores Cía. Ltda. · AUDIT-IA
B4: Proveedores y cuentas por pagar
B6: Cliente | C6: Cliente de muestra S.A. | D6: RUC | E6: 1790000000001
B7: Marco contable | C7: NIIF completas | D7: Fecha de corte | E7: 2025-12-31
B8: Preparó | C8: Ejercicio modelo | D8: Revisó | E8: Pendiente
B10: INDICADORES CLAVE
B11: Ajuste neto propuesto a proveedores | C11: Problemas encontrados
B12: 578.92 | C12: 11
B15: IR A LA CÉDULA
B16: Carátula | C16: Programa | D16: Base técnica | E16: Resumen
B17: Parámetros | C17: Detalle por documento | D17: Antigüedad de proveedores | E17: Pagos posteriores al cierre
B18: Búsqueda de pasivos no registrados | C18: Confirmación de proveedores | D18: Corte de compras | E18: Costo amortizado e intereses implícitos
B19: Clasificación corriente / no corriente | C19: Saldo auditado y ajustes | D19: Asientos propuestos | E19: Problemas encontrados
B20: Conclusión | C20: Control de revisión
B22: PANORAMA | N22: Datos de los gráficos (fórmulas a las cédulas)
N23: Cifras del resumen | O23: Importe (USD)
N24: ='01_Resumen'!A5 | O24: ='01_Resumen'!B5
N25: ='01_Resumen'!A6 | O25: ='01_Resumen'!B6
N26: ='01_Resumen'!A7 | O26: ='01_Resumen'!B7
N27: ='01_Resumen'!A8 | O27: ='01_Resumen'!B8
N28: ='01_Resumen'!A9 | O28: ='01_Resumen'!B9
N29: ='01_Resumen'!A10 | O29: ='01_Resumen'!B10
N30: ='01_Resumen'!A11 | O30: ='01_Resumen'!B11
N31: ='01_Resumen'!A12 | O31: ='01_Resumen'!B12
N32: ='01_Resumen'!A13 | O32: ='01_Resumen'!B13
N33: ='01_Resumen'!A14 | O33: ='01_Resumen'!B14
N34: ='01_Resumen'!A15 | O34: ='01_Resumen'!B15
N35: ='01_Resumen'!A16 | O35: ='01_Resumen'!B16
... N40: ='01_Resumen'!A21 | O40: ='01_Resumen'!B21
N42: Hallazgos de mayor impacto | O42: Importe (USD)
N43: No corriente como corriente | O43: =SUMIFS('13_Problemas'!$C$5:$C$15,'13_Problemas'!$A$5:$A$15,"NO_CORRIENTE_COMO_CORRIENTE",'13_Problemas'!$C$5:$C$15,">0")-SUMIFS('13_Problemas'!$C$5:$C$15,'13_Problemas'!$A$5:$A$15,"NO_CORRIENTE_COMO_CORRIENTE",'13_Problemas'!$C$5:$C$15,"<0")
N44: Pasivo no registrado | O44: =SUMIFS('13_Problemas'!$C$5:$C$15,'13_Problemas'!$A$5:$A$15,"PASIVO_NO_REGISTRADO",'13_Problemas'!$C$5:$C$15,">0")-SUMIFS('13_Problemas'!$C$5:$C$15,'13_Problemas'!$A$5:$A$15,"PASIVO_NO_REGISTRADO",'13_Problemas'!$C$5:$C$15,"<0")
N45: Pago no posterior | O45: =SUMIFS('13_Problemas'!$C$5:$C$15,'13_Problemas'!$A$5:$A$15,"PAGO_NO_POSTERIOR",'13_Problemas'!$C$5:$C$15,">0")-SUMIFS('13_Problemas'!$C$5:$C$15,'13_Problemas'!$A$5:$A$15,"PAGO_NO_POSTERIOR",'13_Problemas'!$C$5:$C$15,"<0")
N46: Moneda extranjera | O46: =SUMIFS('13_Problemas'!$C$5:$C$15,'13_Problemas'!$A$5:$A$15,"MONEDA_EXTRANJERA",'13_Problemas'!$C$5:$C$15,">0")-SUMIFS('13_Problemas'!$C$5:$C$15,'13_Problemas'!$A$5:$A$15,"MONEDA_EXTRANJERA",'13_Problemas'!$C$5:$C$15,"<0")
N47: Error corte compras | O47: =SUMIFS('13_Problemas'!$C$5:$C$15,'13_Problemas'!$A$5:$A$15,"ERROR_CORTE_COMPRAS",'13_Problemas'!$C$5:$C$15,">0")-SUMIFS('13_Problemas'!$C$5:$C$15,'13_Problemas'!$A$5:$A$15,"ERROR_CORTE_COMPRAS",'13_Problemas'!$C$5:$C$15,"<0")
N48: Financiacion no reconocida | O48: =SUMIFS('13_Problemas'!$C$5:$C$15,'13_Problemas'!$A$5:$A$15,"FINANCIACION_NO_RECONOCIDA",'13_Problemas'!$C$5:$C$15,">0")-SUMIFS('13_Problemas'!$C$5:$C$15,'13_Problemas'!$A$5:$A$15,"FINANCIACION_NO_RECONOCIDA",'13_Problemas'!$C$5:$C$15,"<0")
N49: Saldos deudores | O49: =SUMIFS('13_Problemas'!$C$5:$C$15,'13_Problemas'!$A$5:$A$15,"SALDOS_DEUDORES",'13_Problemas'!$C$5:$C$15,">0")-SUMIFS('13_Problemas'!$C$5:$C$15,'13_Problemas'!$A$5:$A$15,"SALDOS_DEUDORES",'13_Problemas'!$C$5:$C$15,"<0")
N50: Otros (4 tipos) | O50: =SUMIF('13_Problemas'!$C$5:$C$15,">0")-SUMIF('13_Problemas'!$C$5:$C$15,"<0")-((SUMIFS('13_Problemas'!$C$5:$C$15,'13_Problemas'!$A$5:$A$15,"NO_CORRIENTE_COMO_CORRIENTE",'13_Problemas'!$C$5:$C$15,">0")-SUMIFS('13_Problemas'!$C$5:$C$15,'13_Problemas'!$A$5:$A$15,"NO_CORRIENTE_COMO_CORRIENTE",'13_Problemas'!$C$5:$C$15,"<0"))+(SUMIFS('13_Problemas'!$C$5:$C$15,'13_Problemas'!$A$5:$A$15,"PASIVO_NO_REGISTRADO",'13_Problemas'!$C$5:$C$15,">0")-SUMIFS('13_Problemas'!$C$5:$C$15,'13_Problemas'!$A$5:$A$15,"PASIVO_NO_REGISTRADO",'13_Problemas'!$C$5:$C$15,"<0"))+(SUMIFS('13_Problemas'!$C$5:$C$15,'13_Problemas'!$A$5:$A$15,"PAGO_NO_POSTERIOR",'13_Problemas'!$C$5:$C$15,">0")-SUMIFS('13_Problemas'!$C$5:$C$15,'13_Problemas'!$A$5:$A$15,"PAGO_NO_POSTERIOR",'13_Problemas'!$C$5:$C$15,"<0"))+(SUMIFS('13_Problemas'!$C$5:$C$15,'13_Problemas'!$A$5:$A$15,"MONEDA_EXTRANJERA",'13_Problemas'!$C$5:$C$15,">0")-SUMIFS('13_Problemas'!$C$5:$C$15,'13_Problemas'!$A$5:$A$15,"MONEDA_EXTRANJERA",'13_Problemas'!$C$5:$C$15,"<0"))+(SUMIFS('13_Problemas'!$C$5:$C$15,'13_Problemas'!$A$5:$A$15,"ERROR_CORTE_COMPRAS",'13_Problemas'!$C$5:$C$15,">0")-SUMIFS('13_Problemas'!$C$5:$C$15,'13_Problemas'!$A$5:$A$15,"ERROR_CORTE_COMPRAS",'13_Problemas'!$C$5:$C$15,"<0"))+(SUMIFS('13_Problemas'!$C$5:$C$15,'13_Problemas'!$A$5:$A$15,"FINANCIACION_NO_RECONOCIDA",'13_Problemas'!$C$5:$C$15,">0")-SUMIFS('13_Problemas'!$C$5:$C$15,'13_Problemas'!$A$5:$A$15,"FINANCIACION_NO_RECONOCIDA",'13_Problemas'!$C$5:$C$15,"<0"))+(SUMIFS('13_Problemas'!$C$5:$C$15,'13_Problemas'!$A$5:$A$15,"SALDOS_DEUDORES",'13_Problemas'!$C$5:$C$15,">0")-SUMIFS('13_Problemas'!$C$5:$C$15,'13_Problemas'!$A$5:$A$15,"SALDOS_DEUDORES",'13_Problemas'!$C$5:$C$15,"<0")))

Sheet 00_Caratula
A1: Carátula | H1: ⟵ Inicio | J1: Siguiente ▶
A2: Proveedores y cuentas por pagar · Cliente de muestra S.A. · corte 2025-12-31
A4: Concepto | B4: Detalle
A5: Firma | B5: AuditConsulting Auditores Cía. Ltda.
A6: Cliente | B6: Cliente de muestra S.A.
A7: RUC | B7: 1790000000001
A8: Ejercicio | B8: 2025
A9: Fecha de corte | B9: 2025-12-31
A10: Marco contable | B10: NIIF completas
A11: Herramienta | B11: Proveedores y cuentas por pagar
A12: Rubro | B12: Proveedores y cuentas por pagar
A13: Motor | B13: proveedores_cxp 1.0
A14: Versión del papel | B14: v1
A15: Estado | B15: MUESTRA
... A17: Revisó | B17: Pendiente
A18: Aprobó
A19: Fecha de aprobación
A20: Huella de la ejecución (SHA-256)

Sheet 00_Programa
A1: Programa | H1: ⟵ Inicio | I1: ◀ Anterior | J1: Siguiente ▶
A2: Proveedores y cuentas por pagar · Cliente de muestra S.A. · corte 2025-12-31
A4: Código | B4: Objetivo | C4: Afirmación | D4: Procedimiento | E4: Evidencia | F4: Criterio | G4: Referencia
A5: CXP-01 | B5: Integridad y antigüedad del auxiliar | C5: Integridad | D5: Conciliar el auxiliar por documento con el mayor y recalcular la antigüedad | E5: Auxiliar y mayor | F5: Diferencia cero o explicada | G5: NIA 500 párr. 9
A6: CXP-02 | B6: Búsqueda de pasivos no registrados | C6: Integridad | D6: Revisar pagos y facturas posteriores al corte y comparar la fecha de recepción con el corte | E6: Egresos y facturas posteriores, actas de recepción | F6: Pasivos con causa hasta el corte registrados | G6: NIA 330 · NIIF 9 3.1.1 y B3.1.2 b) · PYMES 11.12
A7: CXP-03 | B7: Pagos posteriores | C7: Existencia / Exactitud | D7: Cotejar los pagos posteriores con el saldo de cada documento | E7: Estados de cuenta bancarios y comprobantes de egreso | F7: Pago igual al saldo o diferencia explicada | G7: NIA 500
A8: CXP-04 | B8: Confirmación de proveedores | C8: Existencia / Integridad | D8: Enviar confirmaciones y conciliar las diferencias | E8: Respuestas de proveedores | F8: Diferencias conciliadas o ajustadas | G8: NIA 505
A9: CXP-05 | B9: Corte de compras | C9: Corte | D9: Comparar la fecha de recepción del bien o servicio con el corte | E9: Ingresos a bodega, actas de servicio | F9: Pasivo reconocido desde la recepción | G9: NIA 330
A10: CXP-06 | B10: Costo amortizado e intereses implícitos | C10: Valoración | D10: Identificar documentos con plazo mayor al umbral y medir su valor presente, TIE e interés devengado | E10: Contratos, términos de pago, tasa de mercado | F10: Financiación implícita reconocida | G10: NIIF 9 5.1.1, B5.1.1, 4.2.1 · PYMES 11.13
A11: CXP-07 | B11: Clasificación y presentación | C11: Presentación | D11: Clasificar por vencimiento: ciclo de operación solo en las partidas de explotación, 12 meses en las demás; reclasificar los saldos deudores al activo | E11: Auxiliar con la marca de partida de explotación, estado de situación financiera | F11: NIC 1.70 (el plazo del ciclo solo alcanza a las partidas de explotación) y NIC 1.32 / PYMES 2.52 (no compensación de anticipos) | G11: NIC 1 69–70 y 32 · PYMES 4.7–4.8 y 2.52 · NIIF 7 39

Sheet 00_Fuentes
A1: Base técnica | H1: ⟵ Inicio | I1: ◀ Anterior | J1: Siguiente ▶
A2: Proveedores y cuentas por pagar · Cliente de muestra S.A. · corte 2025-12-31
A4: Categoría | B4: Documento | C4: Párrafos | D4: URL | E4: Verificada
A5: NIA · NIA 505 | B5: Confirmaciones externas a proveedores; investigar las diferencias. | C5: párr. 7 y 14
A6: NIA · NIA 500 | B6: Exactitud e integridad del auxiliar contra el mayor. | C6: párr. 9
A7: NIA · NIA 330 | B7: Procedimientos sustantivos de corte y conciliación de registros con los estados. | C7: párr. 18 y 20
A8: NIA · NIA 540 (Revisada) | B8: La tasa de mercado del valor presente es un supuesto de una estimación. | C8: párr. 13 y 24 a) (supuestos significativos)
A9: NIA · NIA 550 | B9: Identificar y revelar saldos con partes relacionadas. | C9: párr. 13 y 25 a)

Sheet 01_Resumen
A1: Resumen | H1: ⟵ Inicio | I1: ◀ Anterior | J1: Siguiente ▶
A2: Proveedores y cuentas por pagar · Cliente de muestra S.A. · corte 2025-12-31
A4: Concepto | B4: Importe
A5: Proveedores según auxiliar (nominal) | B5: ='11_Ajuste'!B5
A6: Saldo según el mayor | B6: ='11_Ajuste'!B18
A7: Diferencia auxiliar − mayor | B7: ='11_Ajuste'!B19
A8: Pasivos no registrados | B8: ='11_Ajuste'!B8
A9: Compras registradas antes de la recepción | B9: ='11_Ajuste'!B9
A10: Diferencias de confirmación (absolutas) | B10: ='11_Ajuste'!B20
A11: Pagos posteriores mayores al saldo | B11: ='11_Ajuste'!B21
A12: Intereses implícitos por devengar | B12: ='11_Ajuste'!B10
A13: Intereses por devengar registrados | B13: ='11_Ajuste'!B6
A14: Ajuste por financiación implícita | B14: ='11_Ajuste'!B11
A15: Saldos deudores a reclasificar al activo | B15: ='11_Ajuste'!B12
A16: Saldo de proveedores auditado | B16: ='11_Ajuste'!B13
A17: Ajuste neto propuesto a proveedores | B17: ='11_Ajuste'!B14
A18: Porción no corriente requerida | B18: ='11_Ajuste'!B15
A19: Porción no corriente presentada | B19: ='11_Ajuste'!B16
A20: Reclasificación a no corriente | B20: ='11_Ajuste'!B17
A21: Saldos con partes relacionadas | B21: ='11_Ajuste'!B22
A23: ⓘ Cómo se calcula esta hoja
A24: Columna | B24: Fórmula (Excel) | C24: Cómo se calcula (sencillo) | D24: Ejemplo con números reales | E24: De dónde viene | F24: Norma
A25: Importe | B25: '='11_Ajuste'!B5 | C25: Trae cada importe de la hoja 11 (Saldo auditado y ajustes), concepto por concepto: el saldo del auxiliar, los pasivos no registrados, el corte, la financiación implícita, los saldos deudores, el saldo auditado, el ajuste neto, la clasificación y los datos de control (mayor, confirmaciones, pagos posteriores y relacionadas). | D25: Fila 1: 80.300,00 → 80.300,00 | E25: hoja «Saldo auditado y ajustes» | F25: —

Sheet 02_Parametros
A1: Parámetros | H1: ⟵ Inicio | I1: ◀ Anterior | J1: Siguiente ▶
A2: Proveedores y cuentas por pagar · Cliente de muestra S.A. · corte 2025-12-31
A4: Parámetro | B4: Valor | C4: Sustento
A5: Corte del ejercicio | B5: 46022 | C5: Ficha del encargo
A6: Marco contable | B6: NIIF completas | C6: Mismo modelo en ambos marcos; cambian las citas
A7: Tasa de mercado anual para el valor presente (%) | B7: 10 | C7: NIIF 9 5.1.1, B5.1.1 — tasa de un instrumento de deuda similar
A8: Plazo que se considera financiación (meses) | B8: 12 | C8: NIIF 9 5.1.1, B5.1.1; NIC 2.18 / NIC 16.23 — juicio: plazo mayor a las condiciones normales de crédito
A9: Ciclo normal de operación (meses) | B9: 12 | C9: NIC 1 69–70 (NIIF 18 párr. 101 y B96 desde 2027) — si no es identificable, 12 meses; el ciclo solo alcanza a las partidas de explotación
A10: Intereses implícitos por devengar registrados (mayor) | C10: Mayor contable
A11: Proveedores presentados como no corrientes | B11: 0 | C11: Estado de situación financiera
A12: Saldo de proveedores según el mayor | B12: 80000 | C12: Mayor / balance de comprobación

Sheet 03_Detalle
A1: Detalle por documento | H1: ⟵ Inicio | I1: ◀ Anterior | J1: Siguiente ▶
A2: Proveedores y cuentas por pagar · Cliente de muestra S.A. · corte 2025-12-31
A4: Documento | B4: Proveedor | C4: Fecha factura | D4: Recepción | E4: Vencimiento | F4: Saldo | G4: Relacionado | H4: Moneda | I4: Días desde vencimiento | J4: Tramo | K4: Plazo de pago (días) | L4: Financiación implícita | M4: Costo amortizado | N4: Interés implícito por devengar | O4: Días por vencer | P4: No corriente | Q4: Importe no corriente | R4: Saldo deudor | S4: Partida de explotación
A5: P-001 | B5: Aceros del Pacífico S.A. | C5: 45996 | D5: 45996 | E5: 46026 | F5: 15000 | G5: No | H5: USD | I5: ='02_Parametros'!$B$5-E5 | J5: =IF(I5<=0,"Corriente / por vencer",IF(I5<=30,"1 a 30 días",IF(I5<=60,"31 a 60 días",IF(I5<=90,"61 a 90 días",IF(I5<=180,"91 a 180 días",IF(I5<=360,"181 a 360 días","Más de 360 días")))))) | K5: =E5-C5 | L5: =IF(AND(F5>0,K5>'02_Parametros'!$B$8*365/12),"Sí","No") | M5: =IF(AND(L5="Sí",'02_Parametros'!$B$7<>""),F5/(1+'02_Parametros'!$B$7/100)^(K5/365)*(1+'02_Parametros'!$B$7/100)^(MIN(MAX('02_Parametros'!$B$5-C5,0),K5)/365),F5) | N5: =IF(AND(L5="Sí",'02_Parametros'!$B$7=""),"",F5-M5) | O5: =MAX(E5-'02_Parametros'!$B$5,0) | P5: =IF(AND(F5>0,O5>IF(S5="No",12*365/12,MAX(12,'02_Parametros'!$B$9)*365/12)),"Sí","No") | Q5: =IF(P5="Sí",M5,0) | R5: =IF(F5<0,-F5,0) | S5: Sí
A6: P-002 | B6: Plásticos Andinos Cía. Ltda. | C6: 46020 | D6: 46028 | E6: 46050 | F6: 7000 | G6: No | H6: USD | I6: ='02_Parametros'!$B$5-E6 | J6: =IF(I6<=0,"Corriente / por vencer",IF(I6<=30,"1 a 30 días",IF(I6<=60,"31 a 60 días",IF(I6<=90,"61 a 90 días",IF(I6<=180,"91 a 180 días",IF(I6<=360,"181 a 360 días","Más de 360 días")))))) | K6: =E6-C6 | L6: =IF(AND(F6>0,K6>'02_Parametros'!$B$8*365/12),"Sí","No") | M6: =IF(AND(L6="Sí",'02_Parametros'!$B$7<>""),F6/(1+'02_Parametros'!$B$7/100)^(K6/365)*(1+'02_Parametros'!$B$7/100)^(MIN(MAX('02_Parametros'!$B$5-C6,0),K6)/365),F6) | N6: =IF(AND(L6="Sí",'02_Parametros'!$B$7=""),"",F6-M6) | O6: =MAX(E6-'02_Parametros'!$B$5,0) | P6: =IF(AND(F6>0,O6>IF(S6="No",12*365/12,MAX(12,'02_Parametros'!$B$9)*365/12)),"Sí","No") | Q6: =IF(P6="Sí",M6,0) | R6: =IF(F6<0,-F6,0) | S6: Sí
A7: P-003 | B7: Servicios Logísticos del Sur | C7: 45971 | D7: 45971 | E7: 46001 | F7: 4000 | G7: No | H7: USD | I7: ='02_Parametros'!$B$5-E7 | J7: =IF(I7<=0,"Corriente / por vencer",IF(I7<=30,"1 a 30 días",IF(I7<=60,"31 a 60 días",IF(I7<=90,"61 a 90 días",IF(I7<=180,"91 a 180 días",IF(I7<=360,"181 a 360 días","Más de 360 días")))))) | K7: =E7-C7 | L7: =IF(AND(F7>0,K7>'02_Parametros'!$B$8*365/12),"Sí","No") | M7: =IF(AND(L7="Sí",'02_Parametros'!$B$7<>""),F7/(1+'02_Parametros'!$B$7/100)^(K7/365)*(1+'02_Parametros'!$B$7/100)^(MIN(MAX('02_Parametros'!$B$5-C7,0),K7)/365),F7) | N7: =IF(AND(L7="Sí",'02_Parametros'!$B$7=""),"",F7-M7) | O7: =MAX(E7-'02_Parametros'!$B$5,0) | P7: =IF(AND(F7>0,O7>IF(S7="No",12*365/12,MAX(12,'02_Parametros'!$B$9)*365/12)),"Sí","No") | Q7: =IF(P7="Sí",M7,0) | R7: =IF(F7<0,-F7,0) | S7: Sí
A8: P-004 | B8: Químicos Unidos S.A. | C8: 45915 | E8: 45945 | F8: 3000 | G8: No | H8: USD | I8: ='02_Parametros'!$B$5-E8 | J8: =IF(I8<=0,"Corriente / por vencer",IF(I8<=30,"1 a 30 días",IF(I8<=60,"31 a 60 días",IF(I8<=90,"61 a 90 días",IF(I8<=180,"91 a 180 días",IF(I8<=360,"181 a 360 días","Más de 360 días")))))) | K8: =E8-C8 | L8: =IF(AND(F8>0,K8>'02_Parametros'!$B$8*365/12),"Sí","No") | M8: =IF(AND(L8="Sí",'02_Parametros'!$B$7<>""),F8/(1+'02_Parametros'!$B$7/100)^(K8/365)*(1+'02_Parametros'!$B$7/100)^(MIN(MAX('02_Parametros'!$B$5-C8,0),K8)/365),F8) | N8: =IF(AND(L8="Sí",'02_Parametros'!$B$7=""),"",F8-M8) | O8: =MAX(E8-'02_Parametros'!$B$5,0) | P8: =IF(AND(F8>0,O8>IF(S8="No",12*365/12,MAX(12,'02_Parametros'!$B$9)*365/12)),"Sí","No") | Q8: =IF(P8="Sí",M8,0) | R8: =IF(F8<0,-F8,0) | S8: Sí
A9: P-005 | B9: Maquinarias Industriales S.A. | C9: 45839 | D9: 45839 | E9: 46569 | F9: 24200 | G9: No | H9: USD | I9: ='02_Parametros'!$B$5-E9 | J9: =IF(I9<=0,"Corriente / por vencer",IF(I9<=30,"1 a 30 días",IF(I9<=60,"31 a 60 días",IF(I9<=90,"61 a 90 días",IF(I9<=180,"91 a 180 días",IF(I9<=360,"181 a 360 días","Más de 360 días")))))) | K9: =E9-C9 | L9: =IF(AND(F9>0,K9>'02_Parametros'!$B$8*365/12),"Sí","No") | M9: =IF(AND(L9="Sí",'02_Parametros'!$B$7<>""),F9/(1+'02_Parametros'!$B$7/100)^(K9/365)*(1+'02_Parametros'!$B$7/100)^(MIN(MAX('02_Parametros'!$B$5-C9,0),K9)/365),F9) | N9: =IF(AND(L9="Sí",'02_Parametros'!$B$7=""),"",F9-M9) | O9: =MAX(E9-'02_Parametros'!$B$5,0) | P9: =IF(AND(F9>0,O9>IF(S9="No",12*365/12,MAX(12,'02_Parametros'!$B$9)*365/12)),"Sí","No") | Q9: =IF(P9="Sí",M9,0) | R9: =IF(F9<0,-F9,0) | S9: No
A10: P-006 | B10: Holding Andes S.A. | C10: 45838 | E10: 46203 | F10: 10000 | G10: Sí | H10: USD | I10: ='02_Parametros'!$B$5-E10 | J10: =IF(I10<=0,"Corriente / por vencer",IF(I10<=30,"1 a 30 días",IF(I10<=60,"31 a 60 días",IF(I10<=90,"61 a 90 días",IF(I10<=180,"91 a 180 días",IF(I10<=360,"181 a 360 días","Más de 360 días")))))) | K10: =E10-C10 | L10: =IF(AND(F10>0,K10>'02_Parametros'!$B$8*365/12),"Sí","No") | M10: =IF(AND(L10="Sí",'02_Parametros'!$B$7<>""),F10/(1+'02_Parametros'!$B$7/100)^(K10/365)*(1+'02_Parametros'!$B$7/100)^(MIN(MAX('02_Parametros'!$B$5-C10,0),K10)/365),F10) | N10: =IF(AND(L10="Sí",'02_Parametros'!$B$7=""),"",F10-M10) | O10: =MAX(E10-'02_Parametros'!$B$5,0) | P10: =IF(AND(F10>0,O10>IF(S10="No",12*365/12,MAX(12,'02_Parametros'!$B$9)*365/12)),"Sí","No") | Q10: =IF(P10="Sí",M10,0) | R10: =IF(F10<0,-F10,0)
A11: P-007 | B11: Transportes Rápidos | C11: 46011 | E11: 46041 | F11: -1800 | G11: No | H11: USD | I11: ='02_Parametros'!$B$5-E11 | J11: =IF(I11<=0,"Corriente / por vencer",IF(I11<=30,"1 a 30 días",IF(I11<=60,"31 a 60 días",IF(I11<=90,"61 a 90 días",IF(I11<=180,"91 a 180 días",IF(I11<=360,"181 a 360 días","Más de 360 días")))))) | K11: =E11-C11 | L11: =IF(AND(F11>0,K11>'02_Parametros'!$B$8*365/12),"Sí","No") | M11: =IF(AND(L11="Sí",'02_Parametros'!$B$7<>""),F11/(1+'02_Parametros'!$B$7/100)^(K11/365)*(1+'02_Parametros'!$B$7/100)^(MIN(MAX('02_Parametros'!$B$5-C11,0),K11)/365),F11) | N11: =IF(AND(L11="Sí",'02_Parametros'!$B$7=""),"",F11-M11) | O11: =MAX(E11-'02_Parametros'!$B$5,0) | P11: =IF(AND(F11>0,O11>IF(S11="No",12*365/12,MAX(12,'02_Parametros'!$B$9)*365/12)),"Sí","No") | Q11: =IF(P11="Sí",M11,0) | R11: =IF(F11<0,-F11,0)
A12: P-008 | B12: Empaques Sierra | C12: 45779 | E12: 45809 | F12: 2500 | G12: No | H12: USD | I12: ='02_Parametros'!$B$5-E12 | J12: =IF(I12<=0,"Corriente / por vencer",IF(I12<=30,"1 a 30 días",IF(I12<=60,"31 a 60 días",IF(I12<=90,"61 a 90 días",IF(I12<=180,"91 a 180 días",IF(I12<=360,"181 a 360 días","Más de 360 días")))))) | K12: =E12-C12 | L12: =IF(AND(F12>0,K12>'02_Parametros'!$B$8*365/12),"Sí","No") | M12: =IF(AND(L12="Sí",'02_Parametros'!$B$7<>""),F12/(1+'02_Parametros'!$B$7/100)^(K12/365)*(1+'02_Parametros'!$B$7/100)^(MIN(MAX('02_Parametros'!$B$5-C12,0),K12)/365),F12) | N12: =IF(AND(L12="Sí",'02_Parametros'!$B$7=""),"",F12-M12) | O12: =MAX(E12-'02_Parametros'!$B$5,0) | P12: =IF(AND(F12>0,O12>IF(S12="No",12*365/12,MAX(12,'02_Parametros'!$B$9)*365/12)),"Sí","No") | Q12: =IF(P12="Sí",M12,0) | R12: =IF(F12<0,-F12,0)
A13: P-009 | B13: Importadora Global GmbH | C13: 45992 | E13: 46052 | F13: 9000 | G13: No | H13: EUR | I13: ='02_Parametros'!$B$5-E13 | J13: =IF(I13<=0,"Corriente / por vencer",IF(I13<=30,"1 a 30 días",IF(I13<=60,"31 a 60 días",IF(I13<=90,"61 a 90 días",IF(I13<=180,"91 a 180 días",IF(I13<=360,"181 a 360 días","Más de 360 días")))))) | K13: =E13-C13 | L13: =IF(AND(F13>0,K13>'02_Parametros'!$B$8*365/12),"Sí","No") | M13: =IF(AND(L13="Sí",'02_Parametros'!$B$7<>""),F13/(1+'02_Parametros'!$B$7/100)^(K13/365)*(1+'02_Parametros'!$B$7/100)^(MIN(MAX('02_Parametros'!$B$5-C13,0),K13)/365),F13) | N13: =IF(AND(L13="Sí",'02_Parametros'!$B$7=""),"",F13-M13) | O13: =MAX(E13-'02_Parametros'!$B$5,0) | P13: =IF(AND(F13>0,O13>IF(S13="No",12*365/12,MAX(12,'02_Parametros'!$B$9)*365/12)),"Sí","No") | Q13: =IF(P13="Sí",M13,0) | R13: =IF(F13<0,-F13,0)
A14: P-010 | B14: Empresa Eléctrica | C14: 46006 | D14: 45991 | E14: 46036 | F14: 1300 | G14: No | H14: USD | I14: ='02_Parametros'!$B$5-E14 | J14: =IF(I14<=0,"Corriente / por vencer",IF(I14<=30,"1 a 30 días",IF(I14<=60,"31 a 60 días",IF(I14<=90,"61 a 90 días",IF(I14<=180,"91 a 180 días",IF(I14<=360,"181 a 360 días","Más de 360 días")))))) | K14: =E14-C14 | L14: =IF(AND(F14>0,K14>'02_Parametros'!$B$8*365/12),"Sí","No") | M14: =IF(AND(L14="Sí",'02_Parametros'!$B$7<>""),F14/(1+'02_Parametros'!$B$7/100)^(K14/365)*(1+'02_Parametros'!$B$7/100)^(MIN(MAX('02_Parametros'!$B$5-C14,0),K14)/365),F14) | N14: =IF(AND(L14="Sí",'02_Parametros'!$B$7=""),"",F14-M14) | O14: =MAX(E14-'02_Parametros'!$B$5,0) | P14: =IF(AND(F14>0,O14>IF(S14="No",12*365/12,MAX(12,'02_Parametros'!$B$9)*365/12)),"Sí","No") | Q14: =IF(P14="Sí",M14,0) | R14: =IF(F14<0,-F14,0)
A15: P-011 | B15: Asesores Legales Asociados | C15: 45566 | E15: 45596 | F15: 600 | G15: No | H15: USD | I15: ='02_Parametros'!$B$5-E15 | J15: =IF(I15<=0,"Corriente / por vencer",IF(I15<=30,"1 a 30 días",IF(I15<=60,"31 a 60 días",IF(I15<=90,"61 a 90 días",IF(I15<=180,"91 a 180 días",IF(I15<=360,"181 a 360 días","Más de 360 días")))))) | K15: =E15-C15 | L15: =IF(AND(F15>0,K15>'02_Parametros'!$B$8*365/12),"Sí","No") | M15: =IF(AND(L15="Sí",'02_Parametros'!$B$7<>""),F15/(1+'02_Parametros'!$B$7/100)^(K15/365)*(1+'02_Parametros'!$B$7/100)^(MIN(MAX('02_Parametros'!$B$5-C15,0),K15)/365),F15) | N15: =IF(AND(L15="Sí",'02_Parametros'!$B$7=""),"",F15-M15) | O15: =MAX(E15-'02_Parametros'!$B$5,0) | P15: =IF(AND(F15>0,O15>IF(S15="No",12*365/12,MAX(12,'02_Parametros'!$B$9)*365/12)),"Sí","No") | Q15: =IF(P15="Sí",M15,0) | R15: =IF(F15<0,-F15,0)
A16: P-012 | B16: Mantenimiento Técnico | C16: 46022 | D16: 46022 | E16: 46067 | F16: 5500 | G16: No | H16: USD | I16: ='02_Parametros'!$B$5-E16 | J16: =IF(I16<=0,"Corriente / por vencer",IF(I16<=30,"1 a 30 días",IF(I16<=60,"31 a 60 días",IF(I16<=90,"61 a 90 días",IF(I16<=180,"91 a 180 días",IF(I16<=360,"181 a 360 días","Más de 360 días")))))) | K16: =E16-C16 | L16: =IF(AND(F16>0,K16>'02_Parametros'!$B$8*365/12),"Sí","No") | M16: =IF(AND(L16="Sí",'02_Parametros'!$B$7<>""),F16/(1+'02_Parametros'!$B$7/100)^(K16/365)*(1+'02_Parametros'!$B$7/100)^(MIN(MAX('02_Parametros'!$B$5-C16,0),K16)/365),F16) | N16: =IF(AND(L16="Sí",'02_Parametros'!$B$7=""),"",F16-M16) | O16: =MAX(E16-'02_Parametros'!$B$5,0) | P16: =IF(AND(F16>0,O16>IF(S16="No",12*365/12,MAX(12,'02_Parametros'!$B$9)*365/12)),"Sí","No") | Q16: =IF(P16="Sí",M16,0) | R16: =IF(F16<0,-F16,0)
A17: TOTAL | F17: =SUM(F5:F16) | M17: =SUM(M5:M16) | N17: =SUM(N5:N16) | Q17: =SUM(Q5:Q16) | R17: =SUM(R5:R16)
A19: ⓘ Cómo se calcula esta hoja
A20: Columna | B20: Fórmula (Excel) | C20: Cómo se calcula (sencillo) | D20: Ejemplo con números reales | E20: De dónde viene | F20: Norma
A21: Días desde vencimiento | B21: '='02_Parametros'!$B$5-E5 | C21: Resta la fecha de vencimiento de la fecha de corte (hoja 02): días que el documento lleva vencido. Si es negativo, todavía no vence. | D21: Fila 1: «2025-12-31»-«2026-01-04» → -4 | E21: «Vencimiento» (esta hoja), hoja «Parámetros» | F21: —
A22: Tramo | B22: '=IF(I5<=0,"Corriente / por vencer",IF(I5<=30,"1 a 30 días",IF(I5<=60,"31 a 60 días",IF(I5<=90,"61 a 90 días",IF(I5<=180,"91 a 180 días",IF(I5<=360,"181 a 360 días","Más de 360 días")))))) | C22: Ubica los días desde el vencimiento en su tramo de antigüedad: cero o menos es «Corriente / por vencer»; luego 1 a 30, 31 a 60, 61 a 90, 91 a 180, 181 a 360 y más de 360 días. | D22: Fila 1: IF(-4<=0; "Corriente / por vencer"; IF(-4<=30; "1 a 30 días"; IF(-4<=60; "31 a 60 días"; IF(-4<=90; "61 a 90 días"; IF(-4<=180; "91 a 180 días"; IF(-4<=360; "181 a 360 días"; "Más de 360 días")))))) → Corriente / por vencer | E22: «Días desde vencimiento» (esta hoja) | F22: —
A23: Plazo de pago (días) | B23: '=E5-C5 | C23: Resta la fecha de la factura de la fecha de vencimiento: es el plazo de crédito que dio el proveedor, en días. | D23: Fila 1: «2026-01-04»-«2025-12-05» → 30 | E23: «Vencimiento» (esta hoja), «Fecha factura» (esta hoja) | F23: —
A24: Financiación implícita | B24: '=IF(AND(F5>0,K5>'02_Parametros'!$B$8*365/12),"Sí","No") | C24: «Sí» cuando el saldo es positivo y el plazo de pago supera el plazo que se considera financiación (meses de la hoja 02 convertidos a días); en otro caso, «No». | D24: Fila 1: IF(AND(15.000,00>0; 30>12,00*365/12); "Sí"; "No") → No | E24: «Saldo» (esta hoja), «Plazo de pago (días)» (esta hoja), hoja «Parámetros» | F24: —
A25: Costo amortizado | B25: '=IF(AND(L5="Sí",'02_Parametros'!$B$7<>""),F5/(1+'02_Parametros'!$B$7/100)^(K5/365)*(1+'02_Parametros'!$B$7/100)^(MIN(MAX('02_Parametros'!$B$5-C5,0),K5)/365),F5) | C25: Si hay financiación implícita y tasa de mercado (hoja 02), descuenta el saldo a esa tasa por todo el plazo y lo hace crecer por los días ya transcurridos hasta el corte; si no, deja el saldo nominal. | D25: Fila 1: IF(AND(«No»="Sí"; 10,00<>""); 15.000,00/(1+10,00/100)^(30/365)*(1+10,00/100)^(MIN(MAX(«2025-12-31»-«2025-12-05»; 0); 30)/365); 15.000,00) → 15.000,00 | E25: «Financiación implícita» (esta hoja), «Saldo» (esta hoja), «Plazo de pago (días)» (esta hoja), «Fecha factura» (esta hoja), hoja «Parámetros» | F25: —
A26: Interés implícito por devengar | B26: '=IF(AND(L5="Sí",'02_Parametros'!$B$7=""),"",F5-M5) | C26: Resta el costo amortizado del saldo nominal: interés implícito que aún no se devenga. En blanco si hay financiación pero falta la tasa de mercado; cero si no hay financiación. | D26: Fila 1: IF(AND(«No»="Sí"; 10,00=""); ""; 15.000,00-15.000,00) → 0,00 | E26: «Financiación implícita» (esta hoja), «Saldo» (esta hoja), «Costo amortizado» (esta hoja), hoja «Parámetros» | F26: —
A27: Días por vencer | B27: '=MAX(E5-'02_Parametros'!$B$5,0) | C27: Resta la fecha de corte (hoja 02) de la fecha de vencimiento; si el documento ya venció, cuenta cero. | D27: Fila 1: MAX(«2026-01-04»-«2025-12-31»; 0) → 4 | E27: «Vencimiento» (esta hoja), hoja «Parámetros» | F27: —
A28: No corriente | B28: '=IF(AND(F5>0,O5>IF(S5="No",12*365/12,MAX(12,'02_Parametros'!$B$9)*365/12)),"Sí","No") | C28: «Sí» cuando el saldo es positivo y los días por vencer superan el límite: 12 meses si la partida no es de explotación; si lo es o no se informó, el mayor entre 12 meses y el ciclo de operación (hoja 02). | D28: Fila 1: IF(AND(15.000,00>0; 4>IF(«Sí»="No"; 12*365/12; MAX(12; 12,00)*365/12)); "Sí"; "No") → No | E28: «Saldo» (esta hoja), «Días por vencer» (esta hoja), «Partida de explotación» (esta hoja), hoja «Parámetros» | F28: —
A29: Importe no corriente | B29: '=IF(P5="Sí",M5,0) | C29: Si el documento es no corriente, toma su costo amortizado; si es corriente, cero. | D29: Fila 1: IF(«No»="Sí"; 15.000,00; 0) → 0,00 | E29: «No corriente» (esta hoja), «Costo amortizado» (esta hoja) | F29: —
A30: Saldo deudor | B30: '=IF(F5<0,-F5,0) | C30: Si el saldo es negativo (un anticipo o saldo a favor), lo pasa a positivo para reclasificarlo al activo; si no, cero. | D30: Fila 1: IF(15.000,00<0; -15.000,00; 0) → 0,00 | E30: «Saldo» (esta hoja) | F30: —

Sheet 04_Aging
A1: Antigüedad de proveedores | H1: ⟵ Inicio | I1: ◀ Anterior | J1: Siguiente ▶
A2: Proveedores y cuentas por pagar · Cliente de muestra S.A. · corte 2025-12-31
A4: Tramo | B4: Documentos | C4: Saldo | D4: % del saldo | E4: Vencido
A5: Corriente / por vencer | B5: =COUNTIF('03_Detalle'!$J$5:$J$16,A5) | C5: =SUMIF('03_Detalle'!$J$5:$J$16,A5,'03_Detalle'!$F$5:$F$16) | D5: =IF(SUM('03_Detalle'!$F$5:$F$16)=0,"",C5/SUM('03_Detalle'!$F$5:$F$16)) | E5: No
A6: 1 a 30 días | B6: =COUNTIF('03_Detalle'!$J$5:$J$16,A6) | C6: =SUMIF('03_Detalle'!$J$5:$J$16,A6,'03_Detalle'!$F$5:$F$16) | D6: =IF(SUM('03_Detalle'!$F$5:$F$16)=0,"",C6/SUM('03_Detalle'!$F$5:$F$16)) | E6: Sí
A7: 31 a 60 días | B7: =COUNTIF('03_Detalle'!$J$5:$J$16,A7) | C7: =SUMIF('03_Detalle'!$J$5:$J$16,A7,'03_Detalle'!$F$5:$F$16) | D7: =IF(SUM('03_Detalle'!$F$5:$F$16)=0,"",C7/SUM('03_Detalle'!$F$5:$F$16)) | E7: Sí
A8: 61 a 90 días | B8: =COUNTIF('03_Detalle'!$J$5:$J$16,A8) | C8: =SUMIF('03_Detalle'!$J$5:$J$16,A8,'03_Detalle'!$F$5:$F$16) | D8: =IF(SUM('03_Detalle'!$F$5:$F$16)=0,"",C8/SUM('03_Detalle'!$F$5:$F$16)) | E8: Sí
A9: 91 a 180 días | B9: =COUNTIF('03_Detalle'!$J$5:$J$16,A9) | C9: =SUMIF('03_Detalle'!$J$5:$J$16,A9,'03_Detalle'!$F$5:$F$16) | D9: =IF(SUM('03_Detalle'!$F$5:$F$16)=0,"",C9/SUM('03_Detalle'!$F$5:$F$16)) | E9: Sí
A10: 181 a 360 días | B10: =COUNTIF('03_Detalle'!$J$5:$J$16,A10) | C10: =SUMIF('03_Detalle'!$J$5:$J$16,A10,'03_Detalle'!$F$5:$F$16) | D10: =IF(SUM('03_Detalle'!$F$5:$F$16)=0,"",C10/SUM('03_Detalle'!$F$5:$F$16)) | E10: Sí
A11: Más de 360 días | B11: =COUNTIF('03_Detalle'!$J$5:$J$16,A11) | C11: =SUMIF('03_Detalle'!$J$5:$J$16,A11,'03_Detalle'!$F$5:$F$16) | D11: =IF(SUM('03_Detalle'!$F$5:$F$16)=0,"",C11/SUM('03_Detalle'!$F$5:$F$16)) | E11: Sí
A12: TOTAL | B12: =SUM(B5:B11) | C12: =SUM(C5:C11)
A14: ⓘ Cómo se calcula esta hoja
A15: Columna | B15: Fórmula (Excel) | C15: Cómo se calcula (sencillo) | D15: Ejemplo con números reales | E15: De dónde viene | F15: Norma
A16: Documentos | B16: '=COUNTIF('03_Detalle'!$J$5:$J$16,A5) | C16: Cuenta cuántos documentos del detalle (hoja 03) caen en este tramo de antigüedad. | D16: Fila 1: COUNTIF([«Tramo» de «Detalle por documento», 12 filas]; «Corriente / por vencer») → 8 | E16: «Tramo» (esta hoja), hoja «Detalle por documento» | F16: —
A17: Saldo | B17: '=SUMIF('03_Detalle'!$J$5:$J$16,A5,'03_Detalle'!$F$5:$F$16) | C17: Suma el saldo por pagar de los documentos del detalle (hoja 03) que caen en este tramo de antigüedad. | D17: Fila 1: SUMIF([«Tramo» de «Detalle por documento», 12 filas]; «Corriente / por vencer»; [«Saldo» de «Detalle por documento», 12 filas]) → 70.200,00 | E17: «Tramo» (esta hoja), hoja «Detalle por documento» | F17: —
A18: % del saldo | B18: '=IF(SUM('03_Detalle'!$F$5:$F$16)=0,"",C5/SUM('03_Detalle'!$F$5:$F$16)) | C18: Divide el saldo del tramo para el saldo total del detalle (hoja 03): qué parte de la deuda con proveedores está en este tramo. En blanco si el total es cero. | D18: Fila 1: IF(SUM([«Saldo» de «Detalle por documento», 12 filas])=0; ""; 70.200,00/SUM([«Saldo» de «Detalle por documento», 12 filas])) → 87,42 % | E18: «Saldo» (esta hoja), hoja «Detalle por documento» | F18: —

Sheet 05_Pagos_posteriores
A1: Pagos posteriores al cierre | H1: ⟵ Inicio | I1: ◀ Anterior | J1: Siguiente ▶
A2: Proveedores y cuentas por pagar · Cliente de muestra S.A. · corte 2025-12-31
A4: Documento | B4: Proveedor | C4: Días desde vencimiento | D4: Saldo al corte | E4: Pago informado | F4: Fecha del pago | G4: Pago posterior aplicable | H4: Saldo sin pago posterior | I4: Pago mayor al saldo
A5: P-001 | B5: Aceros del Pacífico S.A. | C5: ='03_Detalle'!I5 | D5: ='03_Detalle'!F5 | E5: 15000 | F5: 46026 | G5: =IF(OR(E5="",F5=""),0,IF(F5>'02_Parametros'!$B$5,MIN(E5,D5),0)) | H5: =D5-G5 | I5: =IF(OR(E5="",F5=""),0,IF(F5>'02_Parametros'!$B$5,MAX(E5-D5,0),0))
A6: P-002 | B6: Plásticos Andinos Cía. Ltda. | C6: ='03_Detalle'!I6 | D6: ='03_Detalle'!F6 | G6: =IF(OR(E6="",F6=""),0,IF(F6>'02_Parametros'!$B$5,MIN(E6,D6),0)) | H6: =D6-G6 | I6: =IF(OR(E6="",F6=""),0,IF(F6>'02_Parametros'!$B$5,MAX(E6-D6,0),0))
A7: P-003 | B7: Servicios Logísticos del Sur | C7: ='03_Detalle'!I7 | D7: ='03_Detalle'!F7 | G7: =IF(OR(E7="",F7=""),0,IF(F7>'02_Parametros'!$B$5,MIN(E7,D7),0)) | H7: =D7-G7 | I7: =IF(OR(E7="",F7=""),0,IF(F7>'02_Parametros'!$B$5,MAX(E7-D7,0),0))
A8: P-004 | B8: Químicos Unidos S.A. | C8: ='03_Detalle'!I8 | D8: ='03_Detalle'!F8 | E8: 3500 | F8: 46042 | G8: =IF(OR(E8="",F8=""),0,IF(F8>'02_Parametros'!$B$5,MIN(E8,D8),0)) | H8: =D8-G8 | I8: =IF(OR(E8="",F8=""),0,IF(F8>'02_Parametros'!$B$5,MAX(E8-D8,0),0))
A9: P-005 | B9: Maquinarias Industriales S.A. | C9: ='03_Detalle'!I9 | D9: ='03_Detalle'!F9 | G9: =IF(OR(E9="",F9=""),0,IF(F9>'02_Parametros'!$B$5,MIN(E9,D9),0)) | H9: =D9-G9 | I9: =IF(OR(E9="",F9=""),0,IF(F9>'02_Parametros'!$B$5,MAX(E9-D9,0),0))
A10: P-006 | B10: Holding Andes S.A. | C10: ='03_Detalle'!I10 | D10: ='03_Detalle'!F10 | G10: =IF(OR(E10="",F10=""),0,IF(F10>'02_Parametros'!$B$5,MIN(E10,D10),0)) | H10: =D10-G10 | I10: =IF(OR(E10="",F10=""),0,IF(F10>'02_Parametros'!$B$5,MAX(E10-D10,0),0))
A11: P-007 | B11: Transportes Rápidos | C11: ='03_Detalle'!I11 | D11: ='03_Detalle'!F11 | G11: =IF(OR(E11="",F11=""),0,IF(F11>'02_Parametros'!$B$5,MIN(E11,D11),0)) | H11: =D11-G11 | I11: =IF(OR(E11="",F11=""),0,IF(F11>'02_Parametros'!$B$5,MAX(E11-D11,0),0))
A12: P-008 | B12: Empaques Sierra | C12: ='03_Detalle'!I12 | D12: ='03_Detalle'!F12 | G12: =IF(OR(E12="",F12=""),0,IF(F12>'02_Parametros'!$B$5,MIN(E12,D12),0)) | H12: =D12-G12 | I12: =IF(OR(E12="",F12=""),0,IF(F12>'02_Parametros'!$B$5,MAX(E12-D12,0),0))
A13: P-009 | B13: Importadora Global GmbH | C13: ='03_Detalle'!I13 | D13: ='03_Detalle'!F13 | E13: 9000 | F13: 46019 | G13: =IF(OR(E13="",F13=""),0,IF(F13>'02_Parametros'!$B$5,MIN(E13,D13),0)) | H13: =D13-G13 | I13: =IF(OR(E13="",F13=""),0,IF(F13>'02_Parametros'!$B$5,MAX(E13-D13,0),0))
A14: P-010 | B14: Empresa Eléctrica | C14: ='03_Detalle'!I14 | D14: ='03_Detalle'!F14 | E14: 1300 | F14: 46036 | G14: =IF(OR(E14="",F14=""),0,IF(F14>'02_Parametros'!$B$5,MIN(E14,D14),0)) | H14: =D14-G14 | I14: =IF(OR(E14="",F14=""),0,IF(F14>'02_Parametros'!$B$5,MAX(E14-D14,0),0))
A15: P-011 | B15: Asesores Legales Asociados | C15: ='03_Detalle'!I15 | D15: ='03_Detalle'!F15 | G15: =IF(OR(E15="",F15=""),0,IF(F15>'02_Parametros'!$B$5,MIN(E15,D15),0)) | H15: =D15-G15 | I15: =IF(OR(E15="",F15=""),0,IF(F15>'02_Parametros'!$B$5,MAX(E15-D15,0),0))
A16: P-012 | B16: Mantenimiento Técnico | C16: ='03_Detalle'!I16 | D16: ='03_Detalle'!F16 | E16: 5500 | F16: 46067 | G16: =IF(OR(E16="",F16=""),0,IF(F16>'02_Parametros'!$B$5,MIN(E16,D16),0)) | H16: =D16-G16 | I16: =IF(OR(E16="",F16=""),0,IF(F16>'02_Parametros'!$B$5,MAX(E16-D16,0),0))
A17: TOTAL | D17: =SUM(D5:D16) | G17: =SUM(G5:G16) | H17: =SUM(H5:H16) | I17: =SUM(I5:I16)
A19: ⓘ Cómo se calcula esta hoja
A20: Columna | B20: Fórmula (Excel) | C20: Cómo se calcula (sencillo) | D20: Ejemplo con números reales | E20: De dónde viene | F20: Norma
A21: Días desde vencimiento | B21: '='03_Detalle'!I5 | C21: Trae de la hoja 03 (Detalle por documento) los días que el documento lleva vencido a la fecha de corte. | D21: Fila 1: -4 → -4 | E21: hoja «Detalle por documento» | F21: —
A22: Saldo al corte | B22: '='03_Detalle'!F5 | C22: Trae de la hoja 03 (Detalle por documento) el saldo por pagar del documento a la fecha de corte. | D22: Fila 1: 15.000,00 → 15.000,00 | E22: hoja «Detalle por documento» | F22: —
A23: Pago posterior aplicable | B23: '=IF(OR(E5="",F5=""),0,IF(F5>'02_Parametros'!$B$5,MIN(E5,D5),0)) | C23: Si hay pago y fecha de pago, y la fecha es posterior al corte, toma el menor entre el pago y el saldo al corte; si falta el pago o su fecha, o se pagó antes del corte, cero. | D23: Fila 1: IF(OR(15.000,00=""; «2026-01-04»=""); 0; IF(«2026-01-04»>«2025-12-31»; MIN(15.000,00; 15.000,00); 0)) → 15.000,00 | E23: «Pago informado» (esta hoja), «Fecha del pago» (esta hoja), «Saldo al corte» (esta hoja), hoja «Parámetros» | F23: —
A24: Saldo sin pago posterior | B24: '=D5-G5 | C24: Resta el pago posterior aplicable del saldo al corte: es la parte del saldo que no quedó respaldada por un pago después del cierre. | D24: Fila 1: 15.000,00-15.000,00 → 0,00 | E24: «Saldo al corte» (esta hoja), «Pago posterior aplicable» (esta hoja) | F24: —
A25: Pago mayor al saldo | B25: '=IF(OR(E5="",F5=""),0,IF(F5>'02_Parametros'!$B$5,MAX(E5-D5,0),0)) | C25: Si el pago es posterior al corte, toma lo que el pago excede al saldo registrado (cero si no lo excede): indica un posible pasivo subestimado. | D25: Fila 1: IF(OR(15.000,00=""; «2026-01-04»=""); 0; IF(«2026-01-04»>«2025-12-31»; MAX(15.000,00-15.000,00; 0); 0)) → 0,00 | E25: «Pago informado» (esta hoja), «Fecha del pago» (esta hoja), «Saldo al corte» (esta hoja), hoja «Parámetros» | F25: —

Sheet 06_Pasivos_no_registrados
A1: Búsqueda de pasivos no registrados | H1: ⟵ Inicio | I1: ◀ Anterior | J1: Siguiente ▶
A2: Proveedores y cuentas por pagar · Cliente de muestra S.A. · corte 2025-12-31
A4: Documento | B4: Proveedor | C4: Fecha pago / factura | D4: Recepción | E4: Importe | F4: ¿Registrado al corte? | G4: Posterior al corte | H4: Causa hasta el corte | I4: Pasivo no registrado
A5: CE-001 | B5: Aceros del Pacífico S.A. | C5: 46032 | D5: 46013 | E5: 6200 | F5: No | G5: =IF(C5>'02_Parametros'!$B$5,"Sí","No") | H5: =IF(D5<='02_Parametros'!$B$5,"Sí","No") | I5: =IF(AND(G5="Sí",H5="Sí",F5="No"),E5,0)
A6: CE-002 | B6: Servicios Contables | C6: 46037 | D6: 46022 | E6: 1850 | F6: No | G6: =IF(C6>'02_Parametros'!$B$5,"Sí","No") | H6: =IF(D6<='02_Parametros'!$B$5,"Sí","No") | I6: =IF(AND(G6="Sí",H6="Sí",F6="No"),E6,0)
A7: CE-003 | B7: Plásticos Andinos Cía. Ltda. | C7: 46042 | D7: 46034 | E7: 3100 | F7: No | G7: =IF(C7>'02_Parametros'!$B$5,"Sí","No") | H7: =IF(D7<='02_Parametros'!$B$5,"Sí","No") | I7: =IF(AND(G7="Sí",H7="Sí",F7="No"),E7,0)
A8: CE-004 | B8: Empresa Eléctrica | C8: 46036 | D8: 45991 | E8: 1300 | F8: Sí | G8: =IF(C8>'02_Parametros'!$B$5,"Sí","No") | H8: =IF(D8<='02_Parametros'!$B$5,"Sí","No") | I8: =IF(AND(G8="Sí",H8="Sí",F8="No"),E8,0)
A9: CE-005 | B9: Químicos Unidos S.A. | C9: 46058 | D9: 46009 | E9: 2750 | F9: Sí | G9: =IF(C9>'02_Parametros'!$B$5,"Sí","No") | H9: =IF(D9<='02_Parametros'!$B$5,"Sí","No") | I9: =IF(AND(G9="Sí",H9="Sí",F9="No"),E9,0)
A10: CE-006 | B10: Seguridad Privada | C10: 46053 | D10: 46022 | E10: 950 | F10: No | G10: =IF(C10>'02_Parametros'!$B$5,"Sí","No") | H10: =IF(D10<='02_Parametros'!$B$5,"Sí","No") | I10: =IF(AND(G10="Sí",H10="Sí",F10="No"),E10,0)
A11: CE-007 | B11: Papelería Central | C11: 46011 | D11: 46006 | E11: 300 | F11: No | G11: =IF(C11>'02_Parametros'!$B$5,"Sí","No") | H11: =IF(D11<='02_Parametros'!$B$5,"Sí","No") | I11: =IF(AND(G11="Sí",H11="Sí",F11="No"),E11,0)
A12: CE-008 | B12: Consultora Beta | C12: 46073 | D12: 46054 | E12: 4000 | F12: No | G12: =IF(C12>'02_Parametros'!$B$5,"Sí","No") | H12: =IF(D12<='02_Parametros'!$B$5,"Sí","No") | I12: =IF(AND(G12="Sí",H12="Sí",F12="No"),E12,0)
A13: TOTAL | E13: =SUM(E5:E12) | I13: =SUM(I5:I12)
A15: ⓘ Cómo se calcula esta hoja
A16: Columna | B16: Fórmula (Excel) | C16: Cómo se calcula (sencillo) | D16: Ejemplo con números reales | E16: De dónde viene | F16: Norma
A17: Posterior al corte | B17: '=IF(C5>'02_Parametros'!$B$5,"Sí","No") | C17: «Sí» si la fecha del pago o de la factura es posterior a la fecha de corte de la hoja 02 (Parámetros). | D17: Fila 1: IF(«2026-01-10»>«2025-12-31»; "Sí"; "No") → Sí | E17: «Fecha pago / factura» (esta hoja), hoja «Parámetros» | F17: —
A18: Causa hasta el corte | B18: '=IF(D5<='02_Parametros'!$B$5,"Sí","No") | C18: «Sí» si el bien o servicio se recibió hasta la fecha de corte (hoja 02): la obligación ya existía al cierre. | D18: Fila 1: IF(«2025-12-22»<=«2025-12-31»; "Sí"; "No") → Sí | E18: «Recepción» (esta hoja), hoja «Parámetros» | F18: —
A19: Pasivo no registrado | B19: '=IF(AND(G5="Sí",H5="Sí",F5="No"),E5,0) | C19: Si el documento es posterior al corte, la recepción fue hasta el corte y el pasivo no estaba registrado, toma su importe: es un pasivo omitido. En otro caso, cero. | D19: Fila 1: IF(AND(«Sí»="Sí"; «Sí»="Sí"; «No»="No"); 6.200,00; 0) → 6.200,00 | E19: «Posterior al corte» (esta hoja), «Causa hasta el corte» (esta hoja), «¿Registrado al corte?» (esta hoja), «Importe» (esta hoja) | F19: —

Sheet 07_Confirmaciones
A1: Confirmación de proveedores | H1: ⟵ Inicio | I1: ◀ Anterior | J1: Siguiente ▶
A2: Proveedores y cuentas por pagar · Cliente de muestra S.A. · corte 2025-12-31
A4: Documento | B4: Proveedor | C4: Saldo en libros | D4: Saldo confirmado | E4: Diferencia | F4: Diferencia absoluta | G4: Estado
A5: P-001 | B5: Aceros del Pacífico S.A. | C5: ='03_Detalle'!F5 | D5: 15000 | E5: =D5-C5 | F5: =ABS(E5) | G5: =IF(ABS(E5)<=0.005,"Conforme",IF(E5>0,"Proveedor reporta más","Proveedor reporta menos"))
A6: P-003 | B6: Servicios Logísticos del Sur | C6: ='03_Detalle'!F7 | D6: 5200 | E6: =D6-C6 | F6: =ABS(E6) | G6: =IF(ABS(E6)<=0.005,"Conforme",IF(E6>0,"Proveedor reporta más","Proveedor reporta menos"))
A7: P-005 | B7: Maquinarias Industriales S.A. | C7: ='03_Detalle'!F9 | D7: 24200 | E7: =D7-C7 | F7: =ABS(E7) | G7: =IF(ABS(E7)<=0.005,"Conforme",IF(E7>0,"Proveedor reporta más","Proveedor reporta menos"))
A8: TOTAL | C8: =SUM(C5:C7) | D8: =SUM(D5:D7) | E8: =SUM(E5:E7) | F8: =SUM(F5:F7)
A10: ⓘ Cómo se calcula esta hoja
A11: Columna | B11: Fórmula (Excel) | C11: Cómo se calcula (sencillo) | D11: Ejemplo con números reales | E11: De dónde viene | F11: Norma
A12: Saldo en libros | B12: '='03_Detalle'!F5 | C12: Trae de la hoja 03 (Detalle por documento) el saldo por pagar registrado para el documento confirmado. | D12: Fila 1: 15.000,00 → 15.000,00 | E12: hoja «Detalle por documento» | F12: —
A13: Diferencia | B13: '=D5-C5 | C13: Resta el saldo en libros del saldo confirmado por el proveedor. Positivo: el proveedor reporta más de lo registrado. | D13: Fila 1: 15.000,00-15.000,00 → 0,00 | E13: «Saldo confirmado» (esta hoja), «Saldo en libros» (esta hoja) | F13: —
A14: Diferencia absoluta | B14: '=ABS(E5) | C14: Toma la diferencia sin signo, para sumar las diferencias sin que se compensen unas con otras. | D14: Fila 1: ABS(0,00) → 0,00 | E14: «Diferencia» (esta hoja) | F14: —
A15: Estado | B15: '=IF(ABS(E5)<=0.005,"Conforme",IF(E5>0,"Proveedor reporta más","Proveedor reporta menos")) | C15: Califica la respuesta: «Conforme» si la diferencia no pasa de medio centavo; si no, «Proveedor reporta más» o «Proveedor reporta menos», según el signo. | D15: Fila 1: IF(ABS(0,00)<=0.005; "Conforme"; IF(0,00>0; "Proveedor reporta más"; "Proveedor reporta menos")) → Conforme | E15: «Diferencia» (esta hoja) | F15: —

Sheet 08_Corte_compras
A1: Corte de compras | H1: ⟵ Inicio | I1: ◀ Anterior | J1: Siguiente ▶
A2: Proveedores y cuentas por pagar · Cliente de muestra S.A. · corte 2025-12-31
A4: Documento | B4: Proveedor | C4: Fecha factura | D4: Recepción | E4: Saldo | F4: Recibida en el ejercicio | G4: Registrada antes de la recepción
A5: P-001 | B5: Aceros del Pacífico S.A. | C5: 45996 | D5: 45996 | E5: ='03_Detalle'!F5 | F5: =IF(D5<='02_Parametros'!$B$5,"Sí","No") | G5: =IF(F5="No",E5,0)
A6: P-002 | B6: Plásticos Andinos Cía. Ltda. | C6: 46020 | D6: 46028 | E6: ='03_Detalle'!F6 | F6: =IF(D6<='02_Parametros'!$B$5,"Sí","No") | G6: =IF(F6="No",E6,0)
A7: P-003 | B7: Servicios Logísticos del Sur | C7: 45971 | D7: 45971 | E7: ='03_Detalle'!F7 | F7: =IF(D7<='02_Parametros'!$B$5,"Sí","No") | G7: =IF(F7="No",E7,0)
A8: P-005 | B8: Maquinarias Industriales S.A. | C8: 45839 | D8: 45839 | E8: ='03_Detalle'!F9 | F8: =IF(D8<='02_Parametros'!$B$5,"Sí","No") | G8: =IF(F8="No",E8,0)
A9: P-010 | B9: Empresa Eléctrica | C9: 46006 | D9: 45991 | E9: ='03_Detalle'!F14 | F9: =IF(D9<='02_Parametros'!$B$5,"Sí","No") | G9: =IF(F9="No",E9,0)
A10: P-012 | B10: Mantenimiento Técnico | C10: 46022 | D10: 46022 | E10: ='03_Detalle'!F16 | F10: =IF(D10<='02_Parametros'!$B$5,"Sí","No") | G10: =IF(F10="No",E10,0)
A11: TOTAL | E11: =SUM(E5:E10) | G11: =SUM(G5:G10)
A13: ⓘ Cómo se calcula esta hoja
A14: Columna | B14: Fórmula (Excel) | C14: Cómo se calcula (sencillo) | D14: Ejemplo con números reales | E14: De dónde viene | F14: Norma
A15: Saldo | B15: '='03_Detalle'!F5 | C15: Trae de la hoja 03 (Detalle por documento) el saldo por pagar del documento con fecha de recepción informada. | D15: Fila 1: 15.000,00 → 15.000,00 | E15: hoja «Detalle por documento» | F15: —
A16: Recibida en el ejercicio | B16: '=IF(D5<='02_Parametros'!$B$5,"Sí","No") | C16: «Sí» si la fecha de recepción del bien o servicio es anterior o igual a la fecha de corte (hoja 02). | D16: Fila 1: IF(«2025-12-05»<=«2025-12-31»; "Sí"; "No") → Sí | E16: «Recepción» (esta hoja), hoja «Parámetros» | F16: —
A17: Registrada antes de la recepción | B17: '=IF(F5="No",E5,0) | C17: Si el bien o servicio no se recibió hasta el corte, toma el saldo del documento: es una compra registrada antes de tiempo. Si se recibió, cero. | D17: Fila 1: IF(«Sí»="No"; 15.000,00; 0) → 0,00 | E17: «Recibida en el ejercicio» (esta hoja), «Saldo» (esta hoja) | F17: —

Sheet 09_Costo_amortizado
A1: Costo amortizado e intereses implícitos | H1: ⟵ Inicio | I1: ◀ Anterior | J1: Siguiente ▶
A2: Proveedores y cuentas por pagar · Cliente de muestra S.A. · corte 2025-12-31
A4: Documento | B4: Proveedor | C4: Fecha factura | D4: Vencimiento | E4: Nominal | F4: Plazo (días) | G4: Días transcurridos | H4: TIE = tasa de mercado | I4: Pasivo inicial (valor presente) | J4: Financiación implícita | K4: TIE recalculada | L4: Interés devengado al corte | M4: Costo amortizado al corte | N4: Interés por devengar
A5: P-005 | B5: Maquinarias Industriales S.A. | C5: 45839 | D5: 46569 | E5: ='03_Detalle'!F9 | F5: =D5-C5 | G5: =MIN(MAX('02_Parametros'!$B$5-C5,0),F5) | H5: =IF('02_Parametros'!$B$7="","",'02_Parametros'!$B$7/100) | I5: =IF(H5="","",E5/(1+H5)^(F5/365)) | J5: =IF(H5="","",E5-I5) | K5: =IF(H5="","",(E5/I5)^(365/F5)-1) | L5: =IF(H5="","",I5*((1+H5)^(G5/365)-1)) | M5: =IF(H5="","",I5+L5) | N5: =IF(H5="","",E5-M5)
A6: TOTAL | E6: =SUM(E5:E5) | I6: =SUM(I5:I5) | J6: =SUM(J5:J5) | L6: =SUM(L5:L5) | M6: =SUM(M5:M5) | N6: =SUM(N5:N5)
A8: ⓘ Cómo se calcula esta hoja
A9: Columna | B9: Fórmula (Excel) | C9: Cómo se calcula (sencillo) | D9: Ejemplo con números reales | E9: De dónde viene | F9: Norma
A10: Nominal | B10: '='03_Detalle'!F9 | C10: Trae de la hoja 03 (Detalle por documento) el saldo por pagar del documento con financiación implícita. | D10: Fila 1: 24.200,00 → 24.200,00 | E10: hoja «Detalle por documento» | F10: —
A11: Plazo (días) | B11: '=D5-C5 | C11: Resta la fecha de la factura de la fecha de vencimiento: días de crédito que dio el proveedor. | D11: Fila 1: «2027-07-01»-«2025-07-01» → 730 | E11: «Vencimiento» (esta hoja), «Fecha factura» (esta hoja) | F11: —
A12: Días transcurridos | B12: '=MIN(MAX('02_Parametros'!$B$5-C5,0),F5) | C12: Días desde la fecha de la factura hasta el corte (hoja 02), sin bajar de cero ni pasar del plazo del documento. | D12: Fila 1: MIN(MAX(«2025-12-31»-«2025-07-01»; 0); 730) → 183 | E12: «Fecha factura» (esta hoja), «Plazo (días)» (esta hoja), hoja «Parámetros» | F12: —
A13: TIE = tasa de mercado | B13: '=IF('02_Parametros'!$B$7="","",'02_Parametros'!$B$7/100) | C13: Trae la tasa de mercado anual de la hoja 02 (Parámetros) y la divide para 100; en blanco si no se informó. | D13: Fila 1: IF(10,00=""; ""; 10,00/100) → 10,00 % | E13: hoja «Parámetros» | F13: —
A14: Pasivo inicial (valor presente) | B14: '=IF(H5="","",E5/(1+H5)^(F5/365)) | C14: Descuenta el nominal a la tasa de mercado por el plazo: nominal ÷ (1 + tasa) elevado a plazo/365. Es el pasivo que debió reconocerse al comprar. | D14: Fila 1: IF(10,00 %=""; ""; 24.200,00/(1+10,00 %)^(730/365)) → 20.000,00 | E14: «TIE = tasa de mercado» (esta hoja), «Nominal» (esta hoja), «Plazo (días)» (esta hoja) | F14: —
A15: Financiación implícita | B15: '=IF(H5="","",E5-I5) | C15: Resta el pasivo inicial (valor presente) del nominal: es el interés escondido en el precio de la compra. | D15: Fila 1: IF(10,00 %=""; ""; 24.200,00-20.000,00) → 4.200,00 | E15: «TIE = tasa de mercado» (esta hoja), «Nominal» (esta hoja), «Pasivo inicial (valor presente)» (esta hoja) | F15: —
A16: TIE recalculada | B16: '=IF(H5="","",(E5/I5)^(365/F5)-1) | C16: Despeja la tasa que convierte el pasivo inicial en el nominal en el plazo del documento; debe coincidir con la tasa de mercado y sirve de control. | D16: Fila 1: IF(10,00 %=""; ""; (24.200,00/20.000,00)^(365/730)-1) → 10,00 % | E16: «TIE = tasa de mercado» (esta hoja), «Nominal» (esta hoja), «Pasivo inicial (valor presente)» (esta hoja), «Plazo (días)» (esta hoja) | F16: —
A17: Interés devengado al corte | B17: '=IF(H5="","",I5*((1+H5)^(G5/365)-1)) | C17: Aplica al pasivo inicial la tasa de mercado por los días transcurridos: pasivo inicial × ((1 + tasa) elevado a días/365 − 1). | D17: Fila 1: IF(10,00 %=""; ""; 20.000,00*((1+10,00 %)^(183/365)-1)) → 978,92 | E17: «TIE = tasa de mercado» (esta hoja), «Pasivo inicial (valor presente)» (esta hoja), «Días transcurridos» (esta hoja) | F17: —
A18: Costo amortizado al corte | B18: '=IF(H5="","",I5+L5) | C18: Suma el pasivo inicial y el interés devengado al corte: es el saldo que corresponde presentar a la fecha de corte. | D18: Fila 1: IF(10,00 %=""; ""; 20.000,00+978,92) → 20.978,92 | E18: «TIE = tasa de mercado» (esta hoja), «Pasivo inicial (valor presente)» (esta hoja), «Interés devengado al corte» (esta hoja) | F18: —
A19: Interés por devengar | B19: '=IF(H5="","",E5-M5) | C19: Resta el costo amortizado al corte del nominal: es el interés implícito que queda por devengar después del corte. | D19: Fila 1: IF(10,00 %=""; ""; 24.200,00-20.978,92) → 3.221,08 | E19: «TIE = tasa de mercado» (esta hoja), «Nominal» (esta hoja), «Costo amortizado al corte» (esta hoja) | F19: —

Sheet 10_Clasificacion
A1: Clasificación corriente / no corriente | H1: ⟵ Inicio | I1: ◀ Anterior | J1: Siguiente ▶
A2: Proveedores y cuentas por pagar · Cliente de muestra S.A. · corte 2025-12-31
A4: Documento | B4: Proveedor | C4: Vencimiento | D4: Días por vencer | E4: Costo amortizado | F4: Clasificación requerida | G4: Corriente | H4: No corriente | I4: Saldo deudor (activo) | J4: Partida de explotación | K4: Límite aplicado (días)
A5: P-001 | B5: Aceros del Pacífico S.A. | C5: 46026 | D5: ='03_Detalle'!O5 | E5: ='03_Detalle'!M5 | F5: =IF(E5<0,"Activo (anticipo)",IF('03_Detalle'!P5="Sí","No corriente","Corriente")) | G5: =IF(F5="Corriente",E5,0) | H5: ='03_Detalle'!Q5 | I5: ='03_Detalle'!R5 | J5: =IF('03_Detalle'!S5="","",'03_Detalle'!S5) | K5: =IF(J5="No",12*365/12,MAX(12,'02_Parametros'!$B$9)*365/12)
A6: P-002 | B6: Plásticos Andinos Cía. Ltda. | C6: 46050 | D6: ='03_Detalle'!O6 | E6: ='03_Detalle'!M6 | F6: =IF(E6<0,"Activo (anticipo)",IF('03_Detalle'!P6="Sí","No corriente","Corriente")) | G6: =IF(F6="Corriente",E6,0) | H6: ='03_Detalle'!Q6 | I6: ='03_Detalle'!R6 | J6: =IF('03_Detalle'!S6="","",'03_Detalle'!S6) | K6: =IF(J6="No",12*365/12,MAX(12,'02_Parametros'!$B$9)*365/12)
A7: P-003 | B7: Servicios Logísticos del Sur | C7: 46001 | D7: ='03_Detalle'!O7 | E7: ='03_Detalle'!M7 | F7: =IF(E7<0,"Activo (anticipo)",IF('03_Detalle'!P7="Sí","No corriente","Corriente")) | G7: =IF(F7="Corriente",E7,0) | H7: ='03_Detalle'!Q7 | I7: ='03_Detalle'!R7 | J7: =IF('03_Detalle'!S7="","",'03_Detalle'!S7) | K7: =IF(J7="No",12*365/12,MAX(12,'02_Parametros'!$B$9)*365/12)
A8: P-004 | B8: Químicos Unidos S.A. | C8: 45945 | D8: ='03_Detalle'!O8 | E8: ='03_Detalle'!M8 | F8: =IF(E8<0,"Activo (anticipo)",IF('03_Detalle'!P8="Sí","No corriente","Corriente")) | G8: =IF(F8="Corriente",E8,0) | H8: ='03_Detalle'!Q8 | I8: ='03_Detalle'!R8 | J8: =IF('03_Detalle'!S8="","",'03_Detalle'!S8) | K8: =IF(J8="No",12*365/12,MAX(12,'02_Parametros'!$B$9)*365/12)
A9: P-005 | B9: Maquinarias Industriales S.A. | C9: 46569 | D9: ='03_Detalle'!O9 | E9: ='03_Detalle'!M9 | F9: =IF(E9<0,"Activo (anticipo)",IF('03_Detalle'!P9="Sí","No corriente","Corriente")) | G9: =IF(F9="Corriente",E9,0) | H9: ='03_Detalle'!Q9 | I9: ='03_Detalle'!R9 | J9: =IF('03_Detalle'!S9="","",'03_Detalle'!S9) | K9: =IF(J9="No",12*365/12,MAX(12,'02_Parametros'!$B$9)*365/12)
A10: P-006 | B10: Holding Andes S.A. | C10: 46203 | D10: ='03_Detalle'!O10 | E10: ='03_Detalle'!M10 | F10: =IF(E10<0,"Activo (anticipo)",IF('03_Detalle'!P10="Sí","No corriente","Corriente")) | G10: =IF(F10="Corriente",E10,0) | H10: ='03_Detalle'!Q10 | I10: ='03_Detalle'!R10 | J10: =IF('03_Detalle'!S10="","",'03_Detalle'!S10) | K10: =IF(J10="No",12*365/12,MAX(12,'02_Parametros'!$B$9)*365/12)
A11: P-007 | B11: Transportes Rápidos | C11: 46041 | D11: ='03_Detalle'!O11 | E11: ='03_Detalle'!M11 | F11: =IF(E11<0,"Activo (anticipo)",IF('03_Detalle'!P11="Sí","No corriente","Corriente")) | G11: =IF(F11="Corriente",E11,0) | H11: ='03_Detalle'!Q11 | I11: ='03_Detalle'!R11 | J11: =IF('03_Detalle'!S11="","",'03_Detalle'!S11) | K11: =IF(J11="No",12*365/12,MAX(12,'02_Parametros'!$B$9)*365/12)
A12: P-008 | B12: Empaques Sierra | C12: 45809 | D12: ='03_Detalle'!O12 | E12: ='03_Detalle'!M12 | F12: =IF(E12<0,"Activo (anticipo)",IF('03_Detalle'!P12="Sí","No corriente","Corriente")) | G12: =IF(F12="Corriente",E12,0) | H12: ='03_Detalle'!Q12 | I12: ='03_Detalle'!R12 | J12: =IF('03_Detalle'!S12="","",'03_Detalle'!S12) | K12: =IF(J12="No",12*365/12,MAX(12,'02_Parametros'!$B$9)*365/12)
A13: P-009 | B13: Importadora Global GmbH | C13: 46052 | D13: ='03_Detalle'!O13 | E13: ='03_Detalle'!M13 | F13: =IF(E13<0,"Activo (anticipo)",IF('03_Detalle'!P13="Sí","No corriente","Corriente")) | G13: =IF(F13="Corriente",E13,0) | H13: ='03_Detalle'!Q13 | I13: ='03_Detalle'!R13 | J13: =IF('03_Detalle'!S13="","",'03_Detalle'!S13) | K13: =IF(J13="No",12*365/12,MAX(12,'02_Parametros'!$B$9)*365/12)
A14: P-010 | B14: Empresa Eléctrica | C14: 46036 | D14: ='03_Detalle'!O14 | E14: ='03_Detalle'!M14 | F14: =IF(E14<0,"Activo (anticipo)",IF('03_Detalle'!P14="Sí","No corriente","Corriente")) | G14: =IF(F14="Corriente",E14,0) | H14: ='03_Detalle'!Q14 | I14: ='03_Detalle'!R14 | J14: =IF('03_Detalle'!S14="","",'03_Detalle'!S14) | K14: =IF(J14="No",12*365/12,MAX(12,'02_Parametros'!$B$9)*365/12)
A15: P-011 | B15: Asesores Legales Asociados | C15: 45596 | D15: ='03_Detalle'!O15 | E15: ='03_Detalle'!M15 | F15: =IF(E15<0,"Activo (anticipo)",IF('03_Detalle'!P15="Sí","No corriente","Corriente")) | G15: =IF(F15="Corriente",E15,0) | H15: ='03_Detalle'!Q15 | I15: ='03_Detalle'!R15 | J15: =IF('03_Detalle'!S15="","",'03_Detalle'!S15) | K15: =IF(J15="No",12*365/12,MAX(12,'02_Parametros'!$B$9)*365/12)
A16: P-012 | B16: Mantenimiento Técnico | C16: 46067 | D16: ='03_Detalle'!O16 | E16: ='03_Detalle'!M16 | F16: =IF(E16<0,"Activo (anticipo)",IF('03_Detalle'!P16="Sí","No corriente","Corriente")) | G16: =IF(F16="Corriente",E16,0) | H16: ='03_Detalle'!Q16 | I16: ='03_Detalle'!R16 | J16: =IF('03_Detalle'!S16="","",'03_Detalle'!S16) | K16: =IF(J16="No",12*365/12,MAX(12,'02_Parametros'!$B$9)*365/12)
A17: TOTAL | E17: =SUM(E5:E16) | G17: =SUM(G5:G16) | H17: =SUM(H5:H16) | I17: =SUM(I5:I16)
A19: ⓘ Cómo se calcula esta hoja
A20: Columna | B20: Fórmula (Excel) | C20: Cómo se calcula (sencillo) | D20: Ejemplo con números reales | E20: De dónde viene | F20: Norma
A21: Días por vencer | B21: '='03_Detalle'!O5 | C21: Trae de la hoja 03 (Detalle por documento) los días que faltan desde el corte hasta el vencimiento. | D21: Fila 1: 4 → 4 | E21: hoja «Detalle por documento» | F21: —
A22: Costo amortizado | B22: '='03_Detalle'!M5 | C22: Trae de la hoja 03 (Detalle por documento) el costo amortizado del documento. | D22: Fila 1: 15.000,00 → 15.000,00 | E22: hoja «Detalle por documento» | F22: —
A23: Clasificación requerida | B23: '=IF(E5<0,"Activo (anticipo)",IF('03_Detalle'!P5="Sí","No corriente","Corriente")) | C23: «Activo (anticipo)» si el costo amortizado es negativo; «No corriente» si en la hoja 03 el documento quedó marcado como no corriente; si no, «Corriente». | D23: Fila 1: IF(15.000,00<0; "Activo (anticipo)"; IF(«No»="Sí"; "No corriente"; "Corriente")) → Corriente | E23: «Costo amortizado» (esta hoja), hoja «Detalle por documento» | F23: —
A24: Corriente | B24: '=IF(F5="Corriente",E5,0) | C24: Si la clasificación requerida es «Corriente», toma el costo amortizado del documento; en otro caso, cero. | D24: Fila 1: IF(«Corriente»="Corriente"; 15.000,00; 0) → 15.000,00 | E24: «Clasificación requerida» (esta hoja), «Costo amortizado» (esta hoja) | F24: —
A25: No corriente | B25: '='03_Detalle'!Q5 | C25: Trae de la hoja 03 (Detalle por documento) el importe no corriente del documento (su costo amortizado si vence después del límite). | D25: Fila 1: 0,00 → 0,00 | E25: hoja «Detalle por documento» | F25: —
A26: Saldo deudor (activo) | B26: '='03_Detalle'!R5 | C26: Trae de la hoja 03 (Detalle por documento) el saldo deudor en positivo, que se reclasifica al activo. | D26: Fila 1: 0,00 → 0,00 | E26: hoja «Detalle por documento» | F26: —
A27: Partida de explotación | B27: '=IF('03_Detalle'!S5="","",'03_Detalle'!S5) | C27: Copia de la hoja 03 si el documento es una partida de explotación (sí/no); en blanco si no se informó. | D27: Fila 1: IF(«Sí»=""; ""; «Sí») → Sí | E27: hoja «Detalle por documento» | F27: —
A28: Límite aplicado (días) | B28: '=IF(J5="No",12*365/12,MAX(12,'02_Parametros'!$B$9)*365/12) | C28: Días a partir de los cuales el documento es no corriente: 365 si no es partida de explotación; si lo es o no se informó, el mayor entre 12 meses y el ciclo de operación (hoja 02), en días. | D28: Fila 1: IF(«Sí»="No"; 12*365/12; MAX(12; 12,00)*365/12) → 365 | E28: «Partida de explotación» (esta hoja), hoja «Parámetros» | F28: —

Sheet 11_Ajuste
A1: Saldo auditado y ajustes | H1: ⟵ Inicio | I1: ◀ Anterior | J1: Siguiente ▶
A2: Proveedores y cuentas por pagar · Cliente de muestra S.A. · corte 2025-12-31
A4: Concepto | B4: Importe | C4: Referencia
A5: Proveedores según auxiliar (nominal) | B5: =SUM('03_Detalle'!$F$5:$F$16) | C5: 03_Detalle
A6: (-) Intereses implícitos por devengar registrados | B6: ='02_Parametros'!$B$10 | C6: Parámetros (mayor)
A7: Saldo en libros neto | B7: =B5-B6
A8: (+) Pasivos no registrados | B8: ='06_Pasivos_no_registrados'!I13 | C8: 06_Pasivos_no_registrados · NIIF 9 3.1.1 y B3.1.2 b) / PYMES 11.12; NIA 500
A9: (-) Compras registradas antes de la recepción | B9: ='08_Corte_compras'!G11 | C9: 08_Corte_compras
A10: Intereses implícitos por devengar requeridos | B10: =SUM('03_Detalle'!$N$5:$N$16) | C10: NIIF 9 5.1.1, B5.1.1
A11: (-) Ajuste por financiación implícita | B11: =B10-B6 | C11: Requerido − registrado
A12: (+) Saldos deudores reclasificados al activo | B12: =SUM('03_Detalle'!$R$5:$R$16) | C12: Anticipos: no se compensan (NIC 1.32); NIC 32.42 solo para notas de crédito
A13: Saldo de proveedores auditado | B13: =B7+B8-B9-B11+B12
A14: Ajuste neto propuesto a proveedores | B14: =B13-B7 | C14: Positivo: aumenta el pasivo
A15: Porción no corriente requerida | B15: =SUM('03_Detalle'!$Q$5:$Q$16) | C15: NIC 1 69–70 (NIIF 18 párr. 101 y B96 desde 2027)
A16: Porción no corriente presentada | B16: ='02_Parametros'!$B$11 | C16: Parámetros
A17: Reclasificación a no corriente | B17: =B15-B16 | C17: Positivo: pasar de corriente a no corriente
A18: Saldo según el mayor | B18: =IF('02_Parametros'!$B$12<>"",'02_Parametros'!$B$12,"") | C18: Parámetros
A19: Diferencia auxiliar − mayor | B19: =IF(B18="","",B5-B18) | C19: NIA 500
A20: Diferencias de confirmación (absolutas) | B20: ='07_Confirmaciones'!F8 | C20: NIA 505
A21: Pagos posteriores mayores al saldo | B21: ='05_Pagos_posteriores'!I17 | C21: 05_Pagos_posteriores
A22: Saldos con partes relacionadas | B22: =SUMIF('03_Detalle'!$G$5:$G$16,"Sí",'03_Detalle'!$F$5:$F$16) | C22: NIC 24 párr. 18
A24: ⓘ Cómo se calcula esta hoja
A25: Columna | B25: Fórmula (Excel) | C25: Cómo se calcula (sencillo) | D25: Ejemplo con números reales | E25: De dónde viene | F25: Norma
A26: Importe | B26: '=SUM('03_Detalle'!$F$5:$F$16) | C26: Cada fila tiene su propia fórmula: suma columnas de la hoja 03 (saldo, interés por devengar, no corriente, saldos deudores, relacionadas), trae los totales de las hojas 05 a 08 o valores de la hoja 02, y arma el saldo auditado: libros netos + omitidos − compras anticipadas − ajuste por financiación + saldos deudores. | D26: Fila 1: SUM([«Saldo» de «Detalle por documento», 12 filas]) → 80.300,00 | E26: hoja «Detalle por documento» | F26: —

Sheet 12_Asientos
A1: Asientos propuestos | H1: ⟵ Inicio | I1: ◀ Anterior | J1: Siguiente ▶
A2: Proveedores y cuentas por pagar · Cliente de muestra S.A. · corte 2025-12-31
A4: Asiento | B4: Cuenta | C4: Debe | D4: Haber
A5: 1 · Pasivos no registrados | B5: Inventarios / costos y gastos (bienes y servicios recibidos al corte) | C5: ='11_Ajuste'!B8
B6: Proveedores | D6: ='11_Ajuste'!B8
A7: 2 · Compras registradas antes de la recepción | B7: Proveedores | C7: ='11_Ajuste'!B9
