Workbook

Sheet 00_Inicio
B2: AuditConsulting Auditores Cía. Ltda. · AUDIT-IA
B4: Cobertura de seguros de activos
B6: Cliente | C6: Cliente de muestra S.A. | D6: RUC | E6: 1790000000001
B7: Marco contable | C7: NIIF completas | D7: Fecha de corte | E7: 2025-12-31
B8: Preparó | C8: Ejercicio modelo | D8: Revisó | E8: Pendiente
B10: INDICADORES CLAVE
B11: Ajuste propuesto en resultados (prima anticipada) | C11: Problemas encontrados
B12: -1600 | C12: 21
B15: IR A LA CÉDULA
B16: Carátula | C16: Programa | D16: Base técnica | E16: Resumen
B17: Parámetros | C17: Activos asegurables (datos del cliente) | D17: Pólizas (datos del cliente) | E17: Vigencia de pólizas al corte
B18: Universo y cobertura por activo | C18: Cobertura por póliza (infraseguro) | D18: Deducibles y exposición máxima | E18: Activos sin cobertura
B19: Prima pagada por anticipado | C19: Siniestros pendientes y revelación | D19: Indicadores y conclusión | E19: Ajustes propuestos y conciliación
B20: Problemas encontrados | C20: Conclusión | D20: Control de revisión
B22: PANORAMA | N22: Datos de los gráficos (fórmulas a las cédulas)
N23: Cifras del resumen | O23: Importe (USD)
N24: ='01_Resumen'!A5 | O24: ='01_Resumen'!B5
N25: ='01_Resumen'!A6 | O25: ='01_Resumen'!B6
N26: ='01_Resumen'!A8 | O26: ='01_Resumen'!B8
N27: ='01_Resumen'!A9 | O27: ='01_Resumen'!B9
N28: ='01_Resumen'!A10 | O28: ='01_Resumen'!B10
N29: ='01_Resumen'!A11 | O29: ='01_Resumen'!B11
N30: ='01_Resumen'!A12 | O30: ='01_Resumen'!B12
N31: ='01_Resumen'!A13 | O31: ='01_Resumen'!B13
N32: ='01_Resumen'!A14 | O32: ='01_Resumen'!B14
N33: ='01_Resumen'!A15 | O33: ='01_Resumen'!B15
N34: ='01_Resumen'!A16 | O34: ='01_Resumen'!B16
N35: ='01_Resumen'!A17 | O35: ='01_Resumen'!B17
N36: ='01_Resumen'!A18 | O36: ='01_Resumen'!B18
N38: Hallazgos de mayor impacto | O38: Importe (USD)
N39: Infraseguro (×3) | O39: =SUMIFS('14_Problemas'!$C$5:$C$25,'14_Problemas'!$A$5:$A$25,"INFRASEGURO",'14_Problemas'!$C$5:$C$25,">0")-SUMIFS('14_Problemas'!$C$5:$C$25,'14_Problemas'!$A$5:$A$25,"INFRASEGURO",'14_Problemas'!$C$5:$C$25,"<0")
N40: Infraseguro poliza | O40: =SUMIFS('14_Problemas'!$C$5:$C$25,'14_Problemas'!$A$5:$A$25,"INFRASEGURO_POLIZA",'14_Problemas'!$C$5:$C$25,">0")-SUMIFS('14_Problemas'!$C$5:$C$25,'14_Problemas'!$A$5:$A$25,"INFRASEGURO_POLIZA",'14_Problemas'!$C$5:$C$25,"<0")
N41: Activo sin cobertura (×5) | O41: =SUMIFS('14_Problemas'!$C$5:$C$25,'14_Problemas'!$A$5:$A$25,"ACTIVO_SIN_COBERTURA",'14_Problemas'!$C$5:$C$25,">0")-SUMIFS('14_Problemas'!$C$5:$C$25,'14_Problemas'!$A$5:$A$25,"ACTIVO_SIN_COBERTURA",'14_Problemas'!$C$5:$C$25,"<0")
N42: Poliza por vencer | O42: =SUMIFS('14_Problemas'!$C$5:$C$25,'14_Problemas'!$A$5:$A$25,"POLIZA_POR_VENCER",'14_Problemas'!$C$5:$C$25,">0")-SUMIFS('14_Problemas'!$C$5:$C$25,'14_Problemas'!$A$5:$A$25,"POLIZA_POR_VENCER",'14_Problemas'!$C$5:$C$25,"<0")
N43: Exposicion maxima | O43: =SUMIFS('14_Problemas'!$C$5:$C$25,'14_Problemas'!$A$5:$A$25,"EXPOSICION_MAXIMA",'14_Problemas'!$C$5:$C$25,">0")-SUMIFS('14_Problemas'!$C$5:$C$25,'14_Problemas'!$A$5:$A$25,"EXPOSICION_MAXIMA",'14_Problemas'!$C$5:$C$25,"<0")
N44: Poliza no iniciada | O44: =SUMIFS('14_Problemas'!$C$5:$C$25,'14_Problemas'!$A$5:$A$25,"POLIZA_NO_INICIADA",'14_Problemas'!$C$5:$C$25,">0")-SUMIFS('14_Problemas'!$C$5:$C$25,'14_Problemas'!$A$5:$A$25,"POLIZA_NO_INICIADA",'14_Problemas'!$C$5:$C$25,"<0")
N45: Poliza vencida | O45: =SUMIFS('14_Problemas'!$C$5:$C$25,'14_Problemas'!$A$5:$A$25,"POLIZA_VENCIDA",'14_Problemas'!$C$5:$C$25,">0")-SUMIFS('14_Problemas'!$C$5:$C$25,'14_Problemas'!$A$5:$A$25,"POLIZA_VENCIDA",'14_Problemas'!$C$5:$C$25,"<0")
N46: Otros (6 tipos) | O46: =SUMIF('14_Problemas'!$C$5:$C$25,">0")-SUMIF('14_Problemas'!$C$5:$C$25,"<0")-((SUMIFS('14_Problemas'!$C$5:$C$25,'14_Problemas'!$A$5:$A$25,"INFRASEGURO",'14_Problemas'!$C$5:$C$25,">0")-SUMIFS('14_Problemas'!$C$5:$C$25,'14_Problemas'!$A$5:$A$25,"INFRASEGURO",'14_Problemas'!$C$5:$C$25,"<0"))+(SUMIFS('14_Problemas'!$C$5:$C$25,'14_Problemas'!$A$5:$A$25,"INFRASEGURO_POLIZA",'14_Problemas'!$C$5:$C$25,">0")-SUMIFS('14_Problemas'!$C$5:$C$25,'14_Problemas'!$A$5:$A$25,"INFRASEGURO_POLIZA",'14_Problemas'!$C$5:$C$25,"<0"))+(SUMIFS('14_Problemas'!$C$5:$C$25,'14_Problemas'!$A$5:$A$25,"ACTIVO_SIN_COBERTURA",'14_Problemas'!$C$5:$C$25,">0")-SUMIFS('14_Problemas'!$C$5:$C$25,'14_Problemas'!$A$5:$A$25,"ACTIVO_SIN_COBERTURA",'14_Problemas'!$C$5:$C$25,"<0"))+(SUMIFS('14_Problemas'!$C$5:$C$25,'14_Problemas'!$A$5:$A$25,"POLIZA_POR_VENCER",'14_Problemas'!$C$5:$C$25,">0")-SUMIFS('14_Problemas'!$C$5:$C$25,'14_Problemas'!$A$5:$A$25,"POLIZA_POR_VENCER",'14_Problemas'!$C$5:$C$25,"<0"))+(SUMIFS('14_Problemas'!$C$5:$C$25,'14_Problemas'!$A$5:$A$25,"EXPOSICION_MAXIMA",'14_Problemas'!$C$5:$C$25,">0")-SUMIFS('14_Problemas'!$C$5:$C$25,'14_Problemas'!$A$5:$A$25,"EXPOSICION_MAXIMA",'14_Problemas'!$C$5:$C$25,"<0"))+(SUMIFS('14_Problemas'!$C$5:$C$25,'14_Problemas'!$A$5:$A$25,"POLIZA_NO_INICIADA",'14_Problemas'!$C$5:$C$25,">0")-SUMIFS('14_Problemas'!$C$5:$C$25,'14_Problemas'!$A$5:$A$25,"POLIZA_NO_INICIADA",'14_Problemas'!$C$5:$C$25,"<0"))+(SUMIFS('14_Problemas'!$C$5:$C$25,'14_Problemas'!$A$5:$A$25,"POLIZA_VENCIDA",'14_Problemas'!$C$5:$C$25,">0")-SUMIFS('14_Problemas'!$C$5:$C$25,'14_Problemas'!$A$5:$A$25,"POLIZA_VENCIDA",'14_Problemas'!$C$5:$C$25,"<0")))

Sheet 00_Caratula
A1: Carátula | H1: ⟵ Inicio | J1: Siguiente ▶
A2: Cobertura de seguros de activos · Cliente de muestra S.A. · corte 2025-12-31
A4: Concepto | B4: Detalle
A5: Firma | B5: AuditConsulting Auditores Cía. Ltda.
A6: Cliente | B6: Cliente de muestra S.A.
A7: RUC | B7: 1790000000001
A8: Ejercicio | B8: 2025
A9: Fecha de corte | B9: 2025-12-31
A10: Marco contable | B10: NIIF completas
A11: Herramienta | B11: Cobertura de seguros de activos
A12: Rubro | B12: Seguros
A13: Motor | B13: seguros_cobertura 1.0
A14: Versión del papel | B14: v1
A15: Estado | B15: MUESTRA
... A17: Revisó | B17: Pendiente
A18: Aprobó
A19: Fecha de aprobación
A20: Huella de la ejecución (SHA-256)

Sheet 00_Programa
A1: Programa | H1: ⟵ Inicio | I1: ◀ Anterior | J1: Siguiente ▶
A2: Cobertura de seguros de activos · Cliente de muestra S.A. · corte 2025-12-31
A4: Código | B4: Objetivo | C4: Afirmación | D4: Procedimiento | E4: Evidencia | F4: Criterio | G4: Referencia
A5: INS-01 | B5: Universo de activos vs pólizas | C5: Integridad (riesgo) | D5: Cruzar el maestro de activos con el detalle de pólizas | E5: Maestro de activos, pólizas y endosos | F5: Todo activo significativo con póliza vigente | G5: NIA 315 · NIA 330
A6: INS-02 | B6: Vigencia | C6: Riesgo operativo | D6: Comparar la vigencia de cada póliza con la fecha de corte y alertar las próximas a vencer | E6: Pólizas y renovaciones | F6: Póliza vigente al corte | G6: NIA 330 · NIA 570
A7: INS-03 | B7: Suma asegurada e infraseguro | C7: Riesgo de pérdida | D7: Calcular el % de cobertura por activo y por póliza y aplicar la regla proporcional | E7: Tasaciones, valores de reposición | F7: Cobertura ≥ mínimo definido | G7: Especificación MÓDULO 09 · NIA 315
A8: INS-04 | B8: Sobreseguro y deducibles | C8: Riesgo | D8: Identificar sumas sobre el valor real y calcular el deducible ante pérdida total | E8: Condiciones particulares de la póliza | F8: Sumas razonables frente al valor asegurable | G8: Especificación MÓDULO 09
A9: INS-05 | B9: Exposición máxima | C9: Continuidad operativa | D9: Determinar la mayor pérdida total no cubierta y evaluar su efecto | E9: Cédula de exposición | F9: Exposición informada al encargado del gobierno | G9: NIA 570 párr. 25 · NIA 260 párr. 16
A10: INS-06 | B10: Prima pagada por anticipado | C10: Valoración / Corte | D10: Recalcular la prima por devengar al corte y conciliar con el mayor | E10: Pólizas, facturas de prima, mayor | F10: Diferencia dentro de tolerancia | G10: NIC 1.27–28 · PYMES 2.36 (2015) / 3.16A (2025)
A11: INS-07 | B11: Siniestros pendientes: tratamiento y revelación | C11: Presentación y revelación | D11: Clasificar cada siniestro (daño a activo propio o reclamo de terceros), verificar si el cobro es exigible al corte y revisar su revelación | E11: Reclamos, cartas de la aseguradora, liquidaciones de siniestro, notas | F11: Daño a activo propio: compensación en resultados cuando es exigible (NIC 16.65–66 / PYMES 17.25), separada del deterioro (NIC 36.12 e); si no es exigible, activo contingente. Reclamo de terceros: reembolso solo si es prácticamente seguro (NIC 37.53) | G11: NIC 16.65–66 · NIC 36.12 e) · NIC 37.31–35, 53, 86, 89 · PYMES 17.25 y 21 · NIA 501 · NIA 560

Sheet 00_Fuentes
A1: Base técnica | H1: ⟵ Inicio | I1: ◀ Anterior | J1: Siguiente ▶
A2: Cobertura de seguros de activos · Cliente de muestra S.A. · corte 2025-12-31
A4: Categoría | B4: Documento | C4: Párrafos | D4: URL | E4: Verificada
A5: NIA · NIA 315 (Revisada 2019) | B5: Entender el entorno y los riesgos: pérdida de activos no asegurados como factor de riesgo. | C5: párr. 19 y 28
A6: NIA · NIA 330 | B6: Respuestas a los riesgos valorados; evidencia sobre la cobertura. | C6: párr. 6 y 18
A7: NIA · NIA 570 (Revisada) | B7: Empresa en marcha: pérdida no asegurada de activos clave. La NIA 570 (Revisada 2024) rige para períodos desde el 15-12-2026. | C7: párr. 10–16
A8: NIA · NIA 500 | B8: Exactitud e integridad del maestro de activos y del detalle de pólizas. | C8: párr. 9
A9: NIA · NIA 501 / NIA 560 | B9: Litigios y reclamaciones (siniestros) y hechos posteriores al cierre. | C9: NIA 501 párr. 9 / NIA 560 párr. 6

Sheet 01_Resumen
A1: Resumen | H1: ⟵ Inicio | I1: ◀ Anterior | J1: Siguiente ▶
A2: Cobertura de seguros de activos · Cliente de muestra S.A. · corte 2025-12-31
A4: Concepto | B4: Importe
A5: Valor de referencia de los activos | B5: ='12_Conclusion'!B5
A6: Suma asegurada vigente al corte | B6: ='12_Conclusion'!B6
A7: Cobertura global (%) | B7: ='12_Conclusion'!C7*100
A8: Déficit de cobertura (exposición no asegurada) | B8: ='12_Conclusion'!B8
A9: Activos sin cobertura: valor en libros | B9: ='12_Conclusion'!B9
A10: Activos sin cobertura: valor de referencia | B10: ='12_Conclusion'!B10
A11: Sobreseguro (suma sobre el valor de referencia) | B11: ='12_Conclusion'!B12
A12: Exposición máxima (pérdida total no cubierta del activo mayor) | B12: ='12_Conclusion'!B13
A13: Siniestros pendientes sin revelación | B13: ='12_Conclusion'!B16
A14: Compensaciones de seguro exigibles a reconocer en resultados | B14: ='12_Conclusion'!B17
A15: Prima pagada por anticipado registrada | B15: ='13_Ajustes'!B5
A16: Prima pagada por anticipado recalculada | B16: ='13_Ajustes'!B6
A17: Diferencia detalle − mayor (prima anticipada) | B17: ='13_Ajustes'!B10
A18: Ajuste propuesto en resultados (prima anticipada) | B18: ='13_Ajustes'!B8
A20: ⓘ Cómo se calcula esta hoja
A21: Columna | B21: Fórmula (Excel) | C21: Cómo se calcula (sencillo) | D21: Ejemplo con números reales | E21: De dónde viene | F21: Norma
A22: Importe | B22: '='12_Conclusion'!B5 | C22: Trae cada importe de la hoja que lo calcula, concepto por concepto: los indicadores de cobertura, siniestros y exposición salen de la hoja 12 (Indicadores y conclusión) y los de prima anticipada y el ajuste, de la hoja 13 (Ajustes propuestos y conciliación). La cobertura global se muestra multiplicada por 100 (en %). | D22: Fila 1: 1.499.000,00 → 1.499.000,00 | E22: hoja «Indicadores y conclusión» | F22: —

Sheet 02_Parametros
A1: Parámetros | H1: ⟵ Inicio | I1: ◀ Anterior | J1: Siguiente ▶
A2: Cobertura de seguros de activos · Cliente de muestra S.A. · corte 2025-12-31
A4: Parámetro | B4: Valor | C4: Sustento
A5: Corte del ejercicio | B5: 46022 | C5: Ficha del encargo
A6: Marco contable | B6: NIIF completas | C6: Mismo tratamiento en NIIF completas y PYMES: prueba de riesgo, no medición NIIF
A7: Edición PYMES | C7: 2025: devengo en 3.16A (antes 2.36); la tercera edición rige desde el 1-1-2027
A8: Cobertura mínima (%) | B8: 80 | C8: Juicio del auditor / política de seguros de la entidad
A9: Sobreseguro desde (%) | B9: 120 | C9: Juicio del auditor
A10: Alerta por vencer (días) | B10: 30 | C10: Juicio del auditor
A11: Tolerancia (importe) | B11: 1 | C11: Materialidad de ejecución
A12: Mayor: seguros pagados por anticipado | B12: 8000 | C12: Mayor contable

Sheet 03_Activos
A1: Activos asegurables (datos del cliente) | H1: ⟵ Inicio | I1: ◀ Anterior | J1: Siguiente ▶
A2: Cobertura de seguros de activos · Cliente de muestra S.A. · corte 2025-12-31
A4: Código | B4: Descripción | C4: Clase | D4: Valor en libros | E4: Valor de referencia | F4: Póliza | G4: Suma asignada | H4: Deducible %
A5: EDIF-01 | B5: Edificio administrativo | C5: Edificios | D5: 437500 | E5: 650000 | F5: POL-01 | H5: 2
A6: BOD-01 | B6: Bodega central | C6: Edificios | D6: 180000 | E6: 300000 | F6: POL-01 | H6: 2
A7: MAQ-01 | B7: Línea de envasado | C7: Maquinaria | D7: 40000 | E7: 160000 | F7: POL-04 | G7: 160000 | H7: 10
A8: MAQ-02 | B8: Compresor industrial | C8: Maquinaria | D8: 25000 | E8: 60000 | F8: POL-04 | G8: 40000 | H8: 10
A9: VEH-01 | B9: Camioneta 4x4 | C9: Vehículos | D9: 21600 | E9: 35000 | F9: POL-02 | G9: 35000 | H9: 5
A10: VEH-02 | B10: Camión de reparto | C10: Vehículos | D10: 60000 | E10: 70000 | F10: POL-02 | G10: 95000 | H10: 5
A11: VEH-03 | B11: Furgoneta | C11: Vehículos | D11: 12000 | F11: POL-02 | G11: 20000 | H11: 5
A12: EQC-01 | B12: Servidores | C12: Equipo de cómputo | D12: 10000 | E12: 30000 | F12: POL-03 | G12: 30000
A13: EQC-02 | B13: Computadores portátiles | C13: Equipo de cómputo | D13: 6000 | E13: 12000 | F13: POL-03 | G13: 10000
A14: BOD-02 | B14: Bodega norte | C14: Edificios | D14: 90000 | E14: 110000 | F14: POL-05 | G14: 80000
A15: MOB-01 | B15: Mobiliario de oficinas | C15: Muebles y enseres | D15: 8000 | E15: 15000
A16: GEN-01 | B16: Generador eléctrico | C16: Maquinaria | D16: 15000 | E16: 45000 | F16: POL-09 | G16: 45000
A17: TOTAL | D17: =SUM(D5:D16)

Sheet 04_Polizas
A1: Pólizas (datos del cliente) | H1: ⟵ Inicio | I1: ◀ Anterior | J1: Siguiente ▶
A2: Cobertura de seguros de activos · Cliente de muestra S.A. · corte 2025-12-31
A4: Póliza | B4: Aseguradora | C4: Ramo | D4: Vigencia desde | E4: Vigencia hasta | F4: Suma asegurada total | G4: Prima total | H4: Prima anticipada registrada | I4: Siniestro pendiente | J4: Monto del siniestro | K4: Revelado | L4: Tipo de siniestro | M4: Cobro exigible
A5: POL-01 | B5: Aseguradora Alfa S.A. | C5: Incendio y líneas aliadas | D5: 45839 | E5: 46204 | F5: 700000 | G5: 7300 | H5: 3640
A6: POL-02 | B6: Aseguradora Beta S.A. | C6: Vehículos | D6: 45717 | E6: 46082 | F6: 150000 | G6: 5475 | H6: 2500 | I6: Choque del camión VEH-02 | J6: 18000 | K6: No | L6: Daño a activo propio | M6: Sí
A7: POL-03 | B7: Aseguradora Gamma S.A. | C7: Equipo electrónico | D7: 45641 | E7: 46006 | F7: 40000 | G7: 1200 | H7: 0
A8: POL-04 | B8: Aseguradora Alfa S.A. | C8: Rotura de maquinaria | D8: 45677 | E8: 46042 | F8: 200000 | G8: 3650 | H8: 200 | I8: Daño en compresor | J8: 5000 | K8: Sí | L8: Daño a activo propio | M8: No
A9: POL-05 | B9: Aseguradora Beta S.A. | C9: Incendio bodega norte | D9: 46037 | E9: 46402 | F9: 80000 | G9: 1460 | H9: 1460

Sheet 05_Vigencia
A1: Vigencia de pólizas al corte | H1: ⟵ Inicio | I1: ◀ Anterior | J1: Siguiente ▶
A2: Cobertura de seguros de activos · Cliente de muestra S.A. · corte 2025-12-31
A4: Póliza | B4: Desde | C4: Hasta | D4: Días de vigencia | E4: Estado al corte | F4: Días por vencer | G4: Alerta
A5: POL-01 | B5: 45839 | C5: 46204 | D5: ='04_Polizas'!E5-'04_Polizas'!D5 | E5: =IF('04_Polizas'!E5<'02_Parametros'!$B$5,"Vencida",IF('04_Polizas'!D5>'02_Parametros'!$B$5,"No iniciada","Vigente")) | F5: =IF(E5="Vigente",'04_Polizas'!E5-'02_Parametros'!$B$5,"") | G5: =IF(F5="","",IF(F5<='02_Parametros'!$B$10,"Por vencer",""))
A6: POL-02 | B6: 45717 | C6: 46082 | D6: ='04_Polizas'!E6-'04_Polizas'!D6 | E6: =IF('04_Polizas'!E6<'02_Parametros'!$B$5,"Vencida",IF('04_Polizas'!D6>'02_Parametros'!$B$5,"No iniciada","Vigente")) | F6: =IF(E6="Vigente",'04_Polizas'!E6-'02_Parametros'!$B$5,"") | G6: =IF(F6="","",IF(F6<='02_Parametros'!$B$10,"Por vencer",""))
A7: POL-03 | B7: 45641 | C7: 46006 | D7: ='04_Polizas'!E7-'04_Polizas'!D7 | E7: =IF('04_Polizas'!E7<'02_Parametros'!$B$5,"Vencida",IF('04_Polizas'!D7>'02_Parametros'!$B$5,"No iniciada","Vigente")) | F7: =IF(E7="Vigente",'04_Polizas'!E7-'02_Parametros'!$B$5,"") | G7: =IF(F7="","",IF(F7<='02_Parametros'!$B$10,"Por vencer",""))
A8: POL-04 | B8: 45677 | C8: 46042 | D8: ='04_Polizas'!E8-'04_Polizas'!D8 | E8: =IF('04_Polizas'!E8<'02_Parametros'!$B$5,"Vencida",IF('04_Polizas'!D8>'02_Parametros'!$B$5,"No iniciada","Vigente")) | F8: =IF(E8="Vigente",'04_Polizas'!E8-'02_Parametros'!$B$5,"") | G8: =IF(F8="","",IF(F8<='02_Parametros'!$B$10,"Por vencer",""))
A9: POL-05 | B9: 46037 | C9: 46402 | D9: ='04_Polizas'!E9-'04_Polizas'!D9 | E9: =IF('04_Polizas'!E9<'02_Parametros'!$B$5,"Vencida",IF('04_Polizas'!D9>'02_Parametros'!$B$5,"No iniciada","Vigente")) | F9: =IF(E9="Vigente",'04_Polizas'!E9-'02_Parametros'!$B$5,"") | G9: =IF(F9="","",IF(F9<='02_Parametros'!$B$10,"Por vencer",""))
A11: ⓘ Cómo se calcula esta hoja
A12: Columna | B12: Fórmula (Excel) | C12: Cómo se calcula (sencillo) | D12: Ejemplo con números reales | E12: De dónde viene | F12: Norma
A13: Días de vigencia | B13: '='04_Polizas'!E5-'04_Polizas'!D5 | C13: Resta la fecha «desde» a la fecha «hasta» de la póliza en la hoja 04 (Pólizas): son los días que dura la cobertura. | D13: Fila 1: «2026-07-01»-«2025-07-01» → 365 | E13: hoja «Pólizas (datos del cliente)» | F13: —
A14: Estado al corte | B14: '=IF('04_Polizas'!E5<'02_Parametros'!$B$5,"Vencida",IF('04_Polizas'!D5>'02_Parametros'!$B$5,"No iniciada","Vigente")) | C14: Compara las fechas de la hoja 04 (Pólizas) con el corte de la hoja 02 (Parámetros): «Vencida» si terminó antes del corte, «No iniciada» si empieza después y «Vigente» en los demás casos. | D14: Fila 1: IF(«2026-07-01»<«2025-12-31»; "Vencida"; IF(«2025-07-01»>«2025-12-31»; "No iniciada"; "Vigente")) → Vigente | E14: hoja «Pólizas (datos del cliente)», hoja «Parámetros» | F14: —
A15: Días por vencer | B15: '=IF(E5="Vigente",'04_Polizas'!E5-'02_Parametros'!$B$5,"") | C15: Solo para pólizas vigentes, resta la fecha de corte a la fecha «hasta» de la hoja 04 (Pólizas); en las demás queda en blanco. | D15: Fila 1: IF(«Vigente»="Vigente"; «2026-07-01»-«2025-12-31»; "") → 182 | E15: «Estado al corte» (esta hoja), hoja «Pólizas (datos del cliente)», hoja «Parámetros» | F15: —
A16: Alerta | B16: '=IF(F5="","",IF(F5<='02_Parametros'!$B$10,"Por vencer","")) | C16: Marca «Por vencer» cuando los días por vencer no superan el umbral de alerta de la hoja 02 (Parámetros); si la póliza no está vigente o vence más tarde, queda en blanco. | D16: Fila 1: IF(182=""; ""; IF(182<=30,00; "Por vencer"; "")) → (en blanco) | E16: «Días por vencer» (esta hoja), hoja «Parámetros» | F16: —

Sheet 06_Cobertura_activo
A1: Universo y cobertura por activo | H1: ⟵ Inicio | I1: ◀ Anterior | J1: Siguiente ▶
A2: Cobertura de seguros de activos · Cliente de muestra S.A. · corte 2025-12-31
A4: Código | B4: Póliza | C4: Valor de referencia | D4: Base de referencia | E4: Estado de la póliza | F4: Suma asegurada asignada | G4: Suma asegurada vigente | H4: % cobertura | I4: Déficit | J4: Exceso | K4: Clasificación
A5: EDIF-01 | B5: POL-01 | C5: =IF('03_Activos'!E5<>"",'03_Activos'!E5,'03_Activos'!D5) | D5: =IF('03_Activos'!E5<>"","Reposición/tasación","Valor en libros") | E5: =IF('03_Activos'!F5="","Sin póliza",IF(ISNA(MATCH('03_Activos'!F5,'04_Polizas'!$A$5:$A$9,0)),"Póliza no encontrada",INDEX('05_Vigencia'!$E$5:$E$9,MATCH('03_Activos'!F5,'04_Polizas'!$A$5:$A$9,0)))) | F5: =IF(OR(E5="Sin póliza",E5="Póliza no encontrada"),0,IF('03_Activos'!G5<>"",'03_Activos'!G5,IF(SUMIF('03_Activos'!$F$5:$F$16,'03_Activos'!F5,'06_Cobertura_activo'!$C$5:$C$16)=0,0,INDEX('04_Polizas'!$F$5:$F$9,MATCH('03_Activos'!F5,'04_Polizas'!$A$5:$A$9,0))*C5/SUMIF('03_Activos'!$F$5:$F$16,'03_Activos'!F5,'06_Cobertura_activo'!$C$5:$C$16)))) | G5: =IF(E5="Vigente",F5,0) | H5: =IF(C5=0,"",G5/C5) | I5: =MAX(C5-G5,0) | J5: =MAX(G5-C5,0) | K5: =IF(G5=0,"Sin cobertura",IF(H5="","",IF(H5<'02_Parametros'!$B$8/100,"Infraseguro",IF(H5>'02_Parametros'!$B$9/100,"Sobreseguro","Adecuada"))))
A6: BOD-01 | B6: POL-01 | C6: =IF('03_Activos'!E6<>"",'03_Activos'!E6,'03_Activos'!D6) | D6: =IF('03_Activos'!E6<>"","Reposición/tasación","Valor en libros") | E6: =IF('03_Activos'!F6="","Sin póliza",IF(ISNA(MATCH('03_Activos'!F6,'04_Polizas'!$A$5:$A$9,0)),"Póliza no encontrada",INDEX('05_Vigencia'!$E$5:$E$9,MATCH('03_Activos'!F6,'04_Polizas'!$A$5:$A$9,0)))) | F6: =IF(OR(E6="Sin póliza",E6="Póliza no encontrada"),0,IF('03_Activos'!G6<>"",'03_Activos'!G6,IF(SUMIF('03_Activos'!$F$5:$F$16,'03_Activos'!F6,'06_Cobertura_activo'!$C$5:$C$16)=0,0,INDEX('04_Polizas'!$F$5:$F$9,MATCH('03_Activos'!F6,'04_Polizas'!$A$5:$A$9,0))*C6/SUMIF('03_Activos'!$F$5:$F$16,'03_Activos'!F6,'06_Cobertura_activo'!$C$5:$C$16)))) | G6: =IF(E6="Vigente",F6,0) | H6: =IF(C6=0,"",G6/C6) | I6: =MAX(C6-G6,0) | J6: =MAX(G6-C6,0) | K6: =IF(G6=0,"Sin cobertura",IF(H6="","",IF(H6<'02_Parametros'!$B$8/100,"Infraseguro",IF(H6>'02_Parametros'!$B$9/100,"Sobreseguro","Adecuada"))))
A7: MAQ-01 | B7: POL-04 | C7: =IF('03_Activos'!E7<>"",'03_Activos'!E7,'03_Activos'!D7) | D7: =IF('03_Activos'!E7<>"","Reposición/tasación","Valor en libros") | E7: =IF('03_Activos'!F7="","Sin póliza",IF(ISNA(MATCH('03_Activos'!F7,'04_Polizas'!$A$5:$A$9,0)),"Póliza no encontrada",INDEX('05_Vigencia'!$E$5:$E$9,MATCH('03_Activos'!F7,'04_Polizas'!$A$5:$A$9,0)))) | F7: =IF(OR(E7="Sin póliza",E7="Póliza no encontrada"),0,IF('03_Activos'!G7<>"",'03_Activos'!G7,IF(SUMIF('03_Activos'!$F$5:$F$16,'03_Activos'!F7,'06_Cobertura_activo'!$C$5:$C$16)=0,0,INDEX('04_Polizas'!$F$5:$F$9,MATCH('03_Activos'!F7,'04_Polizas'!$A$5:$A$9,0))*C7/SUMIF('03_Activos'!$F$5:$F$16,'03_Activos'!F7,'06_Cobertura_activo'!$C$5:$C$16)))) | G7: =IF(E7="Vigente",F7,0) | H7: =IF(C7=0,"",G7/C7) | I7: =MAX(C7-G7,0) | J7: =MAX(G7-C7,0) | K7: =IF(G7=0,"Sin cobertura",IF(H7="","",IF(H7<'02_Parametros'!$B$8/100,"Infraseguro",IF(H7>'02_Parametros'!$B$9/100,"Sobreseguro","Adecuada"))))
A8: MAQ-02 | B8: POL-04 | C8: =IF('03_Activos'!E8<>"",'03_Activos'!E8,'03_Activos'!D8) | D8: =IF('03_Activos'!E8<>"","Reposición/tasación","Valor en libros") | E8: =IF('03_Activos'!F8="","Sin póliza",IF(ISNA(MATCH('03_Activos'!F8,'04_Polizas'!$A$5:$A$9,0)),"Póliza no encontrada",INDEX('05_Vigencia'!$E$5:$E$9,MATCH('03_Activos'!F8,'04_Polizas'!$A$5:$A$9,0)))) | F8: =IF(OR(E8="Sin póliza",E8="Póliza no encontrada"),0,IF('03_Activos'!G8<>"",'03_Activos'!G8,IF(SUMIF('03_Activos'!$F$5:$F$16,'03_Activos'!F8,'06_Cobertura_activo'!$C$5:$C$16)=0,0,INDEX('04_Polizas'!$F$5:$F$9,MATCH('03_Activos'!F8,'04_Polizas'!$A$5:$A$9,0))*C8/SUMIF('03_Activos'!$F$5:$F$16,'03_Activos'!F8,'06_Cobertura_activo'!$C$5:$C$16)))) | G8: =IF(E8="Vigente",F8,0) | H8: =IF(C8=0,"",G8/C8) | I8: =MAX(C8-G8,0) | J8: =MAX(G8-C8,0) | K8: =IF(G8=0,"Sin cobertura",IF(H8="","",IF(H8<'02_Parametros'!$B$8/100,"Infraseguro",IF(H8>'02_Parametros'!$B$9/100,"Sobreseguro","Adecuada"))))
A9: VEH-01 | B9: POL-02 | C9: =IF('03_Activos'!E9<>"",'03_Activos'!E9,'03_Activos'!D9) | D9: =IF('03_Activos'!E9<>"","Reposición/tasación","Valor en libros") | E9: =IF('03_Activos'!F9="","Sin póliza",IF(ISNA(MATCH('03_Activos'!F9,'04_Polizas'!$A$5:$A$9,0)),"Póliza no encontrada",INDEX('05_Vigencia'!$E$5:$E$9,MATCH('03_Activos'!F9,'04_Polizas'!$A$5:$A$9,0)))) | F9: =IF(OR(E9="Sin póliza",E9="Póliza no encontrada"),0,IF('03_Activos'!G9<>"",'03_Activos'!G9,IF(SUMIF('03_Activos'!$F$5:$F$16,'03_Activos'!F9,'06_Cobertura_activo'!$C$5:$C$16)=0,0,INDEX('04_Polizas'!$F$5:$F$9,MATCH('03_Activos'!F9,'04_Polizas'!$A$5:$A$9,0))*C9/SUMIF('03_Activos'!$F$5:$F$16,'03_Activos'!F9,'06_Cobertura_activo'!$C$5:$C$16)))) | G9: =IF(E9="Vigente",F9,0) | H9: =IF(C9=0,"",G9/C9) | I9: =MAX(C9-G9,0) | J9: =MAX(G9-C9,0) | K9: =IF(G9=0,"Sin cobertura",IF(H9="","",IF(H9<'02_Parametros'!$B$8/100,"Infraseguro",IF(H9>'02_Parametros'!$B$9/100,"Sobreseguro","Adecuada"))))
A10: VEH-02 | B10: POL-02 | C10: =IF('03_Activos'!E10<>"",'03_Activos'!E10,'03_Activos'!D10) | D10: =IF('03_Activos'!E10<>"","Reposición/tasación","Valor en libros") | E10: =IF('03_Activos'!F10="","Sin póliza",IF(ISNA(MATCH('03_Activos'!F10,'04_Polizas'!$A$5:$A$9,0)),"Póliza no encontrada",INDEX('05_Vigencia'!$E$5:$E$9,MATCH('03_Activos'!F10,'04_Polizas'!$A$5:$A$9,0)))) | F10: =IF(OR(E10="Sin póliza",E10="Póliza no encontrada"),0,IF('03_Activos'!G10<>"",'03_Activos'!G10,IF(SUMIF('03_Activos'!$F$5:$F$16,'03_Activos'!F10,'06_Cobertura_activo'!$C$5:$C$16)=0,0,INDEX('04_Polizas'!$F$5:$F$9,MATCH('03_Activos'!F10,'04_Polizas'!$A$5:$A$9,0))*C10/SUMIF('03_Activos'!$F$5:$F$16,'03_Activos'!F10,'06_Cobertura_activo'!$C$5:$C$16)))) | G10: =IF(E10="Vigente",F10,0) | H10: =IF(C10=0,"",G10/C10) | I10: =MAX(C10-G10,0) | J10: =MAX(G10-C10,0) | K10: =IF(G10=0,"Sin cobertura",IF(H10="","",IF(H10<'02_Parametros'!$B$8/100,"Infraseguro",IF(H10>'02_Parametros'!$B$9/100,"Sobreseguro","Adecuada"))))
A11: VEH-03 | B11: POL-02 | C11: =IF('03_Activos'!E11<>"",'03_Activos'!E11,'03_Activos'!D11) | D11: =IF('03_Activos'!E11<>"","Reposición/tasación","Valor en libros") | E11: =IF('03_Activos'!F11="","Sin póliza",IF(ISNA(MATCH('03_Activos'!F11,'04_Polizas'!$A$5:$A$9,0)),"Póliza no encontrada",INDEX('05_Vigencia'!$E$5:$E$9,MATCH('03_Activos'!F11,'04_Polizas'!$A$5:$A$9,0)))) | F11: =IF(OR(E11="Sin póliza",E11="Póliza no encontrada"),0,IF('03_Activos'!G11<>"",'03_Activos'!G11,IF(SUMIF('03_Activos'!$F$5:$F$16,'03_Activos'!F11,'06_Cobertura_activo'!$C$5:$C$16)=0,0,INDEX('04_Polizas'!$F$5:$F$9,MATCH('03_Activos'!F11,'04_Polizas'!$A$5:$A$9,0))*C11/SUMIF('03_Activos'!$F$5:$F$16,'03_Activos'!F11,'06_Cobertura_activo'!$C$5:$C$16)))) | G11: =IF(E11="Vigente",F11,0) | H11: =IF(C11=0,"",G11/C11) | I11: =MAX(C11-G11,0) | J11: =MAX(G11-C11,0) | K11: =IF(G11=0,"Sin cobertura",IF(H11="","",IF(H11<'02_Parametros'!$B$8/100,"Infraseguro",IF(H11>'02_Parametros'!$B$9/100,"Sobreseguro","Adecuada"))))
A12: EQC-01 | B12: POL-03 | C12: =IF('03_Activos'!E12<>"",'03_Activos'!E12,'03_Activos'!D12) | D12: =IF('03_Activos'!E12<>"","Reposición/tasación","Valor en libros") | E12: =IF('03_Activos'!F12="","Sin póliza",IF(ISNA(MATCH('03_Activos'!F12,'04_Polizas'!$A$5:$A$9,0)),"Póliza no encontrada",INDEX('05_Vigencia'!$E$5:$E$9,MATCH('03_Activos'!F12,'04_Polizas'!$A$5:$A$9,0)))) | F12: =IF(OR(E12="Sin póliza",E12="Póliza no encontrada"),0,IF('03_Activos'!G12<>"",'03_Activos'!G12,IF(SUMIF('03_Activos'!$F$5:$F$16,'03_Activos'!F12,'06_Cobertura_activo'!$C$5:$C$16)=0,0,INDEX('04_Polizas'!$F$5:$F$9,MATCH('03_Activos'!F12,'04_Polizas'!$A$5:$A$9,0))*C12/SUMIF('03_Activos'!$F$5:$F$16,'03_Activos'!F12,'06_Cobertura_activo'!$C$5:$C$16)))) | G12: =IF(E12="Vigente",F12,0) | H12: =IF(C12=0,"",G12/C12) | I12: =MAX(C12-G12,0) | J12: =MAX(G12-C12,0) | K12: =IF(G12=0,"Sin cobertura",IF(H12="","",IF(H12<'02_Parametros'!$B$8/100,"Infraseguro",IF(H12>'02_Parametros'!$B$9/100,"Sobreseguro","Adecuada"))))
A13: EQC-02 | B13: POL-03 | C13: =IF('03_Activos'!E13<>"",'03_Activos'!E13,'03_Activos'!D13) | D13: =IF('03_Activos'!E13<>"","Reposición/tasación","Valor en libros") | E13: =IF('03_Activos'!F13="","Sin póliza",IF(ISNA(MATCH('03_Activos'!F13,'04_Polizas'!$A$5:$A$9,0)),"Póliza no encontrada",INDEX('05_Vigencia'!$E$5:$E$9,MATCH('03_Activos'!F13,'04_Polizas'!$A$5:$A$9,0)))) | F13: =IF(OR(E13="Sin póliza",E13="Póliza no encontrada"),0,IF('03_Activos'!G13<>"",'03_Activos'!G13,IF(SUMIF('03_Activos'!$F$5:$F$16,'03_Activos'!F13,'06_Cobertura_activo'!$C$5:$C$16)=0,0,INDEX('04_Polizas'!$F$5:$F$9,MATCH('03_Activos'!F13,'04_Polizas'!$A$5:$A$9,0))*C13/SUMIF('03_Activos'!$F$5:$F$16,'03_Activos'!F13,'06_Cobertura_activo'!$C$5:$C$16)))) | G13: =IF(E13="Vigente",F13,0) | H13: =IF(C13=0,"",G13/C13) | I13: =MAX(C13-G13,0) | J13: =MAX(G13-C13,0) | K13: =IF(G13=0,"Sin cobertura",IF(H13="","",IF(H13<'02_Parametros'!$B$8/100,"Infraseguro",IF(H13>'02_Parametros'!$B$9/100,"Sobreseguro","Adecuada"))))
A14: BOD-02 | B14: POL-05 | C14: =IF('03_Activos'!E14<>"",'03_Activos'!E14,'03_Activos'!D14) | D14: =IF('03_Activos'!E14<>"","Reposición/tasación","Valor en libros") | E14: =IF('03_Activos'!F14="","Sin póliza",IF(ISNA(MATCH('03_Activos'!F14,'04_Polizas'!$A$5:$A$9,0)),"Póliza no encontrada",INDEX('05_Vigencia'!$E$5:$E$9,MATCH('03_Activos'!F14,'04_Polizas'!$A$5:$A$9,0)))) | F14: =IF(OR(E14="Sin póliza",E14="Póliza no encontrada"),0,IF('03_Activos'!G14<>"",'03_Activos'!G14,IF(SUMIF('03_Activos'!$F$5:$F$16,'03_Activos'!F14,'06_Cobertura_activo'!$C$5:$C$16)=0,0,INDEX('04_Polizas'!$F$5:$F$9,MATCH('03_Activos'!F14,'04_Polizas'!$A$5:$A$9,0))*C14/SUMIF('03_Activos'!$F$5:$F$16,'03_Activos'!F14,'06_Cobertura_activo'!$C$5:$C$16)))) | G14: =IF(E14="Vigente",F14,0) | H14: =IF(C14=0,"",G14/C14) | I14: =MAX(C14-G14,0) | J14: =MAX(G14-C14,0) | K14: =IF(G14=0,"Sin cobertura",IF(H14="","",IF(H14<'02_Parametros'!$B$8/100,"Infraseguro",IF(H14>'02_Parametros'!$B$9/100,"Sobreseguro","Adecuada"))))
A15: MOB-01 | C15: =IF('03_Activos'!E15<>"",'03_Activos'!E15,'03_Activos'!D15) | D15: =IF('03_Activos'!E15<>"","Reposición/tasación","Valor en libros") | E15: =IF('03_Activos'!F15="","Sin póliza",IF(ISNA(MATCH('03_Activos'!F15,'04_Polizas'!$A$5:$A$9,0)),"Póliza no encontrada",INDEX('05_Vigencia'!$E$5:$E$9,MATCH('03_Activos'!F15,'04_Polizas'!$A$5:$A$9,0)))) | F15: =IF(OR(E15="Sin póliza",E15="Póliza no encontrada"),0,IF('03_Activos'!G15<>"",'03_Activos'!G15,IF(SUMIF('03_Activos'!$F$5:$F$16,'03_Activos'!F15,'06_Cobertura_activo'!$C$5:$C$16)=0,0,INDEX('04_Polizas'!$F$5:$F$9,MATCH('03_Activos'!F15,'04_Polizas'!$A$5:$A$9,0))*C15/SUMIF('03_Activos'!$F$5:$F$16,'03_Activos'!F15,'06_Cobertura_activo'!$C$5:$C$16)))) | G15: =IF(E15="Vigente",F15,0) | H15: =IF(C15=0,"",G15/C15) | I15: =MAX(C15-G15,0) | J15: =MAX(G15-C15,0) | K15: =IF(G15=0,"Sin cobertura",IF(H15="","",IF(H15<'02_Parametros'!$B$8/100,"Infraseguro",IF(H15>'02_Parametros'!$B$9/100,"Sobreseguro","Adecuada"))))
A16: GEN-01 | B16: POL-09 | C16: =IF('03_Activos'!E16<>"",'03_Activos'!E16,'03_Activos'!D16) | D16: =IF('03_Activos'!E16<>"","Reposición/tasación","Valor en libros") | E16: =IF('03_Activos'!F16="","Sin póliza",IF(ISNA(MATCH('03_Activos'!F16,'04_Polizas'!$A$5:$A$9,0)),"Póliza no encontrada",INDEX('05_Vigencia'!$E$5:$E$9,MATCH('03_Activos'!F16,'04_Polizas'!$A$5:$A$9,0)))) | F16: =IF(OR(E16="Sin póliza",E16="Póliza no encontrada"),0,IF('03_Activos'!G16<>"",'03_Activos'!G16,IF(SUMIF('03_Activos'!$F$5:$F$16,'03_Activos'!F16,'06_Cobertura_activo'!$C$5:$C$16)=0,0,INDEX('04_Polizas'!$F$5:$F$9,MATCH('03_Activos'!F16,'04_Polizas'!$A$5:$A$9,0))*C16/SUMIF('03_Activos'!$F$5:$F$16,'03_Activos'!F16,'06_Cobertura_activo'!$C$5:$C$16)))) | G16: =IF(E16="Vigente",F16,0) | H16: =IF(C16=0,"",G16/C16) | I16: =MAX(C16-G16,0) | J16: =MAX(G16-C16,0) | K16: =IF(G16=0,"Sin cobertura",IF(H16="","",IF(H16<'02_Parametros'!$B$8/100,"Infraseguro",IF(H16>'02_Parametros'!$B$9/100,"Sobreseguro","Adecuada"))))
A17: TOTAL | C17: =SUM(C5:C16) | G17: =SUM(G5:G16) | I17: =SUM(I5:I16)
A19: ⓘ Cómo se calcula esta hoja
A20: Columna | B20: Fórmula (Excel) | C20: Cómo se calcula (sencillo) | D20: Ejemplo con números reales | E20: De dónde viene | F20: Norma
A21: Valor de referencia | B21: '=IF('03_Activos'!E5<>"",'03_Activos'!E5,'03_Activos'!D5) | C21: Usa el valor de reposición o tasación del activo en la hoja 03 (Activos asegurables); si el cliente no lo informó, toma el valor en libros. | D21: Fila 1: IF(650.000,00<>""; 650.000,00; 437.500,00) → 650.000,00 | E21: hoja «Activos asegurables (datos del cliente)» | F21: —
A22: Base de referencia | B22: '=IF('03_Activos'!E5<>"","Reposición/tasación","Valor en libros") | C22: Indica qué valor se usó como referencia: «Reposición/tasación» si existe en la hoja 03 (Activos asegurables); si no, «Valor en libros». | D22: Fila 1: IF(650.000,00<>""; "Reposición/tasación"; "Valor en libros") → Reposición/tasación | E22: hoja «Activos asegurables (datos del cliente)» | F22: —
A23: Estado de la póliza | B23: '=IF('03_Activos'!F5="","Sin póliza",IF(ISNA(MATCH('03_Activos'!F5,'04_Polizas'!$A$5:$A$9,0)),"Póliza no encontrada",INDEX('05_Vigencia'!$E$5:$E$9,MATCH('03_Activos'!F5,'04_Polizas'!$A$5:$A$9,0)))) | C23: Busca la póliza del activo en la hoja 04 (Pólizas) y trae su estado al corte de la hoja 05 (Vigencia). Si el activo no tiene póliza dice «Sin póliza»; si la póliza no está en la lista, «Póliza no encontrada». | D23: Fila 1: IF(«POL-01»=""; "Sin póliza"; IF(ISNA(MATCH(«POL-01»; [«Póliza» de «Pólizas (datos del cliente)», 5 filas]; 0)); "Póliza no encontrada"; INDEX([«Estado al corte» de «Vigencia de pólizas al corte», 5 filas]; MATCH(«POL-01»; [«Póliza» de «Pólizas (datos del cliente)», 5 filas]; 0)))) → Vigente | E23: hoja «Activos asegurables (datos del cliente)», hoja «Pólizas (datos del cliente)», hoja «Vigencia de pólizas al corte» | F23: —
A24: Suma asegurada asignada | B24: '=IF(OR(E5="Sin póliza",E5="Póliza no encontrada"),0,IF('03_Activos'!G5<>"",'03_Activos'!G5,IF(SUMIF('03_Activos'!$F$5:$F$16,'03_Activos'!F5,'06_Cobertura_activo'!$C$5:$C$16)=0,0,INDEX('04_Polizas'!$F$5:$F$9,MATCH('03_Activos'!F5,'04_Polizas'!$A$5:$A$9,0))*C5/SUMIF('03_Activos'!$F$5:$F$16,'03_Activos'!F5,'06_Cobertura_activo'!$C$5:$C$16)))) | C24: Usa la suma asignada por el cliente al activo en la hoja 03 (Activos asegurables). Si no la hay, reparte la suma asegurada de la póliza (hoja 04) entre sus activos en proporción a su valor de referencia. Es cero sin póliza o si la póliza no se encuentra. | D24: Fila 1: IF(OR(«Vigente»="Sin póliza"; «Vigente»="Póliza no encontrada"); 0; IF((vacío)<>""; (vacío); IF(SUMIF([«Póliza» de «Activos asegurables (datos del cliente)», 12 filas]; «POL-01»; [«Valor de referencia» de «Universo y cobertura por activo», 12 filas])=0; 0; INDEX([«Suma asegurada total» de «Pólizas (datos del cliente)», 5 filas]; MATCH(«POL-01»; [«Póliza» de «Pólizas (datos del cliente)», 5 filas]; 0))*650.000,00/SUMIF([«Póliza» de «Activos asegurables (datos del cliente)», 12 filas]; «POL-01»; [«Valor de referencia» de «Universo y cobertura por activo», 12 filas])))) → 478.947,37 | E24: «Estado de la póliza» (esta hoja), «Valor de referencia» (esta hoja), hoja «Activos asegurables (datos del cliente)», hoja «Universo y cobertura por activo», hoja «Pólizas (datos del cliente)» | F24: —
A25: Suma asegurada vigente | B25: '=IF(E5="Vigente",F5,0) | C25: Mantiene la suma asegurada asignada solo si la póliza está vigente al corte; si está vencida o no iniciada, es cero. | D25: Fila 1: IF(«Vigente»="Vigente"; 478.947,37; 0) → 478.947,37 | E25: «Estado de la póliza» (esta hoja), «Suma asegurada asignada» (esta hoja) | F25: —
A26: % cobertura | B26: '=IF(C5=0,"",G5/C5) | C26: Divide la suma asegurada vigente entre el valor de referencia del activo; en blanco si la referencia es cero. | D26: Fila 1: IF(650.000,00=0; ""; 478.947,37/650.000,00) → 73,68 % | E26: «Valor de referencia» (esta hoja), «Suma asegurada vigente» (esta hoja) | F26: —
A27: Déficit | B27: '=MAX(C5-G5,0) | C27: Resta la suma asegurada vigente al valor de referencia: es la parte del activo que no está asegurada (nunca menos de cero). | D27: Fila 1: MAX(650.000,00-478.947,37; 0) → 171.052,63 | E27: «Valor de referencia» (esta hoja), «Suma asegurada vigente» (esta hoja) | F27: —
A28: Exceso | B28: '=MAX(G5-C5,0) | C28: Resta el valor de referencia a la suma asegurada vigente: es lo asegurado por encima del valor del activo (mínimo cero). | D28: Fila 1: MAX(478.947,37-650.000,00; 0) → 0,00 | E28: «Suma asegurada vigente» (esta hoja), «Valor de referencia» (esta hoja) | F28: —
A29: Clasificación | B29: '=IF(G5=0,"Sin cobertura",IF(H5="","",IF(H5<'02_Parametros'!$B$8/100,"Infraseguro",IF(H5>'02_Parametros'!$B$9/100,"Sobreseguro","Adecuada")))) | C29: Califica la cobertura del activo: «Sin cobertura» si la suma vigente es cero; «Infraseguro» bajo la cobertura mínima y «Sobreseguro» sobre el umbral de la hoja 02 (Parámetros); si no, «Adecuada». | D29: Fila 1: IF(478.947,37=0; "Sin cobertura"; IF(73,68 %=""; ""; IF(73,68 %<80,00/100; "Infraseguro"; IF(73,68 %>120,00/100; "Sobreseguro"; "Adecuada")))) → Infraseguro | E29: «Suma asegurada vigente» (esta hoja), «% cobertura» (esta hoja), hoja «Parámetros» | F29: —

Sheet 07_Cobertura_poliza
A1: Cobertura por póliza (infraseguro) | H1: ⟵ Inicio | I1: ◀ Anterior | J1: Siguiente ▶
A2: Cobertura de seguros de activos · Cliente de muestra S.A. · corte 2025-12-31
A4: Póliza | B4: Estado | C4: Suma asegurada total | D4: Referencia asignada | E4: Activos | F4: % cobertura | G4: Factor proporcional | H4: Déficit | I4: Sumas asignadas | J4: Total − asignadas | K4: Clasificación
A5: POL-01 | B5: ='05_Vigencia'!E5 | C5: ='04_Polizas'!F5 | D5: =SUMIF('03_Activos'!$F$5:$F$16,A5,'06_Cobertura_activo'!$C$5:$C$16) | E5: =COUNTIF('03_Activos'!$F$5:$F$16,A5) | F5: =IF(D5=0,"",C5/D5) | G5: =IF(F5="","",MIN(F5,1)) | H5: =MAX(D5-C5,0) | I5: =SUMIF('03_Activos'!$F$5:$F$16,A5,'06_Cobertura_activo'!$F$5:$F$16) | J5: =C5-I5 | K5: =IF(F5="","Sin activos asignados",IF(F5<'02_Parametros'!$B$8/100,"Infraseguro",IF(F5>'02_Parametros'!$B$9/100,"Sobreseguro","Adecuada")))
A6: POL-02 | B6: ='05_Vigencia'!E6 | C6: ='04_Polizas'!F6 | D6: =SUMIF('03_Activos'!$F$5:$F$16,A6,'06_Cobertura_activo'!$C$5:$C$16) | E6: =COUNTIF('03_Activos'!$F$5:$F$16,A6) | F6: =IF(D6=0,"",C6/D6) | G6: =IF(F6="","",MIN(F6,1)) | H6: =MAX(D6-C6,0) | I6: =SUMIF('03_Activos'!$F$5:$F$16,A6,'06_Cobertura_activo'!$F$5:$F$16) | J6: =C6-I6 | K6: =IF(F6="","Sin activos asignados",IF(F6<'02_Parametros'!$B$8/100,"Infraseguro",IF(F6>'02_Parametros'!$B$9/100,"Sobreseguro","Adecuada")))
A7: POL-03 | B7: ='05_Vigencia'!E7 | C7: ='04_Polizas'!F7 | D7: =SUMIF('03_Activos'!$F$5:$F$16,A7,'06_Cobertura_activo'!$C$5:$C$16) | E7: =COUNTIF('03_Activos'!$F$5:$F$16,A7) | F7: =IF(D7=0,"",C7/D7) | G7: =IF(F7="","",MIN(F7,1)) | H7: =MAX(D7-C7,0) | I7: =SUMIF('03_Activos'!$F$5:$F$16,A7,'06_Cobertura_activo'!$F$5:$F$16) | J7: =C7-I7 | K7: =IF(F7="","Sin activos asignados",IF(F7<'02_Parametros'!$B$8/100,"Infraseguro",IF(F7>'02_Parametros'!$B$9/100,"Sobreseguro","Adecuada")))
A8: POL-04 | B8: ='05_Vigencia'!E8 | C8: ='04_Polizas'!F8 | D8: =SUMIF('03_Activos'!$F$5:$F$16,A8,'06_Cobertura_activo'!$C$5:$C$16) | E8: =COUNTIF('03_Activos'!$F$5:$F$16,A8) | F8: =IF(D8=0,"",C8/D8) | G8: =IF(F8="","",MIN(F8,1)) | H8: =MAX(D8-C8,0) | I8: =SUMIF('03_Activos'!$F$5:$F$16,A8,'06_Cobertura_activo'!$F$5:$F$16) | J8: =C8-I8 | K8: =IF(F8="","Sin activos asignados",IF(F8<'02_Parametros'!$B$8/100,"Infraseguro",IF(F8>'02_Parametros'!$B$9/100,"Sobreseguro","Adecuada")))
A9: POL-05 | B9: ='05_Vigencia'!E9 | C9: ='04_Polizas'!F9 | D9: =SUMIF('03_Activos'!$F$5:$F$16,A9,'06_Cobertura_activo'!$C$5:$C$16) | E9: =COUNTIF('03_Activos'!$F$5:$F$16,A9) | F9: =IF(D9=0,"",C9/D9) | G9: =IF(F9="","",MIN(F9,1)) | H9: =MAX(D9-C9,0) | I9: =SUMIF('03_Activos'!$F$5:$F$16,A9,'06_Cobertura_activo'!$F$5:$F$16) | J9: =C9-I9 | K9: =IF(F9="","Sin activos asignados",IF(F9<'02_Parametros'!$B$8/100,"Infraseguro",IF(F9>'02_Parametros'!$B$9/100,"Sobreseguro","Adecuada")))
A11: ⓘ Cómo se calcula esta hoja
A12: Columna | B12: Fórmula (Excel) | C12: Cómo se calcula (sencillo) | D12: Ejemplo con números reales | E12: De dónde viene | F12: Norma
A13: Estado | B13: '='05_Vigencia'!E5 | C13: Trae el estado de la póliza al corte (vigente, vencida o no iniciada) desde la hoja 05 (Vigencia de pólizas). | D13: Fila 1: «Vigente» → Vigente | E13: hoja «Vigencia de pólizas al corte» | F13: —
A14: Suma asegurada total | B14: '='04_Polizas'!F5 | C14: Trae la suma asegurada total contratada en la póliza, según la hoja 04 (Pólizas). | D14: Fila 1: 700.000,00 → 700.000,00 | E14: hoja «Pólizas (datos del cliente)» | F14: —
A15: Referencia asignada | B15: '=SUMIF('03_Activos'!$F$5:$F$16,A5,'06_Cobertura_activo'!$C$5:$C$16) | C15: Suma el valor de referencia de todos los activos que el cliente asignó a esta póliza, tomado de la hoja 06 (Universo y cobertura por activo). | D15: Fila 1: SUMIF([«Póliza» de «Activos asegurables (datos del cliente)», 12 filas]; «POL-01»; [«Valor de referencia» de «Universo y cobertura por activo», 12 filas]) → 950.000,00 | E15: «Póliza» (esta hoja), hoja «Activos asegurables (datos del cliente)», hoja «Universo y cobertura por activo» | F15: —
A16: Activos | B16: '=COUNTIF('03_Activos'!$F$5:$F$16,A5) | C16: Cuenta cuántos activos de la hoja 03 (Activos asegurables) están asignados a esta póliza. | D16: Fila 1: COUNTIF([«Póliza» de «Activos asegurables (datos del cliente)», 12 filas]; «POL-01») → 2 | E16: «Póliza» (esta hoja), hoja «Activos asegurables (datos del cliente)» | F16: —
A17: % cobertura | B17: '=IF(D5=0,"",C5/D5) | C17: Divide la suma asegurada total de la póliza entre el valor de referencia asignado; en blanco si no tiene activos asignados. | D17: Fila 1: IF(950.000,00=0; ""; 700.000,00/950.000,00) → 73,68 % | E17: «Referencia asignada» (esta hoja), «Suma asegurada total» (esta hoja) | F17: —
A18: Factor proporcional | B18: '=IF(F5="","",MIN(F5,1)) | C18: Toma el % de cobertura con un máximo de 100 %: es la proporción del daño que pagaría la aseguradora si aplica la regla proporcional por infraseguro. | D18: Fila 1: IF(73,68 %=""; ""; MIN(73,68 %; 1)) → 73,68 % | E18: «% cobertura» (esta hoja) | F18: —
A19: Déficit | B19: '=MAX(D5-C5,0) | C19: Resta la suma asegurada total al valor de referencia asignado: lo que falta asegurar en la póliza (mínimo cero). | D19: Fila 1: MAX(950.000,00-700.000,00; 0) → 250.000,00 | E19: «Referencia asignada» (esta hoja), «Suma asegurada total» (esta hoja) | F19: —
A20: Sumas asignadas | B20: '=SUMIF('03_Activos'!$F$5:$F$16,A5,'06_Cobertura_activo'!$F$5:$F$16) | C20: Suma las sumas aseguradas asignadas a los activos de esta póliza en la hoja 06 (Universo y cobertura por activo). | D20: Fila 1: SUMIF([«Póliza» de «Activos asegurables (datos del cliente)», 12 filas]; «POL-01»; [«Suma asegurada asignada» de «Universo y cobertura por activo», 12 filas]) → 700.000,00 | E20: «Póliza» (esta hoja), hoja «Activos asegurables (datos del cliente)», hoja «Universo y cobertura por activo» | F20: —
A21: Total − asignadas | B21: '=C5-I5 | C21: Resta las sumas asignadas a los activos a la suma asegurada total: distinto de cero indica que la asignación por activo no cuadra con la póliza. | D21: Fila 1: 700.000,00-700.000,00 → 0,00 | E21: «Suma asegurada total» (esta hoja), «Sumas asignadas» (esta hoja) | F21: —
A22: Clasificación | B22: '=IF(F5="","Sin activos asignados",IF(F5<'02_Parametros'!$B$8/100,"Infraseguro",IF(F5>'02_Parametros'!$B$9/100,"Sobreseguro","Adecuada"))) | C22: Califica la póliza con su % de cobertura y los umbrales de la hoja 02 (Parámetros): infraseguro, sobreseguro o adecuada; si no tiene activos asignados, lo indica. | D22: Fila 1: IF(73,68 %=""; "Sin activos asignados"; IF(73,68 %<80,00/100; "Infraseguro"; IF(73,68 %>120,00/100; "Sobreseguro"; "Adecuada"))) → Infraseguro | E22: «% cobertura» (esta hoja), hoja «Parámetros» | F22: —

Sheet 08_Deducibles_exposicion
A1: Deducibles y exposición máxima | H1: ⟵ Inicio | I1: ◀ Anterior | J1: Siguiente ▶
A2: Cobertura de seguros de activos · Cliente de muestra S.A. · corte 2025-12-31
A4: Código | B4: Pérdida total (referencia) | C4: Factor proporcional | D4: Indemnización bruta | E4: Deducible % | F4: Deducible | G4: Indemnización neta | H4: Pérdida no cubierta
A5: EDIF-01 | B5: ='06_Cobertura_activo'!C5 | C5: =IF(B5=0,0,MIN('06_Cobertura_activo'!G5/B5,1)) | D5: =B5*C5 | E5: =IF('03_Activos'!H5="",0,'03_Activos'!H5) | F5: =IF(D5=0,0,MIN(B5*E5/100,D5)) | G5: =D5-F5 | H5: =B5-G5
A6: BOD-01 | B6: ='06_Cobertura_activo'!C6 | C6: =IF(B6=0,0,MIN('06_Cobertura_activo'!G6/B6,1)) | D6: =B6*C6 | E6: =IF('03_Activos'!H6="",0,'03_Activos'!H6) | F6: =IF(D6=0,0,MIN(B6*E6/100,D6)) | G6: =D6-F6 | H6: =B6-G6
A7: MAQ-01 | B7: ='06_Cobertura_activo'!C7 | C7: =IF(B7=0,0,MIN('06_Cobertura_activo'!G7/B7,1)) | D7: =B7*C7 | E7: =IF('03_Activos'!H7="",0,'03_Activos'!H7) | F7: =IF(D7=0,0,MIN(B7*E7/100,D7)) | G7: =D7-F7 | H7: =B7-G7
A8: MAQ-02 | B8: ='06_Cobertura_activo'!C8 | C8: =IF(B8=0,0,MIN('06_Cobertura_activo'!G8/B8,1)) | D8: =B8*C8 | E8: =IF('03_Activos'!H8="",0,'03_Activos'!H8) | F8: =IF(D8=0,0,MIN(B8*E8/100,D8)) | G8: =D8-F8 | H8: =B8-G8
A9: VEH-01 | B9: ='06_Cobertura_activo'!C9 | C9: =IF(B9=0,0,MIN('06_Cobertura_activo'!G9/B9,1)) | D9: =B9*C9 | E9: =IF('03_Activos'!H9="",0,'03_Activos'!H9) | F9: =IF(D9=0,0,MIN(B9*E9/100,D9)) | G9: =D9-F9 | H9: =B9-G9
A10: VEH-02 | B10: ='06_Cobertura_activo'!C10 | C10: =IF(B10=0,0,MIN('06_Cobertura_activo'!G10/B10,1)) | D10: =B10*C10 | E10: =IF('03_Activos'!H10="",0,'03_Activos'!H10) | F10: =IF(D10=0,0,MIN(B10*E10/100,D10)) | G10: =D10-F10 | H10: =B10-G10
A11: VEH-03 | B11: ='06_Cobertura_activo'!C11 | C11: =IF(B11=0,0,MIN('06_Cobertura_activo'!G11/B11,1)) | D11: =B11*C11 | E11: =IF('03_Activos'!H11="",0,'03_Activos'!H11) | F11: =IF(D11=0,0,MIN(B11*E11/100,D11)) | G11: =D11-F11 | H11: =B11-G11
A12: EQC-01 | B12: ='06_Cobertura_activo'!C12 | C12: =IF(B12=0,0,MIN('06_Cobertura_activo'!G12/B12,1)) | D12: =B12*C12 | E12: =IF('03_Activos'!H12="",0,'03_Activos'!H12) | F12: =IF(D12=0,0,MIN(B12*E12/100,D12)) | G12: =D12-F12 | H12: =B12-G12
A13: EQC-02 | B13: ='06_Cobertura_activo'!C13 | C13: =IF(B13=0,0,MIN('06_Cobertura_activo'!G13/B13,1)) | D13: =B13*C13 | E13: =IF('03_Activos'!H13="",0,'03_Activos'!H13) | F13: =IF(D13=0,0,MIN(B13*E13/100,D13)) | G13: =D13-F13 | H13: =B13-G13
A14: BOD-02 | B14: ='06_Cobertura_activo'!C14 | C14: =IF(B14=0,0,MIN('06_Cobertura_activo'!G14/B14,1)) | D14: =B14*C14 | E14: =IF('03_Activos'!H14="",0,'03_Activos'!H14) | F14: =IF(D14=0,0,MIN(B14*E14/100,D14)) | G14: =D14-F14 | H14: =B14-G14
A15: MOB-01 | B15: ='06_Cobertura_activo'!C15 | C15: =IF(B15=0,0,MIN('06_Cobertura_activo'!G15/B15,1)) | D15: =B15*C15 | E15: =IF('03_Activos'!H15="",0,'03_Activos'!H15) | F15: =IF(D15=0,0,MIN(B15*E15/100,D15)) | G15: =D15-F15 | H15: =B15-G15
A16: GEN-01 | B16: ='06_Cobertura_activo'!C16 | C16: =IF(B16=0,0,MIN('06_Cobertura_activo'!G16/B16,1)) | D16: =B16*C16 | E16: =IF('03_Activos'!H16="",0,'03_Activos'!H16) | F16: =IF(D16=0,0,MIN(B16*E16/100,D16)) | G16: =D16-F16 | H16: =B16-G16
A17: TOTAL | F17: =SUM(F5:F16) | H17: =SUM(H5:H16)
A19: ⓘ Cómo se calcula esta hoja
A20: Columna | B20: Fórmula (Excel) | C20: Cómo se calcula (sencillo) | D20: Ejemplo con números reales | E20: De dónde viene | F20: Norma
A21: Pérdida total (referencia) | B21: '='06_Cobertura_activo'!C5 | C21: Supone la pérdida total del activo: trae su valor de referencia de la hoja 06 (Universo y cobertura por activo). | D21: Fila 1: 650.000,00 → 650.000,00 | E21: hoja «Universo y cobertura por activo» | F21: —
A22: Factor proporcional | B22: '=IF(B5=0,0,MIN('06_Cobertura_activo'!G5/B5,1)) | C22: Divide la suma asegurada vigente del activo (hoja 06) entre la pérdida total, con un máximo de 100 %; si la pérdida es cero, el factor es cero. | D22: Fila 1: IF(650.000,00=0; 0; MIN(478.947,37/650.000,00; 1)) → 73,68 % | E22: «Pérdida total (referencia)» (esta hoja), hoja «Universo y cobertura por activo» | F22: —
A23: Indemnización bruta | B23: '=B5*C5 | C23: Multiplica la pérdida total por el factor proporcional: lo que pagaría la aseguradora antes del deducible. | D23: Fila 1: 650.000,00*73,68 % → 478.947,37 | E23: «Pérdida total (referencia)» (esta hoja), «Factor proporcional» (esta hoja) | F23: —
A24: Deducible % | B24: '=IF('03_Activos'!H5="",0,'03_Activos'!H5) | C24: Trae el porcentaje de deducible del activo informado en la hoja 03 (Activos asegurables); si está en blanco, se toma como cero. | D24: Fila 1: IF(2,00=""; 0; 2,00) → 2,00 | E24: hoja «Activos asegurables (datos del cliente)» | F24: —
A25: Deducible | B25: '=IF(D5=0,0,MIN(B5*E5/100,D5)) | C25: Aplica el porcentaje de deducible sobre la pérdida total, sin pasar de la indemnización bruta; si no hay indemnización, es cero. | D25: Fila 1: IF(478.947,37=0; 0; MIN(650.000,00*2,00/100; 478.947,37)) → 13.000,00 | E25: «Indemnización bruta» (esta hoja), «Pérdida total (referencia)» (esta hoja), «Deducible %» (esta hoja) | F25: —
A26: Indemnización neta | B26: '=D5-F5 | C26: Resta el deducible a la indemnización bruta: es lo que efectivamente cobraría la entidad. | D26: Fila 1: 478.947,37-13.000,00 → 465.947,37 | E26: «Indemnización bruta» (esta hoja), «Deducible» (esta hoja) | F26: —
A27: Pérdida no cubierta | B27: '=B5-G5 | C27: Resta la indemnización neta a la pérdida total: es lo que la entidad perdería de su bolsillo. | D27: Fila 1: 650.000,00-465.947,37 → 184.052,63 | E27: «Pérdida total (referencia)» (esta hoja), «Indemnización neta» (esta hoja) | F27: —

Sheet 09_Sin_cobertura
A1: Activos sin cobertura | H1: ⟵ Inicio | I1: ◀ Anterior | J1: Siguiente ▶
A2: Cobertura de seguros de activos · Cliente de muestra S.A. · corte 2025-12-31
A4: Código | B4: Descripción | C4: Póliza | D4: Motivo | E4: Valor en libros | F4: Valor de referencia
A5: EQC-01 | B5: Servidores | C5: POL-03 | D5: ='06_Cobertura_activo'!E12 | E5: ='03_Activos'!D12 | F5: ='06_Cobertura_activo'!C12
A6: EQC-02 | B6: Computadores portátiles | C6: POL-03 | D6: ='06_Cobertura_activo'!E13 | E6: ='03_Activos'!D13 | F6: ='06_Cobertura_activo'!C13
A7: BOD-02 | B7: Bodega norte | C7: POL-05 | D7: ='06_Cobertura_activo'!E14 | E7: ='03_Activos'!D14 | F7: ='06_Cobertura_activo'!C14
A8: MOB-01 | B8: Mobiliario de oficinas | D8: ='06_Cobertura_activo'!E15 | E8: ='03_Activos'!D15 | F8: ='06_Cobertura_activo'!C15
A9: GEN-01 | B9: Generador eléctrico | C9: POL-09 | D9: ='06_Cobertura_activo'!E16 | E9: ='03_Activos'!D16 | F9: ='06_Cobertura_activo'!C16
A10: TOTAL | E10: =SUM(E5:E9) | F10: =SUM(F5:F9)
A12: ⓘ Cómo se calcula esta hoja
A13: Columna | B13: Fórmula (Excel) | C13: Cómo se calcula (sencillo) | D13: Ejemplo con números reales | E13: De dónde viene | F13: Norma
A14: Motivo | B14: '='06_Cobertura_activo'!E12 | C14: Trae de la hoja 06 (Universo y cobertura por activo) el estado de la póliza del activo: sin póliza, póliza no encontrada, vencida o no iniciada. | D14: Fila 1: «Vencida» → Vencida | E14: hoja «Universo y cobertura por activo» | F14: —
A15: Valor en libros | B15: '='03_Activos'!D12 | C15: Trae el valor en libros del activo sin cobertura vigente, tomado de la hoja 03 (Activos asegurables). | D15: Fila 1: 10.000,00 → 10.000,00 | E15: hoja «Activos asegurables (datos del cliente)» | F15: —
A16: Valor de referencia | B16: '='06_Cobertura_activo'!C12 | C16: Trae el valor de referencia (reposición, tasación o libros) del activo desde la hoja 06 (Cobertura por activo). | D16: Fila 1: 30.000,00 → 30.000,00 | E16: hoja «Universo y cobertura por activo» | F16: —

Sheet 10_Prima_anticipada
A1: Prima pagada por anticipado | H1: ⟵ Inicio | I1: ◀ Anterior | J1: Siguiente ▶
A2: Cobertura de seguros de activos · Cliente de muestra S.A. · corte 2025-12-31
A4: Póliza | B4: Prima total | C4: Días de vigencia | D4: Días por transcurrir | E4: Anticipada recalculada | F4: Anticipada registrada | G4: Registrada − recalculada
A5: POL-01 | B5: =IF('04_Polizas'!G5="","",'04_Polizas'!G5) | C5: ='05_Vigencia'!D5 | D5: =MAX(MIN('04_Polizas'!E5-'02_Parametros'!$B$5,C5),0) | E5: =IF(B5="","",B5*D5/C5) | F5: =IF('04_Polizas'!H5="","",'04_Polizas'!H5) | G5: =IF(OR(E5="",F5=""),"",F5-E5)
A6: POL-02 | B6: =IF('04_Polizas'!G6="","",'04_Polizas'!G6) | C6: ='05_Vigencia'!D6 | D6: =MAX(MIN('04_Polizas'!E6-'02_Parametros'!$B$5,C6),0) | E6: =IF(B6="","",B6*D6/C6) | F6: =IF('04_Polizas'!H6="","",'04_Polizas'!H6) | G6: =IF(OR(E6="",F6=""),"",F6-E6)
A7: POL-03 | B7: =IF('04_Polizas'!G7="","",'04_Polizas'!G7) | C7: ='05_Vigencia'!D7 | D7: =MAX(MIN('04_Polizas'!E7-'02_Parametros'!$B$5,C7),0) | E7: =IF(B7="","",B7*D7/C7) | F7: =IF('04_Polizas'!H7="","",'04_Polizas'!H7) | G7: =IF(OR(E7="",F7=""),"",F7-E7)
A8: POL-04 | B8: =IF('04_Polizas'!G8="","",'04_Polizas'!G8) | C8: ='05_Vigencia'!D8 | D8: =MAX(MIN('04_Polizas'!E8-'02_Parametros'!$B$5,C8),0) | E8: =IF(B8="","",B8*D8/C8) | F8: =IF('04_Polizas'!H8="","",'04_Polizas'!H8) | G8: =IF(OR(E8="",F8=""),"",F8-E8)
A9: POL-05 | B9: =IF('04_Polizas'!G9="","",'04_Polizas'!G9) | C9: ='05_Vigencia'!D9 | D9: =MAX(MIN('04_Polizas'!E9-'02_Parametros'!$B$5,C9),0) | E9: =IF(B9="","",B9*D9/C9) | F9: =IF('04_Polizas'!H9="","",'04_Polizas'!H9) | G9: =IF(OR(E9="",F9=""),"",F9-E9)
A10: TOTAL | E10: =SUM(E5:E9) | F10: =SUM(F5:F9) | G10: =SUM(G5:G9)
A12: ⓘ Cómo se calcula esta hoja
A13: Columna | B13: Fórmula (Excel) | C13: Cómo se calcula (sencillo) | D13: Ejemplo con números reales | E13: De dónde viene | F13: Norma
A14: Prima total | B14: '=IF('04_Polizas'!G5="","",'04_Polizas'!G5) | C14: Trae la prima total de la póliza informada en la hoja 04 (Pólizas); si no se informó, queda en blanco. | D14: Fila 1: IF(7.300,00=""; ""; 7.300,00) → 7.300,00 | E14: hoja «Pólizas (datos del cliente)» | F14: —
A15: Días de vigencia | B15: '='05_Vigencia'!D5 | C15: Trae los días que dura la póliza, calculados en la hoja 05 (Vigencia de pólizas al corte). | D15: Fila 1: 365 → 365 | E15: hoja «Vigencia de pólizas al corte» | F15: —
A16: Días por transcurrir | B16: '=MAX(MIN('04_Polizas'!E5-'02_Parametros'!$B$5,C5),0) | C16: Resta la fecha de corte (hoja 02) a la fecha «hasta» de la hoja 04 (Pólizas), sin pasar de los días de vigencia; si la póliza ya venció, es cero. | D16: Fila 1: MAX(MIN(«2026-07-01»-«2025-12-31»; 365); 0) → 182 | E16: «Días de vigencia» (esta hoja), hoja «Pólizas (datos del cliente)», hoja «Parámetros» | F16: —
A17: Anticipada recalculada | B17: '=IF(B5="","",B5*D5/C5) | C17: Multiplica la prima total por los días por transcurrir y la divide para los días de vigencia: es la parte de la prima que aún no se ha devengado. | D17: Fila 1: IF(7.300,00=""; ""; 7.300,00*182/365) → 3.640,00 | E17: «Prima total» (esta hoja), «Días por transcurrir» (esta hoja), «Días de vigencia» (esta hoja) | F17: —
A18: Anticipada registrada | B18: '=IF('04_Polizas'!H5="","",'04_Polizas'!H5) | C18: Trae la prima pagada por anticipado que registró el cliente para la póliza en la hoja 04 (Pólizas); en blanco si falta. | D18: Fila 1: IF(3.640,00=""; ""; 3.640,00) → 3.640,00 | E18: hoja «Pólizas (datos del cliente)» | F18: —
A19: Registrada − recalculada | B19: '=IF(OR(E5="",F5=""),"",F5-E5) | C19: Resta la anticipada recalculada a la registrada: positivo es anticipo de más (falta llevar a gasto); en blanco si falta alguna de las dos. | D19: Fila 1: IF(OR(3.640,00=""; 3.640,00=""); ""; 3.640,00-3.640,00) → 0,00 | E19: «Anticipada recalculada» (esta hoja), «Anticipada registrada» (esta hoja) | F19: —

Sheet 11_Siniestros
A1: Siniestros pendientes y revelación | H1: ⟵ Inicio | I1: ◀ Anterior | J1: Siguiente ▶
A2: Cobertura de seguros de activos · Cliente de muestra S.A. · corte 2025-12-31
A4: Póliza | B4: Aseguradora | C4: Siniestro | D4: Monto | E4: Revelado | F4: Estado de la póliza | G4: Evaluación | H4: Tipo de siniestro | I4: Cobro exigible | J4: Tratamiento contable | K4: Compensación exigible a reconocer
A5: POL-02 | B5: Aseguradora Beta S.A. | C5: Choque del camión VEH-02 | D5: =IF('04_Polizas'!J6="","",'04_Polizas'!J6) | E5: No | F5: ='05_Vigencia'!E6 | G5: =IF(OR('04_Polizas'!K6="Sí",'04_Polizas'!K6="Si"),"Revelado","Sin revelación: evaluar NIC 16.65–66, NIC 36.12 e), NIC 37.31–35/86/89 · PYMES 17.25 y 21") | H5: =IF('04_Polizas'!L6="","",'04_Polizas'!L6) | I5: =IF('04_Polizas'!M6="","",'04_Polizas'!M6) | J5: =IF(H5="","Tipo no informado: se mantiene el tratamiento de reclamo de terceros (NIC 37.53)",IF(H5="Daño a activo propio",IF(I5="Sí","Compensación exigible: reconocer en resultados (NIC 16.65–66 · PYMES 17.25)",IF(I5="No","Activo contingente: no se reconoce; revelar si es probable (NIC 37.31–35 y 89 · PYMES 21.16)","Exigibilidad no informada: tratado como activo contingente (NIC 37.31–35)")),"Reclamo de terceros: provisión y reembolso solo si es prácticamente seguro (NIC 37.53 · PYMES 21.9)")) | K5: =IF(J5="Compensación exigible: reconocer en resultados (NIC 16.65–66 · PYMES 17.25)",N(D5),0)
A6: POL-04 | B6: Aseguradora Alfa S.A. | C6: Daño en compresor | D6: =IF('04_Polizas'!J8="","",'04_Polizas'!J8) | E6: Sí | F6: ='05_Vigencia'!E8 | G6: =IF(OR('04_Polizas'!K8="Sí",'04_Polizas'!K8="Si"),"Revelado","Sin revelación: evaluar NIC 16.65–66, NIC 36.12 e), NIC 37.31–35/86/89 · PYMES 17.25 y 21") | H6: =IF('04_Polizas'!L8="","",'04_Polizas'!L8) | I6: =IF('04_Polizas'!M8="","",'04_Polizas'!M8) | J6: =IF(H6="","Tipo no informado: se mantiene el tratamiento de reclamo de terceros (NIC 37.53)",IF(H6="Daño a activo propio",IF(I6="Sí","Compensación exigible: reconocer en resultados (NIC 16.65–66 · PYMES 17.25)",IF(I6="No","Activo contingente: no se reconoce; revelar si es probable (NIC 37.31–35 y 89 · PYMES 21.16)","Exigibilidad no informada: tratado como activo contingente (NIC 37.31–35)")),"Reclamo de terceros: provisión y reembolso solo si es prácticamente seguro (NIC 37.53 · PYMES 21.9)")) | K6: =IF(J6="Compensación exigible: reconocer en resultados (NIC 16.65–66 · PYMES 17.25)",N(D6),0)
A8: ⓘ Cómo se calcula esta hoja
A9: Columna | B9: Fórmula (Excel) | C9: Cómo se calcula (sencillo) | D9: Ejemplo con números reales | E9: De dónde viene | F9: Norma
A10: Monto | B10: '=IF('04_Polizas'!J6="","",'04_Polizas'!J6) | C10: Trae el monto del siniestro pendiente informado en la hoja 04 (Pólizas); en blanco si no se informó. | D10: Fila 1: IF(18.000,00=""; ""; 18.000,00) → 18.000,00 | E10: hoja «Pólizas (datos del cliente)» | F10: —
A11: Estado de la póliza | B11: '='05_Vigencia'!E6 | C11: Trae el estado al corte de la póliza del siniestro desde la hoja 05 (Vigencia de pólizas al corte). | D11: Fila 1: «Vigente» → Vigente | E11: hoja «Vigencia de pólizas al corte» | F11: —
A12: Evaluación | B12: '=IF(OR('04_Polizas'!K6="Sí",'04_Polizas'!K6="Si"),"Revelado","Sin revelación: evaluar NIC 16.65–66, NIC 36.12 e), NIC 37.31–35/86/89 · PYMES 17.25 y 21") | C12: Si el cliente indicó en la hoja 04 (Pólizas) que el siniestro está revelado (Sí), dice «Revelado»; si no, advierte que falta la revelación y qué normas evaluar. | D12: Fila 1: IF(OR(«No»="Sí"; «No»="Si"); "Revelado"; "Sin revelación: evaluar NIC 16.65–66, NIC 36.12 e), NIC 37.31–35/86/89 · PYMES 17.25 y 21") → Sin revelación: evaluar NIC 16.65–66, NIC 36.12 e), NIC 37.31–35/86/89 · PYMES 17.25 y 21 | E12: hoja «Pólizas (datos del cliente)» | F12: —
A13: Tipo de siniestro | B13: '=IF('04_Polizas'!L6="","",'04_Polizas'!L6) | C13: Trae el tipo de siniestro (daño a activo propio o reclamo de terceros) informado en la hoja 04 (Pólizas). | D13: Fila 1: IF(«Daño a activo propio»=""; ""; «Daño a activo propio») → Daño a activo propio | E13: hoja «Pólizas (datos del cliente)» | F13: —
A14: Cobro exigible | B14: '=IF('04_Polizas'!M6="","",'04_Polizas'!M6) | C14: Trae la respuesta del cliente (Sí/No) sobre si el cobro a la aseguradora ya es exigible, según la hoja 04 (Pólizas). | D14: Fila 1: IF(«Sí»=""; ""; «Sí») → Sí | E14: hoja «Pólizas (datos del cliente)» | F14: —
